Workbook

Sheet 生產管理報表(週) 
A1: 長家廠生產管理報表
A3: 月別 | B3: 3 | C3: 週別 | D3: W4 | E3: 工廠 | F3: 長家廠
A4: （１）收支狀況 | E4: ※單位：千元 | G4: （２）ＫＰＩ達成進度
A5: 項目 | B5: 當週 | C5: 前週 | D5: 差異 | E5: 累計 | G5: 項目 | H5: KPI | I5: 當週 | J5: 前週 | K5: 累計 | L5: ※補充
A6: 業績金額 | B6: 17930.76 | C6: 18647 | D6: =B6-C6 -> -716.24 | E6: ='（１）收支狀況'!H5/1000 -> 82375.817 | G6: 人時性(個/月均) | H6: 126.9 | I6: 116.1 | J6: 111.7 | K6: 113.6 | L6: 個／MH
A7: 訂單數量 | B7: 386754 | C7: 398848 | D7: =B7-C7 -> -12094 | E7: ='（１）收支狀況'!K5 -> 1781527 | G7: 人時達成率(%/月均) | H7: 0.8 | I7: =I6/H6 -> 0.91489362 | J7: =J6/H6 -> 0.88022065 | K7: =K6/H6 -> 0.89519307 | L7: 達成率
A8: 材料費 | B8: 11336.93 | C8: 11775.45 | D8: =B8-C8 -> -438.52 | E8: 52023.518 | G8: 半成品-報廢(%) | H8: 0.0025 | I8: 0.0019 | J8: 0.0042 | K8: 0.0031 | L8: 報廢率
A9: 材料費率 | B9: =B8/B6 -> 0.63226154 | C9: =C8/C6 -> 0.631493 | D9: =B9-C9 -> 0.00076854229 | E9: =E8/E6 -> 0.63153872 | G9: 半成品-超用(%) | H9: 0.0025 | I9: 0.0019 | J9: 0.0026 | K9: 0.0021 | L9: 超用率
A10: 勞務成本 | D10: =B10-C10 -> 0 | G10: 固定產線-導入率(%) | H10: 1 | I10: 0.2857 | J10: 0.2857 | K10: 0.2857 | L10: 導入率
A11: 勞務費率 | D11: =B11-C11 -> 0 | G11: 教育訓練-實施率(%) | H11: 1 | I11: 0.928 | J11: 0.88 | K11: 0.807 | L11: 實施率
A13: （３）業績構成比 | G13: （４）訂單數量構成比
B14: 當週 | C14: 比例 | D14: 前週 | E14: 差異 | H14: 當週 | I14: 比例 | J14: 前週 | K14: 差異
A15: 熱食義麵(122,123,124,126) | B15: 16014.995 | C15: =B15/B6 -> 0.89315762 | D15: 0.8987 | E15: =IFERROR(C15-D15,"") -> -0.0055423759 | G15: 熱食義麵(122,123,124,126) | H15: 316604 | I15: =IFERROR(H15/$B$7,"") -> 0.81861855 | J15: 0.827 | K15: =IFERROR(I15-J15,"") -> -0.0083814466
A16: 季節調理麵(111,112) | C16: =IFERROR(B16/$B$6,"") -> 0 | D16: 0 | E16: =IFERROR(C16-D16,"") -> 0 | G16: 季節調理麵(111,112) | I16: =IFERROR(H16/$B$7,"") -> 0 | J16: 0 | K16: =IFERROR(I16-J16,"") -> 0
A17: 微波小吃(153,154,155) | B17: 1915.767 | C17: =B17/B6 -> 0.10684249 | D17: 0.1014 | E17: =IFERROR(C17-D17,"") -> 0.0054424874 | G17: 微波小吃(153,154,155) | H17: 70150 | I17: =IFERROR(H17/$B$7,"") -> 0.18138145 | J17: 0.173 | K17: =IFERROR(I17-J17,"") -> 0.0083814466
C18: =SUM(C15:C17) -> 1.0000001 | D18: =SUM(D15:D17) -> 1.0001 | I18: =SUM(I15:I17) -> 1 | J18: =SUM(J15:J17) -> 1
A20: （５）品群別人時生產性
A21: 品群 | B21: 當週 | C21: 前週 | D21: 差異 | E21: 累計
A22: 熱食義麵(122,123,124,126) | B22: 112.6 | C22: 110.7 | D22: =B22-C22 -> 1.9 | E22: 109.6
A23: 季節調理麵(111,112) | D23: =B23-C23 -> 0
A24: 微波小吃(153,154,155) | B24: 121.9 | C24: 114.6 | D24: =B24-C24 -> 7.3 | E24: 120

Sheet （１）收支狀況
B2: （１）收支狀況
B3: 資料繳交日 | C3: 月份 | D3: 日期 | F3: 營業額(元) | I3: 訂單數量(個) | L3: 材料費(元) | O3: 材料費率（材料費／營業額） | R3: 勞務成本（全廠人事成本） | U3: 勞務費率（勞務成本／營業額）
F4: 日 | G4: 週累積 | H4: 月累積 | I4: 日 | J4: 週累積 | K4: 月累積 | L4: 日 | M4: 週累積 | N4: 月累積 | O4: 日 | P4: 週累積 | Q4: 月累積 | R4: 日 | S4: 週累積 | T4: 月累積 | U4: 日 | V4: 週累積 | W4: 月累積
C5: 三 | D5: 46082 | E5: 日 | F5: 2884541 | H5: =SUM(F5:F35) -> 82375817 | I5: 61259 | K5: =SUM(I5:I35) -> 1781527 | L5: 1818960.8 | N5: =SUM(L5:L35) -> 52023518 | O5: =L5/F5 -> 0.63058935 | Q5: =N5/H5 -> 0.63153872 | T5: 0 | U5: =R5/F5 -> 0 | W5: =T5/H5 -> 0
D6: 46083 | E6: 一 | F6: 2709898.6 | I6: 57720 | L6: 1712236.1 | O6: =L6/F6 -> 0.63184509 | U6: =R6/F6 -> 0 | V6: =S6/M6 -> #DIV/0!
B7: 46092 | D7: 46084 | E7: 二 | F7: 3337838.2 | G7: =SUM(F7:F13) -> 19804480 | I7: 73597 | J7: =SUM(I7:I13) -> 433192 | L7: 2108838.1 | M7: =SUM(L7:L13) -> 12499922 | O7: =L7/F7 -> 0.63179757 | P7: =M7/G7 -> 0.6311664 | U7: =R7/F7 -> 0
D8: 46085 | E8: 三 | F8: 2776992.8 | I8: 60633 | L8: 1752505.5 | O8: =L8/F8 -> 0.63108031 | U8: =R8/F8 -> 0
D9: 46086 | E9: 四 | F9: 2540968.6 | I9: 55438 | L9: 1603810.2 | O9: =L9/F9 -> 0.63118065 | U9: =R9/F9 -> 0
D10: 46087 | E10: 五 | F10: 2368939.6 | I10: 51832 | L10: 1496032 | O10: =L10/F10 -> 0.63151967 | S10: =SUM(R10:R16) -> 0 | U10: =R10/F10 -> 0
D11: 46088 | E11: 六 | F11: 2565603.7 | I11: 55948 | L11: 1617830.4 | O11: =L11/F11 -> 0.63058466 | U11: =R11/F11 -> 0
D12: 46089 | E12: 日 | F12: 3233667.1 | I12: 70541 | L12: 2041210.3 | O12: =L12/F12 -> 0.63123699 | U12: =R12/F12 -> 0
D13: 46090 | E13: 一 | F13: 2980469.7 | I13: 65203 | L13: 1879695.9 | O13: =L13/F13 -> 0.63067104 | U13: =R13/F13 -> 0 | V13: =S13/M13 -> #DIV/0!
B14: 46099 | D14: 46091 | E14: 二 | F14: 2748349.5 | G14: =SUM(F14:F20) -> 17944672 | I14: 59799 | J14: =SUM(I14:I20) -> 390398 | L14: 1735460.2 | M14: =SUM(L14:L20) -> 11328143 | O14: =L14/F14 -> 0.63145542 | P14: =M14/G14 -> 0.63128172 | U14: =R14/F14 -> 0
D15: 46092 | E15: 三 | F15: 2487921.2 | I15: 53821 | L15: 1570390.3 | O15: =L15/F15 -> 0.63120583 | U15: =R15/F15 -> 0
D16: 46093 | E16: 四 | F16: 2263445.3 | I16: 49504 | L16: 1428970.5 | O16: =L16/F16 -> 0.63132541 | U16: =R16/F16 -> 0
D17: 46094 | E17: 五 | F17: 2289733.2 | I17: 49829 | L17: 1445531.9 | O17: =L17/F17 -> 0.6313102 | S17: =SUM(R17:R23) -> 0 | U17: =R17/F17 -> 0
D18: 46095 | E18: 六 | F18: 2363381 | I18: 51404 | L18: 1490930 | O18: =L18/F18 -> 0.63084625 | U18: =R18/F18 -> 0
D19: 46096 | E19: 日 | F19: 2928861.1 | I19: 63491 | L19: 1849182.5 | O19: =L19/F19 -> 0.63136572 | U19: =R19/F19 -> 0
D20: 46097 | E20: 一 | F20: 2862980.4 | I20: 62550 | L20: 1807677.7 | O20: =L20/F20 -> 0.63139715 | U20: =R20/F20 -> 0 | V20: =S20/M20 -> #DIV/0!
B21: 46106 | D21: 46098 | E21: 二 | F21: 3035263.9 | G21: =SUM(F21:F27) -> 18647709 | I21: 64275 | J21: =SUM(I21:I27) -> 398848 | L21: 1917616.3 | M21: =SUM(L21:L27) -> 11775457 | O21: =L21/F21 -> 0.63177909 | P21: =M21/G21 -> 0.63146935 | U21: =R21/F21 -> 0
D22: 46099 | E22: 三 | F22: 2618616 | I22: 56324 | L22: 1653728.1 | O22: =L22/F22 -> 0.63152752 | U22: =R22/F22 -> 0
D23: 46100 | E23: 四 | F23: 2451921.8 | I23: 52529 | L23: 1547710.7 | O23: =L23/F23 -> 0.63122353 | U23: =R23/F23 -> 0
D24: 46101 | E24: 五 | F24: 2235775.4 | I24: 47947 | L24: 1412538.5 | O24: =L24/F24 -> 0.63178909 | S24: =SUM(R24:R30) -> 0 | U24: =R24/F24 -> 0
D25: 46102 | E25: 六 | F25: 2420850.6 | I25: 51828 | L25: 1528135.9 | O25: =L25/F25 -> 0.63123923 | U25: =R25/F25 -> 0
D26: 46103 | E26: 日 | F26: 3043824.1 | I26: 64946 | L26: 1922609.2 | O26: =L26/F26 -> 0.63164267 | U26: =R26/F26 -> 0
D27: 46104 | E27: 一 | F27: 2841457.1 | I27: 60999 | L27: 1793118 | O27: =L27/F27 -> 0.6310558 | U27: =R27/F27 -> 0 | V27: =S27/M27 -> #DIV/0!
B28: 46113 | D28: 46105 | E28: 二 | F28: 2669131.3 | G28: =SUM(F28:F34) -> 17930762 | I28: 57426 | J28: =SUM(I28:I34) -> 386754 | L28: 1689006.1 | M28: =SUM(L28:L34) -> 11336934 | O28: =L28/F28 -> 0.63279244 | P28: =M28/G28 -> 0.63226167 | U28: =R28/F28 -> 0
D29: 46106 | E29: 三 | F29: 2480475.9 | I29: 53463 | L29: 1567699.8 | O29: =L29/F29 -> 0.63201574 | U29: =R29/F29 -> 0
D30: 46107 | E30: 四 | F30: 2391314.5 | I30: 51604 | L30: 1511528.2 | O30: =L30/F30 -> 0.6320909 | U30: =R30/F30 -> 0
D31: 46108 | E31: 五 | F31: 2289329.2 | I31: 49468 | L31: 1448277.4 | O31: =L31/F31 -> 0.63262086 | S31: =SUM(R31:R37) -> 0 | U31: =R31/F31 -> 0
D32: 46109 | E32: 六 | F32: 2435638.2 | I32: 52737 | L32: 1539552.1 | O32: =L32/F32 -> 0.63209391 | U32: =R32/F32 -> 0
D33: 46110 | E33: 日 | F33: 2895859.1 | I33: 62601 | L33: 1830391.2 | O33: =L33/F33 -> 0.63207192 | U33: =R33/F33 -> 0
D34: 46111 | E34: 一 | F34: 2769014.1 | I34: 59455 | L34: 1750478.9 | O34: =L34/F34 -> 0.63216684 | U34: =R34/F34 -> 0
D35: 46112 | E35: 二 | F35: 2453754.9 | I35: 53356 | L35: 1551865.6 | O35: =L35/F35 -> 0.63244523 | U35: =R35/F35 -> 0
V37: =SUM(U37:U43) -> 0

Sheet （２）ＫＰＩ達成進度
D1: 126.9
B2: （２）ＫＰＩ達成進度
B3: 資料繳交日 | C3: 月份 | D3: 日期 | F3: 人時生產性(個/人) | I3: 人時生產性達成率(%) | L3: 半成品報廢(%) | O3: 半成品超用(%) | R3: 固定產線-導入率(固定產線數/總產線數) | U3: 教育訓練-實施率(進度/計畫)
F4: 日 | G4: 週平均 | H4: 月平均 | I4: 日 | J4: 週平均 | K4: 月平均 | L4: 日 | M4: 週平均 | N4: 月平均 | O4: 日 | P4: 週平均 | Q4: 月平均 | R4: 日 | S4: 週平均 | T4: 月平均 | U4: 日 | V4: 週平均 | W4: 月平均
C5: 三 | D5: 46082 | E5: 日 | F5: 107.6 | H5: =AVERAGE(F5:F35) -> 113.56333 | I5: =F5/$D$1 -> 0.84791174 | K5: =AVERAGE(I5:I35) -> 0.86603625 | L5: 0.0019247429 | N5: =AVERAGE(L5:L35) -> 0.0031016587 | O5: 0.00044235807 | Q5: =AVERAGE(O5:O35) -> 0.0020506641 | R5: 0.2857 | T5: =AVERAGE(R5:R34) -> 0.2857 | U5: 0.7 | W5: =AVERAGE(U5:U34) -> 0.80677333
D6: 46083 | E6: 一 | F6: 109.4 | I6: =F6/$D$1 -> 0.86209614 | L6: 0.0053906077 | O6: 0.002698625 | R6: 0.2857 | U6: 0.7
B7: 46092 | D7: 46084 | E7: 二 | F7: 110.9 | G7: =AVERAGE(F7:F13) -> 111.87143 | I7: =F7/$D$1 -> 0.87391647 | J7: =AVERAGE(I7:I13) -> 0.88157154 | L7: 0.0030909227 | M7: =AVERAGE(L7:L13) -> 0.0033344489 | O7: 0.001666348 | P7: =AVERAGE(O7:O13) -> 0.0015562027 | R7: 0.2857 | S7: =AVERAGE(R7:R13) -> 0.2857 | U7: 0.7 | V7: =AVERAGE(U7:U13) -> 0.7
D8: 46085 | E8: 三 | F8: 108.4 | I8: =F8/$D$1 -> 0.85421592 | L8: 0.0024144823 | O8: 0.00070075802 | R8: 0.2857 | U8: 0.7
D9: 46086 | E9: 四 | F9: 108.7 | I9: =F9/$D$1 -> 0.85657998 | L9: 0.0037367639 | O9: 0.0016123772 | R9: 0.2857 | U9: 0.7
D10: 46087 | E10: 五 | F10: 112.3 | I10: =F10/$D$1 -> 0.88494878 | L10: 0.00076912048 | O10: 0.0022795009 | R10: 0.2857 | U10: 0.7
D11: 46088 | E11: 六 | F11: 111.6 | I11: =F11/$D$1 -> 0.87943262 | L11: 0.0023557808 | O11: 0.0012488289 | R11: 0.2857 | U11: 0.7
D12: 46089 | E12: 日 | F12: 113.2 | I12: =F12/$D$1 -> 0.89204098 | L12: 0.010525821 | O12: 0.0025209769 | R12: 0.2857 | U12: 0.7
D13: 46090 | E13: 一 | F13: 118 | I13: =F13/$D$1 -> 0.92986604 | L13: 0.00044825149 | O13: 0.00086462881 | R13: 0.2857 | U13: 0.7
B14: 46099 | D14: 46091 | E14: 二 | F14: 116.4 | G14: =AVERAGE(F14:F20) -> 115.98571 | I14: =F14/$D$1 -> 0.91725768 | J14: =AVERAGE(I14:I20) -> 0.91399302 | L14: 0.0027631129 | M14: =AVERAGE(L14:L20) -> 0.0030380967 | O14: 0.0023275788 | P14: =AVERAGE(O14:O20) -> 0.0022638894 | R14: 0.2857 | S14: =AVERAGE(R14:R20) -> 0.2857 | U14: 0.75 | V14: =AVERAGE(U14:U20) -> 0.75
D15: 46092 | E15: 三 | F15: 114 | I15: =F15/$D$1 -> 0.89834515 | L15: 0.0029675378 | O15: 0.0012854105 | R15: 0.2857 | U15: 0.75
D16: 46093 | E16: 四 | F16: 113.8 | I16: =F16/$D$1 -> 0.89676911 | L16: 0.0052225694 | O16: 0.00044843143 | R16: 0.2857 | U16: 0.75
D17: 46094 | E17: 五 | F17: 113.8 | I17: =F17/$D$1 -> 0.89676911 | L17: 0.0020596286 | O17: 0.0013944856 | R17: 0.2857 | U17: 0.75
D18: 46095 | E18: 六 | F18: 118.6 | I18: =F18/$D$1 -> 0.93459417 | L18: 0.003829683 | O18: 0.0052793011 | R18: 0.2857 | U18: 0.75
D19: 46096 | E19: 日 | F19: 118.6 | I19: =F19/$D$1 -> 0.93459417 | L19: 0.0023794232 | O19: 0.0024497577 | R19: 0.2857 | U19: 0.75
D20: 46097 | E20: 一 | F20: 116.7 | I20: =F20/$D$1 -> 0.91962175 | L20: 0.0020447223 | O20: 0.0026622606 | R20: 0.2857 | U20: 0.75
B21: 46106 | D21: 46098 | E21: 二 | F21: 108.1 | G21: =AVERAGE(F21:F27) -> 111.71429 | I21: =F21/$D$1 -> 0.85185185 | J21: =AVERAGE(I21:I27) -> 0.88033322 | L21: 0.0043175817 | M21: =AVERAGE(L21:L27) -> 0.0041674387 | O21: 0.002415276 | P21: =AVERAGE(O21:O27) -> 0.0025760167 | R21: 0.2857 | S21: =AVERAGE(R21:R27) -> 0.2857 | U21: 0.88 | V21: =AVERAGE(U21:U27) -> 0.88
D22: 46099 | E22: 三 | F22: 108.6 | I22: =F22/$D$1 -> 0.85579196 | L22: 0.010036218 | O22: 0.0037748949 | R22: 0.2857 | U22: 0.88
D23: 46100 | E23: 四 | F23: 112.3 | I23: =F23/$D$1 -> 0.88494878 | L23: 0.0047195633 | O23: 0.0028793741 | R23: 0.2857 | U23: 0.88
D24: 46101 | E24: 五 | F24: 109.8 | I24: =F24/$D$1 -> 0.86524823 | L24: 0.0041784162 | O24: 0.0039189984 | R24: 0.2857 | U24: 0.88
D25: 46102 | E25: 六 | F25: 114.6 | I25: =F25/$D$1 -> 0.90307329 | L25: 0.0024892077 | O25: 0.0025553002 | R25: 0.2857 | U25: 0.88
D26: 46103 | E26: 日 | F26: 116.3 | I26: =F26/$D$1 -> 0.91646966 | L26: 0.0018269781 | O26: 0.0020244271 | R26: 0.2857 | U26: 0.88
D27: 46104 | E27: 一 | F27: 112.3 | I27: =F27/$D$1 -> 0.88494878 | L27: 0.0016041065 | O27: 0.00046384652 | R27: 0.2857 | U27: 0.88
B28: 46113 | D28: 46105 | E28: 二 | F28: 116.2 | G28: =AVERAGE(F28:F34) -> 116.12857 | I28: =F28/$D$1 -> 0.91568164 | J28: =AVERAGE(I28:I34) -> 0.91511877 | L28: 0.00098421536 | M28: =AVERAGE(L28:L34) -> 0.0019191096 | O28: 0.0014532818 | P28: =AVERAGE(O28:O34) -> 0.001931096 | R28: 0.2857 | S28: =AVERAGE(R28:R34) -> 0.2857 | U28: 0.9276 | V28: =AVERAGE(U28:U34) -> 0.9276
D29: 46106 | E29: 三 | F29: 116.6 | I29: =F29/$D$1 -> 0.91883373 | L29: 0.00053820317 | O29: 0.0016706471 | R29: 0.2857 | U29: 0.9276
D30: 46107 | E30: 四 | F30: 113 | I30: =F30/$D$1 -> 0.89046493 | L30: 0.00083426917 | O30: 0.00073892412 | R30: 0.2857 | U30: 0.9276
D31: 46108 | E31: 五 | F31: 115.5 | I31: =F31/$D$1 -> 0.91016548 | L31: 0.0039885045 | O31: 0.0018979359 | R31: 0.2857 | U31: 0.9276
D32: 46109 | E32: 六 | F32: 115.5 | I32: =F32/$D$1 -> 0.91016548 | L32: 0.0021567242 | O32: 0.0011742302 | R32: 0.2857 | U32: 0.9276
D33: 46110 | E33: 日 | F33: 119.9 | I33: =F33/$D$1 -> 0.94483846 | L33: 0.0023937629 | O33: 0.0034967171 | R33: 0.2857 | U33: 0.9276
D34: 46111 | E34: 一 | F34: 116.2 | I34: =F34/$D$1 -> 0.91568164 | L34: 0.0025380875 | O34: 0.0030859359 | R34: 0.2857 | U34: 0.9276
D35: 46112 | E35: 二 | I35: =F35/$D$1 -> 0 | L35: 0.0016224115 | O35: 0.0021391705 | R35: 0.2857 | U35: 0.9276

Sheet （３）業績構成比
B2: （3）業績構成比
B3: 資料繳交日 | C3: 月份 | D3: 日期 | F3: 營業額 | I3: 品類業績
I4: 熱食義麵 | K4: 季節調理麵 | M4: 微波小吃
F5: 日 | G5: 週累積 | H5: 月累積 | I5: 一配 | K5: 一配 | M5: 一配
I6: 業績(元) | J6: 比例(%) | K6: 業績(元) | L6: 比例(%) | M6: 業績(元) | N6: 比例(%)
C7: 三 | D7: 46082 | E7: 日 | F7: =I7+M7 -> 3086432.2 | H7: =SUM(F7:F37) -> 82783016 | I7: 2884541 | J7: =I7/F7 -> 0.93458752 | L7: =K7/F7 -> 0 | M7: 201891.18 | N7: =M7/F7 -> 0.065412478
D8: 46083 | E8: 一 | F8: =I8+M8 -> 2915206.3 | I8: 2709898.6 | J8: =I8/F8 -> 0.92957351 | L8: =K8/F8 -> 0 | M8: 205307.76 | N8: =M8/F8 -> 0.070426494
B9: 46092 | D9: 46084 | E9: 二 | F9: =I9+M9 -> 3337838.2 | G9: =SUM(F9:F15) -> 19804480 | I9: 2883186 | J9: =I9/F9 -> 0.86378844 | L9: =K9/F9 -> 0 | M9: 454652.16 | N9: =M9/F9 -> 0.13621156
D10: 46085 | E10: 三 | F10: =I10+M10 -> 2776992.8 | I10: 2448732.8 | J10: =I10/F10 -> 0.881793 | L10: =K10/F10 -> 0 | M10: 328259.99 | N10: =M10/F10 -> 0.118207
D11: 46086 | E11: 四 | F11: =I11+M11 -> 2540968.6 | I11: 2229621.1 | J11: =I11/F11 -> 0.87746895 | L11: =K11/F11 -> 0 | M11: 311347.56 | N11: =M11/F11 -> 0.12253105
D12: 46087 | E12: 五 | F12: =I12+M12 -> 2368939.6 | I12: 2090737 | J12: =I12/F12 -> 0.88256239 | L12: =K12/F12 -> 0 | M12: 278202.61 | N12: =M12/F12 -> 0.11743761
D13: 46088 | E13: 六 | F13: =I13+M13 -> 2565603.7 | I13: 2265447.1 | J13: =I13/F13 -> 0.88300742 | L13: =K13/F13 -> 0 | M13: 300156.59 | N13: =M13/F13 -> 0.11699258
D14: 46089 | E14: 日 | F14: =I14+M14 -> 3233667.1 | I14: 2856007.3 | J14: =I14/F14 -> 0.88321006 | L14: =K14/F14 -> 0 | M14: 377659.8 | N14: =M14/F14 -> 0.11678994
D15: 46090 | E15: 一 | F15: =I15+M15 -> 2980469.7 | I15: 2631141.6 | J15: =I15/F15 -> 0.88279426 | L15: =K15/F15 -> 0 | M15: 349328.17 | N15: =M15/F15 -> 0.11720574
B16: 46099 | D16: 46091 | E16: 二 | F16: =I16+M16 -> 2748349.5 | G16: =SUM(F16:F22) -> 17944672 | I16: 2450009.4 | J16: =I16/F16 -> 0.89144753 | L16: =K16/F16 -> 0 | M16: 298340.13 | N16: =M16/F16 -> 0.10855247
D17: 46092 | E17: 三 | F17: =I17+M17 -> 2487921.2 | I17: 2219603.3 | J17: =I17/F17 -> 0.89215178 | L17: =K17/F17 -> 0 | M17: 268317.86 | N17: =M17/F17 -> 0.10784822
D18: 46093 | E18: 四 | F18: =I18+M18 -> 2263445.3 | I18: 1980864.8 | J18: =I18/F18 -> 0.87515472 | L18: =K18/F18 -> 0 | M18: 282580.45 | N18: =M18/F18 -> 0.12484528
D19: 46094 | E19: 五 | F19: =I19+M19 -> 2289733.2 | I19: 2018904.3 | J19: =I19/F19 -> 0.88172033 | L19: =K19/F19 -> 0 | M19: 270828.89 | N19: =M19/F19 -> 0.11827967
D20: 46095 | E20: 六 | F20: =I20+M20 -> 2363381 | I20: 2088211.2 | J20: =I20/F20 -> 0.88356943 | L20: =K20/F20 -> 0 | M20: 275169.8 | N20: =M20/F20 -> 0.11643057
D21: 46096 | E21: 日 | F21: =I21+M21 -> 2928861.1 | I21: 2610805.8 | J21: =I21/F21 -> 0.8914065 | L21: =K21/F21 -> 0 | M21: 318055.29 | N21: =M21/F21 -> 0.1085935
D22: 46097 | E22: 一 | F22: =I22+M22 -> 2862980.4 | I22: 2518150.8 | J22: =I22/F22 -> 0.87955571 | L22: =K22/F22 -> 0 | M22: 344829.65 | N22: =M22/F22 -> 0.12044429
B23: 46106 | D23: 46098 | E23: 二 | F23: =I23+M23 -> 3035263.9 | G23: =SUM(F23:F29) -> 18647709 | I23: 2753961.8 | J23: =I23/F23 -> 0.90732203 | L23: =K23/F23 -> 0 | M23: 281302.1 | N23: =M23/F23 -> 0.09267797
D24: 46099 | E24: 三 | F24: =I24+M24 -> 2618616 | I24: 2333905.2 | J24: =I24/F24 -> 0.89127435 | L24: =K24/F24 -> 0 | M24: 284710.73 | N24: =M24/F24 -> 0.10872565
D25: 46100 | E25: 四 | F25: =I25+M25 -> 2451921.8 | I25: 2193250 | J25: =I25/F25 -> 0.89450243 | L25: =K25/F25 -> 0 | M25: 258671.8 | N25: =M25/F25 -> 0.10549757
D26: 46101 | E26: 五 | F26: =I26+M26 -> 2235775.4 | I26: 2001389.9 | J26: =I26/F26 -> 0.89516592 | L26: =K26/F26 -> 0 | M26: 234385.46 | N26: =M26/F26 -> 0.10483408
D27: 46102 | E27: 六 | F27: =I27+M27 -> 2420850.6 | I27: 2172423.4 | J27: =I27/F27 -> 0.89738021 | L27: =K27/F27 -> 0 | M27: 248427.19 | N27: =M27/F27 -> 0.10261979
D28: 46103 | E28: 日 | F28: =I28+M28 -> 3043824.1 | I28: 2751015.2 | J28: =I28/F28 -> 0.90380229 | L28: =K28/F28 -> 0 | M28: 292808.92 | N28: =M28/F28 -> 0.096197712
D29: 46104 | E29: 一 | F29: =I29+M29 -> 2841457.1 | I29: 2551752.5 | J29: =I29/F29 -> 0.89804362 | L29: =K29/F29 -> 0 | M29: 289704.69 | N29: =M29/F29 -> 0.10195638
B30: 46113 | D30: 46105 | E30: 二 | F30: =I30+M30 -> 2669131.3 | G30: =SUM(F30:F36) -> 17930762 | I30: 2392839.5 | J30: =I30/F30 -> 0.89648625 | L30: =K30/F30 -> 0 | M30: 276291.78 | N30: =M30/F30 -> 0.10351375
D31: 46106 | E31: 三 | F31: =I31+M31 -> 2480475.9 | I31: 2217252.8 | J31: =I31/F31 -> 0.89388199 | L31: =K31/F31 -> 0 | M31: 263223.17 | N31: =M31/F31 -> 0.10611801
D32: 46107 | E32: 四 | F32: =I32+M32 -> 2391314.5 | I32: 2129349.6 | J32: =I32/F32 -> 0.89045151 | L32: =K32/F32 -> 0 | M32: 261964.89 | N32: =M32/F32 -> 0.10954849
D33: 46108 | E33: 五 | F33: =I33+M33 -> 2289329.2 | I33: 2033931.6 | J33: =I33/F33 -> 0.88843997 | L33: =K33/F33 -> 0 | M33: 255397.63 | N33: =M33/F33 -> 0.11156003
D34: 46109 | E34: 六 | F34: =I34+M34 -> 2435638.2 | I34: 2159571.6 | J34: =I34/F34 -> 0.88665532 | L34: =K34/F34 -> 0 | M34: 276066.63 | N34: =M34/F34 -> 0.11334468
D35: 46110 | E35: 日 | F35: =I35+M35 -> 2895859.1 | I35: 2586954.4 | J35: =I35/F35 -> 0.89332884 | L35: =K35/F35 -> 0 | M35: 308904.64 | N35: =M35/F35 -> 0.10667116
D36: 46111 | E36: 一 | F36: =I36+M36 -> 2769014.1 | I36: 2495095.6 | J36: =I36/F36 -> 0.90107727 | L36: =K36/F36 -> 0 | M36: 273918.42 | N36: =M36/F36 -> 0.098922726
D37: 46112 | E37: 二 | F37: =I37+M37 -> 2453754.9 | I37: 2193208.1 | J37: =I37/F37 -> 0.89381712 | L37: =K37/F37 -> 0 | M37: 260546.75 | N37: =M37/F37 -> 0.10618288
J38: =I38/F38 -> #DIV/0! | N38: =M38/F38 -> #DIV/0!
J39: =I39/F39 -> #DIV/0! | N39: =M39/F39 -> #DIV/0!

Sheet （４）訂單數量構成比
B2: （4）訂單數量構成比
B3: 資料繳交日 | C3: 月份 | D3: 日期 | F3: 訂單量 | I3: 品類訂單量
I4: 熱食義麵 | K4: 季節調理麵 | M4: 微波小吃
F5: 日 | G5: 週累積 | H5: 月累積 | I5: 一配 | K5: 一配 | M5: 一配
I6: 訂單數 | J6: 比例(%) | K6: 訂單數 | L6: 比例(%) | M6: 訂單數 | N6: 比例(%)
C7: 三 | D7: 46082 | E7: 日 | F7: =SUM(I7,K7,M7) -> 61259 | H7: =SUM(F7:F37) -> 1728171 | I7: 53927 | J7: =I7/F7 -> 0.88031146 | L7: =K7/F7 -> 0 | M7: 7332 | N7: =M7/F7 -> 0.11968854
D8: 46083 | E8: 一 | F8: =SUM(I8,K8,M8) -> 57720 | I8: 50276 | J8: =I8/F8 -> 0.87103257 | L8: =K8/F8 -> 0 | M8: 7444 | N8: =M8/F8 -> 0.12896743
B9: 46092 | D9: 46084 | E9: 二 | F9: =SUM(I9,K9,M9) -> 73597 | G9: =SUM(F9:F15) -> 433192 | I9: 56901 | J9: =I9/F9 -> 0.77314293 | L9: =K9/F9 -> 0 | M9: 16696 | N9: =M9/F9 -> 0.22685707
D10: 46085 | E10: 三 | F10: =SUM(I10,K10,M10) -> 60633 | I10: 48627 | J10: =I10/F10 -> 0.80198902 | L10: =K10/F10 -> 0 | M10: 12006 | N10: =M10/F10 -> 0.19801098
D11: 46086 | E11: 四 | F11: =SUM(I11,K11,M11) -> 55438 | I11: 44046 | J11: =I11/F11 -> 0.79450918 | L11: =K11/F11 -> 0 | M11: 11392 | N11: =M11/F11 -> 0.20549082
D12: 46087 | E12: 五 | F12: =SUM(I12,K12,M12) -> 51832 | I12: 41655 | J12: =I12/F12 -> 0.80365411 | L12: =K12/F12 -> 0 | M12: 10177 | N12: =M12/F12 -> 0.19634589
D13: 46088 | E13: 六 | F13: =SUM(I13,K13,M13) -> 55948 | I13: 44973 | J13: =I13/F13 -> 0.8038357 | L13: =K13/F13 -> 0 | M13: 10975 | N13: =M13/F13 -> 0.1961643
D14: 46089 | E14: 日 | F14: =SUM(I14,K14,M14) -> 70541 | I14: 56690 | J14: =I14/F14 -> 0.80364611 | L14: =K14/F14 -> 0 | M14: 13851 | N14: =M14/F14 -> 0.19635389
D15: 46090 | E15: 一 | F15: =SUM(I15,K15,M15) -> 65203 | I15: 52413 | J15: =I15/F15 -> 0.80384338 | L15: =K15/F15 -> 0 | M15: 12790 | N15: =M15/F15 -> 0.19615662
B16: 46099 | D16: 46091 | E16: 二 | F16: =SUM(I16,K16,M16) -> 59799 | G16: =SUM(F16:F22) -> 390398 | I16: 48894 | J16: =I16/F16 -> 0.81763909 | L16: =K16/F16 -> 0 | M16: 10905 | N16: =M16/F16 -> 0.18236091
D17: 46092 | E17: 三 | F17: =SUM(I17,K17,M17) -> 53821 | I17: 44022 | J17: =I17/F17 -> 0.81793352 | L17: =K17/F17 -> 0 | M17: 9799 | N17: =M17/F17 -> 0.18206648
D18: 46093 | E18: 四 | F18: =SUM(I18,K18,M18) -> 49504 | I18: 39176 | J18: =I18/F18 -> 0.79137039 | L18: =K18/F18 -> 0 | M18: 10328 | N18: =M18/F18 -> 0.20862961
D19: 46094 | E19: 五 | F19: =SUM(I19,K19,M19) -> 49829 | I19: 39928 | J19: =I19/F19 -> 0.80130045 | L19: =K19/F19 -> 0 | M19: 9901 | N19: =M19/F19 -> 0.19869955
D20: 46095 | E20: 六 | F20: =SUM(I20,K20,M20) -> 51404 | I20: 41352 | J20: =I20/F20 -> 0.80445102 | L20: =K20/F20 -> 0 | M20: 10052 | N20: =M20/F20 -> 0.19554898
D21: 46096 | E21: 日 | F21: =SUM(I21,K21,M21) -> 63491 | I21: 51847 | J21: =I21/F21 -> 0.81660393 | L21: =K21/F21 -> 0 | M21: 11644 | N21: =M21/F21 -> 0.18339607
D22: 46097 | E22: 一 | F22: =SUM(I22,K22,M22) -> 62550 | I22: 49921 | J22: =I22/F22 -> 0.79809752 | L22: =K22/F22 -> 0 | M22: 12629 | N22: =M22/F22 -> 0.20190248
B23: 46106 | D23: 46098 | E23: 二 | F23: =SUM(I23,K23,M23) -> 64275 | G23: =SUM(F23:F29) -> 398848 | I23: 53993 | J23: =I23/F23 -> 0.84003112 | L23: =K23/F23 -> 0 | M23: 10282 | N23: =M23/F23 -> 0.15996888
D24: 46099 | E24: 三 | F24: =SUM(I24,K24,M24) -> 56324 | I24: 45906 | J24: =I24/F24 -> 0.81503444 | L24: =K24/F24 -> 0 | M24: 10418 | N24: =M24/F24 -> 0.18496556
D25: 46100 | E25: 四 | F25: =SUM(I25,K25,M25) -> 52529 | I25: 43074 | J25: =I25/F25 -> 0.82000419 | L25: =K25/F25 -> 0 | M25: 9455 | N25: =M25/F25 -> 0.17999581
D26: 46101 | E26: 五 | F26: =SUM(I26,K26,M26) -> 47947 | I26: 39471 | J26: =I26/F26 -> 0.82322147 | L26: =K26/F26 -> 0 | M26: 8476 | N26: =M26/F26 -> 0.17677853
D27: 46102 | E27: 六 | F27: =SUM(I27,K27,M27) -> 51828 | I27: 42756 | J27: =I27/F27 -> 0.82495948 | L27: =K27/F27 -> 0 | M27: 9072 | N27: =M27/F27 -> 0.17504052
D28: 46103 | E28: 日 | F28: =SUM(I28,K28,M28) -> 64946 | I28: 54226 | J28: =I28/F28 -> 0.8349398 | L28: =K28/F28 -> 0 | M28: 10720 | N28: =M28/F28 -> 0.1650602
D29: 46104 | E29: 一 | F29: =SUM(I29,K29,M29) -> 60999 | I29: 50405 | J29: =I29/F29 -> 0.82632502 | L29: =K29/F29 -> 0 | M29: 10594 | N29: =M29/F29 -> 0.17367498
B30: 46113 | D30: 46105 | E30: 二 | F30: =SUM(I30,K30,M30) -> 57426 | G30: =SUM(F30:F36) -> 386754 | I30: 47323 | J30: =I30/F30 -> 0.82406924 | L30: =K30/F30 -> 0 | M30: 10103 | N30: =M30/F30 -> 0.17593076
D31: 46106 | E31: 三 | F31: =SUM(I31,K31,M31) -> 53463 | I31: 43833 | J31: =I31/F31 -> 0.81987543 | L31: =K31/F31 -> 0 | M31: 9630 | N31: =M31/F31 -> 0.18012457
D32: 46107 | E32: 四 | F32: =SUM(I32,K32,M32) -> 51604 | I32: 42017 | J32: =I32/F32 -> 0.81421983 | L32: =K32/F32 -> 0 | M32: 9587 | N32: =M32/F32 -> 0.18578017
D33: 46108 | E33: 五 | F33: =SUM(I33,K33,M33) -> 49468 | I33: 40119 | J33: =I33/F33 -> 0.81100914 | L33: =K33/F33 -> 0 | M33: 9349 | N33: =M33/F33 -> 0.18899086
D34: 46109 | E34: 六 | F34: =SUM(I34,K34,M34) -> 52737 | I34: 42639 | J34: =I34/F34 -> 0.80852153 | L34: =K34/F34 -> 0 | M34: 10098 | N34: =M34/F34 -> 0.19147847
D35: 46110 | E35: 日 | F35: =SUM(I35,K35,M35) -> 62601 | I35: 51283 | J35: =I35/F35 -> 0.81920417 | L35: =K35/F35 -> 0 | M35: 11318 | N35: =M35/F35 -> 0.18079583
D36: 46111 | E36: 一 | F36: =SUM(I36,K36,M36) -> 59455 | I36: 49390 | J36: =I36/F36 -> 0.8307123 | L36: =K36/F36 -> 0 | M36: 10065 | N36: =M36/F36 -> 0.1692877
D37: 46112 | E37: 二 | I37: 43782 | J37: =I37/F37 -> #DIV/0! | L37: =K37/F37 -> #DIV/0! | M37: 9574 | N37: =M37/F37 -> #DIV/0!
J38: =I38/F38 -> #DIV/0! | N38: =M38/F38 -> #DIV/0!
J39: =I39/F39 -> #DIV/0! | N39: =M39/F39 -> #DIV/0!

Sheet （５-1）品群別人時生產性（熱食義麵）
B1: 月平均人時性 | C1: =AVERAGE(L7,L30,L53,L76,L99,L122) -> 109.92454
B2: 產線配置圖－每週更新 | N2: 資料繳交 | O2: 日期 | AO2: 46082 | AT2: 46083
P3: 二 | U3: 三 | Z3: 四 | AE3: 五 | AJ3: 六 | AO3: 日 | AT3: 一
B4: 品群 | C4: 商品名稱 | E4: 計畫 | H4: 平均人時性 | I4: 實績 | L4: 平均人時性 | M4: 排名 | O4: 日報 | P4: 實際 | T4: 平均人時性 | U4: 實際 | Y4: 平均人時性 | Z4: 實際 | AD4: 平均人時性 | AE4: 實際 | AI4: 平均人時性 | AJ4: 實際 | AN4: 平均人時性 | AO4: 實際 | AS4: 平均人時性 | AT4: 實際 | AX4: 平均人時性
E5: 產線配置圖 | I5: 產線配置圖 | P5: 生產實績 | U5: 生產實績 | Z5: 生產實績 | AE5: 生產實績 | AJ5: 生產實績 | AO5: 生產實績 | AT5: 生產實績
E6: 人數 | F6: 產能／時 | G6: 人時性 | I6: 人數 | J6: 產能／時 | K6: 人時性 | P6: 人數 | Q6: 產能／時 | R6: 人時性 | S6: 排名 | U6: 人數 | V6: 產能／時 | W6: 人時性 | X6: 排名 | Z6: 人數 | AA6: 產能／時 | AB6: 人時性 | AC6: 排名 | AE6: 人數 | AF6: 產能／時 | AG6: 人時性 | AH6: 排名 | AJ6: 人數 | AK6: 產能／時 | AL6: 人時性 | AM6: 排名 | AO6: 人數 | AP6: 產能／時 | AQ6: 人時性 | AR6: 排名 | AT6: 人數 | AU6: 產能／時 | AV6: 人時性 | AW6: 排名
B7: 熱食義麵 | C7: 1 | D7: 義式蕃茄起司義大利麵 | E7: =VLOOKUP(D7,'12產線配置圖'!$A$2:$C$25,2,0) -> 11 | F7: =VLOOKUP(D7,'12產線配置圖'!$A$2:$C$25,3,0) -> 2118 | G7: =F7/E7 -> 192.54545 | H7: =AVERAGE(G7:G24) -> #N/A | I7: =AVERAGE(P7,U7,Z7,AE7,AJ7,AO7,AT7) -> 13 | J7: =AVERAGE(Q7,V7,AA7,AF7,AK7,AP7,AU7) -> 1993.5 | K7: =AVERAGE(AQ7,AV7) -> 155.36061 | L7: =IFERROR(AVERAGE(K7:K24),"-") -> 106.91084 | M7: =RANK(K7,$K$7:$K$22) -> 1 | R7: =Q7/P7 -> #DIV/0! | S7: =RANK(R7,R$7:R$22) -> #DIV/0! | T7: =AVERAGE(R7:R24) -> #DIV/0! | W7: =V7/U7 -> #DIV/0! | X7: =RANK(W7,W$7:W$22) -> #DIV/0! | Y7: =AVERAGE(W7:W24) -> #DIV/0! | AB7: =AA7/Z7 -> #DIV/0! | AC7: =RANK(AB7,AB$7:AB$22) -> #DIV/0! | AD7: =AVERAGE(AB7:AB24) -> #DIV/0! | AG7: =AF7/AE7 -> #DIV/0! | AH7: =RANK(AG7,AG$7:AG$22) -> #DIV/0! | AI7: =AVERAGE(AG7:AG24) -> #DIV/0! | AL7: =AK7/AJ7 -> #DIV/0! | AM7: =RANK(AL7,AL$7:AL$22) -> #DIV/0! | AN7: =AVERAGE(AL7:AL24) -> #DIV/0! | AO7: 15 | AP7: 2134 | AQ7: =AP7/AO7 -> 142.26667 | AR7: =RANK(AQ7,$AQ$99:$AQ$116) -> #N/A | AS7: =AVERAGE(AQ7:AQ24) -> 105.78078 | AT7: 11 | AU7: 1853 | AV7: =AU7/AT7 -> 168.45455 | AW7: =RANK(AV7,$AV$99:$AV$116) -> #N/A | AX7: =AVERAGE(AV7:AV24) -> 108.0409
C8: 2 | D8: 奶油培根義大利麵 | E8: =VLOOKUP(D8,'12產線配置圖'!$A$2:$C$25,2,0) -> 13 | F8: =VLOOKUP(D8,'12產線配置圖'!$A$2:$C$25,3,0) -> 2118 | G8: =F8/E8 -> 162.92308 | I8: =AVERAGE(P8,U8,Z8,AE8,AJ8,AO8,AT8) -> 14.5 | J8: =AVERAGE(Q8,V8,AA8,AF8,AK8,AP8,AU8) -> 1941.5 | K8: =AVERAGE(AQ8,AV8) -> 133.76905 | M8: =RANK(K8,$K$7:$K$22) -> 4 | R8: =Q8/P8 -> #DIV/0! | S8: =RANK(R8,R$7:R$22) -> #DIV/0! | W8: =V8/U8 -> #DIV/0! | X8: =RANK(W8,W$7:W$22) -> #DIV/0! | AB8: =AA8/Z8 -> #DIV/0! | AC8: =RANK(AB8,AB$7:AB$22) -> #DIV/0! | AG8: =AF8/AE8 -> #DIV/0! | AH8: =RANK(AG8,AG$7:AG$22) -> #DIV/0! | AL8: =AK8/AJ8 -> #DIV/0! | AM8: =RANK(AL8,AL$7:AL$22) -> #DIV/0! | AO8: 15 | AP8: 2062 | AQ8: =AP8/AO8 -> 137.46667 | AR8: =RANK(AQ8,$AQ$99:$AQ$116) -> #N/A | AT8: 14 | AU8: 1821 | AV8: =AU8/AT8 -> 130.07143 | AW8: =RANK(AV8,$AV$99:$AV$116) -> #N/A
C9: 3 | D9: 青醬蛤蜊義大利麵 | E9: =VLOOKUP(D9,'12產線配置圖'!$A$2:$C$25,2,0) -> 12 | F9: =VLOOKUP(D9,'12產線配置圖'!$A$2:$C$25,3,0) -> 2118 | G9: =F9/E9 -> 176.5 | I9: =AVERAGE(P9,U9,Z9,AE9,AJ9,AO9,AT9) -> 14.5 | J9: =AVERAGE(Q9,V9,AA9,AF9,AK9,AP9,AU9) -> 2011 | K9: =AVERAGE(AQ9,AV9) -> 138.47619 | M9: =RANK(K9,$K$7:$K$22) -> 3 | R9: =Q9/P9 -> #DIV/0! | S9: =RANK(R9,R$7:R$22) -> #DIV/0! | W9: =V9/U9 -> #DIV/0! | X9: =RANK(W9,W$7:W$22) -> #DIV/0! | AB9: =AA9/Z9 -> #DIV/0! | AC9: =RANK(AB9,AB$7:AB$22) -> #DIV/0! | AG9: =AF9/AE9 -> #DIV/0! | AH9: =RANK(AG9,AG$7:AG$22) -> #DIV/0! | AL9: =AK9/AJ9 -> #DIV/0! | AM9: =RANK(AL9,AL$7:AL$22) -> #DIV/0! | AO9: 15 | AP9: 2170 | AQ9: =AP9/AO9 -> 144.66667 | AR9: =RANK(AQ9,$AQ$99:$AQ$116) -> #N/A | AT9: 14 | AU9: 1852 | AV9: =AU9/AT9 -> 132.28571 | AW9: =RANK(AV9,$AV$99:$AV$116) -> #N/A
C10: 4 | D10: 焗烤起司雙饗筆尖麵 | E10: =VLOOKUP(D10,'12產線配置圖'!$A$2:$C$25,2,0) -> 16 | F10: =VLOOKUP(D10,'12產線配置圖'!$A$2:$C$25,3,0) -> 1800 | G10: =F10/E10 -> 112.5 | I10: =AVERAGE(P10,U10,Z10,AE10,AJ10,AO10,AT10) -> 16 | J10: =AVERAGE(Q10,V10,AA10,AF10,AK10,AP10,AU10) -> 1685.5 | K10: =AVERAGE(AQ10,AV10) -> 105.34375 | M10: =RANK(K10,$K$7:$K$22) -> 6 | R10: =Q10/P10 -> #DIV/0! | S10: =RANK(R10,R$7:R$22) -> #DIV/0! | W10: =V10/U10 -> #DIV/0! | X10: =RANK(W10,W$7:W$22) -> #DIV/0! | AB10: =AA10/Z10 -> #DIV/0! | AC10: =RANK(AB10,AB$7:AB$22) -> #DIV/0! | AG10: =AF10/AE10 -> #DIV/0! | AH10: =RANK(AG10,AG$7:AG$22) -> #DIV/0! | AL10: =AK10/AJ10 -> #DIV/0! | AM10: =RANK(AL10,AL$7:AL$22) -> #DIV/0! | AO10: 16 | AP10: 1697 | AQ10: =AP10/AO10 -> 106.0625 | AR10: =RANK(AQ10,$AQ$99:$AQ$116) -> #N/A | AT10: 16 | AU10: 1674 | AV10: =AU10/AT10 -> 104.625 | AW10: =RANK(AV10,$AV$99:$AV$116) -> #N/A
C11: 5 | D11: 白酒蛤蜊義大利麵 | E11: =VLOOKUP(D11,'12產線配置圖'!$A$2:$C$25,2,0) -> #N/A | F11: =VLOOKUP(D11,'12產線配置圖'!$A$2:$C$25,3,0) -> #N/A | G11: =F11/E11 -> #N/A | I11: =AVERAGE(P11,U11,Z11,AE11,AJ11,AO11,AT11) -> 15.5 | J11: =AVERAGE(Q11,V11,AA11,AF11,AK11,AP11,AU11) -> 2167.5 | K11: =AVERAGE(AQ11,AV11) -> 139.77708 | M11: =RANK(K11,$K$7:$K$22) -> 2 | R11: =Q11/P11 -> #DIV/0! | S11: =RANK(R11,R$7:R$22) -> #DIV/0! | W11: =V11/U11 -> #DIV/0! | X11: =RANK(W11,W$7:W$22) -> #DIV/0! | AB11: =AA11/Z11 -> #DIV/0! | AC11: =RANK(AB11,AB$7:AB$22) -> #DIV/0! | AG11: =AF11/AE11 -> #DIV/0! | AH11: =RANK(AG11,AG$7:AG$22) -> #DIV/0! | AL11: =AK11/AJ11 -> #DIV/0! | AM11: =RANK(AL11,AL$7:AL$22) -> #DIV/0! | AO11: 16 | AP11: 2267 | AQ11: =AP11/AO11 -> 141.6875 | AR11: =RANK(AQ11,$AQ$99:$AQ$116) -> #N/A | AT11: 15 | AU11: 2068 | AV11: =AU11/AT11 -> 137.86667 | AW11: =RANK(AV11,$AV$99:$AV$116) -> #N/A
C12: 6 | D12: 青花椒麻雞肉拌麵 | E12: =VLOOKUP(D12,'12產線配置圖'!$A$2:$C$25,2,0) -> 15 | F12: =VLOOKUP(D12,'12產線配置圖'!$A$2:$C$25,3,0) -> 1714 | G12: =F12/E12 -> 114.26667 | I12: 15 | J12: 1420 | K12: 94.666667 | M12: =RANK(K12,$K$7:$K$22) -> 10 | R12: =Q12/P12 -> #DIV/0! | S12: =RANK(R12,R$7:R$22) -> #DIV/0! | W12: =V12/U12 -> #DIV/0! | X12: =RANK(W12,W$7:W$22) -> #DIV/0! | AB12: =AA12/Z12 -> #DIV/0! | AC12: =RANK(AB12,AB$7:AB$22) -> #DIV/0! | AG12: =AF12/AE12 -> #DIV/0! | AH12: =RANK(AG12,AG$7:AG$22) -> #DIV/0! | AL12: =AK12/AJ12 -> #DIV/0! | AM12: =RANK(AL12,AL$7:AL$22) -> #DIV/0! | AO12: 15 | AP12: 1439 | AQ12: 95.933333 | AR12: 9 | AT12: 15 | AU12: 1401 | AV12: 93.4 | AW12: 10
C13: 7 | D13: 剝皮辣椒雞奶油扁麵 | E13: =VLOOKUP(D13,'12產線配置圖'!$A$2:$C$25,2,0) -> 17 | F13: =VLOOKUP(D13,'12產線配置圖'!$A$2:$C$25,3,0) -> 1714 | G13: =F13/E13 -> 100.82353 | I13: 17.5 | J13: 1258.5 | K13: 72.222039 | M13: =RANK(K13,$K$7:$K$22) -> 13 | R13: =Q13/P13 -> #DIV/0! | S13: =RANK(R13,R$7:R$22) -> #DIV/0! | W13: =V13/U12 -> #DIV/0! | X13: =RANK(W13,W$7:W$22) -> #DIV/0! | AB13: =AA13/Z13 -> #DIV/0! | AC13: =RANK(AB13,AB$7:AB$22) -> #DIV/0! | AG13: =AF13/AE13 -> #DIV/0! | AH13: =RANK(AG13,AG$7:AG$22) -> #DIV/0! | AL13: =AK13/AJ13 -> #DIV/0! | AM13: =RANK(AL13,AL$7:AL$22) -> #DIV/0! | AO13: 19 | AP13: 1304 | AQ13: 68.631579 | AR13: 14 | AT13: 16 | AU13: 1213 | AV13: 75.8125 | AW13: 13
C14: 8 | D14: 濃拿坡里義大利麵 | E14: =VLOOKUP(D14,'12產線配置圖'!$A$2:$C$25,2,0) -> 16 | F14: =VLOOKUP(D14,'12產線配置圖'!$A$2:$C$25,3,0) -> 1406 | G14: =F14/E14 -> 87.875 | I14: 13.5 | J14: 976 | K14: 72.1 | M14: =RANK(K14,$K$7:$K$22) -> 14 | R14: =Q14/P14 -> #DIV/0! | S14: =RANK(R14,R$7:R$22) -> #DIV/0! | W14: =V14/U14 -> #DIV/0! | X14: =RANK(W14,W$7:W$22) -> #DIV/0! | AB14: =AA14/Z14 -> #DIV/0! | AC14: =RANK(AB14,AB$7:AB$22) -> #DIV/0! | AG14: =AF14/AE14 -> #DIV/0! | AH14: =RANK(AG14,AG$7:AG$22) -> #DIV/0! | AL14: =AK14/AJ14 -> #DIV/0! | AM14: =RANK(AL14,AL$7:AL$22) -> #DIV/0! | AO14: 15 | AP14: 1108 | AQ14: 73.866667 | AR14: 13 | AT14: 12 | AU14: 844 | AV14: 70.333333 | AW14: 14
C15: 9 | D15: 奶油起司蝦仁通心粉 | E15: =VLOOKUP(D15,'12產線配置圖'!$A$2:$C$25,2,0) -> #N/A | F15: =VLOOKUP(D15,'12產線配置圖'!$A$2:$C$25,3,0) -> #N/A | G15: =F15/E15 -> #N/A | I15: 16.5 | J15: 1653 | K15: 100.14154 | M15: =RANK(K15,$K$7:$K$22) -> 9 | R15: =Q15/P15 -> #DIV/0! | S15: =RANK(R15,R$7:R$22) -> #DIV/0! | W15: =V15/U15 -> #DIV/0! | X15: =RANK(W15,W$7:W$22) -> #DIV/0! | AB15: =AA15/Z15 -> #DIV/0! | AC15: =RANK(AB15,AB$7:AB$22) -> #DIV/0! | AG15: =AF15/AE15 -> #DIV/0! | AH15: =RANK(AG15,AG$7:AG$22) -> #DIV/0! | AL15: =AK15/AJ15 -> #DIV/0! | AM15: =RANK(AL15,AL$7:AL$22) -> #DIV/0! | AO15: 17 | AP15: 1725 | AQ15: 101.47059 | AR15: 7 | AT15: 16 | AU15: 1581 | AV15: 98.8125 | AW15: 9
C16: 10 | D16: 惡魔乳酪生義大利麵 | E16: =VLOOKUP(D16,'12產線配置圖'!$A$2:$C$25,2,0) -> #N/A | F16: =VLOOKUP(D16,'12產線配置圖'!$A$2:$C$25,3,0) -> #N/A | G16: =F16/E16 -> #N/A | I16: 14.5 | J16: 1489 | K16: 102.82619 | M16: =RANK(K16,$K$7:$K$22) -> 7 | R16: =Q16/P16 -> #DIV/0! | S16: =RANK(R16,R$7:R$22) -> #DIV/0! | W16: =V16/U16 -> #DIV/0! | X16: =RANK(W16,W$7:W$22) -> #DIV/0! | AB16: =AA16/Z16 -> #DIV/0! | AC16: =RANK(AB16,AB$7:AB$22) -> #DIV/0! | AG16: =AF16/AE16 -> #DIV/0! | AH16: =RANK(AG16,AG$7:AG$22) -> #DIV/0! | AL16: =AK16/AJ16 -> #DIV/0! | AM16: =RANK(AL16,AL$7:AL$22) -> #DIV/0! | AO16: 15 | AP16: 1483 | AQ16: 98.866667 | AR16: 8 | AT16: 14 | AU16: 1495 | AV16: 106.78571 | AW16: 7
C17: 11 | D17: 沙茶豬肉炒麵 | E17: =VLOOKUP(D17,'12產線配置圖'!$A$2:$C$25,2,0) -> 17 | F17: =VLOOKUP(D17,'12產線配置圖'!$A$2:$C$25,3,0) -> 1440 | G17: =F17/E17 -> 84.705882 | I17: 15.5 | J17: 1301 | K17: 83.908333 | M17: =RANK(K17,$K$7:$K$22) -> 11 | R17: =Q17/P17 -> #DIV/0! | S17: =RANK(R17,R$7:R$22) -> #DIV/0! | W17: =V17/U17 -> #DIV/0! | X17: =RANK(W17,W$7:W$22) -> #DIV/0! | AB17: =AA17/Z17 -> #DIV/0! | AC17: =RANK(AB17,AB$7:AB$22) -> #DIV/0! | AG17: =AF17/AE17 -> #DIV/0! | AH17: =RANK(AG17,AG$7:AG$22) -> #DIV/0! | AL17: =AK17/AJ17 -> #DIV/0! | AM17: =RANK(AL17,AL$7:AL$22) -> #DIV/0! | AO17: 16 | AP17: 1356 | AQ17: 84.75 | AR17: 11 | AT17: 15 | AU17: 1246 | AV17: 83.066667 | AW17: 12
C18: 12 | D18: 府城鹽水意麵 | E18: =VLOOKUP(D18,'12產線配置圖'!$A$2:$C$25,2,0) -> 17 | F18: =VLOOKUP(D18,'12產線配置圖'!$A$2:$C$25,3,0) -> 1565 | G18: =F18/E18 -> 92.058824 | I18: 17 | J18: 1422.5 | K18: 83.676471 | M18: =RANK(K18,$K$7:$K$22) -> 12 | R18: =Q18/P18 -> #DIV/0! | S18: =RANK(R18,R$7:R$22) -> #DIV/0! | W18: =V18/U18 -> #DIV/0! | X18: =RANK(W18,W$7:W$22) -> #DIV/0! | AB18: =AA18/Z18 -> #DIV/0! | AC18: =RANK(AB18,AB$7:AB$22) -> #DIV/0! | AG18: =AF18/AE18 -> #DIV/0! | AH18: =RANK(AG18,AG$7:AG$22) -> #DIV/0! | AL18: =AK18/AJ18 -> #DIV/0! | AM18: =RANK(AL18,AL$7:AL$22) -> #DIV/0! | AO18: 17 | AP18: 1409 | AQ18: 82.882353 | AR18: 12 | AT18: 17 | AU18: 1436 | AV18: 84.470588 | AW18: 11
C19: 13 | D19: 焗烤起司肉醬筆尖麵 | E19: =VLOOKUP(D19,'12產線配置圖'!$A$2:$C$25,2,0) -> 13 | F19: =VLOOKUP(D19,'12產線配置圖'!$A$2:$C$25,3,0) -> 1440 | G19: =F19/E19 -> 110.76923 | I19: 11 | J19: 1118.5 | K19: 101.68182 | M19: =RANK(K19,$K$7:$K$22) -> 8 | R19: =Q19/P19 -> #DIV/0! | S19: =RANK(R19,R$7:R$22) -> #DIV/0! | W19: =V19/U19 -> #DIV/0! | X19: =RANK(W19,W$7:W$22) -> #DIV/0! | AB19: =AA19/Z19 -> #DIV/0! | AC19: =RANK(AB19,AB$7:AB$22) -> #DIV/0! | AG19: =AF19/AE19 -> #DIV/0! | AH19: =RANK(AG19,AG$7:AG$22) -> #DIV/0! | AL19: =AK19/AJ19 -> #DIV/0! | AM19: =RANK(AL19,AL$7:AL$22) -> #DIV/0! | AO19: 11 | AP19: 1044 | AQ19: 94.909091 | AR19: 10 | AT19: 11 | AU19: 1193 | AV19: 108.45455 | AW19: 6
C20: 14 | D20: 辣味香菜雞肉義大利麵 | E20: =VLOOKUP(D20,'12產線配置圖'!$A$2:$C$25,2,0) -> 15 | F20: =VLOOKUP(D20,'12產線配置圖'!$A$2:$C$25,3,0) -> 1800 | G20: =F20/E20 -> 120 | I20: 16 | J20: 1799.5 | K20: 112.80196 | M20: =RANK(K20,$K$7:$K$22) -> 5 | R20: =Q20/P20 -> #DIV/0! | S20: =RANK(R20,R$7:R$22) -> #DIV/0! | W20: =V20/U20 -> #DIV/0! | X20: =RANK(W20,W$7:W$22) -> #DIV/0! | AB20: =AA20/Z20 -> #DIV/0! | AC20: =RANK(AB20,AB$7:AB$22) -> #DIV/0! | AG20: =AF20/AE20 -> #DIV/0! | AH20: =RANK(AG20,AG$7:AG$22) -> #DIV/0! | AL20: =AK20/AJ20 -> #DIV/0! | AM20: =RANK(AL20,AL$7:AL$22) -> #DIV/0! | AO20: 17 | AP20: 1827 | AQ20: 107.47059 | AR20: 5 | AT20: 15 | AU20: 1772 | AV20: 118.13333 | AW20: 5
C21: 15 | R21: =Q21/P21 -> #DIV/0! | S21: =RANK(R21,R$7:R$22) -> #DIV/0! | W21: =V21/U21 -> #DIV/0! | X21: =RANK(W21,W$7:W$22) -> #DIV/0! | AB21: =AA21/Z21 -> #DIV/0! | AC21: =RANK(AB21,AB$7:AB$22) -> #DIV/0! | AG21: =AF21/AE21 -> #DIV/0! | AH21: =RANK(AG21,AG$7:AG$22) -> #DIV/0! | AL21: =AK21/AJ21 -> #DIV/0! | AM21: =RANK(AL21,AL$7:AL$22) -> #DIV/0!
C22: 16 | R22: =Q22/P22 -> #DIV/0! | S22: =RANK(R22,R$7:R$22) -> #DIV/0! | W22: =V22/U22 -> #DIV/0! | X22: =RANK(W22,W$7:W$22) -> #DIV/0! | AB22: =AA22/Z22 -> #DIV/0! | AC22: =RANK(AB22,AB$7:AB$22) -> #DIV/0! | AG22: =AF22/AE22 -> #DIV/0! | AH22: =RANK(AG22,AG$7:AG$22) -> #DIV/0! | AL22: =AK22/AJ22 -> #DIV/0! | AM22: =RANK(AL22,AL$7:AL$22) -> #DIV/0!
C23: 17
C24: 18
B25: 產線配置圖－每週更新 | N25: 資料繳交 | O25: 日期 | P25: 46084 | U25: 46085 | Z25: 46086 | AE25: 46087 | AJ25: 46088 | AO25: 46089 | AT25: 46090
P26: 二 | U26: 三 | Z26: 四 | AE26: 五 | AJ26: 六 | AO26: 日 | AT26: 一
B27: 品群 | C27: 商品名稱 | E27: 計畫 | H27: 平均人時性 | I27: 實績 | L27: 平均人時性 | M27: 排名 | O27: 日報 | P27: 實際 | T27: 平均人時性 | U27: 實際 | Y27: 平均人時性 | Z27: 實際 | AD27: 平均人時性 | AE27: 實際 | AI27: 平均人時性 | AJ27: 實際 | AN27: 平均人時性 | AO27: 實際 | AS27: 平均人時性 | AT27: 實際 | AX27: 平均人時性
E28: 產線配置圖 | I28: 產線配置圖 | P28: 生產實績 | U28: 生產實績 | Z28: 生產實績 | AE28: 生產實績 | AJ28: 生產實績 | AO28: 生產實績 | AT28: 生產實績
E29: 人數 | F29: 產能／時 | G29: 人時性 | I29: 人數 | J29: 產能／時 | K29: 人時性 | P29: 人數 | Q29: 產能／時 | R29: 人時性 | S29: 排名 | U29: 人數 | V29: 產能／時 | W29: 人時性 | X29: 排名 | Z29: 人數 | AA29: 產能／時 | AB29: 人時性 | AC29: 排名 | AE29: 人數 | AF29: 產能／時 | AG29: 人時性 | AH29: 排名 | AJ29: 人數 | AK29: 產能／時 | AL29: 人時性 | AM29: 排名 | AO29: 人數 | AP29: 產能／時 | AQ29: 人時性 | AR29: 排名 | AT29: 人數 | AU29: 產能／時 | AV29: 人時性 | AW29: 排名
B30: 熱食義麵 | C30: 1 | D30: 義式蕃茄起司義大利麵 | E30: =VLOOKUP(D30,'12產線配置圖'!$A$2:$C$25,2,0) -> 11 | F30: =VLOOKUP(D30,'12產線配置圖'!$A$2:$C$25,3,0) -> 2118 | G30: =F30/E30 -> 192.54545 | H30: =AVERAGE(G30:G47) -> #N/A | I30: =AVERAGE(P30,U30,Z30,AE30,AJ30,AO30,AT30) -> 11.428571 | J30: =AVERAGE(Q30,V30,AA30,AF30,AK30,AP30,AU30) -> 1840 | K30: =AVERAGE(R30,W30,AB30,AG30,AL30,AQ30,AV30) -> 161.13395 | L30: =IFERROR(AVERAGE(K30:K47),"-") -> 107.18173 | M30: =RANK(K30, K$30:$K$47) -> 1 | P30: 12 | Q30: 1871 | R30: =Q30/P30 -> 155.91667 | S30: =RANK(R30,$R$30:$R$47) -> 1 | T30: =AVERAGE(R30:R47) -> 107.0214 | U30: 11 | V30: 1667 | W30: =V30/U30 -> 151.54545 | X30: =RANK(W30, $W$30:$W$47) -> 2 | Y30: =AVERAGE(W30:W47) -> 103.58431 | Z30: 11 | AA30: 1679 | AB30: =AA30/Z30 -> 152.63636 | AC30: =RANK(AB30, $AB$30:$AB$47) -> 2 | AD30: =AVERAGE(AB30:AB47) -> 104.38408 | AE30: 13 | AF30: 2059 | AG30: =AF30/AE30 -> 158.38462 | AH30: =RANK(AG30, $AG$30:$AG$47) -> 1 | AI30: =AVERAGE(AG30:AG47) -> 105.42782 | AJ30: 11 | AK30: 1757 | AL30: =AK30/AJ30 -> 159.72727 | AM30: =RANK(AL30, $AL$30:$AL$47) -> 2 | AN30: =AVERAGE(AL30:AL47) -> 108.86491 | AO30: 11 | AP30: 1882 | AQ30: =AP30/AO30 -> 171.09091 | AR30: =RANK(AQ30,$AQ$30:$AQ$47) -> 1 | AS30: =AVERAGE(AQ30:AQ47) -> 109.90538 | AT30: 11 | AU30: 1965 | AV30: =AU30/AT30 -> 178.63636 | AW30: =RANK(AV30, $AV$30:$AV$47) -> 1 | AX30: =AVERAGE(AV30:AV47) -> 111.08418
C31: 2 | D31: 奶油培根義大利麵 | E31: =VLOOKUP(D31,'12產線配置圖'!$A$2:$C$25,2,0) -> 13 | F31: =VLOOKUP(D31,'12產線配置圖'!$A$2:$C$25,3,0) -> 2118 | G31: =F31/E31 -> 162.92308 | I31: =AVERAGE(P31,U31,Z31,AE31,AJ31,AO31,AT31) -> 13.428571 | J31: =AVERAGE(Q31,V31,AA31,AF31,AK31,AP31,AU31) -> 1853.1429 | K31: =AVERAGE(R31,W31,AB31,AG31,AL31,AQ31,AV31) -> 138.18168 | M31: =RANK(K31, K$30:$K$47) -> 4 | P31: 14 | Q31: 1848 | R31: =Q31/P31 -> 132 | S31: =RANK(R31,$R$30:$R$47) -> 4 | U31: 13 | V31: 1730 | W31: =V31/U31 -> 133.07692 | X31: =RANK(W31, $W$30:$W$47) -> 4 | Z31: 13 | AA31: 1665 | AB31: =AA31/Z31 -> 128.07692 | AC31: =RANK(AB31, $AB$30:$AB$47) -> 4 | AE31: 15 | AF31: 1991 | AG31: =AF31/AE31 -> 132.73333 | AH31: =RANK(AG31, $AG$30:$AG$47) -> 4 | AJ31: 13 | AK31: 1923 | AL31: =AK31/AJ31 -> 147.92308 | AM31: =RANK(AL31, $AL$30:$AL$47) -> 4 | AO31: 13 | AP31: 1926 | AQ31: =AP31/AO31 -> 148.15385 | AR31: =RANK(AQ31,$AQ$30:$AQ$47) -> 4 | AT31: 13 | AU31: 1889 | AV31: =AU31/AT31 -> 145.30769 | AW31: =RANK(AV31, $AV$30:$AV$47) -> 4
C32: 3 | D32: 青醬蛤蜊義大利麵 | E32: =VLOOKUP(D32,'12產線配置圖'!$A$2:$C$25,2,0) -> 12 | F32: =VLOOKUP(D32,'12產線配置圖'!$A$2:$C$25,3,0) -> 2118 | G32: =F32/E32 -> 176.5 | I32: =AVERAGE(P32,U32,Z32,AE32,AJ32,AO32,AT32) -> 12.571429 | J32: =AVERAGE(Q32,V32,AA32,AF32,AK32,AP32,AU32) -> 1947.8571 | K32: =AVERAGE(R32,W32,AB32,AG32,AL32,AQ32,AV32) -> 154.88535 | M32: =RANK(K32, K$30:$K$47) -> 2 | P32: 15 | Q32: 2327 | R32: =Q32/P32 -> 155.13333 | S32: =RANK(R32,$R$30:$R$47) -> 3 | U32: 13 | V32: 2070 | W32: =V32/U32 -> 159.23077 | X32: =RANK(W32, $W$30:$W$47) -> 1 | Z32: 12 | AA32: 1643 | AB32: =AA32/Z32 -> 136.91667 | AC32: =RANK(AB32, $AB$30:$AB$47) -> 3 | AE32: 12 | AF32: 1702 | AG32: =AF32/AE32 -> 141.83333 | AH32: =RANK(AG32, $AG$30:$AG$47) -> 3 | AJ32: 12 | AK32: 1984 | AL32: =AK32/AJ32 -> 165.33333 | AM32: =RANK(AL32, $AL$30:$AL$47) -> 1 | AO32: 12 | AP32: 1956 | AQ32: =AP32/AO32 -> 163 | AR32: =RANK(AQ32,$AQ$30:$AQ$47) -> 2 | AT32: 12 | AU32: 1953 | AV32: =AU32/AT32 -> 162.75 | AW32: =RANK(AV32, $AV$30:$AV$47) -> 3
C33: 4 | D33: 焗烤起司雙饗筆尖麵 | E33: =VLOOKUP(D33,'12產線配置圖'!$A$2:$C$25,2,0) -> 16 | F33: =VLOOKUP(D33,'12產線配置圖'!$A$2:$C$25,3,0) -> 1800 | G33: =F33/E33 -> 112.5 | I33: =AVERAGE(P33,U33,Z33,AE33,AJ33,AO33,AT33) -> 16.428571 | J33: =AVERAGE(Q33,V33,AA33,AF33,AK33,AP33,AU33) -> 1641.1429 | K33: =AVERAGE(R33,W33,AB33,AG33,AL33,AQ33,AV33) -> 99.928571 | M33: =RANK(K33, K$30:$K$47) -> 7 | P33: 16 | Q33: 1639 | R33: =Q33/P33 -> 102.4375 | S33: =RANK(R33,$R$30:$R$47) -> 7 | U33: 17 | V33: 1686 | W33: =V33/U33 -> 99.176471 | X33: =RANK(W33, $W$30:$W$47) -> 7 | Z33: 16 | AA33: 1555 | AB33: =AA33/Z33 -> 97.1875 | AC33: =RANK(AB33, $AB$30:$AB$47) -> 6 | AE33: 17 | AF33: 1687 | AG33: =AF33/AE33 -> 99.235294 | AH33: =RANK(AG33, $AG$30:$AG$47) -> 7 | AJ33: 16 | AK33: 1632 | AL33: =AK33/AJ33 -> 102 | AM33: =RANK(AL33, $AL$30:$AL$47) -> 6 | AO33: 16 | AP33: 1630 | AQ33: =AP33/AO33 -> 101.875 | AR33: =RANK(AQ33,$AQ$30:$AQ$47) -> 7 | AT33: 17 | AU33: 1659 | AV33: =AU33/AT33 -> 97.588235 | AW33: =RANK(AV33, $AV$30:$AV$47) -> 10
C34: 5 | D34: 白酒蛤蜊義大利麵 | E34: =VLOOKUP(D34,'12產線配置圖'!$A$2:$C$25,2,0) -> #N/A | F34: =VLOOKUP(D34,'12產線配置圖'!$A$2:$C$25,3,0) -> #N/A | G34: =F34/E34 -> #N/A | I34: =AVERAGE(P34,U34,Z34,AE34,AJ34,AO34,AT34) -> 12.428571 | J34: =AVERAGE(Q34,V34,AA34,AF34,AK34,AP34,AU34) -> 1922.7143 | K34: =AVERAGE(R34,W34,AB34,AG34,AL34,AQ34,AV34) -> 154.85191 | M34: =RANK(K34, K$30:$K$47) -> 3 | P34: 14 | Q34: 2179 | R34: =Q34/P34 -> 155.64286 | S34: =RANK(R34,$R$30:$R$47) -> 2 | U34: 13 | V34: 1822 | W34: =V34/U34 -> 140.15385 | X34: =RANK(W34, $W$30:$W$47) -> 3 | Z34: 12 | AA34: 1856 | AB34: =AA34/Z34 -> 154.66667 | AC34: =RANK(AB34, $AB$30:$AB$47) -> 1 | AE34: 12 | AF34: 1884 | AG34: =AF34/AE34 -> 157 | AH34: =RANK(AG34, $AG$30:$AG$47) -> 2 | AJ34: 12 | AK34: 1832 | AL34: =AK34/AJ34 -> 152.66667 | AM34: =RANK(AL34, $AL$30:$AL$47) -> 3 | AO34: 12 | AP34: 1921 | AQ34: =AP34/AO34 -> 160.08333 | AR34: =RANK(AQ34,$AQ$30:$AQ$47) -> 3 | AT34: 12 | AU34: 1965 | AV34: =AU34/AT34 -> 163.75 | AW34: =RANK(AV34, $AV$30:$AV$47) -> 2
C35: 6 | D35: 青花椒麻雞肉拌麵 | E35: =VLOOKUP(D35,'12產線配置圖'!$A$2:$C$25,2,0) -> 15 | F35: =VLOOKUP(D35,'12產線配置圖'!$A$2:$C$25,3,0) -> 1714 | G35: =F35/E35 -> 114.26667 | I35: =AVERAGE(P35,U35,Z35,AE35,AJ35,AO35,AT35) -> 16.142857 | J35: =AVERAGE(Q35,V35,AA35,AF35,AK35,AP35,AU35) -> 1508.4286 | K35: =AVERAGE(R35,W35,AB35,AG35,AL35,AQ35,AV35) -> 93.435924 | M35: =RANK(K35, K$30:$K$47) -> 10 | P35: 16 | Q35: 1620 | R35: =Q35/P35 -> 101.25 | S35: =RANK(R35,$R$30:$R$47) -> 9 | U35: 17 | V35: 1450 | W35: =V35/U35 -> 85.294118 | X35: =RANK(W35, $W$30:$W$47) -> 11 | Z35: 15 | AA35: 1350 | AB35: =AA35/Z35 -> 90 | AC35: =RANK(AB35, $AB$30:$AB$47) -> 11 | AE35: 16 | AF35: 1551 | AG35: =AF35/AE35 -> 96.9375 | AH35: =RANK(AG35, $AG$30:$AG$47) -> 9 | AJ35: 16 | AK35: 1435 | AL35: =AK35/AJ35 -> 89.6875 | AM35: =RANK(AL35, $AL$30:$AL$47) -> 11 | AO35: 16 | AP35: 1472 | AQ35: =AP35/AO35 -> 92 | AR35: =RANK(AQ35,$AQ$30:$AQ$47) -> 10 | AT35: 17 | AU35: 1681 | AV35: =AU35/AT35 -> 98.882353 | AW35: =RANK(AV35, $AV$30:$AV$47) -> 7
C36: 7 | D36: 剝皮辣椒雞奶油扁麵 | E36: =VLOOKUP(D36,'12產線配置圖'!$A$2:$C$25,2,0) -> 17 | F36: =VLOOKUP(D36,'12產線配置圖'!$A$2:$C$25,3,0) -> 1714 | G36: =F36/E36 -> 100.82353 | I36: =AVERAGE(P36,U36,Z36,AE36,AJ36,AO36,AT36) -> 16.857143 | J36: =AVERAGE(Q36,V36,AA36,AF36,AK36,AP36,AU36) -> 1230.1429 | K36: =AVERAGE(R36,W36,AB36,AG36,AL36,AQ36,AV36) -> 73.226457 | M36: =RANK(K36, K$30:$K$47) -> 15 | P36: 19 | Q36: 1273 | R36: =Q36/P36 -> 67 | S36: =RANK(R36,$R$30:$R$47) -> 15 | U36: 16 | V36: 1218 | W36: =V36/U36 -> 76.125 | X36: =RANK(W36, $W$30:$W$47) -> 13 | Z36: 17 | AA36: 1142 | AB36: =AA36/Z36 -> 67.176471 | AC36: =RANK(AB36, $AB$30:$AB$47) -> 15 | AE36: 18 | AF36: 1309 | AG36: =AF36/AE36 -> 72.722222 | AH36: =RANK(AG36, $AG$30:$AG$47) -> 14 | AJ36: 14 | AK36: 1067 | AL36: =AK36/AJ36 -> 76.214286 | AM36: =RANK(AL36, $AL$30:$AL$47) -> 15 | AO36: 18 | AP36: 1336 | AQ36: =AP36/AO36 -> 74.222222 | AR36: =RANK(AQ36,$AQ$30:$AQ$47) -> 15 | AT36: 16 | AU36: 1266 | AV36: =AU36/AT36 -> 79.125 | AW36: =RANK(AV36, $AV$30:$AV$47) -> 14
C37: 8 | D37: 濃拿坡里義大利麵 | E37: =VLOOKUP(D37,'12產線配置圖'!$A$2:$C$25,2,0) -> 16 | F37: =VLOOKUP(D37,'12產線配置圖'!$A$2:$C$25,3,0) -> 1406 | G37: =F37/E37 -> 87.875 | I37: =AVERAGE(P37,U37,Z37,AE37,AJ37,AO37,AT37) -> 13.285714 | J37: =AVERAGE(Q37,V37,AA37,AF37,AK37,AP37,AU37) -> 1046.5714 | K37: =AVERAGE(R37,W37,AB37,AG37,AL37,AQ37,AV37) -> 78.760106 | M37: =RANK(K37, K$30:$K$47) -> 13 | P37: 14 | Q37: 1021 | R37: =Q37/P37 -> 72.928571 | S37: =RANK(R37,$R$30:$R$47) -> 14 | U37: 14 | V37: 1207 | W37: =V37/U37 -> 86.214286 | X37: =RANK(W37, $W$30:$W$47) -> 10 | Z37: 12 | AA37: 997 | AB37: =AA37/Z37 -> 83.083333 | AC37: =RANK(AB37, $AB$30:$AB$47) -> 13 | AE37: 16 | AF37: 1257 | AG37: =AF37/AE37 -> 78.5625 | AH37: =RANK(AG37, $AG$30:$AG$47) -> 12 | AJ37: 12 | AK37: 974 | AL37: =AK37/AJ37 -> 81.166667 | AM37: =RANK(AL37, $AL$30:$AL$47) -> 12 | AO37: 13 | AP37: 1009 | AQ37: =AP37/AO37 -> 77.615385 | AR37: =RANK(AQ37,$AQ$30:$AQ$47) -> 14 | AT37: 12 | AU37: 861 | AV37: =AU37/AT37 -> 71.75 | AW37: =RANK(AV37, $AV$30:$AV$47) -> 15
C38: 9 | D38: 奶油起司蝦仁通心粉 | E38: =VLOOKUP(D38,'12產線配置圖'!$A$2:$C$25,2,0) -> #N/A | F38: =VLOOKUP(D38,'12產線配置圖'!$A$2:$C$25,3,0) -> #N/A | G38: =F38/E38 -> #N/A | I38: =AVERAGE(P38,U38,Z38,AE38,AJ38,AO38,AT38) -> 16.142857 | J38: =AVERAGE(Q38,V38,AA38,AF38,AK38,AP38,AU38) -> 1508.5714 | K38: =AVERAGE(R38,W38,AB38,AG38,AL38,AQ38,AV38) -> 93.413866 | M38: =RANK(K38, K$30:$K$47) -> 11 | P38: 17 | Q38: 1660 | R38: =Q38/P38 -> 97.647059 | S38: =RANK(R38,$R$30:$R$47) -> 10 | U38: 16 | V38: 1007 | W38: =V38/U38 -> 62.9375 | X38: =RANK(W38, $W$30:$W$47) -> 15 | Z38: 16 | AA38: 1555 | AB38: =AA38/Z38 -> 97.1875 | AC38: =RANK(AB38, $AB$30:$AB$47) -> 6 | AE38: 16 | AF38: 1551 | AG38: =AF38/AE38 -> 96.9375 | AH38: =RANK(AG38, $AG$30:$AG$47) -> 9 | AJ38: 16 | AK38: 1616 | AL38: =AK38/AJ38 -> 101 | AM38: =RANK(AL38, $AL$30:$AL$47) -> 8 | AO38: 16 | AP38: 1612 | AQ38: =AP38/AO38 -> 100.75 | AR38: =RANK(AQ38,$AQ$30:$AQ$47) -> 8 | AT38: 16 | AU38: 1559 | AV38: =AU38/AT38 -> 97.4375 | AW38: =RANK(AV38, $AV$30:$AV$47) -> 11
C39: 10 | D39: 惡魔乳酪生義大利麵 | E39: =VLOOKUP(D39,'12產線配置圖'!$A$2:$C$25,2,0) -> #N/A | F39: =VLOOKUP(D39,'12產線配置圖'!$A$2:$C$25,3,0) -> #N/A | G39: =F39/E39 -> #N/A | I39: =AVERAGE(P39,U39,Z39,AE39,AJ39,AO39,AT39) -> 15.857143 | J39: =AVERAGE(Q39,V39,AA39,AF39,AK39,AP39,AU39) -> 1575 | K39: =AVERAGE(R39,W39,AB39,AG39,AL39,AQ39,AV39) -> 99.128196 | M39: =RANK(K39, K$30:$K$47) -> 8 | P39: 17 | Q39: 1738 | R39: =Q39/P39 -> 102.23529 | S39: =RANK(R39,$R$30:$R$47) -> 8 | U39: 16 | V39: 1709 | W39: =V39/U39 -> 106.8125 | X39: =RANK(W39, $W$30:$W$47) -> 6 | Z39: 14 | AA39: 1277 | AB39: =AA39/Z39 -> 91.214286 | AC39: =RANK(AB39, $AB$30:$AB$47) -> 10 | AE39: 16 | AF39: 1574 | AG39: =AF39/AE39 -> 98.375 | AH39: =RANK(AG39, $AG$30:$AG$47) -> 8 | AJ39: 17 | AK39: 1721 | AL39: =AK39/AJ39 -> 101.23529 | AM39: =RANK(AL39, $AL$30:$AL$47) -> 7 | AO39: 16 | AP39: 1530 | AQ39: =AP39/AO39 -> 95.625 | AR39: =RANK(AQ39,$AQ$30:$AQ$47) -> 9 | AT39: 15 | AU39: 1476 | AV39: =AU39/AT39 -> 98.4 | AW39: =RANK(AV39, $AV$30:$AV$47) -> 8
C40: 11 | D40: 沙茶豬肉炒麵 | E40: =VLOOKUP(D40,'12產線配置圖'!$A$2:$C$25,2,0) -> 17 | F40: =VLOOKUP(D40,'12產線配置圖'!$A$2:$C$25,3,0) -> 1440 | G40: =F40/E40 -> 84.705882 | I40: =AVERAGE(P40,U40,Z40,AE40,AJ40,AO40,AT40) -> 15.857143 | J40: =AVERAGE(Q40,V40,AA40,AF40,AK40,AP40,AU40) -> 1223.1429 | K40: =AVERAGE(R40,W40,AB40,AG40,AL40,AQ40,AV40) -> 77.381874 | M40: =RANK(K40, K$30:$K$47) -> 14 | P40: 16 | Q40: 1235 | R40: =Q40/P40 -> 77.1875 | S40: =RANK(R40,$R$30:$R$47) -> 13 | U40: 17 | V40: 1200 | W40: =V40/U40 -> 70.588235 | X40: =RANK(W40, $W$30:$W$47) -> 14 | Z40: 15 | AA40: 1237 | AB40: =AA40/Z40 -> 82.466667 | AC40: =RANK(AB40, $AB$30:$AB$47) -> 14 | AE40: 17 | AF40: 1226 | AG40: =AF40/AE40 -> 72.117647 | AH40: =RANK(AG40, $AG$30:$AG$47) -> 15 | AJ40: 17 | AK40: 1318 | AL40: =AK40/AJ40 -> 77.529412 | AM40: =RANK(AL40, $AL$30:$AL$47) -> 14 | AO40: 16 | AP40: 1295 | AQ40: =AP40/AO40 -> 80.9375 | AR40: =RANK(AQ40,$AQ$30:$AQ$47) -> 12 | AT40: 13 | AU40: 1051 | AV40: =AU40/AT40 -> 80.846154 | AW40: =RANK(AV40, $AV$30:$AV$47) -> 13
...

Sheet （５-2）品群別人時生產性(季節調理麵) 
B1: 月平均人時性 | C1: =AVERAGE(L7,L27,L47,L67,L87) -> #DIV/0!
B2: 產線配置圖－每週更新 | N2: 資料繳交 | O2: 日期 | AE2: 45870 | AJ2: 45871 | AO2: 45872 | AT2: 45873
P3: 二 | U3: 三 | Z3: 四 | AE3: 五 | AJ3: 六 | AO3: 日 | AT3: 一
B4: 品群 | C4: 商品名稱 | E4: 計畫 | H4: 平均人時性 | I4: 實績 | L4: 平均人時性 | M4: 排名 | O4: 日報 | P4: 實際 | T4: 平均人時性 | U4: 實際 | Y4: 平均人時性 | Z4: 實際 | AD4: 平均人時性 | AE4: 實際 | AI4: 平均人時性 | AJ4: 實際 | AN4: 平均人時性 | AO4: 實際 | AS4: 平均人時性 | AT4: 實際 | AX4: 平均人時性
E5: 產線配置圖 | I5: 產線配置圖 | P5: 生產實績 | U5: 生產實績 | Z5: 生產實績 | AE5: 生產實績 | AJ5: 生產實績 | AO5: 生產實績 | AT5: 生產實績
E6: 人數 | F6: 產能／時 | G6: 人時性 | I6: 人數 | J6: 產能／時 | K6: 人時性 | P6: 人數 | Q6: 產能／時 | R6: 人時性 | S6: 排名 | U6: 人數 | V6: 產能／時 | W6: 人時性 | X6: 排名 | Z6: 人數 | AA6: 產能／時 | AB6: 人時性 | AC6: 排名 | AE6: 人數 | AF6: 產能／時 | AG6: 人時性 | AH6: 排名 | AJ6: 人數 | AK6: 產能／時 | AL6: 人時性 | AM6: 排名 | AO6: 人數 | AP6: 產能／時 | AQ6: 人時性 | AR6: 排名 | AT6: 人數 | AU6: 產能／時 | AV6: 人時性 | AW6: 排名
B7: 熱食調理麵 | C7: 1 | H7: =AVERAGE(G7:G21) -> #DIV/0! | I7: =AVERAGE(P7,U7,Z7,AE7,AJ7,AO7,AT7) -> #DIV/0! | J7: =AVERAGE(Q7,V7,AA7,AF7,AK7,AP7,AU7) -> #DIV/0! | K7: =AVERAGE(R7,W7,AB7,AG7,AL7,AQ7,AV7) -> #DIV/0! | L7: =AVERAGE(K7:K21) -> #DIV/0! | M7: =RANK(K7, K$7:$K$21) -> #DIV/0! | S7: =RANK(R7, R$7:R$21) -> #N/A | T7: =AVERAGE(R7:R21) -> #DIV/0! | X7: =RANK(W7, W$7:W$21) -> #N/A | Y7: =AVERAGE(W7:W21) -> #DIV/0! | AC7: =RANK(AB7, AB$7:AB$21) -> #N/A | AD7: =AVERAGE(AB7:AB21) -> #DIV/0! | AH7: =RANK(AG7, AG$7:AG$21) -> #N/A | AI7: =AVERAGE(AG7:AG21) -> #DIV/0! | AM7: =RANK(AL7, AL$7:AL$21) -> #N/A | AN7: =AVERAGE(AL7:AL21) -> #DIV/0! | AR7: =RANK(AQ7, AQ$7:AQ$21) -> #N/A | AS7: =AVERAGE(AQ7:AQ21) -> #DIV/0! | AW7: =RANK(AV7, AV$7:AV$21) -> #N/A | AX7: =AVERAGE(AV7:AV21) -> #DIV/0!
C8: 2 | I8: =AVERAGE(P8,U8,Z8,AE8,AJ8,AO8,AT8) -> #DIV/0! | J8: =AVERAGE(Q8,V8,AA8,AF8,AK8,AP8,AU8) -> #DIV/0! | K8: =AVERAGE(R8,W8,AB8,AG8,AL8,AQ8,AV8) -> #DIV/0! | M8: =RANK(K8, K$7:$K$21) -> #DIV/0! | S8: =RANK(R8, R$7:R$21) -> #N/A | X8: =RANK(W8, W$7:W$21) -> #N/A | AC8: =RANK(AB8, AB$7:AB$21) -> #N/A | AH8: =RANK(AG8, AG$7:AG$21) -> #N/A | AM8: =RANK(AL8, AL$7:AL$21) -> #N/A | AR8: =RANK(AQ8, AQ$7:AQ$21) -> #N/A | AW8: =RANK(AV8, AV$7:AV$21) -> #N/A
C9: 3 | I9: =AVERAGE(P9,U9,Z9,AE9,AJ9,AO9,AT9) -> #DIV/0! | J9: =AVERAGE(Q9,V9,AA9,AF9,AK9,AP9,AU9) -> #DIV/0! | K9: =AVERAGE(R9,W9,AB9,AG9,AL9,AQ9,AV9) -> #DIV/0! | M9: =RANK(K9, K$7:$K$21) -> #DIV/0! | S9: =RANK(R9, R$7:R$21) -> #N/A | X9: =RANK(W9, W$7:W$21) -> #N/A | AC9: =RANK(AB9, AB$7:AB$21) -> #N/A | AH9: =RANK(AG9, AG$7:AG$21) -> #N/A | AM9: =RANK(AL9, AL$7:AL$21) -> #N/A | AR9: =RANK(AQ9, AQ$7:AQ$21) -> #N/A | AW9: =RANK(AV9, AV$7:AV$21) -> #N/A
C10: 4 | I10: =AVERAGE(P10,U10,Z10,AE10,AJ10,AO10,AT10) -> #DIV/0! | J10: =AVERAGE(Q10,V10,AA10,AF10,AK10,AP10,AU10) -> #DIV/0! | K10: =AVERAGE(R10,W10,AB10,AG10,AL10,AQ10,AV10) -> #DIV/0! | M10: =RANK(K10, K$7:$K$21) -> #DIV/0! | S10: =RANK(R10, R$7:R$21) -> #N/A | X10: =RANK(W10, W$7:W$21) -> #N/A | AC10: =RANK(AB10, AB$7:AB$21) -> #N/A | AH10: =RANK(AG10, AG$7:AG$21) -> #N/A | AM10: =RANK(AL10, AL$7:AL$21) -> #N/A | AR10: =RANK(AQ10, AQ$7:AQ$21) -> #N/A | AW10: =RANK(AV10, AV$7:AV$21) -> #N/A
C11: 5 | I11: =AVERAGE(P11,U11,Z11,AE11,AJ11,AO11,AT11) -> #DIV/0! | J11: =AVERAGE(Q11,V11,AA11,AF11,AK11,AP11,AU11) -> #DIV/0! | K11: =AVERAGE(R11,W11,AB11,AG11,AL11,AQ11,AV11) -> #DIV/0! | M11: =RANK(K11, K$7:$K$21) -> #DIV/0! | S11: =RANK(R11, R$7:R$21) -> #N/A | X11: =RANK(W11, W$7:W$21) -> #N/A | AC11: =RANK(AB11, AB$7:AB$21) -> #N/A | AH11: =RANK(AG11, AG$7:AG$21) -> #N/A | AM11: =RANK(AL11, AL$7:AL$21) -> #N/A | AR11: =RANK(AQ11, AQ$7:AQ$21) -> #N/A | AW11: =RANK(AV11, AV$7:AV$21) -> #N/A
C12: 6 | I12: =AVERAGE(P12,U12,Z12,AE12,AJ12,AO12,AT12) -> #DIV/0! | J12: =AVERAGE(Q12,V12,AA12,AF12,AK12,AP12,AU12) -> #DIV/0! | K12: =AVERAGE(R12,W12,AB12,AG12,AL12,AQ12,AV12) -> #DIV/0! | M12: =RANK(K12, K$7:$K$21) -> #DIV/0! | S12: =RANK(R12, R$7:R$21) -> #N/A | X12: =RANK(W12, W$7:W$21) -> #N/A | AC12: =RANK(AB12, AB$7:AB$21) -> #N/A | AH12: =RANK(AG12, AG$7:AG$21) -> #N/A | AM12: =RANK(AL12, AL$7:AL$21) -> #N/A | AR12: =RANK(AQ12, AQ$7:AQ$21) -> #N/A | AW12: =RANK(AV12, AV$7:AV$21) -> #N/A
C13: 7 | I13: =AVERAGE(P13,U13,Z13,AE13,AJ13,AO13,AT13) -> #DIV/0! | J13: =AVERAGE(Q13,V13,AA13,AF13,AK13,AP13,AU13) -> #DIV/0! | K13: =AVERAGE(R13,W13,AB13,AG13,AL13,AQ13,AV13) -> #DIV/0! | M13: =RANK(K13, K$7:$K$21) -> #DIV/0! | S13: =RANK(R13, R$7:R$21) -> #N/A | X13: =RANK(W13, W$7:W$21) -> #N/A | AC13: =RANK(AB13, AB$7:AB$21) -> #N/A | AH13: =RANK(AG13, AG$7:AG$21) -> #N/A | AM13: =RANK(AL13, AL$7:AL$21) -> #N/A | AR13: =RANK(AQ13, AQ$7:AQ$21) -> #N/A | AW13: =RANK(AV13, AV$7:AV$21) -> #N/A
C14: 8 | I14: =AVERAGE(P14,U14,Z14,AE14,AJ14,AO14,AT14) -> #DIV/0! | J14: =AVERAGE(Q14,V14,AA14,AF14,AK14,AP14,AU14) -> #DIV/0! | K14: =AVERAGE(R14,W14,AB14,AG14,AL14,AQ14,AV14) -> #DIV/0! | M14: =RANK(K14, K$7:$K$21) -> #DIV/0! | S14: =RANK(R14, R$7:R$21) -> #N/A | X14: =RANK(W14, W$7:W$21) -> #N/A | AC14: =RANK(AB14, AB$7:AB$21) -> #N/A | AH14: =RANK(AG14, AG$7:AG$21) -> #N/A | AM14: =RANK(AL14, AL$7:AL$21) -> #N/A | AR14: =RANK(AQ14, AQ$7:AQ$21) -> #N/A | AW14: =RANK(AV14, AV$7:AV$21) -> #N/A
C15: 9 | I15: =AVERAGE(P15,U15,Z15,AE15,AJ15,AO15,AT15) -> #DIV/0! | J15: =AVERAGE(Q15,V15,AA15,AF15,AK15,AP15,AU15) -> #DIV/0! | K15: =AVERAGE(R15,W15,AB15,AG15,AL15,AQ15,AV15) -> #DIV/0! | M15: =RANK(K15, K$7:$K$21) -> #DIV/0! | S15: =RANK(R15, R$7:R$21) -> #N/A | X15: =RANK(W15, W$7:W$21) -> #N/A | AC15: =RANK(AB15, AB$7:AB$21) -> #N/A | AH15: =RANK(AG15, AG$7:AG$21) -> #N/A | AM15: =RANK(AL15, AL$7:AL$21) -> #N/A | AR15: =RANK(AQ15, AQ$7:AQ$21) -> #N/A | AW15: =RANK(AV15, AV$7:AV$21) -> #N/A
C16: 10 | I16: =AVERAGE(P16,U16,Z16,AE16,AJ16,AO16,AT16) -> #DIV/0! | J16: =AVERAGE(Q16,V16,AA16,AF16,AK16,AP16,AU16) -> #DIV/0! | K16: =AVERAGE(R16,W16,AB16,AG16,AL16,AQ16,AV16) -> #DIV/0! | M16: =RANK(K16, K$7:$K$21) -> #DIV/0! | S16: =RANK(R16, R$7:R$21) -> #N/A | X16: =RANK(W16, W$7:W$21) -> #N/A | AC16: =RANK(AB16, AB$7:AB$21) -> #N/A | AH16: =RANK(AG16, AG$7:AG$21) -> #N/A | AM16: =RANK(AL16, AL$7:AL$21) -> #N/A | AR16: =RANK(AQ16, AQ$7:AQ$21) -> #N/A | AW16: =RANK(AV16, AV$7:AV$21) -> #N/A
C17: 11 | M17: =RANK(K17, K$7:$K$21) -> #DIV/0! | S17: =RANK(R17, R$7:R$21) -> #N/A | X17: =RANK(W17, W$7:W$21) -> #N/A | AC17: =RANK(AB17, AB$7:AB$21) -> #N/A | AH17: =RANK(AG17, AG$7:AG$21) -> #N/A | AM17: =RANK(AL17, AL$7:AL$21) -> #N/A | AR17: =RANK(AQ17, AQ$7:AQ$21) -> #N/A | AW17: =RANK(AV17, AV$7:AV$21) -> #N/A
C18: 12 | M18: =RANK(K18, K$7:$K$21) -> #DIV/0! | S18: =RANK(R18, R$7:R$21) -> #N/A | X18: =RANK(W18, W$7:W$21) -> #N/A | AC18: =RANK(AB18, AB$7:AB$21) -> #N/A | AH18: =RANK(AG18, AG$7:AG$21) -> #N/A | AM18: =RANK(AL18, AL$7:AL$21) -> #N/A | AR18: =RANK(AQ18, AQ$7:AQ$21) -> #N/A | AW18: =RANK(AV18, AV$7:AV$21) -> #N/A
C19: 13 | M19: =RANK(K19, K$7:$K$21) -> #DIV/0! | S19: =RANK(R19, R$7:R$21) -> #N/A | X19: =RANK(W19, W$7:W$21) -> #N/A | AC19: =RANK(AB19, AB$7:AB$21) -> #N/A | AH19: =RANK(AG19, AG$7:AG$21) -> #N/A | AM19: =RANK(AL19, AL$7:AL$21) -> #N/A | AR19: =RANK(AQ19, AQ$7:AQ$21) -> #N/A | AW19: =RANK(AV19, AV$7:AV$21) -> #N/A
C20: 14 | M20: =RANK(K20, K$7:$K$21) -> #DIV/0! | S20: =RANK(R20, R$7:R$21) -> #N/A | X20: =RANK(W20, W$7:W$21) -> #N/A | AC20: =RANK(AB20, AB$7:AB$21) -> #N/A | AH20: =RANK(AG20, AG$7:AG$21) -> #N/A | AM20: =RANK(AL20, AL$7:AL$21) -> #N/A | AR20: =RANK(AQ20, AQ$7:AQ$21) -> #N/A | AW20: =RANK(AV20, AV$7:AV$21) -> #N/A
C21: 15 | M21: =RANK(K21, K$7:$K$21) -> #DIV/0! | S21: =RANK(R21, R$7:R$21) -> #N/A | X21: =RANK(W21, W$7:W$21) -> #N/A | AC21: =RANK(AB21, AB$7:AB$21) -> #N/A | AH21: =RANK(AG21, AG$7:AG$21) -> #N/A | AM21: =RANK(AL21, AL$7:AL$21) -> #N/A | AR21: =RANK(AQ21, AQ$7:AQ$21) -> #N/A | AW21: =RANK(AV21, AV$7:AV$21) -> #N/A
B22: 產線配置圖－每週更新 | N22: 資料繳交 | O22: 日期 | P22: 45874 | U22: 45875 | Z22: 45876 | AE22: 45877 | AJ22: 45878 | AO22: 45879 | AT22: 45880
P23: 二 | U23: 三 | Z23: 四 | AE23: 五 | AJ23: 六 | AO23: 日 | AT23: 一
B24: 品群 | C24: 商品名稱 | E24: 計畫 | H24: 平均人時性 | I24: 實績 | L24: 平均人時性 | M24: 排名 | O24: 日報 | P24: 實際 | T24: 平均人時性 | U24: 實際 | Y24: 平均人時性 | Z24: 實際 | AD24: 平均人時性 | AE24: 實際 | AI24: 平均人時性 | AJ24: 實際 | AN24: 平均人時性 | AO24: 實際 | AS24: 平均人時性 | AT24: 實際 | AX24: 平均人時性
E25: 產線配置圖 | I25: 產線配置圖 | P25: 生產實績 | U25: 生產實績 | Z25: 生產實績 | AE25: 生產實績 | AJ25: 生產實績 | AO25: 生產實績 | AT25: 生產實績
E26: 人數 | F26: 產能／時 | G26: 人時性 | I26: 人數 | J26: 產能／時 | K26: 人時性 | P26: 人數 | Q26: 產能／時 | R26: 人時性 | S26: 排名 | U26: 人數 | V26: 產能／時 | W26: 人時性 | X26: 排名 | Z26: 人數 | AA26: 產能／時 | AB26: 人時性 | AC26: 排名 | AE26: 人數 | AF26: 產能／時 | AG26: 人時性 | AH26: 排名 | AJ26: 人數 | AK26: 產能／時 | AL26: 人時性 | AM26: 排名 | AO26: 人數 | AP26: 產能／時 | AQ26: 人時性 | AR26: 排名 | AT26: 人數 | AU26: 產能／時 | AV26: 人時性 | AW26: 排名
B27: 季節調理麵 | C27: 1 | H27: =AVERAGE(G27:G41) -> #DIV/0! | I27: =AVERAGE(P27,U27,Z27,AE27,AJ27,AO27,AT27) -> #DIV/0! | J27: =AVERAGE(Q27,V27,AA27,AF27,AK27,AP27,AU27) -> #DIV/0! | K27: =AVERAGE(R27,W27,AB27,AG27,AL27,AQ27,AV27) -> #DIV/0! | L27: =AVERAGE(K27:K41) -> #DIV/0! | M27: =RANK(K27, K$27:$K$41) -> #DIV/0! | T27: =AVERAGE(R27:R41) -> #DIV/0! | Y27: =AVERAGE(W27:W41) -> #DIV/0! | AD27: =AVERAGE(AB27:AB41) -> #DIV/0! | AI27: =AVERAGE(AG27:AG41) -> #DIV/0! | AN27: =AVERAGE(AL27:AL41) -> #DIV/0! | AS27: =AVERAGE(AQ27:AQ41) -> #DIV/0! | AX27: =AVERAGE(AV27:AV41) -> #DIV/0!
C28: 2 | I28: =AVERAGE(P28,U28,Z28,AE28,AJ28,AO28,AT28) -> #DIV/0! | J28: =AVERAGE(Q28,V28,AA28,AF28,AK28,AP28,AU28) -> #DIV/0! | K28: =AVERAGE(R28,W28,AB28,AG28,AL28,AQ28,AV28) -> #DIV/0! | M28: =RANK(K28, K$27:$K$41) -> #DIV/0!
C29: 3 | I29: =AVERAGE(P29,U29,Z29,AE29,AJ29,AO29,AT29) -> #DIV/0! | J29: =AVERAGE(Q29,V29,AA29,AF29,AK29,AP29,AU29) -> #DIV/0! | K29: =AVERAGE(R29,W29,AB29,AG29,AL29,AQ29,AV29) -> #DIV/0! | M29: =RANK(K29, K$27:$K$41) -> #DIV/0!
C30: 4 | I30: =AVERAGE(P30,U30,Z30,AE30,AJ30,AO30,AT30) -> #DIV/0! | J30: =AVERAGE(Q30,V30,AA30,AF30,AK30,AP30,AU30) -> #DIV/0! | K30: =AVERAGE(R30,W30,AB30,AG30,AL30,AQ30,AV30) -> #DIV/0! | M30: =RANK(K30, K$27:$K$41) -> #DIV/0!
C31: 5 | I31: =AVERAGE(P31,U31,Z31,AE31,AJ31,AO31,AT31) -> #DIV/0! | J31: =AVERAGE(Q31,V31,AA31,AF31,AK31,AP31,AU31) -> #DIV/0! | K31: =AVERAGE(R31,W31,AB31,AG31,AL31,AQ31,AV31) -> #DIV/0! | M31: =RANK(K31, K$27:$K$41) -> #DIV/0!
C32: 6 | I32: =AVERAGE(P32,U32,Z32,AE32,AJ32,AO32,AT32) -> #DIV/0! | J32: =AVERAGE(Q32,V32,AA32,AF32,AK32,AP32,AU32) -> #DIV/0! | K32: =AVERAGE(R32,W32,AB32,AG32,AL32,AQ32,AV32) -> #DIV/0! | M32: =RANK(K32, K$27:$K$41) -> #DIV/0!
C33: 7 | I33: =AVERAGE(P33,U33,Z33,AE33,AJ33,AO33,AT33) -> #DIV/0! | J33: =AVERAGE(Q33,V33,AA33,AF33,AK33,AP33,AU33) -> #DIV/0! | K33: =AVERAGE(R33,W33,AB33,AG33,AL33,AQ33,AV33) -> #DIV/0! | M33: =RANK(K33, K$27:$K$41) -> #DIV/0!
C34: 8 | I34: =AVERAGE(P34,U34,Z34,AE34,AJ34,AO34,AT34) -> #DIV/0! | J34: =AVERAGE(Q34,V34,AA34,AF34,AK34,AP34,AU34) -> #DIV/0! | K34: =AVERAGE(R34,W34,AB34,AG34,AL34,AQ34,AV34) -> #DIV/0! | M34: =RANK(K34, K$27:$K$41) -> #DIV/0!
C35: 9 | I35: =AVERAGE(P35,U35,Z35,AE35,AJ35,AO35,AT35) -> #DIV/0! | J35: =AVERAGE(Q35,V35,AA35,AF35,AK35,AP35,AU35) -> #DIV/0! | K35: =AVERAGE(R35,W35,AB35,AG35,AL35,AQ35,AV35) -> #DIV/0! | M35: =RANK(K35, K$27:$K$41) -> #DIV/0!
