Workbook

Sheet 生產管理報表(週) 
A1: 長家廠生產管理報表
A3: 月別 | B3: 12 | C3: 週別 | D3: W4 | E3: 工廠 | F3: 長家廠
A4: （１）收支狀況 | E4: ※單位：千元 | G4: （２）ＫＰＩ達成進度
A5: 項目 | B5: 當週 | C5: 前週 | D5: 差異 | E5: 累計 | G5: 項目 | H5: KPI | I5: 當週 | J5: 前週 | K5: 累計 | L5: ※補充
A6: 業績金額 | B6: 16420.35 | C6: 17357 | D6: =B6-C6 -> -936.65 | E6: 68791.95 | G6: 人時性(個/月均) | H6: 112.8 | I6: 100 | J6: 102.7 | K6: 101.2 | L6: 個／MH
A7: 訂單數量 | B7: 345306 | C7: 365761 | D7: =B7-C7 -> -20455 | E7: 1446739 | G7: 人時達成率(%/月均) | H7: 0.8 | I7: =I6/H6 -> 0.88652482 | J7: =J6/H6 -> 0.91046099 | K7: =K6/H6 -> 0.89716312 | L7: 達成率
A8: 材料費 | B8: 10366.82 | C8: 10959 | D8: =B8-C8 -> -592.18 | E8: 43425.21 | G8: 半成品-報廢(%) | H8: 0.0025 | I8: 0.0081 | J8: 0.0026 | K8: 0.0039 | L8: 報廢率
A9: 材料費率 | B9: =B8/B6 -> 0.63133977 | C9: =C8/C6 -> 0.63138791 | D9: =B9-C9 -> -4.814219e-05 | E9: =E8/E6 -> 0.63125424 | G9: 半成品-超用(%) | H9: 0.0025 | I9: 0.0028 | J9: 0.0032 | K9: 0.0026 | L9: 超用率
A10: 勞務成本 | D10: =B10-C10 -> 0 | G10: 固定產線-導入率(%) | H10: 1 | I10: 0.4 | J10: 0.4 | K10: 0.41 | L10: 導入率
A11: 勞務費率 | D11: =B11-C11 -> 0 | G11: 教育訓練-實施率(%) | H11: 1 | I11: 0.85 | J11: 0.85 | K11: 0.85 | L11: 實施率
A13: （３）業績構成比 | G13: （４）訂單數量構成比
B14: 當週 | C14: 比例 | D14: 前週 | E14: 差異 | H14: 當週 | I14: 比例 | J14: 前週 | K14: 差異
A15: 熱食義麵(122,123,124,126) | B15: 15194.21 | C15: =B15/B6 -> 0.92532802 | D15: 0.9202 | E15: =IFERROR(C15-D15,"") -> 0.0051280228 | G15: 熱食義麵(122,123,124,126) | H15: 300846 | I15: =IFERROR(H15/$B$7,"") -> 0.87124464 | J15: 0.8628 | K15: =IFERROR(I15-J15,"") -> 0.0084446352
A16: 季節調理麵(111,112) | C16: =IFERROR(B16/$B$6,"") -> 0 | D16: 0 | E16: =IFERROR(C16-D16,"") -> 0 | G16: 季節調理麵(111,112) | I16: =IFERROR(H16/$B$7,"") -> 0 | J16: 0 | K16: =IFERROR(I16-J16,"") -> 0
A17: 微波小吃(153,154,155) | B17: 1226.14 | C17: =B17/B6 -> 0.074671977 | D17: 0.0798 | E17: =IFERROR(C17-D17,"") -> -0.0051280228 | G17: 微波小吃(153,154,155) | H17: 44460 | I17: =IFERROR(H17/$B$7,"") -> 0.12875536 | J17: 0.1372 | K17: =IFERROR(I17-J17,"") -> -0.0084446352
C18: =SUM(C15:C17) -> 1 | D18: =SUM(D15:D17) -> 1 | I18: =SUM(I15:I17) -> 1 | J18: =SUM(J15:J17) -> 1
A20: （５）品群別人時生產性
A21: 品群 | B21: 當週 | C21: 前週 | D21: 差異 | E21: 累計
A22: 熱食義麵(122,123,124,126) | B22: 97.2 | C22: 96.6 | D22: =B22-C22 -> 0.6 | E22: 98.4
A23: 季節調理麵(111,112) | D23: =B23-C23 -> 0
A24: 微波小吃(153,154,155) | B24: 111.6 | C24: 112.8 | D24: =B24-C24 -> -1.2 | E24: 111.8

Sheet （１）收支狀況
B2: （１）收支狀況
B3: 資料繳交日 | C3: 月份 | D3: 日期 | F3: 營業額(元) | I3: 訂單數量(個) | L3: 材料費(元) | O3: 材料費率（材料費／營業額） | R3: 勞務成本（全廠人事成本） | U3: 勞務費率（勞務成本／營業額）
F4: 日 | G4: 週累積 | H4: 月累積 | I4: 日 | J4: 週累積 | K4: 月累積 | L4: 日 | M4: 週累積 | N4: 月累積 | O4: 日 | P4: 週累積 | Q4: 月累積 | R4: 日 | S4: 週累積 | T4: 月累積 | U4: 日 | V4: 週累積 | W4: 月累積
C5: 十二 | D5: 45992 | E5: 一 | F5: 2513777.5 | H5: =SUM(F5:F35) -> 68791952 | I5: 52776 | K5: =SUM(I5:I34) -> 1446739 | L5: 1585646 | N5: =SUM(L5:L34) -> 43425212 | O5: =L5/F5 -> 0.63078215 | Q5: =N5/H5 -> 0.63125425 | T5: =SUM(R5:R33) -> 0 | U5: =R5/F5 -> 0 | W5: =T5/H5 -> 0
B6: 46001 | D6: 45993 | E6: 二 | F6: 2335255 | G6: =SUM(F6:F12) -> 15371291 | I6: 49145 | J6: =SUM(I6:I12) -> 323563 | L6: 1471646 | M6: =SUM(L6:L12) -> 9688571 | O6: =L6/F6 -> 0.63018644 | P6: =M6/G6 -> 0.63030302 | S6: =SUM(R6:R12) -> 0 | U6: =R6/F6 -> 0 | V6: =S6/M6 -> 0
D7: 45994 | E7: 三 | F7: 2176837.3 | I7: 45862 | L7: 1371646 | O7: =L7/F7 -> 0.63010957 | U7: =R7/F7 -> 0
D8: 45995 | E8: 四 | F8: 2121444.9 | I8: 44569 | L8: 1335646 | O8: =L8/F8 -> 0.6295926 | U8: =R8/F8 -> 0
D9: 45996 | E9: 五 | F9: 1832380.4 | I9: 38620 | L9: 1156695 | O9: =L9/F9 -> 0.63125267 | U9: =R9/F9 -> 0
D10: 45997 | E10: 六 | F10: 1995581.1 | I10: 42013 | L10: 1257646 | O10: =L10/F10 -> 0.63021545 | U10: =R10/F10 -> 0
D11: 45998 | E11: 日 | F11: 2513995.6 | I11: 52933 | L11: 1583646 | O11: =L11/F11 -> 0.62993189 | U11: =R11/F11 -> 0
D12: 45999 | E12: 一 | F12: 2395796.6 | I12: 50421 | L12: 1511646 | O12: =L12/F12 -> 0.63095757 | U12: =R12/F12 -> 0
B13: 46008 | D13: 46000 | E13: 二 | F13: 3129368 | G13: =SUM(F13:F19) -> 17129534 | I13: 66936 | J13: =SUM(I13:I19) -> 359333 | L13: 1980646 | M13: =SUM(L13:L19) -> 10825571 | O13: =L13/F13 -> 0.63292204 | P13: =M13/G13 -> 0.6319828 | S13: =SUM(R13:R19) -> 0 | U13: =R13/F13 -> 0 | V13: =S13/M13 -> 0
D14: 46001 | E14: 三 | F14: 2596020.5 | I14: 53635 | L14: 1640646 | O14: =L14/F14 -> 0.63198499 | U14: =R14/F14 -> 0
D15: 46002 | E15: 四 | F15: 2249510.9 | I15: 46504 | L15: 1421646 | O15: =L15/F15 -> 0.63198005 | U15: =R15/F15 -> 0
D16: 46003 | E16: 五 | F16: 1793030.3 | I16: 37707 | L16: 1133695 | O16: =L16/F16 -> 0.63227878 | U16: =R16/F16 -> 0
D17: 46004 | E17: 六 | F17: 2044428.8 | I17: 43137 | L17: 1290646 | O17: =L17/F17 -> 0.63129907 | U17: =R17/F17 -> 0
D18: 46005 | E18: 日 | F18: 2720484 | I18: 56760 | L18: 1719646 | O18: =L18/F18 -> 0.63211031 | U18: =R18/F18 -> 0
D19: 46006 | E19: 一 | F19: 2596691.6 | I19: 54654 | L19: 1638646 | O19: =L19/F19 -> 0.63105145 | U19: =R19/F19 -> 0
B20: 46015 | D20: 46007 | E20: 二 | F20: 2614596.3 | G20: =SUM(F20:F26) -> 17356992 | I20: 54968 | J20: =SUM(I20:I26) -> 365761 | L20: 1650646 | M20: =SUM(L20:L26) -> 10958602 | O20: =L20/F20 -> 0.63131965 | P20: =M20/G20 -> 0.63136527 | S20: =SUM(R20:R26) -> 0 | U20: =R20/F20 -> 0 | V20: =S20/M20 -> 0
D21: 46008 | E21: 三 | F21: 2455966 | I21: 51643 | L21: 1550646 | O21: =L21/F21 -> 0.63137925 | U21: =R21/F21 -> 0
D22: 46009 | E22: 四 | F22: 2339510.5 | I22: 49206 | L22: 1477026 | O22: =L22/F22 -> 0.63133976 | U22: =R22/F22 -> 0
D23: 46010 | E23: 五 | F23: 2112449.6 | I23: 45379 | L23: 1333346 | O23: =L23/F23 -> 0.63118478 | U23: =R23/F23 -> 0
D24: 46011 | E24: 六 | F24: 2376517 | I24: 49960 | L24: 1500646 | O24: =L24/F24 -> 0.63144761 | U24: =R24/F24 -> 0
D25: 46012 | E25: 日 | F25: 2783602.7 | I25: 58406 | L25: 1757646 | O25: =L25/F25 -> 0.63142846 | U25: =R25/F25 -> 0
D26: 46013 | E26: 一 | F26: 2674350 | I26: 56199 | L26: 1688646 | O26: =L26/F26 -> 0.63142296 | U26: =R26/F26 -> 0
B27: 46022 | D27: 46014 | E27: 二 | F27: 2842340.9 | G27: =SUM(F27:F33) -> 16420357 | I27: 59311 | J27: =SUM(I27:I33) -> 345306 | L27: 1793646 | M27: =SUM(L27:L33) -> 10366822 | O27: =L27/F27 -> 0.63104534 | P27: =M27/G27 -> 0.63133962 | S27: =SUM(R27:R33) -> 0 | U27: =R27/F27 -> 0 | V27: =S27/M27 -> 0
D28: 46015 | E28: 三 | F28: 1906561 | I28: 40396 | L28: 1203646 | O28: =L28/F28 -> 0.63131785 | U28: =R28/F28 -> 0
D29: 46016 | E29: 四 | F29: 2152805.8 | I29: 45518 | L29: 1360046 | O29: =L29/F29 -> 0.63175507 | U29: =R29/F29 -> 0
D30: 46017 | E30: 五 | F30: 2059678.9 | I30: 43115 | L30: 1299346 | O30: =L30/F30 -> 0.63084882 | U30: =R30/F30 -> 0
D31: 46018 | E31: 六 | F31: 2208752.2 | I31: 46400 | L31: 1392846 | O31: =L31/F31 -> 0.63060309 | U31: =R31/F31 -> 0
D32: 46019 | E32: 日 | F32: 2697831 | I32: 56766 | L32: 1707646 | O32: =L32/F32 -> 0.63296998 | U32: =R32/F32 -> 0
D33: 46020 | E33: 一 | F33: 2552387.2 | I33: 53800 | L33: 1609646 | O33: =L33/F33 -> 0.63064335 | U33: =R33/F33 -> 0
D34: 46021 | E34: 二 | O34: =L34/F34 -> #DIV/0! | U34: =R34/F34 -> #DIV/0!
D35: 46022 | E35: 三 | O35: =L35/F35 -> #DIV/0! | U35: =R35/F35 -> #DIV/0!
S37: =SUM(R37:R43) -> 0 | V37: =SUM(U37:U43) -> 0

Sheet （２）ＫＰＩ達成進度
C1: 112.8
B2: （２）ＫＰＩ達成進度
B3: 資料繳交日 | C3: 月份 | D3: 日期 | F3: 人時生產性(個/人) | I3: 人時生產性達成率(%) | L3: 半成品報廢(%) | O3: 半成品超用(%) | R3: 固定產線-導入率(固定產線數/總產線數) | U3: 教育訓練-實施率(進度/計畫)
F4: 日 | G4: 週平均 | H4: 月平均 | I4: 日 | J4: 週平均 | K4: 月平均 | L4: 日 | M4: 週平均 | N4: 月平均 | O4: 日 | P4: 週平均 | Q4: 月平均 | R4: 日 | S4: 週平均 | T4: 月平均 | U4: 日 | V4: 週平均 | W4: 月平均
C5: 十二 | D5: 45992 | E5: 一 | F5: 104.7 | H5: =AVERAGE(F5:F34) -> 101.2 | I5: =F5/$C$1 -> 0.92819149 | K5: =AVERAGE(I5:I35) -> 0.89716312 | L5: 0.00092768751 | N5: =AVERAGE(L5:L35) -> 0.0039194092 | O5: 0.0013358382 | Q5: =AVERAGE(O5:O35) -> 0.0025757191 | R5: 0.429 | T5: =AVERAGE(R5:R35) -> 0.41054545 | U5: 0.85 | W5: =AVERAGE(U5:U35) -> 0.85
B6: 46001 | D6: 45993 | E6: 二 | F6: 99.6 | G6: =AVERAGE(F6:F12) -> 98.771429 | I6: =F6/$C$1 -> 0.88297872 | J6: =AVERAGE(I6:I12) -> 0.87563323 | L6: 9.8490316e-05 | M6: =AVERAGE(L6:L12) -> 0.0014870322 | O6: 0.00031731011 | P6: =AVERAGE(O6:O12) -> 0.0011520047 | R6: 0.429 | S6: =AVERAGE(R6:R12) -> 0.429 | U6: 0.85 | V6: =AVERAGE(U6:U12) -> 0.85
D7: 45994 | E7: 三 | F7: 90.9 | I7: =F7/$C$1 -> 0.80585106 | L7: 7.579804e-05 | O7: 0.00014240844 | R7: 0.429 | U7: 0.85
D8: 45995 | E8: 四 | F8: 100.2 | I8: =F8/$C$1 -> 0.88829787 | L8: 0.00045723554 | O8: 0.00049824532 | R8: 0.429 | U8: 0.85
D9: 45996 | E9: 五 | F9: 98.3 | I9: =F9/$C$1 -> 0.8714539 | L9: 0.0034725323 | O9: 0.0035936862 | R9: 0.429 | U9: 0.85
D10: 45997 | E10: 六 | F10: 97.4 | I10: =F10/$C$1 -> 0.86347518 | L10: 0.0031108734 | O10: 0.0015804921 | R10: 0.429 | U10: 0.85
D11: 45998 | E11: 日 | F11: 101.9 | I11: =F11/$C$1 -> 0.90336879 | L11: 0.0015576797 | O11: 0.00071559393 | R11: 0.429 | U11: 0.85
D12: 45999 | E12: 一 | F12: 103.1 | I12: =F12/$C$1 -> 0.91400709 | L12: 0.0016366164 | O12: 0.0012162969 | R12: 0.429 | U12: 0.85
B13: 46008 | D13: 46000 | E13: 二 | F13: 105.2 | G13: =AVERAGE(F13:F19) -> 102.8 | I13: =F13/$C$1 -> 0.93262411 | J13: =AVERAGE(I13:I19) -> 0.91134752 | L13: 0.0055276336 | M13: =AVERAGE(L13:L19) -> 0.0039033066 | O13: 0.0093881575 | P13: =AVERAGE(O13:O19) -> 0.0033454641 | R13: 0.4 | S13: =AVERAGE(R13:R19) -> 0.4 | U13: 0.85 | V13: =AVERAGE(U13:U19) -> 0.85
D14: 46001 | E14: 三 | F14: 107.7 | I14: =F14/$C$1 -> 0.95478723 | L14: 0.0056390156 | O14: 0.0016113124 | R14: 0.4 | U14: 0.85
D15: 46002 | E15: 四 | F15: 98.2 | I15: =F15/$C$1 -> 0.87056738 | L15: 0.0031998067 | O15: 0.00085840883 | R15: 0.4 | U15: 0.85
D16: 46003 | E16: 五 | F16: 98.6 | I16: =F16/$C$1 -> 0.87411348 | L16: 0.0047863107 | O16: 0.0035755113 | R16: 0.4 | U16: 0.85
D17: 46004 | E17: 六 | F17: 99.7 | I17: =F17/$C$1 -> 0.88386525 | L17: 0.0018327858 | O17: 0.0018063725 | R17: 0.4 | U17: 0.85
D18: 46005 | E18: 日 | F18: 104.1 | I18: =F18/$C$1 -> 0.92287234 | L18: 0.00064804645 | O18: 0.003484674 | R18: 0.4 | U18: 0.85
D19: 46006 | E19: 一 | F19: 106.1 | I19: =F19/$C$1 -> 0.94060284 | L19: 0.0056895474 | O19: 0.0026938124 | R19: 0.4 | U19: 0.85
B20: 46015 | D20: 46007 | E20: 二 | F20: 102.7 | G20: =AVERAGE(F20:F26) -> 102.71429 | I20: =F20/$C$1 -> 0.91046099 | J20: =AVERAGE(I20:I26) -> 0.91058764 | L20: 0.0021915429 | M20: =AVERAGE(L20:L26) -> 0.0026121384 | O20: 0.0031289726 | P20: =AVERAGE(O20:O26) -> 0.0031533166 | R20: 0.4 | S20: =AVERAGE(R20:R26) -> 0.4 | U20: 0.85 | V20: =AVERAGE(U20:U26) -> 0.85
D21: 46008 | E21: 三 | F21: 102.8 | I21: =F21/$C$1 -> 0.91134752 | L21: 0.0023909125 | O21: 0.004776939 | R21: 0.4 | U21: 0.85
D22: 46009 | E22: 四 | F22: 102.2 | I22: =F22/$C$1 -> 0.90602837 | L22: 0.0010891167 | O22: 0.0033190703 | R22: 0.4 | U22: 0.85
D23: 46010 | E23: 五 | F23: 101.9 | I23: =F23/$C$1 -> 0.90336879 | L23: 0.0023063273 | O23: 0.0015058348 | R23: 0.4 | U23: 0.85
D24: 46011 | E24: 六 | F24: 99 | I24: =F24/$C$1 -> 0.87765957 | L24: 0.0017319464 | O24: 0.0041581861 | R24: 0.4 | U24: 0.85
D25: 46012 | E25: 日 | F25: 106.5 | I25: =F25/$C$1 -> 0.94414894 | L25: 0.0047240936 | O25: 0.0026781839 | R25: 0.4 | U25: 0.85
D26: 46013 | E26: 一 | F26: 103.9 | I26: =F26/$C$1 -> 0.92109929 | L26: 0.0038510292 | O26: 0.0025060295 | R26: 0.4 | U26: 0.85
B27: 46022 | D27: 46014 | E27: 二 | F27: 100.3 | G27: =AVERAGE(F27:F33) -> 100.01429 | I27: =F27/$C$1 -> 0.8891844 | J27: =AVERAGE(I27:I33) -> 0.88665147 | L27: 0.0068971318 | M27: =AVERAGE(L27:L33) -> 0.0081025485 | O27: 0.0036582522 | P27: =AVERAGE(O27:O33) -> 0.0028292167 | S27: =AVERAGE(R27:R33) -> #DIV/0! | V27: =AVERAGE(U27:U33) -> #DIV/0!
D28: 46015 | E28: 三 | F28: 99.7 | I28: =F28/$C$1 -> 0.88386525 | L28: 0.03053351 | O28: 0.0047289334
D29: 46016 | E29: 四 | F29: 95.1 | I29: =F29/$C$1 -> 0.84308511 | L29: 0.0011942554 | O29: 0.00076597712
D30: 46017 | E30: 五 | F30: 99.8 | I30: =F30/$C$1 -> 0.88475177 | L30: 0.0063553596 | O30: 0.0017857152
D31: 46018 | E31: 六 | F31: 106.2 | I31: =F31/$C$1 -> 0.94148936 | L31: 0.0035083156 | O31: 0.0033009587
D32: 46019 | E32: 日 | F32: 100.6 | I32: =F32/$C$1 -> 0.89184397 | L32: 0.006261697 | O32: 0.0016898761
D33: 46020 | E33: 一 | F33: 98.4 | I33: =F33/$C$1 -> 0.87234043 | L33: 0.0019675698 | O33: 0.003874804
D34: 46021 | E34: 二
D35: 46022 | E35: 三

Sheet （３）業績構成比
B2: （3）業績構成比
B3: 資料繳交日 | C3: 月份 | D3: 日期 | F3: 營業額 | I3: 品類業績
I4: 熱食義麵 | K4: 季節調理麵 | M4: 微波小吃
F5: 日 | G5: 週累積 | H5: 月累積 | I5: 一配 | K5: 一配 | M5: 一配
I6: 業績(元) | J6: 比例(%) | K6: 業績(元) | L6: 比例(%) | M6: 業績(元) | N6: 比例(%)
C7: 十二 | D7: 45992 | E7: 一 | F7: =SUM(I7,K7,M7) -> 2513777.5 | H7: =SUM(F7:F37) -> 68791952 | I7: 2307139.1 | J7: =I7/F7 -> 0.91779763 | L7: =K7/F7 -> 0 | M7: 206638.46 | N7: =M7/F7 -> 0.082202366
B8: 46001 | D8: 45993 | E8: 二 | F8: =SUM(I8,K8,M8) -> 2335255 | G8: =SUM(F8:F14) -> 15371291 | I8: 2138809.7 | J8: =I8/F8 -> 0.91587846 | L8: =K8/F8 -> 0 | M8: 196445.25 | N8: =M8/F8 -> 0.084121543
D9: 45994 | E9: 三 | F9: =SUM(I9,K9,M9) -> 2176837.3 | I9: 1986919.9 | J9: =I9/F9 -> 0.91275536 | L9: =K9/F9 -> 0 | M9: 189917.38 | N9: =M9/F9 -> 0.087244638
D10: 45995 | E10: 四 | F10: =SUM(I10,K10,M10) -> 2121444.9 | I10: 1941683.6 | J10: =I10/F10 -> 0.91526468 | L10: =K10/F10 -> 0 | M10: 179761.31 | N10: =M10/F10 -> 0.084735319
D11: 45996 | E11: 五 | F11: =SUM(I11,K11,M11) -> 1832380.4 | I11: 1679171.5 | J11: =I11/F11 -> 0.91638809 | L11: =K11/F11 -> 0 | M11: 153208.83 | N11: =M11/F11 -> 0.083611915
D12: 45997 | E12: 六 | F12: =SUM(I12,K12,M12) -> 1995581.1 | I12: 1827891 | J12: =I12/F12 -> 0.91596932 | L12: =K12/F12 -> 0 | M12: 167690.03 | N12: =M12/F12 -> 0.084030679
D13: 45998 | E13: 日 | F13: =SUM(I13,K13,M13) -> 2513995.6 | I13: 2308449.3 | J13: =I13/F13 -> 0.91823919 | L13: =K13/F13 -> 0 | M13: 205546.33 | N13: =M13/F13 -> 0.081760815
D14: 45999 | E14: 一 | F14: =SUM(I14,K14,M14) -> 2395796.6 | I14: 2195513.8 | J14: =I14/F14 -> 0.91640244 | L14: =K14/F14 -> 0 | M14: 200282.76 | N14: =M14/F14 -> 0.083597565
B15: 46008 | D15: 46000 | E15: 二 | F15: =SUM(I15,K15,M15) -> 3129368 | G15: =SUM(F15:F21) -> 17129534 | I15: 2745741.1 | J15: =I15/F15 -> 0.87741074 | L15: =K15/F15 -> 0 | M15: 383626.92 | N15: =M15/F15 -> 0.12258926
D16: 46001 | E16: 三 | F16: =SUM(I16,K16,M16) -> 2596020.5 | I16: 2395378.6 | J16: =I16/F16 -> 0.92271173 | L16: =K16/F16 -> 0 | M16: 200641.93 | N16: =M16/F16 -> 0.077288269
D17: 46002 | E17: 四 | F17: =SUM(I17,K17,M17) -> 2249510.9 | I17: 2086053.9 | J17: =I17/F17 -> 0.92733668 | L17: =K17/F17 -> 0 | M17: 163456.92 | N17: =M17/F17 -> 0.072663316
D18: 46003 | E18: 五 | F18: =SUM(I18,K18,M18) -> 1793030.3 | I18: 1630327.9 | J18: =I18/F18 -> 0.90925845 | L18: =K18/F18 -> 0 | M18: 162702.34 | N18: =M18/F18 -> 0.090741547
D19: 46004 | E19: 六 | F19: =SUM(I19,K19,M19) -> 2044428.8 | I19: 1849536.3 | J19: =I19/F19 -> 0.90467141 | L19: =K19/F19 -> 0 | M19: 194892.51 | N19: =M19/F19 -> 0.095328588
D20: 46005 | E20: 日 | F20: =SUM(I20,K20,M20) -> 2720484 | I20: 2495145.3 | J20: =I20/F20 -> 0.91716963 | L20: =K20/F20 -> 0 | M20: 225338.69 | N20: =M20/F20 -> 0.082830367
D21: 46006 | E21: 一 | F21: =SUM(I21,K21,M21) -> 2596691.6 | I21: 2354149.3 | J21: =I21/F21 -> 0.90659565 | L21: =K21/F21 -> 0 | M21: 242542.28 | N21: =M21/F21 -> 0.093404345
B22: 46015 | D22: 46007 | E22: 二 | F22: =SUM(I22,K22,M22) -> 2614596.3 | G22: =SUM(F22:F28) -> 17356992 | I22: 2405755.4 | J22: =I22/F22 -> 0.920125 | L22: =K22/F22 -> 0 | M22: 208840.87 | N22: =M22/F22 -> 0.079874997
D23: 46008 | E23: 三 | F23: =SUM(I23,K23,M23) -> 2455966 | I23: 2255835.5 | J23: =I23/F23 -> 0.91851251 | L23: =K23/F23 -> 0 | M23: 200130.5 | N23: =M23/F23 -> 0.081487487
D24: 46009 | E24: 四 | F24: =SUM(I24,K24,M24) -> 2339510.5 | I24: 2144015.8 | J24: =I24/F24 -> 0.91643779 | L24: =K24/F24 -> 0 | M24: 195494.68 | N24: =M24/F24 -> 0.083562215
D25: 46010 | E25: 五 | F25: =SUM(I25,K25,M25) -> 2112449.6 | I25: 1944600.6 | J25: =I25/F25 -> 0.92054298 | L25: =K25/F25 -> 0 | M25: 167848.94 | N25: =M25/F25 -> 0.079457017
D26: 46011 | E26: 六 | F26: =SUM(I26,K26,M26) -> 2376517 | I26: 2182977.1 | J26: =I26/F26 -> 0.91856152 | L26: =K26/F26 -> 0 | M26: 193539.94 | N26: =M26/F26 -> 0.081438483
D27: 46012 | E27: 日 | F27: =SUM(I27,K27,M27) -> 2783602.7 | I27: 2575971.4 | J27: =I27/F27 -> 0.92540913 | L27: =K27/F27 -> 0 | M27: 207631.35 | N27: =M27/F27 -> 0.07459087
D28: 46013 | E28: 一 | F28: =SUM(I28,K28,M28) -> 2674350 | I28: 2462210.5 | J28: =I28/F28 -> 0.92067622 | L28: =K28/F28 -> 0 | M28: 212139.55 | N28: =M28/F28 -> 0.07932378
B29: 46022 | D29: 46014 | E29: 二 | F29: =SUM(I29,K29,M29) -> 2842340.9 | G29: =SUM(F29:F35) -> 16420357 | I29: 2647879 | J29: =I29/F29 -> 0.93158388 | L29: =K29/F29 -> 0 | M29: 194461.93 | N29: =M29/F29 -> 0.068416118
D30: 46015 | E30: 三 | F30: =SUM(I30,K30,M30) -> 1906561 | I30: 1746070.6 | J30: =I30/F30 -> 0.91582203 | L30: =K30/F30 -> 0 | M30: 160490.44 | N30: =M30/F30 -> 0.084177972
D31: 46016 | E31: 四 | F31: =SUM(I31,K31,M31) -> 2152805.8 | I31: 1978466.9 | J31: =I31/F31 -> 0.91901781 | L31: =K31/F31 -> 0 | M31: 174338.93 | N31: =M31/F31 -> 0.08098219
D32: 46017 | E32: 五 | F32: =SUM(I32,K32,M32) -> 2059678.9 | I32: 1919678.5 | J32: =I32/F32 -> 0.93202804 | L32: =K32/F32 -> 0 | M32: 140000.41 | N32: =M32/F32 -> 0.067971959
D33: 46018 | E33: 六 | F33: =SUM(I33,K33,M33) -> 2208752.2 | I33: 2043956.6 | J33: =I33/F33 -> 0.92538971 | L33: =K33/F33 -> 0 | M33: 164795.65 | N33: =M33/F33 -> 0.074610292
D34: 46019 | E34: 日 | F34: =SUM(I34,K34,M34) -> 2697831 | I34: 2504177.5 | J34: =I34/F34 -> 0.92821882 | L34: =K34/F34 -> 0 | M34: 193653.5 | N34: =M34/F34 -> 0.071781184
D35: 46020 | E35: 一 | F35: =SUM(I35,K35,M35) -> 2552387.2 | I35: 2353985.5 | J35: =I35/F35 -> 0.9222682 | L35: =K35/F35 -> 0 | M35: 198401.66 | N35: =M35/F35 -> 0.077731804
D36: 46021 | E36: 二 | F36: =SUM(I36,K36,M36) -> 0 | J36: =I36/F36 -> #DIV/0! | L36: =K36/F36 -> #DIV/0! | N36: =M36/F36 -> #DIV/0!
D37: 46022 | E37: 三 | F37: =SUM(I37,K37,M37) -> 0 | J37: =I37/F37 -> #DIV/0! | L37: =K37/F37 -> #DIV/0! | N37: =M37/F37 -> #DIV/0!

Sheet （４）訂單數量構成比
B2: （4）訂單數量構成比
B3: 資料繳交日 | C3: 月份 | D3: 日期 | F3: 訂單量 | I3: 品類訂單量
I4: 熱食義麵 | K4: 季節調理麵 | M4: 微波小吃
F5: 日 | G5: 週累積 | H5: 月累積 | I5: 一配 | K5: 一配 | M5: 一配
I6: 訂單數 | J6: 比例(%) | K6: 訂單數 | L6: 比例(%) | M6: 訂單數 | N6: 比例(%)
C7: 十二 | D7: 45992 | E7: 一 | F7: =SUM(I7,K7,M7) -> 52776 | H7: =SUM(F7:F37) -> 1446739 | I7: 45277 | J7: =I7/F7 -> 0.8579089 | L7: =K7/F7 -> 0 | M7: 7499 | N7: =M7/F7 -> 0.1420911
B8: 46001 | D8: 45993 | E8: 二 | F8: =SUM(I8,K8,M8) -> 49145 | G8: =SUM(F8:F14) -> 323563 | I8: 42009 | J8: =I8/F8 -> 0.85479703 | L8: =K8/F8 -> 0 | M8: 7136 | N8: =M8/F8 -> 0.14520297
D9: 45994 | E9: 三 | F9: =SUM(I9,K9,M9) -> 45862 | I9: 38970 | J9: =I9/F9 -> 0.84972308 | L9: =K9/F9 -> 0 | M9: 6892 | N9: =M9/F9 -> 0.15027692
D10: 45995 | E10: 四 | F10: =SUM(I10,K10,M10) -> 44569 | I10: 38047 | J10: =I10/F10 -> 0.8536651 | L10: =K10/F10 -> 0 | M10: 6522 | N10: =M10/F10 -> 0.1463349
D11: 45996 | E11: 五 | F11: =SUM(I11,K11,M11) -> 38620 | I11: 33053 | J11: =I11/F11 -> 0.85585189 | L11: =K11/F11 -> 0 | M11: 5567 | N11: =M11/F11 -> 0.14414811
D12: 45997 | E12: 六 | F12: =SUM(I12,K12,M12) -> 42013 | I12: 35927 | J12: =I12/F12 -> 0.85514008 | L12: =K12/F12 -> 0 | M12: 6086 | N12: =M12/F12 -> 0.14485992
D13: 45998 | E13: 日 | F13: =SUM(I13,K13,M13) -> 52933 | I13: 45458 | J13: =I13/F13 -> 0.85878375 | L13: =K13/F13 -> 0 | M13: 7475 | N13: =M13/F13 -> 0.14121625
D14: 45999 | E14: 一 | F14: =SUM(I14,K14,M14) -> 50421 | I14: 43151 | J14: =I14/F14 -> 0.85581405 | L14: =K14/F14 -> 0 | M14: 7270 | N14: =M14/F14 -> 0.14418595
B15: 46008 | D15: 46000 | E15: 二 | F15: =SUM(I15,K15,M15) -> 66936 | G15: =SUM(F15:F21) -> 359333 | I15: 53210 | J15: =I15/F15 -> 0.79493845 | L15: =K15/F15 -> 0 | M15: 13726 | N15: =M15/F15 -> 0.20506155
D16: 46001 | E16: 三 | F16: =SUM(I16,K16,M16) -> 53635 | I16: 46360 | J16: =I16/F16 -> 0.86436096 | L16: =K16/F16 -> 0 | M16: 7275 | N16: =M16/F16 -> 0.13563904
D17: 46002 | E17: 四 | F17: =SUM(I17,K17,M17) -> 46504 | I17: 40560 | J17: =I17/F17 -> 0.87218304 | L17: =K17/F17 -> 0 | M17: 5944 | N17: =M17/F17 -> 0.12781696
D18: 46003 | E18: 五 | F18: =SUM(I18,K18,M18) -> 37707 | I18: 31815 | J18: =I18/F18 -> 0.84374254 | L18: =K18/F18 -> 0 | M18: 5892 | N18: =M18/F18 -> 0.15625746
D19: 46004 | E19: 六 | F19: =SUM(I19,K19,M19) -> 43137 | I19: 36099 | J19: =I19/F19 -> 0.8368454 | L19: =K19/F19 -> 0 | M19: 7038 | N19: =M19/F19 -> 0.1631546
D20: 46005 | E20: 日 | F20: =SUM(I20,K20,M20) -> 56760 | I20: 48590 | J20: =I20/F20 -> 0.85606061 | L20: =K20/F20 -> 0 | M20: 8170 | N20: =M20/F20 -> 0.14393939
D21: 46006 | E21: 一 | F21: =SUM(I21,K21,M21) -> 54654 | I21: 45889 | J21: =I21/F21 -> 0.83962747 | L21: =K21/F21 -> 0 | M21: 8765 | N21: =M21/F21 -> 0.16037253
B22: 46015 | D22: 46007 | E22: 二 | F22: =SUM(I22,K22,M22) -> 54968 | G22: =SUM(F22:F28) -> 365761 | I22: 47403 | J22: =I22/F22 -> 0.86237447 | L22: =K22/F22 -> 0 | M22: 7565 | N22: =M22/F22 -> 0.13762553
D23: 46008 | E23: 三 | F23: =SUM(I23,K23,M23) -> 51643 | I23: 44398 | J23: =I23/F23 -> 0.85970993 | L23: =K23/F23 -> 0 | M23: 7245 | N23: =M23/F23 -> 0.14029007
D24: 46009 | E24: 四 | F24: =SUM(I24,K24,M24) -> 49206 | I24: 42136 | J24: =I24/F24 -> 0.85631834 | L24: =K24/F24 -> 0 | M24: 7070 | N24: =M24/F24 -> 0.14368166
D25: 46010 | E25: 五 | F25: =SUM(I25,K25,M25) -> 45379 | I25: 39297 | J25: =I25/F25 -> 0.86597325 | L25: =K25/F25 -> 0 | M25: 6082 | N25: =M25/F25 -> 0.13402675
D26: 46011 | E26: 六 | F26: =SUM(I26,K26,M26) -> 49960 | I26: 42966 | J26: =I26/F26 -> 0.86000801 | L26: =K26/F26 -> 0 | M26: 6994 | N26: =M26/F26 -> 0.13999199
D27: 46012 | E27: 日 | F27: =SUM(I27,K27,M27) -> 58406 | I27: 50869 | J27: =I27/F27 -> 0.87095504 | L27: =K27/F27 -> 0 | M27: 7537 | N27: =M27/F27 -> 0.12904496
D28: 46013 | E28: 一 | F28: =SUM(I28,K28,M28) -> 56199 | I28: 48515 | J28: =I28/F28 -> 0.86327159 | L28: =K28/F28 -> 0 | M28: 7684 | N28: =M28/F28 -> 0.13672841
B29: 46022 | D29: 46014 | E29: 二 | F29: =SUM(I29,K29,M29) -> 59311 | G29: =SUM(F29:F35) -> 345306 | I29: 52265 | J29: =I29/F29 -> 0.88120248 | L29: =K29/F29 -> 0 | M29: 7046 | N29: =M29/F29 -> 0.11879752
D30: 46015 | E30: 三 | F30: =SUM(I30,K30,M30) -> 40396 | I30: 34584 | J30: =I30/F30 -> 0.85612437 | L30: =K30/F30 -> 0 | M30: 5812 | N30: =M30/F30 -> 0.14387563
D31: 46016 | E31: 四 | F31: =SUM(I31,K31,M31) -> 45518 | I31: 39203 | J31: =I31/F31 -> 0.86126368 | L31: =K31/F31 -> 0 | M31: 6315 | N31: =M31/F31 -> 0.13873632
D32: 46017 | E32: 五 | F32: =SUM(I32,K32,M32) -> 43115 | I32: 38034 | J32: =I32/F32 -> 0.88215238 | L32: =K32/F32 -> 0 | M32: 5081 | N32: =M32/F32 -> 0.11784762
D33: 46018 | E33: 六 | F33: =SUM(I33,K33,M33) -> 46400 | I33: 40434 | J33: =I33/F33 -> 0.87142241 | L33: =K33/F33 -> 0 | M33: 5966 | N33: =M33/F33 -> 0.12857759
D34: 46019 | E34: 日 | F34: =SUM(I34,K34,M34) -> 56766 | I34: 49722 | J34: =I34/F34 -> 0.87591164 | L34: =K34/F34 -> 0 | M34: 7044 | N34: =M34/F34 -> 0.12408836
D35: 46020 | E35: 一 | F35: =SUM(I35,K35,M35) -> 53800 | I35: 46604 | J35: =I35/F35 -> 0.86624535 | L35: =K35/F35 -> 0 | M35: 7196 | N35: =M35/F35 -> 0.13375465
D36: 46021 | E36: 二 | F36: =SUM(I36,K36,M36) -> 0 | J36: =I36/F36 -> #DIV/0! | L36: =K36/F36 -> #DIV/0! | N36: =M36/F36 -> #DIV/0!
D37: 46022 | E37: 三 | F37: =SUM(I37,K37,M37) -> 0 | J37: =I37/F37 -> #DIV/0! | L37: =K37/F37 -> #DIV/0! | N37: =M37/F37 -> #DIV/0!

Sheet （５-1）品群別人時生產性（熱食義麵）
B1: 月平均人時性 | C1: =AVERAGE(L7,L30,L53,L73,L96,L119) -> 98.14611
B2: 產線配置圖－每週更新 | N2: 資料繳交 | O2: 日期 | AT2: 45992
P3: 二 | U3: 三 | Z3: 四 | AE3: 五 | AJ3: 六 | AO3: 日 | AT3: 一
B4: 品群 | C4: 商品名稱 | E4: 計畫 | H4: 平均人時性 | I4: 實績 | L4: 平均人時性 | M4: 排名 | O4: 日報 | P4: 實際 | T4: 平均人時性 | U4: 實際 | Y4: 平均人時性 | Z4: 實際 | AD4: 平均人時性 | AE4: 實際 | AI4: 平均人時性 | AJ4: 實際 | AN4: 平均人時性 | AO4: 實際 | AS4: 平均人時性 | AT4: 實際 | AX4: 平均人時性
E5: 產線配置圖 | I5: 產線配置圖 | P5: 生產實績 | U5: 生產實績 | Z5: 生產實績 | AE5: 生產實績 | AJ5: 生產實績 | AO5: 生產實績 | AT5: 生產實績
E6: 人數 | F6: 產能／時 | G6: 人時性 | I6: 人數 | J6: 產能／時 | K6: 人時性 | P6: 人數 | Q6: 產能／時 | R6: 人時性 | S6: 排名 | U6: 人數 | V6: 產能／時 | W6: 人時性 | X6: 排名 | Z6: 人數 | AA6: 產能／時 | AB6: 人時性 | AC6: 排名 | AE6: 人數 | AF6: 產能／時 | AG6: 人時性 | AH6: 排名 | AJ6: 人數 | AK6: 產能／時 | AL6: 人時性 | AM6: 排名 | AO6: 人數 | AP6: 產能／時 | AQ6: 人時性 | AR6: 排名 | AT6: 人數 | AU6: 產能／時 | AV6: 人時性 | AW6: 排名
B7: 熱食義麵 | C7: 1 | D7: 義式蕃茄起司義大利麵 | E7: =VLOOKUP(D7,'11產線配置圖'!$A$2:$C$25,2,0) -> 12 | F7: =VLOOKUP(D7,'11產線配置圖'!$A$2:$C$25,3,0) -> 2000 | G7: =F7/E7 -> 166.66667 | H7: =AVERAGE(G7:G24) -> 112.60546 | I7: =AVERAGE(AT7) -> 12 | J7: =AVERAGE(AU7) -> 1781 | K7: =AVERAGE(AV7) -> 148.41667 | L7: =IFERROR(AVERAGE(K7:K24),"-") -> 102.18112 | M7: =RANK(K7, K$7:$K$24) -> 1 | R7: =Q7/P7 -> #DIV/0! | S7: =RANK(R7, R$7:R$24) -> #DIV/0! | T7: =AVERAGE(R7:R24) -> #DIV/0! | W7: =V7/U7 -> #DIV/0! | X7: =RANK(W7, W$7:W$24) -> #DIV/0! | Y7: =AVERAGE(W7:W24) -> #DIV/0! | AB7: =AA7/Z7 -> #DIV/0! | AC7: =RANK(AB7, AB$7:AB$24) -> #DIV/0! | AD7: =AVERAGE(AB7:AB24) -> #DIV/0! | AG7: =AF7/AE7 -> #DIV/0! | AH7: =RANK(AG7, AG$7:AG$24) -> #DIV/0! | AI7: =AVERAGE(AG7:AG24) -> #DIV/0! | AL7: =AK7/AJ7 -> #DIV/0! | AM7: =RANK(AL7, AL$7:AL$24) -> #DIV/0! | AN7: =AVERAGE(AL7:AL24) -> #DIV/0! | AQ7: =AP7/AO7 -> #DIV/0! | AR7: =RANK(AQ7, AQ$7:AQ$24) -> #DIV/0! | AS7: =AVERAGE(AQ7:AQ24) -> #DIV/0! | AT7: 12 | AU7: 1781 | AV7: =AU7/AT7 -> 148.41667 | AW7: =RANK(AV7, AV$7:AV$24) -> 1 | AX7: =AVERAGE(AV7:AV24) -> 100.0518
C8: 2 | D8: 奶油培根義大利麵 | E8: =VLOOKUP(D8,'11產線配置圖'!$A$2:$C$25,2,0) -> 13 | F8: =VLOOKUP(D8,'11產線配置圖'!$A$2:$C$25,3,0) -> 2000 | G8: =F8/E8 -> 153.84615 | I8: =AVERAGE(AT8) -> 13 | J8: =AVERAGE(AU8) -> 1891 | K8: =AVERAGE(AV8) -> 145.46154 | M8: =RANK(K8, K$7:$K$24) -> 2 | R8: =Q8/P8 -> #DIV/0! | S8: =RANK(R8, R$7:R$24) -> #DIV/0! | W8: =V8/U8 -> #DIV/0! | X8: =RANK(W8, W$7:W$24) -> #DIV/0! | AB8: =AA8/Z8 -> #DIV/0! | AC8: =RANK(AB8, AB$7:AB$24) -> #DIV/0! | AG8: =AF8/AE8 -> #DIV/0! | AH8: =RANK(AG8, AG$7:AG$24) -> #DIV/0! | AL8: =AK8/AJ8 -> #DIV/0! | AM8: =RANK(AL8, AL$7:AL$24) -> #DIV/0! | AQ8: =AP8/AO8 -> #DIV/0! | AR8: =RANK(AQ8, AQ$7:AQ$24) -> #DIV/0! | AT8: 13 | AU8: 1891 | AV8: =AU8/AT8 -> 145.46154 | AW8: =RANK(AV8, AV$7:AV$24) -> 2
C9: 3 | D9: 青醬蛤蜊義大利麵 | E9: =VLOOKUP(D9,'11產線配置圖'!$A$2:$C$25,2,0) -> 15 | F9: =VLOOKUP(D9,'11產線配置圖'!$A$2:$C$25,3,0) -> 2000 | G9: =F9/E9 -> 133.33333 | I9: =AVERAGE(AT9) -> 13 | J9: =AVERAGE(AU9) -> 1591 | K9: =AVERAGE(AV9) -> 122.38462 | M9: =RANK(K9, K$7:$K$24) -> 4 | R9: =Q9/P9 -> #DIV/0! | S9: =RANK(R9, R$7:R$24) -> #DIV/0! | W9: =V9/U9 -> #DIV/0! | X9: =RANK(W9, W$7:W$24) -> #DIV/0! | AB9: =AA9/Z9 -> #DIV/0! | AC9: =RANK(AB9, AB$7:AB$24) -> #DIV/0! | AG9: =AF9/AE9 -> #DIV/0! | AH9: =RANK(AG9, AG$7:AG$24) -> #DIV/0! | AL9: =AK9/AJ9 -> #DIV/0! | AM9: =RANK(AL9, AL$7:AL$24) -> #DIV/0! | AQ9: =AP9/AO9 -> #DIV/0! | AR9: =RANK(AQ9, AQ$7:AQ$24) -> #DIV/0! | AT9: 13 | AU9: 1591 | AV9: =AU9/AT9 -> 122.38462 | AW9: =RANK(AV9, AV$7:AV$24) -> 4
C10: 4 | D10: 焗烤起司雙饗筆尖麵 | E10: =VLOOKUP(D10,'11產線配置圖'!$A$2:$C$25,2,0) -> 18 | F10: =VLOOKUP(D10,'11產線配置圖'!$A$2:$C$25,3,0) -> 1565 | G10: =F10/E10 -> 86.944444 | I10: =AVERAGE(AT10) -> 18 | J10: =AVERAGE(AU10) -> 1545 | K10: =AVERAGE(AV10) -> 85.833333 | M10: =RANK(K10, K$7:$K$24) -> 7 | R10: =Q10/P10 -> #DIV/0! | S10: =RANK(R10, R$7:R$24) -> #DIV/0! | W10: =V10/U10 -> #DIV/0! | X10: =RANK(W10, W$7:W$24) -> #DIV/0! | AB10: =AA10/Z10 -> #DIV/0! | AC10: =RANK(AB10, AB$7:AB$24) -> #DIV/0! | AG10: =AF10/AE10 -> #DIV/0! | AH10: =RANK(AG10, AG$7:AG$24) -> #DIV/0! | AL10: =AK10/AJ10 -> #DIV/0! | AM10: =RANK(AL10, AL$7:AL$24) -> #DIV/0! | AQ10: =AP10/AO10 -> #DIV/0! | AR10: =RANK(AQ10, AQ$7:AQ$24) -> #DIV/0! | AT10: 18 | AU10: 1545 | AV10: =AU10/AT10 -> 85.833333 | AW10: =RANK(AV10, AV$7:AV$24) -> 7
C11: 5 | D11: 白酒蛤蜊義大利麵 | E11: =VLOOKUP(D11,'11產線配置圖'!$A$2:$C$25,2,0) -> 13 | F11: =VLOOKUP(D11,'11產線配置圖'!$A$2:$C$25,3,0) -> 2000 | G11: =F11/E11 -> 153.84615 | I11: =AVERAGE(AT11) -> 13 | J11: =AVERAGE(AU11) -> 1688 | K11: =AVERAGE(AV11) -> 129.84615 | M11: =RANK(K11, K$7:$K$24) -> 3 | R11: =Q11/P11 -> #DIV/0! | S11: =RANK(R11, R$7:R$24) -> #DIV/0! | W11: =V11/U11 -> #DIV/0! | X11: =RANK(W11, W$7:W$24) -> #DIV/0! | AB11: =AA11/Z11 -> #DIV/0! | AC11: =RANK(AB11, AB$7:AB$24) -> #DIV/0! | AG11: =AF11/AE11 -> #DIV/0! | AH11: =RANK(AG11, AG$7:AG$24) -> #DIV/0! | AL11: =AK11/AJ11 -> #DIV/0! | AM11: =RANK(AL11, AL$7:AL$24) -> #DIV/0! | AQ11: =AP11/AO11 -> #DIV/0! | AR11: =RANK(AQ11, AQ$7:AQ$24) -> #DIV/0! | AT11: 13 | AU11: 1688 | AV11: =AU11/AT11 -> 129.84615 | AW11: =RANK(AV11, AV$7:AV$24) -> 3
C12: 6 | D12: 韓式起司炸雞義大利麵 | E12: =VLOOKUP(D12,'11產線配置圖'!$A$2:$C$25,2,0) -> 14 | F12: =VLOOKUP(D12,'11產線配置圖'!$A$2:$C$25,3,0) -> 1895 | G12: =F12/E12 -> 135.35714 | I12: =AVERAGE(AT12) -> 17 | J12: =AVERAGE(AU12) -> 1678 | K12: =AVERAGE(AV12) -> 98.705882 | M12: =RANK(K12, K$7:$K$24) -> 5 | R12: =Q12/P12 -> #DIV/0! | S12: =RANK(R12, R$7:R$24) -> #DIV/0! | W12: =V12/U12 -> #DIV/0! | X12: =RANK(W12, W$7:W$24) -> #DIV/0! | AB12: =AA12/Z12 -> #DIV/0! | AC12: =RANK(AB12, AB$7:AB$24) -> #DIV/0! | AG12: =AF12/AE12 -> #DIV/0! | AH12: =RANK(AG12, AG$7:AG$24) -> #DIV/0! | AL12: =AK12/AJ12 -> #DIV/0! | AM12: =RANK(AL12, AL$7:AL$24) -> #DIV/0! | AQ12: =AP12/AO12 -> #DIV/0! | AR12: =RANK(AQ12, AQ$7:AQ$24) -> #DIV/0! | AT12: 17 | AU12: 1678 | AV12: =AU12/AT12 -> 98.705882 | AW12: =RANK(AV12, AV$7:AV$24) -> 5
C13: 7 | D13: 焗烤明太子筆尖麵 | E13: =VLOOKUP(D13,'11產線配置圖'!$A$2:$C$25,2,0) -> 17 | F13: =VLOOKUP(D13,'11產線配置圖'!$A$2:$C$25,3,0) -> 1385 | G13: =F13/E13 -> 81.470588 | I13: =AVERAGE(AT13) -> 14 | J13: =AVERAGE(AU13) -> 1233 | K13: =AVERAGE(AV13) -> 88.071429 | M13: =RANK(K13, K$7:$K$24) -> 6 | R13: =Q13/P13 -> #DIV/0! | S13: =RANK(R13, R$7:R$24) -> #DIV/0! | W13: =V13/U13 -> #DIV/0! | X13: =RANK(W13, W$7:W$24) -> #DIV/0! | AB13: =AA13/Z13 -> #DIV/0! | AC13: =RANK(AB13, AB$7:AB$24) -> #DIV/0! | AG13: =AF13/AE13 -> #DIV/0! | AH13: =RANK(AG13, AG$7:AG$24) -> #DIV/0! | AL13: =AK13/AJ13 -> #DIV/0! | AM13: =RANK(AL13, AL$7:AL$24) -> #DIV/0! | AQ13: =AP13/AO13 -> #DIV/0! | AR13: =RANK(AQ13, AQ$7:AQ$24) -> #DIV/0! | AT13: 14 | AU13: 1233 | AV13: =AU13/AT13 -> 88.071429 | AW13: =RANK(AV13, AV$7:AV$24) -> 6
C14: 8 | D14: 奶油蒜香雞義大利麵 | E14: =VLOOKUP(D14,'11產線配置圖'!$A$2:$C$25,2,0) -> 18 | F14: =VLOOKUP(D14,'11產線配置圖'!$A$2:$C$25,3,0) -> 1385 | G14: =F14/E14 -> 76.944444 | I14: =AVERAGE(AT14) -> 15 | J14: =AVERAGE(AU14) -> 1202 | K14: =AVERAGE(AV14) -> 80.133333 | M14: =RANK(K14, K$7:$K$24) -> 10 | R14: =Q14/P14 -> #DIV/0! | S14: =RANK(R14, R$7:R$24) -> #DIV/0! | W14: =V14/U14 -> #DIV/0! | X14: =RANK(W14, W$7:W$24) -> #DIV/0! | AB14: =AA14/Z14 -> #DIV/0! | AC14: =RANK(AB14, AB$7:AB$24) -> #DIV/0! | AG14: =AF14/AE14 -> #DIV/0! | AH14: =RANK(AG14, AG$7:AG$24) -> #DIV/0! | AL14: =AK14/AJ14 -> #DIV/0! | AM14: =RANK(AL14, AL$7:AL$24) -> #DIV/0! | AQ14: =AP14/AO14 -> #DIV/0! | AR14: =RANK(AQ14, AQ$7:AQ$24) -> #DIV/0! | AT14: 15 | AU14: 1202 | AV14: =AU14/AT14 -> 80.133333 | AW14: =RANK(AV14, AV$7:AV$24) -> 10
C15: 9 | D15: 青花椒麻雞肉拌麵 | E15: =VLOOKUP(D15,'11產線配置圖'!$A$2:$C$25,2,0) -> 17 | F15: =VLOOKUP(D15,'11產線配置圖'!$A$2:$C$25,3,0) -> 1565 | G15: =F15/E15 -> 92.058824 | I15: =AVERAGE(AT15) -> 16 | J15: =AVERAGE(AU15) -> 1349 | K15: =AVERAGE(AV15) -> 84.3125 | M15: =RANK(K15, K$7:$K$24) -> 8 | R15: =Q15/P15 -> #DIV/0! | S15: =RANK(R15, R$7:R$24) -> #DIV/0! | W15: =V15/U15 -> #DIV/0! | X15: =RANK(W15, W$7:W$24) -> #DIV/0! | AB15: =AA15/Z15 -> #DIV/0! | AC15: =RANK(AB15, AB$7:AB$24) -> #DIV/0! | AG15: =AF15/AE15 -> #DIV/0! | AH15: =RANK(AG15, AG$7:AG$24) -> #DIV/0! | AL15: =AK15/AJ15 -> #DIV/0! | AM15: =RANK(AL15, AL$7:AL$24) -> #DIV/0! | AQ15: =AP15/AO15 -> #DIV/0! | AR15: =RANK(AQ15, AQ$7:AQ$24) -> #DIV/0! | AT15: 16 | AU15: 1349 | AV15: =AU15/AT15 -> 84.3125 | AW15: =RANK(AV15, AV$7:AV$24) -> 8
C16: 10 | D16: 剝皮辣椒雞奶油扁麵 | E16: =VLOOKUP(D16,'11產線配置圖'!$A$2:$C$25,2,0) -> 17 | F16: =VLOOKUP(D16,'11產線配置圖'!$A$2:$C$25,3,0) -> 1500 | G16: =F16/E16 -> 88.235294 | I16: =AVERAGE(AT16) -> 18 | J16: =AVERAGE(AU16) -> 1430 | K16: =AVERAGE(AV16) -> 79.444444 | M16: =RANK(K16, K$7:$K$24) -> 12 | R16: =Q16/P16 -> #DIV/0! | S16: =RANK(R16, R$7:R$24) -> #DIV/0! | W16: =V16/U16 -> #DIV/0! | X16: =RANK(W16, W$7:W$24) -> #DIV/0! | AB16: =AA16/Z16 -> #DIV/0! | AC16: =RANK(AB16, AB$7:AB$24) -> #DIV/0! | AG16: =AF16/AE16 -> #DIV/0! | AH16: =RANK(AG16, AG$7:AG$24) -> #DIV/0! | AL16: =AK16/AJ16 -> #DIV/0! | AM16: =RANK(AL16, AL$7:AL$24) -> #DIV/0! | AQ16: =AP16/AO16 -> #DIV/0! | AR16: =RANK(AQ16, AQ$7:AQ$24) -> #DIV/0! | AT16: 18 | AU16: 1430 | AV16: =AU16/AT16 -> 79.444444 | AW16: =RANK(AV16, AV$7:AV$24) -> 12
C17: 11 | D17: 濃拿坡里義大利麵 | E17: =VLOOKUP(D17,'11產線配置圖'!$A$2:$C$25,2,0) -> 15 | F17: =VLOOKUP(D17,'11產線配置圖'!$A$2:$C$25,3,0) -> 1440 | G17: =F17/E17 -> 96 | I17: =AVERAGE(AT17) -> 14 | J17: =AVERAGE(AU17) -> 1173 | K17: =AVERAGE(AV17) -> 83.785714 | M17: =RANK(K17, K$7:$K$24) -> 9 | R17: =Q17/P17 -> #DIV/0! | S17: =RANK(R17, R$7:R$24) -> #DIV/0! | W17: =V17/U17 -> #DIV/0! | X17: =RANK(W17, W$7:W$24) -> #DIV/0! | AB17: =AA17/Z17 -> #DIV/0! | AC17: =RANK(AB17, AB$7:AB$24) -> #DIV/0! | AG17: =AF17/AE17 -> #DIV/0! | AH17: =RANK(AG17, AG$7:AG$24) -> #DIV/0! | AL17: =AK17/AJ17 -> #DIV/0! | AM17: =RANK(AL17, AL$7:AL$24) -> #DIV/0! | AQ17: =AP17/AO17 -> #DIV/0! | AR17: =RANK(AQ17, AQ$7:AQ$24) -> #DIV/0! | AT17: 14 | AU17: 1173 | AV17: =AU17/AT17 -> 83.785714 | AW17: =RANK(AV17, AV$7:AV$24) -> 9
C18: 12 | D18: 奶油起司蝦仁通心粉 | E18: =VLOOKUP(D18,'11產線配置圖'!$A$2:$C$25,2,0) -> 16 | F18: =VLOOKUP(D18,'11產線配置圖'!$A$2:$C$25,3,0) -> 1385 | G18: =F18/E18 -> 86.5625 | I18: =AVERAGE(AT18) -> 18 | J18: =AVERAGE(AU18) -> 1436 | K18: =AVERAGE(AV18) -> 79.777778 | M18: =RANK(K18, K$7:$K$24) -> 11 | R18: =Q18/P18 -> #DIV/0! | S18: =RANK(R18, R$7:R$24) -> #DIV/0! | W18: =V18/U18 -> #DIV/0! | X18: =RANK(W18, W$7:W$24) -> #DIV/0! | AB18: =AA18/Z18 -> #DIV/0! | AC18: =RANK(AB18, AB$7:AB$24) -> #DIV/0! | AG18: =AF18/AE18 -> #DIV/0! | AH18: =RANK(AG18, AG$7:AG$24) -> #DIV/0! | AL18: =AK18/AJ18 -> #DIV/0! | AM18: =RANK(AL18, AL$7:AL$24) -> #DIV/0! | AQ18: =AP18/AO18 -> #DIV/0! | AR18: =RANK(AQ18, AQ$7:AQ$24) -> #DIV/0! | AT18: 18 | AU18: 1436 | AV18: =AU18/AT18 -> 79.777778 | AW18: =RANK(AV18, AV$7:AV$24) -> 11
C19: 13 | R19: =Q19/P19 -> #DIV/0! | S19: =RANK(R19, R$7:R$24) -> #DIV/0! | W19: =V19/U19 -> #DIV/0! | X19: =RANK(W19, W$7:W$24) -> #DIV/0! | AB19: =AA19/Z19 -> #DIV/0! | AC19: =RANK(AB19, AB$7:AB$24) -> #DIV/0! | AG19: =AF19/AE19 -> #DIV/0! | AH19: =RANK(AG19, AG$7:AG$24) -> #DIV/0! | AT19: 14 | AU19: 1043 | AV19: =AU19/AT19 -> 74.5 | AW19: =RANK(AV19, AV$7:AV$24) -> 13
C20: 14 | R20: =Q20/P20 -> #DIV/0! | S20: =RANK(R20, R$7:R$24) -> #DIV/0! | W20: =V20/U20 -> #DIV/0! | X20: =RANK(W20, W$7:W$24) -> #DIV/0! | AB20: =AA20/Z20 -> #DIV/0! | AC20: =RANK(AB20, AB$7:AB$24) -> #DIV/0! | AG20: =AF20/AE20 -> #DIV/0! | AH20: =RANK(AG20, AG$7:AG$24) -> #DIV/0!
C21: 15 | R21: =Q21/P21 -> #DIV/0! | S21: =RANK(R21, R$7:R$24) -> #DIV/0!
C22: 16 | R22: =Q22/P22 -> #DIV/0! | S22: =RANK(R22, R$7:R$24) -> #DIV/0!
C23: 17 | R23: =Q23/P23 -> #DIV/0! | S23: =RANK(R23, R$7:R$24) -> #DIV/0!
C24: 18 | R24: =Q24/P24 -> #DIV/0! | S24: =RANK(R24, R$7:R$24) -> #DIV/0!
B25: 產線配置圖－每週更新 | N25: 資料繳交 | O25: 日期 | P25: 45993 | U25: 45994 | Z25: 45995 | AE25: 45996 | AJ25: 45997 | AO25: 45998 | AT25: 45999
P26: 二 | U26: 三 | Z26: 四 | AE26: 五 | AJ26: 六 | AO26: 日 | AT26: 一
B27: 品群 | C27: 商品名稱 | E27: 計畫 | H27: 平均人時性 | I27: 實績 | L27: 平均人時性 | M27: 排名 | O27: 日報 | P27: 實際 | T27: 平均人時性 | U27: 實際 | Y27: 平均人時性 | Z27: 實際 | AD27: 平均人時性 | AE27: 實際 | AI27: 平均人時性 | AJ27: 實際 | AN27: 平均人時性 | AO27: 實際 | AS27: 平均人時性 | AT27: 實際 | AX27: 平均人時性
E28: 產線配置圖 | I28: 產線配置圖 | P28: 生產實績 | U28: 生產實績 | Z28: 生產實績 | AE28: 生產實績 | AJ28: 生產實績 | AO28: 生產實績 | AT28: 生產實績
E29: 人數 | F29: 產能／時 | G29: 人時性 | I29: 人數 | J29: 產能／時 | K29: 人時性 | P29: 人數 | Q29: 產能／時 | R29: 人時性 | S29: 排名 | U29: 人數 | V29: 產能／時 | W29: 人時性 | X29: 排名 | Z29: 人數 | AA29: 產能／時 | AB29: 人時性 | AC29: 排名 | AE29: 人數 | AF29: 產能／時 | AG29: 人時性 | AH29: 排名 | AJ29: 人數 | AK29: 產能／時 | AL29: 人時性 | AM29: 排名 | AO29: 人數 | AP29: 產能／時 | AQ29: 人時性 | AR29: 排名 | AT29: 人數 | AU29: 產能／時 | AV29: 人時性 | AW29: 排名
B30: 熱食義麵 | C30: 1 | D30: 義式蕃茄起司義大利麵 | E30: =VLOOKUP(D30,'11產線配置圖'!$A$2:$C$25,2,0) -> 12 | F30: =VLOOKUP(D30,'11產線配置圖'!$A$2:$C$25,3,0) -> 2000 | G30: =F30/E30 -> 166.66667 | H30: =AVERAGE(G30:G47) -> 112.33325 | I30: =AVERAGE(P30,U30,Z30,AE30,AJ30,AO30,AT30) -> 12 | J30: =AVERAGE(Q30,V30,AA30,AF30,AK30,AP30,AU30) -> 1763.2857 | K30: =AVERAGE(R30,W30,AB30,AG30,AL30,AQ30,AV30) -> 146.94048 | L30: =IFERROR(AVERAGE(K30:K47),"-") -> 96.117637 | M30: =RANK(K30, K$30:$K$47) -> 1 | P30: 12 | Q30: 1737 | R30: =Q30/P30 -> 144.75 | S30: =RANK(R30,$R$30:$R$47) -> 1 | T30: =AVERAGE(R30:R47) -> 92.134985 | U30: 12 | V30: 1757 | W30: =V30/U30 -> 146.41667 | X30: =RANK(W30, $W$30:$W$47) -> 2 | Y30: =AVERAGE(W30:W47) -> 90.23587 | Z30: 12 | AA30: 1620 | AB30: =AA30/Z30 -> 135 | AC30: =RANK(AB30, $AB$30:$AB$47) -> 4 | AD30: =AVERAGE(AB30:AB47) -> 97.446521 | AE30: 12 | AF30: 1789 | AG30: =AF30/AE30 -> 149.08333 | AH30: =RANK(AG30, $AG$30:$AG$47) -> 1 | AI30: =AVERAGE(AG30:AG47) -> 97.046616 | AJ30: 12 | AK30: 1674 | AL30: =AK30/AJ30 -> 139.5 | AM30: =RANK(AL30, $AL$30:$AL$47) -> 1 | AN30: =AVERAGE(AL30:AL47) -> 93.118055 | AO30: 12 | AP30: 1896 | AQ30: =AP30/AO30 -> 158 | AR30: =RANK(AQ30,$AQ$30:$AQ$47) -> 1 | AS30: =AVERAGE(AQ30:AQ47) -> 101.24907 | AT30: 12 | AU30: 1870 | AV30: =AU30/AT30 -> 155.83333 | AW30: =RANK(AV30, $AV$30:$AV$47) -> 1 | AX30: =AVERAGE(AV30:AV47) -> 101.59234
C31: 2 | D31: 奶油培根義大利麵 | E31: =VLOOKUP(D31,'11產線配置圖'!$A$2:$C$25,2,0) -> 13 | F31: =VLOOKUP(D31,'11產線配置圖'!$A$2:$C$25,3,0) -> 2000 | G31: =F31/E31 -> 153.84615 | I31: =AVERAGE(P31,U31,Z31,AE31,AJ31,AO31,AT31) -> 13 | J31: =AVERAGE(Q31,V31,AA31,AF31,AK31,AP31,AU31) -> 1742 | K31: =AVERAGE(R31,W31,AB31,AG31,AL31,AQ31,AV31) -> 134 | M31: =RANK(K31, K$30:$K$47) -> 3 | P31: 13 | Q31: 1779 | R31: =Q31/P31 -> 136.84615 | S31: =RANK(R31,$R$30:$R$47) -> 3 | U31: 13 | V31: 1260 | W31: =V31/U31 -> 96.923077 | X31: =RANK(W31, $W$30:$W$47) -> 4 | Z31: 13 | AA31: 1925 | AB31: =AA31/Z31 -> 148.07692 | AC31: =RANK(AB31, $AB$30:$AB$47) -> 1 | AE31: 13 | AF31: 1832 | AG31: =AF31/AE31 -> 140.92308 | AH31: =RANK(AG31, $AG$30:$AG$47) -> 2 | AJ31: 13 | AK31: 1601 | AL31: =AK31/AJ31 -> 123.15385 | AM31: =RANK(AL31, $AL$30:$AL$47) -> 2 | AO31: 13 | AP31: 1912 | AQ31: =AP31/AO31 -> 147.07692 | AR31: =RANK(AQ31,$AQ$30:$AQ$47) -> 2 | AT31: 13 | AU31: 1885 | AV31: =AU31/AT31 -> 145 | AW31: =RANK(AV31, $AV$30:$AV$47) -> 2
C32: 3 | D32: 青醬蛤蜊義大利麵 | E32: =VLOOKUP(D32,'11產線配置圖'!$A$2:$C$25,2,0) -> 15 | F32: =VLOOKUP(D32,'11產線配置圖'!$A$2:$C$25,3,0) -> 2000 | G32: =F32/E32 -> 133.33333 | I32: =AVERAGE(P32,U32,Z32,AE32,AJ32,AO32,AT32) -> 13 | J32: =AVERAGE(Q32,V32,AA32,AF32,AK32,AP32,AU32) -> 1784.2857 | K32: =AVERAGE(R32,W32,AB32,AG32,AL32,AQ32,AV32) -> 137.25275 | M32: =RANK(K32, K$30:$K$47) -> 2 | P32: 13 | Q32: 1807 | R32: =Q32/P32 -> 139 | S32: =RANK(R32,$R$30:$R$47) -> 2 | U32: 13 | V32: 1980 | W32: =V32/U32 -> 152.30769 | X32: =RANK(W32, $W$30:$W$47) -> 1 | Z32: 13 | AA32: 1762 | AB32: =AA32/Z32 -> 135.53846 | AC32: =RANK(AB32, $AB$30:$AB$47) -> 3 | AE32: 13 | AF32: 1749 | AG32: =AF32/AE32 -> 134.53846 | AH32: =RANK(AG32, $AG$30:$AG$47) -> 3 | AJ32: 13 | AK32: 1445 | AL32: =AK32/AJ32 -> 111.15385 | AM32: =RANK(AL32, $AL$30:$AL$47) -> 4 | AO32: 13 | AP32: 1881 | AQ32: =AP32/AO32 -> 144.69231 | AR32: =RANK(AQ32,$AQ$30:$AQ$47) -> 3 | AT32: 13 | AU32: 1866 | AV32: =AU32/AT32 -> 143.53846 | AW32: =RANK(AV32, $AV$30:$AV$47) -> 3
C33: 4 | D33: 焗烤起司雙饗筆尖麵 | E33: =VLOOKUP(D33,'11產線配置圖'!$A$2:$C$25,2,0) -> 18 | F33: =VLOOKUP(D33,'11產線配置圖'!$A$2:$C$25,3,0) -> 1565 | G33: =F33/E33 -> 86.944444 | I33: =AVERAGE(P33,U33,Z33,AE33,AJ33,AO33,AT33) -> 17.571429 | J33: =AVERAGE(Q33,V33,AA33,AF33,AK33,AP33,AU33) -> 1477.7143 | K33: =AVERAGE(R33,W33,AB33,AG33,AL33,AQ33,AV33) -> 84.103641 | M33: =RANK(K33, K$30:$K$47) -> 6 | P33: 18 | Q33: 1538 | R33: =Q33/P33 -> 85.444444 | S33: =RANK(R33,$R$30:$R$47) -> 7 | U33: 17 | V33: 1441 | W33: =V33/U33 -> 84.764706 | X33: =RANK(W33, $W$30:$W$47) -> 6 | Z33: 17 | AA33: 1487 | AB33: =AA33/Z33 -> 87.470588 | AC33: =RANK(AB33, $AB$30:$AB$47) -> 6 | AE33: 18 | AF33: 1526 | AG33: =AF33/AE33 -> 84.777778 | AH33: =RANK(AG33, $AG$30:$AG$47) -> 7 | AJ33: 17 | AK33: 1374 | AL33: =AK33/AJ33 -> 80.823529 | AM33: =RANK(AL33, $AL$30:$AL$47) -> 8 | AO33: 18 | AP33: 1561 | AQ33: =AP33/AO33 -> 86.722222 | AR33: =RANK(AQ33,$AQ$30:$AQ$47) -> 7 | AT33: 18 | AU33: 1417 | AV33: =AU33/AT33 -> 78.722222 | AW33: =RANK(AV33, $AV$30:$AV$47) -> 11
C34: 5 | D34: 白酒蛤蜊義大利麵 | E34: =VLOOKUP(D34,'11產線配置圖'!$A$2:$C$25,2,0) -> 13 | F34: =VLOOKUP(D34,'11產線配置圖'!$A$2:$C$25,3,0) -> 2000 | G34: =F34/E34 -> 153.84615 | I34: =AVERAGE(P34,U34,Z34,AE34,AJ34,AO34,AT34) -> 13 | J34: =AVERAGE(Q34,V34,AA34,AF34,AK34,AP34,AU34) -> 1730.1429 | K34: =AVERAGE(R34,W34,AB34,AG34,AL34,AQ34,AV34) -> 133.08791 | M34: =RANK(K34, K$30:$K$47) -> 4 | P34: 13 | Q34: 1726 | R34: =Q34/P34 -> 132.76923 | S34: =RANK(R34,$R$30:$R$47) -> 4 | U34: 13 | V34: 1742 | W34: =V34/U34 -> 134 | X34: =RANK(W34, $W$30:$W$47) -> 3 | Z34: 13 | AA34: 1840 | AB34: =AA34/Z34 -> 141.53846 | AC34: =RANK(AB34, $AB$30:$AB$47) -> 2 | AE34: 13 | AF34: 1646 | AG34: =AF34/AE34 -> 126.61538 | AH34: =RANK(AG34, $AG$30:$AG$47) -> 4 | AJ34: 13 | AK34: 1558 | AL34: =AK34/AJ34 -> 119.84615 | AM34: =RANK(AL34, $AL$30:$AL$47) -> 3 | AO34: 13 | AP34: 1804 | AQ34: =AP34/AO34 -> 138.76923 | AR34: =RANK(AQ34,$AQ$30:$AQ$47) -> 4 | AT34: 13 | AU34: 1795 | AV34: =AU34/AT34 -> 138.07692 | AW34: =RANK(AV34, $AV$30:$AV$47) -> 4
C35: 6 | D35: 韓式起司炸雞義大利麵 | E35: =VLOOKUP(D35,'11產線配置圖'!$A$2:$C$25,2,0) -> 14 | F35: =VLOOKUP(D35,'11產線配置圖'!$A$2:$C$25,3,0) -> 1895 | G35: =F35/E35 -> 135.35714 | I35: =AVERAGE(P35,U35,Z35,AE35,AJ35,AO35,AT35) -> 17 | J35: =AVERAGE(Q35,V35,AA35,AF35,AK35,AP35,AU35) -> 1599.8571 | K35: =AVERAGE(R35,W35,AB35,AG35,AL35,AQ35,AV35) -> 94.109244 | M35: =RANK(K35, K$30:$K$47) -> 5 | P35: 17 | Q35: 1525 | R35: =Q35/P35 -> 89.705882 | S35: =RANK(R35,$R$30:$R$47) -> 6 | U35: 17 | V35: 1612 | W35: =V35/U35 -> 94.823529 | X35: =RANK(W35, $W$30:$W$47) -> 5 | Z35: 17 | AA35: 1773 | AB35: =AA35/Z35 -> 104.29412 | AC35: =RANK(AB35, $AB$30:$AB$47) -> 5 | AE35: 17 | AF35: 1623 | AG35: =AF35/AE35 -> 95.470588 | AH35: =RANK(AG35, $AG$30:$AG$47) -> 5 | AJ35: 17 | AK35: 1621 | AL35: =AK35/AJ35 -> 95.352941 | AM35: =RANK(AL35, $AL$30:$AL$47) -> 5 | AO35: 17 | AP35: 1288 | AQ35: =AP35/AO35 -> 75.764706 | AR35: =RANK(AQ35,$AQ$30:$AQ$47) -> 11 | AT35: 17 | AU35: 1757 | AV35: =AU35/AT35 -> 103.35294 | AW35: =RANK(AV35, $AV$30:$AV$47) -> 5
C36: 7 | D36: 焗烤明太子筆尖麵 | E36: =VLOOKUP(D36,'11產線配置圖'!$A$2:$C$25,2,0) -> 17 | F36: =VLOOKUP(D36,'11產線配置圖'!$A$2:$C$25,3,0) -> 1385 | G36: =F36/E36 -> 81.470588 | I36: =AVERAGE(P36,U36,Z36,AE36,AJ36,AO36,AT36) -> 14.285714 | J36: =AVERAGE(Q36,V36,AA36,AF36,AK36,AP36,AU36) -> 1090.1429 | K36: =AVERAGE(R36,W36,AB36,AG36,AL36,AQ36,AV36) -> 76.508582 | M36: =RANK(K36, K$30:$K$47) -> 10 | P36: 14 | Q36: 934 | R36: =Q36/P36 -> 66.714286 | S36: =RANK(R36,$R$30:$R$47) -> 10 | U36: 15 | V36: 907 | W36: =V36/U36 -> 60.466667 | X36: =RANK(W36, $W$30:$W$47) -> 12 | Z36: 15 | AA36: 1112 | AB36: =AA36/Z36 -> 74.133333 | AC36: =RANK(AB36, $AB$30:$AB$47) -> 9 | AE36: 15 | AF36: 1183 | AG36: =AF36/AE36 -> 78.866667 | AH36: =RANK(AG36, $AG$30:$AG$47) -> 9 | AJ36: 13 | AK36: 1044 | AL36: =AK36/AJ36 -> 80.307692 | AM36: =RANK(AL36, $AL$30:$AL$47) -> 9 | AO36: 14 | AP36: 1199 | AQ36: =AP36/AO36 -> 85.642857 | AR36: =RANK(AQ36,$AQ$30:$AQ$47) -> 8 | AT36: 14 | AU36: 1252 | AV36: =AU36/AT36 -> 89.428571 | AW36: =RANK(AV36, $AV$30:$AV$47) -> 6
C37: 8 | D37: 奶油蒜香雞義大利麵 | E37: =VLOOKUP(D37,'11產線配置圖'!$A$2:$C$25,2,0) -> 18 | F37: =VLOOKUP(D37,'11產線配置圖'!$A$2:$C$25,3,0) -> 1385 | G37: =F37/E37 -> 76.944444 | I37: =AVERAGE(P37,U37,Z37,AE37,AJ37,AO37,AT37) -> 15.142857 | J37: =AVERAGE(Q37,V37,AA37,AF37,AK37,AP37,AU37) -> 1015.7143 | K37: =AVERAGE(R37,W37,AB37,AG37,AL37,AQ37,AV37) -> 67.339159 | M37: =RANK(K37, K$30:$K$47) -> 12 | P37: 16 | Q37: 1063 | R37: =Q37/P37 -> 66.4375 | S37: =RANK(R37,$R$30:$R$47) -> 11 | U37: 16 | V37: 929 | W37: =V37/U37 -> 58.0625 | X37: =RANK(W37, $W$30:$W$47) -> 13 | Z37: 13 | AA37: 944 | AB37: =AA37/Z37 -> 72.615385 | AC37: =RANK(AB37, $AB$30:$AB$47) -> 11 | AE37: 18 | AF37: 1187 | AG37: =AF37/AE37 -> 65.944444 | AH37: =RANK(AG37, $AG$30:$AG$47) -> 13 | AJ37: 15 | AK37: 1059 | AL37: =AK37/AJ37 -> 70.6 | AM37: =RANK(AL37, $AL$30:$AL$47) -> 12 | AO37: 14 | AP37: 1023 | AQ37: =AP37/AO37 -> 73.071429 | AR37: =RANK(AQ37,$AQ$30:$AQ$47) -> 12 | AT37: 14 | AU37: 905 | AV37: =AU37/AT37 -> 64.642857 | AW37: =RANK(AV37, $AV$30:$AV$47) -> 13
C38: 9 | D38: 青花椒麻雞肉拌麵 | E38: =VLOOKUP(D38,'11產線配置圖'!$A$2:$C$25,2,0) -> 17 | F38: =VLOOKUP(D38,'11產線配置圖'!$A$2:$C$25,3,0) -> 1565 | G38: =F38/E38 -> 92.058824 | I38: =AVERAGE(P38,U38,Z38,AE38,AJ38,AO38,AT38) -> 15.571429 | J38: =AVERAGE(Q38,V38,AA38,AF38,AK38,AP38,AU38) -> 1203.2857 | K38: =AVERAGE(R38,W38,AB38,AG38,AL38,AQ38,AV38) -> 77.214876 | M38: =RANK(K38, K$30:$K$47) -> 8 | P38: 16 | Q38: 1304 | R38: =Q38/P38 -> 81.5 | S38: =RANK(R38,$R$30:$R$47) -> 8 | U38: 16 | V38: 972 | W38: =V38/U38 -> 60.75 | X38: =RANK(W38, $W$30:$W$47) -> 11 | Z38: 15 | AA38: 1071 | AB38: =AA38/Z38 -> 71.4 | AC38: =RANK(AB38, $AB$30:$AB$47) -> 12 | AE38: 15 | AF38: 1121 | AG38: =AF38/AE38 -> 74.733333 | AH38: =RANK(AG38, $AG$30:$AG$47) -> 10 | AJ38: 14 | AK38: 1164 | AL38: =AK38/AJ38 -> 83.142857 | AM38: =RANK(AL38, $AL$30:$AL$47) -> 7 | AO38: 17 | AP38: 1485 | AQ38: =AP38/AO38 -> 87.352941 | AR38: =RANK(AQ38,$AQ$30:$AQ$47) -> 5 | AT38: 16 | AU38: 1306 | AV38: =AU38/AT38 -> 81.625 | AW38: =RANK(AV38, $AV$30:$AV$47) -> 9
C39: 10 | D39: 剝皮辣椒雞奶油扁麵 | E39: =VLOOKUP(D39,'11產線配置圖'!$A$2:$C$25,2,0) -> 17 | F39: =VLOOKUP(D39,'11產線配置圖'!$A$2:$C$25,3,0) -> 1500 | G39: =F39/E39 -> 88.235294 | I39: =AVERAGE(P39,U39,Z39,AE39,AJ39,AO39,AT39) -> 17.714286 | J39: =AVERAGE(Q39,V39,AA39,AF39,AK39,AP39,AU39) -> 1359.8571 | K39: =AVERAGE(R39,W39,AB39,AG39,AL39,AQ39,AV39) -> 76.800638 | M39: =RANK(K39, K$30:$K$47) -> 9 | P39: 18 | Q39: 1244 | R39: =Q39/P39 -> 69.111111 | S39: =RANK(R39,$R$30:$R$47) -> 9 | U39: 17 | V39: 1312 | W39: =V39/U39 -> 77.176471 | X39: =RANK(W39, $W$30:$W$47) -> 8 | Z39: 16 | AA39: 1233 | AB39: =AA39/Z39 -> 77.0625 | AC39: =RANK(AB39, $AB$30:$AB$47) -> 8 | AE39: 18 | AF39: 1455 | AG39: =AF39/AE39 -> 80.833333 | AH39: =RANK(AG39, $AG$30:$AG$47) -> 8 | AJ39: 17 | AK39: 1360 | AL39: =AK39/AJ39 -> 80 | AM39: =RANK(AL39, $AL$30:$AL$47) -> 10 | AO39: 19 | AP39: 1556 | AQ39: =AP39/AO39 -> 81.894737 | AR39: =RANK(AQ39,$AQ$30:$AQ$47) -> 10 | AT39: 19 | AU39: 1359 | AV39: =AU39/AT39 -> 71.526316 | AW39: =RANK(AV39, $AV$30:$AV$47) -> 12
C40: 11 | D40: 濃拿坡里義大利麵 | E40: =VLOOKUP(D40,'11產線配置圖'!$A$2:$C$25,2,0) -> 15 | F40: =VLOOKUP(D40,'11產線配置圖'!$A$2:$C$25,3,0) -> 1440 | G40: =F40/E40 -> 96 | I40: =AVERAGE(P40,U40,Z40,AE40,AJ40,AO40,AT40) -> 14 | J40: =AVERAGE(Q40,V40,AA40,AF40,AK40,AP40,AU40) -> 927.14286 | K40: =AVERAGE(R40,W40,AB40,AG40,AL40,AQ40,AV40) -> 66.424804 | M40: =RANK(K40, K$30:$K$47) -> 13 | P40: 14 | Q40: 814 | R40: =Q40/P40 -> 58.142857 | S40: =RANK(R40,$R$30:$R$47) -> 12 | U40: 15 | V40: 924 | W40: =V40/U40 -> 61.6 | X40: =RANK(W40, $W$30:$W$47) -> 10 | Z40: 15 | AA40: 963 | AB40: =AA40/Z40 -> 64.2 | AC40: =RANK(AB40, $AB$30:$AB$47) -> 13 | AE40: 15 | AF40: 1017 | AG40: =AF40/AE40 -> 67.8 | AH40: =RANK(AG40, $AG$30:$AG$47) -> 12 | AJ40: 13 | AK40: 842 | AL40: =AK40/AJ40 -> 64.769231 | AM40: =RANK(AL40, $AL$30:$AL$47) -> 13 | AO40: 13 | AP40: 862 | AQ40: =AP40/AO40 -> 66.307692 | AR40: =RANK(AQ40,$AQ$30:$AQ$47) -> 13 | AT40: 13 | AU40: 1068 | AV40: =AU40/AT40 -> 82.153846 | AW40: =RANK(AV40, $AV$30:$AV$47) -> 8
...

Sheet （５-2）品群別人時生產性(季節調理麵) 
B1: 月平均人時性 | C1: =AVERAGE(L7,L27,L47,L67,L87) -> #DIV/0!
B2: 產線配置圖－每週更新 | N2: 資料繳交 | O2: 日期 | AE2: 45870 | AJ2: 45871 | AO2: 45872 | AT2: 45873
P3: 二 | U3: 三 | Z3: 四 | AE3: 五 | AJ3: 六 | AO3: 日 | AT3: 一
B4: 品群 | C4: 商品名稱 | E4: 計畫 | H4: 平均人時性 | I4: 實績 | L4: 平均人時性 | M4: 排名 | O4: 日報 | P4: 實際 | T4: 平均人時性 | U4: 實際 | Y4: 平均人時性 | Z4: 實際 | AD4: 平均人時性 | AE4: 實際 | AI4: 平均人時性 | AJ4: 實際 | AN4: 平均人時性 | AO4: 實際 | AS4: 平均人時性 | AT4: 實際 | AX4: 平均人時性
E5: 產線配置圖 | I5: 產線配置圖 | P5: 生產實績 | U5: 生產實績 | Z5: 生產實績 | AE5: 生產實績 | AJ5: 生產實績 | AO5: 生產實績 | AT5: 生產實績
E6: 人數 | F6: 產能／時 | G6: 人時性 | I6: 人數 | J6: 產能／時 | K6: 人時性 | P6: 人數 | Q6: 產能／時 | R6: 人時性 | S6: 排名 | U6: 人數 | V6: 產能／時 | W6: 人時性 | X6: 排名 | Z6: 人數 | AA6: 產能／時 | AB6: 人時性 | AC6: 排名 | AE6: 人數 | AF6: 產能／時 | AG6: 人時性 | AH6: 排名 | AJ6: 人數 | AK6: 產能／時 | AL6: 人時性 | AM6: 排名 | AO6: 人數 | AP6: 產能／時 | AQ6: 人時性 | AR6: 排名 | AT6: 人數 | AU6: 產能／時 | AV6: 人時性 | AW6: 排名
B7: 熱食調理麵 | C7: 1 | H7: =AVERAGE(G7:G21) -> #DIV/0! | I7: =AVERAGE(P7,U7,Z7,AE7,AJ7,AO7,AT7) -> #DIV/0! | J7: =AVERAGE(Q7,V7,AA7,AF7,AK7,AP7,AU7) -> #DIV/0! | K7: =AVERAGE(R7,W7,AB7,AG7,AL7,AQ7,AV7) -> #DIV/0! | L7: =AVERAGE(K7:K21) -> #DIV/0! | M7: =RANK(K7, K$7:$K$21) -> #DIV/0! | S7: =RANK(R7, R$7:R$21) -> #N/A | T7: =AVERAGE(R7:R21) -> #DIV/0! | X7: =RANK(W7, W$7:W$21) -> #N/A | Y7: =AVERAGE(W7:W21) -> #DIV/0! | AC7: =RANK(AB7, AB$7:AB$21) -> #N/A | AD7: =AVERAGE(AB7:AB21) -> #DIV/0! | AH7: =RANK(AG7, AG$7:AG$21) -> #N/A | AI7: =AVERAGE(AG7:AG21) -> #DIV/0! | AM7: =RANK(AL7, AL$7:AL$21) -> #N/A | AN7: =AVERAGE(AL7:AL21) -> #DIV/0! | AR7: =RANK(AQ7, AQ$7:AQ$21) -> #N/A | AS7: =AVERAGE(AQ7:AQ21) -> #DIV/0! | AW7: =RANK(AV7, AV$7:AV$21) -> #N/A | AX7: =AVERAGE(AV7:AV21) -> #DIV/0!
C8: 2 | I8: =AVERAGE(P8,U8,Z8,AE8,AJ8,AO8,AT8) -> #DIV/0! | J8: =AVERAGE(Q8,V8,AA8,AF8,AK8,AP8,AU8) -> #DIV/0! | K8: =AVERAGE(R8,W8,AB8,AG8,AL8,AQ8,AV8) -> #DIV/0! | M8: =RANK(K8, K$7:$K$21) -> #DIV/0! | S8: =RANK(R8, R$7:R$21) -> #N/A | X8: =RANK(W8, W$7:W$21) -> #N/A | AC8: =RANK(AB8, AB$7:AB$21) -> #N/A | AH8: =RANK(AG8, AG$7:AG$21) -> #N/A | AM8: =RANK(AL8, AL$7:AL$21) -> #N/A | AR8: =RANK(AQ8, AQ$7:AQ$21) -> #N/A | AW8: =RANK(AV8, AV$7:AV$21) -> #N/A
C9: 3 | I9: =AVERAGE(P9,U9,Z9,AE9,AJ9,AO9,AT9) -> #DIV/0! | J9: =AVERAGE(Q9,V9,AA9,AF9,AK9,AP9,AU9) -> #DIV/0! | K9: =AVERAGE(R9,W9,AB9,AG9,AL9,AQ9,AV9) -> #DIV/0! | M9: =RANK(K9, K$7:$K$21) -> #DIV/0! | S9: =RANK(R9, R$7:R$21) -> #N/A | X9: =RANK(W9, W$7:W$21) -> #N/A | AC9: =RANK(AB9, AB$7:AB$21) -> #N/A | AH9: =RANK(AG9, AG$7:AG$21) -> #N/A | AM9: =RANK(AL9, AL$7:AL$21) -> #N/A | AR9: =RANK(AQ9, AQ$7:AQ$21) -> #N/A | AW9: =RANK(AV9, AV$7:AV$21) -> #N/A
C10: 4 | I10: =AVERAGE(P10,U10,Z10,AE10,AJ10,AO10,AT10) -> #DIV/0! | J10: =AVERAGE(Q10,V10,AA10,AF10,AK10,AP10,AU10) -> #DIV/0! | K10: =AVERAGE(R10,W10,AB10,AG10,AL10,AQ10,AV10) -> #DIV/0! | M10: =RANK(K10, K$7:$K$21) -> #DIV/0! | S10: =RANK(R10, R$7:R$21) -> #N/A | X10: =RANK(W10, W$7:W$21) -> #N/A | AC10: =RANK(AB10, AB$7:AB$21) -> #N/A | AH10: =RANK(AG10, AG$7:AG$21) -> #N/A | AM10: =RANK(AL10, AL$7:AL$21) -> #N/A | AR10: =RANK(AQ10, AQ$7:AQ$21) -> #N/A | AW10: =RANK(AV10, AV$7:AV$21) -> #N/A
C11: 5 | I11: =AVERAGE(P11,U11,Z11,AE11,AJ11,AO11,AT11) -> #DIV/0! | J11: =AVERAGE(Q11,V11,AA11,AF11,AK11,AP11,AU11) -> #DIV/0! | K11: =AVERAGE(R11,W11,AB11,AG11,AL11,AQ11,AV11) -> #DIV/0! | M11: =RANK(K11, K$7:$K$21) -> #DIV/0! | S11: =RANK(R11, R$7:R$21) -> #N/A | X11: =RANK(W11, W$7:W$21) -> #N/A | AC11: =RANK(AB11, AB$7:AB$21) -> #N/A | AH11: =RANK(AG11, AG$7:AG$21) -> #N/A | AM11: =RANK(AL11, AL$7:AL$21) -> #N/A | AR11: =RANK(AQ11, AQ$7:AQ$21) -> #N/A | AW11: =RANK(AV11, AV$7:AV$21) -> #N/A
C12: 6 | I12: =AVERAGE(P12,U12,Z12,AE12,AJ12,AO12,AT12) -> #DIV/0! | J12: =AVERAGE(Q12,V12,AA12,AF12,AK12,AP12,AU12) -> #DIV/0! | K12: =AVERAGE(R12,W12,AB12,AG12,AL12,AQ12,AV12) -> #DIV/0! | M12: =RANK(K12, K$7:$K$21) -> #DIV/0! | S12: =RANK(R12, R$7:R$21) -> #N/A | X12: =RANK(W12, W$7:W$21) -> #N/A | AC12: =RANK(AB12, AB$7:AB$21) -> #N/A | AH12: =RANK(AG12, AG$7:AG$21) -> #N/A | AM12: =RANK(AL12, AL$7:AL$21) -> #N/A | AR12: =RANK(AQ12, AQ$7:AQ$21) -> #N/A | AW12: =RANK(AV12, AV$7:AV$21) -> #N/A
C13: 7 | I13: =AVERAGE(P13,U13,Z13,AE13,AJ13,AO13,AT13) -> #DIV/0! | J13: =AVERAGE(Q13,V13,AA13,AF13,AK13,AP13,AU13) -> #DIV/0! | K13: =AVERAGE(R13,W13,AB13,AG13,AL13,AQ13,AV13) -> #DIV/0! | M13: =RANK(K13, K$7:$K$21) -> #DIV/0! | S13: =RANK(R13, R$7:R$21) -> #N/A | X13: =RANK(W13, W$7:W$21) -> #N/A | AC13: =RANK(AB13, AB$7:AB$21) -> #N/A | AH13: =RANK(AG13, AG$7:AG$21) -> #N/A | AM13: =RANK(AL13, AL$7:AL$21) -> #N/A | AR13: =RANK(AQ13, AQ$7:AQ$21) -> #N/A | AW13: =RANK(AV13, AV$7:AV$21) -> #N/A
C14: 8 | I14: =AVERAGE(P14,U14,Z14,AE14,AJ14,AO14,AT14) -> #DIV/0! | J14: =AVERAGE(Q14,V14,AA14,AF14,AK14,AP14,AU14) -> #DIV/0! | K14: =AVERAGE(R14,W14,AB14,AG14,AL14,AQ14,AV14) -> #DIV/0! | M14: =RANK(K14, K$7:$K$21) -> #DIV/0! | S14: =RANK(R14, R$7:R$21) -> #N/A | X14: =RANK(W14, W$7:W$21) -> #N/A | AC14: =RANK(AB14, AB$7:AB$21) -> #N/A | AH14: =RANK(AG14, AG$7:AG$21) -> #N/A | AM14: =RANK(AL14, AL$7:AL$21) -> #N/A | AR14: =RANK(AQ14, AQ$7:AQ$21) -> #N/A | AW14: =RANK(AV14, AV$7:AV$21) -> #N/A
C15: 9 | I15: =AVERAGE(P15,U15,Z15,AE15,AJ15,AO15,AT15) -> #DIV/0! | J15: =AVERAGE(Q15,V15,AA15,AF15,AK15,AP15,AU15) -> #DIV/0! | K15: =AVERAGE(R15,W15,AB15,AG15,AL15,AQ15,AV15) -> #DIV/0! | M15: =RANK(K15, K$7:$K$21) -> #DIV/0! | S15: =RANK(R15, R$7:R$21) -> #N/A | X15: =RANK(W15, W$7:W$21) -> #N/A | AC15: =RANK(AB15, AB$7:AB$21) -> #N/A | AH15: =RANK(AG15, AG$7:AG$21) -> #N/A | AM15: =RANK(AL15, AL$7:AL$21) -> #N/A | AR15: =RANK(AQ15, AQ$7:AQ$21) -> #N/A | AW15: =RANK(AV15, AV$7:AV$21) -> #N/A
C16: 10 | I16: =AVERAGE(P16,U16,Z16,AE16,AJ16,AO16,AT16) -> #DIV/0! | J16: =AVERAGE(Q16,V16,AA16,AF16,AK16,AP16,AU16) -> #DIV/0! | K16: =AVERAGE(R16,W16,AB16,AG16,AL16,AQ16,AV16) -> #DIV/0! | M16: =RANK(K16, K$7:$K$21) -> #DIV/0! | S16: =RANK(R16, R$7:R$21) -> #N/A | X16: =RANK(W16, W$7:W$21) -> #N/A | AC16: =RANK(AB16, AB$7:AB$21) -> #N/A | AH16: =RANK(AG16, AG$7:AG$21) -> #N/A | AM16: =RANK(AL16, AL$7:AL$21) -> #N/A | AR16: =RANK(AQ16, AQ$7:AQ$21) -> #N/A | AW16: =RANK(AV16, AV$7:AV$21) -> #N/A
C17: 11 | M17: =RANK(K17, K$7:$K$21) -> #DIV/0! | S17: =RANK(R17, R$7:R$21) -> #N/A | X17: =RANK(W17, W$7:W$21) -> #N/A | AC17: =RANK(AB17, AB$7:AB$21) -> #N/A | AH17: =RANK(AG17, AG$7:AG$21) -> #N/A | AM17: =RANK(AL17, AL$7:AL$21) -> #N/A | AR17: =RANK(AQ17, AQ$7:AQ$21) -> #N/A | AW17: =RANK(AV17, AV$7:AV$21) -> #N/A
C18: 12 | M18: =RANK(K18, K$7:$K$21) -> #DIV/0! | S18: =RANK(R18, R$7:R$21) -> #N/A | X18: =RANK(W18, W$7:W$21) -> #N/A | AC18: =RANK(AB18, AB$7:AB$21) -> #N/A | AH18: =RANK(AG18, AG$7:AG$21) -> #N/A | AM18: =RANK(AL18, AL$7:AL$21) -> #N/A | AR18: =RANK(AQ18, AQ$7:AQ$21) -> #N/A | AW18: =RANK(AV18, AV$7:AV$21) -> #N/A
C19: 13 | M19: =RANK(K19, K$7:$K$21) -> #DIV/0! | S19: =RANK(R19, R$7:R$21) -> #N/A | X19: =RANK(W19, W$7:W$21) -> #N/A | AC19: =RANK(AB19, AB$7:AB$21) -> #N/A | AH19: =RANK(AG19, AG$7:AG$21) -> #N/A | AM19: =RANK(AL19, AL$7:AL$21) -> #N/A | AR19: =RANK(AQ19, AQ$7:AQ$21) -> #N/A | AW19: =RANK(AV19, AV$7:AV$21) -> #N/A
C20: 14 | M20: =RANK(K20, K$7:$K$21) -> #DIV/0! | S20: =RANK(R20, R$7:R$21) -> #N/A | X20: =RANK(W20, W$7:W$21) -> #N/A | AC20: =RANK(AB20, AB$7:AB$21) -> #N/A | AH20: =RANK(AG20, AG$7:AG$21) -> #N/A | AM20: =RANK(AL20, AL$7:AL$21) -> #N/A | AR20: =RANK(AQ20, AQ$7:AQ$21) -> #N/A | AW20: =RANK(AV20, AV$7:AV$21) -> #N/A
C21: 15 | M21: =RANK(K21, K$7:$K$21) -> #DIV/0! | S21: =RANK(R21, R$7:R$21) -> #N/A | X21: =RANK(W21, W$7:W$21) -> #N/A | AC21: =RANK(AB21, AB$7:AB$21) -> #N/A | AH21: =RANK(AG21, AG$7:AG$21) -> #N/A | AM21: =RANK(AL21, AL$7:AL$21) -> #N/A | AR21: =RANK(AQ21, AQ$7:AQ$21) -> #N/A | AW21: =RANK(AV21, AV$7:AV$21) -> #N/A
B22: 產線配置圖－每週更新 | N22: 資料繳交 | O22: 日期 | P22: 45874 | U22: 45875 | Z22: 45876 | AE22: 45877 | AJ22: 45878 | AO22: 45879 | AT22: 45880
P23: 二 | U23: 三 | Z23: 四 | AE23: 五 | AJ23: 六 | AO23: 日 | AT23: 一
B24: 品群 | C24: 商品名稱 | E24: 計畫 | H24: 平均人時性 | I24: 實績 | L24: 平均人時性 | M24: 排名 | O24: 日報 | P24: 實際 | T24: 平均人時性 | U24: 實際 | Y24: 平均人時性 | Z24: 實際 | AD24: 平均人時性 | AE24: 實際 | AI24: 平均人時性 | AJ24: 實際 | AN24: 平均人時性 | AO24: 實際 | AS24: 平均人時性 | AT24: 實際 | AX24: 平均人時性
E25: 產線配置圖 | I25: 產線配置圖 | P25: 生產實績 | U25: 生產實績 | Z25: 生產實績 | AE25: 生產實績 | AJ25: 生產實績 | AO25: 生產實績 | AT25: 生產實績
E26: 人數 | F26: 產能／時 | G26: 人時性 | I26: 人數 | J26: 產能／時 | K26: 人時性 | P26: 人數 | Q26: 產能／時 | R26: 人時性 | S26: 排名 | U26: 人數 | V26: 產能／時 | W26: 人時性 | X26: 排名 | Z26: 人數 | AA26: 產能／時 | AB26: 人時性 | AC26: 排名 | AE26: 人數 | AF26: 產能／時 | AG26: 人時性 | AH26: 排名 | AJ26: 人數 | AK26: 產能／時 | AL26: 人時性 | AM26: 排名 | AO26: 人數 | AP26: 產能／時 | AQ26: 人時性 | AR26: 排名 | AT26: 人數 | AU26: 產能／時 | AV26: 人時性 | AW26: 排名
B27: 季節調理麵 | C27: 1 | H27: =AVERAGE(G27:G41) -> #DIV/0! | I27: =AVERAGE(P27,U27,Z27,AE27,AJ27,AO27,AT27) -> #DIV/0! | J27: =AVERAGE(Q27,V27,AA27,AF27,AK27,AP27,AU27) -> #DIV/0! | K27: =AVERAGE(R27,W27,AB27,AG27,AL27,AQ27,AV27) -> #DIV/0! | L27: =AVERAGE(K27:K41) -> #DIV/0! | M27: =RANK(K27, K$27:$K$41) -> #DIV/0! | T27: =AVERAGE(R27:R41) -> #DIV/0! | Y27: =AVERAGE(W27:W41) -> #DIV/0! | AD27: =AVERAGE(AB27:AB41) -> #DIV/0! | AI27: =AVERAGE(AG27:AG41) -> #DIV/0! | AN27: =AVERAGE(AL27:AL41) -> #DIV/0! | AS27: =AVERAGE(AQ27:AQ41) -> #DIV/0! | AX27: =AVERAGE(AV27:AV41) -> #DIV/0!
C28: 2 | I28: =AVERAGE(P28,U28,Z28,AE28,AJ28,AO28,AT28) -> #DIV/0! | J28: =AVERAGE(Q28,V28,AA28,AF28,AK28,AP28,AU28) -> #DIV/0! | K28: =AVERAGE(R28,W28,AB28,AG28,AL28,AQ28,AV28) -> #DIV/0! | M28: =RANK(K28, K$27:$K$41) -> #DIV/0!
C29: 3 | I29: =AVERAGE(P29,U29,Z29,AE29,AJ29,AO29,AT29) -> #DIV/0! | J29: =AVERAGE(Q29,V29,AA29,AF29,AK29,AP29,AU29) -> #DIV/0! | K29: =AVERAGE(R29,W29,AB29,AG29,AL29,AQ29,AV29) -> #DIV/0! | M29: =RANK(K29, K$27:$K$41) -> #DIV/0!
C30: 4 | I30: =AVERAGE(P30,U30,Z30,AE30,AJ30,AO30,AT30) -> #DIV/0! | J30: =AVERAGE(Q30,V30,AA30,AF30,AK30,AP30,AU30) -> #DIV/0! | K30: =AVERAGE(R30,W30,AB30,AG30,AL30,AQ30,AV30) -> #DIV/0! | M30: =RANK(K30, K$27:$K$41) -> #DIV/0!
C31: 5 | I31: =AVERAGE(P31,U31,Z31,AE31,AJ31,AO31,AT31) -> #DIV/0! | J31: =AVERAGE(Q31,V31,AA31,AF31,AK31,AP31,AU31) -> #DIV/0! | K31: =AVERAGE(R31,W31,AB31,AG31,AL31,AQ31,AV31) -> #DIV/0! | M31: =RANK(K31, K$27:$K$41) -> #DIV/0!
C32: 6 | I32: =AVERAGE(P32,U32,Z32,AE32,AJ32,AO32,AT32) -> #DIV/0! | J32: =AVERAGE(Q32,V32,AA32,AF32,AK32,AP32,AU32) -> #DIV/0! | K32: =AVERAGE(R32,W32,AB32,AG32,AL32,AQ32,AV32) -> #DIV/0! | M32: =RANK(K32, K$27:$K$41) -> #DIV/0!
C33: 7 | I33: =AVERAGE(P33,U33,Z33,AE33,AJ33,AO33,AT33) -> #DIV/0! | J33: =AVERAGE(Q33,V33,AA33,AF33,AK33,AP33,AU33) -> #DIV/0! | K33: =AVERAGE(R33,W33,AB33,AG33,AL33,AQ33,AV33) -> #DIV/0! | M33: =RANK(K33, K$27:$K$41) -> #DIV/0!
C34: 8 | I34: =AVERAGE(P34,U34,Z34,AE34,AJ34,AO34,AT34) -> #DIV/0! | J34: =AVERAGE(Q34,V34,AA34,AF34,AK34,AP34,AU34) -> #DIV/0! | K34: =AVERAGE(R34,W34,AB34,AG34,AL34,AQ34,AV34) -> #DIV/0! | M34: =RANK(K34, K$27:$K$41) -> #DIV/0!
C35: 9 | I35: =AVERAGE(P35,U35,Z35,AE35,AJ35,AO35,AT35) -> #DIV/0! | J35: =AVERAGE(Q35,V35,AA35,AF35,AK35,AP35,AU35) -> #DIV/0! | K35: =AVERAGE(R35,W35,AB35,AG35,AL35,AQ35,AV35) -> #DIV/0! | M35: =RANK(K35, K$27:$K$41) -> #DIV/0!
C36: 10 | I36: =AVERAGE(P36,U36,Z36,AE36,AJ36,AO36,AT36) -> #DIV/0! | J36: =AVERAGE(Q36,V36,AA36,AF36,AK36,AP36,AU36) -> #DIV/0! | K36: =AVERAGE(R36,W36,AB36,AG36,AL36,AQ36,AV36) -> #DIV/0! | M36: =RANK(K36, K$27:$K$41) -> #DIV/0!
C37: 11 | M37: =RANK(K37, K$27:$K$41) -> #DIV/0!
C38: 12 | M38: =RANK(K38, K$27:$K$41) -> #DIV/0!
C39: 13 | M39: =RANK(K39, K$27:$K$41) -> #DIV/0!
C40: 14 | M40: =RANK(K40, K$27:$K$41) -> #DIV/0!
...

Sheet 生產管理報表 6-1(週)
A1: 生產管理報表
A3: （６）人時生產性前幾名品項
A5: 品群 | B5: 1 | C5: 2 | D5: 3
B6: 熱食義麵 | C6: 季節調理麵 | D6: 微波小吃
A7: 品群 | C7: 排名 | D7: 商品名 | G7: 人數 | H7: 產能 | I7: 人時生產性 | J7: 前月比 | K7: 主要原因&對策
A8: 1 | B8: 熱食義麵 | C8: 1 | D8: 義式蕃茄起司義大利麵 | G8: 12 | H8: 1811 | I8: 151.8 | J8: 1.027
C9: 2 | D9: 青醬蛤蜊義大利麵 | G9: 13 | H9: 1893 | I9: 145.6 | J9: 1.099
C10: 3 | D10: 白酒蛤蜊義大利麵 | G10: 13 | H10: 1762 | I10: 135.6 | J10: 1.072
C11: 4 | D11: 奶油培根義大利麵 | G11: 13 | H11: 1791 | I11: 135.2 | J11: 0.979
C12: 5 | D12: 奶油起司蝦仁通心粉 | G12: 14 | H12: 1395 | I12: 96.8 | J12: 1.131 | K12: 轉自動一線生產，人員補齊
C13: ▼1 | D13: 沙茶豬肉炒麵 | G13: 15 | H13: 1024 | I13: 68.3 | K13: 人員不足
C14: ▼2 | D14: 府城鹽水意麵 | G14: 15 | H14: 1100 | I14: 71.7 | K14: 人員不足
C15: ▼3 | D15: 奶油蒜香雞義大利麵 | G15: 15 | H15: 1133 | I15: 74.1 | J15: 1.06
C16: ▼4 | D16: 剝皮辣椒雞奶油扁麵 | G16: 19 | H16: 1419 | I16: 75.2 | J16: 0.93
C17: ▼5 | D17: 焗烤起司肉醬筆尖麵 | G17: 11 | H17: 851 | I17: 75.7 | K17: 新品,人員不足
A18: 品群 | C18: 排名 | D18: 商品名 | G18: 人數 | H18: 產能 | I18: 人時生產性 | J18: 前月比 | K18: 主要原因&對策
A19: 2 | B19: 季節調理麵 | C19: 1
C20: 2
C21: 3
C22: 4
C23: 5
C24: ▼1
C25: ▼2
C26: ▼3
C27: ▼4
C28: ▼5
