Workbook

Sheet 生產管理報表(週) 
A1: 長家廠生產管理報表
A3: 月別 | B3: 11 | C3: 週別 | D3: W23 | E3: 工廠 | F3: 長家廠
A4: （１）收支狀況 | E4: ※單位：千元 | G4: （２）ＫＰＩ達成進度
A5: 項目 | B5: 當週 | C5: 前週 | D5: 差異 | E5: 累計 | G5: 項目 | H5: KPI | I5: 當週 | J5: 前週 | K5: 累計 | L5: ※補充
A6: 業績金額 | B6: 16910.8 | C6: 17347.5 | D6: =B6-C6 -> -436.7 | E6: 59929.5 | G6: 人時性(個/月均) | H6: 113 | I6: 102.3 | J6: 102.5 | K6: 101.7 | L6: 個／MH
A7: 訂單數量 | B7: 354039 | C7: 365747 | D7: =B7-C7 -> -11708 | E7: 1260014 | G7: 人時達成率(%/月均) | H7: 0.8 | I7: =I6/H6 -> 0.90530973 | J7: =J6/H6 -> 0.90707965 | K7: =K6/H6 -> 0.9 | L7: 達成率
A8: 材料費 | B8: 10655 | C8: 10927.4 | D8: =B8-C8 -> -272.4 | E8: 37772.7 | G8: 半成品-報廢(%) | H8: 0.0025 | I8: 0.003 | J8: 0.0026 | K8: 0.0024 | L8: 報廢率
A9: 材料費率 | B9: =B8/B6 -> 0.63007072 | C9: =C8/C6 -> 0.62991209 | D9: =B9-C9 -> 0.00015863295 | E9: =E8/E6 -> 0.63028559 | G9: 半成品-超用(%) | H9: 0.0025 | I9: 0.0009 | J9: 0.0028 | K9: 0.0022 | L9: 超用率
A10: 勞務成本 | D10: =B10-C10 -> 0 | G10: 固定產線-導入率(%) | H10: 1 | I10: 0.429 | J10: 0.429 | K10: 0.429 | L10: 導入率
A11: 勞務費率 | D11: =B11-C11 -> 0 | G11: 教育訓練-實施率(%) | H11: 1 | I11: 0.9 | J11: 0.9 | K11: 0.894 | L11: 實施率
A13: （３）業績構成比 | G13: （４）訂單數量構成比
B14: 當週 | C14: 比例 | D14: 前週 | E14: 差異 | H14: 當週 | I14: 比例 | J14: 前週 | K14: 差異
A15: 熱食義麵(122,123,124,126) | B15: 15522.2 | C15: =B15/B6 -> 0.91788679 | D15: 0.9164 | E15: =IFERROR(C15-D15,"") -> 0.0014867942 | G15: 熱食義麵(122,123,124,126) | H15: 303669 | I15: =IFERROR(H15/$B$7,"") -> 0.85772754 | J15: 0.8562 | K15: =IFERROR(I15-J15,"") -> 0.0015275385
A16: 季節調理麵(111,112) | C16: =IFERROR(B16/$B$6,"") -> 0 | D16: 0 | E16: =IFERROR(C16-D16,"") -> 0 | G16: 季節調理麵(111,112) | I16: =IFERROR(H16/$B$7,"") -> 0 | J16: 0 | K16: =IFERROR(I16-J16,"") -> 0
A17: 微波小吃(153,154,155) | B17: 1388.5 | C17: =B17/B6 -> 0.082107292 | D17: 0.0836 | E17: =IFERROR(C17-D17,"") -> -0.0014927076 | G17: 微波小吃(153,154,155) | H17: 50370 | I17: =IFERROR(H17/$B$7,"") -> 0.14227246 | J17: 0.1438 | K17: =IFERROR(I17-J17,"") -> -0.0015275385
C18: =SUM(C15:C17) -> 0.99999409 | D18: =SUM(D15:D17) -> 1 | I18: =SUM(I15:I17) -> 1 | J18: =SUM(J15:J17) -> 1
A20: （５）品群別人時生產性
A21: 品群 | B21: 當週 | C21: 前週 | D21: 差異 | E21: 累計
A22: 熱食義麵(122,123,124,126) | B22: 99.4 | C22: 100.8 | D22: =B22-C22 -> -1.4 | E22: 100.3
A23: 季節調理麵(111,112) | D23: =B23-C23 -> 0
A24: 微波小吃(153,154,155) | B24: 109 | C24: 113.2 | D24: =B24-C24 -> -4.2 | E24: 111.7

Sheet （１）收支狀況
B2: （１）收支狀況
B3: 資料繳交日 | C3: 月份 | D3: 日期 | F3: 營業額(元) | I3: 訂單數量(個) | L3: 材料費(元) | O3: 材料費率（材料費／營業額） | R3: 勞務成本（全廠人事成本） | U3: 勞務費率（勞務成本／營業額）
F4: 日 | G4: 週累積 | H4: 月累積 | I4: 日 | J4: 週累積 | K4: 月累積 | L4: 日 | M4: 週累積 | N4: 月累積 | O4: 日 | P4: 週累積 | Q4: 月累積 | R4: 日 | S4: 週累積 | T4: 月累積 | U4: 日 | V4: 週累積 | W4: 月累積
C5: 十一 | D5: 45962 | E5: 六 | F5: 2264329.1 | H5: =SUM(F5:F35) -> 59929511 | I5: 47648 | K5: =SUM(I5:I34) -> 1260014 | L5: 1430695 | N5: =SUM(L5:L34) -> 37772746 | O5: =L5/F5 -> 0.63184057 | Q5: =N5/H5 -> 0.63028624 | S5: =SUM(R5) -> 0 | T5: =SUM(R5:R33) -> 0 | U5: =R5/F5 -> 0 | V5: =SUM(U5) -> 0 | W5: =T5/H5 -> 0
D6: 45963 | E6: 日 | F6: 3123033.5 | I6: 65527 | L6: 1971002 | O6: =L6/F6 -> 0.63111779 | S6: =SUM(R6:R12) -> 0 | U6: =R6/F6 -> 0 | V6: =SUM(U6:U12) -> 0
D7: 45964 | E7: 一 | F7: 2673556.9 | I7: 56473 | L7: 1685565 | O7: =L7/F7 -> 0.63045787 | U7: =R7/F7 -> 0
B8: 45973 | D8: 45965 | E8: 二 | F8: 2527418.3 | G8: =SUM(F8:F14) -> 17610222 | I8: 53251 | J8: =SUM(I8:I14) -> 370580 | L8: 1594646 | M8: =SUM(L8:L14) -> 11103030 | O8: =L8/F8 -> 0.6309387 | P8: =M8/G8 -> 0.63048781 | U8: =R8/F8 -> 0
D9: 45966 | E9: 三 | F9: 2528793.2 | I9: 53267 | L9: 1594646 | O9: =L9/F9 -> 0.63059565 | U9: =R9/F9 -> 0
D10: 45967 | E10: 四 | F10: 2482738.1 | I10: 52136 | L10: 1565778 | O10: =L10/F10 -> 0.63066579 | U10: =R10/F10 -> 0
D11: 45968 | E11: 五 | F11: 2173366.7 | I11: 45764 | L11: 1370695 | O11: =L11/F11 -> 0.63067819 | U11: =R11/F11 -> 0
D12: 45969 | E12: 六 | F12: 2234998.1 | I12: 47070 | L12: 1408695 | O12: =L12/F12 -> 0.63028913 | U12: =R12/F12 -> 0
D13: 45970 | E13: 日 | F13: 2858713.4 | I13: 60100 | L13: 1801005 | O13: =L13/F13 -> 0.63000544 | S13: =SUM(R13:R19) -> 0 | U13: =R13/F13 -> 0 | V13: =SUM(U13:U19) -> 0
D14: 45971 | E14: 一 | F14: 2804193.7 | I14: 58992 | L14: 1767565 | O14: =L14/F14 -> 0.63032915 | U14: =R14/F14 -> 0
B15: 45980 | D15: 45972 | E15: 二 | F15: 2660726.3 | G15: =SUM(F15:F21) -> 17347543 | I15: 56087 | J15: =SUM(I15:I21) -> 365747 | L15: 1675565 | M15: =SUM(L15:L21) -> 10927428 | O15: =L15/F15 -> 0.62973971 | P15: =M15/G15 -> 0.62991214 | U15: =R15/F15 -> 0
D16: 45973 | E16: 三 | F16: 2790787.2 | I16: 58816 | L16: 1757565 | O16: =L16/F16 -> 0.62977391 | U16: =R16/F16 -> 0
D17: 45974 | E17: 四 | F17: 2510222.5 | I17: 52853 | L17: 1580778 | O17: =L17/F17 -> 0.6297362 | U17: =R17/F17 -> 0
D18: 45975 | E18: 五 | F18: 2068483 | I18: 43532 | L18: 1303695 | O18: =L18/F18 -> 0.63026624 | U18: =R18/F18 -> 0
D19: 45976 | E19: 六 | F19: 2006658 | I19: 42341 | L19: 1263695 | O19: =L19/F19 -> 0.62975105 | U19: =R19/F19 -> 0
D20: 45977 | E20: 日 | F20: 2660160.4 | I20: 56127 | L20: 1675565 | O20: =L20/F20 -> 0.62987368 | S20: =SUM(R20:R26) -> 0 | U20: =R20/F20 -> 0 | V20: =SUM(U20:U26) -> 0
D21: 45978 | E21: 一 | F21: 2650505.6 | I21: 55991 | L21: 1670565 | O21: =L21/F21 -> 0.63028163 | U21: =R21/F21 -> 0
B22: 45987 | D22: 45979 | E22: 二 | F22: 2921128 | G22: =SUM(F22:F28) -> 16910827 | I22: 60555 | J22: =SUM(I22:I28) -> 354039 | L22: 1840005 | M22: =SUM(L22:L28) -> 10655026 | O22: =L22/F22 -> 0.62989536 | P22: =M22/G22 -> 0.63007126 | U22: =R22/F22 -> 0
D23: 45980 | E23: 三 | F23: 2664581.2 | I23: 55596 | L23: 1679565 | O23: =L23/F23 -> 0.63032982 | U23: =R23/F23 -> 0
D24: 45981 | E24: 四 | F24: 2302855.1 | I24: 48162 | L24: 1449855 | O24: =L24/F24 -> 0.62959021 | U24: =R24/F24 -> 0
D25: 45982 | E25: 五 | F25: 1818810.1 | I25: 38475 | L25: 1146695 | O25: =L25/F25 -> 0.63046438 | U25: =R25/F25 -> 0
D26: 45983 | E26: 六 | F26: 1959163.5 | I26: 41274 | L26: 1233695 | O26: =L26/F26 -> 0.62970498 | U26: =R26/F26 -> 0
D27: 45984 | E27: 日 | F27: 2710208.8 | I27: 56648 | L27: 1708565 | O27: =L27/F27 -> 0.63041823 | S27: =SUM(R27:R33) -> 0 | U27: =R27/F27 -> 0 | V27: =SUM(U27:U33) -> #DIV/0!
D28: 45985 | E28: 一 | F28: 2534080.2 | I28: 53329 | L28: 1596646 | O28: =L28/F28 -> 0.63006925 | U28: =R28/F28 -> 0
B29: 45994 | D29: 45986 | E29: 二 | G29: =SUM(F29:F35) -> 0 | J29: =SUM(I29:I35) -> 0 | M29: =SUM(L29:L35) -> 0 | O29: =L29/F29 -> #DIV/0! | P29: =M29/G29 -> #DIV/0! | U29: =R29/F29 -> #DIV/0!
D30: 45987 | E30: 三 | O30: =L30/F30 -> #DIV/0! | U30: =R30/F30 -> #DIV/0!
D31: 45988 | E31: 四 | O31: =L31/F31 -> #DIV/0! | U31: =R31/F31 -> #DIV/0!
D32: 45989 | E32: 五 | O32: =L32/F32 -> #DIV/0! | U32: =R32/F32 -> #DIV/0!
D33: 45990 | E33: 六 | O33: =L33/F33 -> #DIV/0! | U33: =R33/F33 -> #DIV/0!
D34: 45991 | E34: 日 | O34: =L34/F34 -> #DIV/0! | U34: =R34/F34 -> #DIV/0!
D35: 45992 | E35: 一 | U35: =R35/F35 -> #DIV/0!
S37: =SUM(R37:R43) -> 0 | V37: =SUM(U37:U43) -> 0

Sheet （２）ＫＰＩ達成進度
C1: 112.8
B2: （２）ＫＰＩ達成進度
B3: 資料繳交日 | C3: 月份 | D3: 日期 | F3: 人時生產性(個/人) | I3: 人時生產性達成率(%) | L3: 半成品報廢(%) | O3: 半成品超用(%) | R3: 固定產線-導入率(固定產線數/總產線數) | U3: 教育訓練-實施率(進度/計畫)
F4: 日 | G4: 週平均 | H4: 月平均 | I4: 日 | J4: 週平均 | K4: 月平均 | L4: 日 | M4: 週平均 | N4: 月平均 | O4: 日 | P4: 週平均 | Q4: 月平均 | R4: 日 | S4: 週平均 | T4: 月平均 | U4: 日 | V4: 週平均 | W4: 月平均
C5: 十一 | D5: 45962 | E5: 六 | F5: 93.6 | H5: =AVERAGE(F5:F34) -> 101.69583 | I5: =F5/$C$1 -> 0.82978723 | K5: =AVERAGE(I5:I34) -> 0.72124704 | L5: 0.00062932549 | N5: =AVERAGE(L5:L34) -> 0.0024460919 | O5: 0.0042922206 | Q5: =AVERAGE(O5:O34) -> 0.0021817314 | R5: 0.429 | T5: =AVERAGE(R5:R34) -> 0.429 | U5: 0.85 | W5: =AVERAGE(U5:U34) -> 0.89375
D6: 45963 | E6: 日 | F6: 102.7 | I6: =F6/$C$1 -> 0.91046099 | L6: 0.0023505992 | O6: 0.0037162586 | R6: 0.429 | U6: 0.85
D7: 45964 | E7: 一 | F7: 102.2 | I7: =F7/$C$1 -> 0.90602837 | L7: 0.011514623 | O7: 0.0087808117 | R7: 0.429 | U7: 0.85
B8: 45973 | D8: 45965 | E8: 二 | F8: 103 | G8: =AVERAGE(F8:F14) -> 101.21429 | I8: =F8/$C$1 -> 0.91312057 | J8: =AVERAGE(I8:I14) -> 0.89728977 | L8: 0.0018125215 | M8: =AVERAGE(L8:L14) -> 0.00070247025 | O8: 0.0045955986 | P8: =AVERAGE(O8:O14) -> 0.0014565599 | R8: 0.429 | S8: =AVERAGE(R8:R14) -> 0.429 | U8: 0.9 | V8: =AVERAGE(U8:U14) -> 0.9
D9: 45966 | E9: 三 | F9: 103.9 | I9: =F9/$C$1 -> 0.92109929 | L9: 0 | O9: 5.7339603e-05 | R9: 0.429 | U9: 0.9
D10: 45967 | E10: 四 | F10: 98.9 | I10: =F10/$C$1 -> 0.87677305 | L10: 0.0006843251 | O10: 0.001760959 | R10: 0.429 | U10: 0.9
D11: 45968 | E11: 五 | F11: 99.3 | I11: =F11/$C$1 -> 0.88031915 | L11: 0.00093541507 | O11: 0.0012285087 | R11: 0.429 | U11: 0.9
D12: 45969 | E12: 六 | F12: 101 | I12: =F12/$C$1 -> 0.89539007 | L12: 0.00073154425 | O12: 0.0015360192 | R12: 0.429 | U12: 0.9
D13: 45970 | E13: 日 | F13: 101.6 | I13: =F13/$C$1 -> 0.90070922 | L13: 0.00075348582 | O13: 0.00093083833 | R13: 0.429 | U13: 0.9
D14: 45971 | E14: 一 | F14: 100.8 | I14: =F14/$C$1 -> 0.89361702 | L14: 0 | O14: 8.6655927e-05 | R14: 0.429 | U14: 0.9
B15: 45980 | D15: 45972 | E15: 二 | F15: 100.2 | G15: =AVERAGE(F15:F21) -> 102.51429 | I15: =F15/$C$1 -> 0.88829787 | J15: =AVERAGE(I15:I21) -> 0.90881459 | L15: 0.0034167363 | M15: =AVERAGE(L15:L21) -> 0.0025746898 | O15: 0.0026774644 | P15: =AVERAGE(O15:O21) -> 0.0027603965 | R15: 0.429 | S15: =AVERAGE(R15:R21) -> 0.429 | U15: 0.9 | V15: =AVERAGE(U15:U21) -> 0.9
D16: 45973 | E16: 三 | F16: 104.5 | I16: =F16/$C$1 -> 0.92641844 | L16: 0.00099004322 | O16: 0.00033574756 | R16: 0.429 | U16: 0.9
D17: 45974 | E17: 四 | F17: 102.7 | I17: =F17/$C$1 -> 0.91046099 | L17: 0.0030650669 | O17: 0.0035275757 | R17: 0.429 | U17: 0.9
D18: 45975 | E18: 五 | F18: 98.8 | I18: =F18/$C$1 -> 0.87588652 | L18: 0.0063234747 | O18: 0.0096234776 | R18: 0.429 | U18: 0.9
D19: 45976 | E19: 六 | F19: 104.1 | I19: =F19/$C$1 -> 0.92287234 | L19: 0.0032561602 | O19: 0.00078289373 | R19: 0.429 | U19: 0.9
D20: 45977 | E20: 日 | F20: 103.5 | I20: =F20/$C$1 -> 0.91755319 | L20: 0.00087400746 | O20: 0.0019074038 | R20: 0.429 | U20: 0.9
D21: 45978 | E21: 一 | F21: 103.8 | I21: =F21/$C$1 -> 0.92021277 | L21: 9.7339918e-05 | O21: 0.00046821255 | R21: 0.429 | U21: 0.9
B22: 45987 | D22: 45979 | E22: 二 | F22: 104.4 | G22: =AVERAGE(F22:F28) -> 102.3 | I22: =F22/$C$1 -> 0.92553191 | J22: =AVERAGE(I22:I28) -> 0.90691489 | L22: 0.008609003 | M22: =AVERAGE(L22:L28) -> 0.003038791 | O22: 0.0023638129 | P22: =AVERAGE(O22:O28) -> 0.00086479546 | R22: 0.429 | S22: =AVERAGE(R22:R28) -> 0.429 | U22: 0.9 | V22: =AVERAGE(U22:U28) -> 0.9
D23: 45980 | E23: 三 | F23: 100.6 | I23: =F23/$C$1 -> 0.89184397 | L23: 0.0037859608 | O23: 0.00059746725 | R23: 0.429 | U23: 0.9
D24: 45981 | E24: 四 | F24: 102.8 | I24: =F24/$C$1 -> 0.91134752 | L24: 0.0028060819 | O24: 0.0014620981 | R24: 0.429 | U24: 0.9
D25: 45982 | E25: 五 | F25: 96.9 | I25: =F25/$C$1 -> 0.85904255 | L25: 0.0025527678 | O25: 0.00037607004 | R25: 0.429 | U25: 0.9
D26: 45983 | E26: 六 | F26: 100.5 | I26: =F26/$C$1 -> 0.89095745 | L26: 8.5750884e-05 | O26: 0.0003026802 | R26: 0.429 | U26: 0.9
D27: 45984 | E27: 日 | F27: 105.1 | I27: =F27/$C$1 -> 0.93173759 | L27: 0.0012213081 | O27: 0.00056194933 | R27: 0.429 | U27: 0.9
D28: 45985 | E28: 一 | F28: 105.8 | I28: =F28/$C$1 -> 0.93794326 | L28: 0.0022106641 | O28: 0.00038949044 | R28: 0.429 | U28: 0.9
B29: 45994 | D29: 45986 | E29: 二 | G29: =AVERAGE(F29:F35) -> #DIV/0! | I29: =F29/$C$1 -> 0 | J29: =AVERAGE(I29:I35) -> 0 | M29: =AVERAGE(L29:L35) -> #DIV/0! | P29: =AVERAGE(O29:O35) -> #DIV/0! | S29: =AVERAGE(R29:R35) -> #DIV/0! | V29: =AVERAGE(U29:U35) -> #DIV/0!
D30: 45987 | E30: 三 | I30: =F30/$C$1 -> 0
D31: 45988 | E31: 四 | I31: =F31/$C$1 -> 0
D32: 45989 | E32: 五 | I32: =F32/$C$1 -> 0
D33: 45990 | E33: 六 | I33: =F33/$C$1 -> 0
D34: 45991 | E34: 日 | I34: =F34/$C$1 -> 0
D35: 45992 | E35: 一 | I35: =F35/$C$1 -> 0
I36: =F36/$C$1 -> 0
G37: =AVERAGE(F37:F43) -> #DIV/0! | I37: =F37/$C$1 -> 0 | J37: =AVERAGE(I37:I43) -> 0 | M37: =AVERAGE(L37:L43) -> #DIV/0! | P37: =AVERAGE(O37:O43) -> #DIV/0! | S37: =AVERAGE(R37:R43) -> #DIV/0! | V37: =AVERAGE(U37:U43) -> #DIV/0!
I38: =F38/$C$1 -> 0
I39: =F39/$C$1 -> 0
I40: =F40/$C$1 -> 0
...

Sheet （３）業績構成比
B2: （3）業績構成比
B3: 資料繳交日 | C3: 月份 | D3: 日期 | F3: 營業額 | I3: 品類業績
I4: 熱食義麵 | K4: 季節調理麵 | M4: 微波小吃
F5: 日 | G5: 週累積 | H5: 月累積 | I5: 一配 | K5: 一配 | M5: 一配
I6: 業績(元) | J6: 比例(%) | K6: 業績(元) | L6: 比例(%) | M6: 業績(元) | N6: 比例(%)
C7: 十一 | D7: 45962 | E7: 六 | F7: =SUM(I7,K7,M7) -> 2264329.1 | H7: =SUM(F7:F36) -> 59929511 | I7: 2076011.4 | J7: =I7/F7 -> 0.91683288 | L7: =K7/F7 -> 0 | M7: 188317.73 | N7: =M7/F7 -> 0.083167121
D8: 45963 | E8: 日 | F8: =SUM(I8,K8,M8) -> 3123033.5 | I8: 2875684.5 | J8: =I8/F8 -> 0.92079849 | L8: =K8/F8 -> 0 | M8: 247348.95 | N8: =M8/F8 -> 0.079201505
D9: 45964 | E9: 一 | F9: =SUM(I9,K9,M9) -> 2673556.9 | I9: 2430499.5 | J9: =I9/F9 -> 0.90908837 | L9: =K9/F9 -> 0 | M9: 243057.43 | N9: =M9/F9 -> 0.090911635
B10: 45973 | D10: 45965 | E10: 二 | F10: =SUM(I10,K10,M10) -> 2527418.3 | G10: =SUM(F10:F16) -> 17610222 | I10: 2307469.9 | J10: =I10/F10 -> 0.91297507 | L10: =K10/F10 -> 0 | M10: 219948.41 | N10: =M10/F10 -> 0.087024934
D11: 45966 | E11: 三 | F11: =SUM(I11,K11,M11) -> 2528793.2 | I11: 2308154.6 | J11: =I11/F11 -> 0.91274942 | L11: =K11/F11 -> 0 | M11: 220638.67 | N11: =M11/F11 -> 0.087250578
D12: 45967 | E12: 四 | F12: =SUM(I12,K12,M12) -> 2482738.1 | I12: 2280236.8 | J12: =I12/F12 -> 0.91843631 | L12: =K12/F12 -> 0 | M12: 202501.29 | N12: =M12/F12 -> 0.081563693
D13: 45968 | E13: 五 | F13: =SUM(I13,K13,M13) -> 2173366.7 | I13: 1995602.4 | J13: =I13/F13 -> 0.91820785 | L13: =K13/F13 -> 0 | M13: 177764.34 | N13: =M13/F13 -> 0.081792151
D14: 45969 | E14: 六 | F14: =SUM(I14,K14,M14) -> 2234998.1 | I14: 2048061.4 | J14: =I14/F14 -> 0.91635938 | L14: =K14/F14 -> 0 | M14: 186936.63 | N14: =M14/F14 -> 0.083640622
D15: 45970 | E15: 日 | F15: =SUM(I15,K15,M15) -> 2858713.4 | I15: 2627998.3 | J15: =I15/F15 -> 0.91929409 | L15: =K15/F15 -> 0 | M15: 230715.06 | N15: =M15/F15 -> 0.080705908
D16: 45971 | E16: 一 | F16: =SUM(I16,K16,M16) -> 2804193.7 | I16: 2574252.6 | J16: =I16/F16 -> 0.918001 | L16: =K16/F16 -> 0 | M16: 229941.08 | N16: =M16/F16 -> 0.081999001
B17: 45980 | D17: 45972 | E17: 二 | F17: =SUM(I17,K17,M17) -> 2660726.3 | G17: =SUM(F17:F23) -> 17347543 | I17: 2437313.5 | J17: =I17/F17 -> 0.91603317 | L17: =K17/F17 -> 0 | M17: 223412.74 | N17: =M17/F17 -> 0.083966825
D18: 45973 | E18: 三 | F18: =SUM(I18,K18,M18) -> 2790787.2 | I18: 2560267.4 | J18: =I18/F18 -> 0.9173997 | L18: =K18/F18 -> 0 | M18: 230519.86 | N18: =M18/F18 -> 0.082600299
D19: 45974 | E19: 四 | F19: =SUM(I19,K19,M19) -> 2510222.5 | I19: 2303427.9 | J19: =I19/F19 -> 0.91761898 | L19: =K19/F19 -> 0 | M19: 206794.69 | N19: =M19/F19 -> 0.082381018
D20: 45975 | E20: 五 | F20: =SUM(I20,K20,M20) -> 2068483 | I20: 1898103.2 | J20: =I20/F20 -> 0.91763054 | L20: =K20/F20 -> 0 | M20: 170379.82 | N20: =M20/F20 -> 0.082369456
D21: 45976 | E21: 六 | F21: =SUM(I21,K21,M21) -> 2006658 | I21: 1833409.2 | J21: =I21/F21 -> 0.91366298 | L21: =K21/F21 -> 0 | M21: 173248.87 | N21: =M21/F21 -> 0.086337017
D22: 45977 | E22: 日 | F22: =SUM(I22,K22,M22) -> 2660160.4 | I22: 2437424.2 | J22: =I22/F22 -> 0.91626965 | L22: =K22/F22 -> 0 | M22: 222736.17 | N22: =M22/F22 -> 0.083730355
D23: 45978 | E23: 一 | F23: =SUM(I23,K23,M23) -> 2650505.6 | I23: 2426717.5 | J23: =I23/F23 -> 0.91556778 | L23: =K23/F23 -> 0 | M23: 223788.07 | N23: =M23/F23 -> 0.084432219
B24: 45987 | D24: 45979 | E24: 二 | F24: =SUM(I24,K24,M24) -> 2921128 | G24: =SUM(F24:F30) -> 16910827 | I24: 2707161.4 | J24: =I24/F24 -> 0.92675205 | L24: =K24/F24 -> 0 | M24: 213966.63 | N24: =M24/F24 -> 0.073247947
D25: 45980 | E25: 三 | F25: =SUM(I25,K25,M25) -> 2664581.2 | I25: 2454829.4 | J25: =I25/F25 -> 0.92128152 | L25: =K25/F25 -> 0 | M25: 209751.78 | N25: =M25/F25 -> 0.078718479
D26: 45981 | E26: 四 | F26: =SUM(I26,K26,M26) -> 2302855.1 | I26: 2106897.2 | J26: =I26/F26 -> 0.91490657 | L26: =K26/F26 -> 0 | M26: 195957.84 | N26: =M26/F26 -> 0.085093431
D27: 45982 | E27: 五 | F27: =SUM(I27,K27,M27) -> 1818810.1 | I27: 1647129.2 | J27: =I27/F27 -> 0.90560809 | L27: =K27/F27 -> 0 | M27: 171680.96 | N27: =M27/F27 -> 0.094391909
D28: 45983 | E28: 六 | F28: =SUM(I28,K28,M28) -> 1959163.5 | I28: 1784992 | J28: =I28/F28 -> 0.91109908 | L28: =K28/F28 -> 0 | M28: 174171.44 | N28: =M28/F28 -> 0.088900923
D29: 45984 | E29: 日 | F29: =SUM(I29,K29,M29) -> 2710208.8 | I29: 2496599.1 | J29: =I29/F29 -> 0.92118333 | L29: =K29/F29 -> 0 | M29: 213609.63 | N29: =M29/F29 -> 0.07881667
D30: 45985 | E30: 一 | F30: =SUM(I30,K30,M30) -> 2534080.2 | I30: 2324639.8 | J30: =I30/F30 -> 0.91735054 | L30: =K30/F30 -> 0 | M30: 209440.35 | N30: =M30/F30 -> 0.082649457
B31: 45994 | D31: 45986 | E31: 二 | F31: =SUM(I31,K31,M31) -> 0 | G31: =SUM(F31:F37) -> 0 | J31: =I31/F31 -> #DIV/0! | L31: =K31/F31 -> #DIV/0! | N31: =M31/F31 -> #DIV/0!
D32: 45987 | E32: 三 | F32: =SUM(I32,K32,M32) -> 0 | J32: =I32/F32 -> #DIV/0! | L32: =K32/F32 -> #DIV/0! | N32: =M32/F32 -> #DIV/0!
D33: 45988 | E33: 四 | F33: =SUM(I33,K33,M33) -> 0 | J33: =I33/F33 -> #DIV/0! | L33: =K33/F33 -> #DIV/0! | N33: =M33/F33 -> #DIV/0!
D34: 45989 | E34: 五 | F34: =SUM(I34,K34,M34) -> 0 | J34: =I34/F34 -> #DIV/0! | L34: =K34/F34 -> #DIV/0! | N34: =M34/F34 -> #DIV/0!
D35: 45990 | E35: 六 | F35: =SUM(I35,K35,M35) -> 0 | J35: =I35/F35 -> #DIV/0! | L35: =K35/F35 -> #DIV/0! | N35: =M35/F35 -> #DIV/0!
D36: 45991 | E36: 日 | F36: =SUM(I36,K36,M36) -> 0 | J36: =I36/F36 -> #DIV/0! | L36: =K36/F36 -> #DIV/0! | N36: =M36/F36 -> #DIV/0!
D37: 45992 | E37: 一 | F37: =SUM(I37,K37,M37) -> 0

Sheet （４）訂單數量構成比
B2: （4）訂單數量構成比
B3: 資料繳交日 | C3: 月份 | D3: 日期 | F3: 訂單量 | I3: 品類訂單量
I4: 熱食義麵 | K4: 季節調理麵 | M4: 微波小吃
F5: 日 | G5: 週累積 | H5: 月累積 | I5: 一配 | K5: 一配 | M5: 一配
I6: 訂單數 | J6: 比例(%) | K6: 訂單數 | L6: 比例(%) | M6: 訂單數 | N6: 比例(%)
C7: 十一 | D7: 45962 | E7: 六 | F7: =SUM(I7,K7,M7) -> 47648 | H7: =SUM(F7:F36) -> 1260014 | I7: 40826 | J7: =I7/F7 -> 0.85682505 | L7: =K7/F7 -> 0 | M7: 6822 | N7: =M7/F7 -> 0.14317495
D8: 45963 | E8: 日 | F8: =SUM(I8,K8,M8) -> 65527 | I8: 56546 | J8: =I8/F8 -> 0.86294199 | L8: =K8/F8 -> 0 | M8: 8981 | N8: =M8/F8 -> 0.13705801
D9: 45964 | E9: 一 | F9: =SUM(I9,K9,M9) -> 56473 | I9: 47653 | J9: =I9/F9 -> 0.84381917 | L9: =K9/F9 -> 0 | M9: 8820 | N9: =M9/F9 -> 0.15618083
B10: 45973 | D10: 45965 | E10: 二 | F10: =SUM(I10,K10,M10) -> 53251 | G10: =SUM(F10:F16) -> 370580 | I10: 45275 | J10: =I10/F10 -> 0.85021878 | L10: =K10/F10 -> 0 | M10: 7976 | N10: =M10/F10 -> 0.14978122
D11: 45966 | E11: 三 | F11: =SUM(I11,K11,M11) -> 53267 | I11: 45273 | J11: =I11/F11 -> 0.84992585 | L11: =K11/F11 -> 0 | M11: 7994 | N11: =M11/F11 -> 0.15007415
D12: 45967 | E12: 四 | F12: =SUM(I12,K12,M12) -> 52136 | I12: 44801 | J12: =I12/F12 -> 0.85931027 | L12: =K12/F12 -> 0 | M12: 7335 | N12: =M12/F12 -> 0.14068973
D13: 45968 | E13: 五 | F13: =SUM(I13,K13,M13) -> 45764 | I13: 39326 | J13: =I13/F13 -> 0.85932174 | L13: =K13/F13 -> 0 | M13: 6438 | N13: =M13/F13 -> 0.14067826
D14: 45969 | E14: 六 | F14: =SUM(I14,K14,M14) -> 47070 | I14: 40304 | J14: =I14/F14 -> 0.85625664 | L14: =K14/F14 -> 0 | M14: 6766 | N14: =M14/F14 -> 0.14374336
D15: 45970 | E15: 日 | F15: =SUM(I15,K15,M15) -> 60100 | I15: 51723 | J15: =I15/F15 -> 0.86061564 | L15: =K15/F15 -> 0 | M15: 8377 | N15: =M15/F15 -> 0.13938436
D16: 45971 | E16: 一 | F16: =SUM(I16,K16,M16) -> 58992 | I16: 50650 | J16: =I16/F16 -> 0.858591 | L16: =K16/F16 -> 0 | M16: 8342 | N16: =M16/F16 -> 0.141409
B17: 45980 | D17: 45972 | E17: 二 | F17: =SUM(I17,K17,M17) -> 56087 | G17: =SUM(F17:F23) -> 365747 | I17: 47983 | J17: =I17/F17 -> 0.85551019 | L17: =K17/F17 -> 0 | M17: 8104 | N17: =M17/F17 -> 0.14448981
D18: 45973 | E18: 三 | F18: =SUM(I18,K18,M18) -> 58816 | I18: 50457 | J18: =I18/F18 -> 0.85787881 | L18: =K18/F18 -> 0 | M18: 8359 | N18: =M18/F18 -> 0.14212119
D19: 45974 | E19: 四 | F19: =SUM(I19,K19,M19) -> 52853 | I19: 45358 | J19: =I19/F19 -> 0.85819159 | L19: =K19/F19 -> 0 | M19: 7495 | N19: =M19/F19 -> 0.14180841
D20: 45975 | E20: 五 | F20: =SUM(I20,K20,M20) -> 43532 | I20: 37360 | J20: =I20/F20 -> 0.85821924 | L20: =K20/F20 -> 0 | M20: 6172 | N20: =M20/F20 -> 0.14178076
D21: 45976 | E21: 六 | F21: =SUM(I21,K21,M21) -> 42341 | I21: 36066 | J21: =I21/F21 -> 0.85179849 | L21: =K21/F21 -> 0 | M21: 6275 | N21: =M21/F21 -> 0.14820151
D22: 45977 | E22: 日 | F22: =SUM(I22,K22,M22) -> 56127 | I22: 48040 | J22: =I22/F22 -> 0.85591605 | L22: =K22/F22 -> 0 | M22: 8087 | N22: =M22/F22 -> 0.14408395
D23: 45978 | E23: 一 | F23: =SUM(I23,K23,M23) -> 55991 | I23: 47872 | J23: =I23/F23 -> 0.85499455 | L23: =K23/F23 -> 0 | M23: 8119 | N23: =M23/F23 -> 0.14500545
B24: 45987 | D24: 45979 | E24: 二 | F24: =SUM(I24,K24,M24) -> 60555 | G24: =SUM(F24:F30) -> 354039 | I24: 52788 | J24: =I24/F24 -> 0.87173644 | L24: =K24/F24 -> 0 | M24: 7767 | N24: =M24/F24 -> 0.12826356
D25: 45980 | E25: 三 | F25: =SUM(I25,K25,M25) -> 55596 | I25: 47984 | J25: =I25/F25 -> 0.86308368 | L25: =K25/F25 -> 0 | M25: 7612 | N25: =M25/F25 -> 0.13691632
D26: 45981 | E26: 四 | F26: =SUM(I26,K26,M26) -> 48162 | I26: 41060 | J26: =I26/F26 -> 0.85253935 | L26: =K26/F26 -> 0 | M26: 7102 | N26: =M26/F26 -> 0.14746065
D27: 45982 | E27: 五 | F27: =SUM(I27,K27,M27) -> 38475 | I27: 32260 | J27: =I27/F27 -> 0.83846654 | L27: =K27/F27 -> 0 | M27: 6215 | N27: =M27/F27 -> 0.16153346
D28: 45983 | E28: 六 | F28: =SUM(I28,K28,M28) -> 41274 | I28: 34961 | J28: =I28/F28 -> 0.84704657 | L28: =K28/F28 -> 0 | M28: 6313 | N28: =M28/F28 -> 0.15295343
D29: 45984 | E29: 日 | F29: =SUM(I29,K29,M29) -> 56648 | I29: 48889 | J29: =I29/F29 -> 0.86303135 | L29: =K29/F29 -> 0 | M29: 7759 | N29: =M29/F29 -> 0.13696865
D30: 45985 | E30: 一 | F30: =SUM(I30,K30,M30) -> 53329 | I30: 45727 | J30: =I30/F30 -> 0.85745092 | L30: =K30/F30 -> 0 | M30: 7602 | N30: =M30/F30 -> 0.14254908
B31: 45994 | D31: 45986 | E31: 二 | F31: =SUM(I31,K31,M31) -> 0 | G31: =SUM(F31:F37) -> 0 | J31: =I31/F31 -> #DIV/0! | L31: =K31/F31 -> #DIV/0! | N31: =M31/F31 -> #DIV/0!
D32: 45987 | E32: 三 | F32: =SUM(I32,K32,M32) -> 0 | J32: =I32/F32 -> #DIV/0! | L32: =K32/F32 -> #DIV/0! | N32: =M32/F32 -> #DIV/0!
D33: 45988 | E33: 四 | F33: =SUM(I33,K33,M33) -> 0 | J33: =I33/F33 -> #DIV/0! | L33: =K33/F33 -> #DIV/0! | N33: =M33/F33 -> #DIV/0!
D34: 45989 | E34: 五 | F34: =SUM(I34,K34,M34) -> 0 | J34: =I34/F34 -> #DIV/0! | L34: =K34/F34 -> #DIV/0! | N34: =M34/F34 -> #DIV/0!
D35: 45990 | E35: 六 | F35: =SUM(I35,K35,M35) -> 0 | J35: =I35/F35 -> #DIV/0! | L35: =K35/F35 -> #DIV/0! | N35: =M35/F35 -> #DIV/0!
D36: 45991 | E36: 日 | F36: =SUM(I36,K36,M36) -> 0 | J36: =I36/F36 -> #DIV/0! | L36: =K36/F36 -> #DIV/0! | N36: =M36/F36 -> #DIV/0!
D37: 45992 | E37: 一 | F37: =SUM(I37,K37,M37) -> 0

Sheet （５-1）品群別人時生產性（熱食義麵）
B1: 月平均人時性 | C1: =AVERAGE(L7,L30,L53,L73,L96,L119) -> 100.31891
B2: 產線配置圖－每週更新 | N2: 資料繳交 | O2: 日期 | AJ2: 45962 | AO2: 45963 | AT2: 45964
P3: 二 | U3: 三 | Z3: 四 | AE3: 五 | AJ3: 六 | AO3: 日 | AT3: 一
B4: 品群 | C4: 商品名稱 | E4: 計畫 | H4: 平均人時性 | I4: 實績 | L4: 平均人時性 | M4: 排名 | O4: 日報 | P4: 實際 | T4: 平均人時性 | U4: 實際 | Y4: 平均人時性 | Z4: 實際 | AD4: 平均人時性 | AE4: 實際 | AI4: 平均人時性 | AJ4: 實際 | AN4: 平均人時性 | AO4: 實際 | AS4: 平均人時性 | AT4: 實際 | AX4: 平均人時性
E5: 產線配置圖 | I5: 產線配置圖 | P5: 生產實績 | U5: 生產實績 | Z5: 生產實績 | AE5: 生產實績 | AJ5: 生產實績 | AO5: 生產實績 | AT5: 生產實績
E6: 人數 | F6: 產能／時 | G6: 人時性 | I6: 人數 | J6: 產能／時 | K6: 人時性 | P6: 人數 | Q6: 產能／時 | R6: 人時性 | S6: 排名 | U6: 人數 | V6: 產能／時 | W6: 人時性 | X6: 排名 | Z6: 人數 | AA6: 產能／時 | AB6: 人時性 | AC6: 排名 | AE6: 人數 | AF6: 產能／時 | AG6: 人時性 | AH6: 排名 | AJ6: 人數 | AK6: 產能／時 | AL6: 人時性 | AM6: 排名 | AO6: 人數 | AP6: 產能／時 | AQ6: 人時性 | AR6: 排名 | AT6: 人數 | AU6: 產能／時 | AV6: 人時性 | AW6: 排名
B7: 熱食義麵 | C7: 1 | D7: 義式蕃茄起司義大利麵 | E7: =VLOOKUP(D7,'11產線配置圖'!$A$2:$C$25,2,0) -> 12 | F7: =VLOOKUP(D7,'11產線配置圖'!$A$2:$C$25,3,0) -> 2000 | G7: =F7/E7 -> 166.66667 | H7: =AVERAGE(G7:G24) -> 112.60546 | I7: =AVERAGE(AJ7,AO7,AT7) -> 12 | J7: =AVERAGE(AK7,AP7,AU7) -> 1672 | K7: =AVERAGE(AL7,AQ7,AV7) -> 139.33333 | L7: =IFERROR(AVERAGE(K7:K24),"-") -> 100.97297 | M7: =RANK(K7, K$7:$K$24) -> 2 | R7: =Q7/P7 -> #DIV/0! | S7: =RANK(R7, R$7:R$24) -> #DIV/0! | T7: =AVERAGE(R7:R24) -> #DIV/0! | W7: =V7/U7 -> #DIV/0! | X7: =RANK(W7, W$7:W$24) -> #DIV/0! | Y7: =AVERAGE(W7:W24) -> #DIV/0! | AB7: =AA7/Z7 -> #DIV/0! | AC7: =RANK(AB7, AB$7:AB$24) -> #DIV/0! | AD7: =AVERAGE(AB7:AB24) -> #DIV/0! | AG7: =AF7/AE7 -> #DIV/0! | AH7: =RANK(AG7, AG$7:AG$24) -> #DIV/0! | AI7: =AVERAGE(AG7:AG24) -> #DIV/0! | AJ7: 12 | AK7: 1529 | AL7: =AK7/AJ7 -> 127.41667 | AM7: =RANK(AL7, AL$7:AL$24) -> 3 | AN7: =AVERAGE(AL7:AL24) -> 97.046672 | AO7: 12 | AP7: 1865 | AQ7: =AP7/AO7 -> 155.41667 | AR7: =RANK(AQ7, AQ$7:AQ$24) -> 1 | AS7: =AVERAGE(AQ7:AQ24) -> 103.34742 | AT7: 12 | AU7: 1622 | AV7: =AU7/AT7 -> 135.16667 | AW7: =RANK(AV7, AV$7:AV$24) -> 2 | AX7: =AVERAGE(AV7:AV24) -> 104.62707
C8: 2 | D8: 奶油培根義大利麵 | E8: =VLOOKUP(D8,'11產線配置圖'!$A$2:$C$25,2,0) -> 13 | F8: =VLOOKUP(D8,'11產線配置圖'!$A$2:$C$25,3,0) -> 2000 | G8: =F8/E8 -> 153.84615 | I8: =AVERAGE(AJ8,AO8,AT8) -> 13 | J8: =AVERAGE(AK8,AP8,AU8) -> 1764.6667 | K8: =AVERAGE(AL8,AQ8,AV8) -> 135.74359 | M8: =RANK(K8, K$7:$K$24) -> 3 | R8: =Q8/P8 -> #DIV/0! | S8: =RANK(R8, R$7:R$24) -> #DIV/0! | W8: =V8/U8 -> #DIV/0! | X8: =RANK(W8, W$7:W$24) -> #DIV/0! | AB8: =AA8/Z8 -> #DIV/0! | AC8: =RANK(AB8, AB$7:AB$24) -> #DIV/0! | AG8: =AF8/AE8 -> #DIV/0! | AH8: =RANK(AG8, AG$7:AG$24) -> #DIV/0! | AJ8: 13 | AK8: 1835 | AL8: =AK8/AJ8 -> 141.15385 | AM8: =RANK(AL8, AL$7:AL$24) -> 2 | AO8: 13 | AP8: 1808 | AQ8: =AP8/AO8 -> 139.07692 | AR8: =RANK(AQ8, AQ$7:AQ$24) -> 3 | AT8: 13 | AU8: 1651 | AV8: =AU8/AT8 -> 127 | AW8: =RANK(AV8, AV$7:AV$24) -> 4
C9: 3 | D9: 青醬蛤蜊義大利麵 | E9: =VLOOKUP(D9,'11產線配置圖'!$A$2:$C$25,2,0) -> 15 | F9: =VLOOKUP(D9,'11產線配置圖'!$A$2:$C$25,3,0) -> 2000 | G9: =F9/E9 -> 133.33333 | I9: =AVERAGE(AJ9,AO9,AT9) -> 15 | J9: =AVERAGE(AK9,AP9,AU9) -> 1889 | K9: =AVERAGE(AL9,AQ9,AV9) -> 125.93333 | M9: =RANK(K9, K$7:$K$24) -> 5 | R9: =Q9/P9 -> #DIV/0! | S9: =RANK(R9, R$7:R$24) -> #DIV/0! | W9: =V9/U9 -> #DIV/0! | X9: =RANK(W9, W$7:W$24) -> #DIV/0! | AB9: =AA9/Z9 -> #DIV/0! | AC9: =RANK(AB9, AB$7:AB$24) -> #DIV/0! | AG9: =AF9/AE9 -> #DIV/0! | AH9: =RANK(AG9, AG$7:AG$24) -> #DIV/0! | AJ9: 15 | AK9: 1871 | AL9: =AK9/AJ9 -> 124.73333 | AM9: =RANK(AL9, AL$7:AL$24) -> 4 | AO9: 15 | AP9: 1910 | AQ9: =AP9/AO9 -> 127.33333 | AR9: =RANK(AQ9, AQ$7:AQ$24) -> 4 | AT9: 15 | AU9: 1886 | AV9: =AU9/AT9 -> 125.73333 | AW9: =RANK(AV9, AV$7:AV$24) -> 5
C10: 4 | D10: 焗烤起司雙饗筆尖麵 | E10: =VLOOKUP(D10,'11產線配置圖'!$A$2:$C$25,2,0) -> 18 | F10: =VLOOKUP(D10,'11產線配置圖'!$A$2:$C$25,3,0) -> 1565 | G10: =F10/E10 -> 86.944444 | I10: =AVERAGE(AJ10,AO10,AT10) -> 18 | J10: =AVERAGE(AK10,AP10,AU10) -> 1548.3333 | K10: =AVERAGE(AL10,AQ10,AV10) -> 86.018519 | M10: =RANK(K10, K$7:$K$24) -> 6 | R10: =Q10/P10 -> #DIV/0! | S10: =RANK(R10, R$7:R$24) -> #DIV/0! | W10: =V10/U10 -> #DIV/0! | X10: =RANK(W10, W$7:W$24) -> #DIV/0! | AB10: =AA10/Z10 -> #DIV/0! | AC10: =RANK(AB10, AB$7:AB$24) -> #DIV/0! | AG10: =AF10/AE10 -> #DIV/0! | AH10: =RANK(AG10, AG$7:AG$24) -> #DIV/0! | AJ10: 18 | AK10: 1536 | AL10: =AK10/AJ10 -> 85.333333 | AM10: =RANK(AL10, AL$7:AL$24) -> 6 | AO10: 18 | AP10: 1551 | AQ10: =AP10/AO10 -> 86.166667 | AR10: =RANK(AQ10, AQ$7:AQ$24) -> 6 | AT10: 18 | AU10: 1558 | AV10: =AU10/AT10 -> 86.555556 | AW10: =RANK(AV10, AV$7:AV$24) -> 7
C11: 5 | D11: 白酒蛤蜊義大利麵 | E11: =VLOOKUP(D11,'11產線配置圖'!$A$2:$C$25,2,0) -> 13 | F11: =VLOOKUP(D11,'11產線配置圖'!$A$2:$C$25,3,0) -> 2000 | G11: =F11/E11 -> 153.84615 | I11: =AVERAGE(AJ11,AO11,AT11) -> 13 | J11: =AVERAGE(AK11,AP11,AU11) -> 1915 | K11: =AVERAGE(AL11,AQ11,AV11) -> 147.30769 | M11: =RANK(K11, K$7:$K$24) -> 1 | R11: =Q11/P11 -> #DIV/0! | S11: =RANK(R11, R$7:R$24) -> #DIV/0! | W11: =V11/U11 -> #DIV/0! | X11: =RANK(W11, W$7:W$24) -> #DIV/0! | AB11: =AA11/Z11 -> #DIV/0! | AC11: =RANK(AB11, AB$7:AB$24) -> #DIV/0! | AG11: =AF11/AE11 -> #DIV/0! | AH11: =RANK(AG11, AG$7:AG$24) -> #DIV/0! | AJ11: 13 | AK11: 1890 | AL11: =AK11/AJ11 -> 145.38462 | AM11: =RANK(AL11, AL$7:AL$24) -> 1 | AO11: 13 | AP11: 1954 | AQ11: =AP11/AO11 -> 150.30769 | AR11: =RANK(AQ11, AQ$7:AQ$24) -> 2 | AT11: 13 | AU11: 1901 | AV11: =AU11/AT11 -> 146.23077 | AW11: =RANK(AV11, AV$7:AV$24) -> 1
C12: 6 | D12: 韓式起司炸雞義大利麵 | E12: =VLOOKUP(D12,'11產線配置圖'!$A$2:$C$25,2,0) -> 14 | F12: =VLOOKUP(D12,'11產線配置圖'!$A$2:$C$25,3,0) -> 1895 | G12: =F12/E12 -> 135.35714 | I12: =AVERAGE(AJ12,AO12,AT12) -> 14 | J12: =AVERAGE(AK12,AP12,AU12) -> 1764.3333 | K12: =AVERAGE(AL12,AQ12,AV12) -> 126.02381 | M12: =RANK(K12, K$7:$K$24) -> 4 | R12: =Q12/P12 -> #DIV/0! | S12: =RANK(R12, R$7:R$24) -> #DIV/0! | W12: =V12/U12 -> #DIV/0! | X12: =RANK(W12, W$7:W$24) -> #DIV/0! | AB12: =AA12/Z12 -> #DIV/0! | AC12: =RANK(AB12, AB$7:AB$24) -> #DIV/0! | AG12: =AF12/AE12 -> #DIV/0! | AH12: =RANK(AG12, AG$7:AG$24) -> #DIV/0! | AJ12: 14 | AK12: 1643 | AL12: =AK12/AJ12 -> 117.35714 | AM12: =RANK(AL12, AL$7:AL$24) -> 5 | AO12: 14 | AP12: 1779 | AQ12: =AP12/AO12 -> 127.07143 | AR12: =RANK(AQ12, AQ$7:AQ$24) -> 5 | AT12: 14 | AU12: 1871 | AV12: =AU12/AT12 -> 133.64286 | AW12: =RANK(AV12, AV$7:AV$24) -> 3
C13: 7 | D13: 焗烤明太子筆尖麵 | E13: =VLOOKUP(D13,'11產線配置圖'!$A$2:$C$25,2,0) -> 17 | F13: =VLOOKUP(D13,'11產線配置圖'!$A$2:$C$25,3,0) -> 1385 | G13: =F13/E13 -> 81.470588 | I13: =AVERAGE(AJ13,AO13,AT13) -> 15 | J13: =AVERAGE(AK13,AP13,AU13) -> 1015.6667 | K13: =AVERAGE(AL13,AQ13,AV13) -> 67.889881 | M13: =RANK(K13, K$7:$K$24) -> 12 | R13: =Q13/P13 -> #DIV/0! | S13: =RANK(R13, R$7:R$24) -> #DIV/0! | W13: =V13/U13 -> #DIV/0! | X13: =RANK(W13, W$7:W$24) -> #DIV/0! | AB13: =AA13/Z13 -> #DIV/0! | AC13: =RANK(AB13, AB$7:AB$24) -> #DIV/0! | AG13: =AF13/AE13 -> #DIV/0! | AH13: =RANK(AG13, AG$7:AG$24) -> #DIV/0! | AJ13: 16 | AK13: 925 | AL13: =AK13/AJ13 -> 57.8125 | AM13: =RANK(AL13, AL$7:AL$24) -> 12 | AO13: 14 | AP13: 922 | AQ13: =AP13/AO13 -> 65.857143 | AR13: =RANK(AQ13, AQ$7:AQ$24) -> 12 | AT13: 15 | AU13: 1200 | AV13: =AU13/AT13 -> 80 | AW13: =RANK(AV13, AV$7:AV$24) -> 9
C14: 8 | D14: 奶油蒜香雞義大利麵 | E14: =VLOOKUP(D14,'11產線配置圖'!$A$2:$C$25,2,0) -> 18 | F14: =VLOOKUP(D14,'11產線配置圖'!$A$2:$C$25,3,0) -> 1385 | G14: =F14/E14 -> 76.944444 | I14: =AVERAGE(AJ14,AO14,AT14) -> 16.666667 | J14: =AVERAGE(AK14,AP14,AU14) -> 1138 | K14: =AVERAGE(AL14,AQ14,AV14) -> 68.415033 | M14: =RANK(K14, K$7:$K$24) -> 11 | R14: =Q14/P14 -> #DIV/0! | S14: =RANK(R14, R$7:R$24) -> #DIV/0! | W14: =V14/U14 -> #DIV/0! | X14: =RANK(W14, W$7:W$24) -> #DIV/0! | AB14: =AA14/Z14 -> #DIV/0! | AC14: =RANK(AB14, AB$7:AB$24) -> #DIV/0! | AG14: =AF14/AE14 -> #DIV/0! | AH14: =RANK(AG14, AG$7:AG$24) -> #DIV/0! | AJ14: 17 | AK14: 1078 | AL14: =AK14/AJ14 -> 63.411765 | AM14: =RANK(AL14, AL$7:AL$24) -> 11 | AO14: 18 | AP14: 1251 | AQ14: =AP14/AO14 -> 69.5 | AR14: =RANK(AQ14, AQ$7:AQ$24) -> 11 | AT14: 15 | AU14: 1085 | AV14: =AU14/AT14 -> 72.333333 | AW14: =RANK(AV14, AV$7:AV$24) -> 11
C15: 9 | D15: 青花椒麻雞肉拌麵 | E15: =VLOOKUP(D15,'11產線配置圖'!$A$2:$C$25,2,0) -> 17 | F15: =VLOOKUP(D15,'11產線配置圖'!$A$2:$C$25,3,0) -> 1565 | G15: =F15/E15 -> 92.058824 | I15: =AVERAGE(AJ15,AO15,AT15) -> 16.333333 | J15: =AVERAGE(AK15,AP15,AU15) -> 1273.3333 | K15: =AVERAGE(AL15,AQ15,AV15) -> 78.162092 | M15: =RANK(K15, K$7:$K$24) -> 9 | R15: =Q15/P15 -> #DIV/0! | S15: =RANK(R15, R$7:R$24) -> #DIV/0! | W15: =V15/U15 -> #DIV/0! | X15: =RANK(W15, W$7:W$24) -> #DIV/0! | AB15: =AA15/Z15 -> #DIV/0! | AC15: =RANK(AB15, AB$7:AB$24) -> #DIV/0! | AG15: =AF15/AE15 -> #DIV/0! | AH15: =RANK(AG15, AG$7:AG$24) -> #DIV/0! | AJ15: 17 | AK15: 1275 | AL15: =AK15/AJ15 -> 75 | AM15: =RANK(AL15, AL$7:AL$24) -> 9 | AO15: 17 | AP15: 1298 | AQ15: =AP15/AO15 -> 76.352941 | AR15: =RANK(AQ15, AQ$7:AQ$24) -> 10 | AT15: 15 | AU15: 1247 | AV15: =AU15/AT15 -> 83.133333 | AW15: =RANK(AV15, AV$7:AV$24) -> 8
C16: 10 | D16: 剝皮辣椒雞奶油扁麵 | E16: =VLOOKUP(D16,'11產線配置圖'!$A$2:$C$25,2,0) -> 17 | F16: =VLOOKUP(D16,'11產線配置圖'!$A$2:$C$25,3,0) -> 1500 | G16: =F16/E16 -> 88.235294 | I16: =AVERAGE(AJ16,AO16,AT16) -> 17 | J16: =AVERAGE(AK16,AP16,AU16) -> 1424.6667 | K16: =AVERAGE(AL16,AQ16,AV16) -> 83.803922 | M16: =RANK(K16, K$7:$K$24) -> 7 | R16: =Q16/P16 -> #DIV/0! | S16: =RANK(R16, R$7:R$24) -> #DIV/0! | W16: =V16/U16 -> #DIV/0! | X16: =RANK(W16, W$7:W$24) -> #DIV/0! | AB16: =AA16/Z16 -> #DIV/0! | AC16: =RANK(AB16, AB$7:AB$24) -> #DIV/0! | AG16: =AF16/AE16 -> #DIV/0! | AH16: =RANK(AG16, AG$7:AG$24) -> #DIV/0! | AJ16: 17 | AK16: 1357 | AL16: =AK16/AJ16 -> 79.823529 | AM16: =RANK(AL16, AL$7:AL$24) -> 7 | AO16: 17 | AP16: 1434 | AQ16: =AP16/AO16 -> 84.352941 | AR16: =RANK(AQ16, AQ$7:AQ$24) -> 7 | AT16: 17 | AU16: 1483 | AV16: =AU16/AT16 -> 87.235294 | AW16: =RANK(AV16, AV$7:AV$24) -> 6
C17: 11 | D17: 濃拿坡里義大利麵 | E17: =VLOOKUP(D17,'11產線配置圖'!$A$2:$C$25,2,0) -> 15 | F17: =VLOOKUP(D17,'11產線配置圖'!$A$2:$C$25,3,0) -> 1440 | G17: =F17/E17 -> 96 | I17: =AVERAGE(AJ17,AO17,AT17) -> 15 | J17: =AVERAGE(AK17,AP17,AU17) -> 1104.6667 | K17: =AVERAGE(AL17,AQ17,AV17) -> 73.644444 | M17: =RANK(K17, K$7:$K$24) -> 10 | R17: =Q17/P17 -> #DIV/0! | S17: =RANK(R17, R$7:R$24) -> #DIV/0! | W17: =V17/U17 -> #DIV/0! | X17: =RANK(W17, W$7:W$24) -> #DIV/0! | AB17: =AA17/Z17 -> #DIV/0! | AC17: =RANK(AB17, AB$7:AB$24) -> #DIV/0! | AG17: =AF17/AE17 -> #DIV/0! | AH17: =RANK(AG17, AG$7:AG$24) -> #DIV/0! | AJ17: 15 | AK17: 1034 | AL17: =AK17/AJ17 -> 68.933333 | AM17: =RANK(AL17, AL$7:AL$24) -> 10 | AO17: 15 | AP17: 1172 | AQ17: =AP17/AO17 -> 78.133333 | AR17: =RANK(AQ17, AQ$7:AQ$24) -> 9 | AT17: 15 | AU17: 1108 | AV17: =AU17/AT17 -> 73.866667 | AW17: =RANK(AV17, AV$7:AV$24) -> 10
C18: 12 | D18: 奶油起司蝦仁通心粉 | E18: =VLOOKUP(D18,'11產線配置圖'!$A$2:$C$25,2,0) -> 16 | F18: =VLOOKUP(D18,'11產線配置圖'!$A$2:$C$25,3,0) -> 1385 | G18: =F18/E18 -> 86.5625 | I18: =AVERAGE(AJ18,AO18,AT18) -> 15 | J18: =AVERAGE(AK18,AP18,AU18) -> 1191 | K18: =AVERAGE(AL18,AQ18,AV18) -> 79.4 | M18: =RANK(K18, K$7:$K$24) -> 8 | R18: =Q18/P18 -> #DIV/0! | S18: =RANK(R18, R$7:R$24) -> #DIV/0! | W18: =V18/U18 -> #DIV/0! | X18: =RANK(W18, W$7:W$24) -> #DIV/0! | AB18: =AA18/Z18 -> #DIV/0! | AC18: =RANK(AB18, AB$7:AB$24) -> #DIV/0! | AG18: =AF18/AE18 -> #DIV/0! | AH18: =RANK(AG18, AG$7:AG$24) -> #DIV/0! | AJ18: 15 | AK18: 1173 | AL18: =AK18/AJ18 -> 78.2 | AM18: =RANK(AL18, AL$7:AL$24) -> 8 | AO18: 15 | AP18: 1209 | AQ18: =AP18/AO18 -> 80.6 | AR18: =RANK(AQ18, AQ$7:AQ$24) -> 8
C19: 13 | R19: =Q19/P19 -> #DIV/0! | S19: =RANK(R19, R$7:R$24) -> #DIV/0! | W19: =V19/U19 -> #DIV/0! | X19: =RANK(W19, W$7:W$24) -> #DIV/0! | AB19: =AA19/Z19 -> #DIV/0! | AC19: =RANK(AB19, AB$7:AB$24) -> #DIV/0! | AG19: =AF19/AE19 -> #DIV/0! | AH19: =RANK(AG19, AG$7:AG$24) -> #DIV/0!
C20: 14 | R20: =Q20/P20 -> #DIV/0! | S20: =RANK(R20, R$7:R$24) -> #DIV/0! | W20: =V20/U20 -> #DIV/0! | X20: =RANK(W20, W$7:W$24) -> #DIV/0! | AB20: =AA20/Z20 -> #DIV/0! | AC20: =RANK(AB20, AB$7:AB$24) -> #DIV/0! | AG20: =AF20/AE20 -> #DIV/0! | AH20: =RANK(AG20, AG$7:AG$24) -> #DIV/0!
C21: 15 | R21: =Q21/P21 -> #DIV/0! | S21: =RANK(R21, R$7:R$24) -> #DIV/0!
C22: 16 | R22: =Q22/P22 -> #DIV/0! | S22: =RANK(R22, R$7:R$24) -> #DIV/0!
C23: 17 | R23: =Q23/P23 -> #DIV/0! | S23: =RANK(R23, R$7:R$24) -> #DIV/0!
C24: 18 | R24: =Q24/P24 -> #DIV/0! | S24: =RANK(R24, R$7:R$24) -> #DIV/0!
B25: 產線配置圖－每週更新 | N25: 資料繳交 | O25: 日期 | P25: 45965 | U25: 45966 | Z25: 45967 | AE25: 45968 | AJ25: 45969 | AO25: 45970 | AT25: 45971
P26: 二 | U26: 三 | Z26: 四 | AE26: 五 | AJ26: 六 | AO26: 日 | AT26: 一
B27: 品群 | C27: 商品名稱 | E27: 計畫 | H27: 平均人時性 | I27: 實績 | L27: 平均人時性 | M27: 排名 | O27: 日報 | P27: 實際 | T27: 平均人時性 | U27: 實際 | Y27: 平均人時性 | Z27: 實際 | AD27: 平均人時性 | AE27: 實際 | AI27: 平均人時性 | AJ27: 實際 | AN27: 平均人時性 | AO27: 實際 | AS27: 平均人時性 | AT27: 實際 | AX27: 平均人時性
E28: 產線配置圖 | I28: 產線配置圖 | P28: 生產實績 | U28: 生產實績 | Z28: 生產實績 | AE28: 生產實績 | AJ28: 生產實績 | AO28: 生產實績 | AT28: 生產實績
E29: 人數 | F29: 產能／時 | G29: 人時性 | I29: 人數 | J29: 產能／時 | K29: 人時性 | P29: 人數 | Q29: 產能／時 | R29: 人時性 | S29: 排名 | U29: 人數 | V29: 產能／時 | W29: 人時性 | X29: 排名 | Z29: 人數 | AA29: 產能／時 | AB29: 人時性 | AC29: 排名 | AE29: 人數 | AF29: 產能／時 | AG29: 人時性 | AH29: 排名 | AJ29: 人數 | AK29: 產能／時 | AL29: 人時性 | AM29: 排名 | AO29: 人數 | AP29: 產能／時 | AQ29: 人時性 | AR29: 排名 | AT29: 人數 | AU29: 產能／時 | AV29: 人時性 | AW29: 排名
B30: 熱食義麵 | C30: 1 | D30: 義式蕃茄起司義大利麵 | E30: =VLOOKUP(D30,'11產線配置圖'!$A$2:$C$25,2,0) -> 12 | F30: =VLOOKUP(D30,'11產線配置圖'!$A$2:$C$25,3,0) -> 2000 | G30: =F30/E30 -> 166.66667 | H30: =AVERAGE(G30:G47) -> 112.60546 | I30: =AVERAGE(P30,U30,Z30,AE30,AJ30,AO30,AT30) -> 12.428571 | J30: =AVERAGE(Q30,V30,AA30,AF30,AK30,AP30,AU30) -> 1859 | K30: =AVERAGE(R30,W30,AB30,AG30,AL30,AQ30,AV30) -> 149.66667 | L30: =IFERROR(AVERAGE(K30:K47),"-") -> 100.13525 | M30: =RANK(K30, K$30:$K$47) -> 1 | P30: 12 | Q30: 1917 | R30: =Q30/P30 -> 159.75 | S30: =RANK(R30,$R$30:$R$47) -> 1 | T30: =AVERAGE(R30:R47) -> 103.83546 | U30: 12 | V30: 1889 | W30: =V30/U30 -> 157.41667 | X30: =RANK(W30, $W$30:$W$47) -> 1 | Y30: =AVERAGE(W30:W47) -> 104.07621 | Z30: 13 | AA30: 1842 | AB30: =AA30/Z30 -> 141.69231 | AC30: =RANK(AB30, $AB$30:$AB$47) -> 1 | AD30: =AVERAGE(AB30:AB47) -> 97.652558 | AE30: 12 | AF30: 1766 | AG30: =AF30/AE30 -> 147.16667 | AH30: =RANK(AG30, $AG$30:$AG$47) -> 1 | AI30: =AVERAGE(AG30:AG47) -> 98.493758 | AJ30: 12 | AK30: 1708 | AL30: =AK30/AJ30 -> 142.33333 | AM30: =RANK(AL30, $AL$30:$AL$47) -> 1 | AN30: =AVERAGE(AL30:AL47) -> 100.19224 | AO30: 13 | AP30: 1967 | AQ30: =AP30/AO30 -> 151.30769 | AR30: =RANK(AQ30,$AQ$30:$AQ$47) -> 1 | AS30: =AVERAGE(AQ30:AQ47) -> 98.659491 | AT30: 13 | AU30: 1924 | AV30: =AU30/AT30 -> 148 | AW30: =RANK(AV30, $AV$30:$AV$47) -> 1 | AX30: =AVERAGE(AV30:AV47) -> 98.037053
C31: 2 | D31: 奶油培根義大利麵 | E31: =VLOOKUP(D31,'11產線配置圖'!$A$2:$C$25,2,0) -> 13 | F31: =VLOOKUP(D31,'11產線配置圖'!$A$2:$C$25,3,0) -> 2000 | G31: =F31/E31 -> 153.84615 | I31: =AVERAGE(P31,U31,Z31,AE31,AJ31,AO31,AT31) -> 14 | J31: =AVERAGE(Q31,V31,AA31,AF31,AK31,AP31,AU31) -> 1897.1429 | K31: =AVERAGE(R31,W31,AB31,AG31,AL31,AQ31,AV31) -> 135.87849 | M31: =RANK(K31, K$30:$K$47) -> 3 | P31: 13 | Q31: 1902 | R31: =Q31/P31 -> 146.30769 | S31: =RANK(R31,$R$30:$R$47) -> 3 | U31: 13 | V31: 1942 | W31: =V31/U31 -> 149.38462 | X31: =RANK(W31, $W$30:$W$47) -> 2 | Z31: 14 | AA31: 1900 | AB31: =AA31/Z31 -> 135.71429 | AC31: =RANK(AB31, $AB$30:$AB$47) -> 2 | AE31: 14 | AF31: 1784 | AG31: =AF31/AE31 -> 127.42857 | AH31: =RANK(AG31, $AG$30:$AG$47) -> 4 | AJ31: 14 | AK31: 1858 | AL31: =AK31/AJ31 -> 132.71429 | AM31: =RANK(AL31, $AL$30:$AL$47) -> 3 | AO31: 15 | AP31: 1946 | AQ31: =AP31/AO31 -> 129.73333 | AR31: =RANK(AQ31,$AQ$30:$AQ$47) -> 3 | AT31: 15 | AU31: 1948 | AV31: =AU31/AT31 -> 129.86667 | AW31: =RANK(AV31, $AV$30:$AV$47) -> 3
C32: 3 | D32: 青醬蛤蜊義大利麵 | E32: =VLOOKUP(D32,'11產線配置圖'!$A$2:$C$25,2,0) -> 15 | F32: =VLOOKUP(D32,'11產線配置圖'!$A$2:$C$25,3,0) -> 2000 | G32: =F32/E32 -> 133.33333 | I32: =AVERAGE(P32,U32,Z32,AE32,AJ32,AO32,AT32) -> 13.714286 | J32: =AVERAGE(Q32,V32,AA32,AF32,AK32,AP32,AU32) -> 1868.2857 | K32: =AVERAGE(R32,W32,AB32,AG32,AL32,AQ32,AV32) -> 136.37049 | M32: =RANK(K32, K$30:$K$47) -> 2 | P32: 13 | Q32: 1918 | R32: =Q32/P32 -> 147.53846 | S32: =RANK(R32,$R$30:$R$47) -> 2 | U32: 13 | V32: 1804 | W32: =V32/U32 -> 138.76923 | X32: =RANK(W32, $W$30:$W$47) -> 4 | Z32: 14 | AA32: 1802 | AB32: =AA32/Z32 -> 128.71429 | AC32: =RANK(AB32, $AB$30:$AB$47) -> 3 | AE32: 14 | AF32: 1959 | AG32: =AF32/AE32 -> 139.92857 | AH32: =RANK(AG32, $AG$30:$AG$47) -> 2 | AJ32: 14 | AK32: 1980 | AL32: =AK32/AJ32 -> 141.42857 | AM32: =RANK(AL32, $AL$30:$AL$47) -> 2 | AO32: 14 | AP32: 1837 | AQ32: =AP32/AO32 -> 131.21429 | AR32: =RANK(AQ32,$AQ$30:$AQ$47) -> 2 | AT32: 14 | AU32: 1778 | AV32: =AU32/AT32 -> 127 | AW32: =RANK(AV32, $AV$30:$AV$47) -> 4
C33: 4 | D33: 焗烤起司雙饗筆尖麵 | E33: =VLOOKUP(D33,'11產線配置圖'!$A$2:$C$25,2,0) -> 18 | F33: =VLOOKUP(D33,'11產線配置圖'!$A$2:$C$25,3,0) -> 1565 | G33: =F33/E33 -> 86.944444 | I33: =AVERAGE(P33,U33,Z33,AE33,AJ33,AO33,AT33) -> 18 | J33: =AVERAGE(Q33,V33,AA33,AF33,AK33,AP33,AU33) -> 1520.7143 | K33: =AVERAGE(R33,W33,AB33,AG33,AL33,AQ33,AV33) -> 84.484127 | M33: =RANK(K33, K$30:$K$47) -> 7 | P33: 18 | Q33: 1537 | R33: =Q33/P33 -> 85.388889 | S33: =RANK(R33,$R$30:$R$47) -> 6 | U33: 18 | V33: 1460 | W33: =V33/U33 -> 81.111111 | X33: =RANK(W33, $W$30:$W$47) -> 9 | Z33: 18 | AA33: 1600 | AB33: =AA33/Z33 -> 88.888889 | AC33: =RANK(AB33, $AB$30:$AB$47) -> 6 | AE33: 18 | AF33: 1467 | AG33: =AF33/AE33 -> 81.5 | AH33: =RANK(AG33, $AG$30:$AG$47) -> 9 | AJ33: 18 | AK33: 1473 | AL33: =AK33/AJ33 -> 81.833333 | AM33: =RANK(AL33, $AL$30:$AL$47) -> 8 | AO33: 18 | AP33: 1581 | AQ33: =AP33/AO33 -> 87.833333 | AR33: =RANK(AQ33,$AQ$30:$AQ$47) -> 7 | AT33: 18 | AU33: 1527 | AV33: =AU33/AT33 -> 84.833333 | AW33: =RANK(AV33, $AV$30:$AV$47) -> 7
C34: 5 | D34: 白酒蛤蜊義大利麵 | E34: =VLOOKUP(D34,'11產線配置圖'!$A$2:$C$25,2,0) -> 13 | F34: =VLOOKUP(D34,'11產線配置圖'!$A$2:$C$25,3,0) -> 2000 | G34: =F34/E34 -> 153.84615 | I34: =AVERAGE(P34,U34,Z34,AE34,AJ34,AO34,AT34) -> 13.714286 | J34: =AVERAGE(Q34,V34,AA34,AF34,AK34,AP34,AU34) -> 1829.5714 | K34: =AVERAGE(R34,W34,AB34,AG34,AL34,AQ34,AV34) -> 133.57457 | M34: =RANK(K34, K$30:$K$47) -> 4 | P34: 13 | Q34: 1799 | R34: =Q34/P34 -> 138.38462 | S34: =RANK(R34,$R$30:$R$47) -> 4 | U34: 13 | V34: 1884 | W34: =V34/U34 -> 144.92308 | X34: =RANK(W34, $W$30:$W$47) -> 3 | Z34: 14 | AA34: 1787 | AB34: =AA34/Z34 -> 127.64286 | AC34: =RANK(AB34, $AB$30:$AB$47) -> 4 | AE34: 14 | AF34: 1939 | AG34: =AF34/AE34 -> 138.5 | AH34: =RANK(AG34, $AG$30:$AG$47) -> 3 | AJ34: 14 | AK34: 1813 | AL34: =AK34/AJ34 -> 129.5 | AM34: =RANK(AL34, $AL$30:$AL$47) -> 4 | AO34: 14 | AP34: 1746 | AQ34: =AP34/AO34 -> 124.71429 | AR34: =RANK(AQ34,$AQ$30:$AQ$47) -> 4 | AT34: 14 | AU34: 1839 | AV34: =AU34/AT34 -> 131.35714 | AW34: =RANK(AV34, $AV$30:$AV$47) -> 2
C35: 6 | D35: 韓式起司炸雞義大利麵 | E35: =VLOOKUP(D35,'11產線配置圖'!$A$2:$C$25,2,0) -> 14 | F35: =VLOOKUP(D35,'11產線配置圖'!$A$2:$C$25,3,0) -> 1895 | G35: =F35/E35 -> 135.35714 | I35: =AVERAGE(P35,U35,Z35,AE35,AJ35,AO35,AT35) -> 17.714286 | J35: =AVERAGE(Q35,V35,AA35,AF35,AK35,AP35,AU35) -> 1780.4286 | K35: =AVERAGE(R35,W35,AB35,AG35,AL35,AQ35,AV35) -> 100.55042 | M35: =RANK(K35, K$30:$K$47) -> 5 | P35: 17 | Q35: 1805 | R35: =Q35/P35 -> 106.17647 | S35: =RANK(R35,$R$30:$R$47) -> 5 | U35: 17 | V35: 1703 | W35: =V35/U35 -> 100.17647 | X35: =RANK(W35, $W$30:$W$47) -> 5 | Z35: 18 | AA35: 1791 | AB35: =AA35/Z35 -> 99.5 | AC35: =RANK(AB35, $AB$30:$AB$47) -> 5 | AE35: 18 | AF35: 1698 | AG35: =AF35/AE35 -> 94.333333 | AH35: =RANK(AG35, $AG$30:$AG$47) -> 6 | AJ35: 18 | AK35: 1733 | AL35: =AK35/AJ35 -> 96.277778 | AM35: =RANK(AL35, $AL$30:$AL$47) -> 5 | AO35: 18 | AP35: 1884 | AQ35: =AP35/AO35 -> 104.66667 | AR35: =RANK(AQ35,$AQ$30:$AQ$47) -> 5 | AT35: 18 | AU35: 1849 | AV35: =AU35/AT35 -> 102.72222 | AW35: =RANK(AV35, $AV$30:$AV$47) -> 5
C36: 7 | D36: 焗烤明太子筆尖麵 | E36: =VLOOKUP(D36,'11產線配置圖'!$A$2:$C$25,2,0) -> 17 | F36: =VLOOKUP(D36,'11產線配置圖'!$A$2:$C$25,3,0) -> 1385 | G36: =F36/E36 -> 81.470588 | I36: =AVERAGE(P36,U36,Z36,AE36,AJ36,AO36,AT36) -> 15.857143 | J36: =AVERAGE(Q36,V36,AA36,AF36,AK36,AP36,AU36) -> 1078.7143 | K36: =AVERAGE(R36,W36,AB36,AG36,AL36,AQ36,AV36) -> 68.012735 | M36: =RANK(K36, K$30:$K$47) -> 12 | P36: 16 | Q36: 1024 | R36: =Q36/P36 -> 64 | S36: =RANK(R36,$R$30:$R$47) -> 12 | U36: 16 | V36: 1158 | W36: =V36/U36 -> 72.375 | X36: =RANK(W36, $W$30:$W$47) -> 10 | Z36: 16 | AA36: 1148 | AB36: =AA36/Z36 -> 71.75 | AC36: =RANK(AB36, $AB$30:$AB$47) -> 11 | AE36: 15 | AF36: 814 | AG36: =AF36/AE36 -> 54.266667 | AH36: =RANK(AG36, $AG$30:$AG$47) -> 12 | AJ36: 14 | AK36: 1054 | AL36: =AK36/AJ36 -> 75.285714 | AM36: =RANK(AL36, $AL$30:$AL$47) -> 12 | AO36: 17 | AP36: 1020 | AQ36: =AP36/AO36 -> 60 | AR36: =RANK(AQ36,$AQ$30:$AQ$47) -> 12 | AT36: 17 | AU36: 1333 | AV36: =AU36/AT36 -> 78.411765 | AW36: =RANK(AV36, $AV$30:$AV$47) -> 9
C37: 8 | D37: 奶油蒜香雞義大利麵 | E37: =VLOOKUP(D37,'11產線配置圖'!$A$2:$C$25,2,0) -> 18 | F37: =VLOOKUP(D37,'11產線配置圖'!$A$2:$C$25,3,0) -> 1385 | G37: =F37/E37 -> 76.944444 | I37: =AVERAGE(P37,U37,Z37,AE37,AJ37,AO37,AT37) -> 15.428571 | J37: =AVERAGE(Q37,V37,AA37,AF37,AK37,AP37,AU37) -> 1099.2857 | K37: =AVERAGE(R37,W37,AB37,AG37,AL37,AQ37,AV37) -> 71.377721 | M37: =RANK(K37, K$30:$K$47) -> 11 | P37: 16 | Q37: 1263 | R37: =Q37/P37 -> 78.9375 | S37: =RANK(R37,$R$30:$R$47) -> 10 | U37: 15 | V37: 1049 | W37: =V37/U37 -> 69.933333 | X37: =RANK(W37, $W$30:$W$47) -> 12 | Z37: 15 | AA37: 1137 | AB37: =AA37/Z37 -> 75.8 | AC37: =RANK(AB37, $AB$30:$AB$47) -> 9 | AE37: 16 | AF37: 1004 | AG37: =AF37/AE37 -> 62.75 | AH37: =RANK(AG37, $AG$30:$AG$47) -> 11 | AJ37: 14 | AK37: 1075 | AL37: =AK37/AJ37 -> 76.785714 | AM37: =RANK(AL37, $AL$30:$AL$47) -> 10 | AO37: 16 | AP37: 1128 | AQ37: =AP37/AO37 -> 70.5 | AR37: =RANK(AQ37,$AQ$30:$AQ$47) -> 11 | AT37: 16 | AU37: 1039 | AV37: =AU37/AT37 -> 64.9375 | AW37: =RANK(AV37, $AV$30:$AV$47) -> 12
C38: 9 | D38: 青花椒麻雞肉拌麵 | E38: =VLOOKUP(D38,'11產線配置圖'!$A$2:$C$25,2,0) -> 17 | F38: =VLOOKUP(D38,'11產線配置圖'!$A$2:$C$25,3,0) -> 1565 | G38: =F38/E38 -> 92.058824 | I38: =AVERAGE(P38,U38,Z38,AE38,AJ38,AO38,AT38) -> 15.285714 | J38: =AVERAGE(Q38,V38,AA38,AF38,AK38,AP38,AU38) -> 1242.2857 | K38: =AVERAGE(R38,W38,AB38,AG38,AL38,AQ38,AV38) -> 81.573384 | M38: =RANK(K38, K$30:$K$47) -> 8 | P38: 16 | Q38: 1272 | R38: =Q38/P38 -> 79.5 | S38: =RANK(R38,$R$30:$R$47) -> 9 | U38: 14 | V38: 1270 | W38: =V38/U38 -> 90.714286 | X38: =RANK(W38, $W$30:$W$47) -> 6 | Z38: 16 | AA38: 1304 | AB38: =AA38/Z38 -> 81.5 | AC38: =RANK(AB38, $AB$30:$AB$47) -> 8 | AE38: 15 | AF38: 1289 | AG38: =AF38/AE38 -> 85.933333 | AH38: =RANK(AG38, $AG$30:$AG$47) -> 7 | AJ38: 14 | AK38: 1210 | AL38: =AK38/AJ38 -> 86.428571 | AM38: =RANK(AL38, $AL$30:$AL$47) -> 6 | AO38: 16 | AP38: 1258 | AQ38: =AP38/AO38 -> 78.625 | AR38: =RANK(AQ38,$AQ$30:$AQ$47) -> 9 | AT38: 16 | AU38: 1093 | AV38: =AU38/AT38 -> 68.3125 | AW38: =RANK(AV38, $AV$30:$AV$47) -> 11
C39: 10 | D39: 剝皮辣椒雞奶油扁麵 | E39: =VLOOKUP(D39,'11產線配置圖'!$A$2:$C$25,2,0) -> 17 | F39: =VLOOKUP(D39,'11產線配置圖'!$A$2:$C$25,3,0) -> 1500 | G39: =F39/E39 -> 88.235294 | I39: =AVERAGE(P39,U39,Z39,AE39,AJ39,AO39,AT39) -> 19 | J39: =AVERAGE(Q39,V39,AA39,AF39,AK39,AP39,AU39) -> 1521.8571 | K39: =AVERAGE(R39,W39,AB39,AG39,AL39,AQ39,AV39) -> 80.097744 | M39: =RANK(K39, K$30:$K$47) -> 9 | P39: 19 | Q39: 1554 | R39: =Q39/P39 -> 81.789474 | S39: =RANK(R39,$R$30:$R$47) -> 7 | U39: 19 | V39: 1560 | W39: =V39/U39 -> 82.105263 | X39: =RANK(W39, $W$30:$W$47) -> 8 | Z39: 19 | AA39: 1366 | AB39: =AA39/Z39 -> 71.894737 | AC39: =RANK(AB39, $AB$30:$AB$47) -> 10 | AE39: 19 | AF39: 1558 | AG39: =AF39/AE39 -> 82 | AH39: =RANK(AG39, $AG$30:$AG$47) -> 8 | AJ39: 19 | AK39: 1541 | AL39: =AK39/AJ39 -> 81.105263 | AM39: =RANK(AL39, $AL$30:$AL$47) -> 9 | AO39: 19 | AP39: 1559 | AQ39: =AP39/AO39 -> 82.052632 | AR39: =RANK(AQ39,$AQ$30:$AQ$47) -> 8 | AT39: 19 | AU39: 1515 | AV39: =AU39/AT39 -> 79.736842 | AW39: =RANK(AV39, $AV$30:$AV$47) -> 8
C40: 11 | D40: 濃拿坡里義大利麵 | E40: =VLOOKUP(D40,'11產線配置圖'!$A$2:$C$25,2,0) -> 15 | F40: =VLOOKUP(D40,'11產線配置圖'!$A$2:$C$25,3,0) -> 1440 | G40: =F40/E40 -> 96 | I40: =AVERAGE(P40,U40,Z40,AE40,AJ40,AO40,AT40) -> 14.857143 | J40: =AVERAGE(Q40,V40,AA40,AF40,AK40,AP40,AU40) -> 1068.5714 | K40: =AVERAGE(R40,W40,AB40,AG40,AL40,AQ40,AV40) -> 71.923129 | M40: =RANK(K40, K$30:$K$47) -> 10 | P40: 15 | Q40: 1162 | R40: =Q40/P40 -> 77.466667 | S40: =RANK(R40,$R$30:$R$47) -> 11 | U40: 14 | V40: 1007 | W40: =V40/U40 -> 71.928571 | X40: =RANK(W40, $W$30:$W$47) -> 11 | Z40: 15 | AA40: 925 | AB40: =AA40/Z40 -> 61.666667 | AC40: =RANK(AB40, $AB$30:$AB$47) -> 12 | AE40: 15 | AF40: 1061 | AG40: =AF40/AE40 -> 70.733333 | AH40: =RANK(AG40, $AG$30:$AG$47) -> 10 | AJ40: 15 | AK40: 1131 | AL40: =AK40/AJ40 -> 75.4 | AM40: =RANK(AL40, $AL$30:$AL$47) -> 11 | AO40: 15 | AP40: 1114 | AQ40: =AP40/AO40 -> 74.266667 | AR40: =RANK(AQ40,$AQ$30:$AQ$47) -> 10 | AT40: 15 | AU40: 1080 | AV40: =AU40/AT40 -> 72 | AW40: =RANK(AV40, $AV$30:$AV$47) -> 10
...

Sheet （５-2）品群別人時生產性(季節調理麵) 
B1: 月平均人時性 | C1: =AVERAGE(L7,L27,L47,L67,L87) -> #DIV/0!
B2: 產線配置圖－每週更新 | N2: 資料繳交 | O2: 日期 | AE2: 45870 | AJ2: 45871 | AO2: 45872 | AT2: 45873
P3: 二 | U3: 三 | Z3: 四 | AE3: 五 | AJ3: 六 | AO3: 日 | AT3: 一
B4: 品群 | C4: 商品名稱 | E4: 計畫 | H4: 平均人時性 | I4: 實績 | L4: 平均人時性 | M4: 排名 | O4: 日報 | P4: 實際 | T4: 平均人時性 | U4: 實際 | Y4: 平均人時性 | Z4: 實際 | AD4: 平均人時性 | AE4: 實際 | AI4: 平均人時性 | AJ4: 實際 | AN4: 平均人時性 | AO4: 實際 | AS4: 平均人時性 | AT4: 實際 | AX4: 平均人時性
E5: 產線配置圖 | I5: 產線配置圖 | P5: 生產實績 | U5: 生產實績 | Z5: 生產實績 | AE5: 生產實績 | AJ5: 生產實績 | AO5: 生產實績 | AT5: 生產實績
E6: 人數 | F6: 產能／時 | G6: 人時性 | I6: 人數 | J6: 產能／時 | K6: 人時性 | P6: 人數 | Q6: 產能／時 | R6: 人時性 | S6: 排名 | U6: 人數 | V6: 產能／時 | W6: 人時性 | X6: 排名 | Z6: 人數 | AA6: 產能／時 | AB6: 人時性 | AC6: 排名 | AE6: 人數 | AF6: 產能／時 | AG6: 人時性 | AH6: 排名 | AJ6: 人數 | AK6: 產能／時 | AL6: 人時性 | AM6: 排名 | AO6: 人數 | AP6: 產能／時 | AQ6: 人時性 | AR6: 排名 | AT6: 人數 | AU6: 產能／時 | AV6: 人時性 | AW6: 排名
B7: 熱食調理麵 | C7: 1 | H7: =AVERAGE(G7:G21) -> #DIV/0! | I7: =AVERAGE(P7,U7,Z7,AE7,AJ7,AO7,AT7) -> #DIV/0! | J7: =AVERAGE(Q7,V7,AA7,AF7,AK7,AP7,AU7) -> #DIV/0! | K7: =AVERAGE(R7,W7,AB7,AG7,AL7,AQ7,AV7) -> #DIV/0! | L7: =AVERAGE(K7:K21) -> #DIV/0! | M7: =RANK(K7, K$7:$K$21) -> #DIV/0! | S7: =RANK(R7, R$7:R$21) -> #N/A | T7: =AVERAGE(R7:R21) -> #DIV/0! | X7: =RANK(W7, W$7:W$21) -> #N/A | Y7: =AVERAGE(W7:W21) -> #DIV/0! | AC7: =RANK(AB7, AB$7:AB$21) -> #N/A | AD7: =AVERAGE(AB7:AB21) -> #DIV/0! | AH7: =RANK(AG7, AG$7:AG$21) -> #N/A | AI7: =AVERAGE(AG7:AG21) -> #DIV/0! | AM7: =RANK(AL7, AL$7:AL$21) -> #N/A | AN7: =AVERAGE(AL7:AL21) -> #DIV/0! | AR7: =RANK(AQ7, AQ$7:AQ$21) -> #N/A | AS7: =AVERAGE(AQ7:AQ21) -> #DIV/0! | AW7: =RANK(AV7, AV$7:AV$21) -> #N/A | AX7: =AVERAGE(AV7:AV21) -> #DIV/0!
C8: 2 | I8: =AVERAGE(P8,U8,Z8,AE8,AJ8,AO8,AT8) -> #DIV/0! | J8: =AVERAGE(Q8,V8,AA8,AF8,AK8,AP8,AU8) -> #DIV/0! | K8: =AVERAGE(R8,W8,AB8,AG8,AL8,AQ8,AV8) -> #DIV/0! | M8: =RANK(K8, K$7:$K$21) -> #DIV/0! | S8: =RANK(R8, R$7:R$21) -> #N/A | X8: =RANK(W8, W$7:W$21) -> #N/A | AC8: =RANK(AB8, AB$7:AB$21) -> #N/A | AH8: =RANK(AG8, AG$7:AG$21) -> #N/A | AM8: =RANK(AL8, AL$7:AL$21) -> #N/A | AR8: =RANK(AQ8, AQ$7:AQ$21) -> #N/A | AW8: =RANK(AV8, AV$7:AV$21) -> #N/A
C9: 3 | I9: =AVERAGE(P9,U9,Z9,AE9,AJ9,AO9,AT9) -> #DIV/0! | J9: =AVERAGE(Q9,V9,AA9,AF9,AK9,AP9,AU9) -> #DIV/0! | K9: =AVERAGE(R9,W9,AB9,AG9,AL9,AQ9,AV9) -> #DIV/0! | M9: =RANK(K9, K$7:$K$21) -> #DIV/0! | S9: =RANK(R9, R$7:R$21) -> #N/A | X9: =RANK(W9, W$7:W$21) -> #N/A | AC9: =RANK(AB9, AB$7:AB$21) -> #N/A | AH9: =RANK(AG9, AG$7:AG$21) -> #N/A | AM9: =RANK(AL9, AL$7:AL$21) -> #N/A | AR9: =RANK(AQ9, AQ$7:AQ$21) -> #N/A | AW9: =RANK(AV9, AV$7:AV$21) -> #N/A
C10: 4 | I10: =AVERAGE(P10,U10,Z10,AE10,AJ10,AO10,AT10) -> #DIV/0! | J10: =AVERAGE(Q10,V10,AA10,AF10,AK10,AP10,AU10) -> #DIV/0! | K10: =AVERAGE(R10,W10,AB10,AG10,AL10,AQ10,AV10) -> #DIV/0! | M10: =RANK(K10, K$7:$K$21) -> #DIV/0! | S10: =RANK(R10, R$7:R$21) -> #N/A | X10: =RANK(W10, W$7:W$21) -> #N/A | AC10: =RANK(AB10, AB$7:AB$21) -> #N/A | AH10: =RANK(AG10, AG$7:AG$21) -> #N/A | AM10: =RANK(AL10, AL$7:AL$21) -> #N/A | AR10: =RANK(AQ10, AQ$7:AQ$21) -> #N/A | AW10: =RANK(AV10, AV$7:AV$21) -> #N/A
C11: 5 | I11: =AVERAGE(P11,U11,Z11,AE11,AJ11,AO11,AT11) -> #DIV/0! | J11: =AVERAGE(Q11,V11,AA11,AF11,AK11,AP11,AU11) -> #DIV/0! | K11: =AVERAGE(R11,W11,AB11,AG11,AL11,AQ11,AV11) -> #DIV/0! | M11: =RANK(K11, K$7:$K$21) -> #DIV/0! | S11: =RANK(R11, R$7:R$21) -> #N/A | X11: =RANK(W11, W$7:W$21) -> #N/A | AC11: =RANK(AB11, AB$7:AB$21) -> #N/A | AH11: =RANK(AG11, AG$7:AG$21) -> #N/A | AM11: =RANK(AL11, AL$7:AL$21) -> #N/A | AR11: =RANK(AQ11, AQ$7:AQ$21) -> #N/A | AW11: =RANK(AV11, AV$7:AV$21) -> #N/A
C12: 6 | I12: =AVERAGE(P12,U12,Z12,AE12,AJ12,AO12,AT12) -> #DIV/0! | J12: =AVERAGE(Q12,V12,AA12,AF12,AK12,AP12,AU12) -> #DIV/0! | K12: =AVERAGE(R12,W12,AB12,AG12,AL12,AQ12,AV12) -> #DIV/0! | M12: =RANK(K12, K$7:$K$21) -> #DIV/0! | S12: =RANK(R12, R$7:R$21) -> #N/A | X12: =RANK(W12, W$7:W$21) -> #N/A | AC12: =RANK(AB12, AB$7:AB$21) -> #N/A | AH12: =RANK(AG12, AG$7:AG$21) -> #N/A | AM12: =RANK(AL12, AL$7:AL$21) -> #N/A | AR12: =RANK(AQ12, AQ$7:AQ$21) -> #N/A | AW12: =RANK(AV12, AV$7:AV$21) -> #N/A
C13: 7 | I13: =AVERAGE(P13,U13,Z13,AE13,AJ13,AO13,AT13) -> #DIV/0! | J13: =AVERAGE(Q13,V13,AA13,AF13,AK13,AP13,AU13) -> #DIV/0! | K13: =AVERAGE(R13,W13,AB13,AG13,AL13,AQ13,AV13) -> #DIV/0! | M13: =RANK(K13, K$7:$K$21) -> #DIV/0! | S13: =RANK(R13, R$7:R$21) -> #N/A | X13: =RANK(W13, W$7:W$21) -> #N/A | AC13: =RANK(AB13, AB$7:AB$21) -> #N/A | AH13: =RANK(AG13, AG$7:AG$21) -> #N/A | AM13: =RANK(AL13, AL$7:AL$21) -> #N/A | AR13: =RANK(AQ13, AQ$7:AQ$21) -> #N/A | AW13: =RANK(AV13, AV$7:AV$21) -> #N/A
C14: 8 | I14: =AVERAGE(P14,U14,Z14,AE14,AJ14,AO14,AT14) -> #DIV/0! | J14: =AVERAGE(Q14,V14,AA14,AF14,AK14,AP14,AU14) -> #DIV/0! | K14: =AVERAGE(R14,W14,AB14,AG14,AL14,AQ14,AV14) -> #DIV/0! | M14: =RANK(K14, K$7:$K$21) -> #DIV/0! | S14: =RANK(R14, R$7:R$21) -> #N/A | X14: =RANK(W14, W$7:W$21) -> #N/A | AC14: =RANK(AB14, AB$7:AB$21) -> #N/A | AH14: =RANK(AG14, AG$7:AG$21) -> #N/A | AM14: =RANK(AL14, AL$7:AL$21) -> #N/A | AR14: =RANK(AQ14, AQ$7:AQ$21) -> #N/A | AW14: =RANK(AV14, AV$7:AV$21) -> #N/A
C15: 9 | I15: =AVERAGE(P15,U15,Z15,AE15,AJ15,AO15,AT15) -> #DIV/0! | J15: =AVERAGE(Q15,V15,AA15,AF15,AK15,AP15,AU15) -> #DIV/0! | K15: =AVERAGE(R15,W15,AB15,AG15,AL15,AQ15,AV15) -> #DIV/0! | M15: =RANK(K15, K$7:$K$21) -> #DIV/0! | S15: =RANK(R15, R$7:R$21) -> #N/A | X15: =RANK(W15, W$7:W$21) -> #N/A | AC15: =RANK(AB15, AB$7:AB$21) -> #N/A | AH15: =RANK(AG15, AG$7:AG$21) -> #N/A | AM15: =RANK(AL15, AL$7:AL$21) -> #N/A | AR15: =RANK(AQ15, AQ$7:AQ$21) -> #N/A | AW15: =RANK(AV15, AV$7:AV$21) -> #N/A
C16: 10 | I16: =AVERAGE(P16,U16,Z16,AE16,AJ16,AO16,AT16) -> #DIV/0! | J16: =AVERAGE(Q16,V16,AA16,AF16,AK16,AP16,AU16) -> #DIV/0! | K16: =AVERAGE(R16,W16,AB16,AG16,AL16,AQ16,AV16) -> #DIV/0! | M16: =RANK(K16, K$7:$K$21) -> #DIV/0! | S16: =RANK(R16, R$7:R$21) -> #N/A | X16: =RANK(W16, W$7:W$21) -> #N/A | AC16: =RANK(AB16, AB$7:AB$21) -> #N/A | AH16: =RANK(AG16, AG$7:AG$21) -> #N/A | AM16: =RANK(AL16, AL$7:AL$21) -> #N/A | AR16: =RANK(AQ16, AQ$7:AQ$21) -> #N/A | AW16: =RANK(AV16, AV$7:AV$21) -> #N/A
C17: 11 | M17: =RANK(K17, K$7:$K$21) -> #DIV/0! | S17: =RANK(R17, R$7:R$21) -> #N/A | X17: =RANK(W17, W$7:W$21) -> #N/A | AC17: =RANK(AB17, AB$7:AB$21) -> #N/A | AH17: =RANK(AG17, AG$7:AG$21) -> #N/A | AM17: =RANK(AL17, AL$7:AL$21) -> #N/A | AR17: =RANK(AQ17, AQ$7:AQ$21) -> #N/A | AW17: =RANK(AV17, AV$7:AV$21) -> #N/A
C18: 12 | M18: =RANK(K18, K$7:$K$21) -> #DIV/0! | S18: =RANK(R18, R$7:R$21) -> #N/A | X18: =RANK(W18, W$7:W$21) -> #N/A | AC18: =RANK(AB18, AB$7:AB$21) -> #N/A | AH18: =RANK(AG18, AG$7:AG$21) -> #N/A | AM18: =RANK(AL18, AL$7:AL$21) -> #N/A | AR18: =RANK(AQ18, AQ$7:AQ$21) -> #N/A | AW18: =RANK(AV18, AV$7:AV$21) -> #N/A
C19: 13 | M19: =RANK(K19, K$7:$K$21) -> #DIV/0! | S19: =RANK(R19, R$7:R$21) -> #N/A | X19: =RANK(W19, W$7:W$21) -> #N/A | AC19: =RANK(AB19, AB$7:AB$21) -> #N/A | AH19: =RANK(AG19, AG$7:AG$21) -> #N/A | AM19: =RANK(AL19, AL$7:AL$21) -> #N/A | AR19: =RANK(AQ19, AQ$7:AQ$21) -> #N/A | AW19: =RANK(AV19, AV$7:AV$21) -> #N/A
C20: 14 | M20: =RANK(K20, K$7:$K$21) -> #DIV/0! | S20: =RANK(R20, R$7:R$21) -> #N/A | X20: =RANK(W20, W$7:W$21) -> #N/A | AC20: =RANK(AB20, AB$7:AB$21) -> #N/A | AH20: =RANK(AG20, AG$7:AG$21) -> #N/A | AM20: =RANK(AL20, AL$7:AL$21) -> #N/A | AR20: =RANK(AQ20, AQ$7:AQ$21) -> #N/A | AW20: =RANK(AV20, AV$7:AV$21) -> #N/A
C21: 15 | M21: =RANK(K21, K$7:$K$21) -> #DIV/0! | S21: =RANK(R21, R$7:R$21) -> #N/A | X21: =RANK(W21, W$7:W$21) -> #N/A | AC21: =RANK(AB21, AB$7:AB$21) -> #N/A | AH21: =RANK(AG21, AG$7:AG$21) -> #N/A | AM21: =RANK(AL21, AL$7:AL$21) -> #N/A | AR21: =RANK(AQ21, AQ$7:AQ$21) -> #N/A | AW21: =RANK(AV21, AV$7:AV$21) -> #N/A
B22: 產線配置圖－每週更新 | N22: 資料繳交 | O22: 日期 | P22: 45874 | U22: 45875 | Z22: 45876 | AE22: 45877 | AJ22: 45878 | AO22: 45879 | AT22: 45880
P23: 二 | U23: 三 | Z23: 四 | AE23: 五 | AJ23: 六 | AO23: 日 | AT23: 一
B24: 品群 | C24: 商品名稱 | E24: 計畫 | H24: 平均人時性 | I24: 實績 | L24: 平均人時性 | M24: 排名 | O24: 日報 | P24: 實際 | T24: 平均人時性 | U24: 實際 | Y24: 平均人時性 | Z24: 實際 | AD24: 平均人時性 | AE24: 實際 | AI24: 平均人時性 | AJ24: 實際 | AN24: 平均人時性 | AO24: 實際 | AS24: 平均人時性 | AT24: 實際 | AX24: 平均人時性
E25: 產線配置圖 | I25: 產線配置圖 | P25: 生產實績 | U25: 生產實績 | Z25: 生產實績 | AE25: 生產實績 | AJ25: 生產實績 | AO25: 生產實績 | AT25: 生產實績
E26: 人數 | F26: 產能／時 | G26: 人時性 | I26: 人數 | J26: 產能／時 | K26: 人時性 | P26: 人數 | Q26: 產能／時 | R26: 人時性 | S26: 排名 | U26: 人數 | V26: 產能／時 | W26: 人時性 | X26: 排名 | Z26: 人數 | AA26: 產能／時 | AB26: 人時性 | AC26: 排名 | AE26: 人數 | AF26: 產能／時 | AG26: 人時性 | AH26: 排名 | AJ26: 人數 | AK26: 產能／時 | AL26: 人時性 | AM26: 排名 | AO26: 人數 | AP26: 產能／時 | AQ26: 人時性 | AR26: 排名 | AT26: 人數 | AU26: 產能／時 | AV26: 人時性 | AW26: 排名
B27: 季節調理麵 | C27: 1 | H27: =AVERAGE(G27:G41) -> #DIV/0! | I27: =AVERAGE(P27,U27,Z27,AE27,AJ27,AO27,AT27) -> #DIV/0! | J27: =AVERAGE(Q27,V27,AA27,AF27,AK27,AP27,AU27) -> #DIV/0! | K27: =AVERAGE(R27,W27,AB27,AG27,AL27,AQ27,AV27) -> #DIV/0! | L27: =AVERAGE(K27:K41) -> #DIV/0! | M27: =RANK(K27, K$27:$K$41) -> #DIV/0! | T27: =AVERAGE(R27:R41) -> #DIV/0! | Y27: =AVERAGE(W27:W41) -> #DIV/0! | AD27: =AVERAGE(AB27:AB41) -> #DIV/0! | AI27: =AVERAGE(AG27:AG41) -> #DIV/0! | AN27: =AVERAGE(AL27:AL41) -> #DIV/0! | AS27: =AVERAGE(AQ27:AQ41) -> #DIV/0! | AX27: =AVERAGE(AV27:AV41) -> #DIV/0!
C28: 2 | I28: =AVERAGE(P28,U28,Z28,AE28,AJ28,AO28,AT28) -> #DIV/0! | J28: =AVERAGE(Q28,V28,AA28,AF28,AK28,AP28,AU28) -> #DIV/0! | K28: =AVERAGE(R28,W28,AB28,AG28,AL28,AQ28,AV28) -> #DIV/0! | M28: =RANK(K28, K$27:$K$41) -> #DIV/0!
C29: 3 | I29: =AVERAGE(P29,U29,Z29,AE29,AJ29,AO29,AT29) -> #DIV/0! | J29: =AVERAGE(Q29,V29,AA29,AF29,AK29,AP29,AU29) -> #DIV/0! | K29: =AVERAGE(R29,W29,AB29,AG29,AL29,AQ29,AV29) -> #DIV/0! | M29: =RANK(K29, K$27:$K$41) -> #DIV/0!
C30: 4 | I30: =AVERAGE(P30,U30,Z30,AE30,AJ30,AO30,AT30) -> #DIV/0! | J30: =AVERAGE(Q30,V30,AA30,AF30,AK30,AP30,AU30) -> #DIV/0! | K30: =AVERAGE(R30,W30,AB30,AG30,AL30,AQ30,AV30) -> #DIV/0! | M30: =RANK(K30, K$27:$K$41) -> #DIV/0!
C31: 5 | I31: =AVERAGE(P31,U31,Z31,AE31,AJ31,AO31,AT31) -> #DIV/0! | J31: =AVERAGE(Q31,V31,AA31,AF31,AK31,AP31,AU31) -> #DIV/0! | K31: =AVERAGE(R31,W31,AB31,AG31,AL31,AQ31,AV31) -> #DIV/0! | M31: =RANK(K31, K$27:$K$41) -> #DIV/0!
C32: 6 | I32: =AVERAGE(P32,U32,Z32,AE32,AJ32,AO32,AT32) -> #DIV/0! | J32: =AVERAGE(Q32,V32,AA32,AF32,AK32,AP32,AU32) -> #DIV/0! | K32: =AVERAGE(R32,W32,AB32,AG32,AL32,AQ32,AV32) -> #DIV/0! | M32: =RANK(K32, K$27:$K$41) -> #DIV/0!
C33: 7 | I33: =AVERAGE(P33,U33,Z33,AE33,AJ33,AO33,AT33) -> #DIV/0! | J33: =AVERAGE(Q33,V33,AA33,AF33,AK33,AP33,AU33) -> #DIV/0! | K33: =AVERAGE(R33,W33,AB33,AG33,AL33,AQ33,AV33) -> #DIV/0! | M33: =RANK(K33, K$27:$K$41) -> #DIV/0!
C34: 8 | I34: =AVERAGE(P34,U34,Z34,AE34,AJ34,AO34,AT34) -> #DIV/0! | J34: =AVERAGE(Q34,V34,AA34,AF34,AK34,AP34,AU34) -> #DIV/0! | K34: =AVERAGE(R34,W34,AB34,AG34,AL34,AQ34,AV34) -> #DIV/0! | M34: =RANK(K34, K$27:$K$41) -> #DIV/0!
C35: 9 | I35: =AVERAGE(P35,U35,Z35,AE35,AJ35,AO35,AT35) -> #DIV/0! | J35: =AVERAGE(Q35,V35,AA35,AF35,AK35,AP35,AU35) -> #DIV/0! | K35: =AVERAGE(R35,W35,AB35,AG35,AL35,AQ35,AV35) -> #DIV/0! | M35: =RANK(K35, K$27:$K$41) -> #DIV/0!
C36: 10 | I36: =AVERAGE(P36,U36,Z36,AE36,AJ36,AO36,AT36) -> #DIV/0! | J36: =AVERAGE(Q36,V36,AA36,AF36,AK36,AP36,AU36) -> #DIV/0! | K36: =AVERAGE(R36,W36,AB36,AG36,AL36,AQ36,AV36) -> #DIV/0! | M36: =RANK(K36, K$27:$K$41) -> #DIV/0!
C37: 11 | M37: =RANK(K37, K$27:$K$41) -> #DIV/0!
C38: 12 | M38: =RANK(K38, K$27:$K$41) -> #DIV/0!
C39: 13 | M39: =RANK(K39, K$27:$K$41) -> #DIV/0!
C40: 14 | M40: =RANK(K40, K$27:$K$41) -> #DIV/0!
...

Sheet （５-3）品群別人時生產性(微波小吃)
B1: 月平均人時性 | C1: 111.7
B2: 產線配置圖－每週更新 | N2: 資料繳交 | O2: 日期 | AJ2: 45962 | AO2: 45963 | AT2: 45964
P3: 二 | U3: 三 | Z3: 四 | AE3: 五 | AJ3: 六 | AO3: 日 | AT3: 一
B4: 品群 | C4: 商品名稱 | E4: 計畫 | H4: 平均人時性 | I4: 實績 | L4: 平均人時性 | M4: 排名 | O4: 日報 | P4: 實際 | T4: 平均人時性 | U4: 實際 | Y4: 平均人時性 | Z4: 實際 | AD4: 平均人時性 | AE4: 實際 | AI4: 平均人時性 | AJ4: 實際 | AN4: 平均人時性 | AO4: 實際 | AS4: 平均人時性 | AT4: 實際 | AX4: 平均人時性
E5: 產線配置圖 | I5: 產線配置圖 | P5: 生產實績 | U5: 生產實績 | Z5: 生產實績 | AE5: 生產實績 | AJ5: 生產實績 | AO5: 生產實績 | AT5: 生產實績
E6: 人數 | F6: 產能／時 | G6: 人時性 | I6: 人數 | J6: 產能／時 | K6: 人時性 | P6: 人數 | Q6: 產能／時 | R6: 人時性 | S6: 排名 | U6: 人數 | V6: 產能／時 | W6: 人時性 | X6: 排名 | Z6: 人數 | AA6: 產能／時 | AB6: 人時性 | AC6: 排名 | AE6: 人數 | AF6: 產能／時 | AG6: 人時性 | AH6: 排名 | AJ6: 人數 | AK6: 產能／時 | AL6: 人時性 | AM6: 排名 | AO6: 人數 | AP6: 產能／時 | AQ6: 人時性 | AR6: 排名 | AT6: 人數 | AU6: 產能／時 | AV6: 人時性 | AW6: 排名
