Workbook

Sheet 生產管理報表(月)
A1: 長家廠生產管理報表
A3: 月別 | B3: 9 | C3: 工廠 | D3: 長家
A4: （１）收支狀況 | E4: ※單位：千元 | G4: （２）ＫＰＩ達成進度
A5: 項目 | B5: 當月 | C5: 前月 | D5: 差異 | E5: 累計 | G5: 項目 | H5: KPI | I5: 當月 | J5: 前月 | K5: 累計 | L5: ※補充
A6: 業績金額 | B6: 75756.5 | C6: 84284.94 | D6: =B6-C6 -> -8528.44 | G6: 人時性(個/月均) | H6: 117.9 | I6: 99.6 | J6: 99.8 | L6: 個／MH
A7: 訂單數量 | B7: 1533362 | C7: 1717015 | D7: =B7-C7 -> -183653 | G7: 人時達成率(%/月均) | H7: 0.8 | I7: 0.891 | J7: 0.912 | L7: 達成率
A8: 材料費 | B8: 47758.42 | C8: 53121.6 | D8: =B8-C8 -> -5363.18 | G8: 半成品-報廢(%) | H8: 0.0025 | I8: 0.007 | J8: 0.009 | L8: 報廢率
A9: 材料費率 | B9: 0.6304 | C9: 0.62806824 | D9: =B9-C9 -> 0.0023317574 | G9: 半成品-超用(%) | H9: 0.0025 | I9: 0.0062 | J9: 0.011 | L9: 超用率
A10: 勞務成本 | B10: 9772 | C10: 9693 | D10: =B10-C10 -> 79 | G10: 固定產線-導入率(%) | H10: 1 | I10: 0.429 | J10: 0.429 | L10: 導入率
A11: 勞務費率 | B11: 0.129 | C11: 0.11500014 | D11: =B11-C11 -> 0.013999859 | G11: 教育訓練-實施率(%) | H11: 1 | I11: 0.286 | J11: 0.457 | L11: 實施率
A13: （３）業績構成比 | G13: （４）訂單數量構成比
B14: 當月 | C14: 比例 | D14: 前月 | E14: 差異 | H14: 當月 | I14: 比例 | J14: 前月 | K14: 差異
A15: 熱食義麵(122,123,124,126) | B15: 68817.85 | C15: =IFERROR(B15/$B$6,"") -> 0.90840852 | D15: 0.9187 | E15: =IFERROR(C15-D15,"") -> -0.010291481 | G15: 熱食義麵(122,123,124,126) | H15: 1282561 | I15: =IFERROR(H15/$B$7,"") -> 0.83643719 | J15: 0.8494 | K15: =IFERROR(I15-J15,"") -> -0.012962812
A16: 季節調理麵(111,112) | C16: =IFERROR(B16/$B$6,"") -> 0 | E16: =IFERROR(C16-D16,"") -> 0 | G16: 季節調理麵(111,112) | I16: =IFERROR(H16/$B$7,"") -> 0 | K16: =IFERROR(I16-J16,"") -> 0
A17: 微波小吃(153,154,155) | B17: 6938.64 | C17: =IFERROR(B17/$B$6,"") -> 0.091591349 | D17: 0.08128 | E17: =IFERROR(C17-D17,"") -> 0.010311349 | G17: 微波小吃(153,154,155) | H17: 250801 | I17: =IFERROR(H17/$B$7,"") -> 0.16356281 | J17: 0.1506 | K17: =IFERROR(I17-J17,"") -> 0.012962812
C18: =SUM(C15:C17) -> 0.99999987 | D18: =SUM(D15:D17) -> 0.99998 | I18: =SUM(I15:I17) -> 1 | J18: =SUM(J15:J17) -> 1
A20: （５）品群別人時生產性
A21: 品群 | B21: 當月 | C21: 前月 | D21: 差異 | E21: 累計
A22: 熱食義麵(122,123,124,126) | B22: 95.2 | C22: 97.6 | D22: =B22-C22 -> -2.4
A23: 季節調理麵(111,112) | D23: =B23-C23 -> 0
A24: 微波小吃(153,154,155) | B24: 113 | C24: 112.5 | D24: =B24-C24 -> 0.5

Sheet （１）收支狀況
B2: （１）收支狀況
B3: 資料繳交日 | C3: 月份 | D3: 日期 | F3: 營業額(元) | I3: 訂單數量(個) | L3: 材料費(元) | O3: 材料費率（材料費／營業額） | R3: 勞務成本（全廠人事成本） | U3: 勞務費率（勞務成本／營業額）
F4: 日 | G4: 週累積 | H4: 月累積 | I4: 日 | J4: 週累積 | K4: 月累積 | L4: 日 | M4: 週累積 | N4: 月累積 | O4: 日 | P4: 週累積 | Q4: 月累積 | R4: 日 | S4: 週累積 | T4: 月累積 | U4: 日 | V4: 週累積 | W4: 月累積
C5: 九 | D5: 45901 | E5: 一 | F5: 2893618.9 | G5: =SUM(F5) -> 2893618.9 | H5: =SUM(F5:F34) -> 75756497 | I5: 58795 | J5: =SUM(I5) -> 58795 | K5: =SUM(I5:I34) -> 1476642 | L5: 1819250 | M5: =SUM(L5) -> 1819250 | N5: =SUM(L5:L34) -> 47758424 | O5: =L5/F5 -> 0.62871099 | P5: =M5/G5 -> 0.62871099 | Q5: =N5/H5 -> 0.63042017 | S5: =SUM(R5) -> 0 | T5: =SUM(R5:R34) -> 0 | U5: =R5/F5 -> 0 | V5: =SUM(U5) -> 0 | W5: =T5/H5 -> 0
B6: 45910 | D6: 45902 | E6: 二 | F6: 2792067.2 | G6: =SUM(F6:F12) -> 17039199 | I6: 56974 | J6: =SUM(I6:I12) -> 350126 | L6: 1758759 | M6: =SUM(L6:L12) -> 10732236 | O6: =L6/F6 -> 0.62991285 | P6: =M6/G6 -> 0.62985567 | S6: =SUM(R6:R12) -> 0 | U6: =R6/F6 -> 0 | V6: =SUM(U6:U12) -> 0
D7: 45903 | E7: 三 | F7: 2693780.4 | I7: 55119 | L7: 1698150 | O7: =L7/F7 -> 0.63039661 | U7: =R7/F7 -> 0
D8: 45904 | E8: 四 | F8: 2413420.3 | I8: 49608 | L8: 1517843 | O8: =L8/F8 -> 0.62891782 | U8: =R8/F8 -> 0
D9: 45905 | E9: 五 | F9: 1867882.3 | I9: 38609 | L9: 1177843 | O9: =L9/F9 -> 0.63057667 | U9: =R9/F9 -> 0
D10: 45906 | E10: 六 | F10: 1984347.8 | I10: 40921 | L10: 1247843 | O10: =L10/F10 -> 0.62884288 | U10: =R10/F10 -> 0
D11: 45907 | E11: 日 | F11: 2634379.3 | I11: 54263 | L11: 1663039 | O11: =L11/F11 -> 0.63128305 | U11: =R11/F11 -> 0
D12: 45908 | E12: 一 | F12: 2653321.6 | I12: 54632 | L12: 1668759 | O12: =L12/F12 -> 0.62893206 | U12: =R12/F12 -> 0
B13: 45917 | D13: 45909 | E13: 二 | F13: 2549415.1 | G13: =SUM(F13:F19) -> 16573497 | I13: 54526 | J13: =SUM(I13:I19) -> 344404 | L13: 1600947 | M13: =SUM(L13:L19) -> 10437998 | O13: =L13/F13 -> 0.6279664 | P13: =M13/G13 -> 0.62980058 | S13: =SUM(R13:R19) -> 0 | U13: =R13/F13 -> 0 | V13: =SUM(U13:U19) -> 0
D14: 45910 | E14: 三 | F14: 2484298.8 | I14: 51467 | L14: 1569402 | O14: =L14/F14 -> 0.63172836 | U14: =R14/F14 -> 0
D15: 45911 | E15: 四 | F15: 2285316.2 | I15: 47272 | L15: 1440666 | O15: =L15/F15 -> 0.63040118 | U15: =R15/F15 -> 0
D16: 45912 | E16: 五 | F16: 1942536.6 | I16: 40144 | L16: 1225182 | O16: =L16/F16 -> 0.63071245 | U16: =R16/F16 -> 0
D17: 45913 | E17: 六 | F17: 2052730.4 | I17: 42409 | L17: 1289965 | O17: =L17/F17 -> 0.62841424 | U17: =R17/F17 -> 0
D18: 45914 | E18: 日 | F18: 2615131.3 | I18: 54004 | L18: 1646918 | O18: =L18/F18 -> 0.62976494 | U18: =R18/F18 -> 0
D19: 45915 | E19: 一 | F19: 2644068.6 | I19: 54582 | L19: 1664918 | O19: =L19/F19 -> 0.62968033 | U19: =R19/F19 -> 0
B20: 45924 | D20: 45916 | E20: 二 | F20: 3351676 | G20: =SUM(F20:F26) -> 19143932 | I20: 52594 | J20: =SUM(I20:I26) -> 376041 | L20: 2110250 | M20: =SUM(L20:L26) -> 12097345 | O20: =L20/F20 -> 0.62961039 | P20: =M20/G20 -> 0.63191538 | S20: =SUM(R20:R26) -> 0 | U20: =R20/F20 -> 0 | V20: =SUM(U20:U26) -> 0
D21: 45917 | E21: 三 | F21: 3025640.2 | I21: 61614 | L21: 1908759 | O21: =L21/F21 -> 0.6308612 | U21: =R21/F21 -> 0
D22: 45918 | E22: 四 | F22: 2779379.6 | I22: 56703 | L22: 1752150 | O22: =L22/F22 -> 0.63041047 | U22: =R22/F22 -> 0
D23: 45919 | E23: 五 | F23: 2046591.7 | I23: 42093 | L23: 1300843 | O23: =L23/F23 -> 0.63561434 | U23: =R23/F23 -> 0
D24: 45920 | E24: 六 | F24: 2230582.5 | I24: 45817 | L24: 1427843 | O24: =L24/F24 -> 0.64012112 | U24: =R24/F24 -> 0
D25: 45921 | E25: 日 | F25: 2856812 | I25: 58722 | L25: 1799250 | O25: =L25/F25 -> 0.62981044 | U25: =R25/F25 -> 0
D26: 45922 | E26: 一 | F26: 2853250 | I26: 58498 | L26: 1798250 | O26: =L26/F26 -> 0.63024622 | U26: =R26/F26 -> 0
B27: 45931 | D27: 45923 | E27: 二 | F27: 2623577.6 | G27: =SUM(F27:F33) -> 16941839 | I27: 54036 | J27: =SUM(I27:I33) -> 347276 | L27: 1650250 | M27: =SUM(L27:L33) -> 10676345 | O27: =L27/F27 -> 0.62900751 | P27: =M27/G27 -> 0.63017629 | S27: =SUM(R27:R33) -> 0 | U27: =R27/F27 -> 0 | V27: =SUM(U27:U33) -> 0
D28: 45924 | E28: 三 | F28: 2681520.5 | I28: 55176 | L28: 1685759 | O28: =L28/F28 -> 0.62865788 | U28: =R28/F28 -> 0
D29: 45925 | E29: 四 | F29: 2459851.9 | I29: 50523 | L29: 1552150 | O29: =L29/F29 -> 0.63099327 | U29: =R29/F29 -> 0
D30: 45926 | E30: 五 | F30: 1996517.2 | I30: 40771 | L30: 1259843 | O30: =L30/F30 -> 0.63102037 | U30: =R30/F30 -> 0
D31: 45927 | E31: 六 | F31: 2053881.9 | I31: 41899 | L31: 1297843 | O31: =L31/F31 -> 0.63189758 | U31: =R31/F31 -> 0
D32: 45928 | E32: 日 | F32: 2260837.3 | I32: 46083 | L32: 1422250 | O32: =L32/F32 -> 0.62908108 | U32: =R32/F32 -> 0
D33: 45929 | E33: 一 | F33: 2865652.3 | I33: 58788 | L33: 1808250 | O33: =L33/F33 -> 0.63100817 | U33: =R33/F33 -> 0
D34: 45930 | E34: 二 | F34: 3164412 | G34: =SUM(F34) -> 3164412 | L34: 1995250 | M34: =SUM(L34) -> 1995250 | O34: =L34/F34 -> 0.63052788 | P34: =M34/G34 -> 0.63052788 | U34: =R34/F34 -> 0
U35: =R35/F35 -> #DIV/0!
S37: =SUM(R37:R43) -> 0 | V37: =SUM(U37:U43) -> 0

Sheet （２）ＫＰＩ達成進度
C1: 111.8
B2: （２）ＫＰＩ達成進度
B3: 資料繳交日 | C3: 月份 | D3: 日期 | F3: 人時生產性(個/人) | I3: 人時生產性達成率(%) | L3: 半成品報廢(%) | O3: 半成品超用(%) | R3: 固定產線-導入率(固定產線數/總產線數) | U3: 教育訓練-實施率(進度/計畫)
F4: 日 | G4: 週平均 | H4: 月平均 | I4: 日 | J4: 週平均 | K4: 月平均 | L4: 日 | M4: 週平均 | N4: 月平均 | O4: 日 | P4: 週平均 | Q4: 月平均 | R4: 日 | S4: 週平均 | T4: 月平均 | U4: 日 | V4: 週平均 | W4: 月平均
C5: 九 | D5: 45901 | E5: 一 | F5: 96.8 | G5: =AVERAGE(F5) -> 96.8 | H5: =AVERAGE(F5:F34) -> 99.586667 | I5: =F5/$C$1 -> 0.86583184 | J5: =AVERAGE(I5) -> 0.86583184 | K5: =AVERAGE(I5:I34) -> 0.8907573 | L5: 0.00365 | M5: =AVERAGE(L5) -> 0.00365 | N5: =AVERAGE(L5:L34) -> 0.0073326667 | O5: 0.002 | P5: =AVERAGE(O5) -> 0.002 | Q5: =AVERAGE(O5:O34) -> 0.0035836667 | R5: 0.429 | S5: =AVERAGE(R5) -> 0.429 | T5: =AVERAGE(R5:R34) -> 0.429 | U5: 0.1 | V5: =AVERAGE(U5) -> 0.1 | W5: =AVERAGE(U5:U34) -> 0.45733333
B6: 45910 | D6: 45902 | E6: 二 | F6: 99.3 | G6: =AVERAGE(F6:F12) -> 98.742857 | I6: =F6/$C$1 -> 0.8881932 | J6: =AVERAGE(I6:I12) -> 0.88320981 | L6: 0.00553 | M6: =AVERAGE(L6:L12) -> 0.0056771429 | O6: 0.0018 | P6: =AVERAGE(O6:O12) -> 0.0028285714 | R6: 0.429 | S6: =AVERAGE(R6:R12) -> 0.429 | U6: 0.1 | V6: =AVERAGE(U6:U12) -> 0.27142857
D7: 45903 | E7: 三 | F7: 97.9 | I7: =F7/$C$1 -> 0.87567084 | L7: 0.0054 | O7: 0.0016 | R7: 0.429 | U7: 0.2
D8: 45904 | E8: 四 | F8: 100.7 | I8: =F8/$C$1 -> 0.90071556 | L8: 0.00627 | O8: 0.003 | R8: 0.429 | U8: 0.2
D9: 45905 | E9: 五 | F9: 99.5 | I9: =F9/$C$1 -> 0.88998211 | L9: 0.00495 | O9: 0.0021 | R9: 0.429 | U9: 0.3
D10: 45906 | E10: 六 | F10: 95.9 | I10: =F10/$C$1 -> 0.85778175 | L10: 0.00848 | O10: 0.0055 | R10: 0.429 | U10: 0.3
D11: 45907 | E11: 日 | F11: 94.8 | I11: =F11/$C$1 -> 0.84794275 | L11: 0.00464 | O11: 0.0021 | R11: 0.429 | U11: 0.4
D12: 45908 | E12: 一 | F12: 103.1 | I12: =F12/$C$1 -> 0.92218247 | L12: 0.00447 | O12: 0.0037 | R12: 0.429 | U12: 0.4
B13: 45917 | D13: 45909 | E13: 二 | F13: 103.6 | G13: =AVERAGE(F13:F19) -> 102.05714 | I13: =F13/$C$1 -> 0.92665474 | J13: =AVERAGE(I13:I19) -> 0.91285459 | L13: 0.00988 | M13: =AVERAGE(L13:L19) -> 0.0052857143 | O13: 0.0021 | P13: =AVERAGE(O13:O19) -> 0.0047714286 | R13: 0.429 | S13: =AVERAGE(R13:R19) -> 0.429 | U13: 0.45 | V13: =AVERAGE(U13:U19) -> 0.47142857
D14: 45910 | E14: 三 | F14: 103.3 | I14: =F14/$C$1 -> 0.92397138 | L14: 0.00512 | O14: 0.0036 | R14: 0.429 | U14: 0.45
D15: 45911 | E15: 四 | F15: 102.4 | I15: =F15/$C$1 -> 0.91592129 | L15: 0.00487 | O15: 0.0045 | R15: 0.429 | U15: 0.45
D16: 45912 | E16: 五 | F16: 102.2 | I16: =F16/$C$1 -> 0.91413238 | L16: 0.00457 | O16: 0.0036 | R16: 0.429 | U16: 0.45
D17: 45913 | E17: 六 | F17: 101 | I17: =F17/$C$1 -> 0.90339893 | L17: 0.00415 | O17: 0.0049 | R17: 0.429 | U17: 0.5
D18: 45914 | E18: 日 | F18: 100.5 | I18: =F18/$C$1 -> 0.89892665 | L18: 0.00486 | O18: 0.0069 | R18: 0.429 | U18: 0.5
D19: 45915 | E19: 一 | F19: 101.4 | I19: =F19/$C$1 -> 0.90697674 | L19: 0.00355 | O19: 0.0078 | R19: 0.429 | U19: 0.5
B20: 45924 | D20: 45916 | E20: 二 | F20: 97.1 | G20: =AVERAGE(F20:F26) -> 98.428571 | I20: =F20/$C$1 -> 0.86851521 | J20: =AVERAGE(I20:I26) -> 0.88039867 | L20: 0.00858 | M20: =AVERAGE(L20:L26) -> 0.0093728571 | O20: 0.0049 | P20: =AVERAGE(O20:O26) -> 0.0027014286 | R20: 0.429 | S20: =AVERAGE(R20:R26) -> 0.429 | U20: 0.5 | V20: =AVERAGE(U20:U26) -> 0.5
D21: 45917 | E21: 三 | F21: 100.6 | I21: =F21/$C$1 -> 0.89982111 | L21: 0.00436 | O21: 0.0039 | R21: 0.429 | U21: 0.5
D22: 45918 | E22: 四 | F22: 96.2 | I22: =F22/$C$1 -> 0.86046512 | L22: 0.00377 | O22: 0.0039 | R22: 0.429 | U22: 0.5
D23: 45919 | E23: 五 | F23: 93.5 | I23: =F23/$C$1 -> 0.83631485 | L23: 0.01784 | O23: 1e-05 | R23: 0.429 | U23: 0.5
D24: 45920 | E24: 六 | F24: 94.2 | I24: =F24/$C$1 -> 0.84257603 | L24: 0.01105 | O24: 0.0036 | R24: 0.429 | U24: 0.5
D25: 45921 | E25: 日 | F25: 103.9 | I25: =F25/$C$1 -> 0.9293381 | L25: 0.00801 | O25: 0.002 | R25: 0.429 | U25: 0.5
D26: 45922 | E26: 一 | F26: 103.5 | I26: =F26/$C$1 -> 0.92576029 | L26: 0.012 | O26: 0.0006 | R26: 0.429 | U26: 0.5
B27: 45931 | D27: 45923 | E27: 二 | F27: 103.1 | G27: =AVERAGE(F27:F33) -> 98.714286 | I27: =F27/$C$1 -> 0.92218247 | J27: =AVERAGE(I27:I33) -> 0.88295426 | L27: 0.00759 | M27: =AVERAGE(L27:L33) -> 0.00964 | O27: 0.0019 | P27: =AVERAGE(O27:O33) -> 0.0019285714 | R27: 0.429 | S27: =AVERAGE(R27:R33) -> 0.429 | U27: 0.5 | V27: =AVERAGE(U27:U33) -> 0.60285714
D28: 45924 | E28: 三 | F28: 97.5 | I28: =F28/$C$1 -> 0.87209302 | L28: 0.00716 | O28: 0.0046 | R28: 0.429 | U28: 0.5
D29: 45925 | E29: 四 | F29: 100.8 | I29: =F29/$C$1 -> 0.90161002 | L29: 0.00394 | O29: 0.0024 | R29: 0.429 | U29: 0.55
D30: 45926 | E30: 五 | F30: 97.1 | I30: =F30/$C$1 -> 0.86851521 | L30: 0.00796 | O30: 0 | R30: 0.429 | U30: 0.6
D31: 45927 | E31: 六 | F31: 94.4 | I31: =F31/$C$1 -> 0.84436494 | L31: 0.01105 | O31: 0.0003 | R31: 0.429 | U31: 0.67
D32: 45928 | E32: 日 | F32: 97.9 | I32: =F32/$C$1 -> 0.87567084 | L32: 0.02622 | O32: 0.0032 | R32: 0.429 | U32: 0.7
D33: 45929 | E33: 一 | F33: 100.2 | I33: =F33/$C$1 -> 0.89624329 | L33: 0.00356 | O33: 0.0011 | R33: 0.429 | U33: 0.7
D34: 45930 | E34: 二 | F34: 105.2 | I34: =F34/$C$1 -> 0.94096601 | L34: 0.0065 | O34: 0.0199 | S34: 0.429 | U34: 0.7
I35: =F35/$C$1 -> 0
I36: =F36/$C$1 -> 0
G37: =AVERAGE(F37:F43) -> #DIV/0! | I37: =F37/$C$1 -> 0 | J37: =AVERAGE(I37:I43) -> 0 | M37: =AVERAGE(L37:L43) -> #DIV/0! | P37: =AVERAGE(O37:O43) -> #DIV/0! | S37: =AVERAGE(R37:R43) -> #DIV/0! | V37: =AVERAGE(U37:U43) -> #DIV/0!
I38: =F38/$C$1 -> 0
I39: =F39/$C$1 -> 0
I40: =F40/$C$1 -> 0
...

Sheet （３）業績構成比
B2: （3）業績構成比
B3: 資料繳交日 | C3: 月份 | D3: 日期 | F3: 營業額 | I3: 品類業績
I4: 熱食義麵 | K4: 季節調理麵 | M4: 微波小吃
F5: 日 | G5: 週累積 | H5: 月累積 | I5: 一配 | K5: 一配 | M5: 一配
I6: 業績(元) | J6: 比例(%) | K6: 業績(元) | L6: 比例(%) | M6: 業績(元) | N6: 比例(%)
C7: 九 | D7: 45901 | E7: 一 | F7: =SUM(I7,K7,M7) -> 2893619.4 | G7: =SUM(F7) -> 2893619.4 | H7: =SUM(F7:F36) -> 75756496 | I7: 2647777.4 | J7: =I7/F7 -> 0.91503997 | L7: =K7/F7 -> 0 | M7: 245842 | N7: =M7/F7 -> 0.084960034
B8: 45910 | D8: 45902 | E8: 二 | F8: =SUM(I8,K8,M8) -> 2792067.1 | G8: =SUM(F8:F14) -> 17039197 | I8: 2539987.1 | J8: =I8/F8 -> 0.90971564 | L8: =K8/F8 -> 0 | M8: 252080 | N8: =M8/F8 -> 0.090284364
D9: 45903 | E9: 三 | F9: =SUM(I9,K9,M9) -> 2693780.1 | I9: 2435976.1 | J9: =I9/F9 -> 0.90429657 | L9: =K9/F9 -> 0 | M9: 257804 | N9: =M9/F9 -> 0.09570343
D10: 45904 | E10: 四 | F10: =SUM(I10,K10,M10) -> 2413419.8 | I10: 2170630.8 | J10: =I10/F10 -> 0.89940043 | L10: =K10/F10 -> 0 | M10: 242789 | N10: =M10/F10 -> 0.10059957
D11: 45905 | E11: 五 | F11: =SUM(I11,K11,M11) -> 1867882 | I11: 1668669 | J11: =I11/F11 -> 0.89334819 | L11: =K11/F11 -> 0 | M11: 199213 | N11: =M11/F11 -> 0.10665181
D12: 45906 | E12: 六 | F12: =SUM(I12,K12,M12) -> 1984347.4 | I12: 1778186.4 | J12: =I12/F12 -> 0.8961064 | L12: =K12/F12 -> 0 | M12: 206161 | N12: =M12/F12 -> 0.1038936
D13: 45907 | E13: 日 | F13: =SUM(I13,K13,M13) -> 2634378.9 | I13: 2375462.9 | J13: =I13/F13 -> 0.90171649 | L13: =K13/F13 -> 0 | M13: 258916 | N13: =M13/F13 -> 0.098283507
D14: 45908 | E14: 一 | F14: =SUM(I14,K14,M14) -> 2653322 | I14: 2398288 | J14: =I14/F14 -> 0.90388125 | L14: =K14/F14 -> 0 | M14: 255034 | N14: =M14/F14 -> 0.096118751
B15: 45917 | D15: 45909 | E15: 二 | F15: =SUM(I15,K15,M15) -> 2549415.1 | G15: =SUM(F15:F21) -> 16573497 | I15: 2296014.2 | J15: =I15/F15 -> 0.90060431 | L15: =K15/F15 -> 0 | M15: 253400.88 | N15: =M15/F15 -> 0.099395694
D16: 45910 | E16: 三 | F16: =SUM(I16,K16,M16) -> 2484298.8 | I16: 2233792.7 | J16: =I16/F16 -> 0.89916425 | L16: =K16/F16 -> 0 | M16: 250506.12 | N16: =M16/F16 -> 0.10083575
D17: 45911 | E17: 四 | F17: =SUM(I17,K17,M17) -> 2285316.2 | I17: 2055144.4 | J17: =I17/F17 -> 0.89928233 | L17: =K17/F17 -> 0 | M17: 230171.72 | N17: =M17/F17 -> 0.10071767
D18: 45912 | E18: 五 | F18: =SUM(I18,K18,M18) -> 1942536.6 | I18: 1741782.6 | J18: =I18/F18 -> 0.89665372 | L18: =K18/F18 -> 0 | M18: 200753.93 | N18: =M18/F18 -> 0.10334628
D19: 45913 | E19: 六 | F19: =SUM(I19,K19,M19) -> 2052730.4 | I19: 1839342.2 | J19: =I19/F19 -> 0.89604668 | L19: =K19/F19 -> 0 | M19: 213388.14 | N19: =M19/F19 -> 0.10395332
D20: 45914 | E20: 日 | F20: =SUM(I20,K20,M20) -> 2615131.3 | I20: 2354551.3 | J20: =I20/F20 -> 0.90035681 | L20: =K20/F20 -> 0 | M20: 260580.02 | N20: =M20/F20 -> 0.099643188
D21: 45915 | E21: 一 | F21: =SUM(I21,K21,M21) -> 2644068.6 | I21: 2385129.8 | J21: =I21/F21 -> 0.90206803 | L21: =K21/F21 -> 0 | M21: 258938.86 | N21: =M21/F21 -> 0.097931974
B22: 45924 | D22: 45916 | E22: 二 | F22: =SUM(I22,K22,M22) -> 3351676 | G22: =SUM(F22:F28) -> 19143932 | I22: 3112819 | J22: =I22/F22 -> 0.92873506 | L22: =K22/F22 -> 0 | M22: 238856.98 | N22: =M22/F22 -> 0.071264938
D23: 45917 | E23: 三 | F23: =SUM(I23,K23,M23) -> 3025640.2 | I23: 2790836.3 | J23: =I23/F23 -> 0.92239531 | L23: =K23/F23 -> 0 | M23: 234803.87 | N23: =M23/F23 -> 0.07760469
D24: 45918 | E24: 四 | F24: =SUM(I24,K24,M24) -> 2779379.6 | I24: 2559560.6 | J24: =I24/F24 -> 0.92091077 | L24: =K24/F24 -> 0 | M24: 219818.98 | N24: =M24/F24 -> 0.079089226
D25: 45919 | E25: 五 | F25: =SUM(I25,K25,M25) -> 2046591.7 | I25: 1860368.1 | J25: =I25/F25 -> 0.90900796 | L25: =K25/F25 -> 0 | M25: 186223.55 | N25: =M25/F25 -> 0.09099204
D26: 45920 | E26: 六 | F26: =SUM(I26,K26,M26) -> 2230582.5 | I26: 2028753.4 | J26: =I26/F26 -> 0.90951729 | L26: =K26/F26 -> 0 | M26: 201829.16 | N26: =M26/F26 -> 0.090482713
D27: 45921 | E27: 日 | F27: =SUM(I27,K27,M27) -> 2856812 | I27: 2603708.1 | J27: =I27/F27 -> 0.91140339 | L27: =K27/F27 -> 0 | M27: 253103.86 | N27: =M27/F27 -> 0.088596611
D28: 45922 | E28: 一 | F28: =SUM(I28,K28,M28) -> 2853250 | I28: 2610602.3 | J28: =I28/F28 -> 0.91495746 | L28: =K28/F28 -> 0 | M28: 242647.62 | N28: =M28/F28 -> 0.085042539
B29: 45931 | D29: 45923 | E29: 二 | F29: =SUM(I29,K29,M29) -> 2623577.6 | G29: =SUM(F29:F35) -> 16941839 | I29: 2388726.4 | J29: =I29/F29 -> 0.91048438 | L29: =K29/F29 -> 0 | M29: 234851.18 | N29: =M29/F29 -> 0.089515623
D30: 45924 | E30: 三 | F30: =SUM(I30,K30,M30) -> 2681520.5 | I30: 2442324.6 | J30: =I30/F30 -> 0.91079839 | L30: =K30/F30 -> 0 | M30: 239195.95 | N30: =M30/F30 -> 0.089201611
D31: 45925 | E31: 四 | F31: =SUM(I31,K31,M31) -> 2459851.9 | I31: 2245202.9 | J31: =I31/F31 -> 0.91273904 | L31: =K31/F31 -> 0 | M31: 214649.03 | N31: =M31/F31 -> 0.087260957
D32: 45926 | E32: 五 | F32: =SUM(I32,K32,M32) -> 1996517.2 | I32: 1833726.4 | J32: =I32/F32 -> 0.91846262 | L32: =K32/F32 -> 0 | M32: 162790.77 | N32: =M32/F32 -> 0.081537375
D33: 45927 | E33: 六 | F33: =SUM(I33,K33,M33) -> 2053881.9 | I33: 1888471.4 | J33: =I33/F33 -> 0.91946443 | L33: =K33/F33 -> 0 | M33: 165410.56 | N33: =M33/F33 -> 0.080535575
D34: 45928 | E34: 日 | F34: =SUM(I34,K34,M34) -> 2260837.3 | I34: 2086033.1 | J34: =I34/F34 -> 0.92268162 | L34: =K34/F34 -> 0 | M34: 174804.27 | N34: =M34/F34 -> 0.077318376
D35: 45929 | E35: 一 | F35: =SUM(I35,K35,M35) -> 2865652.3 | I35: 2615939.3 | J35: =I35/F35 -> 0.91285998 | L35: =K35/F35 -> 0 | M35: 249712.99 | N35: =M35/F35 -> 0.087140018
D36: 45930 | E36: 二 | F36: =SUM(I36,K36,M36) -> 3164412 | I36: 2830050 | J36: =I36/F36 -> 0.89433677 | L36: =K36/F36 -> 0 | M36: 334362 | N36: =M36/F36 -> 0.10566323

Sheet （４）訂單數量構成比
B2: （4）訂單數量構成比
B3: 資料繳交日 | C3: 月份 | D3: 日期 | F3: 訂單量 | I3: 品類訂單量
I4: 熱食義麵 | K4: 季節調理麵 | M4: 微波小吃
F5: 日 | G5: 週累積 | H5: 月累積 | I5: 一配 | K5: 一配 | M5: 一配
I6: 訂單數 | J6: 比例(%) | K6: 訂單數 | L6: 比例(%) | M6: 訂單數 | N6: 比例(%)
B7: 45910 | C7: 九 | D7: 45901 | E7: 一 | F7: =SUM(I7,K7,M7) -> 58795 | G7: =SUM(F7) -> 58795 | H7: =SUM(F7:F36) -> 1533362 | I7: 49909 | J7: =I7/F7 -> 0.8488647 | L7: =K7/F7 -> 0 | M7: 8886 | N7: =M7/F7 -> 0.1511353
D8: 45902 | E8: 二 | F8: =SUM(I8,K8,M8) -> 56974 | G8: =SUM(F8:F14) -> 350126 | I8: 47868 | J8: =I8/F8 -> 0.84017271 | L8: =K8/F8 -> 0 | M8: 9106 | N8: =M8/F8 -> 0.15982729
D9: 45903 | E9: 三 | F9: =SUM(I9,K9,M9) -> 55119 | I9: 45818 | J9: =I9/F9 -> 0.83125601 | L9: =K9/F9 -> 0 | M9: 9301 | N9: =M9/F9 -> 0.16874399
D10: 45904 | E10: 四 | F10: =SUM(I10,K10,M10) -> 49608 | I10: 40852 | J10: =I10/F10 -> 0.82349621 | L10: =K10/F10 -> 0 | M10: 8756 | N10: =M10/F10 -> 0.17650379
D11: 45905 | E11: 五 | F11: =SUM(I11,K11,M11) -> 38609 | I11: 31431 | J11: =I11/F11 -> 0.8140848 | L11: =K11/F11 -> 0 | M11: 7178 | N11: =M11/F11 -> 0.1859152
D12: 45906 | E12: 六 | F12: =SUM(I12,K12,M12) -> 40921 | I12: 33483 | J12: =I12/F12 -> 0.81823514 | L12: =K12/F12 -> 0 | M12: 7438 | N12: =M12/F12 -> 0.18176486
D13: 45907 | E13: 日 | F13: =SUM(I13,K13,M13) -> 54263 | I13: 44907 | J13: =I13/F13 -> 0.82758049 | L13: =K13/F13 -> 0 | M13: 9356 | N13: =M13/F13 -> 0.17241951
D14: 45908 | E14: 一 | F14: =SUM(I14,K14,M14) -> 54632 | I14: 45410 | J14: =I14/F14 -> 0.83119783 | L14: =K14/F14 -> 0 | M14: 9222 | N14: =M14/F14 -> 0.16880217
B15: 45917 | D15: 45909 | E15: 二 | F15: =SUM(I15,K15,M15) -> 54526 | G15: =SUM(F15:F21) -> 344404 | I15: 45367 | J15: =I15/F15 -> 0.83202509 | L15: =K15/F15 -> 0 | M15: 9159 | N15: =M15/F15 -> 0.16797491
D16: 45910 | E16: 三 | F16: =SUM(I16,K16,M16) -> 51467 | I16: 42416 | J16: =I16/F16 -> 0.82413974 | L16: =K16/F16 -> 0 | M16: 9051 | N16: =M16/F16 -> 0.17586026
D17: 45911 | E17: 四 | F17: =SUM(I17,K17,M17) -> 47272 | I17: 38956 | J17: =I17/F17 -> 0.82408191 | L17: =K17/F17 -> 0 | M17: 8316 | N17: =M17/F17 -> 0.17591809
D18: 45912 | E18: 五 | F18: =SUM(I18,K18,M18) -> 40144 | I18: 32903 | J18: =I18/F18 -> 0.81962435 | L18: =K18/F18 -> 0 | M18: 7241 | N18: =M18/F18 -> 0.18037565
D19: 45913 | E19: 六 | F19: =SUM(I19,K19,M19) -> 42409 | I19: 34706 | J19: =I19/F19 -> 0.81836403 | L19: =K19/F19 -> 0 | M19: 7703 | N19: =M19/F19 -> 0.18163597
D20: 45914 | E20: 日 | F20: =SUM(I20,K20,M20) -> 54004 | I20: 44584 | J20: =I20/F20 -> 0.82556848 | L20: =K20/F20 -> 0 | M20: 9420 | N20: =M20/F20 -> 0.17443152
D21: 45915 | E21: 一 | F21: =SUM(I21,K21,M21) -> 54582 | I21: 45217 | J21: =I21/F21 -> 0.82842329 | L21: =K21/F21 -> 0 | M21: 9365 | N21: =M21/F21 -> 0.17157671
B22: 45924 | D22: 45916 | E22: 二 | F22: =SUM(I22,K22,M22) -> 52594 | G22: =SUM(F22:F28) -> 376041 | I22: 43941 | J22: =I22/F22 -> 0.83547553 | L22: =K22/F22 -> 0 | M22: 8653 | N22: =M22/F22 -> 0.16452447
D23: 45917 | E23: 三 | F23: =SUM(I23,K23,M23) -> 61614 | I23: 53109 | J23: =I23/F23 -> 0.86196319 | L23: =K23/F23 -> 0 | M23: 8505 | N23: =M23/F23 -> 0.13803681
D24: 45918 | E24: 四 | F24: =SUM(I24,K24,M24) -> 56703 | I24: 48748 | J24: =I24/F24 -> 0.8597076 | L24: =K24/F24 -> 0 | M24: 7955 | N24: =M24/F24 -> 0.1402924
D25: 45919 | E25: 五 | F25: =SUM(I25,K25,M25) -> 42093 | I25: 35357 | J25: =I25/F25 -> 0.83997339 | L25: =K25/F25 -> 0 | M25: 6736 | N25: =M25/F25 -> 0.16002661
D26: 45920 | E26: 六 | F26: =SUM(I26,K26,M26) -> 45817 | I26: 38524 | J26: =I26/F26 -> 0.84082328 | L26: =K26/F26 -> 0 | M26: 7293 | N26: =M26/F26 -> 0.15917672
D27: 45921 | E27: 日 | F27: =SUM(I27,K27,M27) -> 58722 | I27: 49564 | J27: =I27/F27 -> 0.84404482 | L27: =K27/F27 -> 0 | M27: 9158 | N27: =M27/F27 -> 0.15595518
D28: 45922 | E28: 一 | F28: =SUM(I28,K28,M28) -> 58498 | I28: 49713 | J28: =I28/F28 -> 0.84982393 | L28: =K28/F28 -> 0 | M28: 8785 | N28: =M28/F28 -> 0.15017607
B29: 45931 | D29: 45923 | E29: 二 | F29: =SUM(I29,K29,M29) -> 54036 | G29: =SUM(F29:F35) -> 347276 | I29: 45526 | J29: =I29/F29 -> 0.8425124 | L29: =K29/F29 -> 0 | M29: 8510 | N29: =M29/F29 -> 0.1574876
D30: 45924 | E30: 三 | F30: =SUM(I30,K30,M30) -> 55176 | I30: 46509 | J30: =I30/F30 -> 0.84292084 | L30: =K30/F30 -> 0 | M30: 8667 | N30: =M30/F30 -> 0.15707916
D31: 45925 | E31: 四 | F31: =SUM(I31,K31,M31) -> 50523 | I31: 42752 | J31: =I31/F31 -> 0.84618886 | L31: =K31/F31 -> 0 | M31: 7771 | N31: =M31/F31 -> 0.15381114
D32: 45926 | E32: 五 | F32: =SUM(I32,K32,M32) -> 40771 | I32: 34877 | J32: =I32/F32 -> 0.85543646 | L32: =K32/F32 -> 0 | M32: 5894 | N32: =M32/F32 -> 0.14456354
D33: 45927 | E33: 六 | F33: =SUM(I33,K33,M33) -> 41899 | I33: 35916 | J33: =I33/F33 -> 0.85720423 | L33: =K33/F33 -> 0 | M33: 5983 | N33: =M33/F33 -> 0.14279577
D34: 45928 | E34: 日 | F34: =SUM(I34,K34,M34) -> 46083 | I34: 39755 | J34: =I34/F34 -> 0.86268255 | L34: =K34/F34 -> 0 | M34: 6328 | N34: =M34/F34 -> 0.13731745
D35: 45929 | E35: 一 | F35: =SUM(I35,K35,M35) -> 58788 | I35: 49741 | J35: =I35/F35 -> 0.84610805 | L35: =K35/F35 -> 0 | M35: 9047 | N35: =M35/F35 -> 0.15389195
D36: 45930 | E36: 二 | F36: =SUM(I36,K36,M36) -> 56720 | G36: =SUM(F36:F42) -> 56720 | I36: 44702 | J36: =I36/F36 -> 0.78811707 | L36: =K36/F36 -> 0 | M36: 12018 | N36: =M36/F36 -> 0.21188293

Sheet （５-1）品群別人時生產性（熱食義麵）
B1: 月平均人時性 | C1: =AVERAGE(L7,L30,L53,L73,L96,L119) -> 95.245448
B2: 產線配置圖－每週更新 | N2: 資料繳交 | O2: 日期 | AT2: 45901
P3: 二 | U3: 三 | Z3: 四 | AE3: 五 | AJ3: 六 | AO3: 日 | AT3: 一
B4: 品群 | C4: 商品名稱 | E4: 計畫 | H4: 平均人時性 | I4: 實績 | L4: 平均人時性 | M4: 排名 | O4: 日報 | P4: 實際 | T4: 平均人時性 | U4: 實際 | Y4: 平均人時性 | Z4: 實際 | AD4: 平均人時性 | AE4: 實際 | AI4: 平均人時性 | AJ4: 實際 | AN4: 平均人時性 | AO4: 實際 | AS4: 平均人時性 | AT4: 實際 | AX4: 平均人時性
E5: 產線配置圖 | I5: 產線配置圖 | P5: 生產實績 | U5: 生產實績 | Z5: 生產實績 | AE5: 生產實績 | AJ5: 生產實績 | AO5: 生產實績 | AT5: 生產實績
E6: 人數 | F6: 產能／時 | G6: 人時性 | I6: 人數 | J6: 產能／時 | K6: 人時性 | P6: 人數 | Q6: 產能／時 | R6: 人時性 | S6: 排名 | U6: 人數 | V6: 產能／時 | W6: 人時性 | X6: 排名 | Z6: 人數 | AA6: 產能／時 | AB6: 人時性 | AC6: 排名 | AE6: 人數 | AF6: 產能／時 | AG6: 人時性 | AH6: 排名 | AJ6: 人數 | AK6: 產能／時 | AL6: 人時性 | AM6: 排名 | AO6: 人數 | AP6: 產能／時 | AQ6: 人時性 | AR6: 排名 | AT6: 人數 | AU6: 產能／時 | AV6: 人時性 | AW6: 排名
B7: 熱食義麵 | C7: 1 | D7: 義式蕃茄起司義大利麵 | E7: =VLOOKUP(D7,'09產線配置圖'!$A$2:$C$25,2,0) -> 12 | F7: =VLOOKUP(D7,'09產線配置圖'!$A$2:$C$25,3,0) -> 2000 | G7: =F7/E7 -> 166.66667 | H7: =AVERAGE(G7:G24) -> 107.65416 | I7: =AVERAGE(P7,U7,Z7,AE7,AJ7,AO7,AT7) -> 12 | J7: =AVERAGE(Q7,V7,AA7,AF7,AK7,AP7,AU7) -> 1898 | K7: =AVERAGE(AV7) -> 158.16667 | L7: =IFERROR(AVERAGE(K7:K24),"-") -> 93.700303 | M7: =RANK(K7, K$7:$K$24) -> 1 | R7: =Q7/P7 -> #DIV/0! | S7: =RANK(R7, R$7:R$24) -> #DIV/0! | T7: =AVERAGE(R7:R24) -> #DIV/0! | W7: =V7/U7 -> #DIV/0! | X7: =RANK(W7, W$7:W$24) -> #DIV/0! | Y7: =AVERAGE(W7:W24) -> #DIV/0! | AB7: =AA7/Z7 -> #DIV/0! | AC7: =RANK(AB7, AB$7:AB$24) -> #DIV/0! | AD7: =AVERAGE(AB7:AB24) -> #DIV/0! | AG7: =AF7/AE7 -> #DIV/0! | AH7: =RANK(AG7, AG$7:AG$24) -> #DIV/0! | AI7: =AVERAGE(AG7:AG24) -> #DIV/0! | AL7: =AK7/AJ7 -> #DIV/0! | AM7: =RANK(AL7, AL$7:AL$24) -> #DIV/0! | AN7: =AVERAGE(AL7:AL24) -> #DIV/0! | AQ7: =AP7/AO7 -> #DIV/0! | AR7: =RANK(AQ7, AQ$7:AQ$24) -> #DIV/0! | AS7: =AVERAGE(AQ7:AQ24) -> #DIV/0! | AT7: 12 | AU7: 1898 | AV7: =AU7/AT7 -> 158.16667 | AW7: =RANK(AV7, AV$7:AV$24) -> 1 | AX7: =AVERAGE(AV7:AV24) -> 93.700303
C8: 2 | D8: 奶油培根義大利麵 | E8: =VLOOKUP(D8,'09產線配置圖'!$A$2:$C$25,2,0) -> 13 | F8: =VLOOKUP(D8,'09產線配置圖'!$A$2:$C$25,3,0) -> 2000 | G8: =F8/E8 -> 153.84615 | I8: =AVERAGE(P8,U8,Z8,AE8,AJ8,AO8,AT8) -> 13 | J8: =AVERAGE(Q8,V8,AA8,AF8,AK8,AP8,AU8) -> 1877 | K8: =AVERAGE(AV8) -> 144.38462 | M8: =RANK(K8, K$7:$K$24) -> 2 | R8: =Q8/P8 -> #DIV/0! | S8: =RANK(R8, R$7:R$24) -> #DIV/0! | W8: =V8/U8 -> #DIV/0! | X8: =RANK(W8, W$7:W$24) -> #DIV/0! | AB8: =AA8/Z8 -> #DIV/0! | AC8: =RANK(AB8, AB$7:AB$24) -> #DIV/0! | AG8: =AF8/AE8 -> #DIV/0! | AH8: =RANK(AG8, AG$7:AG$24) -> #DIV/0! | AL8: =AK8/AJ8 -> #DIV/0! | AM8: =RANK(AL8, AL$7:AL$24) -> #DIV/0! | AQ8: =AP8/AO8 -> #DIV/0! | AR8: =RANK(AQ8, AQ$7:AQ$24) -> #DIV/0! | AT8: 13 | AU8: 1877 | AV8: =AU8/AT8 -> 144.38462 | AW8: =RANK(AV8, AV$7:AV$24) -> 2
C9: 3 | D9: 熱那亞青醬義大利麵 | E9: =VLOOKUP(D9,'09產線配置圖'!$A$2:$C$25,2,0) -> 16 | F9: =VLOOKUP(D9,'09產線配置圖'!$A$2:$C$25,3,0) -> 1915 | G9: =F9/E9 -> 119.6875 | I9: =AVERAGE(P9,U9,Z9,AE9,AJ9,AO9,AT9) -> 16 | J9: =AVERAGE(Q9,V9,AA9,AF9,AK9,AP9,AU9) -> 1816 | K9: =AVERAGE(AV9) -> 113.5 | M9: =RANK(K9, K$7:$K$24) -> 3 | R9: =Q9/P9 -> #DIV/0! | S9: =RANK(R9, R$7:R$24) -> #DIV/0! | W9: =V9/U9 -> #DIV/0! | X9: =RANK(W9, W$7:W$24) -> #DIV/0! | AB9: =AA9/Z9 -> #DIV/0! | AC9: =RANK(AB9, AB$7:AB$24) -> #DIV/0! | AG9: =AF9/AE9 -> #DIV/0! | AH9: =RANK(AG9, AG$7:AG$24) -> #DIV/0! | AL9: =AK9/AJ9 -> #DIV/0! | AM9: =RANK(AL9, AL$7:AL$24) -> #DIV/0! | AQ9: =AP9/AO9 -> #DIV/0! | AR9: =RANK(AQ9, AQ$7:AQ$24) -> #DIV/0! | AT9: 16 | AU9: 1816 | AV9: =AU9/AT9 -> 113.5 | AW9: =RANK(AV9, AV$7:AV$24) -> 3
C10: 4 | D10: 焗烤起司雙饗筆尖麵 | E10: =VLOOKUP(D10,'09產線配置圖'!$A$2:$C$25,2,0) -> 18 | F10: =VLOOKUP(D10,'09產線配置圖'!$A$2:$C$25,3,0) -> 1565 | G10: =F10/E10 -> 86.944444 | I10: =AVERAGE(P10,U10,Z10,AE10,AJ10,AO10,AT10) -> 17 | J10: =AVERAGE(Q10,V10,AA10,AF10,AK10,AP10,AU10) -> 1443 | K10: =AVERAGE(AV10) -> 84.882353 | M10: =RANK(K10, K$7:$K$24) -> 10 | R10: =Q10/P10 -> #DIV/0! | S10: =RANK(R10, R$7:R$24) -> #DIV/0! | W10: =V10/U10 -> #DIV/0! | X10: =RANK(W10, W$7:W$24) -> #DIV/0! | AB10: =AA10/Z10 -> #DIV/0! | AC10: =RANK(AB10, AB$7:AB$24) -> #DIV/0! | AG10: =AF10/AE10 -> #DIV/0! | AH10: =RANK(AG10, AG$7:AG$24) -> #DIV/0! | AL10: =AK10/AJ10 -> #DIV/0! | AM10: =RANK(AL10, AL$7:AL$24) -> #DIV/0! | AQ10: =AP10/AO10 -> #DIV/0! | AR10: =RANK(AQ10, AQ$7:AQ$24) -> #DIV/0! | AT10: 17 | AU10: 1443 | AV10: =AU10/AT10 -> 84.882353 | AW10: =RANK(AV10, AV$7:AV$24) -> 10
C11: 5 | D11: 白酒蛤蜊義大利麵 | E11: =VLOOKUP(D11,'09產線配置圖'!$A$2:$C$25,2,0) -> 13 | F11: =VLOOKUP(D11,'09產線配置圖'!$A$2:$C$25,3,0) -> 2000 | G11: =F11/E11 -> 153.84615 | I11: =AVERAGE(P11,U11,Z11,AE11,AJ11,AO11,AT11) -> 13 | J11: =AVERAGE(Q11,V11,AA11,AF11,AK11,AP11,AU11) -> 1271 | K11: =AVERAGE(AV11) -> 97.769231 | M11: =RANK(K11, K$7:$K$24) -> 5 | R11: =Q11/P11 -> #DIV/0! | S11: =RANK(R11, R$7:R$24) -> #DIV/0! | W11: =V11/U11 -> #DIV/0! | X11: =RANK(W11, W$7:W$24) -> #DIV/0! | AB11: =AA11/Z11 -> #DIV/0! | AC11: =RANK(AB11, AB$7:AB$24) -> #DIV/0! | AG11: =AF11/AE11 -> #DIV/0! | AH11: =RANK(AG11, AG$7:AG$24) -> #DIV/0! | AL11: =AK11/AJ11 -> #DIV/0! | AM11: =RANK(AL11, AL$7:AL$24) -> #DIV/0! | AQ11: =AP11/AO11 -> #DIV/0! | AR11: =RANK(AQ11, AQ$7:AQ$24) -> #DIV/0! | AT11: 13 | AU11: 1271 | AV11: =AU11/AT11 -> 97.769231 | AW11: =RANK(AV11, AV$7:AV$24) -> 5
C12: 6 | D12: 韓式起司炸雞義大利麵 | E12: =VLOOKUP(D12,'09產線配置圖'!$A$2:$C$25,2,0) -> 16 | F12: =VLOOKUP(D12,'09產線配置圖'!$A$2:$C$25,3,0) -> 1895 | G12: =F12/E12 -> 118.4375 | I12: =AVERAGE(P12,U12,Z12,AE12,AJ12,AO12,AT12) -> 15 | J12: =AVERAGE(Q12,V12,AA12,AF12,AK12,AP12,AU12) -> 1529 | K12: =AVERAGE(AV12) -> 101.93333 | M12: =RANK(K12, K$7:$K$24) -> 4 | R12: =Q12/P12 -> #DIV/0! | S12: =RANK(R12, R$7:R$24) -> #DIV/0! | W12: =V12/U12 -> #DIV/0! | X12: =RANK(W12, W$7:W$24) -> #DIV/0! | AB12: =AA12/Z12 -> #DIV/0! | AC12: =RANK(AB12, AB$7:AB$24) -> #DIV/0! | AG12: =AF12/AE12 -> #DIV/0! | AH12: =RANK(AG12, AG$7:AG$24) -> #DIV/0! | AL12: =AK12/AJ12 -> #DIV/0! | AM12: =RANK(AL12, AL$7:AL$24) -> #DIV/0! | AQ12: =AP12/AO12 -> #DIV/0! | AR12: =RANK(AQ12, AQ$7:AQ$24) -> #DIV/0! | AT12: 15 | AU12: 1529 | AV12: =AU12/AT12 -> 101.93333 | AW12: =RANK(AV12, AV$7:AV$24) -> 4
C13: 7 | D13: 蒜香蝦蝦義大利麵 | E13: =VLOOKUP(D13,'09產線配置圖'!$A$2:$C$25,2,0) -> 16 | F13: =VLOOKUP(D13,'09產線配置圖'!$A$2:$C$25,3,0) -> 1552 | G13: =F13/E13 -> 97 | I13: =AVERAGE(P13,U13,Z13,AE13,AJ13,AO13,AT13) -> 15 | J13: =AVERAGE(Q13,V13,AA13,AF13,AK13,AP13,AU13) -> 1343 | K13: =AVERAGE(AV13) -> 89.533333 | M13: =RANK(K13, K$7:$K$24) -> 6 | R13: =Q13/P13 -> #DIV/0! | S13: =RANK(R13, R$7:R$24) -> #DIV/0! | W13: =V13/U13 -> #DIV/0! | X13: =RANK(W13, W$7:W$24) -> #DIV/0! | AB13: =AA13/Z13 -> #DIV/0! | AC13: =RANK(AB13, AB$7:AB$24) -> #DIV/0! | AG13: =AF13/AE13 -> #DIV/0! | AH13: =RANK(AG13, AG$7:AG$24) -> #DIV/0! | AL13: =AK13/AJ13 -> #DIV/0! | AM13: =RANK(AL13, AL$7:AL$24) -> #DIV/0! | AQ13: =AP13/AO13 -> #DIV/0! | AR13: =RANK(AQ13, AQ$7:AQ$24) -> #DIV/0! | AT13: 15 | AU13: 1343 | AV13: =AU13/AT13 -> 89.533333 | AW13: =RANK(AV13, AV$7:AV$24) -> 6
C14: 8 | D14: 焗奶油扇貝筆尖麵 | E14: =VLOOKUP(D14,'09產線配置圖'!$A$2:$C$25,2,0) -> 15 | F14: =VLOOKUP(D14,'09產線配置圖'!$A$2:$C$25,3,0) -> 1565 | G14: =F14/E14 -> 104.33333 | I14: =AVERAGE(P14,U14,Z14,AE14,AJ14,AO14,AT14) -> 14 | J14: =AVERAGE(Q14,V14,AA14,AF14,AK14,AP14,AU14) -> 1241 | K14: =AVERAGE(AV14) -> 88.642857 | M14: =RANK(K14, K$7:$K$24) -> 7 | R14: =Q14/P14 -> #DIV/0! | S14: =RANK(R14, R$7:R$24) -> #DIV/0! | W14: =V14/U14 -> #DIV/0! | X14: =RANK(W14, W$7:W$24) -> #DIV/0! | AB14: =AA14/Z14 -> #DIV/0! | AC14: =RANK(AB14, AB$7:AB$24) -> #DIV/0! | AG14: =AF14/AE14 -> #DIV/0! | AH14: =RANK(AG14, AG$7:AG$24) -> #DIV/0! | AL14: =AK14/AJ14 -> #DIV/0! | AM14: =RANK(AL14, AL$7:AL$24) -> #DIV/0! | AQ14: =AP14/AO14 -> #DIV/0! | AR14: =RANK(AQ14, AQ$7:AQ$24) -> #DIV/0! | AT14: 14 | AU14: 1241 | AV14: =AU14/AT14 -> 88.642857 | AW14: =RANK(AV14, AV$7:AV$24) -> 7
C15: 9 | D15: 拿坡里義大利麵 | E15: =VLOOKUP(D15,'09產線配置圖'!$A$2:$C$25,2,0) -> 16 | F15: =VLOOKUP(D15,'09產線配置圖'!$A$2:$C$25,3,0) -> 1390 | G15: =F15/E15 -> 86.875 | I15: =AVERAGE(P15,U15,Z15,AE15,AJ15,AO15,AT15) -> 15 | J15: =AVERAGE(Q15,V15,AA15,AF15,AK15,AP15,AU15) -> 856 | K15: =AVERAGE(AV15) -> 57.066667 | M15: =RANK(K15, K$7:$K$24) -> 15 | R15: =Q15/P15 -> #DIV/0! | S15: =RANK(R15, R$7:R$24) -> #DIV/0! | W15: =V15/U15 -> #DIV/0! | X15: =RANK(W15, W$7:W$24) -> #DIV/0! | AB15: =AA15/Z15 -> #DIV/0! | AC15: =RANK(AB15, AB$7:AB$24) -> #DIV/0! | AG15: =AF15/AE15 -> #DIV/0! | AH15: =RANK(AG15, AG$7:AG$24) -> #DIV/0! | AL15: =AK15/AJ15 -> #DIV/0! | AM15: =RANK(AL15, AL$7:AL$24) -> #DIV/0! | AQ15: =AP15/AO15 -> #DIV/0! | AR15: =RANK(AQ15, AQ$7:AQ$24) -> #DIV/0! | AT15: 15 | AU15: 856 | AV15: =AU15/AT15 -> 57.066667 | AW15: =RANK(AV15, AV$7:AV$24) -> 15
C16: 10 | D16: 奶油明太子細扁麵 | E16: =VLOOKUP(D16,'09產線配置圖'!$A$2:$C$25,2,0) -> 19 | F16: =VLOOKUP(D16,'09產線配置圖'!$A$2:$C$25,3,0) -> 1565 | G16: =F16/E16 -> 82.368421 | I16: =AVERAGE(P16,U16,Z16,AE16,AJ16,AO16,AT16) -> 15 | J16: =AVERAGE(Q16,V16,AA16,AF16,AK16,AP16,AU16) -> 1071 | K16: =AVERAGE(AV16) -> 71.4 | M16: =RANK(K16, K$7:$K$24) -> 14 | R16: =Q16/P16 -> #DIV/0! | S16: =RANK(R16, R$7:R$24) -> #DIV/0! | W16: =V16/U16 -> #DIV/0! | X16: =RANK(W16, W$7:W$24) -> #DIV/0! | AB16: =AA16/Z16 -> #DIV/0! | AC16: =RANK(AB16, AB$7:AB$24) -> #DIV/0! | AG16: =AF16/AE16 -> #DIV/0! | AH16: =RANK(AG16, AG$7:AG$24) -> #DIV/0! | AL16: =AK16/AJ16 -> #DIV/0! | AM16: =RANK(AL16, AL$7:AL$24) -> #DIV/0! | AQ16: =AP16/AO16 -> #DIV/0! | AR16: =RANK(AQ16, AQ$7:AQ$24) -> #DIV/0! | AT16: 15 | AU16: 1071 | AV16: =AU16/AT16 -> 71.4 | AW16: =RANK(AV16, AV$7:AV$24) -> 14
C17: 11 | D17: 黑胡椒燻豬腿義大利麵 | E17: =VLOOKUP(D17,'09產線配置圖'!$A$2:$C$25,2,0) -> 18 | F17: =VLOOKUP(D17,'09產線配置圖'!$A$2:$C$25,3,0) -> 1500 | G17: =F17/E17 -> 83.333333 | I17: =AVERAGE(P17,U17,Z17,AE17,AJ17,AO17,AT17) -> 15 | J17: =AVERAGE(Q17,V17,AA17,AF17,AK17,AP17,AU17) -> 1278 | K17: =AVERAGE(AV17) -> 85.2 | M17: =RANK(K17, K$7:$K$24) -> 9 | R17: =Q17/P17 -> #DIV/0! | S17: =RANK(R17, R$7:R$24) -> #DIV/0! | W17: =V17/U17 -> #DIV/0! | X17: =RANK(W17, W$7:W$24) -> #DIV/0! | AB17: =AA17/Z17 -> #DIV/0! | AC17: =RANK(AB17, AB$7:AB$24) -> #DIV/0! | AG17: =AF17/AE17 -> #DIV/0! | AH17: =RANK(AG17, AG$7:AG$24) -> #DIV/0! | AL17: =AK17/AJ17 -> #DIV/0! | AM17: =RANK(AL17, AL$7:AL$24) -> #DIV/0! | AQ17: =AP17/AO17 -> #DIV/0! | AR17: =RANK(AQ17, AQ$7:AQ$24) -> #DIV/0! | AT17: 15 | AU17: 1278 | AV17: =AU17/AT17 -> 85.2 | AW17: =RANK(AV17, AV$7:AV$24) -> 9
C18: 12 | D18: 奶油蒜香雞義大利麵 | E18: =VLOOKUP(D18,'09產線配置圖'!$A$2:$C$25,2,0) -> 18 | F18: =VLOOKUP(D18,'09產線配置圖'!$A$2:$C$25,3,0) -> 1385 | G18: =F18/E18 -> 76.944444 | I18: =AVERAGE(P18,U18,Z18,AE18,AJ18,AO18,AT18) -> 17 | J18: =AVERAGE(Q18,V18,AA18,AF18,AK18,AP18,AU18) -> 1259 | K18: =AVERAGE(AV18) -> 74.058824 | M18: =RANK(K18, K$7:$K$24) -> 12 | R18: =Q18/P18 -> #DIV/0! | S18: =RANK(R18, R$7:R$24) -> #DIV/0! | W18: =V18/U18 -> #DIV/0! | X18: =RANK(W18, W$7:W$24) -> #DIV/0! | AB18: =AA18/Z18 -> #DIV/0! | AC18: =RANK(AB18, AB$7:AB$24) -> #DIV/0! | AG18: =AF18/AE18 -> #DIV/0! | AH18: =RANK(AG18, AG$7:AG$24) -> #DIV/0! | AL18: =AK18/AJ18 -> #DIV/0! | AM18: =RANK(AL18, AL$7:AL$24) -> #DIV/0! | AQ18: =AP18/AO18 -> #DIV/0! | AR18: =RANK(AQ18, AQ$7:AQ$24) -> #DIV/0! | AT18: 17 | AU18: 1259 | AV18: =AU18/AT18 -> 74.058824 | AW18: =RANK(AV18, AV$7:AV$24) -> 12
C19: 13 | D19: 青花椒麻雞肉拌麵 | E19: =VLOOKUP(D19,'09產線配置圖'!$A$2:$C$25,2,0) -> 17 | F19: =VLOOKUP(D19,'09產線配置圖'!$A$2:$C$25,3,0) -> 1565 | G19: =F19/E19 -> 92.058824 | I19: =AVERAGE(P19,U19,Z19,AE19,AJ19,AO19,AT19) -> 12 | J19: =AVERAGE(Q19,V19,AA19,AF19,AK19,AP19,AU19) -> 938 | K19: =AVERAGE(AV19) -> 78.166667 | M19: =RANK(K19, K$7:$K$24) -> 11 | R19: =Q19/P19 -> #DIV/0! | S19: =RANK(R19, R$7:R$24) -> #DIV/0! | W19: =V19/U19 -> #DIV/0! | X19: =RANK(W19, W$7:W$24) -> #DIV/0! | AB19: =AA19/Z19 -> #DIV/0! | AC19: =RANK(AB19, AB$7:AB$24) -> #DIV/0! | AG19: =AF19/AE19 -> #DIV/0! | AH19: =RANK(AG19, AG$7:AG$24) -> #DIV/0! | AL19: =AK19/AJ19 -> #DIV/0! | AM19: =RANK(AL19, AL$7:AL$24) -> #DIV/0! | AQ19: =AP19/AO19 -> #DIV/0! | AR19: =RANK(AQ19, AQ$7:AQ$24) -> #DIV/0! | AT19: 12 | AU19: 938 | AV19: =AU19/AT19 -> 78.166667 | AW19: =RANK(AV19, AV$7:AV$24) -> 11
C20: 14 | D20: 煙花女義大利麵 | E20: =VLOOKUP(D20,'09產線配置圖'!$A$2:$C$25,2,0) -> 17 | F20: =VLOOKUP(D20,'09產線配置圖'!$A$2:$C$25,3,0) -> 1636 | G20: =F20/E20 -> 96.235294 | I20: =AVERAGE(P20,U20,Z20,AE20,AJ20,AO20,AT20) -> 15 | J20: =AVERAGE(Q20,V20,AA20,AF20,AK20,AP20,AU20) -> 1309 | K20: =AVERAGE(AV20) -> 87.266667 | M20: =RANK(K20, K$7:$K$24) -> 8 | R20: =Q20/P20 -> #DIV/0! | S20: =RANK(R20, R$7:R$24) -> #DIV/0! | W20: =V20/U20 -> #DIV/0! | X20: =RANK(W20, W$7:W$24) -> #DIV/0! | AB20: =AA20/Z20 -> #DIV/0! | AC20: =RANK(AB20, AB$7:AB$24) -> #DIV/0! | AG20: =AF20/AE20 -> #DIV/0! | AH20: =RANK(AG20, AG$7:AG$24) -> #DIV/0! | AL20: =AK20/AJ20 -> #DIV/0! | AM20: =RANK(AL20, AL$7:AL$24) -> #DIV/0! | AQ20: =AP20/AO20 -> #DIV/0! | AR20: =RANK(AQ20, AQ$7:AQ$24) -> #DIV/0! | AT20: 15 | AU20: 1309 | AV20: =AU20/AT20 -> 87.266667 | AW20: =RANK(AV20, AV$7:AV$24) -> 8
C21: 15 | D21: 羊乳起司培根筆尖麵 | E21: =VLOOKUP(D21,'09產線配置圖'!$A$2:$C$25,2,0) -> 17 | F21: =VLOOKUP(D21,'09產線配置圖'!$A$2:$C$25,3,0) -> 1636 | G21: =F21/E21 -> 96.235294 | I21: =AVERAGE(P21,U21,Z21,AE21,AJ21,AO21,AT21) -> 15 | J21: =AVERAGE(Q21,V21,AA21,AF21,AK21,AP21,AU21) -> 1103 | K21: =AVERAGE(AV21) -> 73.533333 | M21: =RANK(K21, K$7:$K$24) -> 13 | R21: =Q21/P21 -> #DIV/0! | S21: =RANK(R21, R$7:R$24) -> #DIV/0! | W21: =V21/U21 -> #DIV/0! | X21: =RANK(W21, W$7:W$24) -> #DIV/0! | AB21: =AA21/Z21 -> #DIV/0! | AC21: =RANK(AB21, AB$7:AB$24) -> #DIV/0! | AR21: =RANK(AQ21, AQ$7:AQ$24) -> #DIV/0! | AT21: 15 | AU21: 1103 | AV21: =AU21/AT21 -> 73.533333 | AW21: =RANK(AV21, AV$7:AV$24) -> 13
C22: 16 | I22: =AVERAGE(P22,U22,Z22,AE22,AJ22,AO22,AT22) -> #DIV/0! | J22: =AVERAGE(Q22,V22,AA22,AF22,AK22,AP22,AU22) -> #DIV/0! | R22: =Q22/P22 -> #DIV/0! | S22: =RANK(R22, R$7:R$24) -> #DIV/0! | W22: =V22/U22 -> #DIV/0! | X22: =RANK(W22, W$7:W$24) -> #DIV/0! | AB22: =AA22/Z22 -> #DIV/0! | AC22: =RANK(AB22, AB$7:AB$24) -> #DIV/0! | AR22: =RANK(AQ22, AQ$7:AQ$24) -> #DIV/0!
C23: 17 | I23: =AVERAGE(P23,U23,Z23,AE23,AJ23,AO23,AT23) -> #DIV/0! | J23: =AVERAGE(Q23,V23,AA23,AF23,AK23,AP23,AU23) -> #DIV/0! | R23: =Q23/P23 -> #DIV/0! | S23: =RANK(R23, R$7:R$24) -> #DIV/0! | W23: =V23/U23 -> #DIV/0! | X23: =RANK(W23, W$7:W$24) -> #DIV/0! | AB23: =AA23/Z23 -> #DIV/0! | AC23: =RANK(AB23, AB$7:AB$24) -> #DIV/0! | AR23: =RANK(AQ23, AQ$7:AQ$24) -> #DIV/0!
C24: 18 | I24: =AVERAGE(P24,U24,Z24,AE24,AJ24,AO24,AT24) -> #DIV/0! | J24: =AVERAGE(Q24,V24,AA24,AF24,AK24,AP24,AU24) -> #DIV/0! | R24: =Q24/P24 -> #DIV/0! | S24: =RANK(R24, R$7:R$24) -> #DIV/0! | W24: =V24/U24 -> #DIV/0! | X24: =RANK(W24, W$7:W$24) -> #DIV/0! | AB24: =AA24/Z24 -> #DIV/0! | AC24: =RANK(AB24, AB$7:AB$24) -> #DIV/0! | AR24: =RANK(AQ24, AQ$7:AQ$24) -> #DIV/0!
B25: 產線配置圖－每週更新 | N25: 資料繳交 | O25: 日期 | P25: 45902 | U25: 45903 | Z25: 45904 | AE25: 45905 | AJ25: 45906 | AO25: 45907 | AT25: 45908
P26: 二 | U26: 三 | Z26: 四 | AE26: 五 | AJ26: 六 | AO26: 日 | AT26: 一
B27: 品群 | C27: 商品名稱 | E27: 計畫 | H27: 平均人時性 | I27: 實績 | L27: 平均人時性 | M27: 排名 | O27: 日報 | P27: 實際 | T27: 平均人時性 | U27: 實際 | Y27: 平均人時性 | Z27: 實際 | AD27: 平均人時性 | AE27: 實際 | AI27: 平均人時性 | AJ27: 實際 | AN27: 平均人時性 | AO27: 實際 | AS27: 平均人時性 | AT27: 實際 | AX27: 平均人時性
E28: 產線配置圖 | I28: 產線配置圖 | P28: 生產實績 | U28: 生產實績 | Z28: 生產實績 | AE28: 生產實績 | AJ28: 生產實績 | AO28: 生產實績 | AT28: 生產實績
E29: 人數 | F29: 產能／時 | G29: 人時性 | I29: 人數 | J29: 產能／時 | K29: 人時性 | P29: 人數 | Q29: 產能／時 | R29: 人時性 | S29: 排名 | U29: 人數 | V29: 產能／時 | W29: 人時性 | X29: 排名 | Z29: 人數 | AA29: 產能／時 | AB29: 人時性 | AC29: 排名 | AE29: 人數 | AF29: 產能／時 | AG29: 人時性 | AH29: 排名 | AJ29: 人數 | AK29: 產能／時 | AL29: 人時性 | AM29: 排名 | AO29: 人數 | AP29: 產能／時 | AQ29: 人時性 | AR29: 排名 | AT29: 人數 | AU29: 產能／時 | AV29: 人時性 | AW29: 排名
B30: 熱食義麵 | C30: 1 | D30: 義式蕃茄起司義大利麵 | E30: =VLOOKUP(D30,'09產線配置圖'!$A$2:$C$25,2,0) -> 12 | F30: =VLOOKUP(D30,'09產線配置圖'!$A$2:$C$25,3,0) -> 2000 | G30: =F30/E30 -> 166.66667 | H30: =AVERAGE(G30:G47) -> 107.65416 | I30: =AVERAGE(P30,U30,Z30,AE30,AJ30,AO30,AT30) -> 12 | J30: =AVERAGE(Q30,V30,AA30,AF30,AK30,AP30,AU30) -> 1851.9286 | K30: =AVERAGE(R30,W30,AB30,AG30,AL30,AQ30,AV30) -> 154.32738 | L30: =IFERROR(AVERAGE(K30:K47),"-") -> 95.220498 | M30: =RANK(K30, K$30:$K$47) -> 1 | P30: 12 | Q30: 1897 | R30: =Q30/P30 -> 158.08333 | S30: =RANK(R30,$R$30:$R$47) -> 1 | T30: =AVERAGE(R30:R47) -> 94.995122 | U30: 12 | V30: 1865 | W30: =V30/U30 -> 155.41667 | X30: =RANK(W30, $W$30:$W$47) -> 1 | Y30: =AVERAGE(W30:W47) -> 95.346629 | Z30: 12 | AA30: 1803 | AB30: =AA30/Z30 -> 150.25 | AC30: =RANK(AB30, $AB$30:$AB$47) -> 1 | AD30: =AVERAGE(AB30:AB47) -> 95.838857 | AE30: 12 | AF30: 1867 | AG30: =AF30/AE30 -> 155.58333 | AH30: =RANK(AG30, $AG$30:$AG$47) -> 1 | AI30: =AVERAGE(AG30:AG47) -> 96.043794 | AJ30: 12 | AK30: 1798 | AL30: =AK30/AJ30 -> 149.83333 | AM30: =RANK(AL30, $AL$30:$AL$47) -> 1 | AN30: =AVERAGE(AL30:AL47) -> 94.541482 | AO30: 12 | AP30: 1932 | AQ30: =AP30/AO30 -> 161 | AR30: =RANK(AQ30,$AQ$30:$AQ$47) -> 1 | AS30: =AVERAGE(AQ30:AQ47) -> 94.611444 | AT30: 12 | AU30: 1801.5 | AV30: =AU30/AT30 -> 150.125 | AW30: =RANK(AV30, $AV$30:$AV$47) -> 1 | AX30: =AVERAGE(AV30:AV47) -> 96.717836
C31: 2 | D31: 奶油培根義大利麵 | E31: =VLOOKUP(D31,'09產線配置圖'!$A$2:$C$25,2,0) -> 13 | F31: =VLOOKUP(D31,'09產線配置圖'!$A$2:$C$25,3,0) -> 2000 | G31: =F31/E31 -> 153.84615 | I31: =AVERAGE(P31,U31,Z31,AE31,AJ31,AO31,AT31) -> 13 | J31: =AVERAGE(Q31,V31,AA31,AF31,AK31,AP31,AU31) -> 1818.3571 | K31: =AVERAGE(R31,W31,AB31,AG31,AL31,AQ31,AV31) -> 139.87363 | M31: =RANK(K31, K$30:$K$47) -> 2 | P31: 13 | Q31: 1854 | R31: =Q31/P31 -> 142.61538 | S31: =RANK(R31,$R$30:$R$47) -> 2 | U31: 13 | V31: 1833 | W31: =V31/U31 -> 141 | X31: =RANK(W31, $W$30:$W$47) -> 2 | Z31: 13 | AA31: 1872 | AB31: =AA31/Z31 -> 144 | AC31: =RANK(AB31, $AB$30:$AB$47) -> 2 | AE31: 13 | AF31: 1932 | AG31: =AF31/AE31 -> 148.61538 | AH31: =RANK(AG31, $AG$30:$AG$47) -> 2 | AJ31: 13 | AK31: 1757 | AL31: =AK31/AJ31 -> 135.15385 | AM31: =RANK(AL31, $AL$30:$AL$47) -> 2 | AO31: 13 | AP31: 1764 | AQ31: =AP31/AO31 -> 135.69231 | AR31: =RANK(AQ31,$AQ$30:$AQ$47) -> 2 | AT31: 13 | AU31: 1716.5 | AV31: =AU31/AT31 -> 132.03846 | AW31: =RANK(AV31, $AV$30:$AV$47) -> 3
C32: 3 | D32: 熱那亞青醬義大利麵 | E32: =VLOOKUP(D32,'09產線配置圖'!$A$2:$C$25,2,0) -> 16 | F32: =VLOOKUP(D32,'09產線配置圖'!$A$2:$C$25,3,0) -> 1915 | G32: =F32/E32 -> 119.6875 | I32: =AVERAGE(P32,U32,Z32,AE32,AJ32,AO32,AT32) -> 16 | J32: =AVERAGE(Q32,V32,AA32,AF32,AK32,AP32,AU32) -> 1569.5714 | K32: =AVERAGE(R32,W32,AB32,AG32,AL32,AQ32,AV32) -> 98.098214 | M32: =RANK(K32, K$30:$K$47) -> 6 | P32: 16 | Q32: 1734 | R32: =Q32/P32 -> 108.375 | S32: =RANK(R32,$R$30:$R$47) -> 5 | U32: 16 | V32: 1602 | W32: =V32/U32 -> 100.125 | X32: =RANK(W32, $W$30:$W$47) -> 5 | Z32: 16 | AA32: 1645 | AB32: =AA32/Z32 -> 102.8125 | AC32: =RANK(AB32, $AB$30:$AB$47) -> 5 | AE32: 16 | AF32: 1408 | AG32: =AF32/AE32 -> 88 | AH32: =RANK(AG32, $AG$30:$AG$47) -> 7 | AJ32: 16 | AK32: 1481 | AL32: =AK32/AJ32 -> 92.5625 | AM32: =RANK(AL32, $AL$30:$AL$47) -> 6 | AO32: 16 | AP32: 1704 | AQ32: =AP32/AO32 -> 106.5 | AR32: =RANK(AQ32,$AQ$30:$AQ$47) -> 4 | AT32: 16 | AU32: 1413 | AV32: =AU32/AT32 -> 88.3125 | AW32: =RANK(AV32, $AV$30:$AV$47) -> 8
C33: 4 | D33: 焗烤起司雙饗筆尖麵 | E33: =VLOOKUP(D33,'09產線配置圖'!$A$2:$C$25,2,0) -> 18 | F33: =VLOOKUP(D33,'09產線配置圖'!$A$2:$C$25,3,0) -> 1565 | G33: =F33/E33 -> 86.944444 | I33: =AVERAGE(P33,U33,Z33,AE33,AJ33,AO33,AT33) -> 18.142857 | J33: =AVERAGE(Q33,V33,AA33,AF33,AK33,AP33,AU33) -> 1478.7143 | K33: =AVERAGE(R33,W33,AB33,AG33,AL33,AQ33,AV33) -> 81.646125 | M33: =RANK(K33, K$30:$K$47) -> 10 | P33: 20 | Q33: 1490 | R33: =Q33/P33 -> 74.5 | S33: =RANK(R33,$R$30:$R$47) -> 11 | U33: 18 | V33: 1549 | W33: =V33/U33 -> 86.055556 | X33: =RANK(W33, $W$30:$W$47) -> 9 | Z33: 18 | AA33: 1413 | AB33: =AA33/Z33 -> 78.5 | AC33: =RANK(AB33, $AB$30:$AB$47) -> 12 | AE33: 17 | AF33: 1452 | AG33: =AF33/AE33 -> 85.411765 | AH33: =RANK(AG33, $AG$30:$AG$47) -> 10 | AJ33: 18 | AK33: 1382 | AL33: =AK33/AJ33 -> 76.777778 | AM33: =RANK(AL33, $AL$30:$AL$47) -> 11 | AO33: 18 | AP33: 1536.5 | AQ33: =AP33/AO33 -> 85.361111 | AR33: =RANK(AQ33,$AQ$30:$AQ$47) -> 10 | AT33: 18 | AU33: 1528.5 | AV33: =AU33/AT33 -> 84.916667 | AW33: =RANK(AV33, $AV$30:$AV$47) -> 9
C34: 5 | D34: 白酒蛤蜊義大利麵 | E34: =VLOOKUP(D34,'09產線配置圖'!$A$2:$C$25,2,0) -> 13 | F34: =VLOOKUP(D34,'09產線配置圖'!$A$2:$C$25,3,0) -> 2000 | G34: =F34/E34 -> 153.84615 | I34: =AVERAGE(P34,U34,Z34,AE34,AJ34,AO34,AT34) -> 13.428571 | J34: =AVERAGE(Q34,V34,AA34,AF34,AK34,AP34,AU34) -> 1759.6429 | K34: =AVERAGE(R34,W34,AB34,AG34,AL34,AQ34,AV34) -> 131.2657 | M34: =RANK(K34, K$30:$K$47) -> 3 | P34: 15 | Q34: 1830 | R34: =Q34/P34 -> 122 | S34: =RANK(R34,$R$30:$R$47) -> 3 | U34: 13 | V34: 1792 | W34: =V34/U34 -> 137.84615 | X34: =RANK(W34, $W$30:$W$47) -> 3 | Z34: 13 | AA34: 1699 | AB34: =AA34/Z34 -> 130.69231 | AC34: =RANK(AB34, $AB$30:$AB$47) -> 3 | AE34: 13 | AF34: 1738 | AG34: =AF34/AE34 -> 133.69231 | AH34: =RANK(AG34, $AG$30:$AG$47) -> 3 | AJ34: 13 | AK34: 1664 | AL34: =AK34/AJ34 -> 128 | AM34: =RANK(AL34, $AL$30:$AL$47) -> 3 | AO34: 14 | AP34: 1796.5 | AQ34: =AP34/AO34 -> 128.32143 | AR34: =RANK(AQ34,$AQ$30:$AQ$47) -> 3 | AT34: 13 | AU34: 1798 | AV34: =AU34/AT34 -> 138.30769 | AW34: =RANK(AV34, $AV$30:$AV$47) -> 2
C35: 6 | D35: 韓式起司炸雞義大利麵 | E35: =VLOOKUP(D35,'09產線配置圖'!$A$2:$C$25,2,0) -> 16 | F35: =VLOOKUP(D35,'09產線配置圖'!$A$2:$C$25,3,0) -> 1895 | G35: =F35/E35 -> 118.4375 | I35: =AVERAGE(P35,U35,Z35,AE35,AJ35,AO35,AT35) -> 15.857143 | J35: =AVERAGE(Q35,V35,AA35,AF35,AK35,AP35,AU35) -> 1629 | K35: =AVERAGE(R35,W35,AB35,AG35,AL35,AQ35,AV35) -> 102.76786 | M35: =RANK(K35, K$30:$K$47) -> 4 | P35: 16 | Q35: 1847 | R35: =Q35/P35 -> 115.4375 | S35: =RANK(R35,$R$30:$R$47) -> 4 | U35: 16 | V35: 1649 | W35: =V35/U35 -> 103.0625 | X35: =RANK(W35, $W$30:$W$47) -> 4 | Z35: 16 | AA35: 1623 | AB35: =AA35/Z35 -> 101.4375 | AC35: =RANK(AB35, $AB$30:$AB$47) -> 6 | AE35: 16 | AF35: 1547 | AG35: =AF35/AE35 -> 96.6875 | AH35: =RANK(AG35, $AG$30:$AG$47) -> 4 | AJ35: 16 | AK35: 1526 | AL35: =AK35/AJ35 -> 95.375 | AM35: =RANK(AL35, $AL$30:$AL$47) -> 5 | AO35: 16 | AP35: 1606 | AQ35: =AP35/AO35 -> 100.375 | AR35: =RANK(AQ35,$AQ$30:$AQ$47) -> 6 | AT35: 15 | AU35: 1605 | AV35: =AU35/AT35 -> 107 | AW35: =RANK(AV35, $AV$30:$AV$47) -> 4
C36: 7 | D36: 蒜香蝦蝦義大利麵 | E36: =VLOOKUP(D36,'09產線配置圖'!$A$2:$C$25,2,0) -> 16 | F36: =VLOOKUP(D36,'09產線配置圖'!$A$2:$C$25,3,0) -> 1552 | G36: =F36/E36 -> 97 | I36: =AVERAGE(P36,U36,Z36,AE36,AJ36,AO36,AT36) -> 15.5 | J36: =AVERAGE(Q36,V36,AA36,AF36,AK36,AP36,AU36) -> 1313.5 | K36: =AVERAGE(R36,W36,AB36,AG36,AL36,AQ36,AV36) -> 84.779018 | M36: =RANK(K36, K$30:$K$47) -> 9 | P36: 16 | Q36: 1489 | R36: =Q36/P36 -> 93.0625 | S36: =RANK(R36,$R$30:$R$47) -> 7 | U36: 16 | V36: 1208 | W36: =V36/U36 -> 75.5 | X36: =RANK(W36, $W$30:$W$47) -> 10 | Z36: 16 | AA36: 1354 | AB36: =AA36/Z36 -> 84.625 | AC36: =RANK(AB36, $AB$30:$AB$47) -> 10 | AE36: 14 | AF36: 1203 | AG36: =AF36/AE36 -> 85.928571 | AH36: =RANK(AG36, $AG$30:$AG$47) -> 9
C37: 8 | D37: 焗奶油扇貝筆尖麵 | E37: =VLOOKUP(D37,'09產線配置圖'!$A$2:$C$25,2,0) -> 15 | F37: =VLOOKUP(D37,'09產線配置圖'!$A$2:$C$25,3,0) -> 1565 | G37: =F37/E37 -> 104.33333 | I37: =AVERAGE(P37,U37,Z37,AE37,AJ37,AO37,AT37) -> 16.142857 | J37: =AVERAGE(Q37,V37,AA37,AF37,AK37,AP37,AU37) -> 1601.5714 | K37: =AVERAGE(R37,W37,AB37,AG37,AL37,AQ37,AV37) -> 99.464632 | M37: =RANK(K37, K$30:$K$47) -> 5 | P37: 19 | Q37: 1718 | R37: =Q37/P37 -> 90.421053 | S37: =RANK(R37,$R$30:$R$47) -> 8 | U37: 17 | V37: 1689 | W37: =V37/U37 -> 99.352941 | X37: =RANK(W37, $W$30:$W$47) -> 6 | Z37: 17 | AA37: 1758 | AB37: =AA37/Z37 -> 103.41176 | AC37: =RANK(AB37, $AB$30:$AB$47) -> 4 | AE37: 15 | AF37: 1399 | AG37: =AF37/AE37 -> 93.266667 | AH37: =RANK(AG37, $AG$30:$AG$47) -> 5 | AJ37: 15 | AK37: 1543 | AL37: =AK37/AJ37 -> 102.86667 | AM37: =RANK(AL37, $AL$30:$AL$47) -> 4 | AO37: 15 | AP37: 1540 | AQ37: =AP37/AO37 -> 102.66667 | AR37: =RANK(AQ37,$AQ$30:$AQ$47) -> 5 | AT37: 15 | AU37: 1564 | AV37: =AU37/AT37 -> 104.26667 | AW37: =RANK(AV37, $AV$30:$AV$47) -> 5
C38: 9 | D38: 拿坡里義大利麵 | E38: =VLOOKUP(D38,'09產線配置圖'!$A$2:$C$25,2,0) -> 16 | F38: =VLOOKUP(D38,'09產線配置圖'!$A$2:$C$25,3,0) -> 1390 | G38: =F38/E38 -> 86.875 | I38: =AVERAGE(P38,U38,Z38,AE38,AJ38,AO38,AT38) -> 16.142857 | J38: =AVERAGE(Q38,V38,AA38,AF38,AK38,AP38,AU38) -> 1069.5714 | K38: =AVERAGE(R38,W38,AB38,AG38,AL38,AQ38,AV38) -> 66.282458 | M38: =RANK(K38, K$30:$K$47) -> 15 | P38: 18 | Q38: 1197 | R38: =Q38/P38 -> 66.5 | S38: =RANK(R38,$R$30:$R$47) -> 14 | U38: 17 | V38: 1120 | W38: =V38/U38 -> 65.882353 | X38: =RANK(W38, $W$30:$W$47) -> 15 | Z38: 17 | AA38: 1069 | AB38: =AA38/Z38 -> 62.882353 | AC38: =RANK(AB38, $AB$30:$AB$47) -> 15 | AE38: 15 | AF38: 1100 | AG38: =AF38/AE38 -> 73.333333 | AH38: =RANK(AG38, $AG$30:$AG$47) -> 14 | AJ38: 15 | AK38: 953 | AL38: =AK38/AJ38 -> 63.533333 | AM38: =RANK(AL38, $AL$30:$AL$47) -> 14 | AO38: 15 | AP38: 923 | AQ38: =AP38/AO38 -> 61.533333 | AR38: =RANK(AQ38,$AQ$30:$AQ$47) -> 14 | AT38: 16 | AU38: 1125 | AV38: =AU38/AT38 -> 70.3125 | AW38: =RANK(AV38, $AV$30:$AV$47) -> 12
C39: 10 | D39: 奶油明太子細扁麵 | E39: =VLOOKUP(D39,'09產線配置圖'!$A$2:$C$25,2,0) -> 19 | F39: =VLOOKUP(D39,'09產線配置圖'!$A$2:$C$25,3,0) -> 1565 | G39: =F39/E39 -> 82.368421 | I39: =AVERAGE(P39,U39,Z39,AE39,AJ39,AO39,AT39) -> 15 | J39: =AVERAGE(Q39,V39,AA39,AF39,AK39,AP39,AU39) -> 1095.5 | K39: =AVERAGE(R39,W39,AB39,AG39,AL39,AQ39,AV39) -> 73.415179 | M39: =RANK(K39, K$30:$K$47) -> 13 | P39: 17 | Q39: 1156 | R39: =Q39/P39 -> 68 | S39: =RANK(R39,$R$30:$R$47) -> 13 | U39: 14 | V39: 1030 | W39: =V39/U39 -> 73.571429 | X39: =RANK(W39, $W$30:$W$47) -> 12 | Z39: 14 | AA39: 1195 | AB39: =AA39/Z39 -> 85.357143 | AC39: =RANK(AB39, $AB$30:$AB$47) -> 9 | AE39: 14 | AF39: 1032 | AG39: =AF39/AE39 -> 73.714286 | AH39: =RANK(AG39, $AG$30:$AG$47) -> 13 | AJ39: 14 | AK39: 1097 | AL39: =AK39/AJ39 -> 78.357143 | AM39: =RANK(AL39, $AL$30:$AL$47) -> 10 | AO39: 16 | AP39: 1134 | AQ39: =AP39/AO39 -> 70.875 | AR39: =RANK(AQ39,$AQ$30:$AQ$47) -> 12 | AT39: 16 | AU39: 1024.5 | AV39: =AU39/AT39 -> 64.03125 | AW39: =RANK(AV39, $AV$30:$AV$47) -> 14
C40: 11 | D40: 黑胡椒燻豬腿義大利麵 | E40: =VLOOKUP(D40,'09產線配置圖'!$A$2:$C$25,2,0) -> 18 | F40: =VLOOKUP(D40,'09產線配置圖'!$A$2:$C$25,3,0) -> 1500 | G40: =F40/E40 -> 83.333333 | I40: =AVERAGE(P40,U40,Z40,AE40,AJ40,AO40,AT40) -> 14 | J40: =AVERAGE(Q40,V40,AA40,AF40,AK40,AP40,AU40) -> 1054.7143 | K40: =AVERAGE(R40,W40,AB40,AG40,AL40,AQ40,AV40) -> 76.252064 | M40: =RANK(K40, K$30:$K$47) -> 11 | P40: 17 | Q40: 984 | R40: =Q40/P40 -> 57.882353 | S40: =RANK(R40,$R$30:$R$47) -> 15 | U40: 14 | V40: 1039 | W40: =V40/U40 -> 74.214286 | X40: =RANK(W40, $W$30:$W$47) -> 11 | Z40: 14 | AA40: 1207 | AB40: =AA40/Z40 -> 86.214286 | AC40: =RANK(AB40, $AB$30:$AB$47) -> 8 | AE40: 13 | AF40: 1122 | AG40: =AF40/AE40 -> 86.307692 | AH40: =RANK(AG40, $AG$30:$AG$47) -> 8 | AJ40: 12 | AK40: 973 | AL40: =AK40/AJ40 -> 81.083333 | AM40: =RANK(AL40, $AL$30:$AL$47) -> 9 | AO40: 16 | AP40: 1125 | AQ40: =AP40/AO40 -> 70.3125 | AR40: =RANK(AQ40,$AQ$30:$AQ$47) -> 13 | AT40: 12 | AU40: 933 | AV40: =AU40/AT40 -> 77.75 | AW40: =RANK(AV40, $AV$30:$AV$47) -> 10
...

Sheet （５-2）品群別人時生產性(季節調理麵) 
B1: 月平均人時性 | C1: =AVERAGE(L7,L27,L47,L67,L87) -> #DIV/0!
B2: 產線配置圖－每週更新 | N2: 資料繳交 | O2: 日期 | AE2: 45870 | AJ2: 45871 | AO2: 45872 | AT2: 45873
P3: 二 | U3: 三 | Z3: 四 | AE3: 五 | AJ3: 六 | AO3: 日 | AT3: 一
B4: 品群 | C4: 商品名稱 | E4: 計畫 | H4: 平均人時性 | I4: 實績 | L4: 平均人時性 | M4: 排名 | O4: 日報 | P4: 實際 | T4: 平均人時性 | U4: 實際 | Y4: 平均人時性 | Z4: 實際 | AD4: 平均人時性 | AE4: 實際 | AI4: 平均人時性 | AJ4: 實際 | AN4: 平均人時性 | AO4: 實際 | AS4: 平均人時性 | AT4: 實際 | AX4: 平均人時性
E5: 產線配置圖 | I5: 產線配置圖 | P5: 生產實績 | U5: 生產實績 | Z5: 生產實績 | AE5: 生產實績 | AJ5: 生產實績 | AO5: 生產實績 | AT5: 生產實績
E6: 人數 | F6: 產能／時 | G6: 人時性 | I6: 人數 | J6: 產能／時 | K6: 人時性 | P6: 人數 | Q6: 產能／時 | R6: 人時性 | S6: 排名 | U6: 人數 | V6: 產能／時 | W6: 人時性 | X6: 排名 | Z6: 人數 | AA6: 產能／時 | AB6: 人時性 | AC6: 排名 | AE6: 人數 | AF6: 產能／時 | AG6: 人時性 | AH6: 排名 | AJ6: 人數 | AK6: 產能／時 | AL6: 人時性 | AM6: 排名 | AO6: 人數 | AP6: 產能／時 | AQ6: 人時性 | AR6: 排名 | AT6: 人數 | AU6: 產能／時 | AV6: 人時性 | AW6: 排名
B7: 熱食調理麵 | C7: 1 | H7: =AVERAGE(G7:G21) -> #DIV/0! | I7: =AVERAGE(P7,U7,Z7,AE7,AJ7,AO7,AT7) -> #DIV/0! | J7: =AVERAGE(Q7,V7,AA7,AF7,AK7,AP7,AU7) -> #DIV/0! | K7: =AVERAGE(R7,W7,AB7,AG7,AL7,AQ7,AV7) -> #DIV/0! | L7: =AVERAGE(K7:K21) -> #DIV/0! | M7: =RANK(K7, K$7:$K$21) -> #DIV/0! | S7: =RANK(R7, R$7:R$21) -> #N/A | T7: =AVERAGE(R7:R21) -> #DIV/0! | X7: =RANK(W7, W$7:W$21) -> #N/A | Y7: =AVERAGE(W7:W21) -> #DIV/0! | AC7: =RANK(AB7, AB$7:AB$21) -> #N/A | AD7: =AVERAGE(AB7:AB21) -> #DIV/0! | AH7: =RANK(AG7, AG$7:AG$21) -> #N/A | AI7: =AVERAGE(AG7:AG21) -> #DIV/0! | AM7: =RANK(AL7, AL$7:AL$21) -> #N/A | AN7: =AVERAGE(AL7:AL21) -> #DIV/0! | AR7: =RANK(AQ7, AQ$7:AQ$21) -> #N/A | AS7: =AVERAGE(AQ7:AQ21) -> #DIV/0! | AW7: =RANK(AV7, AV$7:AV$21) -> #N/A | AX7: =AVERAGE(AV7:AV21) -> #DIV/0!
C8: 2 | I8: =AVERAGE(P8,U8,Z8,AE8,AJ8,AO8,AT8) -> #DIV/0! | J8: =AVERAGE(Q8,V8,AA8,AF8,AK8,AP8,AU8) -> #DIV/0! | K8: =AVERAGE(R8,W8,AB8,AG8,AL8,AQ8,AV8) -> #DIV/0! | M8: =RANK(K8, K$7:$K$21) -> #DIV/0! | S8: =RANK(R8, R$7:R$21) -> #N/A | X8: =RANK(W8, W$7:W$21) -> #N/A | AC8: =RANK(AB8, AB$7:AB$21) -> #N/A | AH8: =RANK(AG8, AG$7:AG$21) -> #N/A | AM8: =RANK(AL8, AL$7:AL$21) -> #N/A | AR8: =RANK(AQ8, AQ$7:AQ$21) -> #N/A | AW8: =RANK(AV8, AV$7:AV$21) -> #N/A
C9: 3 | I9: =AVERAGE(P9,U9,Z9,AE9,AJ9,AO9,AT9) -> #DIV/0! | J9: =AVERAGE(Q9,V9,AA9,AF9,AK9,AP9,AU9) -> #DIV/0! | K9: =AVERAGE(R9,W9,AB9,AG9,AL9,AQ9,AV9) -> #DIV/0! | M9: =RANK(K9, K$7:$K$21) -> #DIV/0! | S9: =RANK(R9, R$7:R$21) -> #N/A | X9: =RANK(W9, W$7:W$21) -> #N/A | AC9: =RANK(AB9, AB$7:AB$21) -> #N/A | AH9: =RANK(AG9, AG$7:AG$21) -> #N/A | AM9: =RANK(AL9, AL$7:AL$21) -> #N/A | AR9: =RANK(AQ9, AQ$7:AQ$21) -> #N/A | AW9: =RANK(AV9, AV$7:AV$21) -> #N/A
C10: 4 | I10: =AVERAGE(P10,U10,Z10,AE10,AJ10,AO10,AT10) -> #DIV/0! | J10: =AVERAGE(Q10,V10,AA10,AF10,AK10,AP10,AU10) -> #DIV/0! | K10: =AVERAGE(R10,W10,AB10,AG10,AL10,AQ10,AV10) -> #DIV/0! | M10: =RANK(K10, K$7:$K$21) -> #DIV/0! | S10: =RANK(R10, R$7:R$21) -> #N/A | X10: =RANK(W10, W$7:W$21) -> #N/A | AC10: =RANK(AB10, AB$7:AB$21) -> #N/A | AH10: =RANK(AG10, AG$7:AG$21) -> #N/A | AM10: =RANK(AL10, AL$7:AL$21) -> #N/A | AR10: =RANK(AQ10, AQ$7:AQ$21) -> #N/A | AW10: =RANK(AV10, AV$7:AV$21) -> #N/A
C11: 5 | I11: =AVERAGE(P11,U11,Z11,AE11,AJ11,AO11,AT11) -> #DIV/0! | J11: =AVERAGE(Q11,V11,AA11,AF11,AK11,AP11,AU11) -> #DIV/0! | K11: =AVERAGE(R11,W11,AB11,AG11,AL11,AQ11,AV11) -> #DIV/0! | M11: =RANK(K11, K$7:$K$21) -> #DIV/0! | S11: =RANK(R11, R$7:R$21) -> #N/A | X11: =RANK(W11, W$7:W$21) -> #N/A | AC11: =RANK(AB11, AB$7:AB$21) -> #N/A | AH11: =RANK(AG11, AG$7:AG$21) -> #N/A | AM11: =RANK(AL11, AL$7:AL$21) -> #N/A | AR11: =RANK(AQ11, AQ$7:AQ$21) -> #N/A | AW11: =RANK(AV11, AV$7:AV$21) -> #N/A
C12: 6 | I12: =AVERAGE(P12,U12,Z12,AE12,AJ12,AO12,AT12) -> #DIV/0! | J12: =AVERAGE(Q12,V12,AA12,AF12,AK12,AP12,AU12) -> #DIV/0! | K12: =AVERAGE(R12,W12,AB12,AG12,AL12,AQ12,AV12) -> #DIV/0! | M12: =RANK(K12, K$7:$K$21) -> #DIV/0! | S12: =RANK(R12, R$7:R$21) -> #N/A | X12: =RANK(W12, W$7:W$21) -> #N/A | AC12: =RANK(AB12, AB$7:AB$21) -> #N/A | AH12: =RANK(AG12, AG$7:AG$21) -> #N/A | AM12: =RANK(AL12, AL$7:AL$21) -> #N/A | AR12: =RANK(AQ12, AQ$7:AQ$21) -> #N/A | AW12: =RANK(AV12, AV$7:AV$21) -> #N/A
C13: 7 | I13: =AVERAGE(P13,U13,Z13,AE13,AJ13,AO13,AT13) -> #DIV/0! | J13: =AVERAGE(Q13,V13,AA13,AF13,AK13,AP13,AU13) -> #DIV/0! | K13: =AVERAGE(R13,W13,AB13,AG13,AL13,AQ13,AV13) -> #DIV/0! | M13: =RANK(K13, K$7:$K$21) -> #DIV/0! | S13: =RANK(R13, R$7:R$21) -> #N/A | X13: =RANK(W13, W$7:W$21) -> #N/A | AC13: =RANK(AB13, AB$7:AB$21) -> #N/A | AH13: =RANK(AG13, AG$7:AG$21) -> #N/A | AM13: =RANK(AL13, AL$7:AL$21) -> #N/A | AR13: =RANK(AQ13, AQ$7:AQ$21) -> #N/A | AW13: =RANK(AV13, AV$7:AV$21) -> #N/A
C14: 8 | I14: =AVERAGE(P14,U14,Z14,AE14,AJ14,AO14,AT14) -> #DIV/0! | J14: =AVERAGE(Q14,V14,AA14,AF14,AK14,AP14,AU14) -> #DIV/0! | K14: =AVERAGE(R14,W14,AB14,AG14,AL14,AQ14,AV14) -> #DIV/0! | M14: =RANK(K14, K$7:$K$21) -> #DIV/0! | S14: =RANK(R14, R$7:R$21) -> #N/A | X14: =RANK(W14, W$7:W$21) -> #N/A | AC14: =RANK(AB14, AB$7:AB$21) -> #N/A | AH14: =RANK(AG14, AG$7:AG$21) -> #N/A | AM14: =RANK(AL14, AL$7:AL$21) -> #N/A | AR14: =RANK(AQ14, AQ$7:AQ$21) -> #N/A | AW14: =RANK(AV14, AV$7:AV$21) -> #N/A
C15: 9 | I15: =AVERAGE(P15,U15,Z15,AE15,AJ15,AO15,AT15) -> #DIV/0! | J15: =AVERAGE(Q15,V15,AA15,AF15,AK15,AP15,AU15) -> #DIV/0! | K15: =AVERAGE(R15,W15,AB15,AG15,AL15,AQ15,AV15) -> #DIV/0! | M15: =RANK(K15, K$7:$K$21) -> #DIV/0! | S15: =RANK(R15, R$7:R$21) -> #N/A | X15: =RANK(W15, W$7:W$21) -> #N/A | AC15: =RANK(AB15, AB$7:AB$21) -> #N/A | AH15: =RANK(AG15, AG$7:AG$21) -> #N/A | AM15: =RANK(AL15, AL$7:AL$21) -> #N/A | AR15: =RANK(AQ15, AQ$7:AQ$21) -> #N/A | AW15: =RANK(AV15, AV$7:AV$21) -> #N/A
C16: 10 | I16: =AVERAGE(P16,U16,Z16,AE16,AJ16,AO16,AT16) -> #DIV/0! | J16: =AVERAGE(Q16,V16,AA16,AF16,AK16,AP16,AU16) -> #DIV/0! | K16: =AVERAGE(R16,W16,AB16,AG16,AL16,AQ16,AV16) -> #DIV/0! | M16: =RANK(K16, K$7:$K$21) -> #DIV/0! | S16: =RANK(R16, R$7:R$21) -> #N/A | X16: =RANK(W16, W$7:W$21) -> #N/A | AC16: =RANK(AB16, AB$7:AB$21) -> #N/A | AH16: =RANK(AG16, AG$7:AG$21) -> #N/A | AM16: =RANK(AL16, AL$7:AL$21) -> #N/A | AR16: =RANK(AQ16, AQ$7:AQ$21) -> #N/A | AW16: =RANK(AV16, AV$7:AV$21) -> #N/A
C17: 11 | M17: =RANK(K17, K$7:$K$21) -> #DIV/0! | S17: =RANK(R17, R$7:R$21) -> #N/A | X17: =RANK(W17, W$7:W$21) -> #N/A | AC17: =RANK(AB17, AB$7:AB$21) -> #N/A | AH17: =RANK(AG17, AG$7:AG$21) -> #N/A | AM17: =RANK(AL17, AL$7:AL$21) -> #N/A | AR17: =RANK(AQ17, AQ$7:AQ$21) -> #N/A | AW17: =RANK(AV17, AV$7:AV$21) -> #N/A
C18: 12 | M18: =RANK(K18, K$7:$K$21) -> #DIV/0! | S18: =RANK(R18, R$7:R$21) -> #N/A | X18: =RANK(W18, W$7:W$21) -> #N/A | AC18: =RANK(AB18, AB$7:AB$21) -> #N/A | AH18: =RANK(AG18, AG$7:AG$21) -> #N/A | AM18: =RANK(AL18, AL$7:AL$21) -> #N/A | AR18: =RANK(AQ18, AQ$7:AQ$21) -> #N/A | AW18: =RANK(AV18, AV$7:AV$21) -> #N/A
C19: 13 | M19: =RANK(K19, K$7:$K$21) -> #DIV/0! | S19: =RANK(R19, R$7:R$21) -> #N/A | X19: =RANK(W19, W$7:W$21) -> #N/A | AC19: =RANK(AB19, AB$7:AB$21) -> #N/A | AH19: =RANK(AG19, AG$7:AG$21) -> #N/A | AM19: =RANK(AL19, AL$7:AL$21) -> #N/A | AR19: =RANK(AQ19, AQ$7:AQ$21) -> #N/A | AW19: =RANK(AV19, AV$7:AV$21) -> #N/A
C20: 14 | M20: =RANK(K20, K$7:$K$21) -> #DIV/0! | S20: =RANK(R20, R$7:R$21) -> #N/A | X20: =RANK(W20, W$7:W$21) -> #N/A | AC20: =RANK(AB20, AB$7:AB$21) -> #N/A | AH20: =RANK(AG20, AG$7:AG$21) -> #N/A | AM20: =RANK(AL20, AL$7:AL$21) -> #N/A | AR20: =RANK(AQ20, AQ$7:AQ$21) -> #N/A | AW20: =RANK(AV20, AV$7:AV$21) -> #N/A
C21: 15 | M21: =RANK(K21, K$7:$K$21) -> #DIV/0! | S21: =RANK(R21, R$7:R$21) -> #N/A | X21: =RANK(W21, W$7:W$21) -> #N/A | AC21: =RANK(AB21, AB$7:AB$21) -> #N/A | AH21: =RANK(AG21, AG$7:AG$21) -> #N/A | AM21: =RANK(AL21, AL$7:AL$21) -> #N/A | AR21: =RANK(AQ21, AQ$7:AQ$21) -> #N/A | AW21: =RANK(AV21, AV$7:AV$21) -> #N/A
B22: 產線配置圖－每週更新 | N22: 資料繳交 | O22: 日期 | P22: 45874 | U22: 45875 | Z22: 45876 | AE22: 45877 | AJ22: 45878 | AO22: 45879 | AT22: 45880
P23: 二 | U23: 三 | Z23: 四 | AE23: 五 | AJ23: 六 | AO23: 日 | AT23: 一
B24: 品群 | C24: 商品名稱 | E24: 計畫 | H24: 平均人時性 | I24: 實績 | L24: 平均人時性 | M24: 排名 | O24: 日報 | P24: 實際 | T24: 平均人時性 | U24: 實際 | Y24: 平均人時性 | Z24: 實際 | AD24: 平均人時性 | AE24: 實際 | AI24: 平均人時性 | AJ24: 實際 | AN24: 平均人時性 | AO24: 實際 | AS24: 平均人時性 | AT24: 實際 | AX24: 平均人時性
E25: 產線配置圖 | I25: 產線配置圖 | P25: 生產實績 | U25: 生產實績 | Z25: 生產實績 | AE25: 生產實績 | AJ25: 生產實績 | AO25: 生產實績 | AT25: 生產實績
E26: 人數 | F26: 產能／時 | G26: 人時性 | I26: 人數 | J26: 產能／時 | K26: 人時性 | P26: 人數 | Q26: 產能／時 | R26: 人時性 | S26: 排名 | U26: 人數 | V26: 產能／時 | W26: 人時性 | X26: 排名 | Z26: 人數 | AA26: 產能／時 | AB26: 人時性 | AC26: 排名 | AE26: 人數 | AF26: 產能／時 | AG26: 人時性 | AH26: 排名 | AJ26: 人數 | AK26: 產能／時 | AL26: 人時性 | AM26: 排名 | AO26: 人數 | AP26: 產能／時 | AQ26: 人時性 | AR26: 排名 | AT26: 人數 | AU26: 產能／時 | AV26: 人時性 | AW26: 排名
B27: 季節調理麵 | C27: 1 | H27: =AVERAGE(G27:G41) -> #DIV/0! | I27: =AVERAGE(P27,U27,Z27,AE27,AJ27,AO27,AT27) -> #DIV/0! | J27: =AVERAGE(Q27,V27,AA27,AF27,AK27,AP27,AU27) -> #DIV/0! | K27: =AVERAGE(R27,W27,AB27,AG27,AL27,AQ27,AV27) -> #DIV/0! | L27: =AVERAGE(K27:K41) -> #DIV/0! | M27: =RANK(K27, K$27:$K$41) -> #DIV/0! | T27: =AVERAGE(R27:R41) -> #DIV/0! | Y27: =AVERAGE(W27:W41) -> #DIV/0! | AD27: =AVERAGE(AB27:AB41) -> #DIV/0! | AI27: =AVERAGE(AG27:AG41) -> #DIV/0! | AN27: =AVERAGE(AL27:AL41) -> #DIV/0! | AS27: =AVERAGE(AQ27:AQ41) -> #DIV/0! | AX27: =AVERAGE(AV27:AV41) -> #DIV/0!
