Workbook

Sheet 生產管理報表(週) 
A1: 長家廠生產管理報表
A3: 月別 | B3: 6 | C3: 週別 | D3: W4 | E3: 工廠 | F3: 長家廠
A4: （１）收支狀況 | E4: ※單位：千元 | G4: （２）ＫＰＩ達成進度
A5: 項目 | B5: 當週 | C5: 前週 | D5: 差異 | E5: 累計 | G5: 項目 | H5: KPI | I5: 當週 | J5: 前週 | K5: 累計 | L5: ※補充
A6: 業績金額 | B6: ='（１）收支狀況'!G27/1000 -> 20223.118 | C6: 18557.273 | D6: =B6-C6 -> 1665.845 | E6: ='（１）收支狀況'!H5/1000 -> 80775.187 | G6: 人時性(個/月均) | H6: ='（２）ＫＰＩ達成進度'!C1 -> 122.3 | I6: ='（２）ＫＰＩ達成進度'!G27 -> 108.8 | J6: 113.58571 | K6: ='（２）ＫＰＩ達成進度'!H5 -> 111.22759 | L6: 個／MH
A7: 訂單數量 | B7: =SUM('（１）收支狀況'!J27) -> 444044 | C7: 442049 | D7: =B7-C7 -> 1995 | E7: ='（１）收支狀況'!K5 -> 1751581 | G7: 人時達成率(%/月均) | H7: 0.8 | I7: =I6/H6 -> 0.8896157 | J7: =J6/H6 -> 0.92874664 | K7: =K6/H6 -> 0.90946514 | L7: 達成率
A8: 材料費 | B8: ='（１）收支狀況'!M27/1000 -> 12797.665 | C8: 11728.682 | D8: =B8-C8 -> 1068.9824 | E8: ='（１）收支狀況'!N5/1000 -> 51140.268 | G8: 半成品-報廢(%) | H8: 0.0025 | I8: =SUM('日別報廢率總表 '!C26:C32)/SUM('日別報廢率總表 '!B26:B32) -> 0.0024297556 | J8: =SUM('日別報廢率總表 '!C19:C25)/SUM('日別報廢率總表 '!B19:B25) -> 0.0037456243 | K8: ='日別報廢率總表 '!C36/'日別報廢率總表 '!B36 -> 0.0028298778 | L8: 報廢率
A9: 材料費率 | B9: =B8/B6 -> 0.6328235 | C9: =C8/C6 -> 0.63202616 | D9: =B9-C9 -> 0.00079734152 | E9: =E8/E6 -> 0.63311853 | G9: 半成品-超用(%) | H9: 0.0025 | I9: =SUM('日別報廢率總表 '!E26:E32)/SUM('日別報廢率總表 '!B26:B32) -> 0.0031510731 | J9: =SUM('日別報廢率總表 '!E19:E25)/SUM('日別報廢率總表 '!B19:B25) -> 0.0060725742 | K9: ='日別報廢率總表 '!E36/'日別報廢率總表 '!B36 -> 0.0043013966 | L9: 超用率
A10: 勞務成本 | D10: =B10-C10 -> 0 | G10: 固定產線-導入率(%) | H10: 1 | I10: ='（２）ＫＰＩ達成進度'!S27 -> 0.2857 | J10: 0.2857 | K10: ='（２）ＫＰＩ達成進度'!T5 -> 0.2857 | L10: 導入率
A11: 勞務費率 | D11: =B11-C11 -> 0 | G11: 教育訓練-實施率(%) | H11: 1 | I11: ='（２）ＫＰＩ達成進度'!V27 -> 0.8 | J11: 0.8 | K11: ='（２）ＫＰＩ達成進度'!W5 -> 0.8 | L11: 實施率
A13: （３）業績構成比 | G13: （４）訂單數量構成比
B14: 當週 | C14: 比例 | D14: 前週 | E14: 差異 | H14: 當週 | I14: 比例 | J14: 前週 | K14: 差異
A15: 熱食義麵(122,123,124,126) | B15: =SUM('（３）業績構成比'!I29:I35)/1000 -> 17977.836 | C15: =B15/B6 -> 0.88897445 | D15: 0.90799918 | E15: =C15-D15 -> -0.01902473 | G15: 熱食義麵(122,123,124,126) | H15: =SUM('（４）訂單數量構成比'!I29:I35) -> 362699 | I15: =IFERROR(H15/$B$7,"") -> 0.81680869 | J15: 0.793086 | K15: =IFERROR(I15-J15,"") -> 0.023722692
A16: 季節調理麵(111,112) | C16: =IFERROR(B16/$B$6,"") -> 0 | D16: 0 | E16: =IFERROR(C16-D16,"") -> 0 | G16: 季節調理麵(111,112) | I16: =IFERROR(H16/$B$7,"") -> 0 | J16: 0 | K16: =IFERROR(I16-J16,"") -> 0
A17: 微波小吃(153,154,155) | B17: =SUM('（３）業績構成比'!M29:M35)/1000 -> 2245.2828 | C17: =B17/B6 -> 0.11102555 | D17: 0.092000817 | E17: =C17-D17 -> 0.01902473 | G17: 微波小吃(153,154,155) | H17: =SUM('（４）訂單數量構成比'!M29:M35) -> 81345 | I17: =IFERROR(H17/$B$7,"") -> 0.18319131 | J17: 0.206914 | K17: =IFERROR(I17-J17,"") -> -0.023722692
C18: =SUM(C15:C17) -> 1 | D18: =SUM(D15:D17) -> 1 | I18: =SUM(I15:I17) -> 1 | J18: =SUM(J15:J17) -> 1
A20: （５）品群別人時生產性
A21: 品群 | B21: 當週 | C21: 前週 | D21: 差異 | E21: 累計
A22: 熱食義麵(122,123,124,126) | B22: 108.8 | C22: 112.8 | D22: =B22-C22 -> -4 | E22: ='（５-1）品群別人時生產性（熱食義麵）'!C1 -> 110.84042
A23: 季節調理麵(111,112) | D23: =B23-C23 -> 0
A24: 微波小吃(153,154,155) | B24: 121.5 | C24: 123.6 | D24: =B24-C24 -> -2.1 | E24: ='（５-3）品群別人時生產性(微波小吃)'!C1 -> 116.98271

Sheet （１）收支狀況
B2: （１）收支狀況
B3: 資料繳交日 | C3: 月份 | D3: 日期 | F3: 營業額(元) | I3: 訂單數量(個) | L3: 材料費(元) | O3: 材料費率（材料費／營業額） | R3: 勞務成本（全廠人事成本） | U3: 勞務費率（勞務成本／營業額）
F4: 日 | G4: 週累積 | H4: 月累積 | I4: 日 | J4: 週累積 | K4: 月累積 | L4: 日 | M4: 週累積 | N4: 月累積 | O4: 日 | P4: 週累積 | Q4: 月累積 | R4: 日 | S4: 週累積 | T4: 月累積 | U4: 日 | V4: 週累積 | W4: 月累積
C5: 六 | D5: 46174 | E5: 一 | F5: 2835003 | G5: =SUM(F5) -> 2835003 | H5: =SUM(F5:F34) -> 80775187 | I5: 64603 | J5: =SUM(I5) -> 64603 | K5: =SUM(I5:I34) -> 1751581 | L5: 1795051.9 | M5: =SUM(L5) -> 1795051.9 | N5: =SUM(L5:L34) -> 51140268 | O5: =L5/F5 -> 0.6331746 | P5: =M5/G5 -> 0.6331746 | Q5: =N5/H5 -> 0.63311853 | S5: =SUM(R5) -> 0 | T5: =SUM(R5:R36) -> 0 | U5: =R5/F5 -> 0 | V5: =S5/M5 -> 0 | W5: =T5/N5 -> 0
B6: 46182 | D6: 46175 | E6: 二 | F6: 2722521.9 | G6: =SUM(F6:F12) -> 18052963 | I6: 62091 | J6: =SUM(I6:I12) -> 407538 | L6: 1725188.8 | M6: =SUM(L6:L12) -> 11435367 | O6: =L6/F6 -> 0.63367307 | P6: =M6/G6 -> 0.63343434 | S6: =SUM(R6:R12) -> 0 | U6: =R6/F6 -> 0 | V6: =S6/M6 -> 0
D7: 46176 | E7: 三 | F7: 2452866.6 | I7: 55658 | L7: 1554006 | O7: =L7/F7 -> 0.63354687 | U7: =R7/F7 -> 0
D8: 46177 | E8: 四 | F8: 2382946.1 | I8: 54358 | L8: 1509256 | O8: =L8/F8 -> 0.63335719 | U8: =R8/F8 -> 0
D9: 46178 | E9: 五 | F9: 1944479.1 | I9: 46341 | L9: 1232021.8 | O9: =L9/F9 -> 0.63359994 | U9: =R9/F9 -> 0
D10: 46179 | E10: 六 | F10: 2318273.6 | I10: 53256 | L10: 1468512.4 | O10: =L10/F10 -> 0.63345084 | U10: =R10/F10 -> 0
D11: 46180 | E11: 日 | F11: 2991875.1 | I11: 68143 | L11: 1894881.3 | O11: =L11/F11 -> 0.63334239 | U11: =R11/F11 -> 0
D12: 46181 | E12: 一 | F12: 3240000.7 | I12: 67691 | L12: 2051500.4 | O12: =L12/F12 -> 0.63317901 | U12: =R12/F12 -> 0
B13: 46189 | D13: 46182 | E13: 二 | F13: 3508974.2 | G13: =SUM(F13:F19) -> 21305360 | I13: 73200 | J13: =SUM(I13:I19) -> 442049 | L13: 2219653.8 | M13: =SUM(L13:L19) -> 13486877 | O13: =L13/F13 -> 0.63256485 | P13: =M13/G13 -> 0.63302741 | S13: =SUM(R13:R19) -> 0 | U13: =R13/F13 -> 0 | V13: =S13/M13 -> 0
D14: 46183 | E14: 三 | F14: 3139481 | I14: 64942 | L14: 1986873 | O14: =L14/F14 -> 0.63286672 | U14: =R14/F14 -> 0
D15: 46184 | E15: 四 | F15: 3042840.9 | I15: 62899 | L15: 1926989.7 | O15: =L15/F15 -> 0.6332864 | U15: =R15/F15 -> 0
D16: 46185 | E16: 五 | F16: 2238951.4 | I16: 46456 | L16: 1417539.4 | O16: =L16/F16 -> 0.63312646 | U16: =R16/F16 -> 0
D17: 46186 | E17: 六 | F17: 2665425.6 | I17: 55395 | L17: 1686718.1 | O17: =L17/F17 -> 0.63281381 | U17: =R17/F17 -> 0
D18: 46187 | E18: 日 | F18: 3415399.9 | I18: 70645 | L18: 2162701.9 | O18: =L18/F18 -> 0.63322071 | U18: =R18/F18 -> 0
D19: 46188 | E19: 一 | F19: 3294287.4 | I19: 68512 | L19: 2086401.1 | O19: =L19/F19 -> 0.63333911 | U19: =R19/F19 -> 0
B20: 46196 | D20: 46189 | E20: 二 | F20: 3209761.2 | G20: =SUM(F20:F26) -> 18358742 | I20: 69273 | J20: =SUM(I20:I26) -> 393347 | L20: 2032149.5 | M20: =SUM(L20:L26) -> 11625308 | O20: =L20/F20 -> 0.6331155 | P20: =M20/G20 -> 0.63323007 | S20: =SUM(R20:R26) -> 0 | U20: =R20/F20 -> 0 | V20: =S20/M20 -> 0
D21: 46190 | E21: 三 | F21: 2739001.4 | I21: 59082 | L21: 1734570.9 | O21: =L21/F21 -> 0.63328587 | U21: =R21/F21 -> 0
D22: 46191 | E22: 四 | F22: 2148217.9 | I22: 45667 | L22: 1360077.3 | O22: =L22/F22 -> 0.63311886 | U22: =R22/F22 -> 0
D23: 46192 | E23: 五 | F23: 2051065 | I23: 43813 | L23: 1299170.9 | O23: =L23/F23 -> 0.63341286 | U23: =R23/F23 -> 0
D24: 46193 | E24: 六 | F24: 2183098.7 | I24: 46311 | L24: 1382352.2 | O24: =L24/F24 -> 0.63320645 | U24: =R24/F24 -> 0
D25: 46194 | E25: 日 | F25: 3045937.9 | I25: 65708 | L25: 1928940.9 | O25: =L25/F25 -> 0.63328306 | U25: =R25/F25 -> 0
D26: 46195 | E26: 一 | F26: 2981660.1 | I26: 63493 | L26: 1888045.8 | O26: =L26/F26 -> 0.63321968 | U26: =R26/F26 -> 0
B27: 46203 | D27: 46196 | E27: 二 | F27: 3337100 | G27: =SUM(F27:F33) -> 20223118 | I27: 71426 | J27: =SUM(I27:I33) -> 444044 | L27: 2112373 | M27: =SUM(L27:L33) -> 12797665 | O27: =L27/F27 -> 0.63299661 | P27: =M27/G27 -> 0.6328235 | S27: =SUM(R27:R33) -> 0 | U27: =R27/F27 -> 0 | V27: =S27/M27 -> 0
D28: 46197 | E28: 三 | F28: 2882994.2 | I28: 62078 | L28: 1825286.3 | O28: =L28/F28 -> 0.63312175 | U28: =R28/F28 -> 0
D29: 46198 | E29: 四 | F29: 2814327.4 | I29: 60486 | L29: 1781026.2 | O29: =L29/F29 -> 0.6328426 | U29: =R29/F29 -> 0
D30: 46199 | E30: 五 | F30: 2265418.4 | I30: 48943 | L30: 1433013.6 | O30: =L30/F30 -> 0.63256023 | U30: =R30/F30 -> 0
D31: 46200 | E31: 六 | F31: 2274198.5 | I31: 58607 | L31: 1439045.1 | O31: =L31/F31 -> 0.63277021 | U31: =R31/F31 -> 0
D32: 46201 | E32: 日 | F32: 3370259.7 | I32: 72372 | L32: 2132263.6 | O32: =L32/F32 -> 0.63267042 | U32: =R32/F32 -> 0
D33: 46202 | E33: 一 | F33: 3278820.1 | I33: 70132 | L33: 2074656.7 | O33: =L33/F33 -> 0.63274489 | U33: =R33/F33 -> 0
D34: 46203 | E34: 二 | O34: =L34/F34 -> #DIV/0! | U34: =R34/F34 -> #DIV/0!
U35: =R35/F35 -> #DIV/0!

Sheet （２）ＫＰＩ達成進度
C1: 122.3 | D1: 132.1
B2: （２）ＫＰＩ達成進度
B3: 資料繳交日 | C3: 月份 | D3: 日期 | F3: 人時生產性(個/人) | I3: 人時生產性達成率(%) | L3: 半成品報廢(%) | O3: 半成品超用(%) | R3: 固定產線-導入率(固定產線數/總產線數) | U3: 教育訓練-實施率(進度/計畫)
F4: 日 | G4: 週平均 | H4: 月平均 | I4: 日 | J4: 週平均 | K4: 月平均 | L4: 日 | M4: 週平均 | N4: 月平均 | O4: 日 | P4: 週平均 | Q4: 月平均 | R4: 日 | S4: 週平均 | T4: 月平均 | U4: 日 | V4: 週平均 | W4: 月平均
C5: 六 | D5: 46174 | E5: 一 | F5: 113.1 | G5: =AVERAGE(F5) -> 113.1 | H5: =AVERAGE(F5:F34) -> 111.22759 | I5: =F5/$C$1 -> 0.92477514 | J5: =AVERAGE(I5) -> 0.92477514 | K5: =AVERAGE(I5:I34) -> 0.90946514 | L5: ='日別報廢率總表 '!D4 -> 0.001406143 | M5: =AVERAGE(L5) -> 0.001406143 | N5: =AVERAGE(L5:L34) -> 0.003114795 | O5: ='日別報廢率總表 '!F4 -> 0.0023580468 | P5: =AVERAGE(O5) -> 0.0023580468 | Q5: =AVERAGE(O5:O34) -> 0.0046962068 | R5: 0.2857 | S5: =AVERAGE(R5) -> 0.2857 | T5: =AVERAGE(R5:R33) -> 0.2857 | U5: 0.95 | V5: =AVERAGE(U5) -> 0.95 | W5: =AVERAGE(U5:U33) -> 0.8
B6: 46182 | D6: 46175 | E6: 二 | F6: 104.1 | G6: =AVERAGE(F6:F12) -> 108.45714 | I6: =F6/$C$1 -> 0.85118561 | J6: =AVERAGE(I6:I12) -> 0.88681229 | L6: ='日別報廢率總表 '!D5 -> 0.0010512731 | M6: =AVERAGE(L6:L12) -> 0.0033285442 | O6: ='日別報廢率總表 '!F5 -> 0.0025922333 | P6: =AVERAGE(O6:O12) -> 0.0049776008 | R6: 0.2857 | S6: =AVERAGE(R6:R12) -> 0.2857 | U6: 0.75 | V6: =AVERAGE(U6:U12) -> 0.77857143
D7: 46176 | E7: 三 | F7: 104.6 | I7: =F7/$C$1 -> 0.85527392 | L7: ='日別報廢率總表 '!D6 -> 0.0032308752 | O7: ='日別報廢率總表 '!F6 -> 0.0053133247 | R7: 0.2857 | U7: 0.75
D8: 46177 | E8: 四 | F8: 111.8 | I8: =F8/$C$1 -> 0.91414554 | L8: ='日別報廢率總表 '!D7 -> 0.0023410243 | O8: ='日別報廢率總表 '!F7 -> 0.0022957244 | R8: 0.2857 | U8: 0.75
D9: 46178 | E9: 五 | F9: 110.3 | I9: =F9/$C$1 -> 0.90188062 | L9: ='日別報廢率總表 '!D8 -> 0.013257478 | O9: ='日別報廢率總表 '!F8 -> 0.018265767 | R9: 0.2857 | U9: 0.8
D10: 46179 | E10: 六 | F10: 107.8 | I10: =F10/$C$1 -> 0.88143908 | L10: ='日別報廢率總表 '!D9 -> 0.0010332132 | O10: ='日別報廢率總表 '!F9 -> 0.0033441432 | R10: 0.2857 | U10: 0.8
D11: 46180 | E11: 日 | F11: 110.8 | I11: =F11/$C$1 -> 0.90596893 | L11: ='日別報廢率總表 '!D10 -> 0.0010210003 | O11: ='日別報廢率總表 '!F10 -> 0.0024491895 | R11: 0.2857 | U11: 0.8
D12: 46181 | E12: 一 | F12: 109.8 | I12: =F12/$C$1 -> 0.89779231 | L12: ='日別報廢率總表 '!D11 -> 0.0013649457 | O12: ='日別報廢率總表 '!F11 -> 0.00058282333 | R12: 0.2857 | U12: 0.8
B13: 46189 | D13: 46182 | E13: 二 | F13: 110.1 | G13: =AVERAGE(F13:F19) -> 113.8 | I13: =F13/$C$1 -> 0.9002453 | J13: =AVERAGE(I13:I19) -> 0.93049877 | L13: ='日別報廢率總表 '!D12 -> 0.0015576526 | M13: =AVERAGE(L13:L19) -> 0.0027684545 | O13: ='日別報廢率總表 '!F12 -> 0.0031435727 | P13: =AVERAGE(O13:O19) -> 0.0042695458 | R13: 0.2857 | S13: =AVERAGE(R13:R19) -> 0.2857 | U13: 0.8 | V13: =AVERAGE(U13:U19) -> 0.8
D14: 46183 | E14: 三 | F14: 113.3 | I14: =F14/$C$1 -> 0.92641047 | L14: ='日別報廢率總表 '!D13 -> 0.0028392494 | O14: ='日別報廢率總表 '!F13 -> 0.0041986055 | R14: 0.2857 | U14: 0.8
D15: 46184 | E15: 四 | F15: 112.6 | I15: =F15/$C$1 -> 0.92068684 | L15: ='日別報廢率總表 '!D14 -> 0.00085563331 | O15: ='日別報廢率總表 '!F14 -> 0.001335412 | R15: 0.2857 | U15: 0.8
D16: 46185 | E16: 五 | F16: 114.5 | I16: =F16/$C$1 -> 0.9362224 | L16: ='日別報廢率總表 '!D15 -> 0.0072236617 | O16: ='日別報廢率總表 '!F15 -> 0.0087700052 | R16: 0.2857 | U16: 0.8
D17: 46186 | E17: 六 | F17: 115.4 | I17: =F17/$C$1 -> 0.94358136 | L17: ='日別報廢率總表 '!D16 -> 0.0024199711 | O17: ='日別報廢率總表 '!F16 -> 0.0035087385 | R17: 0.2857 | U17: 0.8
D18: 46187 | E18: 日 | F18: 112.1 | I18: =F18/$C$1 -> 0.91659853 | L18: ='日別報廢率總表 '!D17 -> 0.002504706 | O18: ='日別報廢率總表 '!F17 -> 0.0067843472 | R18: 0.2857 | U18: 0.8
D19: 46188 | E19: 一 | F19: 118.6 | I19: =F19/$C$1 -> 0.96974652 | L19: ='日別報廢率總表 '!D18 -> 0.0019783076 | O19: ='日別報廢率總表 '!F18 -> 0.0021461398 | R19: 0.2857 | U19: 0.8
B20: 46196 | D20: 46189 | E20: 二 | F20: 113.8 | G20: =AVERAGE(F20:F26) -> 113.58571 | I20: =F20/$C$1 -> 0.93049877 | J20: =AVERAGE(I20:I26) -> 0.92874664 | L20: ='日別報廢率總表 '!D19 -> 0.0031413507 | M20: =AVERAGE(L20:L26) -> 0.0038834882 | O20: ='日別報廢率總表 '!F19 -> 0.0046607445 | P20: =AVERAGE(O20:O26) -> 0.006328147 | R20: 0.2857 | S20: =AVERAGE(R20:R26) -> 0.2857 | U20: 0.8 | V20: =AVERAGE(U20:U26) -> 0.8
D21: 46190 | E21: 三 | F21: 114.5 | I21: =F21/$C$1 -> 0.9362224 | L21: ='日別報廢率總表 '!D20 -> 0.0076825287 | O21: ='日別報廢率總表 '!F20 -> 0.01086359 | R21: 0.2857 | U21: 0.8
D22: 46191 | E22: 四 | F22: 111.5 | I22: =F22/$C$1 -> 0.91169256 | L22: ='日別報廢率總表 '!D21 -> 0.00769257 | O22: ='日別報廢率總表 '!F21 -> 0.013364993 | R22: 0.2857 | U22: 0.8
D23: 46192 | E23: 五 | F23: 112.1 | I23: =F23/$C$1 -> 0.91659853 | L23: ='日別報廢率總表 '!D22 -> 0.0044302163 | O23: ='日別報廢率總表 '!F22 -> 0.0062738244 | R23: 0.2857 | U23: 0.8
D24: 46193 | E24: 六 | F24: 114.7 | I24: =F24/$C$1 -> 0.93785773 | L24: ='日別報廢率總表 '!D23 -> 0.00091542356 | O24: ='日別報廢率總表 '!F23 -> 0.0028476962 | R24: 0.2857 | U24: 0.8
D25: 46194 | E25: 日 | F25: 113.6 | I25: =F25/$C$1 -> 0.92886345 | L25: ='日別報廢率總表 '!D24 -> 0.0019138474 | O25: ='日別報廢率總表 '!F24 -> 0.0035869924 | R25: 0.2857 | U25: 0.8
D26: 46195 | E26: 一 | F26: 114.9 | I26: =F26/$C$1 -> 0.93949305 | L26: ='日別報廢率總表 '!D25 -> 0.0014084806 | O26: ='日別報廢率總表 '!F25 -> 0.0026991877 | R26: 0.2857 | U26: 0.8
B27: 46203 | D27: 46196 | E27: 二 | F27: 110.1 | G27: =AVERAGE(F27:F33) -> 108.8 | I27: =F27/$C$1 -> 0.9002453 | J27: =AVERAGE(I27:I33) -> 0.8896157 | L27: 0.0012687569 | M27: =AVERAGE(L27:L33) -> 0.0027227864 | O27: 0.0019496222 | P27: =AVERAGE(O27:O33) -> 0.0035435563 | R27: 0.2857 | S27: =AVERAGE(R27:R33) -> 0.2857 | U27: 0.8 | V27: =AVERAGE(U27:U33) -> 0.8
D28: 46197 | E28: 三 | F28: 108 | I28: =F28/$C$1 -> 0.88307441 | L28: 0.0013829079 | O28: 0.0022644906 | R28: 0.2857 | U28: 0.8
D29: 46198 | E29: 四 | F29: 108.6 | I29: =F29/$C$1 -> 0.88798038 | L29: 0.0020971448 | O29: 0.0032410442 | R29: 0.2857 | U29: 0.8
D30: 46199 | E30: 五 | F30: 107 | I30: =F30/$C$1 -> 0.87489779 | L30: 0.010418428 | O30: 0.013413624 | R30: 0.2857 | U30: 0.8
D31: 46200 | E31: 六 | F31: 108.1 | I31: =F31/$C$1 -> 0.88389207 | L31: 0.0014966272 | O31: 0.0018751045 | R31: 0.2857 | U31: 0.8
D32: 46201 | E32: 日 | F32: 109.5 | I32: =F32/$C$1 -> 0.89533933 | L32: 0.0016809087 | O32: 0.0017395117 | R32: 0.2857 | U32: 0.8
D33: 46202 | E33: 一 | F33: 110.3 | I33: =F33/$C$1 -> 0.90188062 | L33: 0.00071473042 | O33: 0.0003214972 | R33: 0.2857 | U33: 0.8
D34: 46203 | E34: 二
H45: 0.91568164
H46: 0.90622537
H47: 0.88967691
H48: 0.86997636
H49: 0.91883373
H50: 0.88337273
...

Sheet （３）業績構成比
B2: （3）業績構成比
B3: 資料繳交日 | C3: 月份 | D3: 日期 | F3: 營業額 | I3: 品類業績
I4: 熱食義麵 | K4: 季節調理麵 | M4: 微波小吃
F5: 日 | G5: 週累積 | H5: 月累積 | I5: 一配 | K5: 一配 | M5: 一配
I6: 業績(元) | J6: 比例(%) | K6: 業績(元) | L6: 比例(%) | M6: 業績(元) | N6: 比例(%)
C7: 六 | D7: 46174 | E7: 一 | F7: =I7+M7 -> 2835003 | G7: =SUM(F7) -> 2835003 | H7: =SUM(F7:F36) -> 80775187 | I7: 2544713.9 | J7: =I7/F7 -> 0.89760535 | L7: =K7/F7 -> 0 | M7: 290289.13 | N7: =M7/F7 -> 0.10239465
B8: 46182 | D8: 46175 | E8: 二 | F8: =I8+M8 -> 2722521.9 | G8: =SUM(F8:F14) -> 18052963 | I8: 2443673.3 | J8: =I8/F8 -> 0.89757711 | L8: =K8/F8 -> 0 | M8: 278848.56 | N8: =M8/F8 -> 0.10242289
D9: 46176 | E9: 三 | F9: =I9+M9 -> 2452866.6 | I9: 2208140.7 | J9: =I9/F9 -> 0.90022859 | L9: =K9/F9 -> 0 | M9: 244725.97 | N9: =M9/F9 -> 0.099771413
D10: 46177 | E10: 四 | F10: =I10+M10 -> 2382946.1 | I10: 2144642.4 | J10: =I10/F10 -> 0.89999619 | L10: =K10/F10 -> 0 | M10: 238303.68 | N10: =M10/F10 -> 0.10000381
D11: 46178 | E11: 五 | F11: =I11+M11 -> 1944479.1 | I11: 1727826.7 | J11: =I11/F11 -> 0.88858078 | L11: =K11/F11 -> 0 | M11: 216652.34 | N11: =M11/F11 -> 0.11141922
D12: 46179 | E12: 六 | F12: =I12+M12 -> 2318273.6 | I12: 2087765.6 | J12: =I12/F12 -> 0.9005691 | L12: =K12/F12 -> 0 | M12: 230508.04 | N12: =M12/F12 -> 0.099430903
D13: 46180 | E13: 日 | F13: =I13+M13 -> 2991875.1 | I13: 2708252 | J13: =I13/F13 -> 0.90520221 | L13: =K13/F13 -> 0 | M13: 283623.14 | N13: =M13/F13 -> 0.094797786
D14: 46181 | E14: 一 | F14: =I14+M14 -> 3240000.7 | I14: 2957745.5 | J14: =I14/F14 -> 0.91288421 | L14: =K14/F14 -> 0 | M14: 282255.22 | N14: =M14/F14 -> 0.08711579
B15: 46189 | D15: 46182 | E15: 二 | F15: =I15+M15 -> 3508974.2 | G15: =SUM(F15:F21) -> 21305360 | I15: 3234220.6 | J15: =I15/F15 -> 0.92169972 | L15: =K15/F15 -> 0 | M15: 274753.68 | N15: =M15/F15 -> 0.078300284
D16: 46183 | E16: 三 | F16: =I16+M16 -> 3139481 | I16: 2895039.1 | J16: =I16/F16 -> 0.9221394 | L16: =K16/F16 -> 0 | M16: 244441.86 | N16: =M16/F16 -> 0.077860596
D17: 46184 | E17: 四 | F17: =I17+M17 -> 3042840.9 | I17: 2806182.4 | J17: =I17/F17 -> 0.92222449 | L17: =K17/F17 -> 0 | M17: 236658.49 | N17: =M17/F17 -> 0.077775507
D18: 46185 | E18: 五 | F18: =I18+M18 -> 2238951.4 | I18: 2043345.1 | J18: =I18/F18 -> 0.91263487 | L18: =K18/F18 -> 0 | M18: 195606.27 | N18: =M18/F18 -> 0.087365126
D19: 46186 | E19: 六 | F19: =I19+M19 -> 2665425.6 | I19: 2446847.6 | J19: =I19/F19 -> 0.91799507 | L19: =K19/F19 -> 0 | M19: 218578.05 | N19: =M19/F19 -> 0.082004933
D20: 46187 | E20: 日 | F20: =I20+M20 -> 3415399.9 | I20: 3155486.9 | J20: =I20/F20 -> 0.92389968 | L20: =K20/F20 -> 0 | M20: 259913.03 | N20: =M20/F20 -> 0.076100321
D21: 46188 | E21: 一 | F21: =I21+M21 -> 3294287.4 | I21: 3017030.4 | J21: =I21/F21 -> 0.91583704 | L21: =K21/F21 -> 0 | M21: 277256.97 | N21: =M21/F21 -> 0.084162957
B22: 46196 | D22: 46189 | E22: 二 | F22: =I22+M22 -> 3209761.2 | G22: =SUM(F22:F28) -> 18358742 | I22: 2788792.9 | J22: =I22/F22 -> 0.86884746 | L22: =K22/F22 -> 0 | M22: 420968.32 | N22: =M22/F22 -> 0.13115254
D23: 46190 | E23: 三 | F23: =I23+M23 -> 2739001.4 | I23: 2378480.3 | J23: =I23/F23 -> 0.868375 | L23: =K23/F23 -> 0 | M23: 360521.07 | N23: =M23/F23 -> 0.131625
D24: 46191 | E24: 四 | F24: =I24+M24 -> 2148217.9 | I24: 1909519.3 | J24: =I24/F24 -> 0.8888853 | L24: =K24/F24 -> 0 | M24: 238698.58 | N24: =M24/F24 -> 0.1111147
D25: 46192 | E25: 五 | F25: =I25+M25 -> 2051065 | I25: 1797796.4 | J25: =I25/F25 -> 0.87651852 | L25: =K25/F25 -> 0 | M25: 253268.55 | N25: =M25/F25 -> 0.12348148
D26: 46193 | E26: 六 | F26: =I26+M26 -> 2183098.7 | I26: 1939583.9 | J26: =I26/F26 -> 0.8884545 | L26: =K26/F26 -> 0 | M26: 243514.84 | N26: =M26/F26 -> 0.1115455
D27: 46194 | E27: 日 | F27: =I27+M27 -> 3045937.9 | I27: 2651797.9 | J27: =I27/F27 -> 0.87060143 | L27: =K27/F27 -> 0 | M27: 394140.02 | N27: =M27/F27 -> 0.12939857
D28: 46195 | E28: 一 | F28: =I28+M28 -> 2981660.1 | I28: 2644154.9 | J28: =I28/F28 -> 0.8868063 | L28: =K28/F28 -> 0 | M28: 337505.14 | N28: =M28/F28 -> 0.1131937
B29: 46203 | D29: 46196 | E29: 二 | F29: =I29+M29 -> 3337100 | G29: =SUM(F29:F35) -> 20223118 | I29: 3007578.9 | J29: =I29/F29 -> 0.90125525 | L29: =K29/F29 -> 0 | M29: 329521.12 | N29: =M29/F29 -> 0.098744754
D30: 46197 | E30: 三 | F30: =I30+M30 -> 2882994.2 | I30: 2553464.6 | J30: =I30/F30 -> 0.88569885 | L30: =K30/F30 -> 0 | M30: 329529.55 | N30: =M30/F30 -> 0.11430115
D31: 46198 | E31: 四 | F31: =I31+M31 -> 2814327.4 | I31: 2498396.1 | J31: =I31/F31 -> 0.88774182 | L31: =K31/F31 -> 0 | M31: 315931.28 | N31: =M31/F31 -> 0.11225818
D32: 46199 | E32: 五 | F32: =I32+M32 -> 2265418.4 | I32: 2001352.7 | J32: =I32/F32 -> 0.88343623 | L32: =K32/F32 -> 0 | M32: 264065.72 | N32: =M32/F32 -> 0.11656377
D33: 46200 | E33: 六 | F33: =I33+M33 -> 2274198.5 | I33: 1976105 | J33: =I33/F33 -> 0.86892371 | L33: =K33/F33 -> 0 | M33: 298093.52 | N33: =M33/F33 -> 0.13107629
D34: 46201 | E34: 日 | F34: =I34+M34 -> 3370259.7 | I34: 3016228 | J34: =I34/F34 -> 0.89495417 | L34: =K34/F34 -> 0 | M34: 354031.74 | N34: =M34/F34 -> 0.10504583
D35: 46202 | E35: 一 | F35: =I35+M35 -> 3278820.1 | I35: 2924710.3 | J35: =I35/F35 -> 0.89200083 | L35: =K35/F35 -> 0 | M35: 354109.86 | N35: =M35/F35 -> 0.10799917
D36: 46203 | E36: 二 | F36: =I36+M36 -> 0 | J36: =I36/F36 -> #DIV/0! | L36: =K36/F36 -> #DIV/0! | N36: =M36/F36 -> #DIV/0!

Sheet （４）訂單數量構成比
B2: （4）訂單數量構成比
B3: 資料繳交日 | C3: 月份 | D3: 日期 | F3: 訂單量 | I3: 品類訂單量
I4: 熱食義麵 | K4: 季節調理麵 | M4: 微波小吃
F5: 日 | G5: 週累積 | H5: 月累積 | I5: 一配 | K5: 一配 | M5: 一配
I6: 訂單數 | J6: 比例(%) | K6: 訂單數 | L6: 比例(%) | M6: 訂單數 | N6: 比例(%)
C7: 六 | D7: 46174 | E7: 一 | F7: =SUM(I7,K7,M7) -> 64603 | G7: =SUM(F7) -> 64603 | H7: =SUM(F7:F36) -> 1751581 | I7: 53944 | J7: =I7/F7 -> 0.83500766 | L7: =K7/F7 -> 0 | M7: 10659 | N7: =M7/F7 -> 0.16499234
B8: 46182 | D8: 46175 | E8: 二 | F8: =SUM(I8,K8,M8) -> 62091 | G8: =SUM(F8:F14) -> 407538 | I8: 51859 | J8: =I8/F8 -> 0.83520961 | L8: =K8/F8 -> 0 | M8: 10232 | N8: =M8/F8 -> 0.16479039
D9: 46176 | E9: 三 | F9: =SUM(I9,K9,M9) -> 55658 | I9: 46680 | J9: =I9/F9 -> 0.83869345 | L9: =K9/F9 -> 0 | M9: 8978 | N9: =M9/F9 -> 0.16130655
D10: 46177 | E10: 四 | F10: =SUM(I10,K10,M10) -> 54358 | I10: 45611 | J10: =I10/F10 -> 0.83908532 | L10: =K10/F10 -> 0 | M10: 8747 | N10: =M10/F10 -> 0.16091468
D11: 46178 | E11: 五 | F11: =SUM(I11,K11,M11) -> 46341 | I11: 38387 | J11: =I11/F11 -> 0.82835934 | L11: =K11/F11 -> 0 | M11: 7954 | N11: =M11/F11 -> 0.17164066
D12: 46179 | E12: 六 | F12: =SUM(I12,K12,M12) -> 53256 | I12: 44801 | J12: =I12/F12 -> 0.84123855 | L12: =K12/F12 -> 0 | M12: 8455 | N12: =M12/F12 -> 0.15876145
D13: 46180 | E13: 日 | F13: =SUM(I13,K13,M13) -> 68143 | I13: 57735 | J13: =I13/F13 -> 0.84726237 | L13: =K13/F13 -> 0 | M13: 10408 | N13: =M13/F13 -> 0.15273763
D14: 46181 | E14: 一 | F14: =SUM(I14,K14,M14) -> 67691 | I14: 57337 | J14: =I14/F14 -> 0.84704023 | L14: =K14/F14 -> 0 | M14: 10354 | N14: =M14/F14 -> 0.15295977
B15: 46189 | D15: 46182 | E15: 二 | F15: =SUM(I15,K15,M15) -> 73200 | G15: =SUM(F15:F21) -> 442049 | I15: 63123 | J15: =I15/F15 -> 0.86233607 | L15: =K15/F15 -> 0 | M15: 10077 | N15: =M15/F15 -> 0.13766393
D16: 46183 | E16: 三 | F16: =SUM(I16,K16,M16) -> 64942 | I16: 55966 | J16: =I16/F16 -> 0.86178436 | L16: =K16/F16 -> 0 | M16: 8976 | N16: =M16/F16 -> 0.13821564
D17: 46184 | E17: 四 | F17: =SUM(I17,K17,M17) -> 62899 | I17: 54213 | J17: =I17/F17 -> 0.86190559 | L17: =K17/F17 -> 0 | M17: 8686 | N17: =M17/F17 -> 0.13809441
D18: 46185 | E18: 五 | F18: =SUM(I18,K18,M18) -> 46456 | I18: 39286 | J18: =I18/F18 -> 0.84566041 | L18: =K18/F18 -> 0 | M18: 7170 | N18: =M18/F18 -> 0.15433959
D19: 46186 | E19: 六 | F19: =SUM(I19,K19,M19) -> 55395 | I19: 47382 | J19: =I19/F19 -> 0.85534796 | L19: =K19/F19 -> 0 | M19: 8013 | N19: =M19/F19 -> 0.14465204
D20: 46187 | E20: 日 | F20: =SUM(I20,K20,M20) -> 70645 | I20: 61112 | J20: =I20/F20 -> 0.86505768 | L20: =K20/F20 -> 0 | M20: 9533 | N20: =M20/F20 -> 0.13494232
D21: 46188 | E21: 一 | F21: =SUM(I21,K21,M21) -> 68512 | I21: 58336 | J21: =I21/F21 -> 0.85147128 | L21: =K21/F21 -> 0 | M21: 10176 | N21: =M21/F21 -> 0.14852872
B22: 46196 | D22: 46189 | E22: 二 | F22: =SUM(I22,K22,M22) -> 69273 | G22: =SUM(F22:F28) -> 393347 | I22: 54069 | J22: =I22/F22 -> 0.78052055 | L22: =K22/F22 -> 0 | M22: 15204 | N22: =M22/F22 -> 0.21947945
D23: 46190 | E23: 三 | F23: =SUM(I23,K23,M23) -> 59082 | I23: 46055 | J23: =I23/F23 -> 0.77950983 | L23: =K23/F23 -> 0 | M23: 13027 | N23: =M23/F23 -> 0.22049017
D24: 46191 | E24: 四 | F24: =SUM(I24,K24,M24) -> 45667 | I24: 37013 | J24: =I24/F24 -> 0.81049773 | L24: =K24/F24 -> 0 | M24: 8654 | N24: =M24/F24 -> 0.18950227
D25: 46192 | E25: 五 | F25: =SUM(I25,K25,M25) -> 43813 | I25: 34640 | J25: =I25/F25 -> 0.79063292 | L25: =K25/F25 -> 0 | M25: 9173 | N25: =M25/F25 -> 0.20936708
D26: 46193 | E26: 六 | F26: =SUM(I26,K26,M26) -> 46311 | I26: 37481 | J26: =I26/F26 -> 0.80933256 | L26: =K26/F26 -> 0 | M26: 8830 | N26: =M26/F26 -> 0.19066744
D27: 46194 | E27: 日 | F27: =SUM(I27,K27,M27) -> 65708 | I27: 51451 | J27: =I27/F27 -> 0.7830249 | L27: =K27/F27 -> 0 | M27: 14257 | N27: =M27/F27 -> 0.2169751
D28: 46195 | E28: 一 | F28: =SUM(I28,K28,M28) -> 63493 | I28: 51249 | J28: =I28/F28 -> 0.80715984 | L28: =K28/F28 -> 0 | M28: 12244 | N28: =M28/F28 -> 0.19284016
B29: 46203 | D29: 46196 | E29: 二 | F29: =SUM(I29,K29,M29) -> 71426 | G29: =SUM(F29:F35) -> 444044 | I29: 59460 | J29: =I29/F29 -> 0.83246997 | L29: =K29/F29 -> 0 | M29: 11966 | N29: =M29/F29 -> 0.16753003
D30: 46197 | E30: 三 | F30: =SUM(I30,K30,M30) -> 62078 | I30: 50140 | J30: =I30/F30 -> 0.80769355 | L30: =K30/F30 -> 0 | M30: 11938 | N30: =M30/F30 -> 0.19230645
D31: 46198 | E31: 四 | F31: =SUM(I31,K31,M31) -> 60486 | I31: 49053 | J31: =I31/F31 -> 0.81098105 | L31: =K31/F31 -> 0 | M31: 11433 | N31: =M31/F31 -> 0.18901895
D32: 46199 | E32: 五 | F32: =SUM(I32,K32,M32) -> 48943 | I32: 39390 | J32: =I32/F32 -> 0.80481376 | L32: =K32/F32 -> 0 | M32: 9553 | N32: =M32/F32 -> 0.19518624
D33: 46200 | E33: 六 | F33: =SUM(I33,K33,M33) -> 58607 | I33: 47811 | J33: =I33/F33 -> 0.81578992 | L33: =K33/F33 -> 0 | M33: 10796 | N33: =M33/F33 -> 0.18421008
D34: 46201 | E34: 日 | F34: =SUM(I34,K34,M34) -> 72372 | I34: 59541 | J34: =I34/F34 -> 0.82270768 | L34: =K34/F34 -> 0 | M34: 12831 | N34: =M34/F34 -> 0.17729232
D35: 46202 | E35: 一 | F35: =SUM(I35,K35,M35) -> 70132 | I35: 57304 | J35: =I35/F35 -> 0.81708778 | L35: =K35/F35 -> 0 | M35: 12828 | N35: =M35/F35 -> 0.18291222
D36: 46203 | E36: 二 | F36: =SUM(I36,K36,M36) -> 0 | J36: =I36/F36 -> #DIV/0! | L36: =K36/F36 -> #DIV/0! | N36: =M36/F36 -> #DIV/0!

Sheet （５-1）品群別人時生產性（熱食義麵）
B1: 月平均人時性 | C1: =AVERAGE(L7,L30,L53,L76,L99,L122) -> 110.84042
B2: 產線配置圖－每週更新 | N2: 資料繳交 | O2: 日期 | AT2: 46174
P3: 二 | U3: 三 | Z3: 四 | AE3: 五 | AJ3: 六 | AO3: 日 | AT3: 一
B4: 品群 | C4: 商品名稱 | E4: 計畫 | H4: 平均人時性 | I4: 實績 | L4: 平均人時性 | M4: 排名 | O4: 日報 | P4: 實際 | T4: 平均人時性 | U4: 實際 | Y4: 平均人時性 | Z4: 實際 | AD4: 平均人時性 | AE4: 實際 | AI4: 平均人時性 | AJ4: 實際 | AN4: 平均人時性 | AO4: 實際 | AS4: 平均人時性 | AT4: 實際 | AX4: 平均人時性
E5: 產線配置圖 | I5: 產線配置圖 | P5: 生產實績 | U5: 生產實績 | Z5: 生產實績 | AE5: 生產實績 | AJ5: 生產實績 | AO5: 生產實績 | AT5: 生產實績
E6: 人數 | F6: 產能／時 | G6: 人時性 | I6: 人數 | J6: 產能／時 | K6: 人時性 | P6: 人數 | Q6: 產能／時 | R6: 人時性 | S6: 排名 | U6: 人數 | V6: 產能／時 | W6: 人時性 | X6: 排名 | Z6: 人數 | AA6: 產能／時 | AB6: 人時性 | AC6: 排名 | AE6: 人數 | AF6: 產能／時 | AG6: 人時性 | AH6: 排名 | AJ6: 人數 | AK6: 產能／時 | AL6: 人時性 | AM6: 排名 | AO6: 人數 | AP6: 產能／時 | AQ6: 人時性 | AR6: 排名 | AT6: 人數 | AU6: 產能／時 | AV6: 人時性 | AW6: 排名
B7: 熱食義麵 | C7: 1 | D7: 義式蕃茄起司義大利麵 | E7: =VLOOKUP(D7,'12產線配置圖'!$A$2:$C$25,2,0) -> 13 | F7: =VLOOKUP(D7,'12產線配置圖'!$A$2:$C$25,3,0) -> 2250 | G7: =F7/E7 -> 173.07692 | H7: =AVERAGE(G7:G21) -> 124.70503 | I7: =AVERAGE(P7,U7,Z7,AE7,AJ7,AO7,AT7) -> 13 | J7: =AVERAGE(Q7,V7,AA7,AF7,AK7,AP7,AU7) -> 1975 | K7: =AVERAGE(AV7) -> 151.92308 | L7: =IFERROR(AVERAGE(K7:K24),"-") -> 112.42018 | M7: =RANK(K7,$K$7:$K$24) -> 1 | R7: =Q7/P7 -> #DIV/0! | S7: =RANK(R7,$R$99:$R$116) -> #DIV/0! | T7: =AVERAGE(R7:R24) -> #DIV/0! | W7: =V7/U7 -> #DIV/0! | X7: =RANK(W7,$W$99:$W$116) -> #DIV/0! | Y7: =AVERAGE(W7:W24) -> #DIV/0! | AB7: =AA7/Z7 -> #DIV/0! | AC7: =RANK(AB7, $AB$99:$AB$116) -> #DIV/0! | AD7: =AVERAGE(AB7:AB24) -> #DIV/0! | AG7: =AF7/AE7 -> #DIV/0! | AH7: =RANK(AG7,$AG$7:$AG$24) -> #DIV/0! | AI7: =AVERAGE(AG7:AG24) -> #DIV/0! | AL7: =AK7/AJ7 -> #DIV/0! | AM7: =RANK(AL7,$AL$7:$AL$24) -> #DIV/0! | AN7: =AVERAGE(AL7:AL24) -> #DIV/0! | AQ7: =AP7/AO7 -> #DIV/0! | AR7: =RANK(AQ7,$AQ$7:$AQ$21) -> #DIV/0! | AS7: =AVERAGE(AQ7:AQ24) -> #DIV/0! | AT7: 13 | AU7: 1975 | AV7: =AU7/AT7 -> 151.92308 | AW7: =RANK(AV7,$AV$7:$AV$21) -> 1 | AX7: =AVERAGE(AV7:AV24) -> 112.42018
C8: 2 | D8: 奶油培根義大利麵 | E8: =VLOOKUP(D8,'12產線配置圖'!$A$2:$C$25,2,0) -> 15 | F8: =VLOOKUP(D8,'12產線配置圖'!$A$2:$C$25,3,0) -> 2250 | G8: =F8/E8 -> 150 | I8: =AVERAGE(P8,U8,Z8,AE8,AJ8,AO8,AT8) -> 15 | J8: =AVERAGE(Q8,V8,AA8,AF8,AK8,AP8,AU8) -> 2110 | K8: =AVERAGE(AV8) -> 140.66667 | M8: =RANK(K8,$K$7:$K$24) -> 4 | R8: =Q8/P8 -> #DIV/0! | S8: =RANK(R8,$R$99:$R$116) -> #DIV/0! | W8: =V8/U8 -> #DIV/0! | X8: =RANK(W8,$W$99:$W$116) -> #DIV/0! | AB8: =AA8/Z8 -> #DIV/0! | AC8: =RANK(AB8, $AB$99:$AB$116) -> #DIV/0! | AG8: =AF8/AE8 -> #DIV/0! | AH8: =RANK(AG8,$AG$7:$AG$24) -> #DIV/0! | AL8: =AK8/AJ8 -> #DIV/0! | AM8: =RANK(AL8,$AL$7:$AL$24) -> #DIV/0! | AQ8: =AP8/AO8 -> #DIV/0! | AR8: =RANK(AQ8,$AQ$7:$AQ$21) -> #DIV/0! | AT8: 15 | AU8: 2110 | AV8: =AU8/AT8 -> 140.66667 | AW8: =RANK(AV8,$AV$7:$AV$21) -> 4
C9: 3 | D9: 白酒清炒鮮蛤義大利麵 | E9: =VLOOKUP(D9,'12產線配置圖'!$A$2:$C$25,2,0) -> 15 | F9: =VLOOKUP(D9,'12產線配置圖'!$A$2:$C$25,3,0) -> 2250 | G9: =F9/E9 -> 150 | I9: =AVERAGE(P9,U9,Z9,AE9,AJ9,AO9,AT9) -> 15 | J9: =AVERAGE(Q9,V9,AA9,AF9,AK9,AP9,AU9) -> 2109 | K9: =AVERAGE(AV9) -> 140.6 | M9: =RANK(K9,$K$7:$K$24) -> 5 | R9: =Q9/P9 -> #DIV/0! | S9: =RANK(R9,$R$99:$R$116) -> #DIV/0! | W9: =V9/U9 -> #DIV/0! | X9: =RANK(W9,$W$99:$W$116) -> #DIV/0! | AB9: =AA9/Z9 -> #DIV/0! | AC9: =RANK(AB9, $AB$99:$AB$116) -> #DIV/0! | AG9: =AF9/AE9 -> #DIV/0! | AH9: =RANK(AG9,$AG$7:$AG$24) -> #DIV/0! | AL9: =AK9/AJ9 -> #DIV/0! | AM9: =RANK(AL9,$AL$7:$AL$24) -> #DIV/0! | AQ9: =AP9/AO9 -> #DIV/0! | AR9: =RANK(AQ9,$AQ$7:$AQ$21) -> #DIV/0! | AT9: 15 | AU9: 2109 | AV9: =AU9/AT9 -> 140.6 | AW9: =RANK(AV9,$AV$7:$AV$21) -> 5
C10: 4 | D10: 焗烤起司雙饗筆尖麵 | E10: =VLOOKUP(D10,'12產線配置圖'!$A$2:$C$25,2,0) -> 16 | F10: =VLOOKUP(D10,'12產線配置圖'!$A$2:$C$25,3,0) -> 1800 | G10: =F10/E10 -> 112.5 | I10: =AVERAGE(P10,U10,Z10,AE10,AJ10,AO10,AT10) -> 15 | J10: =AVERAGE(Q10,V10,AA10,AF10,AK10,AP10,AU10) -> 1504 | K10: =AVERAGE(AV10) -> 100.26667 | M10: =RANK(K10,$K$7:$K$24) -> 8 | R10: =Q10/P10 -> #DIV/0! | S10: =RANK(R10,$R$99:$R$116) -> #DIV/0! | W10: =V10/U10 -> #DIV/0! | X10: =RANK(W10,$W$99:$W$116) -> #DIV/0! | AB10: =AA10/Z10 -> #DIV/0! | AC10: =RANK(AB10, $AB$99:$AB$116) -> #DIV/0! | AG10: =AF10/AE10 -> #DIV/0! | AH10: =RANK(AG10,$AG$7:$AG$24) -> #DIV/0! | AL10: =AK10/AJ10 -> #DIV/0! | AM10: =RANK(AL10,$AL$7:$AL$24) -> #DIV/0! | AQ10: =AP10/AO10 -> #DIV/0! | AR10: =RANK(AQ10,$AQ$7:$AQ$21) -> #DIV/0! | AT10: 15 | AU10: 1504 | AV10: =AU10/AT10 -> 100.26667 | AW10: =RANK(AV10,$AV$7:$AV$21) -> 8
C11: 5 | D11: 青醬蛤蜊義大利麵 | E11: =VLOOKUP(D11,'12產線配置圖'!$A$2:$C$25,2,0) -> 14 | F11: =VLOOKUP(D11,'12產線配置圖'!$A$2:$C$25,3,0) -> 2250 | G11: =F11/E11 -> 160.71429 | I11: =AVERAGE(P11,U11,Z11,AE11,AJ11,AO11,AT11) -> 14 | J11: =AVERAGE(Q11,V11,AA11,AF11,AK11,AP11,AU11) -> 2053 | K11: =AVERAGE(AV11) -> 146.64286 | M11: =RANK(K11,$K$7:$K$24) -> 2 | R11: =Q11/P11 -> #DIV/0! | S11: =RANK(R11,$R$99:$R$116) -> #DIV/0! | W11: =V11/U11 -> #DIV/0! | X11: =RANK(W11,$W$99:$W$116) -> #DIV/0! | AB11: =AA11/Z11 -> #DIV/0! | AC11: =RANK(AB11, $AB$99:$AB$116) -> #DIV/0! | AG11: =AF11/AE11 -> #DIV/0! | AH11: =RANK(AG11,$AG$7:$AG$24) -> #DIV/0! | AL11: =AK11/AJ11 -> #DIV/0! | AM11: =RANK(AL11,$AL$7:$AL$24) -> #DIV/0! | AQ11: =AP11/AO11 -> #DIV/0! | AR11: =RANK(AQ11,$AQ$7:$AQ$21) -> #DIV/0! | AT11: 14 | AU11: 2053 | AV11: =AU11/AT11 -> 146.64286 | AW11: =RANK(AV11,$AV$7:$AV$21) -> 2
C12: 6 | D12: 青花椒麻雞肉拌麵 | E12: =VLOOKUP(D12,'12產線配置圖'!$A$2:$C$25,2,0) -> 15 | F12: =VLOOKUP(D12,'12產線配置圖'!$A$2:$C$25,3,0) -> 1714 | G12: =F12/E12 -> 114.26667 | I12: =AVERAGE(P12,U12,Z12,AE12,AJ12,AO12,AT12) -> 15 | J12: =AVERAGE(Q12,V12,AA12,AF12,AK12,AP12,AU12) -> 1529 | K12: =AVERAGE(AV12) -> 101.93333 | M12: =RANK(K12,$K$7:$K$24) -> 7 | R12: =Q12/P12 -> #DIV/0! | S12: =RANK(R12,$R$99:$R$116) -> #DIV/0! | W12: =V12/U12 -> #DIV/0! | X12: =RANK(W12,$W$99:$W$116) -> #DIV/0! | AB12: =AA12/Z12 -> #DIV/0! | AC12: =RANK(AB12, $AB$99:$AB$116) -> #DIV/0! | AG12: =AF12/AE12 -> #DIV/0! | AH12: =RANK(AG12,$AG$7:$AG$24) -> #DIV/0! | AL12: =AK12/AJ12 -> #DIV/0! | AM12: =RANK(AL12,$AL$7:$AL$24) -> #DIV/0! | AQ12: =AP12/AO12 -> #DIV/0! | AR12: =RANK(AQ12,$AQ$7:$AQ$21) -> #DIV/0! | AT12: 15 | AU12: 1529 | AV12: =AU12/AT12 -> 101.93333 | AW12: =RANK(AV12,$AV$7:$AV$21) -> 7
C13: 7 | D13: 沙茶豬肉炒麵 | E13: =VLOOKUP(D13,'12產線配置圖'!$A$2:$C$25,2,0) -> 17 | F13: =VLOOKUP(D13,'12產線配置圖'!$A$2:$C$25,3,0) -> 1800 | G13: =F13/E13 -> 105.88235 | I13: =AVERAGE(P13,U13,Z13,AE13,AJ13,AO13,AT13) -> 16 | J13: =AVERAGE(Q13,V13,AA13,AF13,AK13,AP13,AU13) -> 1475 | K13: =AVERAGE(AV13) -> 92.1875 | M13: =RANK(K13,$K$7:$K$24) -> 11 | AQ13: =AP13/AO13 -> #DIV/0! | AR13: =RANK(AQ13,$AQ$7:$AQ$21) -> #DIV/0! | AT13: 16 | AU13: 1475 | AV13: =AU13/AT13 -> 92.1875
C14: 8 | D14: 府城鹽水意麵 | E14: =VLOOKUP(D14,'12產線配置圖'!$A$2:$C$25,2,0) -> 17 | F14: =VLOOKUP(D14,'12產線配置圖'!$A$2:$C$25,3,0) -> 1636 | G14: =F14/E14 -> 96.235294 | I14: =AVERAGE(P14,U14,Z14,AE14,AJ14,AO14,AT14) -> 17 | J14: =AVERAGE(Q14,V14,AA14,AF14,AK14,AP14,AU14) -> 1559 | K14: =AVERAGE(AV14) -> 91.705882 | M14: =RANK(K14,$K$7:$K$24) -> 12 | R14: =Q14/P14 -> #DIV/0! | S14: =RANK(R14,$R$99:$R$116) -> #DIV/0! | W14: =V14/U14 -> #DIV/0! | X14: =RANK(W14,$W$99:$W$116) -> #DIV/0! | AB14: =AA14/Z14 -> #DIV/0! | AC14: =RANK(AB14, $AB$99:$AB$116) -> #DIV/0! | AG14: =AF14/AE14 -> #DIV/0! | AH14: =RANK(AG14,$AG$7:$AG$24) -> #DIV/0! | AL14: =AK14/AJ14 -> #DIV/0! | AM14: =RANK(AL14,$AL$7:$AL$24) -> #DIV/0! | AQ14: =AP14/AO14 -> #DIV/0! | AR14: =RANK(AQ14,$AQ$7:$AQ$21) -> #DIV/0! | AT14: 17 | AU14: 1559 | AV14: =AU14/AT14 -> 91.705882 | AW14: =RANK(AV14,$AV$7:$AV$21) -> 12
C15: 9 | D15: 焗烤起司肉醬筆尖麵 | E15: =VLOOKUP(D15,'12產線配置圖'!$A$2:$C$25,2,0) -> 13 | F15: =VLOOKUP(D15,'12產線配置圖'!$A$2:$C$25,3,0) -> 1440 | G15: =F15/E15 -> 110.76923 | I15: =AVERAGE(P15,U15,Z15,AE15,AJ15,AO15,AT15) -> 13 | J15: =AVERAGE(Q15,V15,AA15,AF15,AK15,AP15,AU15) -> 1288 | K15: =AVERAGE(AV15) -> 99.076923 | M15: =RANK(K15,$K$7:$K$24) -> 9 | R15: =Q15/P15 -> #DIV/0! | S15: =RANK(R15,$R$99:$R$116) -> #DIV/0! | W15: =V15/U15 -> #DIV/0! | X15: =RANK(W15,$W$99:$W$116) -> #DIV/0! | AB15: =AA15/Z15 -> #DIV/0! | AC15: =RANK(AB15, $AB$99:$AB$116) -> #DIV/0! | AG15: =AF15/AE15 -> #DIV/0! | AH15: =RANK(AG15,$AG$7:$AG$24) -> #DIV/0! | AL15: =AK15/AJ15 -> #DIV/0! | AM15: =RANK(AL15,$AL$7:$AL$24) -> #DIV/0! | AQ15: =AP15/AO15 -> #DIV/0! | AR15: =RANK(AQ15,$AQ$7:$AQ$21) -> #DIV/0! | AT15: 13 | AU15: 1288 | AV15: =AU15/AT15 -> 99.076923 | AW15: =RANK(AV15,$AV$7:$AV$21) -> 9
C16: 10 | D16: 蒜香奶油蝦蝦義大利麵 | E16: =VLOOKUP(D16,'12產線配置圖'!$A$2:$C$25,2,0) -> 17 | F16: =VLOOKUP(D16,'12產線配置圖'!$A$2:$C$25,3,0) -> 2250 | G16: =F16/E16 -> 132.35294 | I16: =AVERAGE(P16,U16,Z16,AE16,AJ16,AO16,AT16) -> 17 | J16: =AVERAGE(Q16,V16,AA16,AF16,AK16,AP16,AU16) -> 1663 | K16: =AVERAGE(AV16) -> 97.823529 | M16: =RANK(K16,$K$7:$K$24) -> 10 | R16: =Q16/P16 -> #DIV/0! | S16: =RANK(R16,$R$99:$R$116) -> #DIV/0! | W16: =V16/U16 -> #DIV/0! | X16: =RANK(W16,$W$99:$W$116) -> #DIV/0! | AB16: =AA16/Z16 -> #DIV/0! | AC16: =RANK(AB16, $AB$99:$AB$116) -> #DIV/0! | AG16: =AF16/AE16 -> #DIV/0! | AH16: =RANK(AG16,$AG$7:$AG$24) -> #DIV/0! | AL16: =AK16/AJ16 -> #DIV/0! | AM16: =RANK(AL16,$AL$7:$AL$24) -> #DIV/0! | AQ16: =AP16/AO16 -> #DIV/0! | AR16: =RANK(AQ16,$AQ$7:$AQ$21) -> #DIV/0! | AT16: 17 | AU16: 1663 | AV16: =AU16/AT16 -> 97.823529 | AW16: =RANK(AV16,$AV$7:$AV$21) -> 10
C17: 11 | D17: 義式辣味嫩烤雞腿排義大利麵 | E17: =VLOOKUP(D17,'12產線配置圖'!$A$2:$C$25,2,0) -> 15 | F17: =VLOOKUP(D17,'12產線配置圖'!$A$2:$C$25,3,0) -> 2250 | G17: =F17/E17 -> 150 | I17: =AVERAGE(P17,U17,Z17,AE17,AJ17,AO17,AT17) -> 15 | J17: =AVERAGE(Q17,V17,AA17,AF17,AK17,AP17,AU17) -> 1969 | K17: =AVERAGE(AV17) -> 131.26667 | M17: =RANK(K17,$K$7:$K$24) -> 6 | AT17: 15 | AU17: 1969 | AV17: =AU17/AT17 -> 131.26667
C18: 12 | D18: 香煎魚排佐檸檬奶油義大利麵 | E18: =VLOOKUP(D18,'12產線配置圖'!$A$2:$C$25,2,0) -> 15 | F18: =VLOOKUP(D18,'12產線配置圖'!$A$2:$C$25,3,0) -> 2250 | G18: =F18/E18 -> 150 | I18: =AVERAGE(P18,U18,Z18,AE18,AJ18,AO18,AT18) -> 15 | J18: =AVERAGE(Q18,V18,AA18,AF18,AK18,AP18,AU18) -> 2146 | K18: =AVERAGE(AV18) -> 143.06667 | M18: =RANK(K18,$K$7:$K$24) -> 3 | R18: =Q18/P18 -> #DIV/0! | S18: =RANK(R18,$R$99:$R$116) -> #DIV/0! | W18: =V18/U18 -> #DIV/0! | X18: =RANK(W18,$W$99:$W$116) -> #DIV/0! | AB18: =AA18/Z18 -> #DIV/0! | AC18: =RANK(AB18, $AB$99:$AB$116) -> #DIV/0! | AG18: =AF18/AE18 -> #DIV/0! | AH18: =RANK(AG18,$AG$7:$AG$24) -> #DIV/0! | AL18: =AK18/AJ18 -> #DIV/0! | AM18: =RANK(AL18,$AL$7:$AL$24) -> #DIV/0! | AQ18: =AP18/AO18 -> #DIV/0! | AR18: =RANK(AQ18,$AQ$7:$AQ$21) -> #DIV/0! | AT18: 15 | AU18: 2146 | AV18: =AU18/AT18 -> 143.06667 | AW18: =RANK(AV18,$AV$7:$AV$21) -> 3
C19: 13 | D19: 黑松露野菇義大利麵 | E19: =VLOOKUP(D19,'12產線配置圖'!$A$2:$C$25,2,0) -> 18 | F19: =VLOOKUP(D19,'12產線配置圖'!$A$2:$C$25,3,0) -> 1565 | G19: =F19/E19 -> 86.944444 | I19: =AVERAGE(P19,U19,Z19,AE19,AJ19,AO19,AT19) -> 16 | J19: =AVERAGE(Q19,V19,AA19,AF19,AK19,AP19,AU19) -> 1322 | K19: =AVERAGE(AV19) -> 82.625 | M19: =RANK(K19,$K$7:$K$24) -> 14 | R19: =Q19/P19 -> #DIV/0! | S19: =RANK(R19,$R$99:$R$116) -> #DIV/0! | W19: =V19/U19 -> #DIV/0! | X19: =RANK(W19,$W$99:$W$116) -> #DIV/0! | AB19: =AA19/Z19 -> #DIV/0! | AC19: =RANK(AB19, $AB$99:$AB$116) -> #DIV/0! | AG19: =AF19/AE19 -> #DIV/0! | AH19: =RANK(AG19,$AG$7:$AG$24) -> #DIV/0! | AL19: =AK19/AJ19 -> #DIV/0! | AM19: =RANK(AL19,$AL$7:$AL$24) -> #DIV/0! | AQ19: =AP19/AO19 -> #DIV/0! | AR19: =RANK(AQ19,$AQ$7:$AQ$21) -> #DIV/0! | AT19: 16 | AU19: 1322 | AV19: =AU19/AT19 -> 82.625 | AW19: =RANK(AV19,$AV$7:$AV$21) -> 14
C20: 14 | D20: 整條德式香腸義大利麵 | E20: =VLOOKUP(D20,'12產線配置圖'!$A$2:$C$25,2,0) -> 18 | F20: =VLOOKUP(D20,'12產線配置圖'!$A$2:$C$25,3,0) -> 1565 | G20: =F20/E20 -> 86.944444 | I20: =AVERAGE(P20,U20,Z20,AE20,AJ20,AO20,AT20) -> 14 | J20: =AVERAGE(Q20,V20,AA20,AF20,AK20,AP20,AU20) -> 1143 | K20: =AVERAGE(AV20) -> 81.642857 | M20: =RANK(K20,$K$7:$K$24) -> 15 | R20: =Q20/P20 -> #DIV/0! | S20: =RANK(R20,$R$99:$R$116) -> #DIV/0! | W20: =V20/U20 -> #DIV/0! | X20: =RANK(W20,$W$99:$W$116) -> #DIV/0! | AB20: =AA20/Z20 -> #DIV/0! | AC20: =RANK(AB20, $AB$99:$AB$116) -> #DIV/0! | AG20: =AF20/AE20 -> #DIV/0! | AH20: =RANK(AG20,$AG$7:$AG$24) -> #DIV/0! | AL20: =AK20/AJ20 -> #DIV/0! | AM20: =RANK(AL20,$AL$7:$AL$24) -> #DIV/0! | AQ20: =AP20/AO20 -> #DIV/0! | AR20: =RANK(AQ20,$AQ$7:$AQ$21) -> #DIV/0! | AT20: 14 | AU20: 1143 | AV20: =AU20/AT20 -> 81.642857 | AW20: =RANK(AV20,$AV$7:$AV$21) -> 15
C21: 15 | D21: 奶油鮮蝦明太子細扁麵 | E21: =VLOOKUP(D21,'12產線配置圖'!$A$2:$C$25,2,0) -> 18 | F21: =VLOOKUP(D21,'12產線配置圖'!$A$2:$C$25,3,0) -> 1636 | G21: =F21/E21 -> 90.888889 | I21: =AVERAGE(P21,U21,Z21,AE21,AJ21,AO21,AT21) -> 16 | J21: =AVERAGE(Q21,V21,AA21,AF21,AK21,AP21,AU21) -> 1358 | K21: =AVERAGE(AV21) -> 84.875 | M21: =RANK(K21,$K$7:$K$24) -> 13 | R21: =Q21/P21 -> #DIV/0! | S21: =RANK(R21,$R$99:$R$116) -> #DIV/0! | W21: =V21/U21 -> #DIV/0! | X21: =RANK(W21,$W$99:$W$116) -> #DIV/0! | AB21: =AA21/Z21 -> #DIV/0! | AC21: =RANK(AB21, $AB$99:$AB$116) -> #DIV/0! | AG21: =AF21/AE21 -> #DIV/0! | AH21: =RANK(AG21,$AG$7:$AG$24) -> #DIV/0! | AL21: =AK21/AJ21 -> #DIV/0! | AM21: =RANK(AL21,$AL$7:$AL$24) -> #DIV/0! | AQ21: =AP21/AO21 -> #DIV/0! | AR21: =RANK(AQ21,$AQ$7:$AQ$21) -> #DIV/0! | AT21: 16 | AU21: 1358 | AV21: =AU21/AT21 -> 84.875 | AW21: =RANK(AV21,$AV$7:$AV$21) -> 13
C22: 16
C23: 17
C24: 18
B25: 產線配置圖－每週更新 | N25: 資料繳交 | O25: 日期 | P25: 46175 | U25: =P25+1 -> 46176 | Z25: =U25+1 -> 46177 | AE25: =Z25+1 -> 46178 | AJ25: =AE25+1 -> 46179 | AO25: =AJ25+1 -> 46180 | AT25: =AO25+1 -> 46181
P26: 二 | U26: 三 | Z26: 四 | AE26: 五 | AJ26: 六 | AO26: 日 | AT26: 一
B27: 品群 | C27: 商品名稱 | E27: 計畫 | H27: 平均人時性 | I27: 實績 | L27: 平均人時性 | M27: 排名 | O27: 日報 | P27: 實際 | T27: 平均人時性 | U27: 實際 | Y27: 平均人時性 | Z27: 實際 | AD27: 平均人時性 | AE27: 實際 | AI27: 平均人時性 | AJ27: 實際 | AN27: 平均人時性 | AO27: 實際 | AS27: 平均人時性 | AT27: 實際 | AX27: 平均人時性
E28: 產線配置圖 | I28: 產線配置圖 | P28: 生產實績 | U28: 生產實績 | Z28: 生產實績 | AE28: 生產實績 | AJ28: 生產實績 | AO28: 生產實績 | AT28: 生產實績
E29: 人數 | F29: 產能／時 | G29: 人時性 | I29: 人數 | J29: 產能／時 | K29: 人時性 | P29: 人數 | Q29: 產能／時 | R29: 人時性 | S29: 排名 | U29: 人數 | V29: 產能／時 | W29: 人時性 | X29: 排名 | Z29: 人數 | AA29: 產能／時 | AB29: 人時性 | AC29: 排名 | AE29: 人數 | AF29: 產能／時 | AG29: 人時性 | AH29: 排名 | AJ29: 人數 | AK29: 產能／時 | AL29: 人時性 | AM29: 排名 | AO29: 人數 | AP29: 產能／時 | AQ29: 人時性 | AR29: 排名 | AT29: 人數 | AU29: 產能／時 | AV29: 人時性 | AW29: 排名
B30: 熱食義麵 | C30: 1 | D30: 義式蕃茄起司義大利麵 | E30: =VLOOKUP(D30,'12產線配置圖'!$A$2:$C$25,2,0) -> 13 | F30: =VLOOKUP(D30,'12產線配置圖'!$A$2:$C$25,3,0) -> 2250 | G30: =F30/E30 -> 173.07692 | H30: =AVERAGE(G30:G47) -> 124.70503 | I30: =AVERAGE(P30,U30,Z30,AE30,AJ30,AO30,AT30) -> 13 | J30: =AVERAGE(Q30,V30,AA30,AF30,AK30,AP30,AU30) -> 2034 | K30: =AVERAGE(R30,W30,AB30,AG30,AL30,AQ30,AV30) -> 156.46154 | L30: =IFERROR(AVERAGE(K30:K47),"-") -> 111.07682 | M30: =RANK(K30, K$30:$K$47) -> 1 | P30: 13 | Q30: 1830 | R30: =Q30/P30 -> 140.76923 | S30: =RANK(R30,$R$30:$R$47) -> 1 | T30: =AVERAGE(R30:R47) -> 104.06673 | U30: 13 | V30: 1903 | W30: =V30/U30 -> 146.38462 | X30: =RANK(W30, $W$30:$W$47) -> 2 | Y30: =AVERAGE(W30:W47) -> 110.63293 | Z30: 13 | AA30: 2082 | AB30: =AA30/Z30 -> 160.15385 | AC30: =RANK(AB30, $AB$30:$AB$47) -> 1 | AD30: =AVERAGE(AB30:AB47) -> 113.68754 | AE30: 13 | AF30: 2065 | AG30: =AF30/AE30 -> 158.84615 | AH30: =RANK(AG30, $AG$30:$AG$47) -> 1 | AI30: =AVERAGE(AG30:AG47) -> 112.21335 | AJ30: 13 | AK30: 2162 | AL30: =AK30/AJ30 -> 166.30769 | AM30: =RANK(AL30, $AL$30:$AL$47) -> 1 | AN30: =AVERAGE(AL30:AL47) -> 111.99543 | AO30: 13 | AP30: 2079 | AQ30: =AP30/AO30 -> 159.92308 | AR30: =RANK(AQ30,$AQ$30:$AQ$47) -> 1 | AS30: =AVERAGE(AQ30:AQ47) -> 111.16332 | AT30: 13 | AU30: 2117 | AV30: =AU30/AT30 -> 162.84615 | AW30: =RANK(AV30, $AV$30:$AV$47) -> 1 | AX30: =AVERAGE(AV30:AV47) -> 113.77847
C31: 2 | D31: 奶油培根義大利麵 | E31: =VLOOKUP(D31,'12產線配置圖'!$A$2:$C$25,2,0) -> 15 | F31: =VLOOKUP(D31,'12產線配置圖'!$A$2:$C$25,3,0) -> 2250 | G31: =F31/E31 -> 150 | I31: =AVERAGE(P31,U31,Z31,AE31,AJ31,AO31,AT31) -> 15 | J31: =AVERAGE(Q31,V31,AA31,AF31,AK31,AP31,AU31) -> 2016.7143 | K31: =AVERAGE(R31,W31,AB31,AG31,AL31,AQ31,AV31) -> 134.44762 | M31: =RANK(K31, K$30:$K$47) -> 4 | P31: 15 | Q31: 1884 | R31: =Q31/P31 -> 125.6 | S31: =RANK(R31,$R$30:$R$47) -> 3 | U31: 15 | V31: 1951 | W31: =V31/U31 -> 130.06667 | X31: =RANK(W31, $W$30:$W$47) -> 5 | Z31: 15 | AA31: 1971 | AB31: =AA31/Z31 -> 131.4 | AC31: =RANK(AB31, $AB$30:$AB$47) -> 6 | AE31: 15 | AF31: 2069 | AG31: =AF31/AE31 -> 137.93333 | AH31: =RANK(AG31, $AG$30:$AG$47) -> 4 | AJ31: 15 | AK31: 2147 | AL31: =AK31/AJ31 -> 143.13333 | AM31: =RANK(AL31, $AL$30:$AL$47) -> 3 | AO31: 15 | AP31: 2058 | AQ31: =AP31/AO31 -> 137.2 | AR31: =RANK(AQ31,$AQ$30:$AQ$47) -> 5 | AT31: 15 | AU31: 2037 | AV31: =AU31/AT31 -> 135.8 | AW31: =RANK(AV31, $AV$30:$AV$47) -> 4
C32: 3 | D32: 白酒清炒鮮蛤義大利麵 | E32: =VLOOKUP(D32,'12產線配置圖'!$A$2:$C$25,2,0) -> 15 | F32: =VLOOKUP(D32,'12產線配置圖'!$A$2:$C$25,3,0) -> 2250 | G32: =F32/E32 -> 150 | I32: =AVERAGE(P32,U32,Z32,AE32,AJ32,AO32,AT32) -> 15.142857 | J32: =AVERAGE(Q32,V32,AA32,AF32,AK32,AP32,AU32) -> 2019.1429 | K32: =AVERAGE(R32,W32,AB32,AG32,AL32,AQ32,AV32) -> 133.5506 | M32: =RANK(K32, K$30:$K$47) -> 5 | P32: 15 | Q32: 1850 | R32: =Q32/P32 -> 123.33333 | S32: =RANK(R32,$R$30:$R$47) -> 5 | U32: 15 | V32: 2146 | W32: =V32/U32 -> 143.06667 | X32: =RANK(W32, $W$30:$W$47) -> 4 | Z32: 15 | AA32: 2139 | AB32: =AA32/Z32 -> 142.6 | AC32: =RANK(AB32, $AB$30:$AB$47) -> 4 | AE32: 15 | AF32: 2111 | AG32: =AF32/AE32 -> 140.73333 | AH32: =RANK(AG32, $AG$30:$AG$47) -> 3 | AJ32: 15 | AK32: 2102 | AL32: =AK32/AJ32 -> 140.13333 | AM32: =RANK(AL32, $AL$30:$AL$47) -> 4 | AO32: 16 | AP32: 1779 | AQ32: =AP32/AO32 -> 111.1875 | AR32: =RANK(AQ32,$AQ$30:$AQ$47) -> 7 | AT32: 15 | AU32: 2007 | AV32: =AU32/AT32 -> 133.8 | AW32: =RANK(AV32, $AV$30:$AV$47) -> 6
C33: 4 | D33: 焗烤起司雙饗筆尖麵 | E33: =VLOOKUP(D33,'12產線配置圖'!$A$2:$C$25,2,0) -> 16 | F33: =VLOOKUP(D33,'12產線配置圖'!$A$2:$C$25,3,0) -> 1800 | G33: =F33/E33 -> 112.5 | I33: =AVERAGE(P33,U33,Z33,AE33,AJ33,AO33,AT33) -> 16 | J33: =AVERAGE(Q33,V33,AA33,AF33,AK33,AP33,AU33) -> 1566.5714 | K33: =AVERAGE(R33,W33,AB33,AG33,AL33,AQ33,AV33) -> 97.910714 | M33: =RANK(K33, K$30:$K$47) -> 10 | P33: 16 | Q33: 1526 | R33: =Q33/P33 -> 95.375 | S33: =RANK(R33,$R$30:$R$47) -> 8 | U33: 16 | V33: 1511 | W33: =V33/U33 -> 94.4375 | X33: =RANK(W33, $W$30:$W$47) -> 9 | Z33: 16 | AA33: 1509 | AB33: =AA33/Z33 -> 94.3125 | AC33: =RANK(AB33, $AB$30:$AB$47) -> 10 | AE33: 16 | AF33: 1601 | AG33: =AF33/AE33 -> 100.0625 | AH33: =RANK(AG33, $AG$30:$AG$47) -> 10 | AJ33: 16 | AK33: 1554 | AL33: =AK33/AJ33 -> 97.125 | AM33: =RANK(AL33, $AL$30:$AL$47) -> 10 | AO33: 16 | AP33: 1661 | AQ33: =AP33/AO33 -> 103.8125 | AR33: =RANK(AQ33,$AQ$30:$AQ$47) -> 10 | AT33: 16 | AU33: 1604 | AV33: =AU33/AT33 -> 100.25 | AW33: =RANK(AV33, $AV$30:$AV$47) -> 10
C34: 5 | D34: 青醬蛤蜊義大利麵 | E34: =VLOOKUP(D34,'12產線配置圖'!$A$2:$C$25,2,0) -> 14 | F34: =VLOOKUP(D34,'12產線配置圖'!$A$2:$C$25,3,0) -> 2250 | G34: =F34/E34 -> 160.71429 | I34: =AVERAGE(P34,U34,Z34,AE34,AJ34,AO34,AT34) -> 14 | J34: =AVERAGE(Q34,V34,AA34,AF34,AK34,AP34,AU34) -> 2075.8571 | K34: =AVERAGE(R34,W34,AB34,AG34,AL34,AQ34,AV34) -> 148.27551 | M34: =RANK(K34, K$30:$K$47) -> 2 | P34: 14 | Q34: 1952 | R34: =Q34/P34 -> 139.42857 | S34: =RANK(R34,$R$30:$R$47) -> 2 | U34: 14 | V34: 2171 | W34: =V34/U34 -> 155.07143 | X34: =RANK(W34, $W$30:$W$47) -> 1 | Z34: 14 | AA34: 2024 | AB34: =AA34/Z34 -> 144.57143 | AC34: =RANK(AB34, $AB$30:$AB$47) -> 3 | AE34: 14 | AF34: 2203 | AG34: =AF34/AE34 -> 157.35714 | AH34: =RANK(AG34, $AG$30:$AG$47) -> 2 | AJ34: 14 | AK34: 2079 | AL34: =AK34/AJ34 -> 148.5 | AM34: =RANK(AL34, $AL$30:$AL$47) -> 2 | AO34: 14 | AP34: 2097 | AQ34: =AP34/AO34 -> 149.78571 | AR34: =RANK(AQ34,$AQ$30:$AQ$47) -> 2 | AT34: 14 | AU34: 2005 | AV34: =AU34/AT34 -> 143.21429 | AW34: =RANK(AV34, $AV$30:$AV$47) -> 3
C35: 6 | D35: 青花椒麻雞肉拌麵 | E35: =VLOOKUP(D35,'12產線配置圖'!$A$2:$C$25,2,0) -> 15 | F35: =VLOOKUP(D35,'12產線配置圖'!$A$2:$C$25,3,0) -> 1714 | G35: =F35/E35 -> 114.26667 | I35: =AVERAGE(P35,U35,Z35,AE35,AJ35,AO35,AT35) -> 14.714286 | J35: =AVERAGE(Q35,V35,AA35,AF35,AK35,AP35,AU35) -> 1518.1429 | K35: =AVERAGE(R35,W35,AB35,AG35,AL35,AQ35,AV35) -> 103.20068 | M35: =RANK(K35, K$30:$K$47) -> 8 | P35: 15 | Q35: 1414 | R35: =Q35/P35 -> 94.266667 | S35: =RANK(R35,$R$30:$R$47) -> 9 | U35: 15 | V35: 1516 | W35: =V35/U35 -> 101.06667 | X35: =RANK(W35, $W$30:$W$47) -> 8 | Z35: 14 | AA35: 1515 | AB35: =AA35/Z35 -> 108.21429 | AC35: =RANK(AB35, $AB$30:$AB$47) -> 8 | AE35: 15 | AF35: 1631 | AG35: =AF35/AE35 -> 108.73333 | AH35: =RANK(AG35, $AG$30:$AG$47) -> 8 | AJ35: 14 | AK35: 1412 | AL35: =AK35/AJ35 -> 100.85714 | AM35: =RANK(AL35, $AL$30:$AL$47) -> 9 | AO35: 15 | AP35: 1601 | AQ35: =AP35/AO35 -> 106.73333 | AR35: =RANK(AQ35,$AQ$30:$AQ$47) -> 8 | AT35: 15 | AU35: 1538 | AV35: =AU35/AT35 -> 102.53333 | AW35: =RANK(AV35, $AV$30:$AV$47) -> 9
C36: 7 | D36: 沙茶豬肉炒麵 | E36: =VLOOKUP(D36,'12產線配置圖'!$A$2:$C$25,2,0) -> 17 | F36: =VLOOKUP(D36,'12產線配置圖'!$A$2:$C$25,3,0) -> 1800 | G36: =F36/E36 -> 105.88235 | I36: =AVERAGE(P36,U36,Z36,AE36,AJ36,AO36,AT36) -> 16.714286 | J36: =AVERAGE(Q36,V36,AA36,AF36,AK36,AP36,AU36) -> 1528 | K36: =AVERAGE(R36,W36,AB36,AG36,AL36,AQ36,AV36) -> 91.439601 | M36: =RANK(K36, K$30:$K$47) -> 11 | P36: 17 | Q36: 1549 | R36: =Q36/P36 -> 91.117647 | S36: =RANK(R36,$R$30:$R$47) -> 10 | U36: 16 | V36: 1474 | W36: =V36/U36 -> 92.125 | X36: =RANK(W36, $W$30:$W$47) -> 11 | Z36: 17 | AA36: 1575 | AB36: =AA36/Z36 -> 92.647059 | AC36: =RANK(AB36, $AB$30:$AB$47) -> 11 | AE36: 17 | AF36: 1528 | AG36: =AF36/AE36 -> 89.882353 | AH36: =RANK(AG36, $AG$30:$AG$47) -> 11 | AJ36: 17 | AK36: 1487 | AL36: =AK36/AJ36 -> 87.470588 | AM36: =RANK(AL36, $AL$30:$AL$47) -> 11 | AO36: 16 | AP36: 1491 | AQ36: =AP36/AO36 -> 93.1875 | AR36: =RANK(AQ36,$AQ$30:$AQ$47) -> 11 | AT36: 17 | AU36: 1592 | AV36: =AU36/AT36 -> 93.647059 | AW36: =RANK(AV36, $AV$30:$AV$47) -> 11
C37: 8 | D37: 府城鹽水意麵 | E37: =VLOOKUP(D37,'12產線配置圖'!$A$2:$C$25,2,0) -> 17 | F37: =VLOOKUP(D37,'12產線配置圖'!$A$2:$C$25,3,0) -> 1636 | G37: =F37/E37 -> 96.235294 | I37: =AVERAGE(P37,U37,Z37,AE37,AJ37,AO37,AT37) -> 16.857143 | J37: =AVERAGE(Q37,V37,AA37,AF37,AK37,AP37,AU37) -> 1413.8571 | K37: =AVERAGE(R37,W37,AB37,AG37,AL37,AQ37,AV37) -> 83.879202 | M37: =RANK(K37, K$30:$K$47) -> 12 | P37: 17 | Q37: 1347 | R37: =Q37/P37 -> 79.235294 | S37: =RANK(R37,$R$30:$R$47) -> 14 | U37: 17 | V37: 1486 | W37: =V37/U37 -> 87.411765 | X37: =RANK(W37, $W$30:$W$47) -> 12 | Z37: 17 | AA37: 1441 | AB37: =AA37/Z37 -> 84.764706 | AC37: =RANK(AB37, $AB$30:$AB$47) -> 13 | AE37: 17 | AF37: 1388 | AG37: =AF37/AE37 -> 81.647059 | AH37: =RANK(AG37, $AG$30:$AG$47) -> 13 | AJ37: 16 | AK37: 1354 | AL37: =AK37/AJ37 -> 84.625 | AM37: =RANK(AL37, $AL$30:$AL$47) -> 12 | AO37: 17 | AP37: 1398 | AQ37: =AP37/AO37 -> 82.235294 | AR37: =RANK(AQ37,$AQ$30:$AQ$47) -> 13 | AT37: 17 | AU37: 1483 | AV37: =AU37/AT37 -> 87.235294 | AW37: =RANK(AV37, $AV$30:$AV$47) -> 12
C38: 9 | D38: 焗烤起司肉醬筆尖麵 | E38: =VLOOKUP(D38,'12產線配置圖'!$A$2:$C$25,2,0) -> 13 | F38: =VLOOKUP(D38,'12產線配置圖'!$A$2:$C$25,3,0) -> 1440 | G38: =F38/E38 -> 110.76923 | I38: =AVERAGE(P38,U38,Z38,AE38,AJ38,AO38,AT38) -> 13 | J38: =AVERAGE(Q38,V38,AA38,AF38,AK38,AP38,AU38) -> 1316.8571 | K38: =AVERAGE(R38,W38,AB38,AG38,AL38,AQ38,AV38) -> 101.2967 | M38: =RANK(K38, K$30:$K$47) -> 9 | P38: 13 | Q38: 1176 | R38: =Q38/P38 -> 90.461538 | S38: =RANK(R38,$R$30:$R$47) -> 11 | U38: 13 | V38: 1224 | W38: =V38/U38 -> 94.153846 | X38: =RANK(W38, $W$30:$W$47) -> 10 | Z38: 13 | AA38: 1364 | AB38: =AA38/Z38 -> 104.92308 | AC38: =RANK(AB38, $AB$30:$AB$47) -> 9 | AE38: 13 | AF38: 1363 | AG38: =AF38/AE38 -> 104.84615 | AH38: =RANK(AG38, $AG$30:$AG$47) -> 9 | AJ38: 13 | AK38: 1357 | AL38: =AK38/AJ38 -> 104.38462 | AM38: =RANK(AL38, $AL$30:$AL$47) -> 8 | AO38: 13 | AP38: 1362 | AQ38: =AP38/AO38 -> 104.76923 | AR38: =RANK(AQ38,$AQ$30:$AQ$47) -> 9 | AT38: 13 | AU38: 1372 | AV38: =AU38/AT38 -> 105.53846 | AW38: =RANK(AV38, $AV$30:$AV$47) -> 8
C39: 10 | D39: 蒜香奶油蝦蝦義大利麵 | E39: =VLOOKUP(D39,'12產線配置圖'!$A$2:$C$25,2,0) -> 17 | F39: =VLOOKUP(D39,'12產線配置圖'!$A$2:$C$25,3,0) -> 2250 | G39: =F39/E39 -> 132.35294 | I39: =AVERAGE(P39,U39,Z39,AE39,AJ39,AO39,AT39) -> 17 | J39: =AVERAGE(Q39,V39,AA39,AF39,AK39,AP39,AU39) -> 1948.8571 | K39: =AVERAGE(R39,W39,AB39,AG39,AL39,AQ39,AV39) -> 114.63866 | M39: =RANK(K39, K$30:$K$47) -> 7 | P39: 17 | Q39: 1810 | R39: =Q39/P39 -> 106.47059 | S39: =RANK(R39,$R$30:$R$47) -> 7 | U39: 17 | V39: 1839 | W39: =V39/U39 -> 108.17647 | X39: =RANK(W39, $W$30:$W$47) -> 7 | Z39: 17 | AA39: 1878 | AB39: =AA39/Z39 -> 110.47059 | AC39: =RANK(AB39, $AB$30:$AB$47) -> 7 | AE39: 17 | AF39: 1856 | AG39: =AF39/AE39 -> 109.17647 | AH39: =RANK(AG39, $AG$30:$AG$47) -> 7 | AJ39: 17 | AK39: 2052 | AL39: =AK39/AJ39 -> 120.70588 | AM39: =RANK(AL39, $AL$30:$AL$47) -> 7 | AO39: 17 | AP39: 2072 | AQ39: =AP39/AO39 -> 121.88235 | AR39: =RANK(AQ39,$AQ$30:$AQ$47) -> 6 | AT39: 17 | AU39: 2135 | AV39: =AU39/AT39 -> 125.58824 | AW39: =RANK(AV39, $AV$30:$AV$47) -> 7
C40: 11 | D40: 義式辣味嫩烤雞腿排義大利麵 | E40: =VLOOKUP(D40,'12產線配置圖'!$A$2:$C$25,2,0) -> 15 | F40: =VLOOKUP(D40,'12產線配置圖'!$A$2:$C$25,3,0) -> 2250 | G40: =F40/E40 -> 150 | I40: =AVERAGE(P40,U40,Z40,AE40,AJ40,AO40,AT40) -> 15 | J40: =AVERAGE(Q40,V40,AA40,AF40,AK40,AP40,AU40) -> 1982.5714 | K40: =AVERAGE(R40,W40,AB40,AG40,AL40,AQ40,AV40) -> 132.17143 | M40: =RANK(K40, K$30:$K$47) -> 6 | P40: 15 | Q40: 1867 | R40: =Q40/P40 -> 124.46667 | S40: =RANK(R40,$R$30:$R$47) -> 4 | U40: 15 | V40: 1929 | W40: =V40/U40 -> 128.6 | X40: =RANK(W40, $W$30:$W$47) -> 6 | Z40: 15 | AA40: 2037 | AB40: =AA40/Z40 -> 135.8 | AC40: =RANK(AB40, $AB$30:$AB$47) -> 5 | AE40: 15 | AF40: 1862 | AG40: =AF40/AE40 -> 124.13333 | AH40: =RANK(AG40, $AG$30:$AG$47) -> 6 | AJ40: 15 | AK40: 2093 | AL40: =AK40/AJ40 -> 139.53333 | AM40: =RANK(AL40, $AL$30:$AL$47) -> 5 | AO40: 15 | AP40: 2062 | AQ40: =AP40/AO40 -> 137.46667 | AR40: =RANK(AQ40,$AQ$30:$AQ$47) -> 4 | AT40: 15 | AU40: 2028 | AV40: =AU40/AT40 -> 135.2 | AW40: =RANK(AV40, $AV$30:$AV$47) -> 5
...

Sheet （５-3）品群別人時生產性(微波小吃)
B1: 月平均人時性 | C1: =AVERAGE(L7,L27,L47,L67,L87,L107) -> 116.98271
B2: 產線配置圖－每週更新 | N2: 資料繳交 | O2: 日期 | AT2: 46146
P3: 二 | U3: 三 | Z3: 四 | AE3: 五 | AJ3: 六 | AO3: 日 | AT3: 一
B4: 品群 | C4: 商品名稱 | E4: 計畫 | H4: 平均人時性 | I4: 實績 | L4: 平均人時性 | M4: 排名 | O4: 日報 | P4: 實際 | T4: 平均人時性 | U4: 實際 | Y4: 平均人時性 | Z4: 實際 | AD4: 平均人時性 | AE4: 實際 | AI4: 平均人時性 | AJ4: 實際 | AN4: 平均人時性 | AO4: 實際 | AS4: 平均人時性 | AT4: 實際 | AX4: 平均人時性
E5: 產線配置圖 | I5: 產線配置圖 | P5: 生產實績 | U5: 生產實績 | Z5: 生產實績 | AE5: 生產實績 | AJ5: 生產實績 | AO5: 生產實績 | AT5: 生產實績
E6: 人數 | F6: 產能／時 | G6: 人時性 | I6: 人數 | J6: 產能／時 | K6: 人時性 | P6: 人數 | Q6: 產能／時 | R6: 人時性 | S6: 排名 | U6: 人數 | V6: 產能／時 | W6: 人時性 | X6: 排名 | Z6: 人數 | AA6: 產能／時 | AB6: 人時性 | AC6: 排名 | AE6: 人數 | AF6: 產能／時 | AG6: 人時性 | AH6: 排名 | AJ6: 人數 | AK6: 產能／時 | AL6: 人時性 | AM6: 排名 | AO6: 人數 | AP6: 產能／時 | AQ6: 人時性 | AR6: 排名 | AT6: 人數 | AU6: 產能／時 | AV6: 人時性 | AW6: 排名
B7: 微波小吃 | C7: 1 | D7: 小滷青蔬 | E7: =VLOOKUP(D7,'12產線配置圖'!$A$26:$C$33,2,0) -> 15 | F7: =VLOOKUP(D7,'12產線配置圖'!$A$26:$C$33,3,0) -> 1565 | G7: =F7/E7 -> 104.33333 | H7: =AVERAGE(G7:G21) -> 125.67424 | I7: =AVERAGE(P7,U7,Z7,AE7,AJ7,AO7,AT7) -> 14.666667 | J7: =AVERAGE(Q7,V7,AA7,AF7,AK7,AP7,AU7) -> 1412.3333 | K7: =AVERAGE(AV7) -> 93.2 | L7: =IFERROR(AVERAGE(K7:K21),"-") -> 113.86717 | M7: =RANK(K7,$K$7:$K$21) -> 3 | R7: =Q7/P7 -> #DIV/0! | S7: =RANK(R7, R$7:R$21) -> #DIV/0! | T7: =AVERAGE(R7:R21) -> #DIV/0! | W7: =V7/U7 -> #DIV/0! | X7: =RANK(W7,$W$7:$W$21) -> #DIV/0! | Y7: =AVERAGE(W7:W21) -> #DIV/0! | AB7: =AA7/Z7 -> #DIV/0! | AC7: =RANK(AB7,$AB$7:$AB$21) -> #DIV/0! | AD7: =AVERAGE(AB7:AB21) -> #DIV/0! | AE7: 14 | AF7: 1281 | AG7: =AF7/AE7 -> 91.5 | AH7: =RANK(AG7,$AG$7:$AG$21) -> 2 | AI7: =AVERAGE(AG7:AG21) -> 107.84091 | AJ7: 15 | AK7: 1558 | AL7: =AK7/AJ7 -> 103.86667 | AM7: =RANK(AL7,$AL$7:$AL$21) -> 2 | AN7: =AVERAGE(AL7:AL21) -> 107.76667 | AQ7: =AP7/AO7 -> #DIV/0! | AR7: =RANK(AQ7,$AQ$7:$AQ$21) -> #DIV/0! | AS7: =AVERAGE(AQ7:AQ21) -> #DIV/0! | AT7: 15 | AU7: 1398 | AV7: =AU7/AT7 -> 93.2 | AW7: =RANK(AV7,$AV$7:$AV$21) -> 3 | AX7: =AVERAGE(AV7:AV21) -> 113.86717
C8: 2 | D8: 起司馬鈴薯 | E8: =VLOOKUP(D8,'12產線配置圖'!$A$26:$C$33,2,0) -> 12 | F8: =VLOOKUP(D8,'12產線配置圖'!$A$26:$C$33,3,0) -> 1565 | G8: =F8/E8 -> 130.41667 | I8: =AVERAGE(P8,U8,Z8,AE8,AJ8,AO8,AT8) -> 11.666667 | J8: =AVERAGE(Q8,V8,AA8,AF8,AK8,AP8,AU8) -> 1392.3333 | K8: =AVERAGE(AV8) -> 122.58333 | M8: =RANK(K8,$K$7:$K$21) -> 2 | R8: =Q8/P8 -> #DIV/0! | S8: =RANK(R8, R$7:R$21) -> #DIV/0! | W8: =V8/U8 -> #DIV/0! | X8: =RANK(W8,$W$7:$W$21) -> #DIV/0! | AB8: =AA8/Z8 -> #DIV/0! | AC8: =RANK(AB8,$AB$7:$AB$21) -> #DIV/0! | AE8: 11 | AF8: 1366 | AG8: =AF8/AE8 -> 124.18182 | AH8: =RANK(AG8,$AG$7:$AG$21) -> 1 | AJ8: 12 | AK8: 1340 | AL8: =AK8/AJ8 -> 111.66667 | AM8: =RANK(AL8,$AL$7:$AL$21) -> 1 | AQ8: =AP8/AO8 -> #DIV/0! | AR8: =RANK(AQ8,$AQ$7:$AQ$21) -> #DIV/0! | AT8: 12 | AU8: 1471 | AV8: =AU8/AT8 -> 122.58333 | AW8: =RANK(AV8,$AV$7:$AV$21) -> 2
C9: 3 | D9: 韓式炒冬粉 | E9: =VLOOKUP(D9,'12產線配置圖'!$A$26:$C$33,2,0) -> 11 | F9: =VLOOKUP(D9,'12產線配置圖'!$A$26:$C$33,3,0) -> 1565 | G9: =F9/E9 -> 142.27273 | I9: =AVERAGE(P9,U9,Z9,AE9,AJ9,AO9,AT9) -> 11 | J9: =AVERAGE(Q9,V9,AA9,AF9,AK9,AP9,AU9) -> 1384 | K9: =AVERAGE(AV9) -> 125.81818 | M9: =RANK(K9,$K$7:$K$21) -> 1 | R9: =Q9/P9 -> #DIV/0! | S9: =RANK(R9, R$7:R$21) -> #DIV/0! | W9: =V9/U9 -> #DIV/0! | X9: =RANK(W9,$W$7:$W$21) -> #DIV/0! | AB9: =AA9/Z9 -> #DIV/0! | AC9: =RANK(AB9,$AB$7:$AB$21) -> #DIV/0! | AT9: 11 | AU9: 1384 | AV9: =AU9/AT9 -> 125.81818 | AW9: =RANK(AV9,$AV$7:$AV$21) -> 1
C10: 4
C11: 5
C12: 6
C13: 7
C14: 8
C15: 9
C16: 10
C17: 11
C18: 12
C19: 13
C20: 14
C21: 15
B22: 產線配置圖－每週更新 | N22: 資料繳交 | O22: 日期 | P22: 46175 | U22: =P22+1 -> 46176 | Z22: =U22+1 -> 46177 | AE22: =Z22+1 -> 46178 | AJ22: =AE22+1 -> 46179 | AO22: =AJ22+1 -> 46180 | AT22: =AO22+1 -> 46181
P23: 二 | U23: 三 | Z23: 四 | AE23: 五 | AJ23: 六 | AO23: 日 | AT23: 一
B24: 品群 | C24: 商品名稱 | E24: 計畫 | H24: 平均人時性 | I24: 實績 | L24: 平均人時性 | M24: 排名 | O24: 日報 | P24: 實際 | T24: 平均人時性 | U24: 實際 | Y24: 平均人時性 | Z24: 實際 | AD24: 平均人時性 | AE24: 實際 | AI24: 平均人時性 | AJ24: 實際 | AN24: 平均人時性 | AO24: 實際 | AS24: 平均人時性 | AT24: 實際 | AX24: 平均人時性
E25: 產線配置圖 | I25: 產線配置圖 | P25: 生產實績 | U25: 生產實績 | Z25: 生產實績 | AE25: 生產實績 | AJ25: 生產實績 | AO25: 生產實績 | AT25: 生產實績
E26: 人數 | F26: 產能／時 | G26: 人時性 | I26: 人數 | J26: 產能／時 | K26: 人時性 | P26: 人數 | Q26: 產能／時 | R26: 人時性 | S26: 排名 | U26: 人數 | V26: 產能／時 | W26: 人時性 | X26: 排名 | Z26: 人數 | AA26: 產能／時 | AB26: 人時性 | AC26: 排名 | AE26: 人數 | AF26: 產能／時 | AG26: 人時性 | AH26: 排名 | AJ26: 人數 | AK26: 產能／時 | AL26: 人時性 | AM26: 排名 | AO26: 人數 | AP26: 產能／時 | AQ26: 人時性 | AR26: 排名 | AT26: 人數 | AU26: 產能／時 | AV26: 人時性 | AW26: 排名
B27: 微波小吃 | C27: 1 | D27: 小滷青蔬 | E27: =VLOOKUP(D27,'12產線配置圖'!$A$26:$C$33,2,0) -> 15 | F27: =VLOOKUP(D27,'12產線配置圖'!$A$26:$C$33,3,0) -> 1565 | G27: =F27/E27 -> 104.33333 | H27: =AVERAGE(G27:G41) -> 125.67424 | I27: =AVERAGE(P27,U27,Z27,AE27,AJ27,AO27,AT27) -> 15.571429 | J27: =AVERAGE(Q27,V27,AA27,AF27,AK27,AP27,AU27) -> 1430.8571 | K27: =AVERAGE(R27,W27,AB27,AG27,AL27,AQ27,AV27) -> 92.029552 | L27: =IFERROR(AVERAGE(K27:K41),"-") -> 110.90212 | M27: =RANK(K27, K$27:$K$41) -> 3 | P27: 15 | Q27: 1314 | R27: =Q27/P27 -> 87.6 | S27: =RANK(R27, $R$27:$R$41) -> 3 | T27: =AVERAGE(R27:R41) -> 111.82374 | U27: 16 | V27: 1220 | W27: =V27/U27 -> 76.25 | X27: =RANK(W27, $W$27:$W$41) -> 3 | Y27: =AVERAGE(W27:W41) -> 102.28333 | Z27: 15 | AA27: 1501 | AB27: =AA27/Z27 -> 100.06667 | AC27: =RANK(AB27,$AB$27:$AB$41) -> 3 | AD27: =AVERAGE(AB27:AB41) -> 115.85556 | AE27: 16 | AF27: 1552 | AG27: =AF27/AE27 -> 97 | AH27: =RANK(AG27, $AG$27:$AG$41) -> 3 | AI27: =AVERAGE(AG27:AG41) -> 112.28632 | AJ27: 15 | AK27: 1528 | AL27: =AK27/AJ27 -> 101.86667 | AM27: =RANK(AL27, $AL$27:$AL$41) -> 3 | AN27: =AVERAGE(AL27:AL41) -> 113.59697 | AO27: 15 | AP27: 1374 | AQ27: =AP27/AO27 -> 91.6 | AR27: =RANK(AQ27, $AQ$27:$AQ$41) -> 3 | AS27: =AVERAGE(AQ27:AQ41) -> 112.82626 | AT27: 17 | AU27: 1527 | AV27: =AU27/AT27 -> 89.823529 | AW27: =RANK(AV27, $AV$27:$AV$41) -> 3 | AX27: =AVERAGE(AV27:AV41) -> 107.64264
C28: 2 | D28: 起司馬鈴薯 | E28: =VLOOKUP(D28,'12產線配置圖'!$A$26:$C$33,2,0) -> 12 | F28: =VLOOKUP(D28,'12產線配置圖'!$A$26:$C$33,3,0) -> 1565 | G28: =F28/E28 -> 130.41667 | I28: =AVERAGE(P28,U28,Z28,AE28,AJ28,AO28,AT28) -> 12.571429 | J28: =AVERAGE(Q28,V28,AA28,AF28,AK28,AP28,AU28) -> 1534.4286 | K28: =AVERAGE(R28,W28,AB28,AG28,AL28,AQ28,AV28) -> 122.20264 | M28: =RANK(K28, K$27:$K$41) -> 1 | P28: 12 | Q28: 1481 | R28: =Q28/P28 -> 123.41667 | S28: =RANK(R28, $R$27:$R$41) -> 2 | U28: 13 | V28: 1651 | W28: =V28/U28 -> 127 | X28: =RANK(W28, $W$27:$W$41) -> 1 | Z28: 12 | AA28: 1422 | AB28: =AA28/Z28 -> 118.5 | AC28: =RANK(AB28,$AB$27:$AB$41) -> 2 | AE28: 13 | AF28: 1608 | AG28: =AF28/AE28 -> 123.69231 | AH28: =RANK(AG28, $AG$27:$AG$41) -> 1 | AJ28: 12 | AK28: 1474 | AL28: =AK28/AJ28 -> 122.83333 | AM28: =RANK(AL28, $AL$27:$AL$41) -> 1 | AO28: 12 | AP28: 1528 | AQ28: =AP28/AO28 -> 127.33333 | AR28: =RANK(AQ28, $AQ$27:$AQ$41) -> 1 | AT28: 14 | AU28: 1577 | AV28: =AU28/AT28 -> 112.64286 | AW28: =RANK(AV28, $AV$27:$AV$41) -> 2
C29: 3 | D29: 韓式炒冬粉 | E29: =VLOOKUP(D29,'12產線配置圖'!$A$26:$C$33,2,0) -> 11 | F29: =VLOOKUP(D29,'12產線配置圖'!$A$26:$C$33,3,0) -> 1565 | G29: =F29/E29 -> 142.27273 | I29: =AVERAGE(P29,U29,Z29,AE29,AJ29,AO29,AT29) -> 12 | J29: =AVERAGE(Q29,V29,AA29,AF29,AK29,AP29,AU29) -> 1413.4286 | K29: =AVERAGE(R29,W29,AB29,AG29,AL29,AQ29,AV29) -> 118.47416 | M29: =RANK(K29, K$27:$K$41) -> 2 | P29: 11 | Q29: 1369 | R29: =Q29/P29 -> 124.45455 | S29: =RANK(R29, $R$27:$R$41) -> 1 | U29: 15 | V29: 1554 | W29: =V29/U29 -> 103.6 | X29: =RANK(W29, $W$27:$W$41) -> 2 | Z29: 11 | AA29: 1419 | AB29: =AA29/Z29 -> 129 | AC29: =RANK(AB29,$AB$27:$AB$41) -> 1 | AE29: 12 | AF29: 1394 | AG29: =AF29/AE29 -> 116.16667 | AH29: =RANK(AG29, $AG$27:$AG$41) -> 2 | AJ29: 11 | AK29: 1277 | AL29: =AK29/AJ29 -> 116.09091 | AM29: =RANK(AL29, $AL$27:$AL$41) -> 2 | AO29: 11 | AP29: 1315 | AQ29: =AP29/AO29 -> 119.54545 | AR29: =RANK(AQ29, $AQ$27:$AQ$41) -> 2 | AT29: 13 | AU29: 1566 | AV29: =AU29/AT29 -> 120.46154 | AW29: =RANK(AV29, $AV$27:$AV$41) -> 1
C30: 4
C31: 5
C32: 6
C33: 7
C34: 8
C35: 9
C36: 10
C37: 11
C38: 12
C39: 13
C40: 14
...

Sheet 生產管理報表 6-1(週)
A1: 生產管理報表
A3: （６）人時生產性前幾名品項
A5: 品群 | B5: 1 | C5: 2 | D5: 3
B6: 熱食義麵 | C6: 季節調理麵 | D6: 微波小吃
A7: 品群 | C7: 排名 | D7: 商品名 | G7: 人數 | H7: 產能 | I7: 人時生產性 | J7: 前月比 | K7: 主要原因&對策
A8: 1 | B8: 熱食義麵 | C8: 1 | D8: 義式蕃茄起司義大利麵 | G8: 13 | H8: 1936.4286 | I8: 148.95604 | J8: 0.963 | K8: 煮麵組由調理支援，流程不熟悉
C9: 2 | D9: 青醬蛤蜊義大利麵 | G9: 14 | H9: 1959 | I9: 139.92857 | J9: 0.903 | K9: 煮麵組由調理支援，流程不熟悉
C10: 3 | D10: 白酒清炒鮮蛤義大利麵 | G10: 15 | H10: 1977.7143 | I10: 131.84762 | J10: 0.984 | K10: 煮麵組由調理支援，流程不熟悉
C11: 4 | D11: 奶油培根義大利麵 | G11: 15 | H11: 1936.8571 | I11: 129.12381 | J11: 0.953 | K11: 煮麵組由調理支援，流程不熟悉
C12: 5 | D12: 香煎魚排佐檸檬奶油義大利麵 | G12: 15 | H12: 1904.5714 | I12: 126.97143 | J12: 0.941 | K12: 煮麵組由調理支援，流程不熟悉
C13: ▼1 | D13: 整條德式香腸義大利麵 | G13: 16.428571 | H13: 1160.1429 | I13: 70.061149 | J13: 0.981 | K13: 人員減少測試
C14: ▼2 | D14: 義式蛋蛋青醬鮪魚冷義大利麵 | G14: 15.857143 | H14: 1299.5714 | I14: 81.689516 | K14: 新品
C15: ▼3 | D15: 焦糖拿鐵烤雞細扁麵 | G15: 17.428571 | H15: 1451.7143 | I15: 83.196604 | K15: 新品
C16: ▼4 | D16: 府城鹽水意麵 | G16: 16.857143 | H16: 1421 | I16: 84.28869 | J16: 1.019
C17: ▼5 | D17: 奶油鮮蝦明太子細扁麵 | G17: 17.571429 | H17: 1499.4286 | I17: 85.247899 | J17: 1.002
