Workbook

Sheet 生產管理報表(週) 
A1: 長家廠生產管理報表
A3: 月別 | B3: 7 | C3: 週別 | D3: W3 | E3: 工廠 | F3: 長家廠
A4: （１）收支狀況 | E4: ※單位：千元 | G4: （２）ＫＰＩ達成進度
A5: 項目 | B5: 當週 | C5: 前週 | D5: 差異 | E5: 累計 | G5: 項目 | H5: KPI | I5: 當週 | J5: 前週 | K5: 累計 | L5: ※補充
A6: 業績金額 | B6: ='（１）收支狀況'!G18/1000 -> 20961.818 | C6: 21123.7 | D6: =B6-C6 -> -161.88225 | E6: ='（１）收支狀況'!H5/1000 -> 60007.833 | G6: 人時性(個/月均) | H6: ='（２）ＫＰＩ達成進度'!C1 -> 122.3 | I6: ='（２）ＫＰＩ達成進度'!G18 -> 113.12857 | J6: 113.45714 | K6: ='（２）ＫＰＩ達成進度'!H5 -> 112.25 | L6: 個／MH
A7: 訂單數量 | B7: ='（１）收支狀況'!J18 -> 456696 | C7: 455465 | D7: =B7-C7 -> 1231 | E7: ='（１）收支狀況'!K5 -> 1287266 | G7: 人時達成率(%/月均) | H7: 0.8 | I7: =I6/H6 -> 0.92500876 | J7: =J6/H6 -> 0.92769536 | K7: =K6/H6 -> 0.91782502 | L7: 達成率
A8: 材料費 | B8: ='（１）收支狀況'!M18/1000 -> 13232.255 | C8: 13334.331 | D8: =B8-C8 -> -102.07582 | E8: ='（１）收支狀況'!N5/1000 -> 37884.645 | G8: 半成品-報廢(%) | H8: 0.0025 | I8: =('日別報廢率總表 '!N17)/('日別報廢率總表 '!M17) -> 0.0028275812 | J8: 0.0021085069 | K8: ='日別報廢率總表 '!C36/'日別報廢率總表 '!B36 -> 0.002475859 | L8: 報廢率
A9: 材料費率 | B9: =B8/B6 -> 0.63125514 | C9: =C8/C6 -> 0.63124978 | D9: =B9-C9 -> 5.3581883e-06 | E9: =E8/E6 -> 0.63132833 | G9: 半成品-超用(%) | H9: 0.0025 | I9: =('日別報廢率總表 '!O17)/('日別報廢率總表 '!M17) -> 0.0027065689 | J9: 0.0036409609 | K9: ='日別報廢率總表 '!E36/'日別報廢率總表 '!B36 -> 0.0032437447 | L9: 超用率
A10: 勞務成本 | D10: =B10-C10 -> 0 | G10: 固定產線-導入率(%) | H10: 1 | I10: ='（２）ＫＰＩ達成進度'!S18 -> 0.2857 | J10: 0.2857 | K10: ='（２）ＫＰＩ達成進度'!T5 -> 0.2857 | L10: 導入率
A11: 勞務費率 | D11: =B11-C11 -> 0 | G11: 教育訓練-實施率(%) | H11: 1 | I11: ='（２）ＫＰＩ達成進度'!V18 -> 0.89285714 | J11: 0.8 | K11: ='（２）ＫＰＩ達成進度'!W5 -> 0.82241379 | L11: 實施率
A13: （３）業績構成比 | G13: （４）訂單數量構成比
B14: 當週 | C14: 比例 | D14: 前週 | E14: 差異 | H14: 當週 | I14: 比例 | J14: 前週 | K14: 差異
A15: 熱食義麵(122,123,124,126) | B15: =SUM('（３）業績構成比'!I20:I26)/1000 -> 18823.321 | C15: =B15/B6 -> 0.8979813 | D15: 0.89711264 | E15: =C15-D15 -> 0.00086865859 | G15: 熱食義麵(122,123,124,126) | H15: =SUM('（４）訂單數量構成比'!I20:I26) -> 379277 | I15: =IFERROR(H15/$B$7,"") -> 0.83048023 | J15: 0.82721175 | K15: =IFERROR(I15-J15,"") -> 0.0032684813
A16: 季節調理麵(111,112) | C16: =IFERROR(B16/$B$6,"") -> 0 | D16: 0 | E16: =IFERROR(C16-D16,"") -> 0 | G16: 季節調理麵(111,112) | I16: =IFERROR(H16/$B$7,"") -> 0 | J16: 0 | K16: =IFERROR(I16-J16,"") -> 0
A17: 微波小吃(153,154,155) | B17: =SUM('（３）業績構成比'!M20:M26)/1000 -> 2138.4974 | C17: =B17/B6 -> 0.1020187 | D17: 0.10288736 | E17: =C17-D17 -> -0.00086865859 | G17: 微波小吃(153,154,155) | H17: =SUM('（４）訂單數量構成比'!M20:M26) -> 77419 | I17: =IFERROR(H17/$B$7,"") -> 0.16951977 | J17: 0.17278825 | K17: =IFERROR(I17-J17,"") -> -0.0032684813
C18: =SUM(C15:C17) -> 1 | D18: =SUM(D15:D17) -> 1 | I18: =SUM(I15:I17) -> 1 | J18: =SUM(J15:J17) -> 1
A20: （５）品群別人時生產性
A21: 品群 | B21: 當週 | C21: 前週 | D21: 差異 | E21: 累計
A22: 熱食義麵(122,123,124,126) | B22: 111.5 | C22: 110.7 | D22: =B22-C22 -> 0.8 | E22: ='（５-1）品群別人時生產性（熱食義麵）'!C1 -> 110.49749
A23: 季節調理麵(111,112) | D23: =B23-C23 -> 0
A24: 微波小吃(153,154,155) | B24: 128.6 | C24: 127.6 | D24: =B24-C24 -> 1 | E24: ='（５-3）品群別人時生產性(微波小吃)'!C1 -> 127.68458

Sheet （１）收支狀況
B2: （１）收支狀況
B3: 資料繳交日 | C3: 月份 | D3: 日期 | F3: 營業額(元) | I3: 訂單數量(個) | L3: 材料費(元) | O3: 材料費率（材料費／營業額） | R3: 勞務成本（全廠人事成本） | U3: 勞務費率（勞務成本／營業額）
F4: 日 | G4: 週累積 | H4: 月累積 | I4: 日 | J4: 週累積 | K4: 月累積 | L4: 日 | M4: 週累積 | N4: 月累積 | O4: 日 | P4: 週累積 | Q4: 月累積 | R4: 日 | S4: 週累積 | T4: 月累積 | U4: 日 | V4: 週累積 | W4: 月累積
B5: 46211 | C5: 七 | D5: 46204 | E5: 三 | F5: 3008576 | G5: =SUM(F5:F10) -> 17922315 | H5: =SUM(F5:F35) -> 60007833 | I5: 64740 | J5: =SUM(I5:I10) -> 375105 | K5: =SUM(I5:I35) -> 1287266 | L5: 1900002.9 | M5: =SUM(L5:L10) -> 11318058 | N5: =SUM(L5:L35) -> 37884645 | O5: =L5/F5 -> 0.63152896 | P5: =M5/G5 -> 0.6315065 | Q5: =N5/H5 -> 0.63132833 | S5: =SUM(R5) -> 0 | T5: =SUM(R5:R36) -> 0 | U5: =R5/F5 -> 0 | V5: =S5/M5 -> 0 | W5: =T5/N5 -> 0
D6: 46205 | E6: 四 | F6: 2877019.6 | I6: 51631 | L6: 1816222.3 | O6: =L6/F6 -> 0.63128605 | S6: =SUM(R6:R12) -> 0 | U6: =R6/F6 -> 0 | V6: =S6/M6 -> #DIV/0!
D7: 46206 | E7: 五 | F7: 2420688.2 | I7: 52190 | L7: 1529033.6 | O7: =L7/F7 -> 0.63165242 | U7: =R7/F7 -> 0
D8: 46207 | E8: 六 | F8: 2867965.9 | I8: 61707 | L8: 1811818.5 | O8: =L8/F8 -> 0.6317434 | U8: =R8/F8 -> 0
D9: 46208 | E9: 日 | F9: 3409988.5 | I9: 73271 | L9: 2152992.7 | O9: =L9/F9 -> 0.6313783 | U9: =R9/F9 -> 0
D10: 46209 | E10: 一 | F10: 3338076.8 | I10: 71566 | L10: 2107988.4 | O10: =L10/F10 -> 0.63149787 | U10: =R10/F10 -> 0
B11: 46218 | D11: 46210 | E11: 二 | F11: 2944276.7 | G11: =SUM(F11:F17) -> 21123700 | I11: 63648 | J11: =SUM(I11:I17) -> 455465 | L11: 1858894.3 | M11: =SUM(L11:L17) -> 13334331 | O11: =L11/F11 -> 0.63135857 | P11: =M11/G11 -> 0.63124978 | U11: =R11/F11 -> 0
D12: 46211 | E12: 三 | F12: 3038869.3 | I12: 65338 | L12: 1917487.7 | O12: =L12/F12 -> 0.63098721 | U12: =R12/F12 -> 0
D13: 46212 | E13: 四 | F13: 3350396.6 | I13: 71986 | L13: 2115749.9 | O13: =L13/F13 -> 0.63149236 | S13: =SUM(R13:R19) -> 0 | U13: =R13/F13 -> 0 | V13: =S13/M13 -> #DIV/0!
D14: 46213 | E14: 五 | F14: 2275501.1 | I14: 49267 | L14: 1436565.7 | O14: =L14/F14 -> 0.63131839 | U14: =R14/F14 -> 0
D15: 46214 | E15: 六 | F15: 2731630 | I15: 58998 | L15: 1723926.9 | O15: =L15/F15 -> 0.63109825 | U15: =R15/F15 -> 0
D16: 46215 | E16: 日 | F16: 3362568.3 | I16: 72479 | L16: 2122618.1 | O16: =L16/F16 -> 0.63124905 | U16: =R16/F16 -> 0
D17: 46216 | E17: 一 | F17: 3420458.2 | I17: 73749 | L17: 2159088.7 | O17: =L17/F17 -> 0.63122791 | U17: =R17/F17 -> 0
B18: 46225 | D18: 46217 | E18: 二 | F18: 3528841.4 | G18: =SUM(F18:F24) -> 20961818 | I18: 75526 | J18: =SUM(I18:I24) -> 456696 | L18: 2227860.1 | M18: =SUM(L18:L24) -> 13232255 | O18: =L18/F18 -> 0.63132905 | P18: =M18/G18 -> 0.63125514 | U18: =R18/F18 -> 0
D19: 46218 | E19: 三 | F19: 3157061.3 | I19: 67666 | L19: 1992648.6 | O19: =L19/F19 -> 0.63117198 | U19: =R19/F19 -> 0
D20: 46219 | E20: 四 | F20: 2922058.2 | I20: 62695 | L20: 1844696.7 | O20: =L20/F20 -> 0.63130045 | S20: =SUM(R20:R26) -> 0 | U20: =R20/F20 -> 0 | V20: =S20/M20 -> #DIV/0!
D21: 46220 | E21: 五 | F21: 2282826.5 | I21: 49290 | L21: 1441100.7 | O21: =L21/F21 -> 0.63127912 | U21: =R21/F21 -> 0
D22: 46221 | E22: 六 | F22: 2534267.7 | I22: 54825 | L22: 1599588.7 | O22: =L22/F22 -> 0.63118377 | U22: =R22/F22 -> 0
D23: 46222 | E23: 日 | F23: 3200427.4 | I23: 74386 | L23: 2020269.3 | O23: =L23/F23 -> 0.63124983 | U23: =R23/F23 -> 0
D24: 46223 | E24: 一 | F24: 3336335.4 | I24: 72308 | L24: 2106091.3 | O24: =L24/F24 -> 0.63125887 | U24: =R24/F24 -> 0
B25: 46232 | D25: 46224 | E25: 二 | G25: =SUM(F25:F31) -> 0 | J25: =SUM(I25:I31) -> 0 | M25: =SUM(L25:L31) -> 0 | O25: =L25/F25 -> #DIV/0! | P25: =M25/G25 -> #DIV/0! | U25: =R25/F25 -> #DIV/0!
D26: 46225 | E26: 三 | O26: =L26/F26 -> #DIV/0! | U26: =R26/F26 -> #DIV/0!
D27: 46226 | E27: 四 | O27: =L27/F27 -> #DIV/0! | S27: =SUM(R27:R33) -> 0 | U27: =R27/F27 -> #DIV/0! | V27: =S27/M27 -> #DIV/0!
D28: 46227 | E28: 五 | O28: =L28/F28 -> #DIV/0! | U28: =R28/F28 -> #DIV/0!
D29: 46228 | E29: 六 | O29: =L29/F29 -> #DIV/0! | U29: =R29/F29 -> #DIV/0!
D30: 46229 | E30: 日 | O30: =L30/F30 -> #DIV/0! | U30: =R30/F30 -> #DIV/0!
D31: 46230 | E31: 一 | O31: =L31/F31 -> #DIV/0! | U31: =R31/F31 -> #DIV/0!
D32: 46231 | E32: 二 | O32: =L32/F32 -> #DIV/0! | U32: =R32/F32 -> #DIV/0!
D33: 46232 | E33: 三 | O33: =L33/F33 -> #DIV/0! | U33: =R33/F33 -> #DIV/0!
D34: 46233 | E34: 四 | U34: =R34/F38 -> 0
D35: 46234 | E35: 五 | U35: =R35/F35 -> #DIV/0!
D38: 46203 | E38: 二 | F38: 3411506.4 | I38: 73435 | L38: 2158249.1 | O38: =L38/F38 -> 0.63263813

Sheet （２）ＫＰＩ達成進度
C1: 122.3
B2: （２）ＫＰＩ達成進度
B3: 資料繳交日 | C3: 月份 | D3: 日期 | F3: 人時生產性(個/人) | I3: 人時生產性達成率(%) | L3: 半成品報廢(%) | O3: 半成品超用(%) | R3: 固定產線-導入率(固定產線數/總產線數) | U3: 教育訓練-實施率(進度/計畫)
F4: 日 | G4: 週平均 | H4: 月平均 | I4: 日 | J4: 週平均 | K4: 月平均 | L4: 日 | M4: 週平均 | N4: 月平均 | O4: 日 | P4: 週平均 | Q4: 月平均 | R4: 日 | S4: 週平均 | T4: 月平均 | U4: 日 | V4: 週平均 | W4: 月平均
B5: 46211 | C5: 七 | D5: 46204 | E5: 三 | F5: 108.4 | G5: =(SUM(F5:F10)+F38)/7 -> 110.8 | H5: =AVERAGE(F5:F35) -> 112.25 | I5: =F5/$C$1 -> 0.88634505 | J5: =AVERAGE(F5:F10,F38)/$C$1 -> 0.90596893 | K5: =AVERAGE(I5:I38) -> 0.91803917 | L5: ='日別報廢率總表 '!C4/'日別報廢率總表 '!B4 -> 0.002326038 | M5: ='日別報廢率總表 '!N4/'日別報廢率總表 '!M4 -> 0.0022480417 | N5: ='日別報廢率總表 '!C36/'日別報廢率總表 '!B36 -> 0.002475859 | O5: ='日別報廢率總表 '!E4/'日別報廢率總表 '!B4 -> 0.0044729662 | P5: ='日別報廢率總表 '!O4/'日別報廢率總表 '!M4 -> 0.0038929937 | Q5: ='日別報廢率總表 '!E36/'日別報廢率總表 '!B36 -> 0.0032437447 | R5: 0.2857 | S5: =AVERAGE(R5:R10) -> 0.2857 | T5: =AVERAGE(R5:R35) -> 0.2857 | U5: 0.95 | V5: =AVERAGE(U5:U10) -> 0.8 | W5: =AVERAGE(U5:U33) -> 0.82241379
D6: 46205 | E6: 四 | F6: 108.7 | I6: =F6/$C$1 -> 0.88879804 | L6: ='日別報廢率總表 '!C5/'日別報廢率總表 '!B5 -> 0.0021041336 | O6: ='日別報廢率總表 '!E5/'日別報廢率總表 '!B5 -> 0.0038430133 | R6: 0.2857 | U6: 0.75
D7: 46206 | E7: 五 | F7: 110.3 | I7: =F7/$C$1 -> 0.90188062 | L7: ='日別報廢率總表 '!C6/'日別報廢率總表 '!B6 -> 0.0011981081 | O7: ='日別報廢率總表 '!E6/'日別報廢率總表 '!B6 -> 0.0022266929 | R7: 0.2857 | U7: 0.75
D8: 46207 | E8: 六 | F8: 110.6 | I8: =F8/$C$1 -> 0.90433361 | L8: ='日別報廢率總表 '!C7/'日別報廢率總表 '!B7 -> 0.0036737766 | O8: ='日別報廢率總表 '!E7/'日別報廢率總表 '!B7 -> 0.0059518248 | R8: 0.2857 | U8: 0.75
D9: 46208 | E9: 日 | F9: 112.7 | I9: =F9/$C$1 -> 0.9215045 | L9: ='日別報廢率總表 '!C8/'日別報廢率總表 '!B8 -> 0.0034429345 | O9: ='日別報廢率總表 '!E8/'日別報廢率總表 '!B8 -> 0.0053104474 | R9: 0.2857 | U9: 0.8
D10: 46209 | E10: 一 | F10: 112.1 | I10: =F10/$C$1 -> 0.91659853 | L10: ='日別報廢率總表 '!C9/'日別報廢率總表 '!B9 -> 0.0006175821 | O10: ='日別報廢率總表 '!E9/'日別報廢率總表 '!B9 -> 0.0014048366 | R10: 0.2857 | U10: 0.8
B11: 46218 | D11: 46210 | E11: 二 | F11: 113.9 | G11: =AVERAGE(F11:F17) -> 113.45714 | I11: =F11/$C$1 -> 0.93131643 | J11: =AVERAGE(F11:F17)/$C$1 -> 0.92769536 | L11: ='日別報廢率總表 '!C10/'日別報廢率總表 '!B10 -> 0.0034873564 | M11: ='日別報廢率總表 '!N10/'日別報廢率總表 '!M10 -> 0.002320123 | O11: ='日別報廢率總表 '!E10/'日別報廢率總表 '!B10 -> 0.0043177596 | P11: ='日別報廢率總表 '!O10/'日別報廢率總表 '!M10 -> 0.0032259512 | R11: 0.2857 | S11: =AVERAGE(R11:R17) -> 0.2857 | U11: 0.8 | V11: =AVERAGE(U11:U17) -> 0.8
D12: 46211 | E12: 三 | F12: 113.4 | I12: =F12/$C$1 -> 0.92722813 | L12: ='日別報廢率總表 '!C11/'日別報廢率總表 '!B11 -> 0.00043968656 | O12: ='日別報廢率總表 '!E11/'日別報廢率總表 '!B11 -> 0.00014416777 | R12: 0.2857 | U12: 0.8
D13: 46212 | E13: 四 | F13: 112.2 | I13: =F13/$C$1 -> 0.91741619 | L13: ='日別報廢率總表 '!C12/'日別報廢率總表 '!B12 -> 0.00046947755 | O13: ='日別報廢率總表 '!E12/'日別報廢率總表 '!B12 -> 0.00076458584 | R13: 0.2857 | U13: 0.8
D14: 46213 | E14: 五 | F14: 110.1 | I14: =F14/$C$1 -> 0.9002453 | L14: ='日別報廢率總表 '!C13/'日別報廢率總表 '!B13 -> 0.0025282845 | O14: ='日別報廢率總表 '!E13/'日別報廢率總表 '!B13 -> 0.004058868 | R14: 0.2857 | U14: 0.8
D15: 46214 | E15: 六 | F15: 114.9 | I15: =F15/$C$1 -> 0.93949305 | L15: ='日別報廢率總表 '!C14/'日別報廢率總表 '!B14 -> 0.0033121078 | O15: ='日別報廢率總表 '!E14/'日別報廢率總表 '!B14 -> 0.0054262865 | R15: 0.2857 | U15: 0.8
D16: 46215 | E16: 日 | F16: 113.9 | I16: =F16/$C$1 -> 0.93131643 | L16: ='日別報廢率總表 '!C15/'日別報廢率總表 '!B15 -> 0.0058671193 | O16: ='日別報廢率總表 '!E15/'日別報廢率總表 '!B15 -> 0.0084265973 | R16: 0.2857 | U16: 0.8
D17: 46216 | E17: 一 | F17: 115.8 | I17: =F17/$C$1 -> 0.946852 | L17: ='日別報廢率總表 '!C16/'日別報廢率總表 '!B16 -> 0.00038111794 | O17: ='日別報廢率總表 '!E16/'日別報廢率總表 '!B16 -> 1.1109623e-05 | R17: 0.2857 | U17: 0.8
B18: 46225 | D18: 46217 | E18: 二 | F18: 108.8 | G18: =AVERAGE(F17:F23) -> 113.12857 | I18: =F18/$C$1 -> 0.8896157 | J18: =AVERAGE(F18:F24)/$C$1 -> 0.92045322 | L18: ='日別報廢率總表 '!C17/'日別報廢率總表 '!B17 -> 0.0027490928 | M18: ='日別報廢率總表 '!N17/'日別報廢率總表 '!M17 -> 0.0028275812 | O18: ='日別報廢率總表 '!E17/'日別報廢率總表 '!B17 -> 0.0033046489 | P18: ='日別報廢率總表 '!O17/'日別報廢率總表 '!M17 -> 0.0027065689 | R18: 0.2857 | S18: =AVERAGE(R18:R24) -> 0.2857 | U18: 0.85 | V18: =AVERAGE(U18:U24) -> 0.89285714
D19: 46218 | E19: 三 | F19: 114.6 | I19: =F19/$C$1 -> 0.93704007 | L19: ='日別報廢率總表 '!C18/'日別報廢率總表 '!B18 -> 0.0011240144 | O19: ='日別報廢率總表 '!E18/'日別報廢率總表 '!B18 -> 0.00094866358 | R19: 0.2857 | U19: 0.9
D20: 46219 | E20: 四 | F20: 112.3 | I20: =F20/$C$1 -> 0.91823385 | L20: ='日別報廢率總表 '!C19/'日別報廢率總表 '!B19 -> 0.0020578931 | O20: ='日別報廢率總表 '!E19/'日別報廢率總表 '!B19 -> 0.0018978758 | R20: 0.2857 | U20: 0.9
D21: 46220 | E21: 五 | F21: 112.8 | I21: =F21/$C$1 -> 0.92232216 | L21: ='日別報廢率總表 '!C20/'日別報廢率總表 '!B20 -> 0.0036016492 | O21: ='日別報廢率總表 '!E20/'日別報廢率總表 '!B20 -> 0.0035216037 | R21: 0.2857 | U21: 0.9
D22: 46221 | E22: 六 | F22: 113.3 | I22: =F22/$C$1 -> 0.92641047 | L22: ='日別報廢率總表 '!C21/'日別報廢率總表 '!B21 -> 0.0061825743 | O22: ='日別報廢率總表 '!E21/'日別報廢率總表 '!B21 -> 0.0059989016 | R22: 0.2857 | U22: 0.9
D23: 46222 | E23: 日 | F23: 114.3 | I23: =F23/$C$1 -> 0.93458708 | L23: ='日別報廢率總表 '!C22/'日別報廢率總表 '!B22 -> 0.0014365814 | O23: ='日別報廢率總表 '!E22/'日別報廢率總表 '!B22 -> 0.00029703245 | R23: 0.2857 | U23: 0.9
D24: 46223 | E24: 一 | F24: 111.9 | I24: =F24/$C$1 -> 0.91496321 | L24: ='日別報廢率總表 '!C23/'日別報廢率總表 '!B23 -> 0.0034529955 | O24: ='日別報廢率總表 '!E23/'日別報廢率總表 '!B23 -> 0.0036985687 | R24: 0.2857 | U24: 0.9
B25: 46232 | D25: 46224 | E25: 二 | G25: =AVERAGE(F24:F30) -> 111.9 | J25: =AVERAGE(F25:F31)/$C$1 -> #DIV/0! | L25: ='日別報廢率總表 '!C24/'日別報廢率總表 '!B24 -> #DIV/0! | M25: ='日別報廢率總表 '!N24/'日別報廢率總表 '!M24 -> #DIV/0! | O25: ='日別報廢率總表 '!E24/'日別報廢率總表 '!B24 -> #DIV/0! | P25: ='日別報廢率總表 '!O24/'日別報廢率總表 '!M24 -> #DIV/0! | R25: 0.2857 | S25: =AVERAGE(R25:R31) -> 0.2857 | U25: 0.8 | V25: =AVERAGE(U25:U31) -> 0.8
D26: 46225 | E26: 三 | L26: ='日別報廢率總表 '!C25/'日別報廢率總表 '!B25 -> #DIV/0! | O26: ='日別報廢率總表 '!E25/'日別報廢率總表 '!B25 -> #DIV/0! | R26: 0.2857 | U26: 0.8
D27: 46226 | E27: 四 | L27: ='日別報廢率總表 '!C26/'日別報廢率總表 '!B26 -> #DIV/0! | O27: ='日別報廢率總表 '!E26/'日別報廢率總表 '!B26 -> #DIV/0! | R27: 0.2857 | U27: 0.8
D28: 46227 | E28: 五 | L28: ='日別報廢率總表 '!C27/'日別報廢率總表 '!B27 -> #DIV/0! | O28: ='日別報廢率總表 '!E27/'日別報廢率總表 '!B27 -> #DIV/0! | R28: 0.2857 | U28: 0.8
D29: 46228 | E29: 六 | L29: ='日別報廢率總表 '!C28/'日別報廢率總表 '!B28 -> #DIV/0! | O29: ='日別報廢率總表 '!E28/'日別報廢率總表 '!B28 -> #DIV/0! | R29: 0.2857 | U29: 0.8
D30: 46229 | E30: 日 | L30: ='日別報廢率總表 '!C29/'日別報廢率總表 '!B29 -> #DIV/0! | O30: ='日別報廢率總表 '!E29/'日別報廢率總表 '!B29 -> #DIV/0! | R30: 0.2857 | U30: 0.8
D31: 46230 | E31: 一 | G31: =AVERAGE(F30:F36) -> #DIV/0! | L31: ='日別報廢率總表 '!C30/'日別報廢率總表 '!B30 -> #DIV/0! | O31: ='日別報廢率總表 '!E30/'日別報廢率總表 '!B30 -> #DIV/0! | R31: 0.2857 | U31: 0.8
D32: 46231 | E32: 二 | L32: ='日別報廢率總表 '!C31/'日別報廢率總表 '!B31 -> #DIV/0! | O32: ='日別報廢率總表 '!E31/'日別報廢率總表 '!B31 -> #DIV/0! | R32: 0.2857 | U32: 0.8
D33: 46232 | E33: 三 | L33: ='日別報廢率總表 '!C32/'日別報廢率總表 '!B32 -> #DIV/0! | O33: ='日別報廢率總表 '!E32/'日別報廢率總表 '!B32 -> #DIV/0! | R33: 0.2857 | U33: 0.8
D34: 46233 | E34: 四 | L34: ='日別報廢率總表 '!C33/'日別報廢率總表 '!B33 -> #DIV/0! | O34: ='日別報廢率總表 '!E33/'日別報廢率總表 '!B33 -> #DIV/0! | R34: 0.2857 | U34: 0.8
D35: 46234 | E35: 五 | L35: ='日別報廢率總表 '!C34/'日別報廢率總表 '!B34 -> #DIV/0! | O35: ='日別報廢率總表 '!E34/'日別報廢率總表 '!B34 -> #DIV/0! | R35: 0.2857 | U35: 0.8
D38: 46203 | E38: 二 | F38: 112.8 | I38: =F38/$C$1 -> 0.92232216 | L38: 0.00141 | O38: ='日別報廢率總表 '!E33/'日別報廢率總表 '!B33 -> #DIV/0! | R38: 0.2857 | U38: 0.8
H45: 0.91568164
H46: 0.90622537
H47: 0.88967691
H48: 0.86997636
...

Sheet （３）業績構成比
B2: （3）業績構成比
B3: 資料繳交日 | C3: 月份 | D3: 日期 | F3: 營業額 | I3: 品類業績
I4: 熱食義麵 | K4: 季節調理麵 | M4: 微波小吃
F5: 日 | G5: 週累積 | H5: 月累積 | I5: 一配 | K5: 一配 | M5: 一配
I6: 業績(元) | J6: 比例(%) | K6: 業績(元) | L6: 比例(%) | M6: 業績(元) | N6: 比例(%)
B7: 46211 | C7: 七 | D7: 46204 | E7: 三 | F7: =I7+M7 -> 3008576 | G7: =SUM(F7:F12,F40) -> 21333821 | H7: =SUM(F7:F37) -> 60007833 | I7: 2704766 | J7: =I7/F7 -> 0.89901867 | L7: =K7/F7 -> 0 | M7: 303810 | N7: =M7/F7 -> 0.10098133
D8: 46205 | E8: 四 | F8: =I8+M8 -> 2877019.6 | I8: 2594796.9 | J8: =I8/F8 -> 0.90190448 | L8: =K8/F8 -> 0 | M8: 282222.72 | N8: =M8/F8 -> 0.098095516
D9: 46206 | E9: 五 | F9: =I9+M9 -> 2420688.2 | I9: 2177752.4 | J9: =I9/F9 -> 0.89964181 | L9: =K9/F9 -> 0 | M9: 242935.88 | N9: =M9/F9 -> 0.10035819
D10: 46207 | E10: 六 | F10: =I10+M10 -> 2867965.9 | I10: 2581183.9 | J10: =I10/F10 -> 0.90000508 | L10: =K10/F10 -> 0 | M10: 286782.03 | N10: =M10/F10 -> 0.099994923
D11: 46208 | E11: 日 | F11: =I11+M11 -> 3409988.5 | I11: 3085249.1 | J11: =I11/F11 -> 0.90476818 | L11: =K11/F11 -> 0 | M11: 324739.39 | N11: =M11/F11 -> 0.095231815
D12: 46209 | E12: 一 | F12: =I12+M12 -> 3338076.8 | I12: 3004362.5 | J12: =I12/F12 -> 0.90002798 | L12: =K12/F12 -> 0 | M12: 333714.29 | N12: =M12/F12 -> 0.099972023
B13: 46218 | D13: 46210 | E13: 二 | F13: =I13+M13 -> 2944276.7 | G13: =SUM(F13:F19) -> 21123700 | I13: 2624629.7 | J13: =I13/F13 -> 0.89143445 | L13: =K13/F13 -> 0 | M13: 319647.01 | N13: =M13/F13 -> 0.10856555
D14: 46211 | E14: 三 | F14: =I14+M14 -> 3038869.3 | I14: 2732746.1 | J14: =I14/F14 -> 0.8992641 | L14: =K14/F14 -> 0 | M14: 306123.22 | N14: =M14/F14 -> 0.1007359
D15: 46212 | E15: 四 | F15: =I15+M15 -> 3350396.6 | I15: 3018909.5 | J15: =I15/F15 -> 0.90106035 | L15: =K15/F15 -> 0 | M15: 331487.06 | N15: =M15/F15 -> 0.098939648
D16: 46213 | E16: 五 | F16: =I16+M16 -> 2275501.1 | I16: 2037955 | J16: =I16/F16 -> 0.89560714 | L16: =K16/F16 -> 0 | M16: 237546.06 | N16: =M16/F16 -> 0.10439286
D17: 46214 | E17: 六 | F17: =I17+M17 -> 2731630 | I17: 2452817 | J17: =I17/F17 -> 0.89793164 | L17: =K17/F17 -> 0 | M17: 278812.98 | N17: =M17/F17 -> 0.10206836
D18: 46215 | E18: 日 | F18: =I18+M18 -> 3362568.3 | I18: 3022699.7 | J18: =I18/F18 -> 0.89892587 | L18: =K18/F18 -> 0 | M18: 339868.68 | N18: =M18/F18 -> 0.10107413
D19: 46216 | E19: 一 | F19: =I19+M19 -> 3420458.2 | I19: 3060581.5 | J19: =I19/F19 -> 0.894787 | L19: =K19/F19 -> 0 | M19: 359876.67 | N19: =M19/F19 -> 0.105213
B20: 46225 | D20: 46217 | E20: 二 | F20: =I20+M20 -> 3528841.4 | G20: =SUM(F20:F26) -> 20961818 | I20: 3196165.9 | J20: =I20/F20 -> 0.90572671 | L20: =K20/F20 -> 0 | M20: 332675.48 | N20: =M20/F20 -> 0.094273288
D21: 46218 | E21: 三 | F21: =I21+M21 -> 3157061.3 | I21: 2852950.4 | J21: =I21/F21 -> 0.90367279 | L21: =K21/F21 -> 0 | M21: 304110.91 | N21: =M21/F21 -> 0.09632721
D22: 46219 | E22: 四 | F22: =I22+M22 -> 2922058.2 | I22: 2637733.1 | J22: =I22/F22 -> 0.90269699 | L22: =K22/F22 -> 0 | M22: 284325.07 | N22: =M22/F22 -> 0.097303014
D23: 46220 | E23: 五 | F23: =I23+M23 -> 2282826.5 | I23: 2042641.5 | J23: =I23/F23 -> 0.89478616 | L23: =K23/F23 -> 0 | M23: 240184.93 | N23: =M23/F23 -> 0.10521384
D24: 46221 | E24: 六 | F24: =I24+M24 -> 2534267.7 | I24: 2271670.1 | J24: =I24/F24 -> 0.89638124 | L24: =K24/F24 -> 0 | M24: 262597.67 | N24: =M24/F24 -> 0.10361876
D25: 46222 | E25: 日 | F25: =I25+M25 -> 3200427.4 | I25: 2863270 | J25: =I25/F25 -> 0.89465237 | L25: =K25/F25 -> 0 | M25: 337157.43 | N25: =M25/F25 -> 0.10534763
D26: 46223 | E26: 一 | F26: =I26+M26 -> 3336335.4 | I26: 2958889.5 | J26: =I26/F26 -> 0.88686812 | L26: =K26/F26 -> 0 | M26: 377445.89 | N26: =M26/F26 -> 0.11313188
B27: 46232 | D27: 46224 | E27: 二 | F27: =I27+M27 -> 0 | G27: =SUM(F27:F33) -> 0 | J27: =I27/F27 -> #DIV/0! | L27: =K27/F27 -> #DIV/0! | N27: =M27/F27 -> #DIV/0!
D28: 46225 | E28: 三 | F28: =I28+M28 -> 0 | J28: =I28/F28 -> #DIV/0! | L28: =K28/F28 -> #DIV/0! | N28: =M28/F28 -> #DIV/0!
D29: 46226 | E29: 四 | F29: =I29+M29 -> 0 | J29: =I29/F29 -> #DIV/0! | L29: =K29/F29 -> #DIV/0! | N29: =M29/F29 -> #DIV/0!
D30: 46227 | E30: 五 | F30: =I30+M30 -> 0 | J30: =I30/F30 -> #DIV/0! | L30: =K30/F30 -> #DIV/0! | N30: =M30/F30 -> #DIV/0!
D31: 46228 | E31: 六 | F31: =I31+M31 -> 0 | J31: =I31/F31 -> #DIV/0! | L31: =K31/F31 -> #DIV/0! | N31: =M31/F31 -> #DIV/0!
D32: 46229 | E32: 日 | F32: =I32+M32 -> 0 | J32: =I32/F32 -> #DIV/0! | L32: =K32/F32 -> #DIV/0! | N32: =M32/F32 -> #DIV/0!
D33: 46230 | E33: 一 | F33: =I33+M33 -> 0 | J33: =I33/F33 -> #DIV/0! | L33: =K33/F33 -> #DIV/0! | N33: =M33/F33 -> #DIV/0!
D34: 46231 | E34: 二 | F34: =I34+M34 -> 0 | J34: =I34/F34 -> #DIV/0! | L34: =K34/F34 -> #DIV/0! | N34: =M34/F34 -> #DIV/0!
D35: 46232 | E35: 三 | F35: =I35+M35 -> 0 | J35: =I35/F35 -> #DIV/0! | L35: =K35/F35 -> #DIV/0! | N35: =M35/F35 -> #DIV/0!
D36: 46233 | E36: 四 | F36: =I36+M36 -> 0 | J36: =I36/F36 -> #DIV/0! | L36: =K36/F36 -> #DIV/0! | N36: =M36/F36 -> #DIV/0!
D37: 46234 | E37: 五 | F37: =I37+M37 -> 0 | J37: =I37/F37 -> #DIV/0! | L37: =K37/F37 -> #DIV/0! | N37: =M37/F37 -> #DIV/0!
F40: =I40+M40 -> 3411506.4 | I40: 3076682.5 | J40: =I40/F40 -> 0.90185452 | M40: 334823.93 | N40: =M40/F40 -> 0.098145478
I42: =SUM(I7:I12)+I40 -> 19224793
I43: =SUM(F7:F12)+F40 -> 21333821

Sheet （４）訂單數量構成比
B2: （4）訂單數量構成比
B3: 資料繳交日 | C3: 月份 | D3: 日期 | F3: 訂單量 | I3: 品類訂單量
I4: 熱食義麵 | K4: 季節調理麵 | M4: 微波小吃
F5: 日 | G5: 週累積 | H5: 月累積 | I5: 一配 | K5: 一配 | M5: 一配
I6: 訂單數 | J6: 比例(%) | K6: 訂單數 | L6: 比例(%) | M6: 訂單數 | N6: 比例(%)
B7: 46211 | C7: 七 | D7: 46204 | E7: 三 | F7: =SUM(I7,K7,M7) -> 64740 | G7: =SUM(F7:F12) -> 375105 | H7: =SUM(F7:F36) -> 1287266 | I7: 53739 | J7: =I7/F7 -> 0.83007414 | L7: =K7/F7 -> 0 | M7: 11001 | N7: =M7/F7 -> 0.16992586
D8: 46205 | E8: 四 | F8: =SUM(I8,K8,M8) -> 51631 | I8: 41408 | J8: =I8/F8 -> 0.8019988 | L8: =K8/F8 -> 0 | M8: 10223 | N8: =M8/F8 -> 0.1980012
D9: 46206 | E9: 五 | F9: =SUM(I9,K9,M9) -> 52190 | I9: 43392 | J9: =I9/F9 -> 0.83142364 | L9: =K9/F9 -> 0 | M9: 8798 | N9: =M9/F9 -> 0.16857636
D10: 46207 | E10: 六 | F10: =SUM(I10,K10,M10) -> 61707 | I10: 51314 | J10: =I10/F10 -> 0.83157502 | L10: =K10/F10 -> 0 | M10: 10393 | N10: =M10/F10 -> 0.16842498
D11: 46208 | E11: 日 | F11: =SUM(I11,K11,M11) -> 73271 | I11: 61496 | J11: =I11/F11 -> 0.83929522 | L11: =K11/F11 -> 0 | M11: 11775 | N11: =M11/F11 -> 0.16070478
D12: 46209 | E12: 一 | F12: =SUM(I12,K12,M12) -> 71566 | I12: 59473 | J12: =I12/F12 -> 0.83102311 | L12: =K12/F12 -> 0 | M12: 12093 | N12: =M12/F12 -> 0.16897689
B13: 46218 | D13: 46210 | E13: 二 | F13: =SUM(I13,K13,M13) -> 63648 | G13: =SUM(F13:F19) -> 455465 | I13: 52070 | J13: =I13/F13 -> 0.81809326 | L13: =K13/F13 -> 0 | M13: 11578 | N13: =M13/F13 -> 0.18190674
D14: 46211 | E14: 三 | F14: =SUM(I14,K14,M14) -> 65338 | I14: 54255 | J14: =I14/F14 -> 0.83037436 | L14: =K14/F14 -> 0 | M14: 11083 | N14: =M14/F14 -> 0.16962564
D15: 46212 | E15: 四 | F15: =SUM(I15,K15,M15) -> 71986 | I15: 59985 | J15: =I15/F15 -> 0.83328703 | L15: =K15/F15 -> 0 | M15: 12001 | N15: =M15/F15 -> 0.16671297
D16: 46213 | E16: 五 | F16: =SUM(I16,K16,M16) -> 49267 | I16: 40667 | J16: =I16/F16 -> 0.82544096 | L16: =K16/F16 -> 0 | M16: 8600 | N16: =M16/F16 -> 0.17455904
D17: 46214 | E17: 六 | F17: =SUM(I17,K17,M17) -> 58998 | I17: 48901 | J17: =I17/F17 -> 0.82885861 | L17: =K17/F17 -> 0 | M17: 10097 | N17: =M17/F17 -> 0.17114139
D18: 46215 | E18: 日 | F18: =SUM(I18,K18,M18) -> 72479 | I18: 60167 | J18: =I18/F18 -> 0.83013011 | L18: =K18/F18 -> 0 | M18: 12312 | N18: =M18/F18 -> 0.16986989
D19: 46216 | E19: 一 | F19: =SUM(I19,K19,M19) -> 73749 | I19: 60721 | J19: =I19/F19 -> 0.82334676 | L19: =K19/F19 -> 0 | M19: 13028 | N19: =M19/F19 -> 0.17665324
B20: 46225 | D20: 46217 | E20: 二 | F20: =SUM(I20,K20,M20) -> 75526 | G20: =SUM(F20:F26) -> 456696 | I20: 63483 | J20: =I20/F20 -> 0.84054498 | L20: =K20/F20 -> 0 | M20: 12043 | N20: =M20/F20 -> 0.15945502
D21: 46218 | E21: 三 | F21: =SUM(I21,K21,M21) -> 67666 | I21: 56656 | J21: =I21/F21 -> 0.83728904 | L21: =K21/F21 -> 0 | M21: 11010 | N21: =M21/F21 -> 0.16271096
D22: 46219 | E22: 四 | F22: =SUM(I22,K22,M22) -> 62695 | I22: 52400 | J22: =I22/F22 -> 0.83579233 | L22: =K22/F22 -> 0 | M22: 10295 | N22: =M22/F22 -> 0.16420767
D23: 46220 | E23: 五 | F23: =SUM(I23,K23,M23) -> 49290 | I23: 40594 | J23: =I23/F23 -> 0.82357476 | L23: =K23/F23 -> 0 | M23: 8696 | N23: =M23/F23 -> 0.17642524
D24: 46221 | E24: 六 | F24: =SUM(I24,K24,M24) -> 54825 | I24: 45315 | J24: =I24/F24 -> 0.82653899 | L24: =K24/F24 -> 0 | M24: 9510 | N24: =M24/F24 -> 0.17346101
D25: 46222 | E25: 日 | F25: =SUM(I25,K25,M25) -> 74386 | I25: 62168 | J25: =I25/F25 -> 0.83574866 | L25: =K25/F25 -> 0 | M25: 12218 | N25: =M25/F25 -> 0.16425134
D26: 46223 | E26: 一 | F26: =SUM(I26,K26,M26) -> 72308 | I26: 58661 | J26: =I26/F26 -> 0.8112657 | L26: =K26/F26 -> 0 | M26: 13647 | N26: =M26/F26 -> 0.1887343
B27: 46232 | D27: 46224 | E27: 二 | F27: =SUM(I27,K27,M27) -> 0 | G27: =SUM(F27:F33) -> 0 | J27: =I27/F27 -> #DIV/0! | L27: =K27/F27 -> #DIV/0! | N27: =M27/F27 -> #DIV/0!
D28: 46225 | E28: 三 | F28: =SUM(I28,K28,M28) -> 0 | J28: =I28/F28 -> #DIV/0! | L28: =K28/F28 -> #DIV/0! | N28: =M28/F28 -> #DIV/0!
D29: 46226 | E29: 四 | F29: =SUM(I29,K29,M29) -> 0 | J29: =I29/F29 -> #DIV/0! | L29: =K29/F29 -> #DIV/0! | N29: =M29/F29 -> #DIV/0!
D30: 46227 | E30: 五 | F30: =SUM(I30,K30,M30) -> 0 | J30: =I30/F30 -> #DIV/0! | L30: =K30/F30 -> #DIV/0! | N30: =M30/F30 -> #DIV/0!
D31: 46228 | E31: 六 | F31: =SUM(I31,K31,M31) -> 0 | J31: =I31/F31 -> #DIV/0! | L31: =K31/F31 -> #DIV/0! | N31: =M31/F31 -> #DIV/0!
D32: 46229 | E32: 日 | F32: =SUM(I32,K32,M32) -> 0 | J32: =I32/F32 -> #DIV/0! | L32: =K32/F32 -> #DIV/0! | N32: =M32/F32 -> #DIV/0!
D33: 46230 | E33: 一 | F33: =SUM(I33,K33,M33) -> 0 | J33: =I33/F33 -> #DIV/0! | L33: =K33/F33 -> #DIV/0! | N33: =M33/F33 -> #DIV/0!
D34: 46231 | E34: 二 | F34: =SUM(I34,K34,M34) -> 0 | J34: =I34/F34 -> #DIV/0! | L34: =K34/F34 -> #DIV/0! | N34: =M34/F34 -> #DIV/0!
D35: 46232 | E35: 三 | F35: =SUM(I35,K35,M35) -> 0 | J35: =I35/F35 -> #DIV/0! | L35: =K35/F35 -> #DIV/0! | N35: =M35/F35 -> #DIV/0!
D36: 46233 | E36: 四 | F36: =SUM(I36,K36,M36) -> 0 | J36: =I36/F36 -> #DIV/0! | L36: =K36/F36 -> #DIV/0! | N36: =M36/F36 -> #DIV/0!
D37: 46234 | E37: 五
F40: =SUM(I40,K40,M40) -> 73435 | I40: 61306 | J40: =I40/F40 -> 0.83483353 | M40: 12129 | N40: =M40/F40 -> 0.16516647

Sheet （５-1）品群別人時生產性（熱食義麵）
B1: 月平均人時性 | C1: =AVERAGE(L7,L30,L53,L76,L99,L122) -> 110.49749
B2: 產線配置圖－每週更新 | N2: 資料繳交 | O2: 日期 | P2: 46203 | U2: =P2+1 -> 46204 | Z2: =U2+1 -> 46205 | AE2: =Z2+1 -> 46206 | AJ2: =AE2+1 -> 46207 | AO2: =AJ2+1 -> 46208 | AT2: =AO2+1 -> 46209
P3: 二 | U3: 三 | Z3: 四 | AE3: 五 | AJ3: 六 | AO3: 日 | AT3: 一
B4: 品群 | C4: 商品名稱 | E4: 計畫 | H4: 平均人時性 | I4: 實績 | L4: 平均人時性 | M4: 排名 | O4: 日報 | P4: 實際 | T4: 平均人時性 | U4: 實際 | Y4: 平均人時性 | Z4: 實際 | AD4: 平均人時性 | AE4: 實際 | AI4: 平均人時性 | AJ4: 實際 | AN4: 平均人時性 | AO4: 實際 | AS4: 平均人時性 | AT4: 實際 | AX4: 平均人時性
E5: 產線配置圖 | I5: 產線配置圖 | P5: 生產實績 | U5: 生產實績 | Z5: 生產實績 | AE5: 生產實績 | AJ5: 生產實績 | AO5: 生產實績 | AT5: 生產實績
E6: 人數 | F6: 產能／時 | G6: 人時性 | I6: 人數 | J6: 產能／時 | K6: 人時性 | P6: 人數 | Q6: 產能／時 | R6: 人時性 | S6: 排名 | U6: 人數 | V6: 產能／時 | W6: 人時性 | X6: 排名 | Z6: 人數 | AA6: 產能／時 | AB6: 人時性 | AC6: 排名 | AE6: 人數 | AF6: 產能／時 | AG6: 人時性 | AH6: 排名 | AJ6: 人數 | AK6: 產能／時 | AL6: 人時性 | AM6: 排名 | AO6: 人數 | AP6: 產能／時 | AQ6: 人時性 | AR6: 排名 | AT6: 人數 | AU6: 產能／時 | AV6: 人時性 | AW6: 排名
B7: 熱食義麵 | C7: 1 | D7: 義式蕃茄起司義大利麵 | E7: =VLOOKUP(D7,'07產線配置圖'!$A$2:$C$25,2,0) -> 13 | F7: =VLOOKUP(D7,'07產線配置圖'!$A$2:$C$25,3,0) -> 2250 | G7: =F7/E7 -> 173.07692 | H7: =AVERAGE(G7:G21) -> #N/A | I7: =AVERAGE(P7,U7,Z7,AE7,AJ7,AO7,AT7) -> 13 | J7: =AVERAGE(Q7,V7,AA7,AF7,AK7,AP7,AU7) -> 2085.2857 | K7: =J7/I7 -> 160.40659 | L7: =IFERROR(AVERAGE(K7:K24),"-") -> 109.28977 | M7: =RANK(K7,$K$7:$K$24) -> 1 | P7: 13 | Q7: 2060 | R7: 158.46154 | S7: =RANK(R7,$R$7:$R$24) -> 1 | T7: =AVERAGE(R7:R24) -> 110.71181 | U7: 13 | V7: 2051 | W7: =V7/U7 -> 157.76923 | X7: =RANK(W7,$W$7:$W$24) -> 1 | Y7: =AVERAGE(W7:W24) -> 105.22103 | Z7: 13 | AA7: 2071 | AB7: =AA7/Z7 -> 159.30769 | AC7: =RANK(AB7,$AB$7:$AB$24) -> 1 | AD7: =AVERAGE(AB7:AB24) -> 106.72491 | AE7: 13 | AF7: 2039 | AG7: =AF7/AE7 -> 156.84615 | AH7: =RANK(AG7,$AG$7:$AG$24) -> 2 | AI7: =AVERAGE(AG7:AG24) -> 109.11876 | AJ7: 13 | AK7: 2105 | AL7: =AK7/AJ7 -> 161.92308 | AM7: =RANK(AL7,$AL$7:$AL$24) -> 1 | AN7: =AVERAGE(AL7:AL24) -> 111.02792 | AO7: 13 | AP7: 2143 | AQ7: =AP7/AO7 -> 164.84615 | AR7: =RANK(AQ7,$AQ$7:$AQ$24) -> 1 | AS7: =AVERAGE(AQ7:AQ24) -> 112.81091 | AT7: 13 | AU7: 2128 | AV7: =AU7/AT7 -> 163.69231 | AW7: =RANK(AV7,$AV$7:$AV$24) -> 1 | AX7: =AVERAGE(AV7:AV24) -> 109.81296
C8: 2 | D8: 奶油培根義大利麵 | E8: =VLOOKUP(D8,'07產線配置圖'!$A$2:$C$25,2,0) -> 15 | F8: =VLOOKUP(D8,'07產線配置圖'!$A$2:$C$25,3,0) -> 2250 | G8: =F8/E8 -> 150 | I8: =AVERAGE(P8,U8,Z8,AE8,AJ8,AO8,AT8) -> 15 | J8: =AVERAGE(Q8,V8,AA8,AF8,AK8,AP8,AU8) -> 2077.1429 | K8: =J8/I8 -> 138.47619 | M8: =RANK(K8,$K$7:$K$24) -> 5 | P8: 15 | Q8: 2107 | R8: 140.46667 | S8: =RANK(R8,$R$7:$R$24) -> 4 | U8: 15 | V8: 2045 | W8: =V8/U8 -> 136.33333 | X8: =RANK(W8,$W$7:$W$24) -> 3 | Z8: 15 | AA8: 2014 | AB8: =AA8/Z8 -> 134.26667 | AC8: =RANK(AB8,$AB$7:$AB$24) -> 5 | AE8: 15 | AF8: 2065 | AG8: =AF8/AE8 -> 137.66667 | AH8: =RANK(AG8,$AG$7:$AG$24) -> 5 | AJ8: 15 | AK8: 2111 | AL8: =AK8/AJ8 -> 140.73333 | AM8: =RANK(AL8,$AL$7:$AL$24) -> 5 | AO8: 15 | AP8: 2112 | AQ8: =AP8/AO8 -> 140.8 | AR8: =RANK(AQ8,$AQ$7:$AQ$24) -> 5 | AT8: 15 | AU8: 2086 | AV8: =AU8/AT8 -> 139.06667 | AW8: =RANK(AV8,$AV$7:$AV$24) -> 6
C9: 3 | D9: 白酒清炒鮮蛤義大利麵 | E9: =VLOOKUP(D9,'07產線配置圖'!$A$2:$C$25,2,0) -> 15 | F9: =VLOOKUP(D9,'07產線配置圖'!$A$2:$C$25,3,0) -> 2250 | G9: =F9/E9 -> 150 | I9: =AVERAGE(P9,U9,Z9,AE9,AJ9,AO9,AT9) -> 15 | J9: =AVERAGE(Q9,V9,AA9,AF9,AK9,AP9,AU9) -> 2112.4286 | K9: =J9/I9 -> 140.82857 | M9: =RANK(K9,$K$7:$K$24) -> 3 | P9: 15 | Q9: 2094 | R9: 139.6 | S9: =RANK(R9,$R$7:$R$24) -> 5 | U9: 15 | V9: 2090 | W9: =V9/U9 -> 139.33333 | X9: =RANK(W9,$W$7:$W$24) -> 2 | Z9: 15 | AA9: 2048 | AB9: =AA9/Z9 -> 136.53333 | AC9: =RANK(AB9,$AB$7:$AB$24) -> 4 | AE9: 15 | AF9: 2093 | AG9: =AF9/AE9 -> 139.53333 | AH9: =RANK(AG9,$AG$7:$AG$24) -> 4 | AJ9: 15 | AK9: 2164 | AL9: =AK9/AJ9 -> 144.26667 | AM9: =RANK(AL9,$AL$7:$AL$24) -> 3 | AO9: 15 | AP9: 2192 | AQ9: =AP9/AO9 -> 146.13333 | AR9: =RANK(AQ9,$AQ$7:$AQ$24) -> 3 | AT9: 15 | AU9: 2106 | AV9: =AU9/AT9 -> 140.4 | AW9: =RANK(AV9,$AV$7:$AV$24) -> 4
C10: 4 | D10: 焗烤起司雙饗筆尖麵 | E10: =VLOOKUP(D10,'07產線配置圖'!$A$2:$C$25,2,0) -> 16 | F10: =VLOOKUP(D10,'07產線配置圖'!$A$2:$C$25,3,0) -> 1800 | G10: =F10/E10 -> 112.5 | I10: =AVERAGE(P10,U10,Z10,AE10,AJ10,AO10,AT10) -> 15.428571 | J10: =AVERAGE(Q10,V10,AA10,AF10,AK10,AP10,AU10) -> 1586.5714 | K10: =J10/I10 -> 102.83333 | M10: =RANK(K10,$K$7:$K$24) -> 8 | P10: 16 | Q10: 1549 | R10: 96.8125 | S10: =RANK(R10,$R$7:$R$24) -> 10 | U10: 16 | V10: 1632 | W10: =V10/U10 -> 102 | X10: =RANK(W10,$W$7:$W$24) -> 8 | Z10: 16 | AA10: 1726 | AB10: =AA10/Z10 -> 107.875 | AC10: =RANK(AB10,$AB$7:$AB$24) -> 9 | AE10: 16 | AF10: 1615 | AG10: =AF10/AE10 -> 100.9375 | AH10: =RANK(AG10,$AG$7:$AG$24) -> 9 | AJ10: 16 | AK10: 1628 | AL10: =AK10/AJ10 -> 101.75 | AM10: =RANK(AL10,$AL$7:$AL$24) -> 9 | AO10: 12 | AP10: 1334 | AQ10: =AP10/AO10 -> 111.16667 | AR10: =RANK(AQ10,$AQ$7:$AQ$24) -> 8 | AT10: 16 | AU10: 1622 | AV10: =AU10/AT10 -> 101.375 | AW10: =RANK(AV10,$AV$7:$AV$24) -> 8
C11: 5 | D11: 青醬蛤蜊義大利麵 | E11: =VLOOKUP(D11,'07產線配置圖'!$A$2:$C$25,2,0) -> 14 | F11: =VLOOKUP(D11,'07產線配置圖'!$A$2:$C$25,3,0) -> 2250 | G11: =F11/E11 -> 160.71429 | I11: =AVERAGE(P11,U11,Z11,AE11,AJ11,AO11,AT11) -> 14 | J11: =AVERAGE(Q11,V11,AA11,AF11,AK11,AP11,AU11) -> 2039.8571 | K11: =J11/I11 -> 145.70408 | M11: =RANK(K11,$K$7:$K$24) -> 2 | P11: 14 | Q11: 1987 | R11: 141.92857 | S11: =RANK(R11,$R$7:$R$24) -> 2 | U11: 14 | V11: 1839 | W11: =V11/U11 -> 131.35714 | X11: =RANK(W11,$W$7:$W$24) -> 4 | Z11: 14 | AA11: 2019 | AB11: =AA11/Z11 -> 144.21429 | AC11: =RANK(AB11,$AB$7:$AB$24) -> 2 | AE11: 14 | AF11: 2225 | AG11: =AF11/AE11 -> 158.92857 | AH11: =RANK(AG11,$AG$7:$AG$24) -> 1 | AJ11: 14 | AK11: 2082 | AL11: =AK11/AJ11 -> 148.71429 | AM11: =RANK(AL11,$AL$7:$AL$24) -> 2 | AO11: 14 | AP11: 2114 | AQ11: =AP11/AO11 -> 151 | AR11: =RANK(AQ11,$AQ$7:$AQ$24) -> 2 | AT11: 14 | AU11: 2013 | AV11: =AU11/AT11 -> 143.78571 | AW11: =RANK(AV11,$AV$7:$AV$24) -> 3
C12: 6 | D12: 青花椒麻雞肉拌麵 | E12: =VLOOKUP(D12,'07產線配置圖'!$A$2:$C$25,2,0) -> 15 | F12: =VLOOKUP(D12,'07產線配置圖'!$A$2:$C$25,3,0) -> 1714 | G12: =F12/E12 -> 114.26667 | I12: =AVERAGE(P12,U12,Z12,AE12,AJ12,AO12,AT12) -> 15.142857 | J12: =AVERAGE(Q12,V12,AA12,AF12,AK12,AP12,AU12) -> 1542.4286 | K12: =J12/I12 -> 101.85849 | M12: =RANK(K12,$K$7:$K$24) -> 9 | P12: 15 | Q12: 1521 | R12: 101.4 | S12: =RANK(R12,$R$7:$R$24) -> 8 | U12: 16 | V12: 1394 | W12: =V12/U12 -> 87.125 | X12: =RANK(W12,$W$7:$W$24) -> 13 | Z12: 15 | AA12: 1624 | AB12: =AA12/Z12 -> 108.26667 | AC12: =RANK(AB12,$AB$7:$AB$24) -> 8 | AE12: 15 | AF12: 1608 | AG12: =AF12/AE12 -> 107.2 | AH12: =RANK(AG12,$AG$7:$AG$24) -> 8 | AJ12: 15 | AK12: 1639 | AL12: =AK12/AJ12 -> 109.26667 | AM12: =RANK(AL12,$AL$7:$AL$24) -> 7 | AO12: 15 | AP12: 1589 | AQ12: =AP12/AO12 -> 105.93333 | AR12: =RANK(AQ12,$AQ$7:$AQ$24) -> 9 | AT12: 15 | AU12: 1422 | AV12: =AU12/AT12 -> 94.8 | AW12: =RANK(AV12,$AV$7:$AV$24) -> 10
C13: 7 | D13: 沙茶豬肉炒麵 | E13: =VLOOKUP(D13,'07產線配置圖'!$A$2:$C$25,2,0) -> 17 | F13: =VLOOKUP(D13,'07產線配置圖'!$A$2:$C$25,3,0) -> 1800 | G13: =F13/E13 -> 105.88235 | I13: =AVERAGE(P13,U13,Z13,AE13,AJ13,AO13,AT13) -> 16.857143 | J13: =AVERAGE(Q13,V13,AA13,AF13,AK13,AP13,AU13) -> 1629.5714 | K13: =J13/I13 -> 96.669492 | M13: =RANK(K13,$K$7:$K$24) -> 10 | P13: 16 | Q13: 1573 | R13: 98.3125 | S13: =RANK(R13,$R$7:$R$24) -> 9 | U13: 17 | V13: 1599 | W13: =V13/U13 -> 94.058824 | X13: =RANK(W13,$W$7:$W$24) -> 9 | Z13: 17 | AA13: 1524 | AB13: =AA13/Z13 -> 89.647059 | AC13: =RANK(AB13,$AB$7:$AB$24) -> 11 | AE13: 17 | AF13: 1611 | AG13: =AF13/AE13 -> 94.764706 | AH13: =RANK(AG13,$AG$7:$AG$24) -> 10 | AJ13: 17 | AK13: 1683 | AL13: =AK13/AJ13 -> 99 | AM13: =RANK(AL13,$AL$7:$AL$24) -> 10 | AO13: 17 | AP13: 1766 | AQ13: =AP13/AO13 -> 103.88235 | AR13: =RANK(AQ13,$AQ$7:$AQ$24) -> 10 | AT13: 17 | AU13: 1651 | AV13: =AU13/AT13 -> 97.117647 | AW13: =RANK(AV13,$AV$7:$AV$24) -> 9
C14: 8 | D14: 府城鹽水意麵 | E14: =VLOOKUP(D14,'07產線配置圖'!$A$2:$C$25,2,0) -> 18 | F14: =VLOOKUP(D14,'07產線配置圖'!$A$2:$C$25,3,0) -> 1636 | G14: =F14/E14 -> 90.888889 | I14: =AVERAGE(P14,U14,Z14,AE14,AJ14,AO14,AT14) -> 17.428571 | J14: =AVERAGE(Q14,V14,AA14,AF14,AK14,AP14,AU14) -> 1452.8571 | K14: =J14/I14 -> 83.360656 | M14: =RANK(K14,$K$7:$K$24) -> 14 | P14: 17 | Q14: 1527 | R14: 89.823529 | S14: =RANK(R14,$R$7:$R$24) -> 13 | U14: 19 | V14: 1549 | W14: =V14/U14 -> 81.526316 | X14: =RANK(W14,$W$7:$W$24) -> 16 | Z14: 17 | AA14: 1397 | AB14: =AA14/Z14 -> 82.176471 | AC14: =RANK(AB14,$AB$7:$AB$24) -> 14 | AE14: 18 | AF14: 1422 | AG14: =AF14/AE14 -> 79 | AH14: =RANK(AG14,$AG$7:$AG$24) -> 16 | AJ14: 17 | AK14: 1369 | AL14: =AK14/AJ14 -> 80.529412 | AM14: =RANK(AL14,$AL$7:$AL$24) -> 17 | AO14: 17 | AP14: 1416 | AQ14: =AP14/AO14 -> 83.294118 | AR14: =RANK(AQ14,$AQ$7:$AQ$24) -> 13 | AT14: 17 | AU14: 1490 | AV14: =AU14/AT14 -> 87.647059 | AW14: =RANK(AV14,$AV$7:$AV$24) -> 13
C15: 9 | D15: 焗烤起司肉醬筆尖麵 | E15: =VLOOKUP(D15,'07產線配置圖'!$A$2:$C$25,2,0) -> 13 | F15: =VLOOKUP(D15,'07產線配置圖'!$A$2:$C$25,3,0) -> 1440 | G15: =F15/E15 -> 110.76923 | I15: =AVERAGE(P15,U15,Z15,AE15,AJ15,AO15,AT15) -> 12.428571 | J15: =AVERAGE(Q15,V15,AA15,AF15,AK15,AP15,AU15) -> 1022 | K15: =J15/I15 -> 82.229885 | M15: =RANK(K15,$K$7:$K$24) -> 15 | P15: 11 | Q15: 1063 | R15: 96.636364 | S15: =RANK(R15,$R$7:$R$24) -> 11 | U15: 13 | V15: 1160 | W15: =V15/U15 -> 89.230769 | X15: =RANK(W15,$W$7:$W$24) -> 11 | Z15: 13 | AA15: 759 | AB15: =AA15/Z15 -> 58.384615 | AC15: =RANK(AB15,$AB$7:$AB$24) -> 17 | AE15: 13 | AF15: 968 | AG15: =AF15/AE15 -> 74.461538 | AH15: =RANK(AG15,$AG$7:$AG$24) -> 17 | AJ15: 11 | AK15: 1007 | AL15: =AK15/AJ15 -> 91.545455 | AM15: =RANK(AL15,$AL$7:$AL$24) -> 12 | AO15: 13 | AP15: 1304 | AQ15: =AP15/AO15 -> 100.30769 | AR15: =RANK(AQ15,$AQ$7:$AQ$24) -> 11 | AT15: 13 | AU15: 893 | AV15: =AU15/AT15 -> 68.692308 | AW15: =RANK(AV15,$AV$7:$AV$24) -> 17
C16: 10 | D16: 蒜香奶油蝦蝦義大利麵 | E16: =VLOOKUP(D16,'07產線配置圖'!$A$2:$C$25,2,0) -> 17 | F16: =VLOOKUP(D16,'07產線配置圖'!$A$2:$C$25,3,0) -> 2250 | G16: =F16/E16 -> 132.35294 | I16: =AVERAGE(P16,U16,Z16,AE16,AJ16,AO16,AT16) -> 16.857143 | J16: =AVERAGE(Q16,V16,AA16,AF16,AK16,AP16,AU16) -> 2002.1429 | K16: =J16/I16 -> 118.77119 | M16: =RANK(K16,$K$7:$K$24) -> 7 | P16: 17 | Q16: 2078 | R16: 122.23529 | S16: =RANK(R16,$R$7:$R$24) -> 7 | U16: 17 | V16: 1922 | W16: =V16/U16 -> 113.05882 | X16: =RANK(W16,$W$7:$W$24) -> 6 | Z16: 17 | AA16: 1875 | AB16: =AA16/Z16 -> 110.29412 | AC16: =RANK(AB16,$AB$7:$AB$24) -> 7 | AE16: 16 | AF16: 1818 | AG16: =AF16/AE16 -> 113.625 | AH16: =RANK(AG16,$AG$7:$AG$24) -> 7 | AJ16: 17 | AK16: 2120 | AL16: =AK16/AJ16 -> 124.70588 | AM16: =RANK(AL16,$AL$7:$AL$24) -> 6 | AO16: 17 | AP16: 2096 | AQ16: =AP16/AO16 -> 123.29412 | AR16: =RANK(AQ16,$AQ$7:$AQ$24) -> 7 | AT16: 17 | AU16: 2106 | AV16: =AU16/AT16 -> 123.88235 | AW16: =RANK(AV16,$AV$7:$AV$24) -> 7
C17: 11 | D17: 義式辣味嫩烤雞腿排義大利麵 | E17: =VLOOKUP(D17,'07產線配置圖'!$A$2:$C$25,2,0) -> #N/A | F17: =VLOOKUP(D17,'07產線配置圖'!$A$2:$C$25,3,0) -> #N/A | G17: =F17/E17 -> #N/A | I17: =AVERAGE(P17,U17,Z17,AE17,AJ17,AO17,AT17) -> 15 | J17: =AVERAGE(Q17,V17,AA17,AF17,AK17,AP17,AU17) -> 1837 | K17: =J17/I17 -> 122.46667 | M17: =RANK(K17,$K$7:$K$24) -> 6 | P17: 15 | Q17: 1984 | R17: 132.26667 | S17: =RANK(R17,$R$7:$R$24) -> 6 | U17: 15 | V17: 1673 | W17: =V17/U17 -> 111.53333 | X17: =RANK(W17,$W$7:$W$24) -> 7 | Z17: 15 | AA17: 1814 | AB17: =AA17/Z17 -> 120.93333 | AC17: =RANK(AB17,$AB$7:$AB$24) -> 6 | AE17: 15 | AF17: 1779 | AG17: =AF17/AE17 -> 118.6 | AH17: =RANK(AG17,$AG$7:$AG$24) -> 6 | AJ17: 15 | AK17: 1570 | AL17: =AK17/AJ17 -> 104.66667 | AM17: =RANK(AL17,$AL$7:$AL$24) -> 8 | AO17: 15 | AP17: 1944 | AQ17: =AP17/AO17 -> 129.6 | AR17: =RANK(AQ17,$AQ$7:$AQ$24) -> 6 | AT17: 15 | AU17: 2095 | AV17: =AU17/AT17 -> 139.66667 | AW17: =RANK(AV17,$AV$7:$AV$24) -> 5
C18: 12 | D18: 香煎魚排佐檸檬奶油義大利麵 | E18: =VLOOKUP(D18,'07產線配置圖'!$A$2:$C$25,2,0) -> 15 | F18: =VLOOKUP(D18,'07產線配置圖'!$A$2:$C$25,3,0) -> 2250 | G18: =F18/E18 -> 150 | I18: =AVERAGE(P18,U18,Z18,AE18,AJ18,AO18,AT18) -> 15 | J18: =AVERAGE(Q18,V18,AA18,AF18,AK18,AP18,AU18) -> 2081.4286 | K18: =J18/I18 -> 138.7619 | M18: =RANK(K18,$K$7:$K$24) -> 4 | P18: 15 | Q18: 2118 | R18: 141.2 | S18: =RANK(R18,$R$7:$R$24) -> 3 | U18: 15 | V18: 1795 | W18: =V18/U18 -> 119.66667 | X18: =RANK(W18,$W$7:$W$24) -> 5 | Z18: 15 | AA18: 2087 | AB18: =AA18/Z18 -> 139.13333 | AC18: =RANK(AB18,$AB$7:$AB$24) -> 3 | AE18: 15 | AF18: 2114 | AG18: =AF18/AE18 -> 140.93333 | AH18: =RANK(AG18,$AG$7:$AG$24) -> 3 | AJ18: 15 | AK18: 2132 | AL18: =AK18/AJ18 -> 142.13333 | AM18: =RANK(AL18,$AL$7:$AL$24) -> 4 | AO18: 15 | AP18: 2132 | AQ18: =AP18/AO18 -> 142.13333 | AR18: =RANK(AQ18,$AQ$7:$AQ$24) -> 4 | AT18: 15 | AU18: 2192 | AV18: =AU18/AT18 -> 146.13333 | AW18: =RANK(AV18,$AV$7:$AV$24) -> 2
C19: 13 | D19: 黑松露野菇義大利麵 | E19: =VLOOKUP(D19,'07產線配置圖'!$A$2:$C$25,2,0) -> 17 | F19: =VLOOKUP(D19,'07產線配置圖'!$A$2:$C$25,3,0) -> 1636 | G19: =F19/E19 -> 96.235294 | I19: =AVERAGE(P19,U19,Z19,AE19,AJ19,AO19,AT19) -> 16.571429 | J19: =AVERAGE(Q19,V19,AA19,AF19,AK19,AP19,AU19) -> 1475.2857 | K19: =J19/I19 -> 89.025862 | M19: =RANK(K19,$K$7:$K$24) -> 11 | P19: 16 | Q19: 1485 | R19: 92.8125 | S19: =RANK(R19,$R$7:$R$24) -> 12 | U19: 17 | V19: 1564 | W19: =V19/U19 -> 92 | X19: =RANK(W19,$W$7:$W$24) -> 10 | Z19: 17 | AA19: 1553 | AB19: =AA19/Z19 -> 91.352941 | AC19: =RANK(AB19,$AB$7:$AB$24) -> 10 | AE19: 17 | AF19: 1466 | AG19: =AF19/AE19 -> 86.235294 | AH19: =RANK(AG19,$AG$7:$AG$24) -> 13 | AJ19: 17 | AK19: 1520 | AL19: =AK19/AJ19 -> 89.411765 | AM19: =RANK(AL19,$AL$7:$AL$24) -> 13 | AO19: 16 | AP19: 1319 | AQ19: =AP19/AO19 -> 82.4375 | AR19: =RANK(AQ19,$AQ$7:$AQ$24) -> 15 | AT19: 16 | AU19: 1420 | AV19: =AU19/AT19 -> 88.75 | AW19: =RANK(AV19,$AV$7:$AV$24) -> 12
... C23: 17 | D23: 蕃茄莎莎海鮮冷義大利麵 | E23: =VLOOKUP(D23,'07產線配置圖'!$A$2:$C$25,2,0) -> 16 | F23: =VLOOKUP(D23,'07產線配置圖'!$A$2:$C$25,3,0) -> 1500 | G23: =F23/E23 -> 93.75 | I23: =AVERAGE(P23,U23,Z23,AE23,AJ23,AO23,AT23) -> 15.285714 | J23: =AVERAGE(Q23,V23,AA23,AF23,AK23,AP23,AU23) -> 1255.1429 | K23: =J23/I23 -> 82.11215 | M23: =RANK(K23,$K$7:$K$24) -> 16 | P23: 15 | Q23: 1260 | R23: 84 | S23: =RANK(R23,$R$7:$R$24) -> 15 | U23: 15 | V23: 1185 | W23: =V23/U23 -> 79 | X23: =RANK(W23,$W$7:$W$24) -> 17 | Z23: 15 | AA23: 1185 | AB23: =AA23/Z23 -> 79 | AC23: =RANK(AB23,$AB$7:$AB$24) -> 16 | AE23: 16 | AF23: 1390 | AG23: =AF23/AE23 -> 86.875 | AH23: =RANK(AG23,$AG$7:$AG$24) -> 12 | AJ23: 15 | AK23: 1316 | AL23: =AK23/AJ23 -> 87.733333 | AM23: =RANK(AL23,$AL$7:$AL$24) -> 14 | AO23: 15 | AP23: 1232 | AQ23: =AP23/AO23 -> 82.133333 | AR23: =RANK(AQ23,$AQ$7:$AQ$24) -> 16 | AT23: 16 | AU23: 1218 | AV23: =AU23/AT23 -> 76.125 | AW23: =RANK(AV23,$AV$7:$AV$24) -> 16
C24: 18
B25: 產線配置圖－每週更新 | N25: 資料繳交 | O25: 日期 | P25: =AT2+1 -> 46210 | U25: =P25+1 -> 46211 | Z25: =U25+1 -> 46212 | AE25: =Z25+1 -> 46213 | AJ25: =AE25+1 -> 46214 | AO25: =AJ25+1 -> 46215 | AT25: =AO25+1 -> 46216
P26: 二 | U26: 三 | Z26: 四 | AE26: 五 | AJ26: 六 | AO26: 日 | AT26: 一
B27: 品群 | C27: 商品名稱 | E27: 計畫 | H27: 平均人時性 | I27: 實績 | L27: 平均人時性 | M27: 排名 | O27: 日報 | P27: 實際 | T27: 平均人時性 | U27: 實際 | Y27: 平均人時性 | Z27: 實際 | AD27: 平均人時性 | AE27: 實際 | AI27: 平均人時性 | AJ27: 實際 | AN27: 平均人時性 | AO27: 實際 | AS27: 平均人時性 | AT27: 實際 | AX27: 平均人時性
E28: 產線配置圖 | I28: 產線配置圖 | P28: 生產實績 | U28: 生產實績 | Z28: 生產實績 | AE28: 生產實績 | AJ28: 生產實績 | AO28: 生產實績 | AT28: 生產實績
E29: 人數 | F29: 產能／時 | G29: 人時性 | I29: 人數 | J29: 產能／時 | K29: 人時性 | P29: 人數 | Q29: 產能／時 | R29: 人時性 | S29: 排名 | U29: 人數 | V29: 產能／時 | W29: 人時性 | X29: 排名 | Z29: 人數 | AA29: 產能／時 | AB29: 人時性 | AC29: 排名 | AE29: 人數 | AF29: 產能／時 | AG29: 人時性 | AH29: 排名 | AJ29: 人數 | AK29: 產能／時 | AL29: 人時性 | AM29: 排名 | AO29: 人數 | AP29: 產能／時 | AQ29: 人時性 | AR29: 排名 | AT29: 人數 | AU29: 產能／時 | AV29: 人時性 | AW29: 排名
B30: 熱食義麵 | C30: 1 | D30: 義式蕃茄起司義大利麵 | E30: =VLOOKUP(D30,'07產線配置圖'!$A$2:$C$25,2,0) -> 13 | F30: =VLOOKUP(D30,'07產線配置圖'!$A$2:$C$25,3,0) -> 2250 | G30: =F30/E30 -> 173.07692 | H30: =AVERAGE(G30:G47) -> 121.02256 | I30: =AVERAGE(P30,U30,Z30,AE30,AJ30,AO30,AT30) -> 12.714286 | J30: =AVERAGE(Q30,V30,AA30,AF30,AK30,AP30,AU30) -> 2070.4286 | K30: =J30/I30 -> 162.8427 | L30: =IFERROR(AVERAGE(K30:K47),"-") -> 110.74778 | M30: =RANK(K30, K$30:$K$47) -> 1 | P30: 13 | Q30: 2148 | R30: =Q30/P30 -> 165.23077 | S30: =RANK(R30,$R$30:$R$47) -> 1 | T30: =AVERAGE(R30:R47) -> 111.19833 | U30: 13 | V30: 1997 | W30: =V30/U30 -> 153.61538 | X30: =RANK(W30, $W$30:$W$47) -> 1 | Y30: =AVERAGE(W30:W47) -> 110.0699 | Z30: 13 | AA30: 2154 | AB30: =AA30/Z30 -> 165.69231 | AC30: =RANK(AB30, $AB$30:$AB$47) -> 1 | AD30: =AVERAGE(AB30:AB47) -> 110.15653 | AE30: 13 | AF30: 1948 | AG30: =AF30/AE30 -> 149.84615 | AH30: =RANK(AG30, $AG$30:$AG$47) -> 2 | AI30: =AVERAGE(AG30:AG47) -> 108.39631 | AJ30: 13 | AK30: 2060 | AL30: =AK30/AJ30 -> 158.46154 | AM30: =RANK(AL30, $AL$30:$AL$47) -> 1 | AN30: =AVERAGE(AL30:AL47) -> 111.48999 | AO30: 12 | AP30: 2127 | AQ30: =AP30/AO30 -> 177.25 | AR30: =RANK(AQ30,$AQ$30:$AQ$47) -> 1 | AS30: =AVERAGE(AQ30:AQ47) -> 111.46963 | AT30: 12 | AU30: 2059 | AV30: =AU30/AT30 -> 171.58333 | AW30: =RANK(AV30, $AV$30:$AV$47) -> 1 | AX30: =AVERAGE(AV30:AV47) -> 112.88037
C31: 2 | D31: 奶油培根義大利麵 | E31: =VLOOKUP(D31,'07產線配置圖'!$A$2:$C$25,2,0) -> 15 | F31: =VLOOKUP(D31,'07產線配置圖'!$A$2:$C$25,3,0) -> 2250 | G31: =F31/E31 -> 150 | I31: =AVERAGE(P31,U31,Z31,AE31,AJ31,AO31,AT31) -> 14.714286 | J31: =AVERAGE(Q31,V31,AA31,AF31,AK31,AP31,AU31) -> 2120 | K31: =J31/I31 -> 144.07767 | M31: =RANK(K31, K$30:$K$47) -> 4 | P31: 15 | Q31: 2131 | R31: =Q31/P31 -> 142.06667 | S31: =RANK(R31,$R$30:$R$47) -> 4 | U31: 15 | V31: 2055 | W31: =V31/U31 -> 137 | X31: =RANK(W31, $W$30:$W$47) -> 3 | Z31: 15 | AA31: 2148 | AB31: =AA31/Z31 -> 143.2 | AC31: =RANK(AB31, $AB$30:$AB$47) -> 4 | AE31: 15 | AF31: 2097 | AG31: =AF31/AE31 -> 139.8 | AH31: =RANK(AG31, $AG$30:$AG$47) -> 4 | AJ31: 15 | AK31: 2150 | AL31: =AK31/AJ31 -> 143.33333 | AM31: =RANK(AL31, $AL$30:$AL$47) -> 3 | AO31: 14 | AP31: 2133 | AQ31: =AP31/AO31 -> 152.35714 | AR31: =RANK(AQ31,$AQ$30:$AQ$47) -> 2 | AT31: 14 | AU31: 2126 | AV31: =AU31/AT31 -> 151.85714 | AW31: =RANK(AV31, $AV$30:$AV$47) -> 4
C32: 3 | D32: 白酒清炒鮮蛤義大利麵 | E32: =VLOOKUP(D32,'07產線配置圖'!$A$2:$C$25,2,0) -> 15 | F32: =VLOOKUP(D32,'07產線配置圖'!$A$2:$C$25,3,0) -> 2250 | G32: =F32/E32 -> 150 | I32: =AVERAGE(P32,U32,Z32,AE32,AJ32,AO32,AT32) -> 14.714286 | J32: =AVERAGE(Q32,V32,AA32,AF32,AK32,AP32,AU32) -> 2130.5714 | K32: =J32/I32 -> 144.79612 | M32: =RANK(K32, K$30:$K$47) -> 3 | P32: 15 | Q32: 2130 | R32: =Q32/P32 -> 142 | S32: =RANK(R32,$R$30:$R$47) -> 5 | U32: 15 | V32: 2068 | W32: =V32/U32 -> 137.86667 | X32: =RANK(W32, $W$30:$W$47) -> 2 | Z32: 15 | AA32: 2171 | AB32: =AA32/Z32 -> 144.73333 | AC32: =RANK(AB32, $AB$30:$AB$47) -> 3 | AE32: 15 | AF32: 2142 | AG32: =AF32/AE32 -> 142.8 | AH32: =RANK(AG32, $AG$30:$AG$47) -> 3 | AJ32: 15 | AK32: 2209 | AL32: =AK32/AJ32 -> 147.26667 | AM32: =RANK(AL32, $AL$30:$AL$47) -> 2 | AO32: 14 | AP32: 2062 | AQ32: =AP32/AO32 -> 147.28571 | AR32: =RANK(AQ32,$AQ$30:$AQ$47) -> 3 | AT32: 14 | AU32: 2132 | AV32: =AU32/AT32 -> 152.28571 | AW32: =RANK(AV32, $AV$30:$AV$47) -> 3
C33: 4 | D33: 焗烤起司雙饗筆尖麵 | E33: =VLOOKUP(D33,'07產線配置圖'!$A$2:$C$25,2,0) -> 16 | F33: =VLOOKUP(D33,'07產線配置圖'!$A$2:$C$25,3,0) -> 1800 | G33: =F33/E33 -> 112.5 | I33: =AVERAGE(P33,U33,Z33,AE33,AJ33,AO33,AT33) -> 16 | J33: =AVERAGE(Q33,V33,AA33,AF33,AK33,AP33,AU33) -> 1590.5714 | K33: =J33/I33 -> 99.410714 | M33: =RANK(K33, K$30:$K$47) -> 8 | P33: 16 | Q33: 1635 | R33: =Q33/P33 -> 102.1875 | S33: =RANK(R33,$R$30:$R$47) -> 8 | U33: 16 | V33: 1582 | W33: =V33/U33 -> 98.875 | X33: =RANK(W33, $W$30:$W$47) -> 9 | Z33: 16 | AA33: 1562 | AB33: =AA33/Z33 -> 97.625 | AC33: =RANK(AB33, $AB$30:$AB$47) -> 9 | AE33: 16 | AF33: 1616 | AG33: =AF33/AE33 -> 101 | AH33: =RANK(AG33, $AG$30:$AG$47) -> 8 | AJ33: 16 | AK33: 1552 | AL33: =AK33/AJ33 -> 97 | AM33: =RANK(AL33, $AL$30:$AL$47) -> 9 | AO33: 16 | AP33: 1658 | AQ33: =AP33/AO33 -> 103.625 | AR33: =RANK(AQ33,$AQ$30:$AQ$47) -> 7 | AT33: 16 | AU33: 1529 | AV33: =AU33/AT33 -> 95.5625 | AW33: =RANK(AV33, $AV$30:$AV$47) -> 9
C34: 5 | D34: 青醬蛤蜊義大利麵 | E34: =VLOOKUP(D34,'07產線配置圖'!$A$2:$C$25,2,0) -> 14 | F34: =VLOOKUP(D34,'07產線配置圖'!$A$2:$C$25,3,0) -> 2250 | G34: =F34/E34 -> 160.71429 | I34: =AVERAGE(P34,U34,Z34,AE34,AJ34,AO34,AT34) -> 13.857143 | J34: =AVERAGE(Q34,V34,AA34,AF34,AK34,AP34,AU34) -> 2069.1429 | K34: =J34/I34 -> 149.31959 | M34: =RANK(K34, K$30:$K$47) -> 2 | P34: 14 | Q34: 2151 | R34: =Q34/P34 -> 153.64286 | S34: =RANK(R34,$R$30:$R$47) -> 2 | U34: 14 | V34: 1901 | W34: =V34/U34 -> 135.78571 | X34: =RANK(W34, $W$30:$W$47) -> 4 | Z34: 14 | AA34: 2169 | AB34: =AA34/Z34 -> 154.92857 | AC34: =RANK(AB34, $AB$30:$AB$47) -> 2 | AE34: 14 | AF34: 2135 | AG34: =AF34/AE34 -> 152.5 | AH34: =RANK(AG34, $AG$30:$AG$47) -> 1 | AJ34: 14 | AK34: 2006 | AL34: =AK34/AJ34 -> 143.28571 | AM34: =RANK(AL34, $AL$30:$AL$47) -> 4 | AO34: 14 | AP34: 1978 | AQ34: =AP34/AO34 -> 141.28571 | AR34: =RANK(AQ34,$AQ$30:$AQ$47) -> 6 | AT34: 13 | AU34: 2144 | AV34: =AU34/AT34 -> 164.92308 | AW34: =RANK(AV34, $AV$30:$AV$47) -> 2
C35: 6 | D35: 青花椒麻雞肉拌麵 | E35: =VLOOKUP(D35,'07產線配置圖'!$A$2:$C$25,2,0) -> 15 | F35: =VLOOKUP(D35,'07產線配置圖'!$A$2:$C$25,3,0) -> 1714 | G35: =F35/E35 -> 114.26667 | I35: =AVERAGE(P35,U35,Z35,AE35,AJ35,AO35,AT35) -> 15.142857 | J35: =AVERAGE(Q35,V35,AA35,AF35,AK35,AP35,AU35) -> 1564.8571 | K35: =J35/I35 -> 103.33962 | M35: =RANK(K35, K$30:$K$47) -> 7 | P35: 15 | Q35: 1630 | R35: =Q35/P35 -> 108.66667 | S35: =RANK(R35,$R$30:$R$47) -> 7 | U35: 15 | V35: 1602 | W35: =V35/U35 -> 106.8 | X35: =RANK(W35, $W$30:$W$47) -> 8 | Z35: 15 | AA35: 1580 | AB35: =AA35/Z35 -> 105.33333 | AC35: =RANK(AB35, $AB$30:$AB$47) -> 7 | AE35: 15 | AF35: 1523 | AG35: =AF35/AE35 -> 101.53333 | AH35: =RANK(AG35, $AG$30:$AG$47) -> 7 | AJ35: 15 | AK35: 1620 | AL35: =AK35/AJ35 -> 108 | AM35: =RANK(AL35, $AL$30:$AL$47) -> 7 | AO35: 15 | AP35: 1509 | AQ35: =AP35/AO35 -> 100.6 | AR35: =RANK(AQ35,$AQ$30:$AQ$47) -> 8 | AT35: 16 | AU35: 1490 | AV35: =AU35/AT35 -> 93.125 | AW35: =RANK(AV35, $AV$30:$AV$47) -> 10
C36: 7 | D36: 沙茶豬肉炒麵 | E36: =VLOOKUP(D36,'07產線配置圖'!$A$2:$C$25,2,0) -> 17 | F36: =VLOOKUP(D36,'07產線配置圖'!$A$2:$C$25,3,0) -> 1800 | G36: =F36/E36 -> 105.88235 | I36: =AVERAGE(P36,U36,Z36,AE36,AJ36,AO36,AT36) -> 17 | J36: =AVERAGE(Q36,V36,AA36,AF36,AK36,AP36,AU36) -> 1621.5714 | K36: =J36/I36 -> 95.386555 | M36: =RANK(K36, K$30:$K$47) -> 9 | P36: 17 | Q36: 1637 | R36: =Q36/P36 -> 96.294118 | S36: =RANK(R36,$R$30:$R$47) -> 9 | U36: 17 | V36: 1680 | W36: =V36/U36 -> 98.823529 | X36: =RANK(W36, $W$30:$W$47) -> 10 | Z36: 17 | AA36: 1633 | AB36: =AA36/Z36 -> 96.058824 | AC36: =RANK(AB36, $AB$30:$AB$47) -> 10 | AE36: 17 | AF36: 1428 | AG36: =AF36/AE36 -> 84 | AH36: =RANK(AG36, $AG$30:$AG$47) -> 13 | AJ36: 17 | AK36: 1766 | AL36: =AK36/AJ36 -> 103.88235 | AM36: =RANK(AL36, $AL$30:$AL$47) -> 8 | AO36: 17 | AP36: 1563 | AQ36: =AP36/AO36 -> 91.941176 | AR36: =RANK(AQ36,$AQ$30:$AQ$47) -> 9 | AT36: 17 | AU36: 1644 | AV36: =AU36/AT36 -> 96.705882 | AW36: =RANK(AV36, $AV$30:$AV$47) -> 7
C37: 8 | D37: 府城鹽水意麵 | E37: =VLOOKUP(D37,'07產線配置圖'!$A$2:$C$25,2,0) -> 18 | F37: =VLOOKUP(D37,'07產線配置圖'!$A$2:$C$25,3,0) -> 1636 | G37: =F37/E37 -> 90.888889 | I37: =AVERAGE(P37,U37,Z37,AE37,AJ37,AO37,AT37) -> 17.285714 | J37: =AVERAGE(Q37,V37,AA37,AF37,AK37,AP37,AU37) -> 1431 | K37: =J37/I37 -> 82.785124 | M37: =RANK(K37, K$30:$K$47) -> 15 | P37: 18 | Q37: 1353 | R37: =Q37/P37 -> 75.166667 | S37: =RANK(R37,$R$30:$R$47) -> 15 | U37: 18 | V37: 1526 | W37: =V37/U37 -> 84.777778 | X37: =RANK(W37, $W$30:$W$47) -> 16 | Z37: 17 | AA37: 1404 | AB37: =AA37/Z37 -> 82.588235 | AC37: =RANK(AB37, $AB$30:$AB$47) -> 15 | AE37: 17 | AF37: 1341 | AG37: =AF37/AE37 -> 78.882353 | AH37: =RANK(AG37, $AG$30:$AG$47) -> 15 | AJ37: 16 | AK37: 1370 | AL37: =AK37/AJ37 -> 85.625 | AM37: =RANK(AL37, $AL$30:$AL$47) -> 14 | AO37: 18 | AP37: 1547 | AQ37: =AP37/AO37 -> 85.944444 | AR37: =RANK(AQ37,$AQ$30:$AQ$47) -> 12 | AT37: 17 | AU37: 1476 | AV37: =AU37/AT37 -> 86.823529 | AW37: =RANK(AV37, $AV$30:$AV$47) -> 12
C38: 9 | D38: 蒜香奶油蝦蝦義大利麵 | E38: =VLOOKUP(D38,'07產線配置圖'!$A$2:$C$25,2,0) -> 17 | F38: =VLOOKUP(D38,'07產線配置圖'!$A$2:$C$25,3,0) -> 2250 | G38: =F38/E38 -> 132.35294 | I38: =AVERAGE(P38,U38,Z38,AE38,AJ38,AO38,AT38) -> 14.285714 | J38: =AVERAGE(Q38,V38,AA38,AF38,AK38,AP38,AU38) -> 1126.4286 | K38: =J38/I38 -> 78.85 | M38: =RANK(K38, K$30:$K$47) -> 16 | P38: 13 | Q38: 935 | R38: =Q38/P38 -> 71.923077 | S38: =RANK(R38,$R$30:$R$47) -> 16 | U38: 16 | V38: 1754 | W38: =V38/U38 -> 109.625 | X38: =RANK(W38, $W$30:$W$47) -> 7 | Z38: 15 | AA38: 926 | AB38: =AA38/Z38 -> 61.733333 | AC38: =RANK(AB38, $AB$30:$AB$47) -> 16 | AE38: 15 | AF38: 1131 | AG38: =AF38/AE38 -> 75.4 | AH38: =RANK(AG38, $AG$30:$AG$47) -> 16 | AJ38: 9 | AK38: 735 | AL38: =AK38/AJ38 -> 81.666667 | AM38: =RANK(AL38, $AL$30:$AL$47) -> 15 | AO38: 16 | AP38: 1127 | AQ38: =AP38/AO38 -> 70.4375 | AR38: =RANK(AQ38,$AQ$30:$AQ$47) -> 16 | AT38: 16 | AU38: 1277 | AV38: =AU38/AT38 -> 79.8125 | AW38: =RANK(AV38, $AV$30:$AV$47) -> 15
C39: 10 | D39: 香煎魚排佐檸檬奶油義大利麵 | E39: =VLOOKUP(D39,'07產線配置圖'!$A$2:$C$25,2,0) -> 15 | F39: =VLOOKUP(D39,'07產線配置圖'!$A$2:$C$25,3,0) -> 2250 | G39: =F39/E39 -> 150 | I39: =AVERAGE(P39,U39,Z39,AE39,AJ39,AO39,AT39) -> 14.714286 | J39: =AVERAGE(Q39,V39,AA39,AF39,AK39,AP39,AU39) -> 2056.7143 | K39: =J39/I39 -> 139.7767 | M39: =RANK(K39, K$30:$K$47) -> 5 | P39: 15 | Q39: 2174 | R39: =Q39/P39 -> 144.93333 | S39: =RANK(R39,$R$30:$R$47) -> 3 | U39: 15 | V39: 1919 | W39: =V39/U39 -> 127.93333 | X39: =RANK(W39, $W$30:$W$47) -> 6 | Z39: 15 | AA39: 2080 | AB39: =AA39/Z39 -> 138.66667 | AC39: =RANK(AB39, $AB$30:$AB$47) -> 5 | AE39: 15 | AF39: 2084 | AG39: =AF39/AE39 -> 138.93333 | AH39: =RANK(AG39, $AG$30:$AG$47) -> 5 | AJ39: 15 | AK39: 2080 | AL39: =AK39/AJ39 -> 138.66667 | AM39: =RANK(AL39, $AL$30:$AL$47) -> 5 | AO39: 14 | AP39: 1995 | AQ39: =AP39/AO39 -> 142.5 | AR39: =RANK(AQ39,$AQ$30:$AQ$47) -> 5 | AT39: 14 | AU39: 2065 | AV39: =AU39/AT39 -> 147.5 | AW39: =RANK(AV39, $AV$30:$AV$47) -> 5
C40: 11 | D40: 黑松露野菇義大利麵 | E40: =VLOOKUP(D40,'07產線配置圖'!$A$2:$C$25,2,0) -> 17 | F40: =VLOOKUP(D40,'07產線配置圖'!$A$2:$C$25,3,0) -> 1636 | G40: =F40/E40 -> 96.235294 | I40: =AVERAGE(P40,U40,Z40,AE40,AJ40,AO40,AT40) -> 17 | J40: =AVERAGE(Q40,V40,AA40,AF40,AK40,AP40,AU40) -> 1477 | K40: =J40/I40 -> 86.882353 | M40: =RANK(K40, K$30:$K$47) -> 12 | P40: 17 | Q40: 1505 | R40: =Q40/P40 -> 88.529412 | S40: =RANK(R40,$R$30:$R$47) -> 12 | U40: 17 | V40: 1524 | W40: =V40/U40 -> 89.647059 | X40: =RANK(W40, $W$30:$W$47) -> 12 | Z40: 17 | AA40: 1449 | AB40: =AA40/Z40 -> 85.235294 | AC40: =RANK(AB40, $AB$30:$AB$47) -> 13 | AE40: 17 | AF40: 1579 | AG40: =AF40/AE40 -> 92.882353 | AH40: =RANK(AG40, $AG$30:$AG$47) -> 9 | AJ40: 17 | AK40: 1477 | AL40: =AK40/AJ40 -> 86.882353 | AM40: =RANK(AL40, $AL$30:$AL$47) -> 13 | AO40: 17 | AP40: 1391 | AQ40: =AP40/AO40 -> 81.823529 | AR40: =RANK(AQ40,$AQ$30:$AQ$47) -> 15 | AT40: 17 | AU40: 1414 | AV40: =AU40/AT40 -> 83.176471 | AW40: =RANK(AV40, $AV$30:$AV$47) -> 14
C41: 12 | D41: 奶油鮮蝦明太子細扁麵 | E41: 18 | F41: =VLOOKUP(D41,'07產線配置圖'!$A$2:$C$25,3,0) -> 1636 | G41: =F41/E41 -> 90.888889 | I41: =AVERAGE(P41,U41,Z41,AE41,AJ41,AO41,AT41) -> 17.714286 | J41: =AVERAGE(Q41,V41,AA41,AF41,AK41,AP41,AU41) -> 1528.1429 | K41: =J41/I41 -> 86.266129 | M41: =RANK(K41, K$30:$K$47) -> 13 | P41: 18 | Q41: 1566 | R41: =Q41/P41 -> 87 | S41: =RANK(R41,$R$30:$R$47) -> 13 | U41: 18 | V41: 1529 | W41: =V41/U41 -> 84.944444 | X41: =RANK(W41, $W$30:$W$47) -> 15 | Z41: 17 | AA41: 1444 | AB41: =AA41/Z41 -> 84.941176 | AC41: =RANK(AB41, $AB$30:$AB$47) -> 14 | AE41: 18 | AF41: 1543 | AG41: =AF41/AE41 -> 85.722222 | AH41: =RANK(AG41, $AG$30:$AG$47) -> 12 | AJ41: 17 | AK41: 1491 | AL41: =AK41/AJ41 -> 87.705882 | AM41: =RANK(AL41, $AL$30:$AL$47) -> 12 | AO41: 18 | AP41: 1546 | AQ41: =AP41/AO41 -> 85.888889 | AR41: =RANK(AQ41,$AQ$30:$AQ$47) -> 13 | AT41: 18 | AU41: 1578 | AV41: =AU41/AT41 -> 87.666667 | AW41: =RANK(AV41, $AV$30:$AV$47) -> 11
C42: 13 | D42: 焦糖拿鐵烤雞細扁麵 | E42: =VLOOKUP(D42,'07產線配置圖'!$A$2:$C$25,2,0) -> 18 | F42: =VLOOKUP(D42,'07產線配置圖'!$A$2:$C$25,3,0) -> 1565 | G42: =F42/E42 -> 86.944444 | I42: =AVERAGE(P42,U42,Z42,AE42,AJ42,AO42,AT42) -> 17.428571 | J42: =AVERAGE(Q42,V42,AA42,AF42,AK42,AP42,AU42) -> 1448.7143 | K42: =J42/I42 -> 83.122951 | M42: =RANK(K42, K$30:$K$47) -> 14 | P42: 18 | Q42: 1501 | R42: =Q42/P42 -> 83.388889 | S42: =RANK(R42,$R$30:$R$47) -> 14 | U42: 18 | V42: 1563 | W42: =V42/U42 -> 86.833333 | X42: =RANK(W42, $W$30:$W$47) -> 14 | Z42: 16 | AA42: 1380 | AB42: =AA42/Z42 -> 86.25 | AC42: =RANK(AB42, $AB$30:$AB$47) -> 12 | AE42: 18 | AF42: 1469 | AG42: =AF42/AE42 -> 81.611111 | AH42: =RANK(AG42, $AG$30:$AG$47) -> 14 | AJ42: 17 | AK42: 1383 | AL42: =AK42/AJ42 -> 81.352941 | AM42: =RANK(AL42, $AL$30:$AL$47) -> 16 | AO42: 17 | AP42: 1421 | AQ42: =AP42/AO42 -> 83.588235 | AR42: =RANK(AQ42,$AQ$30:$AQ$47) -> 14 | AT42: 18 | AU42: 1424 | AV42: =AU42/AT42 -> 79.111111 | AW42: =RANK(AV42, $AV$30:$AV$47) -> 16
C43: 14 | D43: 義式蛋蛋青醬鮪魚冷義大利麵 | E43: =VLOOKUP(D43,'07產線配置圖'!$A$2:$C$25,2,0) -> 17 | F43: =VLOOKUP(D43,'07產線配置圖'!$A$2:$C$25,3,0) -> 1500 | G43: =F43/E43 -> 88.235294 | I43: =AVERAGE(P43,U43,Z43,AE43,AJ43,AO43,AT43) -> 17 | J43: =AVERAGE(Q43,V43,AA43,AF43,AK43,AP43,AU43) -> 1513.8571 | K43: =J43/I43 -> 89.05042 | M43: =RANK(K43, K$30:$K$47) -> 11 | P43: 17 | Q43: 1559 | R43: =Q43/P43 -> 91.705882 | S43: =RANK(R43,$R$30:$R$47) -> 11 | U43: 17 | V43: 1526 | W43: =V43/U43 -> 89.764706 | X43: =RANK(W43, $W$30:$W$47) -> 11 | Z43: 17 | AA43: 1508 | AB43: =AA43/Z43 -> 88.705882 | AC43: =RANK(AB43, $AB$30:$AB$47) -> 11 | AE43: 17 | AF43: 1515 | AG43: =AF43/AE43 -> 89.117647 | AH43: =RANK(AG43, $AG$30:$AG$47) -> 11 | AJ43: 17 | AK43: 1518 | AL43: =AK43/AJ43 -> 89.294118 | AM43: =RANK(AL43, $AL$30:$AL$47) -> 11 | AO43: 17 | AP43: 1503 | AQ43: =AP43/AO43 -> 88.411765 | AR43: =RANK(AQ43,$AQ$30:$AQ$47) -> 10 | AT43: 17 | AU43: 1468 | AV43: =AU43/AT43 -> 86.352941 | AW43: =RANK(AV43, $AV$30:$AV$47) -> 13
...

Sheet （５-3）品群別人時生產性(微波小吃)
B1: 月平均人時性 | C1: =AVERAGE(L7,L27,L47,L67,L87,L107) -> 127.68458
B2: 產線配置圖－每週更新 | N2: 資料繳交 | O2: 日期 | P2: 46203 | U2: =P2+1 -> 46204 | Z2: =U2+1 -> 46205 | AE2: =Z2+1 -> 46206 | AJ2: =AE2+1 -> 46207 | AO2: =AJ2+1 -> 46208 | AT2: =AO2+1 -> 46209
P3: 二 | U3: 三 | Z3: 四 | AE3: 五 | AJ3: 六 | AO3: 日 | AT3: 一
B4: 品群 | C4: 商品名稱 | E4: 計畫 | H4: 平均人時性 | I4: 實績 | L4: 平均人時性 | M4: 排名 | O4: 日報 | P4: 實際 | T4: 平均人時性 | U4: 實際 | Y4: 平均人時性 | Z4: 實際 | AD4: 平均人時性 | AE4: 實際 | AI4: 平均人時性 | AJ4: 實際 | AN4: 平均人時性 | AO4: 實際 | AS4: 平均人時性 | AT4: 實際 | AX4: 平均人時性
E5: 產線配置圖 | I5: 產線配置圖 | P5: 生產實績 | U5: 生產實績 | Z5: 生產實績 | AE5: 生產實績 | AJ5: 生產實績 | AO5: 生產實績 | AT5: 生產實績
E6: 人數 | F6: 產能／時 | G6: 人時性 | I6: 人數 | J6: 產能／時 | K6: 人時性 | P6: 人數 | Q6: 產能／時 | R6: 人時性 | S6: 排名 | U6: 人數 | V6: 產能／時 | W6: 人時性 | X6: 排名 | Z6: 人數 | AA6: 產能／時 | AB6: 人時性 | AC6: 排名 | AE6: 人數 | AF6: 產能／時 | AG6: 人時性 | AH6: 排名 | AJ6: 人數 | AK6: 產能／時 | AL6: 人時性 | AM6: 排名 | AO6: 人數 | AP6: 產能／時 | AQ6: 人時性 | AR6: 排名 | AT6: 人數 | AU6: 產能／時 | AV6: 人時性 | AW6: 排名
B7: 微波小吃 | C7: 1 | D7: 小滷青蔬 | E7: =VLOOKUP(D7,'07產線配置圖'!$A$26:$C$33,2,0) -> 15 | F7: =VLOOKUP(D7,'07產線配置圖'!$A$26:$C$33,3,0) -> 1636 | G7: =F7/E7 -> 109.06667 | H7: =AVERAGE(G7:G21) -> 138.81212 | I7: =AVERAGE(P7,U7,Z7,AE7,AJ7,AO7,AT7) -> 14.714286 | J7: =AVERAGE(Q7,V7,AA7,AF7,AK7,AP7,AU7) -> 1518.1429 | K7: =J7/I7 -> 103.17476 | L7: =IFERROR(AVERAGE(K7:K21),"-") -> 126.80811 | M7: =RANK(K7,$K$7:$K$21) -> 4 | P7: 15 | Q7: 1510 | R7: =Q7/P7 -> 100.66667 | S7: =RANK(R7, R$7:R$21) -> 4 | T7: =AVERAGE(R7:R21) -> 121.04735 | U7: 14 | V7: 1487 | W7: =V7/U7 -> 106.21429 | X7: =RANK(W7,$W$7:$W$21) -> 4 | Y7: =AVERAGE(W7:W21) -> 133.00812 | Z7: 15 | AA7: 1589 | AB7: =AA7/Z7 -> 105.93333 | AC7: =RANK(AB7,$AB$7:$AB$21) -> 4 | AD7: =AVERAGE(AB7:AB21) -> 126.94242 | AE7: 15 | AF7: 1560 | AG7: =AF7/AE7 -> 104 | AH7: =RANK(AG7,$AG$7:$AG$21) -> 4 | AI7: =AVERAGE(AG7:AG21) -> 124.31818 | AJ7: 15 | AK7: 1566 | AL7: =AK7/AJ7 -> 104.4 | AM7: =RANK(AL7,$AL$7:$AL$21) -> 4 | AN7: =AVERAGE(AL7:AL21) -> 127.26591 | AO7: 14 | AP7: 1360 | AQ7: =AP7/AO7 -> 97.142857 | AR7: =RANK(AQ7,$AQ$7:$AQ$21) -> 4 | AS7: =AVERAGE(AQ7:AQ21) -> 124.79935 | AT7: 15 | AU7: 1555 | AV7: =AU7/AT7 -> 103.66667 | AW7: =RANK(AV7,$AV$7:$AV$21) -> 4 | AX7: =AVERAGE(AV7:AV21) -> 130.68712
C8: 2 | D8: 起司馬鈴薯 | E8: =VLOOKUP(D8,'07產線配置圖'!$A$26:$C$33,2,0) -> 11 | F8: =VLOOKUP(D8,'07產線配置圖'!$A$26:$C$33,3,0) -> 1636 | G8: =F8/E8 -> 148.72727 | I8: =AVERAGE(P8,U8,Z8,AE8,AJ8,AO8,AT8) -> 11.142857 | J8: =AVERAGE(Q8,V8,AA8,AF8,AK8,AP8,AU8) -> 1534.2857 | K8: =J8/I8 -> 137.69231 | M8: =RANK(K8,$K$7:$K$21) -> 1 | P8: 12 | Q8: 1491 | R8: =Q8/P8 -> 124.25 | S8: =RANK(R8, R$7:R$21) -> 3 | U8: 11 | V8: 1590 | W8: =V8/U8 -> 144.54545 | X8: =RANK(W8,$W$7:$W$21) -> 2 | Z8: 11 | AA8: 1567 | AB8: =AA8/Z8 -> 142.45455 | AC8: =RANK(AB8,$AB$7:$AB$21) -> 1 | AE8: 11 | AF8: 1580 | AG8: =AF8/AE8 -> 143.63636 | AH8: =RANK(AG8,$AG$7:$AG$21) -> 1 | AJ8: 11 | AK8: 1497 | AL8: =AK8/AJ8 -> 136.09091 | AM8: =RANK(AL8,$AL$7:$AL$21) -> 2 | AO8: 11 | AP8: 1490 | AQ8: =AP8/AO8 -> 135.45455 | AR8: =RANK(AQ8,$AQ$7:$AQ$21) -> 2 | AT8: 11 | AU8: 1525 | AV8: =AU8/AT8 -> 138.63636 | AW8: =RANK(AV8,$AV$7:$AV$21) -> 2
C9: 3 | D9: 韓式炒冬粉 | E9: =VLOOKUP(D9,'07產線配置圖'!$A$26:$C$33,2,0) -> 11 | F9: =VLOOKUP(D9,'07產線配置圖'!$A$26:$C$33,3,0) -> 1636 | G9: =F9/E9 -> 148.72727 | I9: =AVERAGE(P9,U9,Z9,AE9,AJ9,AO9,AT9) -> 10.857143 | J9: =AVERAGE(Q9,V9,AA9,AF9,AK9,AP9,AU9) -> 1463.2857 | K9: =J9/I9 -> 134.77632 | M9: =RANK(K9,$K$7:$K$21) -> 2 | P9: 11 | Q9: 1390 | R9: =Q9/P9 -> 126.36364 | S9: =RANK(R9, R$7:R$21) -> 2 | U9: 11 | V9: 1605 | W9: =V9/U9 -> 145.90909 | X9: =RANK(W9,$W$7:$W$21) -> 1 | Z9: 11 | AA9: 1377 | AB9: =AA9/Z9 -> 125.18182 | AC9: =RANK(AB9,$AB$7:$AB$21) -> 3 | AE9: 11 | AF9: 1358 | AG9: =AF9/AE9 -> 123.45455 | AH9: =RANK(AG9,$AG$7:$AG$21) -> 3 | AJ9: 11 | AK9: 1532 | AL9: =AK9/AJ9 -> 139.27273 | AM9: =RANK(AL9,$AL$7:$AL$21) -> 1 | AO9: 10 | AP9: 1413 | AQ9: =AP9/AO9 -> 141.3 | AR9: =RANK(AQ9,$AQ$7:$AQ$21) -> 1 | AT9: 11 | AU9: 1568 | AV9: =AU9/AT9 -> 142.54545 | AW9: =RANK(AV9,$AV$7:$AV$21) -> 1
C10: 4 | D10: 麻辣雞心 | E10: =VLOOKUP(D10,'07產線配置圖'!$A$26:$C$33,2,0) -> 11 | F10: =VLOOKUP(D10,'07產線配置圖'!$A$26:$C$33,3,0) -> 1636 | G10: =F10/E10 -> 148.72727 | I10: =AVERAGE(P10,U10,Z10,AE10,AJ10,AO10,AT10) -> 10.428571 | J10: =AVERAGE(Q10,V10,AA10,AF10,AK10,AP10,AU10) -> 1372.2857 | K10: =J10/I10 -> 131.58904 | M10: =RANK(K10,$K$7:$K$21) -> 3 | P10: 11 | Q10: 1462 | R10: =Q10/P10 -> 132.90909 | S10: =RANK(R10, R$7:R$21) -> 1 | U10: 11 | V10: 1489 | W10: =V10/U10 -> 135.36364 | X10: =RANK(W10,$W$7:$W$21) -> 3 | Z10: 10 | AA10: 1342 | AB10: =AA10/Z10 -> 134.2 | AC10: =RANK(AB10,$AB$7:$AB$21) -> 2 | AE10: 11 | AF10: 1388 | AG10: =AF10/AE10 -> 126.18182 | AH10: =RANK(AG10,$AG$7:$AG$21) -> 2 | AJ10: 10 | AK10: 1293 | AL10: =AK10/AJ10 -> 129.3 | AM10: =RANK(AL10,$AL$7:$AL$21) -> 3 | AO10: 10 | AP10: 1253 | AQ10: =AP10/AO10 -> 125.3 | AR10: =RANK(AQ10,$AQ$7:$AQ$21) -> 3 | AT10: 10 | AU10: 1379 | AV10: =AU10/AT10 -> 137.9 | AW10: =RANK(AV10,$AV$7:$AV$21) -> 3
C11: 5
C12: 6
C13: 7
C14: 8
C15: 9
C16: 10
C17: 11
C18: 12
C19: 13
C20: 14
