Workbook

Sheet 生產管理報表(週) 
A1: 長家廠生產管理報表
A3: 月別 | B3: 8 | C3: 週別 | D3: W3 | E3: 工廠 | F3: 長家廠
A4: （１）收支狀況 | E4: ※單位：千元 | G4: （２）ＫＰＩ達成進度
A5: 項目 | B5: 當週 | C5: 前週 | D5: 差異 | E5: 累計 | G5: 項目 | H5: KPI | I5: 當週 | J5: 前週 | K5: 累計 | L5: ※補充
A6: 業績金額 | B6: ='（１）收支狀況'!G22/1000 -> 17043.774 | C6: 17686.446 | D6: =B6-C6 -> -642.67252 | E6: ='（１）收支狀況'!H5/1000 -> 61106.542 | G6: 人時性(個/月均) | H6: ='（２）ＫＰＩ達成進度'!C1 -> 126.6 | I6: ='（２）ＫＰＩ達成進度'!G22 -> 114.21429 | J6: 113.62857 | K6: ='（２）ＫＰＩ達成進度'!H5 -> 114.1375 | L6: 個／MH
A7: 訂單數量 | B7: ='（１）收支狀況'!J22 -> 368210 | C7: 382077 | D7: =B7-C7 -> -13867 | E7: ='（１）收支狀況'!K5 -> 1320645 | G7: 人時達成率(%/月均) | H7: 0.8 | I7: =I6/H6 -> 0.90216655 | J7: =J6/H6 -> 0.89754006 | K7: =K6/H6 -> 0.90156003 | L7: 達成率
A8: 材料費 | B8: ='（１）收支狀況'!M22/1000 -> 10756.808 | C8: 11162.561 | D8: =B8-C8 -> -405.75369 | E8: ='（１）收支狀況'!N5/1000 -> 38561.051 | G8: 半成品-報廢(%) | H8: 0.0025 | I8: ='（２）ＫＰＩ達成進度'!M22 -> 0.0026055314 | J8: 0.0024047489 | K8: ='日別報廢率總表 '!C36/'日別報廢率總表 '!B36 -> 0.0029544993 | L8: 報廢率
A9: 材料費率 | B9: =B8/B6 -> 0.63112827 | C9: =C8/C6 -> 0.63113646 | D9: =B9-C9 -> -8.1922096e-06 | E9: =E8/E6 -> 0.63104621 | G9: 半成品-超用(%) | H9: 0.0025 | I9: ='（２）ＫＰＩ達成進度'!P22 -> 0.0032068891 | J9: 0.0031849042 | K9: ='日別報廢率總表 '!E36/'日別報廢率總表 '!B36 -> 0.0041353631 | L9: 超用率
A10: 勞務成本 | D10: =B10-C10 -> 0 | G10: 固定產線-導入率(%) | H10: 1 | I10: ='（２）ＫＰＩ達成進度'!S22 -> 0.286 | J10: 0.286 | K10: ='（２）ＫＰＩ達成進度'!T5 -> 0.286 | L10: 導入率
A11: 勞務費率 | D11: =B11-C11 -> 0 | G11: 教育訓練-實施率(%) | H11: 1 | I11: ='（２）ＫＰＩ達成進度'!V22 -> 0.93714286 | J11: 0.92 | K11: ='（２）ＫＰＩ達成進度'!W5 -> 0.905 | L11: 實施率
A13: （３）業績構成比 | G13: （４）訂單數量構成比
B14: 當週 | C14: 比例 | D14: 前週 | E14: 差異 | H14: 當週 | I14: 比例 | J14: 前週 | K14: 差異
A15: 熱食義麵(122,123,124,126) | B15: =SUM('（３）業績構成比'!I24:I30)/1000 -> 15400.169 | C15: =B15/B6 -> 0.90356569 | D15: 0.90272694 | E15: =C15-D15 -> 0.00083875816 | G15: 熱食義麵(122,123,124,126) | H15: =SUM('（４）訂單數量構成比'!I24:I30) -> 308741 | I15: =IFERROR(H15/$B$7,"") -> 0.83849162 | J15: 0.83709043 | K15: =IFERROR(I15-J15,"") -> 0.0014011922
A16: 季節調理麵(111,112) | C16: =IFERROR(B16/$B$6,"") -> 0 | D16: 0 | E16: =IFERROR(C16-D16,"") -> 0 | G16: 季節調理麵(111,112) | I16: =IFERROR(H16/$B$7,"") -> 0 | J16: 0 | K16: =IFERROR(I16-J16,"") -> 0
A17: 微波小吃(153,154,155) | B17: =SUM('（３）業績構成比'!M24:M30)/1000 -> 1643.6045 | C17: =B17/B6 -> 0.096434306 | D17: 0.097273065 | E17: =C17-D17 -> -0.00083875816 | G17: 微波小吃(153,154,155) | H17: =SUM('（４）訂單數量構成比'!M24:M30) -> 59469 | I17: =IFERROR(H17/$B$7,"") -> 0.16150838 | J17: 0.16290957 | K17: =IFERROR(I17-J17,"") -> -0.0014011922
C18: =SUM(C15:C17) -> 1 | D18: =SUM(D15:D17) -> 1 | I18: =SUM(I15:I17) -> 1 | J18: =SUM(J15:J17) -> 1
A20: （５）品群別人時生產性
A21: 品群 | B21: 當週 | C21: 前週 | D21: 差異 | E21: 累計
A22: 熱食義麵(122,123,124,126) | B22: 112.5 | C22: 110.5 | D22: =B22-C22 -> 2 | E22: ='（５-1）品群別人時生產性（熱食義麵）'!C1 -> 111.26856
A23: 季節調理麵(111,112) | D23: =B23-C23 -> 0
A24: 微波小吃(153,154,155) | B24: 121.9 | C24: 125.4 | D24: =B24-C24 -> -3.5 | E24: ='（５-3）品群別人時生產性(微波小吃)'!C1 -> 125.66178

Sheet （１）收支狀況
B2: （１）收支狀況
B3: 資料繳交日 | C3: 月份 | D3: 日期 | F3: 營業額(元) | I3: 訂單數量(個) | L3: 材料費(元) | O3: 材料費率（材料費／營業額） | R3: 勞務成本（全廠人事成本） | U3: 勞務費率（勞務成本／營業額）
F4: 日 | G4: 週累積 | H4: 月累積 | I4: 日 | J4: 週累積 | K4: 月累積 | L4: 日 | M4: 週累積 | N4: 月累積 | O4: 日 | P4: 週累積 | Q4: 月累積 | R4: 日 | S4: 週累積 | T4: 月累積 | U4: 日 | V4: 週累積 | W4: 月累積
C5: 八 | D5: 46235 | E5: 六 | F5: 2319312.8 | G5: =SUM(F5:F7) -> 8367994 | H5: =SUM(F5:F35) -> 61106542 | I5: 50157 | J5: =SUM(I5:I7) -> 180848 | K5: =SUM(I5:I35) -> 1320645 | L5: 1463267 | M5: =SUM(L5:L7) -> 5279336.2 | N5: =SUM(L5:L35) -> 38561051 | O5: =L5/F5 -> 0.63090544 | P5: =M5/G5 -> 0.63089627 | Q5: =N5/H5 -> 0.63104621 | S5: =SUM(R5) -> 0 | T5: =SUM(R5:R36) -> 0 | U5: =R5/F5 -> 0 | V5: =S5/M5 -> 0 | W5: =T5/N5 -> 0
D6: 46236 | E6: 日 | F6: 3023076.5 | I6: 65177 | L6: 1907538.2 | O6: =L6/F6 -> 0.63099237 | S6: =SUM(R6:R12) -> 0 | U6: =R6/F6 -> 0 | V6: =S6/M6 -> #DIV/0!
D7: 46237 | E7: 一 | F7: 3025604.7 | I7: 65514 | L7: 1908530.9 | O7: =L7/F7 -> 0.63079323 | U7: =R7/F7 -> 0
B8: 46246 | D8: 46238 | E8: 二 | F8: 2744836.5 | G8: =SUM(F8:F14) -> 18008328 | I8: 60136 | J8: =SUM(I8:I14) -> 389510 | L8: 1732247 | M8: =SUM(L8:L14) -> 11362346 | O8: =L8/F8 -> 0.63109296 | P8: =M8/G8 -> 0.63094956 | U8: =R8/F8 -> 0
D9: 46239 | E9: 三 | F9: 2568942.7 | I9: 55976 | L9: 1620433.9 | O9: =L9/F9 -> 0.63077853 | U9: =R9/F9 -> 0
D10: 46240 | E10: 四 | F10: 2531185.4 | I10: 54231 | L10: 1596646.8 | O10: =L10/F10 -> 0.63079014 | U10: =R10/F10 -> 0
D11: 46241 | E11: 五 | F11: 1978394.4 | I11: 43046 | L11: 1248388.5 | O11: =L11/F11 -> 0.63101092 | U11: =R11/F11 -> 0
D12: 46242 | E12: 六 | F12: 2143592.4 | I12: 46671 | L12: 1352463.2 | O12: =L12/F12 -> 0.63093301 | U12: =R12/F12 -> 0
D13: 46243 | E13: 日 | F13: 3005927.6 | I13: 64248 | L13: 1896834.4 | O13: =L13/F13 -> 0.6310313 | S13: =SUM(R13:R19) -> 0 | U13: =R13/F13 -> 0 | V13: =S13/M13 -> #DIV/0!
D14: 46244 | E14: 一 | F14: 3035448.5 | I14: 65202 | L14: 1915332.6 | O14: =L14/F14 -> 0.63098832 | U14: =R14/F14 -> 0
B15: 46253 | D15: 46245 | E15: 二 | F15: 2592646.8 | G15: =SUM(F15:F21) -> 17686446 | I15: 56162 | J15: =SUM(I15:I21) -> 382077 | L15: 1636367.5 | M15: =SUM(L15:L21) -> 11162561 | O15: =L15/F15 -> 0.63115712 | P15: =M15/G15 -> 0.63113646 | U15: =R15/F15 -> 0
D16: 46246 | E16: 三 | F16: 2595086.9 | I16: 55867 | L16: 1637904.8 | O16: =L16/F16 -> 0.63115603 | U16: =R16/F16 -> 0
D17: 46247 | E17: 四 | F17: 2476906 | I17: 53441 | L17: 1563050.7 | O17: =L17/F17 -> 0.6310497 | U17: =R17/F17 -> 0
D18: 46248 | E18: 五 | F18: 2004758.6 | I18: 43480 | L18: 1265097.9 | O18: =L18/F18 -> 0.63104751 | U18: =R18/F18 -> 0
D19: 46249 | E19: 六 | F19: 2180067.2 | I19: 47216 | L19: 1375942.3 | O19: =L19/F19 -> 0.63114675 | U19: =R19/F19 -> 0
D20: 46250 | E20: 日 | F20: 2865626.4 | I20: 61768 | L20: 1808344.6 | O20: =L20/F20 -> 0.63104689 | S20: =SUM(R20:R26) -> 0 | U20: =R20/F20 -> 0 | V20: =S20/M20 -> #DIV/0!
D21: 46251 | E21: 一 | F21: 2971354.7 | I21: 64143 | L21: 1875853.4 | O21: =L21/F21 -> 0.63131253 | U21: =R21/F21 -> 0
B22: 46260 | D22: 46252 | E22: 二 | F22: 2636829.4 | G22: =SUM(F22:F28) -> 17043774 | I22: 56950 | J22: =SUM(I22:I28) -> 368210 | L22: 1664202.5 | M22: =SUM(L22:L28) -> 10756808 | O22: =L22/F22 -> 0.63113773 | P22: =M22/G22 -> 0.63112827 | U22: =R22/F22 -> 0
D23: 46253 | E23: 三 | F23: 2408538.3 | I23: 51994 | L23: 1520379.1 | O23: =L23/F23 -> 0.63124557 | U23: =R23/F23 -> 0
D24: 46254 | E24: 四 | F24: 2319925.4 | I24: 50258 | L24: 1464553 | O24: =L24/F24 -> 0.63129315 | U24: =R24/F24 -> 0
D25: 46255 | E25: 五 | F25: 1831621.7 | I25: 39573 | L25: 1155921.6 | O25: =L25/F25 -> 0.63109193 | U25: =R25/F25 -> 0
D26: 46256 | E26: 六 | F26: 2037135.9 | I26: 44045 | L26: 1285695.6 | O26: =L26/F26 -> 0.63112904 | U26: =R26/F26 -> 0
D27: 46257 | E27: 日 | F27: 2878649.5 | I27: 62066 | L27: 1816049.2 | O27: =L27/F27 -> 0.63086846 | S27: =SUM(R27:R33) -> 0 | U27: =R27/F27 -> 0 | V27: =S27/M27 -> #DIV/0!
D28: 46258 | E28: 一 | F28: 2931073.8 | I28: 63324 | L28: 1850006.5 | O28: =L28/F28 -> 0.63117022 | U28: =R28/F28 -> 0
B29: 46267 | D29: 46259 | E29: 二 | G29: =SUM(F29:F35) -> 0 | J29: =SUM(I29:I35) -> 0 | M29: =SUM(L29:L35) -> 0 | O29: =L29/F29 -> #DIV/0! | P29: =M29/G29 -> #DIV/0! | U29: =R29/F29 -> #DIV/0!
D30: 46260 | E30: 三 | O30: =L30/F30 -> #DIV/0! | U30: =R30/F30 -> #DIV/0!
D31: 46261 | E31: 四 | O31: =L31/F31 -> #DIV/0! | U31: =R31/F31 -> #DIV/0!
D32: 46262 | E32: 五 | O32: =L32/F32 -> #DIV/0! | U32: =R32/F32 -> #DIV/0!
D33: 46263 | E33: 六 | O33: =L33/F33 -> #DIV/0! | U33: =R33/F33 -> #DIV/0!
D34: 46264 | E34: 日 | O34: =L34/F34 -> #DIV/0! | U34: =R34/F34 -> #DIV/0!
D35: 46265 | E35: 一 | O35: =L35/F35 -> #DIV/0! | U35: =R35/F35 -> #DIV/0!

Sheet （２）ＫＰＩ達成進度
C1: 126.6
B2: （２）ＫＰＩ達成進度
B3: 資料繳交日 | C3: 月份 | D3: 日期 | F3: 人時生產性(個/人) | I3: 人時生產性達成率(%) | L3: 半成品報廢(%) | O3: 半成品超用(%) | R3: 固定產線-導入率(固定產線數/總產線數) | U3: 教育訓練-實施率(進度/計畫)
F4: 日 | G4: 週平均 | H4: 月平均 | I4: 日 | J4: 週平均 | K4: 月平均 | L4: 日 | M4: 週平均 | N4: 月平均 | O4: 日 | P4: 週平均 | Q4: 月平均 | R4: 日 | S4: 週平均 | T4: 月平均 | U4: 日 | V4: 週平均 | W4: 月平均
C5: 八 | D5: 46235 | E5: 六 | F5: 112.8 | G5: =AVERAGE(F5:F7) -> 114.03333 | H5: =AVERAGE(F5:F35) -> 114.1375 | I5: =F5/$C$1 -> 0.89099526 | J5: =AVERAGE(I5:I7) -> 0.90073723 | K5: =H5/C1 -> 0.90156003 | L5: ='日別報廢率總表 '!C4/'日別報廢率總表 '!B4 -> 0.0024457273 | M5: ='日別報廢率總表 '!N4/'日別報廢率總表 '!M4 -> 0.0034201656 | N5: ='日別報廢率總表 '!C36/'日別報廢率總表 '!B36 -> 0.0029544993 | O5: ='日別報廢率總表 '!E4/'日別報廢率總表 '!B4 -> 0.004845583 | P5: ='日別報廢率總表 '!O4/'日別報廢率總表 '!M4 -> 0.0056793174 | Q5: ='日別報廢率總表 '!E36/'日別報廢率總表 '!B36 -> 0.0041353631 | R5: 0.286 | S5: =AVERAGE(R5:R7) -> 0.286 | T5: =AVERAGE(R5:R35) -> 0.286 | U5: 0.85 | V5: =AVERAGE(U5:U7) -> 0.85 | W5: =AVERAGE(U5:U35) -> 0.905
D6: 46236 | E6: 日 | F6: 115.2 | I6: =F6/$C$1 -> 0.90995261 | L6: ='日別報廢率總表 '!C5/'日別報廢率總表 '!B5 -> 0.0036772843 | O6: ='日別報廢率總表 '!E5/'日別報廢率總表 '!B5 -> 0.005668299 | R6: 0.286 | U6: 0.85
D7: 46237 | E7: 一 | F7: 114.1 | I7: =F7/$C$1 -> 0.90126382 | L7: ='日別報廢率總表 '!C6/'日別報廢率總表 '!B6 -> 0.003910229 | O7: ='日別報廢率總表 '!E6/'日別報廢率總表 '!B6 -> 0.0063294354 | R7: 0.286 | U7: 0.85
B8: 46246 | D8: 46238 | E8: 二 | F8: 114.8 | G8: =AVERAGE(F8:F14) -> 114.61429 | I8: =F8/$C$1 -> 0.90679305 | J8: =AVERAGE(I8:I14) -> 0.90532611 | L8: ='日別報廢率總表 '!C7/'日別報廢率總表 '!B7 -> 0.0023069377 | M8: ='日別報廢率總表 '!N7/'日別報廢率總表 '!M7 -> 0.0036083172 | O8: ='日別報廢率總表 '!E7/'日別報廢率總表 '!B7 -> 0.0036897637 | P8: ='日別報廢率總表 '!O7/'日別報廢率總表 '!M7 -> 0.0052301421 | R8: 0.286 | S8: =AVERAGE(R8:R14) -> 0.286 | U8: 0.85 | V8: =AVERAGE(U8:U14) -> 0.88142857
D9: 46239 | E9: 三 | F9: 116.2 | I9: =F9/$C$1 -> 0.9178515 | L9: ='日別報廢率總表 '!C8/'日別報廢率總表 '!B8 -> 0.0039454187 | O9: ='日別報廢率總表 '!E8/'日別報廢率總表 '!B8 -> 0.0053887511 | R9: 0.286 | U9: 0.85
D10: 46240 | E10: 四 | F10: 113.4 | I10: =F10/$C$1 -> 0.8957346 | L10: ='日別報廢率總表 '!C9/'日別報廢率總表 '!B9 -> 0.0062224004 | O10: ='日別報廢率總表 '!E9/'日別報廢率總表 '!B9 -> 0.011409878 | R10: 0.286 | U10: 0.85
D11: 46241 | E11: 五 | F11: 111.8 | I11: =F11/$C$1 -> 0.88309637 | L11: ='日別報廢率總表 '!C10/'日別報廢率總表 '!B10 -> 0.0046409957 | O11: ='日別報廢率總表 '!E10/'日別報廢率總表 '!B10 -> 0.0052043756 | R11: 0.286 | U11: 0.88
D12: 46242 | E12: 六 | F12: 115.8 | I12: =F12/$C$1 -> 0.91469194 | L12: ='日別報廢率總表 '!C11/'日別報廢率總表 '!B11 -> 0.0040597186 | O12: ='日別報廢率總表 '!E11/'日別報廢率總表 '!B11 -> 0.0042259318 | R12: 0.286 | U12: 0.9
D13: 46243 | E13: 日 | F13: 114.1 | I13: =F13/$C$1 -> 0.90126382 | L13: ='日別報廢率總表 '!C12/'日別報廢率總表 '!B12 -> 0.0026895235 | O13: ='日別報廢率總表 '!E12/'日別報廢率總表 '!B12 -> 0.0042315069 | R13: 0.286 | U13: 0.92
D14: 46244 | E14: 一 | F14: 116.2 | I14: =F14/$C$1 -> 0.9178515 | L14: ='日別報廢率總表 '!C13/'日別報廢率總表 '!B13 -> 0.0022380131 | O14: ='日別報廢率總表 '!E13/'日別報廢率總表 '!B13 -> 0.0030505602 | R14: 0.286 | U14: 0.92
B15: 46253 | D15: 46245 | E15: 二 | F15: 113.7 | G15: =AVERAGE(F15:F21) -> 113.62857 | I15: =F15/$C$1 -> 0.89810427 | J15: =AVERAGE(I15:I21) -> 0.89754006 | L15: ='日別報廢率總表 '!C14/'日別報廢率總表 '!B14 -> 0.0022929871 | M15: ='日別報廢率總表 '!N14/'日別報廢率總表 '!M14 -> 0.0024047489 | O15: ='日別報廢率總表 '!E14/'日別報廢率總表 '!B14 -> 0.0038707885 | P15: ='日別報廢率總表 '!O14/'日別報廢率總表 '!M14 -> 0.0031849042 | R15: 0.286 | S15: =AVERAGE(R15:R21) -> 0.286 | U15: 0.92 | V15: =AVERAGE(U15:U21) -> 0.92
D16: 46246 | E16: 三 | F16: 115.2 | I16: =F16/$C$1 -> 0.90995261 | L16: ='日別報廢率總表 '!C15/'日別報廢率總表 '!B15 -> 0.0024455275 | O16: ='日別報廢率總表 '!E15/'日別報廢率總表 '!B15 -> 0.0027042683 | R16: 0.286 | U16: 0.92
D17: 46247 | E17: 四 | F17: 112.8 | I17: =F17/$C$1 -> 0.89099526 | L17: ='日別報廢率總表 '!C16/'日別報廢率總表 '!B16 -> 0.0035963397 | O17: ='日別報廢率總表 '!E16/'日別報廢率總表 '!B16 -> 0.0039967379 | R17: 0.286 | U17: 0.92
D18: 46248 | E18: 五 | F18: 110.5 | I18: =F18/$C$1 -> 0.8728278 | L18: ='日別報廢率總表 '!C17/'日別報廢率總表 '!B17 -> 0.0027878767 | O18: ='日別報廢率總表 '!E17/'日別報廢率總表 '!B17 -> 0.004885757 | R18: 0.286 | U18: 0.92
D19: 46249 | E19: 六 | F19: 112.6 | I19: =F19/$C$1 -> 0.88941548 | L19: ='日別報廢率總表 '!C18/'日別報廢率總表 '!B18 -> 0.0014516318 | O19: ='日別報廢率總表 '!E18/'日別報廢率總表 '!B18 -> 0.0022652008 | R19: 0.286 | U19: 0.92
D20: 46250 | E20: 日 | F20: 111 | I20: =F20/$C$1 -> 0.87677725 | L20: ='日別報廢率總表 '!C19/'日別報廢率總表 '!B19 -> 0.0023108629 | O20: ='日別報廢率總表 '!E19/'日別報廢率總表 '!B19 -> 0.0015088539 | R20: 0.286 | U20: 0.92
D21: 46251 | E21: 一 | F21: 119.6 | I21: =F21/$C$1 -> 0.94470774 | L21: ='日別報廢率總表 '!C20/'日別報廢率總表 '!B20 -> 0.0020046956 | O21: ='日別報廢率總表 '!E20/'日別報廢率總表 '!B20 -> 0.0034731058 | R21: 0.286 | U21: 0.92
B22: 46260 | D22: 46252 | E22: 二 | F22: 115.4 | G22: =AVERAGE(F22:F28) -> 114.21429 | I22: =F22/$C$1 -> 0.91153239 | J22: =AVERAGE(I22:I28) -> 0.90216655 | L22: ='日別報廢率總表 '!C21/'日別報廢率總表 '!B21 -> 0.0018189986 | M22: ='日別報廢率總表 '!N21/'日別報廢率總表 '!M21 -> 0.0026055314 | O22: 0.0021968366 | P22: ='日別報廢率總表 '!O21/'日別報廢率總表 '!M21 -> 0.0032068891 | R22: 0.286 | S22: =AVERAGE(R22:R28) -> 0.286 | U22: 0.92 | V22: =AVERAGE(U22:U28) -> 0.93714286
D23: 46253 | E23: 三 | F23: 113.1 | I23: =F23/$C$1 -> 0.89336493 | L23: ='日別報廢率總表 '!C22/'日別報廢率總表 '!B22 -> 0.0039910896 | O23: 0.0045338153 | R23: 0.286 | U23: 0.92
D24: 46254 | E24: 四 | F24: 111.6 | I24: =F24/$C$1 -> 0.88151659 | L24: ='日別報廢率總表 '!C23/'日別報廢率總表 '!B23 -> 0.0036775503 | O24: 0.0047135269 | R24: 0.286 | U24: 0.92
D25: 46255 | E25: 五 | F25: 113.3 | I25: =F25/$C$1 -> 0.89494471 | L25: ='日別報廢率總表 '!C24/'日別報廢率總表 '!B24 -> 0.0028317136 | O25: 0.0034401699 | R25: 0.286 | U25: 0.95
D26: 46256 | E26: 六 | F26: 113.6 | I26: =F26/$C$1 -> 0.89731438 | L26: ='日別報廢率總表 '!C25/'日別報廢率總表 '!B25 -> 0.0012580162 | O26: 0.0018664541 | R26: 0.286 | U26: 0.95
D27: 46257 | E27: 日 | F27: 115.4 | I27: =F27/$C$1 -> 0.91153239 | L27: ='日別報廢率總表 '!C26/'日別報廢率總表 '!B26 -> 0.0022477336 | O27: 0.0029283278 | R27: 0.286 | U27: 0.95
D28: 46258 | E28: 一 | F28: 117.1 | I28: =F28/$C$1 -> 0.92496051 | L28: ='日別報廢率總表 '!C27/'日別報廢率總表 '!B27 -> 0.0024726602 | O28: 0.0028921044 | R28: 0.286 | U28: 0.95
B29: 46267 | D29: 46259 | E29: 二 | G29: =AVERAGE(F29:F35) -> #DIV/0! | I29: =F29/$C$1 -> 0 | J29: =AVERAGE(I29:I35) -> 0 | L29: ='日別報廢率總表 '!C28/'日別報廢率總表 '!B28 -> #DIV/0! | M29: ='日別報廢率總表 '!N28/'日別報廢率總表 '!M28 -> #DIV/0! | O29: ='日別報廢率總表 '!E28/'日別報廢率總表 '!B28 -> #DIV/0! | P29: ='日別報廢率總表 '!O28/'日別報廢率總表 '!M28 -> #DIV/0! | S29: =AVERAGE(R29:R35) -> #DIV/0! | V29: =AVERAGE(U29:U35) -> #DIV/0!
D30: 46260 | E30: 三 | I30: =F30/$C$1 -> 0 | L30: ='日別報廢率總表 '!C29/'日別報廢率總表 '!B29 -> #DIV/0! | O30: ='日別報廢率總表 '!E29/'日別報廢率總表 '!B29 -> #DIV/0!
D31: 46261 | E31: 四 | I31: =F31/$C$1 -> 0 | L31: ='日別報廢率總表 '!C30/'日別報廢率總表 '!B30 -> #DIV/0! | O31: ='日別報廢率總表 '!E30/'日別報廢率總表 '!B30 -> #DIV/0!
D32: 46262 | E32: 五 | I32: =F32/$C$1 -> 0 | L32: ='日別報廢率總表 '!C31/'日別報廢率總表 '!B31 -> #DIV/0! | O32: ='日別報廢率總表 '!E31/'日別報廢率總表 '!B31 -> #DIV/0!
D33: 46263 | E33: 六 | I33: =F33/$C$1 -> 0 | L33: ='日別報廢率總表 '!C32/'日別報廢率總表 '!B32 -> #DIV/0! | O33: ='日別報廢率總表 '!E32/'日別報廢率總表 '!B32 -> #DIV/0!
D34: 46264 | E34: 日 | I34: =F34/$C$1 -> 0 | L34: ='日別報廢率總表 '!C33/'日別報廢率總表 '!B33 -> #DIV/0! | O34: ='日別報廢率總表 '!E33/'日別報廢率總表 '!B33 -> #DIV/0!
D35: 46265 | E35: 一 | I35: =F35/$C$1 -> 0 | L35: ='日別報廢率總表 '!C34/'日別報廢率總表 '!B34 -> #DIV/0! | O35: ='日別報廢率總表 '!E34/'日別報廢率總表 '!B34 -> #DIV/0!
D37: 46235 | E37: 六 | F37: 112.8 | I37: =F37/$C$1 -> 0.89099526 | L37: ='日別報廢率總表 '!C39/'日別報廢率總表 '!B39 -> 0.0024457273 | O37: 0.004845583 | R37: 0.2857 | U37: 0.85
D38: 46236 | E38: 日 | F38: 115.2 | I38: =F38/$C$1 -> 0.90995261 | L38: ='日別報廢率總表 '!C40/'日別報廢率總表 '!B40 -> 0.0036772843 | O38: 0.005668299 | R38: 0.2857 | U38: 0.85
D39: 46237 | E39: 一 | F39: 114.1 | I39: =F39/$C$1 -> 0.90126382 | L39: ='日別報廢率總表 '!C41/'日別報廢率總表 '!B41 -> 0.003910229 | O39: 0.0063294354 | R39: 0.2857 | U39: 0.85
H45: 0.91568164
H46: 0.90622537
...

Sheet （３）業績構成比
B2: （3）業績構成比
B3: 資料繳交日 | C3: 月份 | D3: 日期 | F3: 營業額 | I3: 品類業績
I4: 熱食義麵 | K4: 季節調理麵 | M4: 微波小吃
F5: 日 | G5: 週累積 | H5: 月累積 | I5: 一配 | K5: 一配 | M5: 一配
I6: 業績(元) | J6: 比例(%) | K6: 業績(元) | L6: 比例(%) | M6: 業績(元) | N6: 比例(%)
C7: 八 | D7: 46235 | E7: 六 | F7: =I7+M7 -> 2319312.8 | G7: =SUM(F7:F9) -> 8367994 | H7: =SUM(F7:F37) -> 61106542 | I7: 2091826.2 | J7: =I7/F7 -> 0.90191641 | L7: =K7/F7 -> 0 | M7: 227486.52 | N7: =M7/F7 -> 0.09808359
D8: 46236 | E8: 日 | F8: =I8+M8 -> 3023076.5 | I8: 2735272.3 | J8: =I8/F8 -> 0.90479758 | L8: =K8/F8 -> 0 | M8: 287804.21 | N8: =M8/F8 -> 0.095202422
D9: 46237 | E9: 一 | F9: =I9+M9 -> 3025604.7 | I9: 2714410.7 | J9: =I9/F9 -> 0.89714653 | L9: =K9/F9 -> 0 | M9: 311193.94 | N9: =M9/F9 -> 0.10285347
B10: 46246 | D10: 46238 | E10: 二 | F10: =I10+M10 -> 2744836.5 | G10: =SUM(F10:F16) -> 18008328 | I10: 2463511.7 | J10: =I10/F10 -> 0.89750762 | L10: =K10/F10 -> 0 | M10: 281324.84 | N10: =M10/F10 -> 0.10249238
D11: 46239 | E11: 三 | F11: =I11+M11 -> 2568942.7 | I11: 2307967.3 | J11: =I11/F11 -> 0.89841136 | L11: =K11/F11 -> 0 | M11: 260975.39 | N11: =M11/F11 -> 0.10158864
D12: 46240 | E12: 四 | F12: =I12+M12 -> 2531185.4 | I12: 2284902.3 | J12: =I12/F12 -> 0.90270049 | L12: =K12/F12 -> 0 | M12: 246283.09 | N12: =M12/F12 -> 0.097299506
D13: 46241 | E13: 五 | F13: =I13+M13 -> 1978394.4 | I13: 1773495.2 | J13: =I13/F13 -> 0.89643155 | L13: =K13/F13 -> 0 | M13: 204899.24 | N13: =M13/F13 -> 0.10356845
D14: 46242 | E14: 六 | F14: =I14+M14 -> 2143592.4 | I14: 1929960.9 | J14: =I14/F14 -> 0.90033946 | L14: =K14/F14 -> 0 | M14: 213631.58 | N14: =M14/F14 -> 0.09966054
D15: 46243 | E15: 日 | F15: =I15+M15 -> 3005927.6 | I15: 2737188.7 | J15: =I15/F15 -> 0.91059701 | L15: =K15/F15 -> 0 | M15: 268738.92 | N15: =M15/F15 -> 0.08940299
D16: 46244 | E16: 一 | F16: =I16+M16 -> 3035448.5 | I16: 2742937.9 | J16: =I16/F16 -> 0.90363514 | L16: =K16/F16 -> 0 | M16: 292510.58 | N16: =M16/F16 -> 0.096364863
B17: 46253 | D17: 46245 | E17: 二 | F17: =I17+M17 -> 2592646.8 | G17: =SUM(F17:F23) -> 17686446 | I17: 2329329.9 | J17: =I17/F17 -> 0.89843705 | L17: =K17/F17 -> 0 | M17: 263316.86 | N17: =M17/F17 -> 0.10156295
D18: 46246 | E18: 三 | F18: =I18+M18 -> 2595086.9 | I18: 2353355.1 | J18: =I18/F18 -> 0.90685019 | L18: =K18/F18 -> 0 | M18: 241731.85 | N18: =M18/F18 -> 0.093149809
D19: 46247 | E19: 四 | F19: =I19+M19 -> 2476906 | I19: 2237648.6 | J19: =I19/F19 -> 0.90340476 | L19: =K19/F19 -> 0 | M19: 239257.33 | N19: =M19/F19 -> 0.096595242
D20: 46248 | E20: 五 | F20: =I20+M20 -> 2004758.6 | I20: 1800007.8 | J20: =I20/F20 -> 0.89786762 | L20: =K20/F20 -> 0 | M20: 204750.76 | N20: =M20/F20 -> 0.10213238
D21: 46249 | E21: 六 | F21: =I21+M21 -> 2180067.2 | I21: 1966830.5 | J21: =I21/F21 -> 0.90218803 | L21: =K21/F21 -> 0 | M21: 213236.67 | N21: =M21/F21 -> 0.097811972
D22: 46250 | E22: 日 | F22: =I22+M22 -> 2865626.4 | I22: 2600705.2 | J22: =I22/F22 -> 0.90755208 | L22: =K22/F22 -> 0 | M22: 264921.19 | N22: =M22/F22 -> 0.092447916
D23: 46251 | E23: 一 | F23: =I23+M23 -> 2971354.7 | I23: 2678154.5 | J23: =I23/F23 -> 0.9013244 | L23: =K23/F23 -> 0 | M23: 293200.19 | N23: =M23/F23 -> 0.098675595
B24: 46260 | D24: 46252 | E24: 二 | F24: =I24+M24 -> 2636829.4 | G24: =SUM(F24:F30) -> 17043774 | I24: 2379314.7 | J24: =I24/F24 -> 0.90233929 | L24: =K24/F24 -> 0 | M24: 257514.62 | N24: =M24/F24 -> 0.097660707
D25: 46253 | E25: 三 | F25: =I25+M25 -> 2408538.3 | I25: 2174896.7 | J25: =I25/F25 -> 0.90299447 | L25: =K25/F25 -> 0 | M25: 233641.54 | N25: =M25/F25 -> 0.097005534
D26: 46254 | E26: 四 | F26: =I26+M26 -> 2319925.4 | I26: 2090343.5 | J26: =I26/F26 -> 0.90103908 | L26: =K26/F26 -> 0 | M26: 229581.96 | N26: =M26/F26 -> 0.098960922
D27: 46255 | E27: 五 | F27: =I27+M27 -> 1831621.7 | I27: 1648415.9 | J27: =I27/F27 -> 0.89997622 | L27: =K27/F27 -> 0 | M27: 183205.72 | N27: =M27/F27 -> 0.10002378
D28: 46256 | E28: 六 | F28: =I28+M28 -> 2037135.9 | I28: 1840339.6 | J28: =I28/F28 -> 0.9033956 | L28: =K28/F28 -> 0 | M28: 196796.3 | N28: =M28/F28 -> 0.096604402
D29: 46257 | E29: 日 | F29: =I29+M29 -> 2878649.5 | I29: 2623445.3 | J29: =I29/F29 -> 0.91134589 | L29: =K29/F29 -> 0 | M29: 255204.12 | N29: =M29/F29 -> 0.088654115
D30: 46258 | E30: 一 | F30: =I30+M30 -> 2931073.8 | I30: 2643413.5 | J30: =I30/F30 -> 0.9018584 | L30: =K30/F30 -> 0 | M30: 287660.26 | N30: =M30/F30 -> 0.098141595
B31: 46267 | D31: 46259 | E31: 二 | F31: =I31+M31 -> 0 | G31: =SUM(F31:F37) -> 0 | J31: =I31/F31 -> #DIV/0! | L31: =K31/F31 -> #DIV/0! | N31: =M31/F31 -> #DIV/0!
D32: 46260 | E32: 三 | F32: =I32+M32 -> 0 | J32: =I32/F32 -> #DIV/0! | L32: =K32/F32 -> #DIV/0! | N32: =M32/F32 -> #DIV/0!
D33: 46261 | E33: 四 | F33: =I33+M33 -> 0 | J33: =I33/F33 -> #DIV/0! | L33: =K33/F33 -> #DIV/0! | N33: =M33/F33 -> #DIV/0!
D34: 46262 | E34: 五 | F34: =I34+M34 -> 0 | J34: =I34/F34 -> #DIV/0! | L34: =K34/F34 -> #DIV/0! | N34: =M34/F34 -> #DIV/0!
D35: 46263 | E35: 六 | F35: =I35+M35 -> 0 | J35: =I35/F35 -> #DIV/0! | L35: =K35/F35 -> #DIV/0! | N35: =M35/F35 -> #DIV/0!
D36: 46264 | E36: 日 | F36: =I36+M36 -> 0 | J36: =I36/F36 -> #DIV/0! | L36: =K36/F36 -> #DIV/0! | N36: =M36/F36 -> #DIV/0!
D37: 46265 | E37: 一 | F37: =I37+M37 -> 0 | J37: =I37/F37 -> #DIV/0! | L37: =K37/F37 -> #DIV/0! | N37: =M37/F37 -> #DIV/0!
F40: =I40+M40 -> 3411506.4 | I40: 3076682.5 | J40: =I40/F40 -> 0.90185452 | M40: 334823.93 | N40: =M40/F40 -> 0.098145478
D42: 46235 | E42: 六 | F42: =I42+M42 -> 2319312.8 | I42: 2091826.2 | J42: =I42/F42 -> 0.90191641 | M42: 227486.52 | N42: =M42/F42 -> 0.09808359
D43: 46236 | E43: 日 | F43: =I43+M43 -> 3023076.5 | I43: 2735272.3 | J43: =I43/F43 -> 0.90479758 | M43: 287804.21 | N43: =M43/F43 -> 0.095202422
D44: 46237 | E44: 一 | F44: =I44+M44 -> 3025604.7 | I44: 2714410.7 | J44: =I44/F44 -> 0.89714653 | M44: 311193.94 | N44: =M44/F44 -> 0.10285347

Sheet （４）訂單數量構成比
B2: （4）訂單數量構成比
B3: 資料繳交日 | C3: 月份 | D3: 日期 | F3: 訂單量 | I3: 品類訂單量
I4: 熱食義麵 | K4: 季節調理麵 | M4: 微波小吃
F5: 日 | G5: 週累積 | H5: 月累積 | I5: 一配 | K5: 一配 | M5: 一配
I6: 訂單數 | J6: 比例(%) | K6: 訂單數 | L6: 比例(%) | M6: 訂單數 | N6: 比例(%)
C7: 八 | D7: 46235 | E7: 六 | F7: =SUM(I7,K7,M7) -> 50157 | G7: =SUM(F7:F12) -> 351191 | H7: =SUM(F7:F36) -> 1320645 | I7: 41924 | J7: =I7/F7 -> 0.83585541 | L7: =K7/F7 -> 0 | M7: 8233 | N7: =M7/F7 -> 0.16414459
D8: 46236 | E8: 日 | F8: =SUM(I8,K8,M8) -> 65177 | I8: 54753 | J8: =I8/F8 -> 0.84006628 | L8: =K8/F8 -> 0 | M8: 10424 | N8: =M8/F8 -> 0.15993372
D9: 46237 | E9: 一 | F9: =SUM(I9,K9,M9) -> 65514 | I9: 54248 | J9: =I9/F9 -> 0.82803676 | L9: =K9/F9 -> 0 | M9: 11266 | N9: =M9/F9 -> 0.17196324
B10: 46246 | D10: 46238 | E10: 二 | F10: =SUM(I10,K10,M10) -> 60136 | G10: =SUM(F10:F16) -> 389510 | I10: 49950 | J10: =I10/F10 -> 0.83061727 | L10: =K10/F10 -> 0 | M10: 10186 | N10: =M10/F10 -> 0.16938273
D11: 46239 | E11: 三 | F11: =SUM(I11,K11,M11) -> 55976 | I11: 46533 | J11: =I11/F11 -> 0.8313027 | L11: =K11/F11 -> 0 | M11: 9443 | N11: =M11/F11 -> 0.1686973
D12: 46240 | E12: 四 | F12: =SUM(I12,K12,M12) -> 54231 | I12: 45319 | J12: =I12/F12 -> 0.83566595 | L12: =K12/F12 -> 0 | M12: 8912 | N12: =M12/F12 -> 0.16433405
D13: 46241 | E13: 五 | F13: =SUM(I13,K13,M13) -> 43046 | I13: 35639 | J13: =I13/F13 -> 0.82792826 | L13: =K13/F13 -> 0 | M13: 7407 | N13: =M13/F13 -> 0.17207174
D14: 46242 | E14: 六 | F14: =SUM(I14,K14,M14) -> 46671 | I14: 38941 | J14: =I14/F14 -> 0.83437252 | L14: =K14/F14 -> 0 | M14: 7730 | N14: =M14/F14 -> 0.16562748
D15: 46243 | E15: 日 | F15: =SUM(I15,K15,M15) -> 64248 | I15: 54516 | J15: =I15/F15 -> 0.84852447 | L15: =K15/F15 -> 0 | M15: 9732 | N15: =M15/F15 -> 0.15147553
D16: 46244 | E16: 一 | F16: =SUM(I16,K16,M16) -> 65202 | I16: 54614 | J16: =I16/F16 -> 0.83761234 | L16: =K16/F16 -> 0 | M16: 10588 | N16: =M16/F16 -> 0.16238766
B17: 46253 | D17: 46245 | E17: 二 | F17: =SUM(I17,K17,M17) -> 56162 | G17: =SUM(F17:F23) -> 382077 | I17: 46631 | J17: =I17/F17 -> 0.83029451 | L17: =K17/F17 -> 0 | M17: 9531 | N17: =M17/F17 -> 0.16970549
D18: 46246 | E18: 三 | F18: =SUM(I18,K18,M18) -> 55867 | I18: 47121 | J18: =I18/F18 -> 0.84344962 | L18: =K18/F18 -> 0 | M18: 8746 | N18: =M18/F18 -> 0.15655038
D19: 46247 | E19: 四 | F19: =SUM(I19,K19,M19) -> 53441 | I19: 44789 | J19: =I19/F19 -> 0.83810183 | L19: =K19/F19 -> 0 | M19: 8652 | N19: =M19/F19 -> 0.16189817
D20: 46248 | E20: 五 | F20: =SUM(I20,K20,M20) -> 43480 | I20: 36076 | J20: =I20/F20 -> 0.82971481 | L20: =K20/F20 -> 0 | M20: 7404 | N20: =M20/F20 -> 0.17028519
D21: 46249 | E21: 六 | F21: =SUM(I21,K21,M21) -> 47216 | I21: 39504 | J21: =I21/F21 -> 0.83666554 | L21: =K21/F21 -> 0 | M21: 7712 | N21: =M21/F21 -> 0.16333446
D22: 46250 | E22: 日 | F22: =SUM(I22,K22,M22) -> 61768 | I22: 52177 | J22: =I22/F22 -> 0.84472542 | L22: =K22/F22 -> 0 | M22: 9591 | N22: =M22/F22 -> 0.15527458
D23: 46251 | E23: 一 | F23: =SUM(I23,K23,M23) -> 64143 | I23: 53535 | J23: =I23/F23 -> 0.83461952 | L23: =K23/F23 -> 0 | M23: 10608 | N23: =M23/F23 -> 0.16538048
B24: 46260 | D24: 46252 | E24: 二 | F24: =SUM(I24,K24,M24) -> 56950 | G24: =SUM(F24:F30) -> 368210 | I24: 47634 | J24: =I24/F24 -> 0.83641791 | L24: =K24/F24 -> 0 | M24: 9316 | N24: =M24/F24 -> 0.16358209
D25: 46253 | E25: 三 | F25: =SUM(I25,K25,M25) -> 51994 | I25: 43540 | J25: =I25/F25 -> 0.83740432 | L25: =K25/F25 -> 0 | M25: 8454 | N25: =M25/F25 -> 0.16259568
D26: 46254 | E26: 四 | F26: =SUM(I26,K26,M26) -> 50258 | I26: 41952 | J26: =I26/F26 -> 0.83473278 | L26: =K26/F26 -> 0 | M26: 8306 | N26: =M26/F26 -> 0.16526722
D27: 46255 | E27: 五 | F27: =SUM(I27,K27,M27) -> 39573 | I27: 32951 | J27: =I27/F27 -> 0.83266368 | L27: =K27/F27 -> 0 | M27: 6622 | N27: =M27/F27 -> 0.16733632
D28: 46256 | E28: 六 | F28: =SUM(I28,K28,M28) -> 44045 | I28: 36927 | J28: =I28/F28 -> 0.83839255 | L28: =K28/F28 -> 0 | M28: 7118 | N28: =M28/F28 -> 0.16160745
D29: 46257 | E29: 日 | F29: =SUM(I29,K29,M29) -> 62066 | I29: 52821 | J29: =I29/F29 -> 0.85104566 | L29: =K29/F29 -> 0 | M29: 9245 | N29: =M29/F29 -> 0.14895434
D30: 46258 | E30: 一 | F30: =SUM(I30,K30,M30) -> 63324 | I30: 52916 | J30: =I30/F30 -> 0.83563894 | L30: =K30/F30 -> 0 | M30: 10408 | N30: =M30/F30 -> 0.16436106
B31: 46267 | D31: 46259 | E31: 二 | F31: =SUM(I31,K31,M31) -> 0 | G31: =SUM(F31:F37) -> 0 | J31: =I31/F31 -> #DIV/0! | L31: =K31/F31 -> #DIV/0! | N31: =M31/F31 -> #DIV/0!
D32: 46260 | E32: 三 | F32: =SUM(I32,K32,M32) -> 0 | J32: =I32/F32 -> #DIV/0! | L32: =K32/F32 -> #DIV/0! | N32: =M32/F32 -> #DIV/0!
D33: 46261 | E33: 四 | F33: =SUM(I33,K33,M33) -> 0 | J33: =I33/F33 -> #DIV/0! | L33: =K33/F33 -> #DIV/0! | N33: =M33/F33 -> #DIV/0!
D34: 46262 | E34: 五 | F34: =SUM(I34,K34,M34) -> 0 | J34: =I34/F34 -> #DIV/0! | L34: =K34/F34 -> #DIV/0! | N34: =M34/F34 -> #DIV/0!
D35: 46263 | E35: 六 | F35: =SUM(I35,K35,M35) -> 0 | J35: =I35/F35 -> #DIV/0! | L35: =K35/F35 -> #DIV/0! | N35: =M35/F35 -> #DIV/0!
D36: 46264 | E36: 日 | F36: =SUM(I36,K36,M36) -> 0 | J36: =I36/F36 -> #DIV/0! | L36: =K36/F36 -> #DIV/0! | N36: =M36/F36 -> #DIV/0!
D37: 46265 | E37: 一 | F37: =SUM(I37,K37,M37) -> 0 | J37: =I37/F37 -> #DIV/0! | N37: =M37/F37 -> #DIV/0!

Sheet （５-1）品群別人時生產性（熱食義麵）
B1: 月平均人時性 | C1: =AVERAGE(L7,L30,L53,L76,L99,L122) -> 111.26856
B2: 產線配置圖－每週更新 | N2: 資料繳交 | O2: 日期 | AJ2: 46235 | AO2: 46236 | AT2: 46237
P3: 二 | U3: 三 | Z3: 四 | AE3: 五 | AJ3: 六 | AO3: 日 | AT3: 一
B4: 品群 | C4: 商品名稱 | E4: 計畫 | H4: 平均人時性 | I4: 實績 | L4: 平均人時性 | M4: 排名 | O4: 日報 | P4: 實際 | T4: 平均人時性 | U4: 實際 | Y4: 平均人時性 | Z4: 實際 | AD4: 平均人時性 | AE4: 實際 | AI4: 平均人時性 | AJ4: 實際 | AN4: 平均人時性 | AO4: 實際 | AS4: 平均人時性 | AT4: 實際 | AX4: 平均人時性
E5: 產線配置圖 | I5: 產線配置圖 | P5: 生產實績 | U5: 生產實績 | Z5: 生產實績 | AE5: 生產實績 | AJ5: 生產實績 | AO5: 生產實績 | AT5: 生產實績
E6: 人數 | F6: 產能／時 | G6: 人時性 | I6: 人數 | J6: 產能／時 | K6: 人時性 | P6: 人數 | Q6: 產能／時 | R6: 人時性 | S6: 排名 | U6: 人數 | V6: 產能／時 | W6: 人時性 | X6: 排名 | Z6: 人數 | AA6: 產能／時 | AB6: 人時性 | AC6: 排名 | AE6: 人數 | AF6: 產能／時 | AG6: 人時性 | AH6: 排名 | AJ6: 人數 | AK6: 產能／時 | AL6: 人時性 | AM6: 排名 | AO6: 人數 | AP6: 產能／時 | AQ6: 人時性 | AR6: 排名 | AT6: 人數 | AU6: 產能／時 | AV6: 人時性 | AW6: 排名
B7: 熱食義麵 | C7: 1 | D7: 義式蕃茄起司義大利麵 | E7: =VLOOKUP(D7,'07產線配置圖'!$A$2:$C$25,2,0) -> 12 | F7: =VLOOKUP(D7,'07產線配置圖'!$A$2:$C$25,3,0) -> 2250 | G7: =F7/E7 -> 187.5 | H7: =AVERAGE(G7:G24) -> 125.02312 | I7: =AVERAGE(P7,U7,Z7,AE7,AJ7,AO7,AT7) -> 12 | J7: =AVERAGE(Q7,V7,AA7,AF7,AK7,AP7,AU7) -> 2091 | K7: =J7/I7 -> 174.25 | L7: =IFERROR(AVERAGE(K7:K24),"-") -> 110.95107 | M7: =RANK(K7,$K$7:$K$24) -> 1 | R7: =Q7/P7 -> #DIV/0! | S7: =RANK(R7,$R$7:$R$24) -> #DIV/0! | T7: =AVERAGE(R7:R24) -> #DIV/0! | W7: =V7/U7 -> #DIV/0! | X7: =RANK(W7,$W$7:$W$24) -> #DIV/0! | Y7: =AVERAGE(W7:W24) -> #DIV/0! | AB7: =AA7/Z7 -> #DIV/0! | AC7: =RANK(AB7,$AB$7:$AB$24) -> #DIV/0! | AD7: =AVERAGE(AB7:AB24) -> #DIV/0! | AG7: =AF7/AE7 -> #DIV/0! | AH7: =RANK(AG7,$AG$7:$AG$24) -> #DIV/0! | AI7: =AVERAGE(AG7:AG24) -> #DIV/0! | AJ7: 12 | AK7: 2065 | AL7: =AK7/AJ7 -> 172.08333 | AM7: =RANK(AL7,$AL$7:$AL$24) -> 1 | AN7: =AVERAGE(AL7:AL24) -> 109.40634 | AO7: 12 | AP7: 2150 | AQ7: =AP7/AO7 -> 179.16667 | AR7: =RANK(AQ7,$AQ$7:$AQ$24) -> 1 | AS7: =AVERAGE(AQ7:AQ24) -> 112.42245 | AT7: 12 | AU7: 2058 | AV7: =AU7/AT7 -> 171.5 | AW7: =RANK(AV7,$AV$7:$AV$24) -> 1 | AX7: =AVERAGE(AV7:AV24) -> 111.02451
C8: 2 | D8: 奶油培根義大利麵 | E8: =VLOOKUP(D8,'07產線配置圖'!$A$2:$C$25,2,0) -> 15 | F8: =VLOOKUP(D8,'07產線配置圖'!$A$2:$C$25,3,0) -> 2250 | G8: =F8/E8 -> 150 | I8: =AVERAGE(P8,U8,Z8,AE8,AJ8,AO8,AT8) -> 15 | J8: =AVERAGE(Q8,V8,AA8,AF8,AK8,AP8,AU8) -> 2107.6667 | K8: =J8/I8 -> 140.51111 | M8: =RANK(K8,$K$7:$K$24) -> 4 | R8: =Q8/P8 -> #DIV/0! | S8: =RANK(R8,$R$7:$R$24) -> #DIV/0! | W8: =V8/U8 -> #DIV/0! | X8: =RANK(W8,$W$7:$W$24) -> #DIV/0! | AB8: =AA8/Z8 -> #DIV/0! | AC8: =RANK(AB8,$AB$7:$AB$24) -> #DIV/0! | AG8: =AF8/AE8 -> #DIV/0! | AH8: =RANK(AG8,$AG$7:$AG$24) -> #DIV/0! | AJ8: 15 | AK8: 2072 | AL8: =AK8/AJ8 -> 138.13333 | AM8: =RANK(AL8,$AL$7:$AL$24) -> 4 | AO8: 15 | AP8: 2120 | AQ8: =AP8/AO8 -> 141.33333 | AR8: =RANK(AQ8,$AQ$7:$AQ$24) -> 4 | AT8: 15 | AU8: 2131 | AV8: =AU8/AT8 -> 142.06667 | AW8: =RANK(AV8,$AV$7:$AV$24) -> 5
C9: 3 | D9: 白酒清炒鮮蛤義大利麵 | E9: =VLOOKUP(D9,'07產線配置圖'!$A$2:$C$25,2,0) -> 15 | F9: =VLOOKUP(D9,'07產線配置圖'!$A$2:$C$25,3,0) -> 2250 | G9: =F9/E9 -> 150 | I9: =AVERAGE(P9,U9,Z9,AE9,AJ9,AO9,AT9) -> 15 | J9: =AVERAGE(Q9,V9,AA9,AF9,AK9,AP9,AU9) -> 2107.6667 | K9: =J9/I9 -> 140.51111 | M9: =RANK(K9,$K$7:$K$24) -> 4 | R9: =Q9/P9 -> #DIV/0! | S9: =RANK(R9,$R$7:$R$24) -> #DIV/0! | W9: =V9/U9 -> #DIV/0! | X9: =RANK(W9,$W$7:$W$24) -> #DIV/0! | AB9: =AA9/Z9 -> #DIV/0! | AC9: =RANK(AB9,$AB$7:$AB$24) -> #DIV/0! | AG9: =AF9/AE9 -> #DIV/0! | AH9: =RANK(AG9,$AG$7:$AG$24) -> #DIV/0! | AJ9: 15 | AK9: 2044 | AL9: =AK9/AJ9 -> 136.26667 | AM9: =RANK(AL9,$AL$7:$AL$24) -> 5 | AO9: 15 | AP9: 2109 | AQ9: =AP9/AO9 -> 140.6 | AR9: =RANK(AQ9,$AQ$7:$AQ$24) -> 5 | AT9: 15 | AU9: 2170 | AV9: =AU9/AT9 -> 144.66667 | AW9: =RANK(AV9,$AV$7:$AV$24) -> 4
C10: 4 | D10: 焗烤起司雙饗筆尖麵 | E10: =VLOOKUP(D10,'07產線配置圖'!$A$2:$C$25,2,0) -> 16 | F10: =VLOOKUP(D10,'07產線配置圖'!$A$2:$C$25,3,0) -> 1800 | G10: =F10/E10 -> 112.5 | I10: =AVERAGE(P10,U10,Z10,AE10,AJ10,AO10,AT10) -> 16 | J10: =AVERAGE(Q10,V10,AA10,AF10,AK10,AP10,AU10) -> 1556 | K10: =J10/I10 -> 97.25 | M10: =RANK(K10,$K$7:$K$24) -> 7 | R10: =Q10/P10 -> #DIV/0! | S10: =RANK(R10,$R$7:$R$24) -> #DIV/0! | W10: =V10/U10 -> #DIV/0! | X10: =RANK(W10,$W$7:$W$24) -> #DIV/0! | AB10: =AA10/Z10 -> #DIV/0! | AC10: =RANK(AB10,$AB$7:$AB$24) -> #DIV/0! | AG10: =AF10/AE10 -> #DIV/0! | AH10: =RANK(AG10,$AG$7:$AG$24) -> #DIV/0! | AJ10: 16 | AK10: 1565 | AL10: =AK10/AJ10 -> 97.8125 | AM10: =RANK(AL10,$AL$7:$AL$24) -> 7 | AO10: 16 | AP10: 1543 | AQ10: =AP10/AO10 -> 96.4375 | AR10: =RANK(AQ10,$AQ$7:$AQ$24) -> 7 | AT10: 16 | AU10: 1560 | AV10: =AU10/AT10 -> 97.5 | AW10: =RANK(AV10,$AV$7:$AV$24) -> 8
C11: 5 | D11: 青醬蛤蜊義大利麵 | E11: =VLOOKUP(D11,'07產線配置圖'!$A$2:$C$25,2,0) -> 13 | F11: =VLOOKUP(D11,'07產線配置圖'!$A$2:$C$25,3,0) -> 2250 | G11: =F11/E11 -> 173.07692 | I11: =AVERAGE(P11,U11,Z11,AE11,AJ11,AO11,AT11) -> 13 | J11: =AVERAGE(Q11,V11,AA11,AF11,AK11,AP11,AU11) -> 2154.6667 | K11: =J11/I11 -> 165.74359 | M11: =RANK(K11,$K$7:$K$24) -> 2 | R11: =Q11/P11 -> #DIV/0! | S11: =RANK(R11,$R$7:$R$24) -> #DIV/0! | W11: =V11/U11 -> #DIV/0! | X11: =RANK(W11,$W$7:$W$24) -> #DIV/0! | AB11: =AA11/Z11 -> #DIV/0! | AC11: =RANK(AB11,$AB$7:$AB$24) -> #DIV/0! | AG11: =AF11/AE11 -> #DIV/0! | AH11: =RANK(AG11,$AG$7:$AG$24) -> #DIV/0! | AJ11: 13 | AK11: 2109 | AL11: =AK11/AJ11 -> 162.23077 | AM11: =RANK(AL11,$AL$7:$AL$24) -> 2 | AO11: 13 | AP11: 2202 | AQ11: =AP11/AO11 -> 169.38462 | AR11: =RANK(AQ11,$AQ$7:$AQ$24) -> 2 | AT11: 13 | AU11: 2153 | AV11: =AU11/AT11 -> 165.61538 | AW11: =RANK(AV11,$AV$7:$AV$24) -> 2
C12: 6 | D12: 青花椒麻雞肉拌麵 | E12: =VLOOKUP(D12,'07產線配置圖'!$A$2:$C$25,2,0) -> 16 | F12: =VLOOKUP(D12,'07產線配置圖'!$A$2:$C$25,3,0) -> 1714 | G12: =F12/E12 -> 107.125 | I12: =AVERAGE(P12,U12,Z12,AE12,AJ12,AO12,AT12) -> 16 | J12: =AVERAGE(Q12,V12,AA12,AF12,AK12,AP12,AU12) -> 1546.3333 | K12: =J12/I12 -> 96.645833 | M12: =RANK(K12,$K$7:$K$24) -> 8 | R12: =Q12/P12 -> #DIV/0! | S12: =RANK(R12,$R$7:$R$24) -> #DIV/0! | W12: =V12/U12 -> #DIV/0! | X12: =RANK(W12,$W$7:$W$24) -> #DIV/0! | AB12: =AA12/Z12 -> #DIV/0! | AC12: =RANK(AB12,$AB$7:$AB$24) -> #DIV/0! | AG12: =AF12/AE12 -> #DIV/0! | AH12: =RANK(AG12,$AG$7:$AG$24) -> #DIV/0! | AJ12: 16 | AK12: 1551 | AL12: =AK12/AJ12 -> 96.9375 | AM12: =RANK(AL12,$AL$7:$AL$24) -> 8 | AO12: 16 | AP12: 1487 | AQ12: =AP12/AO12 -> 92.9375 | AR12: =RANK(AQ12,$AQ$7:$AQ$24) -> 10 | AT12: 16 | AU12: 1601 | AV12: =AU12/AT12 -> 100.0625 | AW12: =RANK(AV12,$AV$7:$AV$24) -> 7
C13: 7 | D13: 沙茶豬肉炒麵 | E13: =VLOOKUP(D13,'07產線配置圖'!$A$2:$C$25,2,0) -> 17 | F13: =VLOOKUP(D13,'07產線配置圖'!$A$2:$C$25,3,0) -> 1800 | G13: =F13/E13 -> 105.88235 | I13: =AVERAGE(P13,U13,Z13,AE13,AJ13,AO13,AT13) -> 17 | J13: =AVERAGE(Q13,V13,AA13,AF13,AK13,AP13,AU13) -> 1607.3333 | K13: =J13/I13 -> 94.54902 | M13: =RANK(K13,$K$7:$K$24) -> 9 | R13: =Q13/P13 -> #DIV/0! | S13: =RANK(R13,$R$7:$R$24) -> #DIV/0! | W13: =V13/U13 -> #DIV/0! | X13: =RANK(W13,$W$7:$W$24) -> #DIV/0! | AB13: =AA13/Z13 -> #DIV/0! | AC13: =RANK(AB13,$AB$7:$AB$24) -> #DIV/0! | AG13: =AF13/AE13 -> #DIV/0! | AH13: =RANK(AG13,$AG$7:$AG$24) -> #DIV/0! | AJ13: 17 | AK13: 1637 | AL13: =AK13/AJ13 -> 96.294118 | AM13: =RANK(AL13,$AL$7:$AL$24) -> 9 | AO13: 17 | AP13: 1637 | AQ13: =AP13/AO13 -> 96.294118 | AR13: =RANK(AQ13,$AQ$7:$AQ$24) -> 8 | AT13: 17 | AU13: 1548 | AV13: =AU13/AT13 -> 91.058824 | AW13: =RANK(AV13,$AV$7:$AV$24) -> 10
C14: 8 | D14: 府城鹽水意麵 | E14: =VLOOKUP(D14,'07產線配置圖'!$A$2:$C$25,2,0) -> 18 | F14: =VLOOKUP(D14,'07產線配置圖'!$A$2:$C$25,3,0) -> 1636 | G14: =F14/E14 -> 90.888889 | I14: =AVERAGE(P14,U14,Z14,AE14,AJ14,AO14,AT14) -> 17.333333 | J14: =AVERAGE(Q14,V14,AA14,AF14,AK14,AP14,AU14) -> 1377 | K14: =J14/I14 -> 79.442308 | M14: =RANK(K14,$K$7:$K$24) -> 16 | R14: =Q14/P14 -> #DIV/0! | S14: =RANK(R14,$R$7:$R$24) -> #DIV/0! | W14: =V14/U14 -> #DIV/0! | X14: =RANK(W14,$W$7:$W$24) -> #DIV/0! | AB14: =AA14/Z14 -> #DIV/0! | AC14: =RANK(AB14,$AB$7:$AB$24) -> #DIV/0! | AG14: =AF14/AE14 -> #DIV/0! | AH14: =RANK(AG14,$AG$7:$AG$24) -> #DIV/0! | AJ14: 18 | AK14: 1272 | AL14: =AK14/AJ14 -> 70.666667 | AM14: =RANK(AL14,$AL$7:$AL$24) -> 16 | AO14: 18 | AP14: 1498 | AQ14: =AP14/AO14 -> 83.222222 | AR14: =RANK(AQ14,$AQ$7:$AQ$24) -> 13 | AT14: 16 | AU14: 1361 | AV14: =AU14/AT14 -> 85.0625 | AW14: =RANK(AV14,$AV$7:$AV$24) -> 13
C15: 9 | D15: 蒜香奶油蝦蝦義大利麵-手 | E15: =VLOOKUP(D15,'07產線配置圖'!$A$2:$C$25,2,0) -> 17 | F15: =VLOOKUP(D15,'07產線配置圖'!$A$2:$C$25,3,0) -> 1716 | G15: =F15/E15 -> 100.94118 | R15: =Q15/P15 -> #DIV/0! | S15: =RANK(R15,$R$7:$R$24) -> #DIV/0! | W15: =V15/U15 -> #DIV/0! | X15: =RANK(W15,$W$7:$W$24) -> #DIV/0! | AB15: =AA15/Z15 -> #DIV/0! | AC15: =RANK(AB15,$AB$7:$AB$24) -> #DIV/0! | AG15: =AF15/AE15 -> #DIV/0! | AH15: =RANK(AG15,$AG$7:$AG$24) -> #DIV/0!
C16: 10 | D16: 香煎魚排佐檸檬奶油義大利麵 | E16: =VLOOKUP(D16,'07產線配置圖'!$A$2:$C$25,2,0) -> 13 | F16: =VLOOKUP(D16,'07產線配置圖'!$A$2:$C$25,3,0) -> 2250 | G16: =F16/E16 -> 173.07692 | I16: =AVERAGE(P16,U16,Z16,AE16,AJ16,AO16,AT16) -> 13 | J16: =AVERAGE(Q16,V16,AA16,AF16,AK16,AP16,AU16) -> 2013.3333 | K16: =J16/I16 -> 154.87179 | M16: =RANK(K16,$K$7:$K$24) -> 3 | R16: =Q16/P16 -> #DIV/0! | S16: =RANK(R16,$R$7:$R$24) -> #DIV/0! | W16: =V16/U16 -> #DIV/0! | X16: =RANK(W16,$W$7:$W$24) -> #DIV/0! | AB16: =AA16/Z16 -> #DIV/0! | AC16: =RANK(AB16,$AB$7:$AB$24) -> #DIV/0! | AG16: =AF16/AE16 -> #DIV/0! | AH16: =RANK(AG16,$AG$7:$AG$24) -> #DIV/0! | AJ16: 13 | AK16: 1922 | AL16: =AK16/AJ16 -> 147.84615 | AM16: =RANK(AL16,$AL$7:$AL$24) -> 3 | AO16: 13 | AP16: 2155 | AQ16: =AP16/AO16 -> 165.76923 | AR16: =RANK(AQ16,$AQ$7:$AQ$24) -> 3 | AT16: 13 | AU16: 1963 | AV16: =AU16/AT16 -> 151 | AW16: =RANK(AV16,$AV$7:$AV$24) -> 3
C17: 11 | D17: 黑松露野菇義大利麵 | E17: 15 | F17: 2250 | G17: 150 | I17: =AVERAGE(P17,U17,Z17,AE17,AJ17,AO17,AT17) -> 16.666667 | J17: =AVERAGE(Q17,V17,AA17,AF17,AK17,AP17,AU17) -> 1420.6667 | K17: =J17/I17 -> 85.24 | M17: =RANK(K17,$K$7:$K$24) -> 12 | R17: =Q17/P17 -> #DIV/0! | S17: =RANK(R17,$R$7:$R$24) -> #DIV/0! | W17: =V17/U17 -> #DIV/0! | X17: =RANK(W17,$W$7:$W$24) -> #DIV/0! | AB17: =AA17/Z17 -> #DIV/0! | AC17: =RANK(AB17,$AB$7:$AB$24) -> #DIV/0! | AG17: =AF17/AE17 -> #DIV/0! | AH17: =RANK(AG17,$AG$7:$AG$24) -> #DIV/0! | AJ17: 16 | AK17: 1380 | AL17: =AK17/AJ17 -> 86.25 | AM17: =RANK(AL17,$AL$7:$AL$24) -> 13 | AO17: 17 | AP17: 1411 | AQ17: =AP17/AO17 -> 83 | AR17: =RANK(AQ17,$AQ$7:$AQ$24) -> 14 | AT17: 17 | AU17: 1471 | AV17: =AU17/AT17 -> 86.529412 | AW17: =RANK(AV17,$AV$7:$AV$24) -> 11
C18: 12 | D18: 奶油鮮蝦明太子細扁麵 | E18: =VLOOKUP(D18,'07產線配置圖'!$A$2:$C$25,2,0) -> 18 | F18: =VLOOKUP(D18,'07產線配置圖'!$A$2:$C$25,3,0) -> 1636 | G18: =F18/E18 -> 90.888889 | I18: =AVERAGE(P18,U18,Z18,AE18,AJ18,AO18,AT18) -> 17.666667 | J18: =AVERAGE(Q18,V18,AA18,AF18,AK18,AP18,AU18) -> 1441.6667 | K18: =J18/I18 -> 81.603774 | M18: =RANK(K18,$K$7:$K$24) -> 14 | R18: =Q18/P18 -> #DIV/0! | S18: =RANK(R18,$R$7:$R$24) -> #DIV/0! | W18: =V18/U18 -> #DIV/0! | X18: =RANK(W18,$W$7:$W$24) -> #DIV/0! | AB18: =AA18/Z18 -> #DIV/0! | AC18: =RANK(AB18,$AB$7:$AB$24) -> #DIV/0! | AG18: =AF18/AE18 -> #DIV/0! | AH18: =RANK(AG18,$AG$7:$AG$24) -> #DIV/0! | AJ18: 18 | AK18: 1419 | AL18: =AK18/AJ18 -> 78.833333 | AM18: =RANK(AL18,$AL$7:$AL$24) -> 15 | AO18: 17 | AP18: 1443 | AQ18: =AP18/AO18 -> 84.882353 | AR18: =RANK(AQ18,$AQ$7:$AQ$24) -> 12 | AT18: 18 | AU18: 1463 | AV18: =AU18/AT18 -> 81.277778 | AW18: =RANK(AV18,$AV$7:$AV$24) -> 15
C19: 13 | D19: 義式蛋蛋青醬鮪魚冷義大利麵 | E19: =VLOOKUP(D19,'07產線配置圖'!$A$2:$C$25,2,0) -> 17 | F19: =VLOOKUP(D19,'07產線配置圖'!$A$2:$C$25,3,0) -> 1636 | G19: =F19/E19 -> 96.235294 | I19: =AVERAGE(P19,U19,Z19,AE19,AJ19,AO19,AT19) -> 16.666667 | J19: =AVERAGE(Q19,V19,AA19,AF19,AK19,AP19,AU19) -> 1467 | K19: =J19/I19 -> 88.02 | M19: =RANK(K19,$K$7:$K$24) -> 11 | R19: =Q19/P19 -> #DIV/0! | S19: =RANK(R19,$R$7:$R$24) -> #DIV/0! | W19: =V19/U19 -> #DIV/0! | X19: =RANK(W19,$W$7:$W$24) -> #DIV/0! | AB19: =AA19/Z19 -> #DIV/0! | AC19: =RANK(AB19,$AB$7:$AB$24) -> #DIV/0! | AG19: =AF19/AE19 -> #DIV/0! | AH19: =RANK(AG19,$AG$7:$AG$24) -> #DIV/0! | AJ19: 17 | AK19: 1547 | AL19: =AK19/AJ19 -> 91 | AM19: =RANK(AL19,$AL$7:$AL$24) -> 10 | AO19: 17 | AP19: 1516 | AQ19: =AP19/AO19 -> 89.176471 | AR19: =RANK(AQ19,$AQ$7:$AQ$24) -> 11 | AT19: 16 | AU19: 1338 | AV19: =AU19/AT19 -> 83.625 | AW19: =RANK(AV19,$AV$7:$AV$24) -> 14
C20: 14 | D20: 蕃茄莎莎海鮮冷義大利麵 | E20: =VLOOKUP(D20,'07產線配置圖'!$A$2:$C$25,2,0) -> 16 | F20: =VLOOKUP(D20,'07產線配置圖'!$A$2:$C$25,3,0) -> 1636 | G20: =F20/E20 -> 102.25 | I20: =AVERAGE(P20,U20,Z20,AE20,AJ20,AO20,AT20) -> 16 | J20: =AVERAGE(Q20,V20,AA20,AF20,AK20,AP20,AU20) -> 1358.3333 | K20: =J20/I20 -> 84.895833 | M20: =RANK(K20,$K$7:$K$24) -> 13 | R20: =Q20/P20 -> #DIV/0! | S20: =RANK(R20,$R$7:$R$24) -> #DIV/0! | W20: =V20/U20 -> #DIV/0! | X20: =RANK(W20,$W$7:$W$24) -> #DIV/0! | AB20: =AA20/Z20 -> #DIV/0! | AC20: =RANK(AB20,$AB$7:$AB$24) -> #DIV/0! | AG20: =AF20/AE20 -> #DIV/0! | AH20: =RANK(AG20,$AG$7:$AG$24) -> #DIV/0! | AJ20: 16 | AK20: 1384 | AL20: =AK20/AJ20 -> 86.5 | AM20: =RANK(AL20,$AL$7:$AL$24) -> 12 | AO20: 16 | AP20: 1311 | AQ20: =AP20/AO20 -> 81.9375 | AR20: =RANK(AQ20,$AQ$7:$AQ$24) -> 16 | AT20: 16 | AU20: 1380 | AV20: =AU20/AT20 -> 86.25 | AW20: =RANK(AV20,$AV$7:$AV$24) -> 12
C21: 15 | D21: 羅馬黑胡椒起司義大利麵 | E21: =VLOOKUP(D21,'07產線配置圖'!$A$2:$C$25,2,0) -> 17 | F21: =VLOOKUP(D21,'07產線配置圖'!$A$2:$C$25,3,0) -> 2250 | G21: =F21/E21 -> 132.35294 | I21: =AVERAGE(P21,U21,Z21,AE21,AJ21,AO21,AT21) -> 17 | J21: =AVERAGE(Q21,V21,AA21,AF21,AK21,AP21,AU21) -> 2025.3333 | K21: =J21/I21 -> 119.13725 | M21: =RANK(K21,$K$7:$K$24) -> 6 | R21: =Q21/P21 -> #DIV/0! | S21: =RANK(R21,$R$7:$R$24) -> #DIV/0! | W21: =V21/U21 -> #DIV/0! | X21: =RANK(W21,$W$7:$W$24) -> #DIV/0! | AB21: =AA21/Z21 -> #DIV/0! | AC21: =RANK(AB21,$AB$7:$AB$24) -> #DIV/0! | AG21: =AF21/AE21 -> #DIV/0! | AH21: =RANK(AG21,$AG$7:$AG$24) -> #DIV/0! | AJ21: 17 | AK21: 2000 | AL21: =AK21/AJ21 -> 117.64706 | AM21: =RANK(AL21,$AL$7:$AL$24) -> 6 | AO21: 17 | AP21: 2025 | AQ21: =AP21/AO21 -> 119.11765 | AR21: =RANK(AQ21,$AQ$7:$AQ$24) -> 6 | AT21: 17 | AU21: 2051 | AV21: =AU21/AT21 -> 120.64706 | AW21: =RANK(AV21,$AV$7:$AV$24) -> 6
C22: 16 | D22: 鱈魚粉紅青醬筆尖麵 | E22: =VLOOKUP(D22,'07產線配置圖'!$A$2:$C$25,2,0) -> 14 | F22: =VLOOKUP(D22,'07產線配置圖'!$A$2:$C$25,3,0) -> 1565 | G22: =F22/E22 -> 111.78571 | I22: =AVERAGE(P22,U22,Z22,AE22,AJ22,AO22,AT22) -> 11 | J22: =AVERAGE(Q22,V22,AA22,AF22,AK22,AP22,AU22) -> 1018 | K22: =J22/I22 -> 92.545455 | M22: =RANK(K22,$K$7:$K$24) -> 10 | R22: =Q22/P22 -> #DIV/0! | S22: =RANK(R22,$R$7:$R$24) -> #DIV/0! | W22: =V22/U22 -> #DIV/0! | X22: =RANK(W22,$W$7:$W$24) -> #DIV/0! | AB22: =AA22/Z22 -> #DIV/0! | AC22: =RANK(AB22,$AB$7:$AB$24) -> #DIV/0! | AG22: =AF22/AE22 -> #DIV/0! | AH22: =RANK(AG22,$AG$7:$AG$24) -> #DIV/0! | AJ22: 9 | AK22: 807 | AL22: =AK22/AJ22 -> 89.666667 | AM22: =RANK(AL22,$AL$7:$AL$24) -> 11 | AO22: 13 | AP22: 1209 | AQ22: =AP22/AO22 -> 93 | AR22: =RANK(AQ22,$AQ$7:$AQ$24) -> 9 | AT22: 11 | AU22: 1038 | AV22: =AU22/AT22 -> 94.363636 | AW22: =RANK(AV22,$AV$7:$AV$24) -> 9
C23: 17 | D23: 金沙豆腐義大利麵 | E23: =VLOOKUP(D23,'07產線配置圖'!$A$2:$C$25,2,0) -> 18 | F23: =VLOOKUP(D23,'07產線配置圖'!$A$2:$C$25,3,0) -> 1636 | G23: =F23/E23 -> 90.888889 | I23: =AVERAGE(P23,U23,Z23,AE23,AJ23,AO23,AT23) -> 18 | J23: =AVERAGE(Q23,V23,AA23,AF23,AK23,AP23,AU23) -> 1440 | K23: =J23/I23 -> 80 | M23: =RANK(K23,$K$7:$K$24) -> 15 | R23: =Q23/P23 -> #DIV/0! | S23: =RANK(R23,$R$7:$R$24) -> #DIV/0! | W23: =V23/U23 -> #DIV/0! | X23: =RANK(W23,$W$7:$W$24) -> #DIV/0! | AB23: =AA23/Z23 -> #DIV/0! | AC23: =RANK(AB23,$AB$7:$AB$24) -> #DIV/0! | AG23: =AF23/AE23 -> #DIV/0! | AH23: =RANK(AG23,$AG$7:$AG$24) -> #DIV/0! | AJ23: 18 | AK23: 1482 | AL23: =AK23/AJ23 -> 82.333333 | AM23: =RANK(AL23,$AL$7:$AL$24) -> 14 | AO23: 18 | AP23: 1485 | AQ23: =AP23/AO23 -> 82.5 | AR23: =RANK(AQ23,$AQ$7:$AQ$24) -> 15 | AT23: 18 | AU23: 1353 | AV23: =AU23/AT23 -> 75.166667 | AW23: =RANK(AV23,$AV$7:$AV$24) -> 16
C24: 18
B25: 產線配置圖－每週更新 | N25: 資料繳交 | O25: 日期 | P25: =AT2+1 -> 46238 | U25: =P25+1 -> 46239 | Z25: =U25+1 -> 46240 | AE25: =Z25+1 -> 46241 | AJ25: =AE25+1 -> 46242 | AO25: =AJ25+1 -> 46243 | AT25: =AO25+1 -> 46244
P26: 二 | U26: 三 | Z26: 四 | AE26: 五 | AJ26: 六 | AO26: 日 | AT26: 一
B27: 品群 | C27: 商品名稱 | E27: 計畫 | H27: 平均人時性 | I27: 實績 | L27: 平均人時性 | M27: 排名 | O27: 日報 | P27: 實際 | T27: 平均人時性 | U27: 實際 | Y27: 平均人時性 | Z27: 實際 | AD27: 平均人時性 | AE27: 實際 | AI27: 平均人時性 | AJ27: 實際 | AN27: 平均人時性 | AO27: 實際 | AS27: 平均人時性 | AT27: 實際 | AX27: 平均人時性
E28: 產線配置圖 | I28: 產線配置圖 | P28: 生產實績 | U28: 生產實績 | Z28: 生產實績 | AE28: 生產實績 | AJ28: 生產實績 | AO28: 生產實績 | AT28: 生產實績
E29: 人數 | F29: 產能／時 | G29: 人時性 | I29: 人數 | J29: 產能／時 | K29: 人時性 | P29: 人數 | Q29: 產能／時 | R29: 人時性 | S29: 排名 | U29: 人數 | V29: 產能／時 | W29: 人時性 | X29: 排名 | Z29: 人數 | AA29: 產能／時 | AB29: 人時性 | AC29: 排名 | AE29: 人數 | AF29: 產能／時 | AG29: 人時性 | AH29: 排名 | AJ29: 人數 | AK29: 產能／時 | AL29: 人時性 | AM29: 排名 | AO29: 人數 | AP29: 產能／時 | AQ29: 人時性 | AR29: 排名 | AT29: 人數 | AU29: 產能／時 | AV29: 人時性 | AW29: 排名
B30: 熱食義麵 | C30: 1 | D30: 義式蕃茄起司義大利麵 | E30: =VLOOKUP(D30,'07產線配置圖'!$A$2:$C$25,2,0) -> 12 | F30: =VLOOKUP(D30,'07產線配置圖'!$A$2:$C$25,3,0) -> 2250 | G30: =F30/E30 -> 187.5 | H30: =AVERAGE(G30:G47) -> 123.00422 | I30: =AVERAGE(P30,U30,Z30,AE30,AJ30,AO30,AT30) -> 12 | J30: =AVERAGE(Q30,V30,AA30,AF30,AK30,AP30,AU30) -> 2052 | K30: =J30/I30 -> 171 | L30: =IFERROR(AVERAGE(K30:K47),"-") -> 111.12013 | M30: =RANK(K30, K$30:$K$47) -> 1 | P30: 12 | Q30: 1933 | R30: =Q30/P30 -> 161.08333 | S30: =RANK(R30,$R$30:$R$47) -> 3 | T30: =AVERAGE(R30:R47) -> 111.55871 | U30: 12 | V30: 2033 | W30: =V30/U30 -> 169.41667 | X30: =RANK(W30, $W$30:$W$47) -> 1 | Y30: =AVERAGE(W30:W47) -> 111.72832 | Z30: 12 | AA30: 1970 | AB30: =AA30/Z30 -> 164.16667 | AC30: =RANK(AB30, $AB$30:$AB$47) -> 2 | AD30: =AVERAGE(AB30:AB47) -> 111.0565 | AE30: 12 | AF30: 2171 | AG30: =AF30/AE30 -> 180.91667 | AH30: =RANK(AG30, $AG$30:$AG$47) -> 1 | AI30: =AVERAGE(AG30:AG47) -> 109.45992 | AJ30: 12 | AK30: 2204 | AL30: =AK30/AJ30 -> 183.66667 | AM30: =RANK(AL30, $AL$30:$AL$47) -> 1 | AN30: =AVERAGE(AL30:AL47) -> 111.99957 | AO30: 12 | AP30: 2015 | AQ30: =AP30/AO30 -> 167.91667 | AR30: =RANK(AQ30,$AQ$30:$AQ$47) -> 2 | AS30: =AVERAGE(AQ30:AQ47) -> 109.11036 | AT30: 12 | AU30: 2038 | AV30: =AU30/AT30 -> 169.83333 | AW30: =RANK(AV30, $AV$30:$AV$47) -> 1 | AX30: =AVERAGE(AV30:AV47) -> 112.97826
C31: 2 | D31: 奶油培根義大利麵 | E31: =VLOOKUP(D31,'07產線配置圖'!$A$3:$C$26,2,0) -> 15 | F31: =VLOOKUP(D31,'07產線配置圖'!$A$3:$C$26,3,0) -> 2250 | G31: =F31/E31 -> 150 | I31: =AVERAGE(P31,U31,Z31,AE31,AJ31,AO31,AT31) -> 14.857143 | J31: =AVERAGE(Q31,V31,AA31,AF31,AK31,AP31,AU31) -> 2089 | K31: =J31/I31 -> 140.60577 | M31: =RANK(K31, K$30:$K$47) -> 4 | P31: 15 | Q31: 2079 | R31: =Q31/P31 -> 138.6 | S31: =RANK(R31,$R$30:$R$47) -> 5 | U31: 14 | V31: 1997 | W31: =V31/U31 -> 142.64286 | X31: =RANK(W31, $W$30:$W$47) -> 5 | Z31: 15 | AA31: 2087 | AB31: =AA31/Z31 -> 139.13333 | AC31: =RANK(AB31, $AB$30:$AB$47) -> 4 | AE31: 15 | AF31: 2212 | AG31: =AF31/AE31 -> 147.46667 | AH31: =RANK(AG31, $AG$30:$AG$47) -> 4 | AJ31: 15 | AK31: 2204 | AL31: =AK31/AJ31 -> 146.93333 | AM31: =RANK(AL31, $AL$30:$AL$47) -> 4 | AO31: 15 | AP31: 1908 | AQ31: =AP31/AO31 -> 127.2 | AR31: =RANK(AQ31,$AQ$30:$AQ$47) -> 5 | AT31: 15 | AU31: 2136 | AV31: =AU31/AT31 -> 142.4 | AW31: =RANK(AV31, $AV$30:$AV$47) -> 4
C32: 3 | D32: 白酒清炒鮮蛤義大利麵 | E32: =VLOOKUP(D32,'07產線配置圖'!$A$3:$C$26,2,0) -> 15 | F32: =VLOOKUP(D32,'07產線配置圖'!$A$3:$C$26,3,0) -> 2250 | G32: =F32/E32 -> 150 | I32: =AVERAGE(P32,U32,Z32,AE32,AJ32,AO32,AT32) -> 14.714286 | J32: =AVERAGE(Q32,V32,AA32,AF32,AK32,AP32,AU32) -> 2024.1429 | K32: =J32/I32 -> 137.56311 | M32: =RANK(K32, K$30:$K$47) -> 5 | P32: 14 | Q32: 1994 | R32: =Q32/P32 -> 142.42857 | S32: =RANK(R32,$R$30:$R$47) -> 4 | U32: 14 | V32: 2016 | W32: =V32/U32 -> 144 | X32: =RANK(W32, $W$30:$W$47) -> 4 | Z32: 15 | AA32: 2039 | AB32: =AA32/Z32 -> 135.93333 | AC32: =RANK(AB32, $AB$30:$AB$47) -> 5 | AE32: 15 | AF32: 2020 | AG32: =AF32/AE32 -> 134.66667 | AH32: =RANK(AG32, $AG$30:$AG$47) -> 5 | AJ32: 15 | AK32: 2076 | AL32: =AK32/AJ32 -> 138.4 | AM32: =RANK(AL32, $AL$30:$AL$47) -> 5 | AO32: 15 | AP32: 2003 | AQ32: =AP32/AO32 -> 133.53333 | AR32: =RANK(AQ32,$AQ$30:$AQ$47) -> 4 | AT32: 15 | AU32: 2021 | AV32: =AU32/AT32 -> 134.73333 | AW32: =RANK(AV32, $AV$30:$AV$47) -> 5
C33: 4 | D33: 焗烤起司雙饗筆尖麵 | E33: =VLOOKUP(D33,'07產線配置圖'!$A$3:$C$26,2,0) -> 16 | F33: =VLOOKUP(D33,'07產線配置圖'!$A$3:$C$26,3,0) -> 1800 | G33: =F33/E33 -> 112.5 | I33: =AVERAGE(P33,U33,Z33,AE33,AJ33,AO33,AT33) -> 15.857143 | J33: =AVERAGE(Q33,V33,AA33,AF33,AK33,AP33,AU33) -> 1556.4286 | K33: =J33/I33 -> 98.153153 | M33: =RANK(K33, K$30:$K$47) -> 9 | P33: 15 | Q33: 1560 | R33: =Q33/P33 -> 104 | S33: =RANK(R33,$R$30:$R$47) -> 7 | U33: 16 | V33: 1525 | W33: =V33/U33 -> 95.3125 | X33: =RANK(W33, $W$30:$W$47) -> 11 | Z33: 16 | AA33: 1625 | AB33: =AA33/Z33 -> 101.5625 | AC33: =RANK(AB33, $AB$30:$AB$47) -> 9 | AE33: 16 | AF33: 1540 | AG33: =AF33/AE33 -> 96.25 | AH33: =RANK(AG33, $AG$30:$AG$47) -> 10 | AJ33: 16 | AK33: 1643 | AL33: =AK33/AJ33 -> 102.6875 | AM33: =RANK(AL33, $AL$30:$AL$47) -> 9 | AO33: 16 | AP33: 1566 | AQ33: =AP33/AO33 -> 97.875 | AR33: =RANK(AQ33,$AQ$30:$AQ$47) -> 9 | AT33: 16 | AU33: 1436 | AV33: =AU33/AT33 -> 89.75 | AW33: =RANK(AV33, $AV$30:$AV$47) -> 13
C34: 5 | D34: 青醬蛤蜊義大利麵 | E34: =VLOOKUP(D34,'07產線配置圖'!$A$3:$C$26,2,0) -> 13 | F34: =VLOOKUP(D34,'07產線配置圖'!$A$3:$C$26,3,0) -> 2250 | G34: =F34/E34 -> 173.07692 | I34: =AVERAGE(P34,U34,Z34,AE34,AJ34,AO34,AT34) -> 13 | J34: =AVERAGE(Q34,V34,AA34,AF34,AK34,AP34,AU34) -> 2078.8571 | K34: =J34/I34 -> 159.91209 | M34: =RANK(K34, K$30:$K$47) -> 2 | P34: 13 | Q34: 2123 | R34: =Q34/P34 -> 163.30769 | S34: =RANK(R34,$R$30:$R$47) -> 2 | U34: 13 | V34: 2080 | W34: =V34/U34 -> 160 | X34: =RANK(W34, $W$30:$W$47) -> 2 | Z34: 13 | AA34: 1991 | AB34: =AA34/Z34 -> 153.15385 | AC34: =RANK(AB34, $AB$30:$AB$47) -> 3 | AE34: 13 | AF34: 2015 | AG34: =AF34/AE34 -> 155 | AH34: =RANK(AG34, $AG$30:$AG$47) -> 2 | AJ34: 13 | AK34: 2100 | AL34: =AK34/AJ34 -> 161.53846 | AM34: =RANK(AL34, $AL$30:$AL$47) -> 2 | AO34: 13 | AP34: 2192 | AQ34: =AP34/AO34 -> 168.61538 | AR34: =RANK(AQ34,$AQ$30:$AQ$47) -> 1 | AT34: 13 | AU34: 2051 | AV34: =AU34/AT34 -> 157.76923 | AW34: =RANK(AV34, $AV$30:$AV$47) -> 2
C35: 6 | D35: 青花椒麻雞肉拌麵 | E35: =VLOOKUP(D35,'07產線配置圖'!$A$3:$C$26,2,0) -> 16 | F35: =VLOOKUP(D35,'07產線配置圖'!$A$3:$C$26,3,0) -> 1714 | G35: =F35/E35 -> 107.125 | I35: =AVERAGE(P35,U35,Z35,AE35,AJ35,AO35,AT35) -> 15.857143 | J35: =AVERAGE(Q35,V35,AA35,AF35,AK35,AP35,AU35) -> 1600.5714 | K35: =J35/I35 -> 100.93694 | M35: =RANK(K35, K$30:$K$47) -> 8 | P35: 16 | Q35: 1432 | R35: =Q35/P35 -> 89.5 | S35: =RANK(R35,$R$30:$R$47) -> 14 | U35: 15 | V35: 1519 | W35: =V35/U35 -> 101.26667 | X35: =RANK(W35, $W$30:$W$47) -> 8 | Z35: 16 | AA35: 1631 | AB35: =AA35/Z35 -> 101.9375 | AC35: =RANK(AB35, $AB$30:$AB$47) -> 8 | AE35: 16 | AF35: 1605 | AG35: =AF35/AE35 -> 100.3125 | AH35: =RANK(AG35, $AG$30:$AG$47) -> 8 | AJ35: 16 | AK35: 1682 | AL35: =AK35/AJ35 -> 105.125 | AM35: =RANK(AL35, $AL$30:$AL$47) -> 8 | AO35: 16 | AP35: 1693 | AQ35: =AP35/AO35 -> 105.8125 | AR35: =RANK(AQ35,$AQ$30:$AQ$47) -> 8 | AT35: 16 | AU35: 1642 | AV35: =AU35/AT35 -> 102.625 | AW35: =RANK(AV35, $AV$30:$AV$47) -> 8
C36: 7 | D36: 沙茶豬肉炒麵 | E36: =VLOOKUP(D36,'07產線配置圖'!$A$3:$C$26,2,0) -> 17 | F36: =VLOOKUP(D36,'07產線配置圖'!$A$3:$C$26,3,0) -> 1800 | G36: =F36/E36 -> 105.88235 | I36: =AVERAGE(P36,U36,Z36,AE36,AJ36,AO36,AT36) -> 17 | J36: =AVERAGE(Q36,V36,AA36,AF36,AK36,AP36,AU36) -> 1635.1429 | K36: =J36/I36 -> 96.184874 | M36: =RANK(K36, K$30:$K$47) -> 10 | P36: 17 | Q36: 1684 | R36: =Q36/P36 -> 99.058824 | S36: =RANK(R36,$R$30:$R$47) -> 9 | U36: 17 | V36: 1703 | W36: =V36/U36 -> 100.17647 | X36: =RANK(W36, $W$30:$W$47) -> 9 | Z36: 17 | AA36: 1709 | AB36: =AA36/Z36 -> 100.52941 | AC36: =RANK(AB36, $AB$30:$AB$47) -> 10 | AE36: 17 | AF36: 1731 | AG36: =AF36/AE36 -> 101.82353 | AH36: =RANK(AG36, $AG$30:$AG$47) -> 7 | AJ36: 17 | AK36: 1539 | AL36: =AK36/AJ36 -> 90.529412 | AM36: =RANK(AL36, $AL$30:$AL$47) -> 11 | AO36: 17 | AP36: 1558 | AQ36: =AP36/AO36 -> 91.647059 | AR36: =RANK(AQ36,$AQ$30:$AQ$47) -> 11 | AT36: 17 | AU36: 1522 | AV36: =AU36/AT36 -> 89.529412 | AW36: =RANK(AV36, $AV$30:$AV$47) -> 15
C37: 8 | D37: 府城鹽水意麵 | E37: =VLOOKUP(D37,'07產線配置圖'!$A$3:$C$26,2,0) -> 18 | F37: =VLOOKUP(D37,'07產線配置圖'!$A$3:$C$26,3,0) -> 1636 | G37: =F37/E37 -> 90.888889 | I37: =AVERAGE(P37,U37,Z37,AE37,AJ37,AO37,AT37) -> 17.642857 | J37: =AVERAGE(Q37,V37,AA37,AF37,AK37,AP37,AU37) -> 1472.4286 | K37: =J37/I37 -> 83.45749 | M37: =RANK(K37, K$30:$K$47) -> 15 | P37: 17.5 | Q37: 1371 | R37: =Q37/P37 -> 78.342857 | S37: =RANK(R37,$R$30:$R$47) -> 17 | U37: 17 | V37: 1462 | W37: =V37/U37 -> 86 | X37: =RANK(W37, $W$30:$W$47) -> 14 | Z37: 17 | AA37: 1335 | AB37: =AA37/Z37 -> 78.529412 | AC37: =RANK(AB37, $AB$30:$AB$47) -> 17 | AE37: 18 | AF37: 1618 | AG37: =AF37/AE37 -> 89.888889 | AH37: =RANK(AG37, $AG$30:$AG$47) -> 14 | AJ37: 18 | AK37: 1472 | AL37: =AK37/AJ37 -> 81.777778 | AM37: =RANK(AL37, $AL$30:$AL$47) -> 16 | AO37: 18 | AP37: 1436 | AQ37: =AP37/AO37 -> 79.777778 | AR37: =RANK(AQ37,$AQ$30:$AQ$47) -> 14 | AT37: 18 | AU37: 1613 | AV37: =AU37/AT37 -> 89.611111 | AW37: =RANK(AV37, $AV$30:$AV$47) -> 14
C38: 9 | D38: 香煎魚排佐檸檬奶油義大利麵 | E38: =VLOOKUP(D38,'07產線配置圖'!$A$3:$C$26,2,0) -> 13 | F38: =VLOOKUP(D38,'07產線配置圖'!$A$3:$C$26,3,0) -> 2250 | G38: =F38/E38 -> 173.07692 | I38: =AVERAGE(P38,U38,Z38,AE38,AJ38,AO38,AT38) -> 13 | J38: =AVERAGE(Q38,V38,AA38,AF38,AK38,AP38,AU38) -> 2063.4286 | K38: =J38/I38 -> 158.72527 | M38: =RANK(K38, K$30:$K$47) -> 3 | P38: 13 | Q38: 2124 | R38: =Q38/P38 -> 163.38462 | S38: =RANK(R38,$R$30:$R$47) -> 1 | U38: 13 | V38: 2021 | W38: =V38/U38 -> 155.46154 | X38: =RANK(W38, $W$30:$W$47) -> 3 | Z38: 13 | AA38: 2176 | AB38: =AA38/Z38 -> 167.38462 | AC38: =RANK(AB38, $AB$30:$AB$47) -> 1 | AE38: 13 | AF38: 1978 | AG38: =AF38/AE38 -> 152.15385 | AH38: =RANK(AG38, $AG$30:$AG$47) -> 3 | AJ38: 13 | AK38: 2044 | AL38: =AK38/AJ38 -> 157.23077 | AM38: =RANK(AL38, $AL$30:$AL$47) -> 3 | AO38: 13 | AP38: 2130 | AQ38: =AP38/AO38 -> 163.84615 | AR38: =RANK(AQ38,$AQ$30:$AQ$47) -> 3 | AT38: 13 | AU38: 1971 | AV38: =AU38/AT38 -> 151.61538 | AW38: =RANK(AV38, $AV$30:$AV$47) -> 3
C39: 10 | D39: 黑松露野菇義大利麵 | E39: =VLOOKUP(D39,'07產線配置圖'!$A$3:$C$26,2,0) -> 17 | F39: =VLOOKUP(D39,'07產線配置圖'!$A$3:$C$26,3,0) -> 1636 | G39: =F39/E39 -> 96.235294 | I39: =AVERAGE(P39,U39,Z39,AE39,AJ39,AO39,AT39) -> 17.142857 | J39: =AVERAGE(Q39,V39,AA39,AF39,AK39,AP39,AU39) -> 1500 | K39: =J39/I39 -> 87.5 | M39: =RANK(K39, K$30:$K$47) -> 13 | P39: 17 | Q39: 1552 | R39: =Q39/P39 -> 91.294118 | S39: =RANK(R39,$R$30:$R$47) -> 12 | U39: 17 | V39: 1345 | W39: =V39/U39 -> 79.117647 | X39: =RANK(W39, $W$30:$W$47) -> 16 | Z39: 17 | AA39: 1549 | AB39: =AA39/Z39 -> 91.117647 | AC39: =RANK(AB39, $AB$30:$AB$47) -> 13 | AE39: 17 | AF39: 1558 | AG39: =AF39/AE39 -> 91.647059 | AH39: =RANK(AG39, $AG$30:$AG$47) -> 13 | AJ39: 18 | AK39: 1577 | AL39: =AK39/AJ39 -> 87.611111 | AM39: =RANK(AL39, $AL$30:$AL$47) -> 13 | AO39: 17 | AP39: 1350 | AQ39: =AP39/AO39 -> 79.411765 | AR39: =RANK(AQ39,$AQ$30:$AQ$47) -> 15 | AT39: 17 | AU39: 1569 | AV39: =AU39/AT39 -> 92.294118 | AW39: =RANK(AV39, $AV$30:$AV$47) -> 12
C40: 11 | D40: 奶油鮮蝦明太子細扁麵 | E40: =VLOOKUP(D40,'07產線配置圖'!$A$3:$C$26,2,0) -> 18 | F40: =VLOOKUP(D40,'07產線配置圖'!$A$3:$C$26,3,0) -> 1636 | G40: =F40/E40 -> 90.888889 | I40: =AVERAGE(P40,U40,Z40,AE40,AJ40,AO40,AT40) -> 16.428571 | J40: =AVERAGE(Q40,V40,AA40,AF40,AK40,AP40,AU40) -> 1350.1429 | K40: =J40/I40 -> 82.182609 | M40: =RANK(K40, K$30:$K$47) -> 16 | P40: 17 | Q40: 1389 | R40: =Q40/P40 -> 81.705882 | S40: =RANK(R40,$R$30:$R$47) -> 16 | U40: 17 | V40: 1395 | W40: =V40/U40 -> 82.058824 | X40: =RANK(W40, $W$30:$W$47) -> 15 | Z40: 16 | AA40: 1288 | AB40: =AA40/Z40 -> 80.5 | AC40: =RANK(AB40, $AB$30:$AB$47) -> 16 | AE40: 16 | AF40: 1276 | AG40: =AF40/AE40 -> 79.75 | AH40: =RANK(AG40, $AG$30:$AG$47) -> 15 | AJ40: 16 | AK40: 1327 | AL40: =AK40/AJ40 -> 82.9375 | AM40: =RANK(AL40, $AL$30:$AL$47) -> 14 | AO40: 16 | AP40: 1299 | AQ40: =AP40/AO40 -> 81.1875 | AR40: =RANK(AQ40,$AQ$30:$AQ$47) -> 13 | AT40: 17 | AU40: 1477 | AV40: =AU40/AT40 -> 86.882353 | AW40: =RANK(AV40, $AV$30:$AV$47) -> 16
...

Sheet （５-3）品群別人時生產性(微波小吃)
B1: 月平均人時性 | C1: =AVERAGE(L7,L27,L47,L67,L87,L107) -> 125.66178
B2: 產線配置圖－每週更新 | N2: 資料繳交 | O2: 日期 | P2: 46203 | U2: =P2+1 -> 46204 | Z2: =U2+1 -> 46205 | AE2: =Z2+1 -> 46206 | AJ2: 46235 | AO2: 46236 | AT2: 46237
P3: 二 | U3: 三 | Z3: 四 | AE3: 五 | AJ3: 六 | AO3: 日 | AT3: 一
B4: 品群 | C4: 商品名稱 | E4: 計畫 | H4: 平均人時性 | I4: 實績 | L4: 平均人時性 | M4: 排名 | O4: 日報 | P4: 實際 | T4: 平均人時性 | U4: 實際 | Y4: 平均人時性 | Z4: 實際 | AD4: 平均人時性 | AE4: 實際 | AI4: 平均人時性 | AJ4: 實際 | AN4: 平均人時性 | AO4: 實際 | AS4: 平均人時性 | AT4: 實際 | AX4: 平均人時性
E5: 產線配置圖 | I5: 產線配置圖 | P5: 生產實績 | U5: 生產實績 | Z5: 生產實績 | AE5: 生產實績 | AJ5: 生產實績 | AO5: 生產實績 | AT5: 生產實績
E6: 人數 | F6: 產能／時 | G6: 人時性 | I6: 人數 | J6: 產能／時 | K6: 人時性 | P6: 人數 | Q6: 產能／時 | R6: 人時性 | S6: 排名 | U6: 人數 | V6: 產能／時 | W6: 人時性 | X6: 排名 | Z6: 人數 | AA6: 產能／時 | AB6: 人時性 | AC6: 排名 | AE6: 人數 | AF6: 產能／時 | AG6: 人時性 | AH6: 排名 | AJ6: 人數 | AK6: 產能／時 | AL6: 人時性 | AM6: 排名 | AO6: 人數 | AP6: 產能／時 | AQ6: 人時性 | AR6: 排名 | AT6: 人數 | AU6: 產能／時 | AV6: 人時性 | AW6: 排名
B7: 微波小吃 | C7: 1 | D7: 小滷青蔬 | E7: =VLOOKUP(D7,'07產線配置圖'!$A$27:$C$34,2,0) -> 15 | F7: =VLOOKUP(D7,'07產線配置圖'!$A$27:$C$34,3,0) -> 1636 | G7: =F7/E7 -> 109.06667 | H7: =AVERAGE(G7:G21) -> 138.81212 | I7: =AVERAGE(P7,U7,Z7,AE7,AJ7,AO7,AT7) -> 15 | J7: =AVERAGE(Q7,V7,AA7,AF7,AK7,AP7,AU7) -> 1523.6667 | K7: =J7/I7 -> 101.57778 | L7: =IFERROR(AVERAGE(K7:K21),"-") -> 127.14392 | M7: =RANK(K7,$K$7:$K$21) -> 4 | R7: =Q7/P7 -> #DIV/0! | S7: =RANK(R7, R$7:R$21) -> #DIV/0! | T7: =AVERAGE(R7:R21) -> #DIV/0! | W7: =V7/U7 -> #DIV/0! | X7: =RANK(W7,$W$7:$W$21) -> #DIV/0! | Y7: =AVERAGE(W7:W21) -> #DIV/0! | AB7: =AA7/Z7 -> #DIV/0! | AC7: =RANK(AB7,$AB$7:$AB$21) -> #DIV/0! | AD7: =AVERAGE(AB7:AB21) -> #DIV/0! | AG7: =AF7/AE7 -> #DIV/0! | AH7: =RANK(AG7,$AG$7:$AG$21) -> #DIV/0! | AI7: =AVERAGE(AG7:AG21) -> #DIV/0! | AJ7: 15 | AK7: 1512 | AL7: =AK7/AJ7 -> 100.8 | AM7: =RANK(AL7,$AL$7:$AL$21) -> 4 | AN7: =AVERAGE(AL7:AL21) -> 133.14318 | AO7: 15 | AP7: 1517 | AQ7: =AP7/AO7 -> 101.13333 | AR7: =RANK(AQ7,$AQ$7:$AQ$21) -> 4 | AS7: =AVERAGE(AQ7:AQ21) -> 127.1947 | AT7: 15 | AU7: 1542 | AV7: =AU7/AT7 -> 102.8 | AW7: =RANK(AV7,$AV$7:$AV$10) -> 4 | AX7: =AVERAGE(AV7:AV21) -> 121.85909
C8: 2 | D8: 起司馬鈴薯 | E8: =VLOOKUP(D8,'07產線配置圖'!$A$27:$C$34,2,0) -> 11 | F8: =VLOOKUP(D8,'07產線配置圖'!$A$27:$C$34,3,0) -> 1636 | G8: =F8/E8 -> 148.72727 | I8: =AVERAGE(P8,U8,Z8,AE8,AJ8,AO8,AT8) -> 11 | J8: =AVERAGE(Q8,V8,AA8,AF8,AK8,AP8,AU8) -> 1567.6667 | K8: =J8/I8 -> 142.51515 | M8: =RANK(K8,$K$7:$K$21) -> 1 | R8: =Q8/P8 -> #DIV/0! | S8: =RANK(R8, R$7:R$21) -> #DIV/0! | W8: =V8/U8 -> #DIV/0! | X8: =RANK(W8,$W$7:$W$21) -> #DIV/0! | AB8: =AA8/Z8 -> #DIV/0! | AC8: =RANK(AB8,$AB$7:$AB$21) -> #DIV/0! | AG8: =AF8/AE8 -> #DIV/0! | AH8: =RANK(AG8,$AG$7:$AG$21) -> #DIV/0! | AJ8: 11 | AK8: 1622 | AL8: =AK8/AJ8 -> 147.45455 | AM8: =RANK(AL8,$AL$7:$AL$21) -> 1 | AO8: 11 | AP8: 1532 | AQ8: =AP8/AO8 -> 139.27273 | AR8: =RANK(AQ8,$AQ$7:$AQ$21) -> 1 | AT8: 11 | AU8: 1549 | AV8: =AU8/AT8 -> 140.81818 | AW8: =RANK(AV8,$AV$7:$AV$10) -> 1
C9: 3 | D9: 韓式炒冬粉 | E9: =VLOOKUP(D9,'07產線配置圖'!$A$27:$C$34,2,0) -> 11 | F9: =VLOOKUP(D9,'07產線配置圖'!$A$27:$C$34,3,0) -> 1636 | G9: =F9/E9 -> 148.72727 | I9: =AVERAGE(P9,U9,Z9,AE9,AJ9,AO9,AT9) -> 11 | J9: =AVERAGE(Q9,V9,AA9,AF9,AK9,AP9,AU9) -> 1452 | K9: =J9/I9 -> 132 | M9: =RANK(K9,$K$7:$K$21) -> 3 | R9: =Q9/P9 -> #DIV/0! | S9: =RANK(R9, R$7:R$21) -> #DIV/0! | W9: =V9/U9 -> #DIV/0! | X9: =RANK(W9,$W$7:$W$21) -> #DIV/0! | AB9: =AA9/Z9 -> #DIV/0! | AC9: =RANK(AB9,$AB$7:$AB$21) -> #DIV/0! | AG9: =AF9/AE9 -> #DIV/0! | AH9: =RANK(AG9,$AG$7:$AG$21) -> #DIV/0! | AJ9: 11 | AK9: 1560 | AL9: =AK9/AJ9 -> 141.81818 | AM9: =RANK(AL9,$AL$7:$AL$21) -> 3 | AO9: 11 | AP9: 1455 | AQ9: =AP9/AO9 -> 132.27273 | AR9: =RANK(AQ9,$AQ$7:$AQ$21) -> 3 | AT9: 11 | AU9: 1341 | AV9: =AU9/AT9 -> 121.90909 | AW9: =RANK(AV9,$AV$7:$AV$10) -> 2
C10: 4 | D10: 麻辣雞心 | E10: =VLOOKUP(D10,'07產線配置圖'!$A$27:$C$34,2,0) -> 11 | F10: =VLOOKUP(D10,'07產線配置圖'!$A$27:$C$34,3,0) -> 1636 | G10: =F10/E10 -> 148.72727 | I10: =AVERAGE(P10,U10,Z10,AE10,AJ10,AO10,AT10) -> 9.6666667 | J10: =AVERAGE(Q10,V10,AA10,AF10,AK10,AP10,AU10) -> 1280.6667 | K10: =J10/I10 -> 132.48276 | M10: =RANK(K10,$K$7:$K$21) -> 2 | R10: =Q10/P10 -> #DIV/0! | S10: =RANK(R10, R$7:R$21) -> #DIV/0! | W10: =V10/U10 -> #DIV/0! | X10: =RANK(W10,$W$7:$W$21) -> #DIV/0! | AB10: =AA10/Z10 -> #DIV/0! | AC10: =RANK(AB10,$AB$7:$AB$21) -> #DIV/0! | AG10: =AF10/AE10 -> #DIV/0! | AH10: =RANK(AG10,$AG$7:$AG$21) -> #DIV/0! | AJ10: 8 | AK10: 1140 | AL10: =AK10/AJ10 -> 142.5 | AM10: =RANK(AL10,$AL$7:$AL$21) -> 2 | AO10: 10 | AP10: 1361 | AQ10: =AP10/AO10 -> 136.1 | AR10: =RANK(AQ10,$AQ$7:$AQ$21) -> 2 | AT10: 11 | AU10: 1341 | AV10: =AU10/AT10 -> 121.90909 | AW10: =RANK(AV10,$AV$7:$AV$10) -> 2
C11: 5
C12: 6
C13: 7
C14: 8
C15: 9
C16: 10
C17: 11
C18: 12
C19: 13
C20: 14
C21: 15
B22: 產線配置圖－每週更新 | N22: 資料繳交 | O22: 日期 | P22: =AT2+1 -> 46238 | U22: =P22+1 -> 46239 | Z22: =U22+1 -> 46240 | AE22: =Z22+1 -> 46241 | AJ22: =AE22+1 -> 46242 | AO22: =AJ22+1 -> 46243 | AT22: =AO22+1 -> 46244
P23: 二 | U23: 三 | Z23: 四 | AE23: 五 | AJ23: 六 | AO23: 日 | AT23: 一
B24: 品群 | C24: 商品名稱 | E24: 計畫 | H24: 平均人時性 | I24: 實績 | L24: 平均人時性 | M24: 排名 | O24: 日報 | P24: 實際 | T24: 平均人時性 | U24: 實際 | Y24: 平均人時性 | Z24: 實際 | AD24: 平均人時性 | AE24: 實際 | AI24: 平均人時性 | AJ24: 實際 | AN24: 平均人時性 | AO24: 實際 | AS24: 平均人時性 | AT24: 實際 | AX24: 平均人時性
E25: 產線配置圖 | I25: 產線配置圖 | P25: 生產實績 | U25: 生產實績 | Z25: 生產實績 | AE25: 生產實績 | AJ25: 生產實績 | AO25: 生產實績 | AT25: 生產實績
