Workbook

Sheet 生產管理報表(月)
A1: 長家廠生產管理報表
A3: 月別 | B3: 10 | C3: 工廠 | D3: 長家
A4: （１）收支狀況 | E4: ※單位：千元 | G4: （２）ＫＰＩ達成進度
A5: 項目 | B5: 當月 | C5: 前月 | D5: 差異 | E5: 累計 | G5: 項目 | H5: KPI | I5: 當月 | J5: 前月 | K5: 累計 | L5: ※補充
A6: 業績金額 | B6: 7674016.4 | D6: =B6-C6 -> 7674016.4 | G6: 人時性(個/月均) | H6: 109.4 | I6: 99.8 | L6: 個／MH
A7: 訂單數量 | B7: 157800 | D7: =B7-C7 -> 157800 | G7: 人時達成率(%/月均) | H7: 0.8 | I7: 0.912 | L7: 達成率
A8: 材料費 | B8: 4819806 | D8: =B8-C8 -> 4819806 | G8: 半成品-報廢(%) | H8: 0.0025 | I8: 0.009 | L8: 報廢率
A9: 材料費率 | B9: 0.62806824 | D9: =B9-C9 -> 0.62806824 | G9: 半成品-超用(%) | H9: 0.0025 | I9: 0.011 | L9: 超用率
A10: 勞務成本 | D10: =B10-C10 -> 0 | G10: 固定產線-導入率(%) | H10: 1 | I10: 0.429 | L10: 導入率
A11: 勞務費率 | D11: =B11-C11 -> 0 | G11: 教育訓練-實施率(%) | H11: 1 | I11: 0.286 | L11: 實施率
A13: （３）業績構成比 | G13: （４）訂單數量構成比
B14: 當月 | C14: 比例 | D14: 前月 | E14: 差異 | H14: 當月 | I14: 比例 | J14: 前月 | K14: 差異
A15: 熱食義麵(122,123,124,126) | B15: 7050229 | C15: =IFERROR(B15/$B$6,"") -> 0.91871435 | E15: =IFERROR(C15-D15,"") -> 0.91871435 | G15: 熱食義麵(122,123,124,126) | I15: =IFERROR(H15/$B$7,"") -> 0 | K15: =IFERROR(I15-J15,"") -> 0
A16: 季節調理麵(111,112) | C16: =IFERROR(B16/$B$6,"") -> 0 | E16: =IFERROR(C16-D16,"") -> 0 | G16: 季節調理麵(111,112) | I16: =IFERROR(H16/$B$7,"") -> 0 | K16: =IFERROR(I16-J16,"") -> 0
A17: 微波小吃(153,154,155) | B17: 623787 | C17: =IFERROR(B17/$B$6,"") -> 0.081285596 | E17: =IFERROR(C17-D17,"") -> 0.081285596 | G17: 微波小吃(153,154,155) | I17: =IFERROR(H17/$B$7,"") -> 0 | K17: =IFERROR(I17-J17,"") -> 0
C18: =SUM(C15:C17) -> 0.99999995 | D18: =SUM(D15:D17) -> 0 | I18: =SUM(I15:I17) -> 0 | J18: =SUM(J15:J17) -> 0
A20: （５）品群別人時生產性
A21: 品群 | B21: 當月 | C21: 前月 | D21: 差異 | E21: 累計
A22: 熱食義麵(122,123,124,126) | B22: 97.6 | D22: 0
A23: 季節調理麵(111,112) | D23: 0
A24: 微波小吃(153,154,155) | B24: 112.5 | D24: 0

Sheet 生產管理報表(週) 
A1: 長家廠生產管理報表
A3: 月別 | B3: =10 -> 10 | C3: 週別 | D3: W1 | E3: 工廠 | F3: 長家廠
A4: （１）收支狀況 | E4: ※單位：千元 | G4: （２）ＫＰＩ達成進度
A5: 項目 | B5: 當週 | C5: 前週 | D5: 差異 | E5: 累計 | G5: 項目 | H5: KPI | I5: 當週 | J5: 前週 | K5: 累計 | L5: ※補充
A6: 業績金額 | B6: 13981.9 | C6: 16941.8 | D6: =B6-C6 -> -2959.9 | E6: 13981.9 | G6: 人時性(個/月均) | H6: 115.3 | I6: 101.8 | J6: 98.7 | K6: 101.8 | L6: 個／MH
A7: 訂單數量 | B7: 289645 | C7: 347276 | D7: =B7-C7 -> -57631 | E7: 289645 | G7: 人時達成率(%/月均) | H7: 0.8 | I7: =I6/H6 -> 0.88291414 | J7: 0.8621 | K7: 0.8829 | L7: 達成率
A8: 材料費 | B8: 8823.8 | C8: 10676.3 | D8: =B8-C8 -> -1852.5 | E8: 8823.8 | G8: 半成品-報廢(%) | H8: 0.0025 | I8: 0.01 | J8: 0.01 | K8: 0.01 | L8: 報廢率
A9: 材料費率 | B9: =B8/B6 -> 0.63108733 | C9: =C8/C6 -> 0.63017507 | D9: =B9-C9 -> 0.00091226439 | E9: =E8/E6 -> 0.63108733 | G9: 半成品-超用(%) | H9: 0.0025 | I9: 0.004 | J9: 0.002 | K9: 0.004 | L9: 超用率
A10: 勞務成本 | D10: =B10-C10 -> 0 | G10: 固定產線-導入率(%) | H10: 1 | I10: 0.429 | J10: 0.429 | K10: 0.429 | L10: 導入率
A11: 勞務費率 | D11: =B11-C11 -> 0 | G11: 教育訓練-實施率(%) | H11: 1 | I11: 0.7 | J11: 0.603 | K11: 0.7 | L11: 實施率
A13: （３）業績構成比 | G13: （４）訂單數量構成比
B14: 當週 | C14: 比例 | D14: 前週 | E14: 差異 | H14: 當週 | I14: 比例 | J14: 前週 | K14: 差異
A15: 熱食義麵(122,123,124,126) | B15: 12732.4 | C15: =IFERROR(B15/$B$6,"") -> 0.91063446 | D15: 0.9149 | E15: =IFERROR(C15-D15,"") -> -0.0042655369 | G15: 熱食義麵(122,123,124,126) | H15: 244446 | I15: =IFERROR(H15/$B$7,"") -> 0.84395035 | J15: 0.8497 | K15: =IFERROR(I15-J15,"") -> -0.005749647
A16: 季節調理麵(111,112) | C16: =IFERROR(B16/$B$6,"") -> 0 | E16: =IFERROR(C16-D16,"") -> 0 | G16: 季節調理麵(111,112) | I16: =IFERROR(H16/$B$7,"") -> 0 | K16: =IFERROR(I16-J16,"") -> 0
A17: 微波小吃(153,154,155) | B17: 1249.5 | C17: =IFERROR(B17/$B$6,"") -> 0.089365537 | D17: 0.0851 | E17: =IFERROR(C17-D17,"") -> 0.0042655369 | G17: 微波小吃(153,154,155) | H17: 45199 | I17: =IFERROR(H17/$B$7,"") -> 0.15604965 | J17: 0.1503 | K17: =IFERROR(I17-J17,"") -> 0.005749647
C18: =SUM(C15:C17) -> 1 | D18: =SUM(D15:D17) -> 1 | I18: =SUM(I15:I17) -> 1 | J18: =SUM(J15:J17) -> 1
A20: （５）品群別人時生產性
A21: 品群 | B21: 當週 | C21: 前週 | D21: 差異 | E21: 累計
A22: 熱食義麵(122,123,124,126) | B22: 96.2 | C22: 94.5 | D22: =B22-C22 -> 1.7 | E22: 96.2
A23: 季節調理麵(111,112) | D23: =B23-C23 -> 0
A24: 微波小吃(153,154,155) | B24: 111.7 | C24: 110.5 | D24: =B24-C24 -> 1.2 | E24: 111.7

Sheet （１）收支狀況
B2: （１）收支狀況
B3: 資料繳交日 | C3: 月份 | D3: 日期 | F3: 營業額(元) | I3: 訂單數量(個) | L3: 材料費(元) | O3: 材料費率（材料費／營業額） | R3: 勞務成本（全廠人事成本） | U3: 勞務費率（勞務成本／營業額）
F4: 日 | G4: 週累積 | H4: 月累積 | I4: 日 | J4: 週累積 | K4: 月累積 | L4: 日 | M4: 週累積 | N4: 月累積 | O4: 日 | P4: 週累積 | Q4: 月累積 | R4: 日 | S4: 週累積 | T4: 月累積 | U4: 日 | V4: 週累積 | W4: 月累積
B5: 45937 | C5: 十 | D5: 45931 | E5: 三 | F5: 2824753 | G5: =SUM(F5:F10) -> 13981868 | H5: =SUM(F5:F35) -> 13981868 | I5: 59618 | J5: =SUM(I5:I10) -> 289645 | K5: =SUM(I5:I34) -> 289645 | L5: 1783002 | M5: =SUM(L5:L10) -> 8823754 | N5: =SUM(L5:L34) -> 8823754 | O5: =L5/F5 -> 0.63120635 | P5: =M5/G5 -> 0.63108551 | Q5: =N5/H5 -> 0.63108551 | S5: =SUM(R5:R10) -> 0 | T5: =SUM(R5:R34) -> 0 | U5: =R5/F5 -> 0 | V5: =S5/G5 -> 0 | W5: =T5/H5 -> 0
D6: 45932 | E6: 四 | F6: 2491478.9 | I6: 51111 | L6: 1571350 | O6: =L6/F6 -> 0.63068968 | U6: =R6/F6 -> 0
D7: 45933 | E7: 五 | F7: 1927390 | I7: 39570 | L7: 1216995 | O7: =L7/F7 -> 0.63142125 | U7: =R7/F7 -> 0
D8: 45934 | E8: 六 | F8: 1927172.3 | I8: 39717 | L8: 1216147 | O8: =L8/F8 -> 0.63105256 | U8: =R8/F8 -> 0
D9: 45935 | E9: 日 | F9: 2140557.9 | I9: 44134 | L9: 1350695 | O9: =L9/F9 -> 0.63100138 | U9: =R9/F9 -> 0
D10: 45936 | E10: 一 | F10: 2670515.5 | I10: 55495 | L10: 1685565 | O10: =L10/F10 -> 0.63117589 | U10: =R10/F10 -> 0
B11: 45944 | D11: 45937 | E11: 二 | G11: =SUM(F11:F17) -> 0 | J11: =SUM(I11:I17) -> 0 | M11: =SUM(L11:L17) -> 0 | O11: =L11/F11 -> #DIV/0! | P11: =M11/G11 -> #DIV/0! | S11: =SUM(R11:R17) -> 0 | U11: =R11/F11 -> #DIV/0! | V11: =S11/G11 -> #DIV/0!
D12: 45938 | E12: 三 | O12: =L12/F12 -> #DIV/0! | U12: =R12/F12 -> #DIV/0!
D13: 45939 | E13: 四 | O13: =L13/F13 -> #DIV/0! | U13: =R13/F13 -> #DIV/0!
D14: 45940 | E14: 五 | O14: =L14/F14 -> #DIV/0! | U14: =R14/F14 -> #DIV/0!
D15: 45941 | E15: 六 | O15: =L15/F15 -> #DIV/0! | U15: =R15/F15 -> #DIV/0!
D16: 45942 | E16: 日 | O16: =L16/F16 -> #DIV/0! | U16: =R16/F16 -> #DIV/0!
D17: 45943 | E17: 一 | O17: =L17/F17 -> #DIV/0! | U17: =R17/F17 -> #DIV/0!
B18: 45951 | D18: 45944 | E18: 二 | G18: =SUM(F18:F24) -> 0 | J18: =SUM(I18:I24) -> 0 | M18: =SUM(L18:L24) -> 0 | O18: =L18/F18 -> #DIV/0! | P18: =M18/G18 -> #DIV/0! | S18: =SUM(R18:R24) -> 0 | U18: =R18/F18 -> #DIV/0! | V18: =S18/G18 -> #DIV/0!
D19: 45945 | E19: 三 | O19: =L19/F19 -> #DIV/0! | U19: =R19/F19 -> #DIV/0!
D20: 45946 | E20: 四 | O20: =L20/F20 -> #DIV/0! | U20: =R20/F20 -> #DIV/0!
D21: 45947 | E21: 五 | O21: =L21/F21 -> #DIV/0! | U21: =R21/F21 -> #DIV/0!
D22: 45948 | E22: 六 | O22: =L22/F22 -> #DIV/0! | U22: =R22/F22 -> #DIV/0!
D23: 45949 | E23: 日 | O23: =L23/F23 -> #DIV/0! | U23: =R23/F23 -> #DIV/0!
D24: 45950 | E24: 一 | O24: =L24/F24 -> #DIV/0! | U24: =R24/F24 -> #DIV/0!
B25: 45958 | D25: 45951 | E25: 二 | G25: =SUM(F25:F31) -> 0 | J25: =SUM(I25:I31) -> 0 | M25: =SUM(L25:L31) -> 0 | O25: =L25/F25 -> #DIV/0! | P25: =M25/G25 -> #DIV/0! | S25: =SUM(R25:R31) -> 0 | U25: =R25/F25 -> #DIV/0! | V25: =S25/G25 -> #DIV/0!
D26: 45952 | E26: 三 | O26: =L26/F26 -> #DIV/0! | U26: =R26/F26 -> #DIV/0!
D27: 45953 | E27: 四 | O27: =L27/F27 -> #DIV/0! | U27: =R27/F27 -> #DIV/0!
D28: 45954 | E28: 五 | O28: =L28/F28 -> #DIV/0! | U28: =R28/F28 -> #DIV/0!
D29: 45955 | E29: 六 | O29: =L29/F29 -> #DIV/0! | U29: =R29/F29 -> #DIV/0!
D30: 45956 | E30: 日 | O30: =L30/F30 -> #DIV/0! | U30: =R30/F30 -> #DIV/0!
D31: 45957 | E31: 一 | O31: =L31/F31 -> #DIV/0! | U31: =R31/F31 -> #DIV/0!
D32: 45958 | E32: 二 | O32: =L32/F32 -> #DIV/0! | U32: =R32/F32 -> #DIV/0!
D33: 45959 | E33: 三 | O33: =L33/F33 -> #DIV/0! | U33: =R33/F33 -> #DIV/0!
D34: 45960 | E34: 四 | O34: =L34/F34 -> #DIV/0! | U34: =R34/F34 -> #DIV/0!
D35: 45961 | E35: 五 | O35: =L35/F35 -> #DIV/0! | U35: =R35/F35 -> #DIV/0!
O36: =L36/F36 -> #DIV/0!
G37: =SUM(F37:F43) -> 0 | J37: =SUM(I37:I43) -> 0 | M37: =SUM(L37:L43) -> 0 | O37: =L37/F37 -> #DIV/0! | P37: =M37/G37 -> #DIV/0! | S37: =SUM(R37:R43) -> 0 | V37: =SUM(U37:U43) -> 0
O38: =L38/F38 -> #DIV/0!
O39: =L39/F39 -> #DIV/0!
O40: =L40/F40 -> #DIV/0!
O41: =L41/F41 -> #DIV/0!
...

Sheet （２）ＫＰＩ達成進度
C1: 115.3
B2: （２）ＫＰＩ達成進度
B3: 資料繳交日 | C3: 月份 | D3: 日期 | F3: 人時生產性(個/人) | I3: 人時生產性達成率(%) | L3: 半成品報廢(%) | O3: 半成品超用(%) | R3: 固定產線-導入率(固定產線數/總產線數) | U3: 教育訓練-實施率(進度/計畫)
F4: 日 | G4: 週平均 | H4: 月平均 | I4: 日 | J4: 週平均 | K4: 月平均 | L4: 日 | M4: 週平均 | N4: 月平均 | O4: 日 | P4: 週平均 | Q4: 月平均 | R4: 日 | S4: 週平均 | T4: 月平均 | U4: 日 | V4: 週平均 | W4: 月平均
B5: 45937 | C5: 十 | D5: 45931 | E5: 三 | F5: 105.8 | G5: =AVERAGE(F5:F10) -> 101.83333 | H5: =AVERAGE(F5:F35) -> 101.83333 | I5: =F5/$C$1 -> 0.91760624 | J5: =AVERAGE(I5:I10) -> 0.88320324 | K5: =AVERAGE(I5:I35) -> 0.17094256 | L5: 0.00148 | M5: =AVERAGE(L5:L10) -> 0.01019 | N5: =AVERAGE(L5:L35) -> 0.01019 | O5: 0.0043 | P5: =AVERAGE(O5:O10) -> 0.00355 | Q5: =AVERAGE(O5:O35) -> 0.00355 | R5: 0.429 | S5: =AVERAGE(R5:R10) -> 0.429 | T5: =AVERAGE(R5:R35) -> 0.429 | U5: 0.7 | V5: =AVERAGE(U5:U10) -> 0.7 | W5: =AVERAGE(U5:U35) -> 0.7
D6: 45932 | E6: 四 | F6: 100.8 | I6: =F6/$C$1 -> 0.87424111 | L6: 0.00791 | O6: 0.0033 | R6: 0.429 | U6: 0.7
D7: 45933 | E7: 五 | F7: 99 | I7: =F7/$C$1 -> 0.85862966 | L7: 0.0086 | O7: 0.002 | R7: 0.429 | U7: 0.7
D8: 45934 | E8: 六 | F8: 105.1 | I8: =F8/$C$1 -> 0.91153513 | L8: 0.00492 | O8: 0.0047 | R8: 0.429 | U8: 0.7
D9: 45935 | E9: 日 | F9: 100.7 | I9: =F9/$C$1 -> 0.87337381 | L9: 0.0083 | O9: 0.0023 | R9: 0.429 | U9: 0.7
D10: 45936 | E10: 一 | F10: 99.6 | I10: =F10/$C$1 -> 0.86383348 | L10: 0.02993 | O10: 0.0047 | R10: 0.429 | U10: 0.7
B11: 45944 | D11: 45937 | E11: 二 | G11: =AVERAGE(F11:F17) -> #DIV/0! | I11: =F11/$C$1 -> 0 | J11: =AVERAGE(I11:I17) -> 0 | M11: =AVERAGE(L11:L17) -> #DIV/0! | P11: =AVERAGE(O11:O17) -> #DIV/0! | S11: =AVERAGE(R11:R17) -> #DIV/0! | V11: =AVERAGE(U11:U17) -> #DIV/0!
D12: 45938 | E12: 三 | I12: =F12/$C$1 -> 0
D13: 45939 | E13: 四 | I13: =F13/$C$1 -> 0
D14: 45940 | E14: 五 | I14: =F14/$C$1 -> 0
D15: 45941 | E15: 六 | I15: =F15/$C$1 -> 0
D16: 45942 | E16: 日 | I16: =F16/$C$1 -> 0
D17: 45943 | E17: 一 | I17: =F17/$C$1 -> 0
B18: 45951 | D18: 45944 | E18: 二 | G18: =AVERAGE(F18:F24) -> #DIV/0! | I18: =F18/$C$1 -> 0 | J18: =AVERAGE(I18:I24) -> 0 | M18: =AVERAGE(L18:L24) -> #DIV/0! | P18: =AVERAGE(O18:O24) -> #DIV/0! | S18: =AVERAGE(R18:R24) -> #DIV/0! | V18: =AVERAGE(U18:U24) -> #DIV/0!
D19: 45945 | E19: 三 | I19: =F19/$C$1 -> 0
D20: 45946 | E20: 四 | I20: =F20/$C$1 -> 0
D21: 45947 | E21: 五 | I21: =F21/$C$1 -> 0
D22: 45948 | E22: 六 | I22: =F22/$C$1 -> 0
D23: 45949 | E23: 日 | I23: =F23/$C$1 -> 0
D24: 45950 | E24: 一 | I24: =F24/$C$1 -> 0
B25: 45958 | D25: 45951 | E25: 二 | G25: =AVERAGE(F25:F31) -> #DIV/0! | I25: =F25/$C$1 -> 0 | J25: =AVERAGE(I25:I31) -> 0 | M25: =AVERAGE(L25:L31) -> #DIV/0! | P25: =AVERAGE(O25:O31) -> #DIV/0! | S25: =AVERAGE(R25:R31) -> #DIV/0! | V25: =AVERAGE(U25:U31) -> #DIV/0!
D26: 45952 | E26: 三 | I26: =F26/$C$1 -> 0
D27: 45953 | E27: 四 | I27: =F27/$C$1 -> 0
D28: 45954 | E28: 五 | I28: =F28/$C$1 -> 0
D29: 45955 | E29: 六 | I29: =F29/$C$1 -> 0
D30: 45956 | E30: 日 | I30: =F30/$C$1 -> 0
D31: 45957 | E31: 一 | I31: =F31/$C$1 -> 0
D32: 45958 | E32: 二 | I32: =F32/$C$1 -> 0
D33: 45959 | E33: 三 | I33: =F33/$C$1 -> 0
D34: 45960 | E34: 四 | I34: =F34/$C$1 -> 0
D35: 45961 | E35: 五 | I35: =F35/$C$1 -> 0
I36: =F36/$C$1 -> 0
G37: =AVERAGE(F37:F43) -> #DIV/0! | I37: =F37/$C$1 -> 0 | J37: =AVERAGE(I37:I43) -> 0 | M37: =AVERAGE(L37:L43) -> #DIV/0! | P37: =AVERAGE(O37:O43) -> #DIV/0! | S37: =AVERAGE(R37:R43) -> #DIV/0! | V37: =AVERAGE(U37:U43) -> #DIV/0!
I38: =F38/$C$1 -> 0
I39: =F39/$C$1 -> 0
I40: =F40/$C$1 -> 0
...

Sheet （３）業績構成比
B2: （3）業績構成比
B3: 資料繳交日 | C3: 月份 | D3: 日期 | F3: 營業額 | I3: 品類業績
I4: 熱食義麵 | K4: 季節調理麵 | M4: 微波小吃
F5: 日 | G5: 週累積 | H5: 月累積 | I5: 一配 | K5: 一配 | M5: 一配
I6: 業績(元) | J6: 比例(%) | K6: 業績(元) | L6: 比例(%) | M6: 業績(元) | N6: 比例(%)
B7: 45937 | C7: 十 | D7: 45931 | E7: 三 | F7: =SUM(I7,K7,M7) -> 2824753 | G7: =SUM(F7:F12) -> 13981868 | H7: =SUM(F7:F37) -> 13981868 | I7: 2501030.4 | J7: =I7/F7 -> 0.8853979 | L7: =K7/F7 -> 0 | M7: 323722.61 | N7: =M7/F7 -> 0.1146021
D8: 45932 | E8: 四 | F8: =SUM(I8,K8,M8) -> 2491478.9 | I8: 2296406.1 | J8: =I8/F8 -> 0.92170402 | L8: =K8/F8 -> 0 | M8: 195072.79 | N8: =M8/F8 -> 0.078295984
D9: 45933 | E9: 五 | F9: =SUM(I9,K9,M9) -> 1927390 | I9: 1771863.6 | J9: =I9/F9 -> 0.91930726 | L9: =K9/F9 -> 0 | M9: 155526.39 | N9: =M9/F9 -> 0.080692745
D10: 45934 | E10: 六 | F10: =SUM(I10,K10,M10) -> 1927172.3 | I10: 1766457.8 | J10: =I10/F10 -> 0.91660605 | L10: =K10/F10 -> 0 | M10: 160714.5 | N10: =M10/F10 -> 0.083393946
D11: 45935 | E11: 日 | F11: =SUM(I11,K11,M11) -> 2140557.9 | I11: 1964601 | J11: =I11/F11 -> 0.91779858 | L11: =K11/F11 -> 0 | M11: 175956.91 | N11: =M11/F11 -> 0.082201424
D12: 45936 | E12: 一 | F12: =SUM(I12,K12,M12) -> 2670515.5 | I12: 2432019.1 | J12: =I12/F12 -> 0.91069274 | L12: =K12/F12 -> 0 | M12: 238496.41 | N12: =M12/F12 -> 0.089307255
B13: 45944 | D13: 45937 | E13: 二 | F13: =SUM(I13,K13,M13) -> 0 | G13: =SUM(F13:F19) -> 0 | J13: =I13/F13 -> #DIV/0! | L13: =K13/F13 -> #DIV/0! | N13: =M13/F13 -> #DIV/0!
D14: 45938 | E14: 三 | F14: =SUM(I14,K14,M14) -> 0 | J14: =I14/F14 -> #DIV/0! | L14: =K14/F14 -> #DIV/0! | N14: =M14/F14 -> #DIV/0!
D15: 45939 | E15: 四 | F15: =SUM(I15,K15,M15) -> 0 | J15: =I15/F15 -> #DIV/0! | L15: =K15/F15 -> #DIV/0! | N15: =M15/F15 -> #DIV/0!
D16: 45940 | E16: 五 | F16: =SUM(I16,K16,M16) -> 0 | J16: =I16/F16 -> #DIV/0! | L16: =K16/F16 -> #DIV/0! | N16: =M16/F16 -> #DIV/0!
D17: 45941 | E17: 六 | F17: =SUM(I17,K17,M17) -> 0 | J17: =I17/F17 -> #DIV/0! | L17: =K17/F17 -> #DIV/0! | N17: =M17/F17 -> #DIV/0!
D18: 45942 | E18: 日 | F18: =SUM(I18,K18,M18) -> 0 | J18: =I18/F18 -> #DIV/0! | L18: =K18/F18 -> #DIV/0! | N18: =M18/F18 -> #DIV/0!
D19: 45943 | E19: 一 | F19: =SUM(I19,K19,M19) -> 0 | J19: =I19/F19 -> #DIV/0! | L19: =K19/F19 -> #DIV/0! | N19: =M19/F19 -> #DIV/0!
B20: 45951 | D20: 45944 | E20: 二 | F20: =SUM(I20,K20,M20) -> 0 | G20: =SUM(F20:F26) -> 0 | J20: =I20/F20 -> #DIV/0! | L20: =K20/F20 -> #DIV/0! | N20: =M20/F20 -> #DIV/0!
D21: 45945 | E21: 三 | F21: =SUM(I21,K21,M21) -> 0 | J21: =I21/F21 -> #DIV/0! | L21: =K21/F21 -> #DIV/0! | N21: =M21/F21 -> #DIV/0!
D22: 45946 | E22: 四 | F22: =SUM(I22,K22,M22) -> 0 | J22: =I22/F22 -> #DIV/0! | L22: =K22/F22 -> #DIV/0! | N22: =M22/F22 -> #DIV/0!
D23: 45947 | E23: 五 | F23: =SUM(I23,K23,M23) -> 0 | J23: =I23/F23 -> #DIV/0! | L23: =K23/F23 -> #DIV/0! | N23: =M23/F23 -> #DIV/0!
D24: 45948 | E24: 六 | F24: =SUM(I24,K24,M24) -> 0 | J24: =I24/F24 -> #DIV/0! | L24: =K24/F24 -> #DIV/0! | N24: =M24/F24 -> #DIV/0!
D25: 45949 | E25: 日 | F25: =SUM(I25,K25,M25) -> 0 | J25: =I25/F25 -> #DIV/0! | L25: =K25/F25 -> #DIV/0! | N25: =M25/F25 -> #DIV/0!
D26: 45950 | E26: 一 | F26: =SUM(I26,K26,M26) -> 0 | J26: =I26/F26 -> #DIV/0! | L26: =K26/F26 -> #DIV/0! | N26: =M26/F26 -> #DIV/0!
B27: 45958 | D27: 45951 | E27: 二 | F27: =SUM(I27,K27,M27) -> 0 | G27: =SUM(F27:F33) -> 0 | J27: =I27/F27 -> #DIV/0! | L27: =K27/F27 -> #DIV/0! | N27: =M27/F27 -> #DIV/0!
D28: 45952 | E28: 三 | F28: =SUM(I28,K28,M28) -> 0 | J28: =I28/F28 -> #DIV/0! | L28: =K28/F28 -> #DIV/0! | N28: =M28/F28 -> #DIV/0!
D29: 45953 | E29: 四 | F29: =SUM(I29,K29,M29) -> 0 | J29: =I29/F29 -> #DIV/0! | L29: =K29/F29 -> #DIV/0! | N29: =M29/F29 -> #DIV/0!
D30: 45954 | E30: 五 | F30: =SUM(I30,K30,M30) -> 0 | J30: =I30/F30 -> #DIV/0! | L30: =K30/F30 -> #DIV/0! | N30: =M30/F30 -> #DIV/0!
D31: 45955 | E31: 六 | F31: =SUM(I31,K31,M31) -> 0 | J31: =I31/F31 -> #DIV/0! | L31: =K31/F31 -> #DIV/0! | N31: =M31/F31 -> #DIV/0!
D32: 45956 | E32: 日 | F32: =SUM(I32,K32,M32) -> 0 | J32: =I32/F32 -> #DIV/0! | L32: =K32/F32 -> #DIV/0! | N32: =M32/F32 -> #DIV/0!
D33: 45957 | E33: 一 | F33: =SUM(I33,K33,M33) -> 0 | J33: =I33/F33 -> #DIV/0! | L33: =K33/F33 -> #DIV/0! | N33: =M33/F33 -> #DIV/0!
D34: 45958 | E34: 二 | F34: =SUM(I34,K34,M34) -> 0 | J34: =I34/F34 -> #DIV/0! | L34: =K34/F34 -> #DIV/0! | N34: =M34/F34 -> #DIV/0!
D35: 45959 | E35: 三 | F35: =SUM(I35,K35,M35) -> 0 | J35: =I35/F35 -> #DIV/0! | L35: =K35/F35 -> #DIV/0! | N35: =M35/F35 -> #DIV/0!
D36: 45960 | E36: 四 | F36: =SUM(I36,K36,M36) -> 0 | J36: =I36/F36 -> #DIV/0! | L36: =K36/F36 -> #DIV/0! | N36: =M36/F36 -> #DIV/0!
D37: 45961 | E37: 五 | F37: =SUM(I37,K37,M37) -> 0 | J37: =I37/F37 -> #DIV/0! | L37: =K37/F37 -> #DIV/0! | N37: =M37/F37 -> #DIV/0!
F38: =SUM(I38,K38,M38) -> 0 | J38: =I38/F38 -> #DIV/0! | L38: =K38/F38 -> #DIV/0! | N38: =M38/F38 -> #DIV/0!
F39: =SUM(I39,K39,M39) -> 0 | G39: =SUM(F39:F45) -> 0 | J39: =I39/F39 -> #DIV/0! | L39: =K39/F39 -> #DIV/0! | N39: =M39/F39 -> #DIV/0!
F40: =SUM(I40,K40,M40) -> 0 | J40: =I40/F40 -> #DIV/0! | L40: =K40/F40 -> #DIV/0! | N40: =M40/F40 -> #DIV/0!
F41: =SUM(I41,K41,M41) -> 0 | J41: =I41/F41 -> #DIV/0! | L41: =K41/F41 -> #DIV/0! | N41: =M41/F41 -> #DIV/0!
...

Sheet （４）訂單數量構成比
B2: （4）訂單數量構成比
B3: 資料繳交日 | C3: 月份 | D3: 日期 | F3: 訂單量 | I3: 品類訂單量
I4: 熱食義麵 | K4: 季節調理麵 | M4: 微波小吃
F5: 日 | G5: 週累積 | H5: 月累積 | I5: 一配 | K5: 一配 | M5: 一配
I6: 訂單數 | J6: 比例(%) | K6: 訂單數 | L6: 比例(%) | M6: 訂單數 | N6: 比例(%)
B7: 45937 | C7: 十 | D7: 45931 | E7: 三 | F7: =SUM(I7,K7,M7) -> 59618 | G7: =SUM(F7:F12) -> 289645 | H7: =SUM(F7:F37) -> 289645 | I7: 47989 | J7: =I7/F7 -> 0.80494146 | L7: =K7/F7 -> 0 | M7: 11629 | N7: =M7/F7 -> 0.19505854
D8: 45932 | E8: 四 | F8: =SUM(I8,K8,M8) -> 51111 | I8: 44028 | J8: =I8/F8 -> 0.86141926 | L8: =K8/F8 -> 0 | M8: 7083 | N8: =M8/F8 -> 0.13858074
D9: 45933 | E9: 五 | F9: =SUM(I9,K9,M9) -> 39570 | I9: 33924 | J9: =I9/F9 -> 0.85731615 | L9: =K9/F9 -> 0 | M9: 5646 | N9: =M9/F9 -> 0.14268385
D10: 45934 | E10: 六 | F10: =SUM(I10,K10,M10) -> 39717 | I10: 33895 | J10: =I10/F10 -> 0.8534129 | L10: =K10/F10 -> 0 | M10: 5822 | N10: =M10/F10 -> 0.1465871
D11: 45935 | E11: 日 | F11: =SUM(I11,K11,M11) -> 44134 | I11: 37758 | J11: =I11/F11 -> 0.85553088 | L11: =K11/F11 -> 0 | M11: 6376 | N11: =M11/F11 -> 0.14446912
D12: 45936 | E12: 一 | F12: =SUM(I12,K12,M12) -> 55495 | I12: 46852 | J12: =I12/F12 -> 0.84425624 | L12: =K12/F12 -> 0 | M12: 8643 | N12: =M12/F12 -> 0.15574376
B13: 45944 | D13: 45937 | E13: 二 | F13: =SUM(I13,K13,M13) -> 0 | G13: =SUM(F13:F18) -> 0 | J13: =I13/F13 -> #DIV/0! | L13: =K13/F13 -> #DIV/0! | N13: =M13/F13 -> #DIV/0!
D14: 45938 | E14: 三 | F14: =SUM(I14,K14,M14) -> 0 | J14: =I14/F14 -> #DIV/0! | L14: =K14/F14 -> #DIV/0! | N14: =M14/F14 -> #DIV/0!
D15: 45939 | E15: 四 | F15: =SUM(I15,K15,M15) -> 0 | J15: =I15/F15 -> #DIV/0! | L15: =K15/F15 -> #DIV/0! | N15: =M15/F15 -> #DIV/0!
D16: 45940 | E16: 五 | F16: =SUM(I16,K16,M16) -> 0 | J16: =I16/F16 -> #DIV/0! | L16: =K16/F16 -> #DIV/0! | N16: =M16/F16 -> #DIV/0!
D17: 45941 | E17: 六 | F17: =SUM(I17,K17,M17) -> 0 | J17: =I17/F17 -> #DIV/0! | L17: =K17/F17 -> #DIV/0! | N17: =M17/F17 -> #DIV/0!
D18: 45942 | E18: 日 | F18: =SUM(I18,K18,M18) -> 0 | J18: =I18/F18 -> #DIV/0! | L18: =K18/F18 -> #DIV/0! | N18: =M18/F18 -> #DIV/0!
D19: 45943 | E19: 一 | F19: =SUM(I19,K19,M19) -> 0 | J19: =I19/F19 -> #DIV/0! | L19: =K19/F19 -> #DIV/0! | N19: =M19/F19 -> #DIV/0!
B20: 45951 | D20: 45944 | E20: 二 | F20: =SUM(I20,K20,M20) -> 0 | G20: =SUM(F20:F25) -> 0 | J20: =I20/F20 -> #DIV/0! | L20: =K20/F20 -> #DIV/0! | N20: =M20/F20 -> #DIV/0!
D21: 45945 | E21: 三 | F21: =SUM(I21,K21,M21) -> 0 | J21: =I21/F21 -> #DIV/0! | L21: =K21/F21 -> #DIV/0! | N21: =M21/F21 -> #DIV/0!
D22: 45946 | E22: 四 | F22: =SUM(I22,K22,M22) -> 0 | J22: =I22/F22 -> #DIV/0! | L22: =K22/F22 -> #DIV/0! | N22: =M22/F22 -> #DIV/0!
D23: 45947 | E23: 五 | F23: =SUM(I23,K23,M23) -> 0 | J23: =I23/F23 -> #DIV/0! | L23: =K23/F23 -> #DIV/0! | N23: =M23/F23 -> #DIV/0!
D24: 45948 | E24: 六 | F24: =SUM(I24,K24,M24) -> 0 | J24: =I24/F24 -> #DIV/0! | L24: =K24/F24 -> #DIV/0! | N24: =M24/F24 -> #DIV/0!
D25: 45949 | E25: 日 | F25: =SUM(I25,K25,M25) -> 0 | J25: =I25/F25 -> #DIV/0! | L25: =K25/F25 -> #DIV/0! | N25: =M25/F25 -> #DIV/0!
D26: 45950 | E26: 一 | F26: =SUM(I26,K26,M26) -> 0 | J26: =I26/F26 -> #DIV/0! | L26: =K26/F26 -> #DIV/0! | N26: =M26/F26 -> #DIV/0!
B27: 45958 | D27: 45951 | E27: 二 | F27: =SUM(I27,K27,M27) -> 0 | G27: =SUM(F27:F32) -> 0 | J27: =I27/F27 -> #DIV/0! | L27: =K27/F27 -> #DIV/0! | N27: =M27/F27 -> #DIV/0!
D28: 45952 | E28: 三 | F28: =SUM(I28,K28,M28) -> 0 | J28: =I28/F28 -> #DIV/0! | L28: =K28/F28 -> #DIV/0! | N28: =M28/F28 -> #DIV/0!
D29: 45953 | E29: 四 | F29: =SUM(I29,K29,M29) -> 0 | J29: =I29/F29 -> #DIV/0! | L29: =K29/F29 -> #DIV/0! | N29: =M29/F29 -> #DIV/0!
D30: 45954 | E30: 五 | F30: =SUM(I30,K30,M30) -> 0 | J30: =I30/F30 -> #DIV/0! | L30: =K30/F30 -> #DIV/0! | N30: =M30/F30 -> #DIV/0!
D31: 45955 | E31: 六 | F31: =SUM(I31,K31,M31) -> 0 | J31: =I31/F31 -> #DIV/0! | L31: =K31/F31 -> #DIV/0! | N31: =M31/F31 -> #DIV/0!
D32: 45956 | E32: 日 | F32: =SUM(I32,K32,M32) -> 0 | J32: =I32/F32 -> #DIV/0! | L32: =K32/F32 -> #DIV/0! | N32: =M32/F32 -> #DIV/0!
D33: 45957 | E33: 一 | F33: =SUM(I33,K33,M33) -> 0 | J33: =I33/F33 -> #DIV/0! | L33: =K33/F33 -> #DIV/0! | N33: =M33/F33 -> #DIV/0!
D34: 45958 | E34: 二 | F34: =SUM(I34,K34,M34) -> 0 | J34: =I34/F34 -> #DIV/0! | L34: =K34/F34 -> #DIV/0! | N34: =M34/F34 -> #DIV/0!
D35: 45959 | E35: 三 | F35: =SUM(I35,K35,M35) -> 0 | J35: =I35/F35 -> #DIV/0! | L35: =K35/F35 -> #DIV/0! | N35: =M35/F35 -> #DIV/0!
D36: 45960 | E36: 四 | F36: =SUM(I36,K36,M36) -> 0 | J36: =I36/F36 -> #DIV/0! | L36: =K36/F36 -> #DIV/0! | N36: =M36/F36 -> #DIV/0!
D37: 45961 | E37: 五 | F37: =SUM(I37,K37,M37) -> 0 | J37: =I37/F37 -> #DIV/0! | L37: =K37/F37 -> #DIV/0! | N37: =M37/F37 -> #DIV/0!

Sheet （５-1）品群別人時生產性（熱食義麵）
B1: 月平均人時性 | C1: =AVERAGE(L7,L30,L53,L73,L96) -> 96.176076
B2: 產線配置圖－每週更新 | N2: 資料繳交 | O2: 日期 | U2: 45931 | Z2: 45932 | AE2: 45933 | AJ2: 45934 | AO2: 45935 | AT2: 45936
P3: 二 | U3: 三 | Z3: 四 | AE3: 五 | AJ3: 六 | AO3: 日 | AT3: 一
B4: 品群 | C4: 商品名稱 | E4: 計畫 | H4: 平均人時性 | I4: 實績 | L4: 平均人時性 | M4: 排名 | O4: 日報 | P4: 實際 | T4: 平均人時性 | U4: 實際 | Y4: 平均人時性 | Z4: 實際 | AD4: 平均人時性 | AE4: 實際 | AI4: 平均人時性 | AJ4: 實際 | AN4: 平均人時性 | AO4: 實際 | AS4: 平均人時性 | AT4: 實際 | AX4: 平均人時性
E5: 產線配置圖 | I5: 產線配置圖 | P5: 生產實績 | U5: 生產實績 | Z5: 生產實績 | AE5: 生產實績 | AJ5: 生產實績 | AO5: 生產實績 | AT5: 生產實績
E6: 人數 | F6: 產能／時 | G6: 人時性 | I6: 人數 | J6: 產能／時 | K6: 人時性 | P6: 人數 | Q6: 產能／時 | R6: 人時性 | S6: 排名 | U6: 人數 | V6: 產能／時 | W6: 人時性 | X6: 排名 | Z6: 人數 | AA6: 產能／時 | AB6: 人時性 | AC6: 排名 | AE6: 人數 | AF6: 產能／時 | AG6: 人時性 | AH6: 排名 | AJ6: 人數 | AK6: 產能／時 | AL6: 人時性 | AM6: 排名 | AO6: 人數 | AP6: 產能／時 | AQ6: 人時性 | AR6: 排名 | AT6: 人數 | AU6: 產能／時 | AV6: 人時性 | AW6: 排名
B7: 熱食義麵 | C7: 1 | D7: 義式蕃茄起司義大利麵 | E7: =VLOOKUP(D7,'10產線配置圖'!$A$2:$C$25,2,0) -> 12 | F7: =VLOOKUP(D7,'10產線配置圖'!$A$2:$C$25,3,0) -> 2000 | G7: =F7/E7 -> 166.66667 | H7: =AVERAGE(G7:G24) -> 110.95405 | I7: =AVERAGE(P7,U7,Z7,AE7,AJ7,AO7,AT7) -> 12 | J7: =AVERAGE(Q7,V7,AA7,AF7,AK7,AP7,AU7) -> 1795 | K7: =AVERAGE(W7,AB7,AG7,AL7,AQ7,AV7) -> 149.58333 | L7: =IFERROR(AVERAGE(K7:K24),"-") -> 96.176076 | M7: =RANK(K7, K$7:$K$24) -> 1 | R7: =Q7/P7 -> #DIV/0! | S7: =RANK(R7, R$7:R$24) -> #DIV/0! | T7: =AVERAGE(R7:R24) -> #DIV/0! | U7: 12 | V7: 1730 | W7: =V7/U7 -> 144.16667 | X7: =RANK(W7, W$7:W$24) -> 1 | Y7: =AVERAGE(W7:W24) -> 94.697243 | Z7: 12 | AA7: 1553 | AB7: =AA7/Z7 -> 129.41667 | AC7: =RANK(AB7, AB$7:AB$24) -> 3 | AD7: =AVERAGE(AB7:AB24) -> 93.019608 | AE7: 12 | AF7: 1948 | AG7: =AF7/AE7 -> 162.33333 | AH7: =RANK(AG7, AG$7:AG$24) -> 1 | AI7: =AVERAGE(AG7:AG24) -> 97.425233 | AJ7: 12 | AK7: 1899 | AL7: =AK7/AJ7 -> 158.25 | AM7: =RANK(AL7, AL$7:AL$24) -> 1 | AN7: =AVERAGE(AL7:AL24) -> 99.758354 | AO7: 12 | AP7: 1820 | AQ7: =AP7/AO7 -> 151.66667 | AR7: =RANK(AQ7, AQ$7:AQ$24) -> 1 | AS7: =AVERAGE(AQ7:AQ24) -> 98.443947 | AT7: 12 | AU7: 1820 | AV7: =AU7/AT7 -> 151.66667 | AW7: =RANK(AV7, AV$7:AV$24) -> 1 | AX7: =AVERAGE(AV7:AV24) -> 96.157874
C8: 2 | D8: 奶油培根義大利麵 | E8: =VLOOKUP(D8,'10產線配置圖'!$A$2:$C$25,2,0) -> 13 | F8: =VLOOKUP(D8,'10產線配置圖'!$A$2:$C$25,3,0) -> 2000 | G8: =F8/E8 -> 153.84615 | I8: =AVERAGE(P8,U8,Z8,AE8,AJ8,AO8,AT8) -> 13 | J8: =AVERAGE(Q8,V8,AA8,AF8,AK8,AP8,AU8) -> 1826.5 | K8: =AVERAGE(W8,AB8,AG8,AL8,AQ8,AV8) -> 140.5 | M8: =RANK(K8, K$7:$K$24) -> 2 | R8: =Q8/P8 -> #DIV/0! | S8: =RANK(R8, R$7:R$24) -> #DIV/0! | U8: 13 | V8: 1829 | W8: =V8/U8 -> 140.69231 | X8: =RANK(W8, W$7:W$24) -> 2 | Z8: 13 | AA8: 1785 | AB8: =AA8/Z8 -> 137.30769 | AC8: =RANK(AB8, AB$7:AB$24) -> 2 | AE8: 13 | AF8: 1911 | AG8: =AF8/AE8 -> 147 | AH8: =RANK(AG8, AG$7:AG$24) -> 2 | AJ8: 13 | AK8: 1758 | AL8: =AK8/AJ8 -> 135.23077 | AM8: =RANK(AL8, AL$7:AL$24) -> 3 | AO8: 13 | AP8: 1934 | AQ8: =AP8/AO8 -> 148.76923 | AR8: =RANK(AQ8, AQ$7:AQ$24) -> 2 | AT8: 13 | AU8: 1742 | AV8: =AU8/AT8 -> 134 | AW8: =RANK(AV8, AV$7:AV$24) -> 2
C9: 3 | D9: 熱那亞青醬義大利麵 | E9: =VLOOKUP(D9,'10產線配置圖'!$A$2:$C$25,2,0) -> 16 | F9: =VLOOKUP(D9,'10產線配置圖'!$A$2:$C$25,3,0) -> 1915 | G9: =F9/E9 -> 119.6875 | I9: =AVERAGE(P9,U9,Z9,AE9,AJ9,AO9,AT9) -> 16 | J9: =AVERAGE(Q9,V9,AA9,AF9,AK9,AP9,AU9) -> 1579.5 | K9: =AVERAGE(W9,AB9,AG9,AL9,AQ9,AV9) -> 98.71875 | M9: =RANK(K9, K$7:$K$24) -> 5 | R9: =Q9/P9 -> #DIV/0! | S9: =RANK(R9, R$7:R$24) -> #DIV/0! | U9: 16 | V9: 1557 | W9: =V9/U9 -> 97.3125 | X9: =RANK(W9, W$7:W$24) -> 5 | Z9: 16 | AA9: 1657 | AB9: =AA9/Z9 -> 103.5625 | AC9: =RANK(AB9, AB$7:AB$24) -> 4 | AE9: 16 | AF9: 1620 | AG9: =AF9/AE9 -> 101.25 | AH9: =RANK(AG9, AG$7:AG$24) -> 6 | AJ9: 16 | AK9: 1538 | AL9: =AK9/AJ9 -> 96.125 | AM9: =RANK(AL9, AL$7:AL$24) -> 5 | AO9: 16 | AP9: 1564 | AQ9: =AP9/AO9 -> 97.75 | AR9: =RANK(AQ9, AQ$7:AQ$24) -> 5 | AT9: 16 | AU9: 1541 | AV9: =AU9/AT9 -> 96.3125 | AW9: =RANK(AV9, AV$7:AV$24) -> 5
C10: 4 | D10: 焗烤起司雙饗筆尖麵 | E10: =VLOOKUP(D10,'10產線配置圖'!$A$2:$C$25,2,0) -> 18 | F10: =VLOOKUP(D10,'10產線配置圖'!$A$2:$C$25,3,0) -> 1565 | G10: =F10/E10 -> 86.944444 | I10: =AVERAGE(P10,U10,Z10,AE10,AJ10,AO10,AT10) -> 18 | J10: =AVERAGE(Q10,V10,AA10,AF10,AK10,AP10,AU10) -> 1539.5 | K10: =AVERAGE(W10,AB10,AG10,AL10,AQ10,AV10) -> 85.527778 | M10: =RANK(K10, K$7:$K$24) -> 8 | R10: =Q10/P10 -> #DIV/0! | S10: =RANK(R10, R$7:R$24) -> #DIV/0! | U10: 18 | V10: 1515 | W10: =V10/U10 -> 84.166667 | X10: =RANK(W10, W$7:W$24) -> 8 | Z10: 18 | AA10: 1545 | AB10: =AA10/Z10 -> 85.833333 | AC10: =RANK(AB10, AB$7:AB$24) -> 7 | AE10: 18 | AF10: 1561 | AG10: =AF10/AE10 -> 86.722222 | AH10: =RANK(AG10, AG$7:AG$24) -> 7 | AJ10: 18 | AK10: 1564 | AL10: =AK10/AJ10 -> 86.888889 | AM10: =RANK(AL10, AL$7:AL$24) -> 8 | AO10: 18 | AP10: 1550 | AQ10: =AP10/AO10 -> 86.111111 | AR10: =RANK(AQ10, AQ$7:AQ$24) -> 9 | AT10: 18 | AU10: 1502 | AV10: =AU10/AT10 -> 83.444444 | AW10: =RANK(AV10, AV$7:AV$24) -> 8
C11: 5 | D11: 白酒蛤蜊義大利麵 | E11: =VLOOKUP(D11,'10產線配置圖'!$A$2:$C$25,2,0) -> 13 | F11: =VLOOKUP(D11,'10產線配置圖'!$A$2:$C$25,3,0) -> 2000 | G11: =F11/E11 -> 153.84615 | I11: =AVERAGE(P11,U11,Z11,AE11,AJ11,AO11,AT11) -> 13.166667 | J11: =AVERAGE(Q11,V11,AA11,AF11,AK11,AP11,AU11) -> 1775 | K11: =AVERAGE(W11,AB11,AG11,AL11,AQ11,AV11) -> 134.9185 | M11: =RANK(K11, K$7:$K$24) -> 3 | R11: =Q11/P11 -> #DIV/0! | S11: =RANK(R11, R$7:R$24) -> #DIV/0! | U11: 13 | V11: 1684 | W11: =V11/U11 -> 129.53846 | X11: =RANK(W11, W$7:W$24) -> 3 | Z11: 13 | AA11: 1900 | AB11: =AA11/Z11 -> 146.15385 | AC11: =RANK(AB11, AB$7:AB$24) -> 1 | AE11: 13 | AF11: 1679 | AG11: =AF11/AE11 -> 129.15385 | AH11: =RANK(AG11, AG$7:AG$24) -> 3 | AJ11: 13 | AK11: 1852 | AL11: =AK11/AJ11 -> 142.46154 | AM11: =RANK(AL11, AL$7:AL$24) -> 2 | AO11: 13 | AP11: 1766 | AQ11: =AP11/AO11 -> 135.84615 | AR11: =RANK(AQ11, AQ$7:AQ$24) -> 3 | AT11: 14 | AU11: 1769 | AV11: =AU11/AT11 -> 126.35714 | AW11: =RANK(AV11, AV$7:AV$24) -> 4
C12: 6 | D12: 韓式起司炸雞義大利麵 | E12: =VLOOKUP(D12,'10產線配置圖'!$A$2:$C$25,2,0) -> 14 | F12: =VLOOKUP(D12,'10產線配置圖'!$A$2:$C$25,3,0) -> 1895 | G12: =F12/E12 -> 135.35714 | I12: =AVERAGE(P12,U12,Z12,AE12,AJ12,AO12,AT12) -> 14.166667 | J12: =AVERAGE(Q12,V12,AA12,AF12,AK12,AP12,AU12) -> 1610 | K12: =AVERAGE(W12,AB12,AG12,AL12,AQ12,AV12) -> 113.72222 | M12: =RANK(K12, K$7:$K$24) -> 4 | R12: =Q12/P12 -> #DIV/0! | S12: =RANK(R12, R$7:R$24) -> #DIV/0! | U12: 15 | V12: 1610 | W12: =V12/U12 -> 107.33333 | X12: =RANK(W12, W$7:W$24) -> 4 | Z12: 14 | AA12: 1273 | AB12: =AA12/Z12 -> 90.928571 | AC12: =RANK(AB12, AB$7:AB$24) -> 5 | AE12: 14 | AF12: 1556 | AG12: =AF12/AE12 -> 111.14286 | AH12: =RANK(AG12, AG$7:AG$24) -> 4 | AJ12: 14 | AK12: 1734 | AL12: =AK12/AJ12 -> 123.85714 | AM12: =RANK(AL12, AL$7:AL$24) -> 4 | AO12: 14 | AP12: 1661 | AQ12: =AP12/AO12 -> 118.64286 | AR12: =RANK(AQ12, AQ$7:AQ$24) -> 4 | AT12: 14 | AU12: 1826 | AV12: =AU12/AT12 -> 130.42857 | AW12: =RANK(AV12, AV$7:AV$24) -> 3
C13: 7 | D13: 拿坡里義大利麵 | E13: =VLOOKUP(D13,'10產線配置圖'!$A$2:$C$25,2,0) -> 16 | F13: =VLOOKUP(D13,'10產線配置圖'!$A$2:$C$25,3,0) -> 1429 | G13: =F13/E13 -> 89.3125 | I13: =AVERAGE(P13,U13,Z13,AE13,AJ13,AO13,AT13) -> 15 | J13: =AVERAGE(Q13,V13,AA13,AF13,AK13,AP13,AU13) -> 970.33333 | K13: =AVERAGE(W13,AB13,AG13,AL13,AQ13,AV13) -> 65.029762 | M13: =RANK(K13, K$7:$K$24) -> 14 | R13: =Q13/P13 -> #DIV/0! | S13: =RANK(R13, R$7:R$24) -> #DIV/0! | U13: 16 | V13: 1043 | W13: =V13/U13 -> 65.1875 | X13: =RANK(W13, W$7:W$24) -> 14 | Z13: 14 | AA13: 924 | AB13: =AA13/Z13 -> 66 | AC13: =RANK(AB13, AB$7:AB$24) -> 14 | AE13: 14 | AF13: 895 | AG13: =AF13/AE13 -> 63.928571 | AH13: =RANK(AG13, AG$7:AG$24) -> 13 | AJ13: 14 | AK13: 1127 | AL13: =AK13/AJ13 -> 80.5 | AM13: =RANK(AL13, AL$7:AL$24) -> 10 | AO13: 16 | AP13: 1019 | AQ13: =AP13/AO13 -> 63.6875 | AR13: =RANK(AQ13, AQ$7:AQ$24) -> 13 | AT13: 16 | AU13: 814 | AV13: =AU13/AT13 -> 50.875 | AW13: =RANK(AV13, AV$7:AV$24) -> 13
C14: 8 | D14: 黑胡椒燻豬腿義大利麵 | E14: =VLOOKUP(D14,'10產線配置圖'!$A$2:$C$25,2,0) -> 18 | F14: =VLOOKUP(D14,'10產線配置圖'!$A$2:$C$25,3,0) -> 1500 | G14: =F14/E14 -> 83.333333 | I14: =AVERAGE(P14,U14,Z14,AE14,AJ14,AO14,AT14) -> 15 | J14: =AVERAGE(Q14,V14,AA14,AF14,AK14,AP14,AU14) -> 1138 | K14: =AVERAGE(W14,AB14,AG14,AL14,AQ14,AV14) -> 76.056418 | M14: =RANK(K14, K$7:$K$24) -> 11 | R14: =Q14/P14 -> #DIV/0! | S14: =RANK(R14, R$7:R$24) -> #DIV/0! | U14: 16 | V14: 1301 | W14: =V14/U14 -> 81.3125 | X14: =RANK(W14, W$7:W$24) -> 9 | Z14: 15 | AA14: 1092 | AB14: =AA14/Z14 -> 72.8 | AC14: =RANK(AB14, AB$7:AB$24) -> 12 | AE14: 13 | AF14: 1017 | AG14: =AF14/AE14 -> 78.230769 | AH14: =RANK(AG14, AG$7:AG$24) -> 10 | AJ14: 15 | AK14: 1171 | AL14: =AK14/AJ14 -> 78.066667 | AM14: =RANK(AL14, AL$7:AL$24) -> 11 | AO14: 17 | AP14: 1156 | AQ14: =AP14/AO14 -> 68 | AR14: =RANK(AQ14, AQ$7:AQ$24) -> 11 | AT14: 14 | AU14: 1091 | AV14: =AU14/AT14 -> 77.928571 | AW14: =RANK(AV14, AV$7:AV$24) -> 10
C15: 9 | D15: 奶油蒜香雞義大利麵 | E15: =VLOOKUP(D15,'10產線配置圖'!$A$2:$C$25,2,0) -> 18 | F15: =VLOOKUP(D15,'10產線配置圖'!$A$2:$C$25,3,0) -> 1385 | G15: =F15/E15 -> 76.944444 | I15: =AVERAGE(P15,U15,Z15,AE15,AJ15,AO15,AT15) -> 17.166667 | J15: =AVERAGE(Q15,V15,AA15,AF15,AK15,AP15,AU15) -> 1192.3333 | K15: =AVERAGE(W15,AB15,AG15,AL15,AQ15,AV15) -> 69.317974 | M15: =RANK(K15, K$7:$K$24) -> 13 | R15: =Q15/P15 -> #DIV/0! | S15: =RANK(R15, R$7:R$24) -> #DIV/0! | U15: 17 | V15: 1290 | W15: =V15/U15 -> 75.882353 | X15: =RANK(W15, W$7:W$24) -> 12 | Z15: 18 | AA15: 1253 | AB15: =AA15/Z15 -> 69.611111 | AC15: =RANK(AB15, AB$7:AB$24) -> 13 | AE15: 15 | AF15: 952 | AG15: =AF15/AE15 -> 63.466667 | AH15: =RANK(AG15, AG$7:AG$24) -> 14 | AJ15: 18 | AK15: 1351 | AL15: =AK15/AJ15 -> 75.055556 | AM15: =RANK(AL15, AL$7:AL$24) -> 12 | AO15: 17 | AP15: 1123 | AQ15: =AP15/AO15 -> 66.058824 | AR15: =RANK(AQ15, AQ$7:AQ$24) -> 12 | AT15: 18 | AU15: 1185 | AV15: =AU15/AT15 -> 65.833333 | AW15: =RANK(AV15, AV$7:AV$24) -> 12
C16: 10 | D16: 青花椒麻雞肉拌麵 | E16: =VLOOKUP(D16,'10產線配置圖'!$A$2:$C$25,2,0) -> 17 | F16: =VLOOKUP(D16,'10產線配置圖'!$A$2:$C$25,3,0) -> 1565 | G16: =F16/E16 -> 92.058824 | I16: =AVERAGE(P16,U16,Z16,AE16,AJ16,AO16,AT16) -> 16.5 | J16: =AVERAGE(Q16,V16,AA16,AF16,AK16,AP16,AU16) -> 1434.6667 | K16: =AVERAGE(W16,AB16,AG16,AL16,AQ16,AV16) -> 86.907475 | M16: =RANK(K16, K$7:$K$24) -> 6 | R16: =Q16/P16 -> #DIV/0! | S16: =RANK(R16, R$7:R$24) -> #DIV/0! | U16: 16 | V16: 1373 | W16: =V16/U16 -> 85.8125 | X16: =RANK(W16, W$7:W$24) -> 7 | Z16: 17 | AA16: 1478 | AB16: =AA16/Z16 -> 86.941176 | AC16: =RANK(AB16, AB$7:AB$24) -> 6 | AE16: 16 | AF16: 1354 | AG16: =AF16/AE16 -> 84.625 | AH16: =RANK(AG16, AG$7:AG$24) -> 8 | AJ16: 16 | AK16: 1378 | AL16: =AK16/AJ16 -> 86.125 | AM16: =RANK(AL16, AL$7:AL$24) -> 9 | AO16: 17 | AP16: 1551 | AQ16: =AP16/AO16 -> 91.235294 | AR16: =RANK(AQ16, AQ$7:AQ$24) -> 6 | AT16: 17 | AU16: 1474 | AV16: =AU16/AT16 -> 86.705882 | AW16: =RANK(AV16, AV$7:AV$24) -> 6
C17: 11 | D17: 韓式辣醬肉丸義大利麵 | E17: =VLOOKUP(D17,'10產線配置圖'!$A$2:$C$25,2,0) -> 15 | F17: =VLOOKUP(D17,'10產線配置圖'!$A$2:$C$25,3,0) -> 1800 | G17: =F17/E17 -> 120 | I17: =AVERAGE(P17,U17,Z17,AE17,AJ17,AO17,AT17) -> 15.166667 | J17: =AVERAGE(Q17,V17,AA17,AF17,AK17,AP17,AU17) -> 1200.5 | K17: =AVERAGE(W17,AB17,AG17,AL17,AQ17,AV17) -> 79.046767 | M17: =RANK(K17, K$7:$K$24) -> 10 | R17: =Q17/P17 -> #DIV/0! | S17: =RANK(R17, R$7:R$24) -> #DIV/0! | U17: 15 | V17: 1164 | W17: =V17/U17 -> 77.6 | X17: =RANK(W17, W$7:W$24) -> 11 | Z17: 15 | AA17: 1111 | AB17: =AA17/Z17 -> 74.066667 | AC17: =RANK(AB17, AB$7:AB$24) -> 10 | AE17: 13 | AF17: 1054 | AG17: =AF17/AE17 -> 81.076923 | AH17: =RANK(AG17, AG$7:AG$24) -> 9 | AJ17: 17 | AK17: 1478 | AL17: =AK17/AJ17 -> 86.941176 | AM17: =RANK(AL17, AL$7:AL$24) -> 7 | AO17: 16 | AP17: 1233 | AQ17: =AP17/AO17 -> 77.0625 | AR17: =RANK(AQ17, AQ$7:AQ$24) -> 10 | AT17: 15 | AU17: 1163 | AV17: =AU17/AT17 -> 77.533333 | AW17: =RANK(AV17, AV$7:AV$24) -> 11
C18: 12 | D18: 家傳炸醬麵 | E18: =VLOOKUP(D18,'10產線配置圖'!$A$2:$C$25,2,0) -> 18 | F18: =VLOOKUP(D18,'10產線配置圖'!$A$2:$C$25,3,0) -> 1636 | G18: =F18/E18 -> 90.888889 | I18: =AVERAGE(P18,U18,Z18,AE18,AJ18,AO18,AT18) -> 16 | J18: =AVERAGE(Q18,V18,AA18,AF18,AK18,AP18,AU18) -> 1220.5 | K18: =AVERAGE(W18,AB18,AG18,AL18,AQ18,AV18) -> 76.055596 | M18: =RANK(K18, K$7:$K$24) -> 12 | R18: =Q18/P18 -> #DIV/0! | S18: =RANK(R18, R$7:R$24) -> #DIV/0! | U18: 15 | V18: 1176 | W18: =V18/U18 -> 78.4 | X18: =RANK(W18, W$7:W$24) -> 10 | Z18: 18 | AA18: 1317 | AB18: =AA18/Z18 -> 73.166667 | AC18: =RANK(AB18, AB$7:AB$24) -> 11 | AE18: 15 | AF18: 1114 | AG18: =AF18/AE18 -> 74.266667 | AH18: =RANK(AG18, AG$7:AG$24) -> 12 | AJ18: 15 | AK18: 893 | AL18: =AK18/AJ18 -> 59.533333 | AM18: =RANK(AL18, AL$7:AL$24) -> 13 | AO18: 17 | AP18: 1488 | AQ18: =AP18/AO18 -> 87.529412 | AR18: =RANK(AQ18, AQ$7:AQ$24) -> 7 | AT18: 16 | AU18: 1335 | AV18: =AU18/AT18 -> 83.4375 | AW18: =RANK(AV18, AV$7:AV$24) -> 9
C19: 13 | D19: 剝皮辣椒雞奶油扁麵 | E19: =VLOOKUP(D19,'10產線配置圖'!$A$2:$C$25,2,0) -> 17 | F19: =VLOOKUP(D19,'10產線配置圖'!$A$2:$C$25,3,0) -> 1500 | G19: =F19/E19 -> 88.235294 | I19: =AVERAGE(P19,U19,Z19,AE19,AJ19,AO19,AT19) -> 17.166667 | J19: =AVERAGE(Q19,V19,AA19,AF19,AK19,AP19,AU19) -> 1447 | K19: =AVERAGE(W19,AB19,AG19,AL19,AQ19,AV19) -> 84.374183 | M19: =RANK(K19, K$7:$K$24) -> 9 | R19: =Q19/P19 -> #DIV/0! | S19: =RANK(R19, R$7:R$24) -> #DIV/0! | U19: 17 | V19: 1484 | W19: =V19/U19 -> 87.294118 | X19: =RANK(W19, W$7:W$24) -> 6 | Z19: 17 | AA19: 1400 | AB19: =AA19/Z19 -> 82.352941 | AC19: =RANK(AB19, AB$7:AB$24) -> 9 | AE19: 18 | AF19: 1365 | AG19: =AF19/AE19 -> 75.833333 | AH19: =RANK(AG19, AG$7:AG$24) -> 11 | AJ19: 17 | AK19: 1493 | AL19: =AK19/AJ19 -> 87.823529 | AM19: =RANK(AL19, AL$7:AL$24) -> 6 | AO19: 17 | AP19: 1486 | AQ19: =AP19/AO19 -> 87.411765 | AR19: =RANK(AQ19, AQ$7:AQ$24) -> 8 | AT19: 17 | AU19: 1454 | AV19: =AU19/AT19 -> 85.529412 | AW19: =RANK(AV19, AV$7:AV$24) -> 7
C20: 14 | D20: 羊乳起司培根筆尖麵 | E20: =VLOOKUP(D20,'10產線配置圖'!$A$2:$C$25,2,0) -> 17 | F20: =VLOOKUP(D20,'10產線配置圖'!$A$2:$C$25,3,0) -> 1636 | G20: =F20/E20 -> 96.235294 | I20: =AVERAGE(P20,U20,Z20,AE20,AJ20,AO20,AT20) -> 14.666667 | J20: =AVERAGE(Q20,V20,AA20,AF20,AK20,AP20,AU20) -> 1254.3333 | K20: =AVERAGE(W20,AB20,AG20,AL20,AQ20,AV20) -> 86.706303 | M20: =RANK(K20, K$7:$K$24) -> 7 | R20: =Q20/P20 -> #DIV/0! | S20: =RANK(R20, R$7:R$24) -> #DIV/0! | U20: 16 | V20: 1137 | W20: =V20/U20 -> 71.0625 | X20: =RANK(W20, W$7:W$24) -> 13 | Z20: 15 | AA20: 1262 | AB20: =AA20/Z20 -> 84.133333 | AC20: =RANK(AB20, AB$7:AB$24) -> 8 | AE20: 13 | AF20: 1364 | AG20: =AF20/AE20 -> 104.92308 | AH20: =RANK(AG20, AG$7:AG$24) -> 5
C21: 15 | R21: =Q21/P21 -> #DIV/0! | S21: =RANK(R21, R$7:R$24) -> #DIV/0!
C22: 16 | R22: =Q22/P22 -> #DIV/0! | S22: =RANK(R22, R$7:R$24) -> #DIV/0!
C23: 17 | R23: =Q23/P23 -> #DIV/0! | S23: =RANK(R23, R$7:R$24) -> #DIV/0!
C24: 18 | R24: =Q24/P24 -> #DIV/0! | S24: =RANK(R24, R$7:R$24) -> #DIV/0!
B25: 產線配置圖－每週更新 | N25: 資料繳交 | O25: 日期 | P25: 45937 | U25: 45938 | Z25: 45939 | AE25: 45940 | AJ25: 45941 | AO25: 45942 | AT25: 45943
P26: 二 | U26: 三 | Z26: 四 | AE26: 五 | AJ26: 六 | AO26: 日 | AT26: 一
B27: 品群 | C27: 商品名稱 | E27: 計畫 | H27: 平均人時性 | I27: 實績 | L27: 平均人時性 | M27: 排名 | O27: 日報 | P27: 實際 | T27: 平均人時性 | U27: 實際 | Y27: 平均人時性 | Z27: 實際 | AD27: 平均人時性 | AE27: 實際 | AI27: 平均人時性 | AJ27: 實際 | AN27: 平均人時性 | AO27: 實際 | AS27: 平均人時性 | AT27: 實際 | AX27: 平均人時性
E28: 產線配置圖 | I28: 產線配置圖 | P28: 生產實績 | U28: 生產實績 | Z28: 生產實績 | AE28: 生產實績 | AJ28: 生產實績 | AO28: 生產實績 | AT28: 生產實績
E29: 人數 | F29: 產能／時 | G29: 人時性 | I29: 人數 | J29: 產能／時 | K29: 人時性 | P29: 人數 | Q29: 產能／時 | R29: 人時性 | S29: 排名 | U29: 人數 | V29: 產能／時 | W29: 人時性 | X29: 排名 | Z29: 人數 | AA29: 產能／時 | AB29: 人時性 | AC29: 排名 | AE29: 人數 | AF29: 產能／時 | AG29: 人時性 | AH29: 排名 | AJ29: 人數 | AK29: 產能／時 | AL29: 人時性 | AM29: 排名 | AO29: 人數 | AP29: 產能／時 | AQ29: 人時性 | AR29: 排名 | AT29: 人數 | AU29: 產能／時 | AV29: 人時性 | AW29: 排名
B30: 熱食義麵 | C30: 1 | D30: 義式蕃茄起司義大利麵 | E30: =VLOOKUP(D30,'10產線配置圖'!$A$2:$C$25,2,0) -> 12 | F30: =VLOOKUP(D30,'10產線配置圖'!$A$2:$C$25,3,0) -> 2000 | G30: =F30/E30 -> 166.66667 | H30: =AVERAGE(G30:G47) -> 110.95405 | I30: =AVERAGE(P30,U30,Z30,AE30,AJ30,AO30,AT30) -> #DIV/0! | J30: =AVERAGE(Q30,V30,AA30,AF30,AK30,AP30,AU30) -> #DIV/0! | K30: =AVERAGE(R30,W30,AB30,AG30,AL30,AQ30,AV30) -> #DIV/0! | L30: =IFERROR(AVERAGE(K30:K47),"-") -> - | M30: =RANK(K30, K$30:$K$47) -> #DIV/0! | R30: =Q30/P30 -> #DIV/0! | S30: =RANK(R30,$R$30:$R$47) -> #DIV/0! | T30: =AVERAGE(R30:R47) -> #DIV/0! | W30: =V30/U30 -> #DIV/0! | X30: =RANK(W30, $W$30:$W$47) -> #DIV/0! | Y30: =AVERAGE(W30:W47) -> #DIV/0! | AB30: =AA30/Z30 -> #DIV/0! | AC30: =RANK(AB30, $AB$30:$AB$47) -> #DIV/0! | AD30: =AVERAGE(AB30:AB47) -> #DIV/0! | AG30: =AF30/AE30 -> #DIV/0! | AH30: =RANK(AG30, $AG$30:$AG$47) -> #DIV/0! | AI30: =AVERAGE(AG30:AG47) -> #DIV/0! | AL30: =AK30/AJ30 -> #DIV/0! | AM30: =RANK(AL30, $AL$30:$AL$47) -> #DIV/0! | AN30: =AVERAGE(AL30:AL47) -> #DIV/0! | AQ30: =AP30/AO30 -> #DIV/0! | AR30: =RANK(AQ30,$AQ$30:$AQ$47) -> #DIV/0! | AS30: =AVERAGE(AQ30:AQ47) -> #DIV/0! | AV30: =AU30/AT30 -> #DIV/0! | AW30: =RANK(AV30, $AV$30:$AV$47) -> #DIV/0! | AX30: =AVERAGE(AV30:AV47) -> #DIV/0!
C31: 2 | D31: 奶油培根義大利麵 | E31: =VLOOKUP(D31,'10產線配置圖'!$A$2:$C$25,2,0) -> 13 | F31: =VLOOKUP(D31,'10產線配置圖'!$A$2:$C$25,3,0) -> 2000 | G31: =F31/E31 -> 153.84615 | I31: =AVERAGE(P31,U31,Z31,AE31,AJ31,AO31,AT31) -> #DIV/0! | J31: =AVERAGE(Q31,V31,AA31,AF31,AK31,AP31,AU31) -> #DIV/0! | K31: =AVERAGE(R31,W31,AB31,AG31,AL31,AQ31,AV31) -> #DIV/0! | M31: =RANK(K31, K$30:$K$47) -> #DIV/0! | R31: =Q31/P31 -> #DIV/0! | S31: =RANK(R31,$R$30:$R$47) -> #DIV/0! | W31: =V31/U31 -> #DIV/0! | X31: =RANK(W31, $W$30:$W$47) -> #DIV/0! | AB31: =AA31/Z31 -> #DIV/0! | AC31: =RANK(AB31, $AB$30:$AB$47) -> #DIV/0! | AG31: =AF31/AE31 -> #DIV/0! | AH31: =RANK(AG31, $AG$30:$AG$47) -> #DIV/0! | AL31: =AK31/AJ31 -> #DIV/0! | AM31: =RANK(AL31, $AL$30:$AL$47) -> #DIV/0! | AQ31: =AP31/AO31 -> #DIV/0! | AR31: =RANK(AQ31,$AQ$30:$AQ$47) -> #DIV/0! | AV31: =AU31/AT31 -> #DIV/0! | AW31: =RANK(AV31, $AV$30:$AV$47) -> #DIV/0!
C32: 3 | D32: 熱那亞青醬義大利麵 | E32: =VLOOKUP(D32,'10產線配置圖'!$A$2:$C$25,2,0) -> 16 | F32: =VLOOKUP(D32,'10產線配置圖'!$A$2:$C$25,3,0) -> 1915 | G32: =F32/E32 -> 119.6875 | I32: =AVERAGE(P32,U32,Z32,AE32,AJ32,AO32,AT32) -> #DIV/0! | J32: =AVERAGE(Q32,V32,AA32,AF32,AK32,AP32,AU32) -> #DIV/0! | K32: =AVERAGE(R32,W32,AB32,AG32,AL32,AQ32,AV32) -> #DIV/0! | M32: =RANK(K32, K$30:$K$47) -> #DIV/0! | R32: =Q32/P32 -> #DIV/0! | S32: =RANK(R32,$R$30:$R$47) -> #DIV/0! | W32: =V32/U32 -> #DIV/0! | X32: =RANK(W32, $W$30:$W$47) -> #DIV/0! | AB32: =AA32/Z32 -> #DIV/0! | AC32: =RANK(AB32, $AB$30:$AB$47) -> #DIV/0! | AG32: =AF32/AE32 -> #DIV/0! | AH32: =RANK(AG32, $AG$30:$AG$47) -> #DIV/0! | AL32: =AK32/AJ32 -> #DIV/0! | AM32: =RANK(AL32, $AL$30:$AL$47) -> #DIV/0! | AQ32: =AP32/AO32 -> #DIV/0! | AR32: =RANK(AQ32,$AQ$30:$AQ$47) -> #DIV/0! | AV32: =AU32/AT32 -> #DIV/0! | AW32: =RANK(AV32, $AV$30:$AV$47) -> #DIV/0!
C33: 4 | D33: 焗烤起司雙饗筆尖麵 | E33: =VLOOKUP(D33,'10產線配置圖'!$A$2:$C$25,2,0) -> 18 | F33: =VLOOKUP(D33,'10產線配置圖'!$A$2:$C$25,3,0) -> 1565 | G33: =F33/E33 -> 86.944444 | I33: =AVERAGE(P33,U33,Z33,AE33,AJ33,AO33,AT33) -> #DIV/0! | J33: =AVERAGE(Q33,V33,AA33,AF33,AK33,AP33,AU33) -> #DIV/0! | K33: =AVERAGE(R33,W33,AB33,AG33,AL33,AQ33,AV33) -> #DIV/0! | M33: =RANK(K33, K$30:$K$47) -> #DIV/0! | R33: =Q33/P33 -> #DIV/0! | S33: =RANK(R33,$R$30:$R$47) -> #DIV/0! | W33: =V33/U33 -> #DIV/0! | X33: =RANK(W33, $W$30:$W$47) -> #DIV/0! | AB33: =AA33/Z33 -> #DIV/0! | AC33: =RANK(AB33, $AB$30:$AB$47) -> #DIV/0! | AG33: =AF33/AE33 -> #DIV/0! | AH33: =RANK(AG33, $AG$30:$AG$47) -> #DIV/0! | AL33: =AK33/AJ33 -> #DIV/0! | AM33: =RANK(AL33, $AL$30:$AL$47) -> #DIV/0! | AQ33: =AP33/AO33 -> #DIV/0! | AR33: =RANK(AQ33,$AQ$30:$AQ$47) -> #DIV/0! | AV33: =AU33/AT33 -> #DIV/0! | AW33: =RANK(AV33, $AV$30:$AV$47) -> #DIV/0!
C34: 5 | D34: 白酒蛤蜊義大利麵 | E34: =VLOOKUP(D34,'10產線配置圖'!$A$2:$C$25,2,0) -> 13 | F34: =VLOOKUP(D34,'10產線配置圖'!$A$2:$C$25,3,0) -> 2000 | G34: =F34/E34 -> 153.84615 | I34: =AVERAGE(P34,U34,Z34,AE34,AJ34,AO34,AT34) -> #DIV/0! | J34: =AVERAGE(Q34,V34,AA34,AF34,AK34,AP34,AU34) -> #DIV/0! | K34: =AVERAGE(R34,W34,AB34,AG34,AL34,AQ34,AV34) -> #DIV/0! | M34: =RANK(K34, K$30:$K$47) -> #DIV/0! | R34: =Q34/P34 -> #DIV/0! | S34: =RANK(R34,$R$30:$R$47) -> #DIV/0! | W34: =V34/U34 -> #DIV/0! | X34: =RANK(W34, $W$30:$W$47) -> #DIV/0! | AB34: =AA34/Z34 -> #DIV/0! | AC34: =RANK(AB34, $AB$30:$AB$47) -> #DIV/0! | AG34: =AF34/AE34 -> #DIV/0! | AH34: =RANK(AG34, $AG$30:$AG$47) -> #DIV/0! | AL34: =AK34/AJ34 -> #DIV/0! | AM34: =RANK(AL34, $AL$30:$AL$47) -> #DIV/0! | AQ34: =AP34/AO34 -> #DIV/0! | AR34: =RANK(AQ34,$AQ$30:$AQ$47) -> #DIV/0! | AV34: =AU34/AT34 -> #DIV/0! | AW34: =RANK(AV34, $AV$30:$AV$47) -> #DIV/0!
C35: 6 | D35: 韓式起司炸雞義大利麵 | E35: =VLOOKUP(D35,'10產線配置圖'!$A$2:$C$25,2,0) -> 14 | F35: =VLOOKUP(D35,'10產線配置圖'!$A$2:$C$25,3,0) -> 1895 | G35: =F35/E35 -> 135.35714 | I35: =AVERAGE(P35,U35,Z35,AE35,AJ35,AO35,AT35) -> #DIV/0! | J35: =AVERAGE(Q35,V35,AA35,AF35,AK35,AP35,AU35) -> #DIV/0! | K35: =AVERAGE(R35,W35,AB35,AG35,AL35,AQ35,AV35) -> #DIV/0! | M35: =RANK(K35, K$30:$K$47) -> #DIV/0! | R35: =Q35/P35 -> #DIV/0! | S35: =RANK(R35,$R$30:$R$47) -> #DIV/0! | W35: =V35/U35 -> #DIV/0! | X35: =RANK(W35, $W$30:$W$47) -> #DIV/0! | AB35: =AA35/Z35 -> #DIV/0! | AC35: =RANK(AB35, $AB$30:$AB$47) -> #DIV/0! | AG35: =AF35/AE35 -> #DIV/0! | AH35: =RANK(AG35, $AG$30:$AG$47) -> #DIV/0! | AL35: =AK35/AJ35 -> #DIV/0! | AM35: =RANK(AL35, $AL$30:$AL$47) -> #DIV/0! | AQ35: =AP35/AO35 -> #DIV/0! | AR35: =RANK(AQ35,$AQ$30:$AQ$47) -> #DIV/0! | AV35: =AU35/AT35 -> #DIV/0! | AW35: =RANK(AV35, $AV$30:$AV$47) -> #DIV/0!
C36: 7 | D36: 拿坡里義大利麵 | E36: =VLOOKUP(D36,'10產線配置圖'!$A$2:$C$25,2,0) -> 16 | F36: =VLOOKUP(D36,'10產線配置圖'!$A$2:$C$25,3,0) -> 1429 | G36: =F36/E36 -> 89.3125 | I36: =AVERAGE(P36,U36,Z36,AE36,AJ36,AO36,AT36) -> #DIV/0! | J36: =AVERAGE(Q36,V36,AA36,AF36,AK36,AP36,AU36) -> #DIV/0! | K36: =AVERAGE(R36,W36,AB36,AG36,AL36,AQ36,AV36) -> #DIV/0! | M36: =RANK(K36, K$30:$K$47) -> #DIV/0! | R36: =Q36/P36 -> #DIV/0! | S36: =RANK(R36,$R$30:$R$47) -> #DIV/0! | W36: =V36/U36 -> #DIV/0! | X36: =RANK(W36, $W$30:$W$47) -> #DIV/0! | AB36: =AA36/Z36 -> #DIV/0! | AC36: =RANK(AB36, $AB$30:$AB$47) -> #DIV/0! | AG36: =AF36/AE36 -> #DIV/0! | AH36: =RANK(AG36, $AG$30:$AG$47) -> #DIV/0!
C37: 8 | D37: 黑胡椒燻豬腿義大利麵 | E37: =VLOOKUP(D37,'10產線配置圖'!$A$2:$C$25,2,0) -> 18 | F37: =VLOOKUP(D37,'10產線配置圖'!$A$2:$C$25,3,0) -> 1500 | G37: =F37/E37 -> 83.333333 | I37: =AVERAGE(P37,U37,Z37,AE37,AJ37,AO37,AT37) -> #DIV/0! | J37: =AVERAGE(Q37,V37,AA37,AF37,AK37,AP37,AU37) -> #DIV/0! | K37: =AVERAGE(R37,W37,AB37,AG37,AL37,AQ37,AV37) -> #DIV/0! | M37: =RANK(K37, K$30:$K$47) -> #DIV/0! | R37: =Q37/P37 -> #DIV/0! | S37: =RANK(R37,$R$30:$R$47) -> #DIV/0! | W37: =V37/U37 -> #DIV/0! | X37: =RANK(W37, $W$30:$W$47) -> #DIV/0! | AB37: =AA37/Z37 -> #DIV/0! | AC37: =RANK(AB37, $AB$30:$AB$47) -> #DIV/0! | AG37: =AF37/AE37 -> #DIV/0! | AH37: =RANK(AG37, $AG$30:$AG$47) -> #DIV/0! | AL37: =AK37/AJ37 -> #DIV/0! | AM37: =RANK(AL37, $AL$30:$AL$47) -> #DIV/0! | AQ37: =AP37/AO37 -> #DIV/0! | AR37: =RANK(AQ37,$AQ$30:$AQ$47) -> #DIV/0! | AV37: =AU37/AT37 -> #DIV/0! | AW37: =RANK(AV37, $AV$30:$AV$47) -> #DIV/0!
C38: 9 | D38: 奶油蒜香雞義大利麵 | E38: =VLOOKUP(D38,'10產線配置圖'!$A$2:$C$25,2,0) -> 18 | F38: =VLOOKUP(D38,'10產線配置圖'!$A$2:$C$25,3,0) -> 1385 | G38: =F38/E38 -> 76.944444 | I38: =AVERAGE(P38,U38,Z38,AE38,AJ38,AO38,AT38) -> #DIV/0! | J38: =AVERAGE(Q38,V38,AA38,AF38,AK38,AP38,AU38) -> #DIV/0! | K38: =AVERAGE(R38,W38,AB38,AG38,AL38,AQ38,AV38) -> #DIV/0! | M38: =RANK(K38, K$30:$K$47) -> #DIV/0! | R38: =Q38/P38 -> #DIV/0! | S38: =RANK(R38,$R$30:$R$47) -> #DIV/0! | W38: =V38/U38 -> #DIV/0! | X38: =RANK(W38, $W$30:$W$47) -> #DIV/0! | AB38: =AA38/Z38 -> #DIV/0! | AC38: =RANK(AB38, $AB$30:$AB$47) -> #DIV/0! | AG38: =AF38/AE38 -> #DIV/0! | AH38: =RANK(AG38, $AG$30:$AG$47) -> #DIV/0! | AL38: =AK38/AJ38 -> #DIV/0! | AM38: =RANK(AL38, $AL$30:$AL$47) -> #DIV/0! | AQ38: =AP38/AO38 -> #DIV/0! | AR38: =RANK(AQ38,$AQ$30:$AQ$47) -> #DIV/0! | AV38: =AU38/AT38 -> #DIV/0! | AW38: =RANK(AV38, $AV$30:$AV$47) -> #DIV/0!
C39: 10 | D39: 青花椒麻雞肉拌麵 | E39: =VLOOKUP(D39,'10產線配置圖'!$A$2:$C$25,2,0) -> 17 | F39: =VLOOKUP(D39,'10產線配置圖'!$A$2:$C$25,3,0) -> 1565 | G39: =F39/E39 -> 92.058824 | I39: =AVERAGE(P39,U39,Z39,AE39,AJ39,AO39,AT39) -> #DIV/0! | J39: =AVERAGE(Q39,V39,AA39,AF39,AK39,AP39,AU39) -> #DIV/0! | K39: =AVERAGE(R39,W39,AB39,AG39,AL39,AQ39,AV39) -> #DIV/0! | M39: =RANK(K39, K$30:$K$47) -> #DIV/0! | R39: =Q39/P39 -> #DIV/0! | S39: =RANK(R39,$R$30:$R$47) -> #DIV/0! | W39: =V39/U39 -> #DIV/0! | X39: =RANK(W39, $W$30:$W$47) -> #DIV/0! | AB39: =AA39/Z39 -> #DIV/0! | AC39: =RANK(AB39, $AB$30:$AB$47) -> #DIV/0! | AG39: =AF39/AE39 -> #DIV/0! | AH39: =RANK(AG39, $AG$30:$AG$47) -> #DIV/0! | AL39: =AK39/AJ39 -> #DIV/0! | AM39: =RANK(AL39, $AL$30:$AL$47) -> #DIV/0! | AQ39: =AP39/AO39 -> #DIV/0! | AR39: =RANK(AQ39,$AQ$30:$AQ$47) -> #DIV/0! | AV39: =AU39/AT39 -> #DIV/0! | AW39: =RANK(AV39, $AV$30:$AV$47) -> #DIV/0!
C40: 11 | D40: 羊乳起司培根筆尖麵 | E40: =VLOOKUP(D40,'10產線配置圖'!$A$2:$C$25,2,0) -> 17 | F40: =VLOOKUP(D40,'10產線配置圖'!$A$2:$C$25,3,0) -> 1636 | G40: =F40/E40 -> 96.235294 | I40: =AVERAGE(P40,U40,Z40,AE40,AJ40,AO40,AT40) -> #DIV/0! | J40: =AVERAGE(Q40,V40,AA40,AF40,AK40,AP40,AU40) -> #DIV/0! | K40: =AVERAGE(R40,W40,AB40,AG40,AL40,AQ40,AV40) -> #DIV/0! | M40: =RANK(K40, K$30:$K$47) -> #DIV/0! | R40: =Q40/P40 -> #DIV/0! | S40: =RANK(R40,$R$30:$R$47) -> #DIV/0! | W40: =V40/U40 -> #DIV/0! | X40: =RANK(W40, $W$30:$W$47) -> #DIV/0! | AB40: =AA40/Z40 -> #DIV/0! | AC40: =RANK(AB40, $AB$30:$AB$47) -> #DIV/0! | AG40: =AF40/AE40 -> #DIV/0! | AH40: =RANK(AG40, $AG$30:$AG$47) -> #DIV/0! | AL40: =AK40/AJ40 -> #DIV/0! | AM40: =RANK(AL40, $AL$30:$AL$47) -> #DIV/0! | AQ40: =AP40/AO40 -> #DIV/0! | AR40: =RANK(AQ40,$AQ$30:$AQ$47) -> #DIV/0! | AV40: =AU40/AT40 -> #DIV/0! | AW40: =RANK(AV40, $AV$30:$AV$47) -> #DIV/0!
...

Sheet （５-2）品群別人時生產性(季節調理麵) 
B1: 月平均人時性 | C1: =AVERAGE(L7,L27,L47,L67,L87) -> #DIV/0!
B2: 產線配置圖－每週更新 | N2: 資料繳交 | O2: 日期 | AE2: 45870 | AJ2: 45871 | AO2: 45872 | AT2: 45873
P3: 二 | U3: 三 | Z3: 四 | AE3: 五 | AJ3: 六 | AO3: 日 | AT3: 一
B4: 品群 | C4: 商品名稱 | E4: 計畫 | H4: 平均人時性 | I4: 實績 | L4: 平均人時性 | M4: 排名 | O4: 日報 | P4: 實際 | T4: 平均人時性 | U4: 實際 | Y4: 平均人時性 | Z4: 實際 | AD4: 平均人時性 | AE4: 實際 | AI4: 平均人時性 | AJ4: 實際 | AN4: 平均人時性 | AO4: 實際 | AS4: 平均人時性 | AT4: 實際 | AX4: 平均人時性
E5: 產線配置圖 | I5: 產線配置圖 | P5: 生產實績 | U5: 生產實績 | Z5: 生產實績 | AE5: 生產實績 | AJ5: 生產實績 | AO5: 生產實績 | AT5: 生產實績
E6: 人數 | F6: 產能／時 | G6: 人時性 | I6: 人數 | J6: 產能／時 | K6: 人時性 | P6: 人數 | Q6: 產能／時 | R6: 人時性 | S6: 排名 | U6: 人數 | V6: 產能／時 | W6: 人時性 | X6: 排名 | Z6: 人數 | AA6: 產能／時 | AB6: 人時性 | AC6: 排名 | AE6: 人數 | AF6: 產能／時 | AG6: 人時性 | AH6: 排名 | AJ6: 人數 | AK6: 產能／時 | AL6: 人時性 | AM6: 排名 | AO6: 人數 | AP6: 產能／時 | AQ6: 人時性 | AR6: 排名 | AT6: 人數 | AU6: 產能／時 | AV6: 人時性 | AW6: 排名
B7: 熱食調理麵 | C7: 1 | H7: =AVERAGE(G7:G21) -> #DIV/0! | I7: =AVERAGE(P7,U7,Z7,AE7,AJ7,AO7,AT7) -> #DIV/0! | J7: =AVERAGE(Q7,V7,AA7,AF7,AK7,AP7,AU7) -> #DIV/0! | K7: =AVERAGE(R7,W7,AB7,AG7,AL7,AQ7,AV7) -> #DIV/0! | L7: =AVERAGE(K7:K21) -> #DIV/0! | M7: =RANK(K7, K$7:$K$21) -> #DIV/0! | S7: =RANK(R7, R$7:R$21) -> #N/A | T7: =AVERAGE(R7:R21) -> #DIV/0! | X7: =RANK(W7, W$7:W$21) -> #N/A | Y7: =AVERAGE(W7:W21) -> #DIV/0! | AC7: =RANK(AB7, AB$7:AB$21) -> #N/A | AD7: =AVERAGE(AB7:AB21) -> #DIV/0! | AH7: =RANK(AG7, AG$7:AG$21) -> #N/A | AI7: =AVERAGE(AG7:AG21) -> #DIV/0! | AM7: =RANK(AL7, AL$7:AL$21) -> #N/A | AN7: =AVERAGE(AL7:AL21) -> #DIV/0! | AR7: =RANK(AQ7, AQ$7:AQ$21) -> #N/A | AS7: =AVERAGE(AQ7:AQ21) -> #DIV/0! | AW7: =RANK(AV7, AV$7:AV$21) -> #N/A | AX7: =AVERAGE(AV7:AV21) -> #DIV/0!
C8: 2 | I8: =AVERAGE(P8,U8,Z8,AE8,AJ8,AO8,AT8) -> #DIV/0! | J8: =AVERAGE(Q8,V8,AA8,AF8,AK8,AP8,AU8) -> #DIV/0! | K8: =AVERAGE(R8,W8,AB8,AG8,AL8,AQ8,AV8) -> #DIV/0! | M8: =RANK(K8, K$7:$K$21) -> #DIV/0! | S8: =RANK(R8, R$7:R$21) -> #N/A | X8: =RANK(W8, W$7:W$21) -> #N/A | AC8: =RANK(AB8, AB$7:AB$21) -> #N/A | AH8: =RANK(AG8, AG$7:AG$21) -> #N/A | AM8: =RANK(AL8, AL$7:AL$21) -> #N/A | AR8: =RANK(AQ8, AQ$7:AQ$21) -> #N/A | AW8: =RANK(AV8, AV$7:AV$21) -> #N/A
C9: 3 | I9: =AVERAGE(P9,U9,Z9,AE9,AJ9,AO9,AT9) -> #DIV/0! | J9: =AVERAGE(Q9,V9,AA9,AF9,AK9,AP9,AU9) -> #DIV/0! | K9: =AVERAGE(R9,W9,AB9,AG9,AL9,AQ9,AV9) -> #DIV/0! | M9: =RANK(K9, K$7:$K$21) -> #DIV/0! | S9: =RANK(R9, R$7:R$21) -> #N/A | X9: =RANK(W9, W$7:W$21) -> #N/A | AC9: =RANK(AB9, AB$7:AB$21) -> #N/A | AH9: =RANK(AG9, AG$7:AG$21) -> #N/A | AM9: =RANK(AL9, AL$7:AL$21) -> #N/A | AR9: =RANK(AQ9, AQ$7:AQ$21) -> #N/A | AW9: =RANK(AV9, AV$7:AV$21) -> #N/A
C10: 4 | I10: =AVERAGE(P10,U10,Z10,AE10,AJ10,AO10,AT10) -> #DIV/0! | J10: =AVERAGE(Q10,V10,AA10,AF10,AK10,AP10,AU10) -> #DIV/0! | K10: =AVERAGE(R10,W10,AB10,AG10,AL10,AQ10,AV10) -> #DIV/0! | M10: =RANK(K10, K$7:$K$21) -> #DIV/0! | S10: =RANK(R10, R$7:R$21) -> #N/A | X10: =RANK(W10, W$7:W$21) -> #N/A | AC10: =RANK(AB10, AB$7:AB$21) -> #N/A | AH10: =RANK(AG10, AG$7:AG$21) -> #N/A | AM10: =RANK(AL10, AL$7:AL$21) -> #N/A | AR10: =RANK(AQ10, AQ$7:AQ$21) -> #N/A | AW10: =RANK(AV10, AV$7:AV$21) -> #N/A
C11: 5 | I11: =AVERAGE(P11,U11,Z11,AE11,AJ11,AO11,AT11) -> #DIV/0! | J11: =AVERAGE(Q11,V11,AA11,AF11,AK11,AP11,AU11) -> #DIV/0! | K11: =AVERAGE(R11,W11,AB11,AG11,AL11,AQ11,AV11) -> #DIV/0! | M11: =RANK(K11, K$7:$K$21) -> #DIV/0! | S11: =RANK(R11, R$7:R$21) -> #N/A | X11: =RANK(W11, W$7:W$21) -> #N/A | AC11: =RANK(AB11, AB$7:AB$21) -> #N/A | AH11: =RANK(AG11, AG$7:AG$21) -> #N/A | AM11: =RANK(AL11, AL$7:AL$21) -> #N/A | AR11: =RANK(AQ11, AQ$7:AQ$21) -> #N/A | AW11: =RANK(AV11, AV$7:AV$21) -> #N/A
C12: 6 | I12: =AVERAGE(P12,U12,Z12,AE12,AJ12,AO12,AT12) -> #DIV/0! | J12: =AVERAGE(Q12,V12,AA12,AF12,AK12,AP12,AU12) -> #DIV/0! | K12: =AVERAGE(R12,W12,AB12,AG12,AL12,AQ12,AV12) -> #DIV/0! | M12: =RANK(K12, K$7:$K$21) -> #DIV/0! | S12: =RANK(R12, R$7:R$21) -> #N/A | X12: =RANK(W12, W$7:W$21) -> #N/A | AC12: =RANK(AB12, AB$7:AB$21) -> #N/A | AH12: =RANK(AG12, AG$7:AG$21) -> #N/A | AM12: =RANK(AL12, AL$7:AL$21) -> #N/A | AR12: =RANK(AQ12, AQ$7:AQ$21) -> #N/A | AW12: =RANK(AV12, AV$7:AV$21) -> #N/A
C13: 7 | I13: =AVERAGE(P13,U13,Z13,AE13,AJ13,AO13,AT13) -> #DIV/0! | J13: =AVERAGE(Q13,V13,AA13,AF13,AK13,AP13,AU13) -> #DIV/0! | K13: =AVERAGE(R13,W13,AB13,AG13,AL13,AQ13,AV13) -> #DIV/0! | M13: =RANK(K13, K$7:$K$21) -> #DIV/0! | S13: =RANK(R13, R$7:R$21) -> #N/A | X13: =RANK(W13, W$7:W$21) -> #N/A | AC13: =RANK(AB13, AB$7:AB$21) -> #N/A | AH13: =RANK(AG13, AG$7:AG$21) -> #N/A | AM13: =RANK(AL13, AL$7:AL$21) -> #N/A | AR13: =RANK(AQ13, AQ$7:AQ$21) -> #N/A | AW13: =RANK(AV13, AV$7:AV$21) -> #N/A
C14: 8 | I14: =AVERAGE(P14,U14,Z14,AE14,AJ14,AO14,AT14) -> #DIV/0! | J14: =AVERAGE(Q14,V14,AA14,AF14,AK14,AP14,AU14) -> #DIV/0! | K14: =AVERAGE(R14,W14,AB14,AG14,AL14,AQ14,AV14) -> #DIV/0! | M14: =RANK(K14, K$7:$K$21) -> #DIV/0! | S14: =RANK(R14, R$7:R$21) -> #N/A | X14: =RANK(W14, W$7:W$21) -> #N/A | AC14: =RANK(AB14, AB$7:AB$21) -> #N/A | AH14: =RANK(AG14, AG$7:AG$21) -> #N/A | AM14: =RANK(AL14, AL$7:AL$21) -> #N/A | AR14: =RANK(AQ14, AQ$7:AQ$21) -> #N/A | AW14: =RANK(AV14, AV$7:AV$21) -> #N/A
C15: 9 | I15: =AVERAGE(P15,U15,Z15,AE15,AJ15,AO15,AT15) -> #DIV/0! | J15: =AVERAGE(Q15,V15,AA15,AF15,AK15,AP15,AU15) -> #DIV/0! | K15: =AVERAGE(R15,W15,AB15,AG15,AL15,AQ15,AV15) -> #DIV/0! | M15: =RANK(K15, K$7:$K$21) -> #DIV/0! | S15: =RANK(R15, R$7:R$21) -> #N/A | X15: =RANK(W15, W$7:W$21) -> #N/A | AC15: =RANK(AB15, AB$7:AB$21) -> #N/A | AH15: =RANK(AG15, AG$7:AG$21) -> #N/A | AM15: =RANK(AL15, AL$7:AL$21) -> #N/A | AR15: =RANK(AQ15, AQ$7:AQ$21) -> #N/A | AW15: =RANK(AV15, AV$7:AV$21) -> #N/A
C16: 10 | I16: =AVERAGE(P16,U16,Z16,AE16,AJ16,AO16,AT16) -> #DIV/0! | J16: =AVERAGE(Q16,V16,AA16,AF16,AK16,AP16,AU16) -> #DIV/0! | K16: =AVERAGE(R16,W16,AB16,AG16,AL16,AQ16,AV16) -> #DIV/0! | M16: =RANK(K16, K$7:$K$21) -> #DIV/0! | S16: =RANK(R16, R$7:R$21) -> #N/A | X16: =RANK(W16, W$7:W$21) -> #N/A | AC16: =RANK(AB16, AB$7:AB$21) -> #N/A | AH16: =RANK(AG16, AG$7:AG$21) -> #N/A | AM16: =RANK(AL16, AL$7:AL$21) -> #N/A | AR16: =RANK(AQ16, AQ$7:AQ$21) -> #N/A | AW16: =RANK(AV16, AV$7:AV$21) -> #N/A
C17: 11 | M17: =RANK(K17, K$7:$K$21) -> #DIV/0! | S17: =RANK(R17, R$7:R$21) -> #N/A | X17: =RANK(W17, W$7:W$21) -> #N/A | AC17: =RANK(AB17, AB$7:AB$21) -> #N/A | AH17: =RANK(AG17, AG$7:AG$21) -> #N/A | AM17: =RANK(AL17, AL$7:AL$21) -> #N/A | AR17: =RANK(AQ17, AQ$7:AQ$21) -> #N/A | AW17: =RANK(AV17, AV$7:AV$21) -> #N/A
C18: 12 | M18: =RANK(K18, K$7:$K$21) -> #DIV/0! | S18: =RANK(R18, R$7:R$21) -> #N/A | X18: =RANK(W18, W$7:W$21) -> #N/A | AC18: =RANK(AB18, AB$7:AB$21) -> #N/A | AH18: =RANK(AG18, AG$7:AG$21) -> #N/A | AM18: =RANK(AL18, AL$7:AL$21) -> #N/A | AR18: =RANK(AQ18, AQ$7:AQ$21) -> #N/A | AW18: =RANK(AV18, AV$7:AV$21) -> #N/A
C19: 13 | M19: =RANK(K19, K$7:$K$21) -> #DIV/0! | S19: =RANK(R19, R$7:R$21) -> #N/A | X19: =RANK(W19, W$7:W$21) -> #N/A | AC19: =RANK(AB19, AB$7:AB$21) -> #N/A | AH19: =RANK(AG19, AG$7:AG$21) -> #N/A | AM19: =RANK(AL19, AL$7:AL$21) -> #N/A | AR19: =RANK(AQ19, AQ$7:AQ$21) -> #N/A | AW19: =RANK(AV19, AV$7:AV$21) -> #N/A
C20: 14 | M20: =RANK(K20, K$7:$K$21) -> #DIV/0! | S20: =RANK(R20, R$7:R$21) -> #N/A | X20: =RANK(W20, W$7:W$21) -> #N/A | AC20: =RANK(AB20, AB$7:AB$21) -> #N/A | AH20: =RANK(AG20, AG$7:AG$21) -> #N/A | AM20: =RANK(AL20, AL$7:AL$21) -> #N/A | AR20: =RANK(AQ20, AQ$7:AQ$21) -> #N/A | AW20: =RANK(AV20, AV$7:AV$21) -> #N/A
C21: 15 | M21: =RANK(K21, K$7:$K$21) -> #DIV/0! | S21: =RANK(R21, R$7:R$21) -> #N/A | X21: =RANK(W21, W$7:W$21) -> #N/A | AC21: =RANK(AB21, AB$7:AB$21) -> #N/A | AH21: =RANK(AG21, AG$7:AG$21) -> #N/A | AM21: =RANK(AL21, AL$7:AL$21) -> #N/A | AR21: =RANK(AQ21, AQ$7:AQ$21) -> #N/A | AW21: =RANK(AV21, AV$7:AV$21) -> #N/A
B22: 產線配置圖－每週更新 | N22: 資料繳交 | O22: 日期 | P22: 45874 | U22: 45875 | Z22: 45876 | AE22: 45877 | AJ22: 45878 | AO22: 45879 | AT22: 45880
P23: 二 | U23: 三 | Z23: 四 | AE23: 五 | AJ23: 六 | AO23: 日 | AT23: 一
B24: 品群 | C24: 商品名稱 | E24: 計畫 | H24: 平均人時性 | I24: 實績 | L24: 平均人時性 | M24: 排名 | O24: 日報 | P24: 實際 | T24: 平均人時性 | U24: 實際 | Y24: 平均人時性 | Z24: 實際 | AD24: 平均人時性 | AE24: 實際 | AI24: 平均人時性 | AJ24: 實際 | AN24: 平均人時性 | AO24: 實際 | AS24: 平均人時性 | AT24: 實際 | AX24: 平均人時性
E25: 產線配置圖 | I25: 產線配置圖 | P25: 生產實績 | U25: 生產實績 | Z25: 生產實績 | AE25: 生產實績 | AJ25: 生產實績 | AO25: 生產實績 | AT25: 生產實績
E26: 人數 | F26: 產能／時 | G26: 人時性 | I26: 人數 | J26: 產能／時 | K26: 人時性 | P26: 人數 | Q26: 產能／時 | R26: 人時性 | S26: 排名 | U26: 人數 | V26: 產能／時 | W26: 人時性 | X26: 排名 | Z26: 人數 | AA26: 產能／時 | AB26: 人時性 | AC26: 排名 | AE26: 人數 | AF26: 產能／時 | AG26: 人時性 | AH26: 排名 | AJ26: 人數 | AK26: 產能／時 | AL26: 人時性 | AM26: 排名 | AO26: 人數 | AP26: 產能／時 | AQ26: 人時性 | AR26: 排名 | AT26: 人數 | AU26: 產能／時 | AV26: 人時性 | AW26: 排名
B27: 季節調理麵 | C27: 1 | H27: =AVERAGE(G27:G41) -> #DIV/0! | I27: =AVERAGE(P27,U27,Z27,AE27,AJ27,AO27,AT27) -> #DIV/0! | J27: =AVERAGE(Q27,V27,AA27,AF27,AK27,AP27,AU27) -> #DIV/0! | K27: =AVERAGE(R27,W27,AB27,AG27,AL27,AQ27,AV27) -> #DIV/0! | L27: =AVERAGE(K27:K41) -> #DIV/0! | M27: =RANK(K27, K$27:$K$41) -> #DIV/0! | T27: =AVERAGE(R27:R41) -> #DIV/0! | Y27: =AVERAGE(W27:W41) -> #DIV/0! | AD27: =AVERAGE(AB27:AB41) -> #DIV/0! | AI27: =AVERAGE(AG27:AG41) -> #DIV/0! | AN27: =AVERAGE(AL27:AL41) -> #DIV/0! | AS27: =AVERAGE(AQ27:AQ41) -> #DIV/0! | AX27: =AVERAGE(AV27:AV41) -> #DIV/0!
C28: 2 | I28: =AVERAGE(P28,U28,Z28,AE28,AJ28,AO28,AT28) -> #DIV/0! | J28: =AVERAGE(Q28,V28,AA28,AF28,AK28,AP28,AU28) -> #DIV/0! | K28: =AVERAGE(R28,W28,AB28,AG28,AL28,AQ28,AV28) -> #DIV/0! | M28: =RANK(K28, K$27:$K$41) -> #DIV/0!
C29: 3 | I29: =AVERAGE(P29,U29,Z29,AE29,AJ29,AO29,AT29) -> #DIV/0! | J29: =AVERAGE(Q29,V29,AA29,AF29,AK29,AP29,AU29) -> #DIV/0! | K29: =AVERAGE(R29,W29,AB29,AG29,AL29,AQ29,AV29) -> #DIV/0! | M29: =RANK(K29, K$27:$K$41) -> #DIV/0!
C30: 4 | I30: =AVERAGE(P30,U30,Z30,AE30,AJ30,AO30,AT30) -> #DIV/0! | J30: =AVERAGE(Q30,V30,AA30,AF30,AK30,AP30,AU30) -> #DIV/0! | K30: =AVERAGE(R30,W30,AB30,AG30,AL30,AQ30,AV30) -> #DIV/0! | M30: =RANK(K30, K$27:$K$41) -> #DIV/0!
C31: 5 | I31: =AVERAGE(P31,U31,Z31,AE31,AJ31,AO31,AT31) -> #DIV/0! | J31: =AVERAGE(Q31,V31,AA31,AF31,AK31,AP31,AU31) -> #DIV/0! | K31: =AVERAGE(R31,W31,AB31,AG31,AL31,AQ31,AV31) -> #DIV/0! | M31: =RANK(K31, K$27:$K$41) -> #DIV/0!
C32: 6 | I32: =AVERAGE(P32,U32,Z32,AE32,AJ32,AO32,AT32) -> #DIV/0! | J32: =AVERAGE(Q32,V32,AA32,AF32,AK32,AP32,AU32) -> #DIV/0! | K32: =AVERAGE(R32,W32,AB32,AG32,AL32,AQ32,AV32) -> #DIV/0! | M32: =RANK(K32, K$27:$K$41) -> #DIV/0!
C33: 7 | I33: =AVERAGE(P33,U33,Z33,AE33,AJ33,AO33,AT33) -> #DIV/0! | J33: =AVERAGE(Q33,V33,AA33,AF33,AK33,AP33,AU33) -> #DIV/0! | K33: =AVERAGE(R33,W33,AB33,AG33,AL33,AQ33,AV33) -> #DIV/0! | M33: =RANK(K33, K$27:$K$41) -> #DIV/0!
C34: 8 | I34: =AVERAGE(P34,U34,Z34,AE34,AJ34,AO34,AT34) -> #DIV/0! | J34: =AVERAGE(Q34,V34,AA34,AF34,AK34,AP34,AU34) -> #DIV/0! | K34: =AVERAGE(R34,W34,AB34,AG34,AL34,AQ34,AV34) -> #DIV/0! | M34: =RANK(K34, K$27:$K$41) -> #DIV/0!
C35: 9 | I35: =AVERAGE(P35,U35,Z35,AE35,AJ35,AO35,AT35) -> #DIV/0! | J35: =AVERAGE(Q35,V35,AA35,AF35,AK35,AP35,AU35) -> #DIV/0! | K35: =AVERAGE(R35,W35,AB35,AG35,AL35,AQ35,AV35) -> #DIV/0! | M35: =RANK(K35, K$27:$K$41) -> #DIV/0!
C36: 10 | I36: =AVERAGE(P36,U36,Z36,AE36,AJ36,AO36,AT36) -> #DIV/0! | J36: =AVERAGE(Q36,V36,AA36,AF36,AK36,AP36,AU36) -> #DIV/0! | K36: =AVERAGE(R36,W36,AB36,AG36,AL36,AQ36,AV36) -> #DIV/0! | M36: =RANK(K36, K$27:$K$41) -> #DIV/0!
C37: 11 | M37: =RANK(K37, K$27:$K$41) -> #DIV/0!
C38: 12 | M38: =RANK(K38, K$27:$K$41) -> #DIV/0!
C39: 13 | M39: =RANK(K39, K$27:$K$41) -> #DIV/0!
C40: 14 | M40: =RANK(K40, K$27:$K$41) -> #DIV/0!
...

Sheet （５-3）品群別人時生產性(微波小吃)
B1: 月平均人時性 | C1: =AVERAGE(L7,L27,L47,L67,L87) -> 111.71652
B2: 產線配置圖－每週更新 | N2: 資料繳交 | O2: 日期 | U2: 45931 | Z2: 45932 | AE2: 45933 | AJ2: 45934 | AO2: 45935 | AT2: 45936
P3: 二 | U3: 三 | Z3: 四 | AE3: 五 | AJ3: 六 | AO3: 日 | AT3: 一
B4: 品群 | C4: 商品名稱 | E4: 計畫 | H4: 平均人時性 | I4: 實績 | L4: 平均人時性 | M4: 排名 | O4: 日報 | P4: 實際 | T4: 平均人時性 | U4: 實際 | Y4: 平均人時性 | Z4: 實際 | AD4: 平均人時性 | AE4: 實際 | AI4: 平均人時性 | AJ4: 實際 | AN4: 平均人時性 | AO4: 實際 | AS4: 平均人時性 | AT4: 實際 | AX4: 平均人時性
E5: 產線配置圖 | I5: 產線配置圖 | P5: 生產實績 | U5: 生產實績 | Z5: 生產實績 | AE5: 生產實績 | AJ5: 生產實績 | AO5: 生產實績 | AT5: 生產實績
E6: 人數 | F6: 產能／時 | G6: 人時性 | I6: 人數 | J6: 產能／時 | K6: 人時性 | P6: 人數 | Q6: 產能／時 | R6: 人時性 | S6: 排名 | U6: 人數 | V6: 產能／時 | W6: 人時性 | X6: 排名 | Z6: 人數 | AA6: 產能／時 | AB6: 人時性 | AC6: 排名 | AE6: 人數 | AF6: 產能／時 | AG6: 人時性 | AH6: 排名 | AJ6: 人數 | AK6: 產能／時 | AL6: 人時性 | AM6: 排名 | AO6: 人數 | AP6: 產能／時 | AQ6: 人時性 | AR6: 排名 | AT6: 人數 | AU6: 產能／時 | AV6: 人時性 | AW6: 排名
