Workbook

Sheet 生產管理報表(月)
A1: 長家廠生產管理報表
A3: 月別 | B3: 1 | C3: 工廠 | D3: 長家
A4: （１）收支狀況 | E4: ※單位：千元 | G4: （２）ＫＰＩ達成進度
A5: 項目 | B5: 當月 | C5: 前月 | D5: 差異 | E5: 累計 | G5: 項目 | H5: KPI | I5: 當月 | J5: 前月 | K5: 累計 | L5: ※補充
A6: 業績金額 | B6: 73906 | C6: 73077 | D6: =B6-C6 -> 829 | G6: 人時性(個/月均) | H6: 112.8 | I6: 99.6 | J6: 100.9 | L6: 個／MH
A7: 訂單數量 | B7: 1572945 | C7: 1537451 | D7: =B7-C7 -> 35494 | G7: 人時達成率(%/月均) | H7: 0.8 | I7: =I6/H6 -> 0.88297872 | J7: 0.8945 | L7: 達成率
A8: 材料費 | B8: 46645.866 | C8: 46135 | D8: =B8-C8 -> 510.866 | G8: 半成品-報廢(%) | H8: 0.0025 | I8: 0.0034 | J8: 0.0039 | L8: 報廢率
A9: 材料費率 | B9: =B8/B6 -> 0.63115127 | C9: 0.6313 | D9: =B9-C9 -> -0.00014872676 | G9: 半成品-超用(%) | H9: 0.0025 | I9: 0.0023 | J9: 0.0025 | L9: 超用率
A10: 勞務成本 | B10: =B6*B11 -> 9755.592 | C10: =C6*C11 -> 9573.087 | D10: =B10-C10 -> 182.505 | G10: 固定產線-導入率(%) | H10: 1 | I10: 0.286 | J10: 0.407 | L10: 導入率
A11: 勞務費率 | B11: 0.132 | C11: 0.131 | D11: =B11-C11 -> 0.001 | G11: 教育訓練-實施率(%) | H11: 1 | I11: 0.903 | J11: 0.85 | L11: 實施率
A13: （３）業績構成比 | G13: （４）訂單數量構成比
B14: 當月 | C14: 比例 | D14: 前月 | E14: 差異 | H14: 當月 | I14: 比例 | J14: 前月 | K14: 差異
A15: 熱食義麵(122,123,124,126) | B15: 67377.8 | C15: =IFERROR(B15/$B$6,"") -> 0.91166888 | D15: 0.9174 | E15: =IFERROR(C15-D15,"") -> -0.0057311233 | G15: 熱食義麵(122,123,124,126) | H15: 1336654 | I15: =IFERROR(H15/$B$7,"") -> 0.84977796 | J15: 0.8577 | K15: =IFERROR(I15-J15,"") -> -0.0079220357
A16: 季節調理麵(111,112) | C16: =IFERROR(B16/$B$6,"") -> 0 | D16: 0 | E16: =IFERROR(C16-D16,"") -> 0 | G16: 季節調理麵(111,112) | I16: =IFERROR(H16/$B$7,"") -> 0 | J16: 0 | K16: =IFERROR(I16-J16,"") -> 0
A17: 微波小吃(153,154,155) | B17: 6528.1 | C17: =IFERROR(B17/$B$6,"") -> 0.08832977 | D17: 0.0826 | E17: =IFERROR(C17-D17,"") -> 0.0057297702 | G17: 微波小吃(153,154,155) | H17: 236291 | I17: =IFERROR(H17/$B$7,"") -> 0.15022204 | J17: 0.1423 | K17: =IFERROR(I17-J17,"") -> 0.0079220357
C18: =SUM(C15:C17) -> 0.99999865 | D18: =SUM(D15:D17) -> 1 | I18: =SUM(I15:I17) -> 1 | J18: =SUM(J15:J17) -> 1
A20: （５）品群別人時生產性
A21: 品群 | B21: 當月 | C21: 前月 | D21: 差異 | E21: 累計
A22: 熱食義麵(122,123,124,126) | B22: 98.7 | C22: 98.3 | D22: =B22-C22 -> 0.4
A23: 季節調理麵(111,112) | D23: =B23-C23 -> 0
A24: 微波小吃(153,154,155) | B24: 104.2 | C24: 110.1 | D24: =B24-C24 -> -5.9

Sheet （１）收支狀況
B2: （１）收支狀況
B3: 資料繳交日 | C3: 月份 | D3: 日期 | F3: 營業額(元) | I3: 訂單數量(個) | L3: 材料費(元) | O3: 材料費率（材料費／營業額） | R3: 勞務成本（全廠人事成本） | U3: 勞務費率（勞務成本／營業額）
F4: 日 | G4: 週累積 | H4: 月累積 | I4: 日 | J4: 週累積 | K4: 月累積 | L4: 日 | M4: 週累積 | N4: 月累積 | O4: 日 | P4: 週累積 | Q4: 月累積 | R4: 日 | S4: 週累積 | T4: 月累積 | U4: 日 | V4: 週累積 | W4: 月累積
C5: 一 | D5: 46023 | E5: 四 | F5: 2226674.2 | H5: =SUM(F5:F35) -> 73906002 | I5: 46936 | K5: =SUM(I5:I35) -> 1572945 | L5: 1406826 | N5: =SUM(L5:L35) -> 46645866 | O5: =L5/F5 -> 0.63180594 | Q5: =N5/H5 -> 0.63115125 | T5: 0 | U5: =R5/F5 -> 0 | W5: =T5/H5 -> 0
D6: 46024 | E6: 五 | F6: 1942096.7 | I6: 40942 | L6: 1226646 | O6: =L6/F6 -> 0.63160912 | U6: =R6/F6 -> 0 | V6: =S6/M6 -> #DIV/0!
D7: 46025 | E7: 六 | F7: 2189422.6 | I7: 46190 | L7: 1380846 | O7: =L7/F7 -> 0.63068957 | U7: =R7/F7 -> 0
D8: 46026 | E8: 日 | F8: 2542916.1 | I8: 53732 | L8: 1606646 | O8: =L8/F8 -> 0.63181243 | U8: =R8/F8 -> 0
D9: 46027 | E9: 一 | F9: 2525170.7 | I9: 53395 | L9: 1593646 | O9: =L9/F9 -> 0.63110428 | U9: =R9/F9 -> 0
B10: 46036 | D10: 46028 | E10: 二 | F10: 2404271.4 | G10: =SUM(F10:F16) -> 16024792 | I10: 50902 | J10: =SUM(I10:I16) -> 340021 | L10: 1518646 | M10: =SUM(L10:L16) -> 10118922 | O10: =L10/F10 -> 0.63164499 | P10: =M10/G10 -> 0.6314542 | S10: =SUM(R10:R16) -> 0 | U10: =R10/F10 -> 0
D11: 46029 | E11: 三 | F11: 2398862.3 | I11: 50807 | L11: 1518646 | O11: =L11/F11 -> 0.63306927 | U11: =R11/F11 -> 0
D12: 46030 | E12: 四 | F12: 2212516.4 | I12: 46922 | L12: 1395846 | O12: =L12/F12 -> 0.63088619 | U12: =R12/F12 -> 0
D13: 46031 | E13: 五 | F13: 1901554.6 | I13: 40461 | L13: 1199646 | O13: =L13/F13 -> 0.63087643 | U13: =R13/F13 -> 0 | V13: =S13/M13 -> #DIV/0!
D14: 46032 | E14: 六 | F14: 2097914.6 | I14: 44509 | L14: 1323846 | O14: =L14/F14 -> 0.63102949 | U14: =R14/F14 -> 0
D15: 46033 | E15: 日 | F15: 2521908.2 | I15: 53689 | L15: 1591646 | O15: =L15/F15 -> 0.63112765 | U15: =R15/F15 -> 0
D16: 46034 | E16: 一 | F16: 2487764.2 | I16: 52731 | L16: 1570646 | O16: =L16/F16 -> 0.63134842 | U16: =R16/F16 -> 0
B17: 46043 | D17: 46035 | E17: 二 | F17: 2453924.5 | G17: =SUM(F17:F23) -> 15713578 | I17: 52361 | J17: =SUM(I17:I23) -> 333826 | L17: 1548646 | M17: =SUM(L17:L23) -> 9915482 | O17: =L17/F17 -> 0.63108951 | P17: =M17/G17 -> 0.63101364 | S17: =SUM(R17:R23) -> 0 | U17: =R17/F17 -> 0
D18: 46036 | E18: 三 | F18: 2232406.1 | I18: 47532 | L18: 1408826 | O18: =L18/F18 -> 0.63107962 | U18: =R18/F18 -> 0
D19: 46037 | E19: 四 | F19: 2042060.4 | I19: 43661 | L19: 1287846 | O19: =L19/F19 -> 0.63066009 | U19: =R19/F19 -> 0
D20: 46038 | E20: 五 | F20: 1901136.5 | I20: 40479 | L20: 1200646 | O20: =L20/F20 -> 0.63154118 | U20: =R20/F20 -> 0 | V20: =S20/M20 -> #DIV/0!
D21: 46039 | E21: 六 | F21: 2122148.1 | I21: 45067 | L21: 1338826 | O21: =L21/F21 -> 0.63088244 | U21: =R21/F21 -> 0
D22: 46040 | E22: 日 | F22: 2467886.5 | I22: 52042 | L22: 1558646 | O22: =L22/F22 -> 0.63157119 | U22: =R22/F22 -> 0
D23: 46041 | E23: 一 | F23: 2494015.7 | I23: 52684 | L23: 1572046 | O23: =L23/F23 -> 0.63032723 | U23: =R23/F23 -> 0
B24: 46050 | D24: 46042 | E24: 二 | F24: 2998261.9 | G24: =SUM(F24:F30) -> 18269389 | I24: 65681 | J24: =SUM(I24:I30) -> 392919 | L24: 1890646 | M24: =SUM(L24:L30) -> 11520322 | O24: =L24/F24 -> 0.63058067 | P24: =M24/G24 -> 0.6305806 | S24: =SUM(R24:R30) -> 0 | U24: =R24/F24 -> 0
D25: 46043 | E25: 三 | F25: 2518253.1 | I25: 54921 | L25: 1587446 | O25: =L25/F25 -> 0.63037588 | U25: =R25/F25 -> 0
D26: 46044 | E26: 四 | F26: 2624434.2 | I26: 56062 | L26: 1654646 | O26: =L26/F26 -> 0.63047724 | U26: =R26/F26 -> 0
D27: 46045 | E27: 五 | F27: 2037145.7 | I27: 43620 | L27: 1283846 | O27: =L27/F27 -> 0.63021807 | U27: =R27/F27 -> 0 | V27: =S27/M27 -> #DIV/0!
D28: 46046 | E28: 六 | F28: 2368780.8 | I28: 50213 | L28: 1493646 | O28: =L28/F28 -> 0.63055475 | U28: =R28/F28 -> 0
D29: 46047 | E29: 日 | F29: 2961303.2 | I29: 63573 | L29: 1868446 | O29: =L29/F29 -> 0.63095397 | U29: =R29/F29 -> 0
D30: 46048 | E30: 一 | F30: 2761209.8 | I30: 58849 | L30: 1741646 | O30: =L30/F30 -> 0.63075469 | U30: =R30/F30 -> 0
B31: 46057 | D31: 46049 | E31: 二 | F31: 2551423.9 | G31: =SUM(F31:F37) -> 12471964 | I31: 54594 | J31: =SUM(I31:I37) -> 264984 | L31: 1612446 | M31: =SUM(L31:L37) -> 7876530 | O31: =L31/F31 -> 0.63197888 | P31: =M31/G31 -> 0.63153888 | S31: =SUM(R31:R37) -> 0 | U31: =R31/F31 -> 0
D32: 46050 | E32: 三 | F32: 2542380.2 | I32: 54168 | L32: 1607046 | O32: =L32/F32 -> 0.63210293 | U32: =R32/F32 -> 0
D33: 46051 | E33: 四 | F33: 2589823.7 | I33: 54574 | L33: 1634446 | O33: =L33/F33 -> 0.63110318 | U33: =R33/F33 -> 0
D34: 46052 | E34: 五 | F34: 2295961.3 | I34: 49058 | L34: 1449646 | O34: =L34/F34 -> 0.63138957 | U34: =R34/F34 -> 0
D35: 46053 | E35: 六 | F35: 2492374.6 | I35: 52590 | L35: 1572946 | O35: =L35/F35 -> 0.63110337 | U35: =R35/F35 -> 0
D36: 46054 | E36: 日 | O36: =L36/F36 -> #DIV/0!
D37: 46055 | E37: 一 | O37: =L37/F37 -> #DIV/0! | V37: =SUM(U37:U43) -> 0
O38: =L38/F38 -> #DIV/0!
O39: =L39/F39 -> #DIV/0!
O40: =L40/F40 -> #DIV/0!

Sheet （２）ＫＰＩ達成進度
C1: 112.8
B2: （２）ＫＰＩ達成進度
B3: 資料繳交日 | C3: 月份 | D3: 日期 | F3: 人時生產性(個/人) | I3: 人時生產性達成率(%) | L3: 半成品報廢(%) | O3: 半成品超用(%) | R3: 固定產線-導入率(固定產線數/總產線數) | U3: 教育訓練-實施率(進度/計畫)
F4: 日 | G4: 週平均 | H4: 月平均 | I4: 日 | J4: 週平均 | K4: 月平均 | L4: 日 | M4: 週平均 | N4: 月平均 | O4: 日 | P4: 週平均 | Q4: 月平均 | R4: 日 | S4: 週平均 | T4: 月平均 | U4: 日 | V4: 週平均 | W4: 月平均
C5: 一 | D5: 46023 | E5: 四 | F5: 95.4 | H5: =AVERAGE(F5:F35) -> 99.593548 | I5: =F5/$C$1 -> 0.84574468 | K5: =AVERAGE(I5:I35) -> 0.88292153 | L5: 0.0034163058 | N5: =AVERAGE(L5:L35) -> 0.0033669673 | O5: 0.0016109227 | Q5: =AVERAGE(O5:O35) -> 0.0022864484 | R5: 0.2857 | T5: =AVERAGE(R5:R35) -> 0.2857 | U5: 0.833 | W5: =AVERAGE(U5:U35) -> 0.9031871
D6: 46024 | E6: 五 | F6: 92 | I6: =F6/$C$1 -> 0.81560284 | L6: 0.0058905408 | O6: 0.0025616644 | R6: 0.2857 | U6: 0.833
D7: 46025 | E7: 六 | F7: 94.6 | I7: =F7/$C$1 -> 0.83865248 | L7: 0.0023755121 | O7: 0.0021275016 | R7: 0.2857 | U7: 0.833
D8: 46026 | E8: 日 | F8: 95.4 | I8: =F8/$C$1 -> 0.84574468 | L8: 0.0025753897 | O8: 0.00086868773 | R8: 0.2857 | U8: 0.833
D9: 46027 | E9: 一 | F9: 102.1 | I9: =F9/$C$1 -> 0.90514184 | L9: 0.00042531779 | O9: 0.00096191518 | R9: 0.2857 | U9: 0.833
B10: 46036 | D10: 46028 | E10: 二 | F10: 101.2 | G10: =AVERAGE(F10:F16) -> 96.6 | I10: =F10/$C$1 -> 0.89716312 | J10: =AVERAGE(I10:I16) -> 0.85638298 | L10: 0.0018350674 | M10: =AVERAGE(L10:L16) -> 0.004586451 | O10: 0.0011783195 | P10: =AVERAGE(O10:O16) -> 0.0023241943 | R10: 0.2857 | S10: =AVERAGE(R10:R16) -> 0.2857 | U10: 0.833 | V10: =AVERAGE(U10:U16) -> 0.88705714
D11: 46029 | E11: 三 | F11: 94.7 | I11: =F11/$C$1 -> 0.83953901 | L11: 0.0018512943 | O11: 0.0035766955 | R11: 0.2857 | U11: 0.833
D12: 46030 | E12: 四 | F12: 92.1 | I12: =F12/$C$1 -> 0.81648936 | L12: 0.0022426953 | O12: 0.0014752433 | R12: 0.2857 | U12: 0.833
D13: 46031 | E13: 五 | F13: 91.1 | I13: =F13/$C$1 -> 0.80762411 | L13: 0.009134631 | O13: 0.0039683319 | R13: 0.2857 | U13: 0.9276
D14: 46032 | E14: 六 | F14: 98.3 | I14: =F14/$C$1 -> 0.8714539 | L14: 0.0069359352 | O14: 0.0016449668 | R14: 0.2857 | U14: 0.9276
D15: 46033 | E15: 日 | F15: 101.3 | I15: =F15/$C$1 -> 0.89804965 | L15: 0.0076386603 | O15: 0.0016297183 | R15: 0.2857 | U15: 0.9276
D16: 46034 | E16: 一 | F16: 97.5 | I16: =F16/$C$1 -> 0.8643617 | L16: 0.0024668736 | O16: 0.0027960849 | R16: 0.2857 | U16: 0.9276
B17: 46043 | D17: 46035 | E17: 二 | F17: 100.5 | G17: =AVERAGE(F17:F23) -> 101.62857 | I17: =F17/$C$1 -> 0.89095745 | J17: =AVERAGE(I17:I23) -> 0.90096251 | L17: 0.0018810685 | M17: =AVERAGE(L17:L23) -> 0.0035858674 | O17: 0.00073922406 | P17: =AVERAGE(O17:O23) -> 0.0023320924 | R17: 0.2857 | S17: =AVERAGE(R17:R23) -> 0.2857 | U17: 0.9276 | V17: =AVERAGE(U17:U23) -> 0.9276
D18: 46036 | E18: 三 | F18: 98.8 | I18: =F18/$C$1 -> 0.87588652 | L18: 0.0047415208 | O18: 0.0027844396 | R18: 0.2857 | U18: 0.9276
D19: 46037 | E19: 四 | F19: 98.9 | I19: =F19/$C$1 -> 0.87677305 | L19: 0.01125285 | O19: 0.0044112309 | R19: 0.2857 | U19: 0.9276
D20: 46038 | E20: 五 | F20: 102.2 | I20: =F20/$C$1 -> 0.90602837 | L20: 0.0011430005 | O20: 0.0017678899 | R20: 0.2857 | U20: 0.9276
D21: 46039 | E21: 六 | F21: 102.4 | I21: =F21/$C$1 -> 0.90780142 | L21: 0.0022236902 | O21: 0.0038965234 | R21: 0.2857 | U21: 0.9276
D22: 46040 | E22: 日 | F22: 103.3 | I22: =F22/$C$1 -> 0.91578014 | L22: 0.002000092 | O22: 0.0011495667 | R22: 0.2857 | U22: 0.9276
D23: 46041 | E23: 一 | F23: 105.3 | I23: =F23/$C$1 -> 0.93351064 | L23: 0.0018588496 | O23: 0.001575772 | R23: 0.2857 | U23: 0.9276
B24: 46050 | D24: 46042 | E24: 二 | F24: 94.8 | G24: =AVERAGE(F24:F30) -> 100.8 | I24: =F24/$C$1 -> 0.84042553 | J24: =AVERAGE(I24:I30) -> 0.89361702 | L24: 0.0029823945 | M24: =AVERAGE(L24:L30) -> 0.0027983954 | O24: 0.0015842512 | P24: =AVERAGE(O24:O30) -> 0.0019335476 | R24: 0.2857 | S24: =AVERAGE(R24:R30) -> 0.2857 | U24: 0.9276 | V24: =AVERAGE(U24:U30) -> 0.9276
D25: 46043 | E25: 三 | F25: 99.4 | I25: =F25/$C$1 -> 0.88120567 | L25: 0.0041588354 | O25: 0.0013501423 | R25: 0.2857 | U25: 0.9276
D26: 46044 | E26: 四 | F26: 98.7 | I26: =F26/$C$1 -> 0.875 | L26: 0.0020301519 | O26: 0.0016060605 | R26: 0.2857 | U26: 0.9276
D27: 46045 | E27: 五 | F27: 98.2 | I27: =F27/$C$1 -> 0.87056738 | L27: 0.0021230686 | O27: 0.0004913738 | R27: 0.2857 | U27: 0.9276
D28: 46046 | E28: 六 | F28: 106 | I28: =F28/$C$1 -> 0.93971631 | L28: 0.0039940377 | O28: 0.0044145072 | R28: 0.2857 | U28: 0.9276
D29: 46047 | E29: 日 | F29: 102.1 | I29: =F29/$C$1 -> 0.90514184 | L29: 0.0024539872 | O29: 0.0028676564 | R29: 0.2857 | U29: 0.9276
D30: 46048 | E30: 一 | F30: 106.4 | I30: =F30/$C$1 -> 0.94326241 | L30: 0.0018462922 | O30: 0.0012208417 | R30: 0.2857 | U30: 0.9276
B31: 46057 | D31: 46049 | E31: 二 | F31: 102.3 | G31: =AVERAGE(F31:F37) -> 102.94 | I31: =F31/$C$1 -> 0.90691489 | J31: =AVERAGE(I31:I37) -> 0.65184904 | L31: 0.0023383022 | M31: =AVERAGE(L31:L37) -> 0.0025795846 | O31: 0.0010327567 | P31: =AVERAGE(O31:O37) -> 0.0033240737 | R31: 0.2857 | S31: =AVERAGE(R31:R37) -> 0.2857 | U31: 0.9276 | V31: =AVERAGE(U31:U37) -> 0.9276
D32: 46050 | E32: 三 | F32: 104.2 | I32: =F32/$C$1 -> 0.92375887 | L32: 0.0022872267 | O32: 0.0029554981 | R32: 0.2857 | U32: 0.9276
D33: 46051 | E33: 四 | F33: 102.8 | I33: =F33/$C$1 -> 0.91134752 | L33: 0.0033894199 | O33: 0.0033376789 | R33: 0.2857 | U33: 0.9276
D34: 46052 | E34: 五 | F34: 100.8 | I34: =F34/$C$1 -> 0.89361702 | L34: 0.002383751 | O34: 0.0027962144 | R34: 0.2857 | U34: 0.9276
D35: 46053 | E35: 六 | F35: 104.6 | I35: =F35/$C$1 -> 0.92730496 | L35: 0.002499223 | O35: 0.0064982206 | R35: 0.2857 | U35: 0.9276
D36: 46054 | E36: 日 | I36: =F36/$C$1 -> 0
D37: 46055 | E37: 一 | I37: =F37/$C$1 -> 0

Sheet （３）業績構成比
B2: （3）業績構成比
B3: 資料繳交日 | C3: 月份 | D3: 日期 | F3: 營業額 | I3: 品類業績
I4: 熱食義麵 | K4: 季節調理麵 | M4: 微波小吃
F5: 日 | G5: 週累積 | H5: 月累積 | I5: 一配 | K5: 一配 | M5: 一配
I6: 業績(元) | J6: 比例(%) | K6: 業績(元) | L6: 比例(%) | M6: 業績(元) | N6: 比例(%)
C7: 一 | D7: 46023 | E7: 四 | F7: =I7+M7 -> 2226674.2 | H7: =SUM(F7:F37) -> 73906002 | I7: 2051241.4 | J7: =I7/F7 -> 0.92121306 | L7: =K7/F7 -> 0 | M7: 175432.84 | N7: =M7/F7 -> 0.078786936
D8: 46024 | E8: 五 | F8: =I8+M8 -> 1942096.7 | I8: 1798121.2 | J8: =I8/F8 -> 0.92586595 | L8: =K8/F8 -> 0 | M8: 143975.5 | N8: =M8/F8 -> 0.074134052
D9: 46025 | E9: 六 | F9: =I9+M9 -> 2189422.6 | I9: 2020696.8 | J9: =I9/F9 -> 0.92293593 | L9: =K9/F9 -> 0 | M9: 168725.82 | N9: =M9/F9 -> 0.077064071
D10: 46026 | E10: 日 | F10: =I10+M10 -> 2542916.1 | I10: 2352461.2 | J10: =I10/F10 -> 0.92510375 | L10: =K10/F10 -> 0 | M10: 190454.89 | N10: =M10/F10 -> 0.074896254
D11: 46027 | E11: 一 | F11: =I11+M11 -> 2525170.7 | I11: 2327172 | J11: =I11/F11 -> 0.92158997 | L11: =K11/F11 -> 0 | M11: 197998.7 | N11: =M11/F11 -> 0.078410027
B12: 46036 | D12: 46028 | E12: 二 | F12: =I12+M12 -> 2404271.4 | G12: =SUM(F12:F18) -> 16024792 | I12: 2213659.4 | J12: =I12/F12 -> 0.92071944 | L12: =K12/F12 -> 0 | M12: 190611.99 | N12: =M12/F12 -> 0.079280562
D13: 46029 | E13: 三 | F13: =I13+M13 -> 2398862.3 | I13: 2202216.9 | J13: =I13/F13 -> 0.91802554 | L13: =K13/F13 -> 0 | M13: 196645.44 | N13: =M13/F13 -> 0.08197446
D14: 46030 | E14: 四 | F14: =I14+M14 -> 2212516.4 | I14: 2027834.5 | J14: =I14/F14 -> 0.91652858 | L14: =K14/F14 -> 0 | M14: 184681.88 | N14: =M14/F14 -> 0.083471419
D15: 46031 | E15: 五 | F15: =I15+M15 -> 1901554.6 | I15: 1744086.2 | J15: =I15/F15 -> 0.91718963 | L15: =K15/F15 -> 0 | M15: 157468.44 | N15: =M15/F15 -> 0.082810368
D16: 46032 | E16: 六 | F16: =I16+M16 -> 2097914.6 | I16: 1923722.2 | J16: =I16/F16 -> 0.91696877 | L16: =K16/F16 -> 0 | M16: 174192.43 | N16: =M16/F16 -> 0.083031229
D17: 46033 | E17: 日 | F17: =I17+M17 -> 2521908.2 | I17: 2315859.6 | J17: =I17/F17 -> 0.91829655 | L17: =K17/F17 -> 0 | M17: 206048.6 | N17: =M17/F17 -> 0.08170345
D18: 46034 | E18: 一 | F18: =I18+M18 -> 2487764.2 | I18: 2287407.7 | J18: =I18/F18 -> 0.9194632 | L18: =K18/F18 -> 0 | M18: 200356.56 | N18: =M18/F18 -> 0.080536796
B19: 46043 | D19: 46035 | E19: 二 | F19: =I19+M19 -> 2453924.5 | G19: =SUM(F19:F25) -> 15713578 | I19: 2255797.2 | J19: =I19/F19 -> 0.91926105 | L19: =K19/F19 -> 0 | M19: 198127.29 | N19: =M19/F19 -> 0.080738952
D20: 46036 | E20: 三 | F20: =I20+M20 -> 2232406.1 | I20: 2047648.1 | J20: =I20/F20 -> 0.91723818 | L20: =K20/F20 -> 0 | M20: 184758 | N20: =M20/F20 -> 0.082761824
D21: 46037 | E21: 四 | F21: =I21+M21 -> 2042060.4 | I21: 1859636.4 | J21: =I21/F21 -> 0.91066671 | L21: =K21/F21 -> 0 | M21: 182423.98 | N21: =M21/F21 -> 0.089333293
D22: 46038 | E22: 五 | F22: =I22+M22 -> 1901136.5 | I22: 1755348.3 | J22: =I22/F22 -> 0.92331522 | L22: =K22/F22 -> 0 | M22: 145788.23 | N22: =M22/F22 -> 0.076684777
D23: 46039 | E23: 六 | F23: =I23+M23 -> 2122148.1 | I23: 1958563.6 | J23: =I23/F23 -> 0.92291558 | L23: =K23/F23 -> 0 | M23: 163584.56 | N23: =M23/F23 -> 0.07708442
D24: 46040 | E24: 日 | F24: =I24+M24 -> 2467886.5 | I24: 2309290.4 | J24: =I24/F24 -> 0.93573608 | L24: =K24/F24 -> 0 | M24: 158596.05 | N24: =M24/F24 -> 0.064263917
D25: 46041 | E25: 一 | F25: =I25+M25 -> 2494015.7 | I25: 2317836.2 | J25: =I25/F25 -> 0.92935912 | L25: =K25/F25 -> 0 | M25: 176179.46 | N25: =M25/F25 -> 0.070640879
B26: 46050 | D26: 46042 | E26: 二 | F26: =I26+M26 -> 2998261.9 | G26: =SUM(F26:F32) -> 18269389 | I26: 2571737.2 | J26: =I26/F26 -> 0.85774269 | L26: =K26/F26 -> 0 | M26: 426524.69 | N26: =M26/F26 -> 0.14225731
D27: 46043 | E27: 三 | F27: =I27+M27 -> 2518253.1 | I27: 2204016.4 | J27: =I27/F27 -> 0.87521642 | L27: =K27/F27 -> 0 | M27: 314236.63 | N27: =M27/F27 -> 0.12478358
D28: 46044 | E28: 四 | F28: =I28+M28 -> 2624434.2 | I28: 2334346.2 | J28: =I28/F28 -> 0.88946647 | L28: =K28/F28 -> 0 | M28: 290087.96 | N28: =M28/F28 -> 0.11053353
D29: 46045 | E29: 五 | F29: =I29+M29 -> 2037145.7 | I29: 1848792.6 | J29: =I29/F29 -> 0.90754072 | L29: =K29/F29 -> 0 | M29: 188353.03 | N29: =M29/F29 -> 0.092459285
D30: 46046 | E30: 六 | F30: =I30+M30 -> 2368780.8 | I30: 2149544.8 | J30: =I30/F30 -> 0.90744774 | L30: =K30/F30 -> 0 | M30: 219236.01 | N30: =M30/F30 -> 0.092552256
D31: 46047 | E31: 日 | F31: =I31+M31 -> 2961303.2 | I31: 2644189.6 | J31: =I31/F31 -> 0.89291419 | L31: =K31/F31 -> 0 | M31: 317113.56 | N31: =M31/F31 -> 0.10708581
D32: 46048 | E32: 一 | F32: =I32+M32 -> 2761209.8 | I32: 2501915.3 | J32: =I32/F32 -> 0.90609388 | L32: =K32/F32 -> 0 | M32: 259294.49 | N32: =M32/F32 -> 0.093906118
B33: 46057 | D33: 46049 | E33: 二 | F33: =I33+M33 -> 2551423.9 | G33: =SUM(F33:F39) -> 12471964 | I33: 2314194.8 | J33: =I33/F33 -> 0.90702091 | L33: =K33/F33 -> 0 | M33: 237229.07 | N33: =M33/F33 -> 0.09297909
D34: 46050 | E34: 三 | F34: =I34+M34 -> 2542380.2 | I34: 2309341.5 | J34: =I34/F34 -> 0.90833834 | L34: =K34/F34 -> 0 | M34: 233038.8 | N34: =M34/F34 -> 0.091661662
D35: 46051 | E35: 四 | F35: =I35+M35 -> 2589823.7 | I35: 2365683.5 | J35: =I35/F35 -> 0.91345348 | L35: =K35/F35 -> 0 | M35: 224140.22 | N35: =M35/F35 -> 0.086546515
D36: 46052 | E36: 五 | F36: =I36+M36 -> 2295961.3 | I36: 2074512.9 | J36: =I36/F36 -> 0.90354873 | L36: =K36/F36 -> 0 | M36: 221448.39 | N36: =M36/F36 -> 0.096451274
D37: 46053 | E37: 六 | F37: =I37+M37 -> 2492374.6 | I37: 2290975.7 | J37: =I37/F37 -> 0.91919397 | L37: =K37/F37 -> 0 | M37: 201398.89 | N37: =M37/F37 -> 0.080806028
D38: 46054 | E38: 日 | F38: =I38+M38 -> 0 | J38: =I38/F38 -> #DIV/0! | N38: =M38/F38 -> #DIV/0!
D39: 46055 | E39: 一 | F39: =I39+M39 -> 0 | J39: =I39/F39 -> #DIV/0! | N39: =M39/F39 -> #DIV/0!

Sheet （４）訂單數量構成比
B2: （4）訂單數量構成比
B3: 資料繳交日 | C3: 月份 | D3: 日期 | F3: 訂單量 | I3: 品類訂單量
I4: 熱食義麵 | K4: 季節調理麵 | M4: 微波小吃
F5: 日 | G5: 週累積 | H5: 月累積 | I5: 一配 | K5: 一配 | M5: 一配
I6: 訂單數 | J6: 比例(%) | K6: 訂單數 | L6: 比例(%) | M6: 訂單數 | N6: 比例(%)
C7: 一 | D7: 46023 | E7: 四 | F7: =SUM(I7,K7,M7) -> 46936 | H7: =SUM(F7:F37) -> 1572945 | I7: 40568 | J7: =I7/F7 -> 0.86432589 | L7: =K7/F7 -> 0 | M7: 6368 | N7: =M7/F7 -> 0.13567411
D8: 46024 | E8: 五 | F8: =SUM(I8,K8,M8) -> 40942 | I8: 35709 | J8: =I8/F8 -> 0.87218504 | L8: =K8/F8 -> 0 | M8: 5233 | N8: =M8/F8 -> 0.12781496
D9: 46025 | E9: 六 | F9: =SUM(I9,K9,M9) -> 46190 | I9: 40068 | J9: =I9/F9 -> 0.86746049 | L9: =K9/F9 -> 0 | M9: 6122 | N9: =M9/F9 -> 0.13253951
D10: 46026 | E10: 日 | F10: =SUM(I10,K10,M10) -> 53732 | I10: 46794 | J10: =I10/F10 -> 0.87087769 | L10: =K10/F10 -> 0 | M10: 6938 | N10: =M10/F10 -> 0.12912231
D11: 46027 | E11: 一 | F11: =SUM(I11,K11,M11) -> 53395 | I11: 46199 | J11: =I11/F11 -> 0.86523083 | L11: =K11/F11 -> 0 | M11: 7196 | N11: =M11/F11 -> 0.13476917
B12: 46036 | D12: 46028 | E12: 二 | F12: =SUM(I12,K12,M12) -> 50902 | G12: =SUM(F12:F18) -> 340021 | I12: 43968 | J12: =I12/F12 -> 0.86377745 | L12: =K12/F12 -> 0 | M12: 6934 | N12: =M12/F12 -> 0.13622255
D13: 46029 | E13: 三 | F13: =SUM(I13,K13,M13) -> 50807 | I13: 43657 | J13: =I13/F13 -> 0.85927136 | L13: =K13/F13 -> 0 | M13: 7150 | N13: =M13/F13 -> 0.14072864
D14: 46030 | E14: 四 | F14: =SUM(I14,K14,M14) -> 46922 | I14: 40206 | J14: =I14/F14 -> 0.85686885 | L14: =K14/F14 -> 0 | M14: 6716 | N14: =M14/F14 -> 0.14313115
D15: 46031 | E15: 五 | F15: =SUM(I15,K15,M15) -> 40461 | I15: 34721 | J15: =I15/F15 -> 0.85813499 | L15: =K15/F15 -> 0 | M15: 5740 | N15: =M15/F15 -> 0.14186501
D16: 46032 | E16: 六 | F16: =SUM(I16,K16,M16) -> 44509 | I16: 38173 | J16: =I16/F16 -> 0.85764677 | L16: =K16/F16 -> 0 | M16: 6336 | N16: =M16/F16 -> 0.14235323
D17: 46033 | E17: 日 | F17: =SUM(I17,K17,M17) -> 53689 | I17: 46167 | J17: =I17/F17 -> 0.85989681 | L17: =K17/F17 -> 0 | M17: 7522 | N17: =M17/F17 -> 0.14010319
D18: 46034 | E18: 一 | F18: =SUM(I18,K18,M18) -> 52731 | I18: 45437 | J18: =I18/F18 -> 0.8616753 | L18: =K18/F18 -> 0 | M18: 7294 | N18: =M18/F18 -> 0.1383247
B19: 46043 | D19: 46035 | E19: 二 | F19: =SUM(I19,K19,M19) -> 52361 | G19: =SUM(F19:F25) -> 333826 | I19: 45139 | J19: =I19/F19 -> 0.86207292 | L19: =K19/F19 -> 0 | M19: 7222 | N19: =M19/F19 -> 0.13792708
D20: 46036 | E20: 三 | F20: =SUM(I20,K20,M20) -> 47532 | I20: 40806 | J20: =I20/F20 -> 0.85849533 | L20: =K20/F20 -> 0 | M20: 6726 | N20: =M20/F20 -> 0.14150467
D21: 46037 | E21: 四 | F21: =SUM(I21,K21,M21) -> 43661 | I21: 37017 | J21: =I21/F21 -> 0.84782758 | L21: =K21/F21 -> 0 | M21: 6644 | N21: =M21/F21 -> 0.15217242
D22: 46038 | E22: 五 | F22: =SUM(I22,K22,M22) -> 40479 | I22: 35165 | J22: =I22/F22 -> 0.86872205 | L22: =K22/F22 -> 0 | M22: 5314 | N22: =M22/F22 -> 0.13127795
D23: 46039 | E23: 六 | F23: =SUM(I23,K23,M23) -> 45067 | I23: 39118 | J23: =I23/F23 -> 0.86799654 | L23: =K23/F23 -> 0 | M23: 5949 | N23: =M23/F23 -> 0.13200346
D24: 46040 | E24: 日 | F24: =SUM(I24,K24,M24) -> 52042 | I24: 46266 | J24: =I24/F24 -> 0.88901272 | L24: =K24/F24 -> 0 | M24: 5776 | N24: =M24/F24 -> 0.11098728
D25: 46041 | E25: 一 | F25: =SUM(I25,K25,M25) -> 52684 | I25: 46277 | J25: =I25/F25 -> 0.87838813 | L25: =K25/F25 -> 0 | M25: 6407 | N25: =M25/F25 -> 0.12161187
B26: 46050 | D26: 46042 | E26: 二 | F26: =SUM(I26,K26,M26) -> 65681 | G26: =SUM(F26:F32) -> 392919 | I26: 50410 | J26: =I26/F26 -> 0.76749745 | L26: =K26/F26 -> 0 | M26: 15271 | N26: =M26/F26 -> 0.23250255
D27: 46043 | E27: 三 | F27: =SUM(I27,K27,M27) -> 54921 | I27: 43626 | J27: =I27/F27 -> 0.79434096 | L27: =K27/F27 -> 0 | M27: 11295 | N27: =M27/F27 -> 0.20565904
D28: 46044 | E28: 四 | F28: =SUM(I28,K28,M28) -> 56062 | I28: 45641 | J28: =I28/F28 -> 0.81411651 | L28: =K28/F28 -> 0 | M28: 10421 | N28: =M28/F28 -> 0.18588349
D29: 46045 | E29: 五 | F29: =SUM(I29,K29,M29) -> 43620 | I29: 36825 | J29: =I29/F29 -> 0.84422283 | L29: =K29/F29 -> 0 | M29: 6795 | N29: =M29/F29 -> 0.15577717
D30: 46046 | E30: 六 | F30: =SUM(I30,K30,M30) -> 50213 | I30: 42319 | J30: =I30/F30 -> 0.84278972 | L30: =K30/F30 -> 0 | M30: 7894 | N30: =M30/F30 -> 0.15721028
D31: 46047 | E31: 日 | F31: =SUM(I31,K31,M31) -> 63573 | I31: 52169 | J31: =I31/F31 -> 0.82061567 | L31: =K31/F31 -> 0 | M31: 11404 | N31: =M31/F31 -> 0.17938433
D32: 46048 | E32: 一 | F32: =SUM(I32,K32,M32) -> 58849 | I32: 49500 | J32: =I32/F32 -> 0.84113579 | L32: =K32/F32 -> 0 | M32: 9349 | N32: =M32/F32 -> 0.15886421
B33: 46057 | D33: 46049 | E33: 二 | F33: =SUM(I33,K33,M33) -> 54594 | G33: =SUM(F33:F39) -> 264984 | I33: 46035 | J33: =I33/F33 -> 0.84322453 | L33: =K33/F33 -> 0 | M33: 8559 | N33: =M33/F33 -> 0.15677547
D34: 46050 | E34: 三 | F34: =SUM(I34,K34,M34) -> 54168 | I34: 45768 | J34: =I34/F34 -> 0.84492689 | L34: =K34/F34 -> 0 | M34: 8400 | N34: =M34/F34 -> 0.15507311
D35: 46051 | E35: 四 | F35: =SUM(I35,K35,M35) -> 54574 | I35: 46495 | J35: =I35/F35 -> 0.85196247 | L35: =K35/F35 -> 0 | M35: 8079 | N35: =M35/F35 -> 0.14803753
D36: 46052 | E36: 五 | F36: =SUM(I36,K36,M36) -> 49058 | I36: 41087 | J36: =I36/F36 -> 0.83751886 | L36: =K36/F36 -> 0 | M36: 7971 | N36: =M36/F36 -> 0.16248114
D37: 46053 | E37: 六 | F37: =SUM(I37,K37,M37) -> 52590 | I37: 45324 | J37: =I37/F37 -> 0.86183685 | L37: =K37/F37 -> 0 | M37: 7266 | N37: =M37/F37 -> 0.13816315
D38: 46054 | E38: 日 | F38: =SUM(I38,K38,M38) -> 0 | J38: =I38/F38 -> #DIV/0! | N38: =M38/F38 -> #DIV/0!
D39: 46055 | E39: 一 | F39: =SUM(I39,K39,M39) -> 0 | J39: =I39/F39 -> #DIV/0! | N39: =M39/F39 -> #DIV/0!

Sheet （５-1）品群別人時生產性（熱食義麵）
B1: 月平均人時性 | C1: =AVERAGE(L7,L30,L53,L76,L99,L122) -> 98.714281
B2: 產線配置圖－每週更新 | N2: 資料繳交 | O2: 日期 | Z2: 46023 | AE2: 46024 | AJ2: 46025 | AO2: 46026 | AT2: 46027
P3: 二 | U3: 三 | Z3: 四 | AE3: 五 | AJ3: 六 | AO3: 日 | AT3: 一
B4: 品群 | C4: 商品名稱 | E4: 計畫 | H4: 平均人時性 | I4: 實績 | L4: 平均人時性 | M4: 排名 | O4: 日報 | P4: 實際 | T4: 平均人時性 | U4: 實際 | Y4: 平均人時性 | Z4: 實際 | AD4: 平均人時性 | AE4: 實際 | AI4: 平均人時性 | AJ4: 實際 | AN4: 平均人時性 | AO4: 實際 | AS4: 平均人時性 | AT4: 實際 | AX4: 平均人時性
E5: 產線配置圖 | I5: 產線配置圖 | P5: 生產實績 | U5: 生產實績 | Z5: 生產實績 | AE5: 生產實績 | AJ5: 生產實績 | AO5: 生產實績 | AT5: 生產實績
E6: 人數 | F6: 產能／時 | G6: 人時性 | I6: 人數 | J6: 產能／時 | K6: 人時性 | P6: 人數 | Q6: 產能／時 | R6: 人時性 | S6: 排名 | U6: 人數 | V6: 產能／時 | W6: 人時性 | X6: 排名 | Z6: 人數 | AA6: 產能／時 | AB6: 人時性 | AC6: 排名 | AE6: 人數 | AF6: 產能／時 | AG6: 人時性 | AH6: 排名 | AJ6: 人數 | AK6: 產能／時 | AL6: 人時性 | AM6: 排名 | AO6: 人數 | AP6: 產能／時 | AQ6: 人時性 | AR6: 排名 | AT6: 人數 | AU6: 產能／時 | AV6: 人時性 | AW6: 排名
B7: 熱食義麵 | C7: 1 | D7: 義式蕃茄起司義大利麵 | E7: =VLOOKUP(D7,'12產線配置圖 (2)'!$A$2:$C$25,2,0) -> 12 | F7: =VLOOKUP(D7,'12產線配置圖 (2)'!$A$2:$C$25,3,0) -> 2000 | G7: =F7/E7 -> 166.66667 | H7: =AVERAGE(G7:G24) -> 108.17676 | I7: =AVERAGE(P7,U7,Z7,AE7,AJ7,AO7,AT7) -> 12 | J7: =AVERAGE(Q7,V7,AA7,AF7,AK7,AP7,AU7) -> 1764.4 | K7: =AVERAGE(AB7,AG7,AL7,AQ7,AV7) -> 147.03333 | L7: =IFERROR(AVERAGE(K7:K24),"-") -> 94.972233 | M7: =RANK(K7,$K$7:$K$22) -> 1 | R7: =Q7/P7 -> #DIV/0! | S7: =RANK(R7,R$7:R$22) -> #DIV/0! | T7: =AVERAGE(R7:R24) -> #DIV/0! | W7: =V7/U7 -> #DIV/0! | X7: =RANK(W7,W$7:W$22) -> #DIV/0! | Y7: =AVERAGE(W7:W24) -> #DIV/0! | Z7: 12 | AA7: 1577 | AB7: =AA7/Z7 -> 131.41667 | AC7: =RANK(AB7,AB$7:AB$22) -> 3 | AD7: =AVERAGE(AB7:AB24) -> 95.058132 | AE7: 12 | AF7: 1604 | AG7: =AF7/AE7 -> 133.66667 | AH7: =RANK(AG7,AG$7:AG$22) -> 3 | AI7: =AVERAGE(AG7:AG24) -> 91.564589 | AJ7: 12 | AK7: 1881 | AL7: =AK7/AJ7 -> 156.75 | AM7: =RANK(AL7,AL$7:AL$22) -> 1 | AN7: =AVERAGE(AL7:AL24) -> 95.613343 | AO7: 12 | AP7: 1873 | AQ7: =AP7/AO7 -> 156.08333 | AR7: =RANK(AQ7,AQ$7:AQ$22) -> 1 | AS7: =AVERAGE(AQ7:AQ24) -> 92.271357 | AT7: 12 | AU7: 1887 | AV7: =AU7/AT7 -> 157.25 | AW7: =RANK(AV7,AV$7:AV$22) -> 1 | AX7: =AVERAGE(AV7:AV24) -> 100.35374
C8: 2 | D8: 奶油培根義大利麵 | E8: =VLOOKUP(D8,'12產線配置圖 (2)'!$A$2:$C$25,2,0) -> 14 | F8: =VLOOKUP(D8,'12產線配置圖 (2)'!$A$2:$C$25,3,0) -> 2000 | G8: =F8/E8 -> 142.85714 | I8: =AVERAGE(P8,U8,Z8,AE8,AJ8,AO8,AT8) -> 13 | J8: =AVERAGE(Q8,V8,AA8,AF8,AK8,AP8,AU8) -> 1766.2 | K8: =AVERAGE(AB8,AG8,AL8,AQ8,AV8) -> 135.86154 | M8: =RANK(K8,$K$7:$K$22) -> 3 | R8: =Q8/P8 -> #DIV/0! | S8: =RANK(R8,R$7:R$22) -> #DIV/0! | W8: =V8/U8 -> #DIV/0! | X8: =RANK(W8,W$7:W$22) -> #DIV/0! | Z8: 13 | AA8: 1592 | AB8: =AA8/Z8 -> 122.46154 | AC8: =RANK(AB8,AB$7:AB$22) -> 4 | AE8: 13 | AF8: 1786 | AG8: =AF8/AE8 -> 137.38462 | AH8: =RANK(AG8,AG$7:AG$22) -> 2 | AJ8: 13 | AK8: 1813 | AL8: =AK8/AJ8 -> 139.46154 | AM8: =RANK(AL8,AL$7:AL$22) -> 4 | AO8: 13 | AP8: 1852 | AQ8: =AP8/AO8 -> 142.46154 | AR8: =RANK(AQ8,AQ$7:AQ$22) -> 3 | AT8: 13 | AU8: 1788 | AV8: =AU8/AT8 -> 137.53846 | AW8: =RANK(AV8,AV$7:AV$22) -> 4
C9: 3 | D9: 青醬蛤蜊義大利麵 | E9: =VLOOKUP(D9,'12產線配置圖 (2)'!$A$2:$C$25,2,0) -> 13 | F9: =VLOOKUP(D9,'12產線配置圖 (2)'!$A$2:$C$25,3,0) -> 2000 | G9: =F9/E9 -> 153.84615 | I9: =AVERAGE(P9,U9,Z9,AE9,AJ9,AO9,AT9) -> 13 | J9: =AVERAGE(Q9,V9,AA9,AF9,AK9,AP9,AU9) -> 1841 | K9: =AVERAGE(AB9,AG9,AL9,AQ9,AV9) -> 141.61538 | M9: =RANK(K9,$K$7:$K$22) -> 2 | R9: =Q9/P9 -> #DIV/0! | S9: =RANK(R9,R$7:R$22) -> #DIV/0! | W9: =V9/U9 -> #DIV/0! | X9: =RANK(W9,W$7:W$22) -> #DIV/0! | Z9: 13 | AA9: 1991 | AB9: =AA9/Z9 -> 153.15385 | AC9: =RANK(AB9,AB$7:AB$22) -> 1 | AE9: 13 | AF9: 1485 | AG9: =AF9/AE9 -> 114.23077 | AH9: =RANK(AG9,AG$7:AG$22) -> 4 | AJ9: 13 | AK9: 1983 | AL9: =AK9/AJ9 -> 152.53846 | AM9: =RANK(AL9,AL$7:AL$22) -> 3 | AO9: 13 | AP9: 1860 | AQ9: =AP9/AO9 -> 143.07692 | AR9: =RANK(AQ9,AQ$7:AQ$22) -> 2 | AT9: 13 | AU9: 1886 | AV9: =AU9/AT9 -> 145.07692 | AW9: =RANK(AV9,AV$7:AV$22) -> 3
C10: 4 | D10: 焗烤起司雙饗筆尖麵 | E10: =VLOOKUP(D10,'12產線配置圖 (2)'!$A$2:$C$25,2,0) -> 18 | F10: =VLOOKUP(D10,'12產線配置圖 (2)'!$A$2:$C$25,3,0) -> 1600 | G10: =F10/E10 -> 88.888889 | I10: =AVERAGE(P10,U10,Z10,AE10,AJ10,AO10,AT10) -> 17.2 | J10: =AVERAGE(Q10,V10,AA10,AF10,AK10,AP10,AU10) -> 1449.4 | K10: =AVERAGE(AB10,AG10,AL10,AQ10,AV10) -> 84.187663 | M10: =RANK(K10,$K$7:$K$22) -> 9 | R10: =Q10/P10 -> #DIV/0! | S10: =RANK(R10,R$7:R$22) -> #DIV/0! | W10: =V10/U10 -> #DIV/0! | X10: =RANK(W10,W$7:W$22) -> #DIV/0! | Z10: 17 | AA10: 1403 | AB10: =AA10/Z10 -> 82.529412 | AC10: =RANK(AB10,AB$7:AB$22) -> 9 | AE10: 16 | AF10: 1329 | AG10: =AF10/AE10 -> 83.0625 | AH10: =RANK(AG10,AG$7:AG$22) -> 9 | AJ10: 17 | AK10: 1381 | AL10: =AK10/AJ10 -> 81.235294 | AM10: =RANK(AL10,AL$7:AL$22) -> 8 | AO10: 18 | AP10: 1556 | AQ10: =AP10/AO10 -> 86.444444 | AR10: =RANK(AQ10,AQ$7:AQ$22) -> 8 | AT10: 18 | AU10: 1578 | AV10: =AU10/AT10 -> 87.666667 | AW10: =RANK(AV10,AV$7:AV$22) -> 8
C11: 5 | D11: 白酒蛤蜊義大利麵 | E11: =VLOOKUP(D11,'12產線配置圖 (2)'!$A$2:$C$25,2,0) -> 13 | F11: =VLOOKUP(D11,'12產線配置圖 (2)'!$A$2:$C$25,3,0) -> 2105 | G11: =F11/E11 -> 161.92308 | I11: =AVERAGE(P11,U11,Z11,AE11,AJ11,AO11,AT11) -> 13.6 | J11: =AVERAGE(Q11,V11,AA11,AF11,AK11,AP11,AU11) -> 1782.6 | K11: =AVERAGE(AB11,AG11,AL11,AQ11,AV11) -> 130.40549 | M11: =RANK(K11,$K$7:$K$22) -> 4 | R11: =Q11/P11 -> #DIV/0! | S11: =RANK(R11,R$7:R$22) -> #DIV/0! | W11: =V11/U11 -> #DIV/0! | X11: =RANK(W11,W$7:W$22) -> #DIV/0! | Z11: 14 | AA11: 1937 | AB11: =AA11/Z11 -> 138.35714 | AC11: =RANK(AB11,AB$7:AB$22) -> 2 | AE11: 14 | AF11: 2008 | AG11: =AF11/AE11 -> 143.42857 | AH11: =RANK(AG11,AG$7:AG$22) -> 1 | AJ11: 14 | AK11: 2168 | AL11: =AK11/AJ11 -> 154.85714 | AM11: =RANK(AL11,AL$7:AL$22) -> 2 | AO11: 13 | AP11: 838 | AQ11: =AP11/AO11 -> 64.461538 | AR11: =RANK(AQ11,AQ$7:AQ$22) -> 15 | AT11: 13 | AU11: 1962 | AV11: =AU11/AT11 -> 150.92308 | AW11: =RANK(AV11,AV$7:AV$22) -> 2
C12: 6 | D12: 韓式起司炸雞義大利麵 | E12: =VLOOKUP(D12,'12產線配置圖 (2)'!$A$2:$C$25,2,0) -> 17 | F12: =VLOOKUP(D12,'12產線配置圖 (2)'!$A$2:$C$25,3,0) -> 2000 | G12: =F12/E12 -> 117.64706 | I12: =AVERAGE(P12,U12,Z12,AE12,AJ12,AO12,AT12) -> 16.6 | J12: =AVERAGE(Q12,V12,AA12,AF12,AK12,AP12,AU12) -> 1661.8 | K12: =AVERAGE(AB12,AG12,AL12,AQ12,AV12) -> 99.825098 | M12: =RANK(K12,$K$7:$K$22) -> 5 | R12: =Q12/P12 -> #DIV/0! | S12: =RANK(R12,R$7:R$22) -> #DIV/0! | W12: =V12/U12 -> #DIV/0! | X12: =RANK(W12,W$7:W$22) -> #DIV/0! | Z12: 17 | AA12: 1868 | AB12: =AA12/Z12 -> 109.88235 | AC12: =RANK(AB12,AB$7:AB$22) -> 5 | AE12: 15 | AF12: 1321 | AG12: =AF12/AE12 -> 88.066667 | AH12: =RANK(AG12,AG$7:AG$22) -> 5 | AJ12: 17 | AK12: 1715 | AL12: =AK12/AJ12 -> 100.88235 | AM12: =RANK(AL12,AL$7:AL$22) -> 5 | AO12: 17 | AP12: 1540 | AQ12: =AP12/AO12 -> 90.588235 | AR12: =RANK(AQ12,AQ$7:AQ$22) -> 6 | AT12: 17 | AU12: 1865 | AV12: =AU12/AT12 -> 109.70588 | AW12: =RANK(AV12,AV$7:AV$22) -> 5
C13: 7 | D13: 焗烤明太子筆尖麵 | E13: =VLOOKUP(D13,'12產線配置圖 (2)'!$A$2:$C$25,2,0) -> 16 | F13: =VLOOKUP(D13,'12產線配置圖 (2)'!$A$2:$C$25,3,0) -> 1385 | G13: =F13/E13 -> 86.5625 | I13: =AVERAGE(P13,U12,Z13,AE13,AJ13,AO13,AT13) -> 14.4 | J13: =AVERAGE(Q13,V13,AA13,AF13,AK13,AP13,AU13) -> 1144.2 | K13: =AVERAGE(AB13,AG13,AL13,AQ13,AV13) -> 79.510476 | M13: =RANK(K13,$K$7:$K$22) -> 10 | R13: =Q13/P13 -> #DIV/0! | S13: =RANK(R13,R$7:R$22) -> #DIV/0! | W13: =V13/U12 -> #DIV/0! | X13: =RANK(W13,W$7:W$22) -> #DIV/0! | Z13: 14 | AA13: 1150 | AB13: =AA13/Z13 -> 82.142857 | AC13: =RANK(AB13,AB$7:AB$22) -> 10 | AE13: 15 | AF13: 1122 | AG13: =AF13/AE13 -> 74.8 | AH13: =RANK(AG13,AG$7:AG$22) -> 13 | AJ13: 14 | AK13: 1084 | AL13: =AK13/AJ13 -> 77.428571 | AM13: =RANK(AL13,AL$7:AL$22) -> 10 | AO13: 14 | AP13: 1158 | AQ13: =AP13/AO13 -> 82.714286 | AR13: =RANK(AQ13,AQ$7:AQ$22) -> 9 | AT13: 15 | AU13: 1207 | AV13: =AU13/AT13 -> 80.466667 | AW13: =RANK(AV13,AV$7:AV$22) -> 12
C14: 8 | D14: 奶油蒜香雞義大利麵 | E14: =VLOOKUP(D14,'12產線配置圖 (2)'!$A$2:$C$25,2,0) -> 17 | F14: =VLOOKUP(D14,'12產線配置圖 (2)'!$A$2:$C$25,3,0) -> 1385 | G14: =F14/E14 -> 81.470588 | I14: =AVERAGE(P14,U14,Z14,AE14,AJ14,AO14,AT14) -> 16.4 | J14: =AVERAGE(Q14,V14,AA14,AF14,AK14,AP14,AU14) -> 1180 | K14: =AVERAGE(AB14,AG14,AL14,AQ14,AV14) -> 71.844444 | M14: =RANK(K14,$K$7:$K$22) -> 14 | R14: =Q14/P14 -> #DIV/0! | S14: =RANK(R14,R$7:R$22) -> #DIV/0! | W14: =V14/U14 -> #DIV/0! | X14: =RANK(W14,W$7:W$22) -> #DIV/0! | Z14: 18 | AA14: 1360 | AB14: =AA14/Z14 -> 75.555556 | AC14: =RANK(AB14,AB$7:AB$22) -> 13 | AE14: 15 | AF14: 973 | AG14: =AF14/AE14 -> 64.866667 | AH14: =RANK(AG14,AG$7:AG$22) -> 15 | AJ14: 15 | AK14: 1127 | AL14: =AK14/AJ14 -> 75.133333 | AM14: =RANK(AL14,AL$7:AL$22) -> 11 | AO14: 18 | AP14: 1272 | AQ14: =AP14/AO14 -> 70.666667 | AR14: =RANK(AQ14,AQ$7:AQ$22) -> 12 | AT14: 16 | AU14: 1168 | AV14: =AU14/AT14 -> 73 | AW14: =RANK(AV14,AV$7:AV$22) -> 15
C15: 9 | D15: 青花椒麻雞肉拌麵 | E15: =VLOOKUP(D15,'12產線配置圖 (2)'!$A$2:$C$25,2,0) -> 17 | F15: =VLOOKUP(D15,'12產線配置圖 (2)'!$A$2:$C$25,3,0) -> 1565 | G15: =F15/E15 -> 92.058824 | I15: =AVERAGE(P15,U15,Z15,AE15,AJ15,AO15,AT15) -> 16.6 | J15: =AVERAGE(Q15,V15,AA15,AF15,AK15,AP15,AU15) -> 1441.8 | K15: =AVERAGE(AB15,AG15,AL15,AQ15,AV15) -> 86.788235 | M15: =RANK(K15,$K$7:$K$22) -> 7 | R15: =Q15/P15 -> #DIV/0! | S15: =RANK(R15,R$7:R$22) -> #DIV/0! | W15: =V15/U15 -> #DIV/0! | X15: =RANK(W15,W$7:W$22) -> #DIV/0! | Z15: 17 | AA15: 1421 | AB15: =AA15/Z15 -> 83.588235 | AC15: =RANK(AB15,AB$7:AB$22) -> 8 | AE15: 16 | AF15: 1386 | AG15: =AF15/AE15 -> 86.625 | AH15: =RANK(AG15,AG$7:AG$22) -> 7 | AJ15: 16 | AK15: 1302 | AL15: =AK15/AJ15 -> 81.375 | AM15: =RANK(AL15,AL$7:AL$22) -> 7 | AO15: 17 | AP15: 1536 | AQ15: =AP15/AO15 -> 90.352941 | AR15: =RANK(AQ15,AQ$7:AQ$22) -> 7 | AT15: 17 | AU15: 1564 | AV15: =AU15/AT15 -> 92 | AW15: =RANK(AV15,AV$7:AV$22) -> 7
C16: 10 | D16: 剝皮辣椒雞奶油扁麵 | E16: =VLOOKUP(D16,'12產線配置圖 (2)'!$A$2:$C$25,2,0) -> 18 | F16: =VLOOKUP(D16,'12產線配置圖 (2)'!$A$2:$C$25,3,0) -> 1565 | G16: =F16/E16 -> 86.944444 | I16: =AVERAGE(P16,U16,Z16,AE16,AJ16,AO16,AT16) -> 17.6 | J16: =AVERAGE(Q16,V16,AA16,AF16,AK16,AP16,AU16) -> 1337.8 | K16: =AVERAGE(AB16,AG16,AL16,AQ16,AV16) -> 75.815364 | M16: =RANK(K16,$K$7:$K$22) -> 12 | R16: =Q16/P16 -> #DIV/0! | S16: =RANK(R16,R$7:R$22) -> #DIV/0! | W16: =V16/U16 -> #DIV/0! | X16: =RANK(W16,W$7:W$22) -> #DIV/0! | Z16: 17 | AA16: 1200 | AB16: =AA16/Z16 -> 70.588235 | AC16: =RANK(AB16,AB$7:AB$22) -> 14 | AE16: 17 | AF16: 1381 | AG16: =AF16/AE16 -> 81.235294 | AH16: =RANK(AG16,AG$7:AG$22) -> 10 | AJ16: 16 | AK16: 1119 | AL16: =AK16/AJ16 -> 69.9375 | AM16: =RANK(AL16,AL$7:AL$22) -> 13 | AO16: 19 | AP16: 1424 | AQ16: =AP16/AO16 -> 74.947368 | AR16: =RANK(AQ16,AQ$7:AQ$22) -> 11 | AT16: 19 | AU16: 1565 | AV16: =AU16/AT16 -> 82.368421 | AW16: =RANK(AV16,AV$7:AV$22) -> 11
C17: 11 | D17: 濃拿坡里義大利麵 | E17: =VLOOKUP(D17,'12產線配置圖 (2)'!$A$2:$C$25,2,0) -> 16 | F17: =VLOOKUP(D17,'12產線配置圖 (2)'!$A$2:$C$25,3,0) -> 1406 | G17: =F17/E17 -> 87.875 | I17: =AVERAGE(P17,U17,Z17,AE17,AJ17,AO17,AT17) -> 14.4 | J17: =AVERAGE(Q17,V17,AA17,AF17,AK17,AP17,AU17) -> 936.4 | K17: =AVERAGE(AB17,AG17,AL17,AQ17,AV17) -> 65.12381 | M17: =RANK(K17,$K$7:$K$22) -> 16 | R17: =Q17/P17 -> #DIV/0! | S17: =RANK(R17,R$7:R$22) -> #DIV/0! | W17: =V17/U17 -> #DIV/0! | X17: =RANK(W17,W$7:W$22) -> #DIV/0! | Z17: 14 | AA17: 839 | AB17: =AA17/Z17 -> 59.928571 | AC17: =RANK(AB17,AB$7:AB$22) -> 16 | AE17: 14 | AF17: 958 | AG17: =AF17/AE17 -> 68.428571 | AH17: =RANK(AG17,AG$7:AG$22) -> 14 | AJ17: 14 | AK17: 1035 | AL17: =AK17/AJ17 -> 73.928571 | AM17: =RANK(AL17,AL$7:AL$22) -> 12 | AO17: 15 | AP17: 942 | AQ17: =AP17/AO17 -> 62.8 | AR17: =RANK(AQ17,AQ$7:AQ$22) -> 16 | AT17: 15 | AU17: 908 | AV17: =AU17/AT17 -> 60.533333 | AW17: =RANK(AV17,AV$7:AV$22) -> 16
C18: 12 | D18: 奶油起司蝦仁通心粉 | E18: =VLOOKUP(D18,'12產線配置圖 (2)'!$A$2:$C$25,2,0) -> 14 | F18: =VLOOKUP(D18,'12產線配置圖 (2)'!$A$2:$C$25,3,0) -> 1440 | G18: =F18/E18 -> 102.85714 | I18: =AVERAGE(P18,U18,Z18,AE18,AJ18,AO18,AT18) -> 14.8 | J18: =AVERAGE(Q18,V18,AA18,AF18,AK18,AP18,AU18) -> 1396.2 | K18: =AVERAGE(AB18,AG18,AL18,AQ18,AV18) -> 94.248571 | M18: =RANK(K18,$K$7:$K$22) -> 6 | R18: =Q18/P18 -> #DIV/0! | S18: =RANK(R18,R$7:R$22) -> #DIV/0! | W18: =V18/U18 -> #DIV/0! | X18: =RANK(W18,W$7:W$22) -> #DIV/0! | Z18: 15 | AA18: 1490 | AB18: =AA18/Z18 -> 99.333333 | AC18: =RANK(AB18,AB$7:AB$22) -> 6 | AE18: 14 | AF18: 1227 | AG18: =AF18/AE18 -> 87.642857 | AH18: =RANK(AG18,AG$7:AG$22) -> 6 | AJ18: 15 | AK18: 1353 | AL18: =AK18/AJ18 -> 90.2 | AM18: =RANK(AL18,AL$7:AL$22) -> 6 | AO18: 15 | AP18: 1414 | AQ18: =AP18/AO18 -> 94.266667 | AR18: =RANK(AQ18,AQ$7:AQ$22) -> 4 | AT18: 15 | AU18: 1497 | AV18: =AU18/AT18 -> 99.8 | AW18: =RANK(AV18,AV$7:AV$22) -> 6
C19: 13 | D19: 惡魔乳酪生義大利麵 | E19: =VLOOKUP(D19,'12產線配置圖 (2)'!$A$2:$C$25,2,0) -> 17 | F19: =VLOOKUP(D19,'12產線配置圖 (2)'!$A$2:$C$25,3,0) -> 1500 | G19: =F19/E19 -> 88.235294 | I19: =AVERAGE(P19,U19,Z19,AE19,AJ19,AO19,AT19) -> 14.4 | J19: =AVERAGE(Q19,V19,AA19,AF19,AK19,AP19,AU19) -> 1241.6 | K19: =AVERAGE(AB19,AG19,AL19,AQ19,AV19) -> 86.111429 | M19: =RANK(K19,$K$7:$K$22) -> 8 | R19: =Q19/P19 -> #DIV/0! | S19: =RANK(R19,R$7:R$22) -> #DIV/0! | W19: =V19/U19 -> #DIV/0! | X19: =RANK(W19,W$7:W$22) -> #DIV/0! | Z19: 14 | AA19: 1202 | AB19: =AA19/Z19 -> 85.857143 | AC19: =RANK(AB19,AB$7:AB$22) -> 7 | AE19: 14 | AF19: 1210 | AG19: =AF19/AE19 -> 86.428571 | AH19: =RANK(AG19,AG$7:AG$22) -> 8 | AJ19: 14 | AK19: 1093 | AL19: =AK19/AJ19 -> 78.071429 | AM19: =RANK(AL19,AL$7:AL$22) -> 9 | AO19: 15 | AP19: 1408 | AQ19: =AP19/AO19 -> 93.866667 | AR19: =RANK(AQ19,AQ$7:AQ$22) -> 5 | AT19: 15 | AU19: 1295 | AV19: =AU19/AT19 -> 86.333333 | AW19: =RANK(AV19,AV$7:AV$22) -> 10
C20: 14 | D20: 沙茶豬肉炒麵 | E20: =VLOOKUP(D20,'12產線配置圖 (2)'!$A$2:$C$25,2,0) -> 17 | F20: =VLOOKUP(D20,'12產線配置圖 (2)'!$A$2:$C$25,3,0) -> 1440 | G20: =F20/E20 -> 84.705882 | I20: =AVERAGE(P20,U20,Z20,AE20,AJ20,AO20,AT20) -> 15.4 | J20: =AVERAGE(Q20,V20,AA20,AF20,AK20,AP20,AU20) -> 1130.6 | K20: =AVERAGE(AB20,AG20,AL20,AQ20,AV20) -> 73.460635 | M20: =RANK(K20,$K$7:$K$22) -> 13 | R20: =Q20/P20 -> #DIV/0! | S20: =RANK(R20,R$7:R$22) -> #DIV/0! | W20: =V20/U20 -> #DIV/0! | X20: =RANK(W20,W$7:W$22) -> #DIV/0! | Z20: 15 | AA20: 1137 | AB20: =AA20/Z20 -> 75.8 | AC20: =RANK(AB20,AB$7:AB$22) -> 12 | AE20: 15 | AF20: 1135 | AG20: =AF20/AE20 -> 75.666667 | AH20: =RANK(AG20,AG$7:AG$22) -> 12 | AJ20: 14 | AK20: 955 | AL20: =AK20/AJ20 -> 68.214286 | AM20: =RANK(AL20,AL$7:AL$22) -> 14 | AO20: 18 | AP20: 1270 | AQ20: =AP20/AO20 -> 70.555556 | AR20: =RANK(AQ20,AQ$7:AQ$22) -> 14 | AT20: 15 | AU20: 1156 | AV20: =AU20/AT20 -> 77.066667 | AW20: =RANK(AV20,AV$7:AV$22) -> 14
C21: 15 | D21: 府城鹽水意麵 | E21: =VLOOKUP(D21,'12產線配置圖 (2)'!$A$2:$C$25,2,0) -> 19 | F21: =VLOOKUP(D21,'12產線配置圖 (2)'!$A$2:$C$25,3,0) -> 1440 | G21: =F21/E21 -> 75.789474 | I21: =AVERAGE(P21,U21,Z21,AE21,AJ21,AO21,AT21) -> 16.4 | J21: =AVERAGE(Q21,V21,AA21,AF21,AK21,AP21,AU21) -> 1150.6 | K21: =AVERAGE(AB21,AG21,AL21,AQ21,AV21) -> 69.986879 | M21: =RANK(K21,$K$7:$K$22) -> 15 | R21: =Q21/P21 -> #DIV/0! | S21: =RANK(R21,R$7:R$22) -> #DIV/0! | W21: =V21/U21 -> #DIV/0! | X21: =RANK(W21,W$7:W$22) -> #DIV/0! | Z21: 16 | AA21: 1121 | AB21: =AA21/Z21 -> 70.0625 | AC21: =RANK(AB21,AB$7:AB$22) -> 15 | AE21: 16 | AF21: 1016 | AG21: =AF21/AE21 -> 63.5 | AH21: =RANK(AG21,AG$7:AG$22) -> 16 | AJ21: 15 | AK21: 997 | AL21: =AK21/AJ21 -> 66.466667 | AM21: =RANK(AL21,AL$7:AL$22) -> 15 | AO21: 18 | AP21: 1271 | AQ21: =AP21/AO21 -> 70.611111 | AR21: =RANK(AQ21,AQ$7:AQ$22) -> 13 | AT21: 17 | AU21: 1348 | AV21: =AU21/AT21 -> 79.294118 | AW21: =RANK(AV21,AV$7:AV$22) -> 13
C22: 16 | D22: 焗烤起司肉醬筆尖麵 | E22: =VLOOKUP(D22,'12產線配置圖 (2)'!$A$2:$C$25,2,0) -> 10 | F22: =VLOOKUP(D22,'12產線配置圖 (2)'!$A$2:$C$25,3,0) -> 1125 | G22: =F22/E22 -> 112.5 | I22: =AVERAGE(P22,U22,Z22,AE22,AJ22,AO22,AT22) -> 10.8 | J22: =AVERAGE(Q22,V22,AA22,AF22,AK22,AP22,AU22) -> 834.8 | K22: =AVERAGE(AB22,AG22,AL22,AQ22,AV22) -> 77.737374 | M22: =RANK(K22,$K$7:$K$22) -> 11 | R22: =Q22/P22 -> #DIV/0! | S22: =RANK(R22,R$7:R$22) -> #DIV/0! | W22: =V22/U22 -> #DIV/0! | X22: =RANK(W22,W$7:W$22) -> #DIV/0! | Z22: 11 | AA22: 883 | AB22: =AA22/Z22 -> 80.272727 | AC22: =RANK(AB22,AB$7:AB$22) -> 11 | AE22: 11 | AF22: 836 | AG22: =AF22/AE22 -> 76 | AH22: =RANK(AG22,AG$7:AG$22) -> 11 | AJ22: 12 | AK22: 760 | AL22: =AK22/AJ22 -> 63.333333 | AM22: =RANK(AL22,AL$7:AL$22) -> 16 | AO22: 9 | AP22: 742 | AQ22: =AP22/AO22 -> 82.444444 | AR22: =RANK(AQ22,AQ$7:AQ$22) -> 10 | AT22: 11 | AU22: 953 | AV22: =AU22/AT22 -> 86.636364 | AW22: =RANK(AV22,AV$7:AV$22) -> 9
C23: 17
C24: 18
B25: 產線配置圖－每週更新 | N25: 資料繳交 | O25: 日期 | P25: 46028 | U25: 46029 | Z25: 46030 | AE25: 46031 | AJ25: 46032 | AO25: 46033 | AT25: 46034
P26: 二 | U26: 三 | Z26: 四 | AE26: 五 | AJ26: 六 | AO26: 日 | AT26: 一
B27: 品群 | C27: 商品名稱 | E27: 計畫 | H27: 平均人時性 | I27: 實績 | L27: 平均人時性 | M27: 排名 | O27: 日報 | P27: 實際 | T27: 平均人時性 | U27: 實際 | Y27: 平均人時性 | Z27: 實際 | AD27: 平均人時性 | AE27: 實際 | AI27: 平均人時性 | AJ27: 實際 | AN27: 平均人時性 | AO27: 實際 | AS27: 平均人時性 | AT27: 實際 | AX27: 平均人時性
E28: 產線配置圖 | I28: 產線配置圖 | P28: 生產實績 | U28: 生產實績 | Z28: 生產實績 | AE28: 生產實績 | AJ28: 生產實績 | AO28: 生產實績 | AT28: 生產實績
E29: 人數 | F29: 產能／時 | G29: 人時性 | I29: 人數 | J29: 產能／時 | K29: 人時性 | P29: 人數 | Q29: 產能／時 | R29: 人時性 | S29: 排名 | U29: 人數 | V29: 產能／時 | W29: 人時性 | X29: 排名 | Z29: 人數 | AA29: 產能／時 | AB29: 人時性 | AC29: 排名 | AE29: 人數 | AF29: 產能／時 | AG29: 人時性 | AH29: 排名 | AJ29: 人數 | AK29: 產能／時 | AL29: 人時性 | AM29: 排名 | AO29: 人數 | AP29: 產能／時 | AQ29: 人時性 | AR29: 排名 | AT29: 人數 | AU29: 產能／時 | AV29: 人時性 | AW29: 排名
B30: 熱食義麵 | C30: 1 | D30: 義式蕃茄起司義大利麵 | E30: =VLOOKUP(D30,'12產線配置圖 (2)'!$A$2:$C$25,2,0) -> 12 | F30: =VLOOKUP(D30,'12產線配置圖 (2)'!$A$2:$C$25,3,0) -> 2000 | G30: =F30/E30 -> 166.66667 | H30: =AVERAGE(G30:G47) -> 108.17676 | I30: =AVERAGE(P30,U30,Z30,AE30,AJ30,AO30,AT30) -> 12 | J30: =AVERAGE(Q30,V30,AA30,AF30,AK30,AP30,AU30) -> 1787 | K30: =AVERAGE(R30,W30,AB30,AG30,AL30,AQ30,AV30) -> 148.91667 | L30: =IFERROR(AVERAGE(K30:K47),"-") -> 96.533083 | M30: =RANK(K30, K$30:$K$47) -> 1 | P30: 12 | Q30: 1843 | R30: =Q30/P30 -> 153.58333 | S30: =RANK(R30,$R$30:$R$47) -> 1 | T30: =AVERAGE(R30:R47) -> 99.172443 | U30: 12 | V30: 1808 | W30: =V30/U30 -> 150.66667 | X30: =RANK(W30, $W$30:$W$47) -> 1 | Y30: =AVERAGE(W30:W47) -> 96.140258 | Z30: 12 | AA30: 1707 | AB30: =AA30/Z30 -> 142.25 | AC30: =RANK(AB30, $AB$30:$AB$47) -> 1 | AD30: =AVERAGE(AB30:AB47) -> 90.651539 | AE30: 12 | AF30: 1439 | AG30: =AF30/AE30 -> 119.91667 | AH30: =RANK(AG30, $AG$30:$AG$47) -> 3 | AI30: =AVERAGE(AG30:AG47) -> 90.796712 | AJ30: 12 | AK30: 1831 | AL30: =AK30/AJ30 -> 152.58333 | AM30: =RANK(AL30, $AL$30:$AL$47) -> 1 | AN30: =AVERAGE(AL30:AL47) -> 100.26519 | AO30: 12 | AP30: 1955 | AQ30: =AP30/AO30 -> 162.91667 | AR30: =RANK(AQ30,$AQ$30:$AQ$47) -> 1 | AS30: =AVERAGE(AQ30:AQ47) -> 100.39555 | AT30: 12 | AU30: 1926 | AV30: =AU30/AT30 -> 160.5 | AW30: =RANK(AV30, $AV$30:$AV$47) -> 1 | AX30: =AVERAGE(AV30:AV47) -> 98.309896
C31: 2 | D31: 奶油培根義大利麵 | E31: =VLOOKUP(D31,'12產線配置圖 (2)'!$A$2:$C$25,2,0) -> 14 | F31: =VLOOKUP(D31,'12產線配置圖 (2)'!$A$2:$C$25,3,0) -> 2000 | G31: =F31/E31 -> 142.85714 | I31: =AVERAGE(P31,U31,Z31,AE31,AJ31,AO31,AT31) -> 14 | J31: =AVERAGE(Q31,V31,AA31,AF31,AK31,AP31,AU31) -> 1824.4286 | K31: =AVERAGE(R31,W31,AB31,AG31,AL31,AQ31,AV31) -> 130.31633 | M31: =RANK(K31, K$30:$K$47) -> 4 | P31: 14 | Q31: 1816 | R31: =Q31/P31 -> 129.71429 | S31: =RANK(R31,$R$30:$R$47) -> 4 | U31: 14 | V31: 1819 | W31: =V31/U31 -> 129.92857 | X31: =RANK(W31, $W$30:$W$47) -> 4 | Z31: 14 | AA31: 1703 | AB31: =AA31/Z31 -> 121.64286 | AC31: =RANK(AB31, $AB$30:$AB$47) -> 3 | AE31: 14 | AF31: 1677 | AG31: =AF31/AE31 -> 119.78571 | AH31: =RANK(AG31, $AG$30:$AG$47) -> 4 | AJ31: 14 | AK31: 1869 | AL31: =AK31/AJ31 -> 133.5 | AM31: =RANK(AL31, $AL$30:$AL$47) -> 3 | AO31: 14 | AP31: 1987 | AQ31: =AP31/AO31 -> 141.92857 | AR31: =RANK(AQ31,$AQ$30:$AQ$47) -> 3 | AT31: 14 | AU31: 1900 | AV31: =AU31/AT31 -> 135.71429 | AW31: =RANK(AV31, $AV$30:$AV$47) -> 3
C32: 3 | D32: 青醬蛤蜊義大利麵 | E32: =VLOOKUP(D32,'12產線配置圖 (2)'!$A$2:$C$25,2,0) -> 13 | F32: =VLOOKUP(D32,'12產線配置圖 (2)'!$A$2:$C$25,3,0) -> 2000 | G32: =F32/E32 -> 153.84615 | I32: =AVERAGE(P32,U32,Z32,AE32,AJ32,AO32,AT32) -> 13 | J32: =AVERAGE(Q32,V32,AA32,AF32,AK32,AP32,AU32) -> 1767.7143 | K32: =AVERAGE(R32,W32,AB32,AG32,AL32,AQ32,AV32) -> 135.97802 | M32: =RANK(K32, K$30:$K$47) -> 2 | P32: 13 | Q32: 1989 | R32: =Q32/P32 -> 153 | S32: =RANK(R32,$R$30:$R$47) -> 2 | U32: 13 | V32: 1910 | W32: =V32/U32 -> 146.92308 | X32: =RANK(W32, $W$30:$W$47) -> 2 | Z32: 13 | AA32: 1439 | AB32: =AA32/Z32 -> 110.69231 | AC32: =RANK(AB32, $AB$30:$AB$47) -> 4 | AE32: 13 | AF32: 1696 | AG32: =AF32/AE32 -> 130.46154 | AH32: =RANK(AG32, $AG$30:$AG$47) -> 1 | AJ32: 13 | AK32: 1947 | AL32: =AK32/AJ32 -> 149.76923 | AM32: =RANK(AL32, $AL$30:$AL$47) -> 2 | AO32: 13 | AP32: 1855 | AQ32: =AP32/AO32 -> 142.69231 | AR32: =RANK(AQ32,$AQ$30:$AQ$47) -> 2 | AT32: 13 | AU32: 1538 | AV32: =AU32/AT32 -> 118.30769 | AW32: =RANK(AV32, $AV$30:$AV$47) -> 4
C33: 4 | D33: 焗烤起司雙饗筆尖麵 | E33: =VLOOKUP(D33,'12產線配置圖 (2)'!$A$2:$C$25,2,0) -> 18 | F33: =VLOOKUP(D33,'12產線配置圖 (2)'!$A$2:$C$25,3,0) -> 1600 | G33: =F33/E33 -> 88.888889 | I33: =AVERAGE(P33,U33,Z33,AE33,AJ33,AO33,AT33) -> 17.428571 | J33: =AVERAGE(Q33,V33,AA33,AF33,AK33,AP33,AU33) -> 1524.8571 | K33: =AVERAGE(R33,W33,AB33,AG33,AL33,AQ33,AV33) -> 88.088435 | M33: =RANK(K33, K$30:$K$47) -> 7 | P33: 18 | Q33: 1480 | R33: =Q33/P33 -> 82.222222 | S33: =RANK(R33,$R$30:$R$47) -> 12 | U33: 18 | V33: 1562 | W33: =V33/U33 -> 86.777778 | X33: =RANK(W33, $W$30:$W$47) -> 7 | Z33: 18 | AA33: 1560 | AB33: =AA33/Z33 -> 86.666667 | AC33: =RANK(AB33, $AB$30:$AB$47) -> 6 | AE33: 18 | AF33: 1414 | AG33: =AF33/AE33 -> 78.555556 | AH33: =RANK(AG33, $AG$30:$AG$47) -> 9 | AJ33: 14 | AK33: 1488 | AL33: =AK33/AJ33 -> 106.28571 | AM33: =RANK(AL33, $AL$30:$AL$47) -> 6 | AO33: 18 | AP33: 1590 | AQ33: =AP33/AO33 -> 88.333333 | AR33: =RANK(AQ33,$AQ$30:$AQ$47) -> 8 | AT33: 18 | AU33: 1580 | AV33: =AU33/AT33 -> 87.777778 | AW33: =RANK(AV33, $AV$30:$AV$47) -> 8
C34: 5 | D34: 白酒蛤蜊義大利麵 | E34: =VLOOKUP(D34,'12產線配置圖 (2)'!$A$2:$C$25,2,0) -> 13 | F34: =VLOOKUP(D34,'12產線配置圖 (2)'!$A$2:$C$25,3,0) -> 2105 | G34: =F34/E34 -> 161.92308 | I34: =AVERAGE(P34,U34,Z34,AE34,AJ34,AO34,AT34) -> 13.714286 | J34: =AVERAGE(Q34,V34,AA34,AF34,AK34,AP34,AU34) -> 1819.4286 | K34: =AVERAGE(R34,W34,AB34,AG34,AL34,AQ34,AV34) -> 132.69545 | M34: =RANK(K34, K$30:$K$47) -> 3 | P34: 14 | Q34: 1891 | R34: =Q34/P34 -> 135.07143 | S34: =RANK(R34,$R$30:$R$47) -> 3 | U34: 14 | V34: 1881 | W34: =V34/U34 -> 134.35714 | X34: =RANK(W34, $W$30:$W$47) -> 3 | Z34: 14 | AA34: 1793 | AB34: =AA34/Z34 -> 128.07143 | AC34: =RANK(AB34, $AB$30:$AB$47) -> 2 | AE34: 14 | AF34: 1750 | AG34: =AF34/AE34 -> 125 | AH34: =RANK(AG34, $AG$30:$AG$47) -> 2 | AJ34: 13 | AK34: 1658 | AL34: =AK34/AJ34 -> 127.53846 | AM34: =RANK(AL34, $AL$30:$AL$47) -> 4 | AO34: 13 | AP34: 1828 | AQ34: =AP34/AO34 -> 140.61538 | AR34: =RANK(AQ34,$AQ$30:$AQ$47) -> 4 | AT34: 14 | AU34: 1935 | AV34: =AU34/AT34 -> 138.21429 | AW34: =RANK(AV34, $AV$30:$AV$47) -> 2
C35: 6 | D35: 韓式起司炸雞義大利麵 | E35: =VLOOKUP(D35,'12產線配置圖 (2)'!$A$2:$C$25,2,0) -> 17 | F35: =VLOOKUP(D35,'12產線配置圖 (2)'!$A$2:$C$25,3,0) -> 2000 | G35: =F35/E35 -> 117.64706 | I35: =AVERAGE(P35,U35,Z35,AE35,AJ35,AO35,AT35) -> 16.714286 | J35: =AVERAGE(Q35,V35,AA35,AF35,AK35,AP35,AU35) -> 1716.1429 | K35: =AVERAGE(R35,W35,AB35,AG35,AL35,AQ35,AV35) -> 102.90588 | M35: =RANK(K35, K$30:$K$47) -> 5 | P35: 17 | Q35: 1645 | R35: =Q35/P35 -> 96.764706 | S35: =RANK(R35,$R$30:$R$47) -> 7 | U35: 17 | V35: 1743 | W35: =V35/U35 -> 102.52941 | X35: =RANK(W35, $W$30:$W$47) -> 5 | Z35: 17 | AA35: 1276 | AB35: =AA35/Z35 -> 75.058824 | AC35: =RANK(AB35, $AB$30:$AB$47) -> 11 | AE35: 17 | AF35: 1629 | AG35: =AF35/AE35 -> 95.823529 | AH35: =RANK(AG35, $AG$30:$AG$47) -> 6 | AJ35: 15 | AK35: 1746 | AL35: =AK35/AJ35 -> 116.4 | AM35: =RANK(AL35, $AL$30:$AL$47) -> 5 | AO35: 17 | AP35: 1983 | AQ35: =AP35/AO35 -> 116.64706 | AR35: =RANK(AQ35,$AQ$30:$AQ$47) -> 5 | AT35: 17 | AU35: 1991 | AV35: =AU35/AT35 -> 117.11765 | AW35: =RANK(AV35, $AV$30:$AV$47) -> 5
C36: 7 | D36: 焗烤明太子筆尖麵 | E36: =VLOOKUP(D36,'12產線配置圖 (2)'!$A$2:$C$25,2,0) -> 16 | F36: =VLOOKUP(D36,'12產線配置圖 (2)'!$A$2:$C$25,3,0) -> 1385 | G36: =F36/E36 -> 86.5625 | I36: =AVERAGE(P36,U36,Z36,AE36,AJ36,AO36,AT36) -> 13.857143 | J36: =AVERAGE(Q36,V36,AA36,AF36,AK36,AP36,AU36) -> 1099.8571 | K36: =AVERAGE(R36,W36,AB36,AG36,AL36,AQ36,AV36) -> 79.879644 | M36: =RANK(K36, K$30:$K$47) -> 11 | P36: 14 | Q36: 1159 | R36: =Q36/P36 -> 82.785714 | S36: =RANK(R36,$R$30:$R$47) -> 11 | U36: 13 | V36: 982 | W36: =V36/U36 -> 75.538462 | X36: =RANK(W36, $W$30:$W$47) -> 12 | Z36: 15 | AA36: 1097 | AB36: =AA36/Z36 -> 73.133333 | AC36: =RANK(AB36, $AB$30:$AB$47) -> 13 | AE36: 15 | AF36: 1257 | AG36: =AF36/AE36 -> 83.8 | AH36: =RANK(AG36, $AG$30:$AG$47) -> 8 | AJ36: 10 | AK36: 909 | AL36: =AK36/AJ36 -> 90.9 | AM36: =RANK(AL36, $AL$30:$AL$47) -> 11 | AO36: 15 | AP36: 1164 | AQ36: =AP36/AO36 -> 77.6 | AR36: =RANK(AQ36,$AQ$30:$AQ$47) -> 13 | AT36: 15 | AU36: 1131 | AV36: =AU36/AT36 -> 75.4 | AW36: =RANK(AV36, $AV$30:$AV$47) -> 13
C37: 8 | D37: 奶油蒜香雞義大利麵 | E37: =VLOOKUP(D37,'12產線配置圖 (2)'!$A$2:$C$25,2,0) -> 17 | F37: =VLOOKUP(D37,'12產線配置圖 (2)'!$A$2:$C$25,3,0) -> 1385 | G37: =F37/E37 -> 81.470588 | I37: =AVERAGE(P37,U37,Z37,AE37,AJ37,AO37,AT37) -> 15.714286 | J37: =AVERAGE(Q37,V37,AA37,AF37,AK37,AP37,AU37) -> 1182 | K37: =AVERAGE(R37,W37,AB37,AG37,AL37,AQ37,AV37) -> 74.952756 | M37: =RANK(K37, K$30:$K$47) -> 13 | P37: 16 | Q37: 1227 | R37: =Q37/P37 -> 76.6875 | S37: =RANK(R37,$R$30:$R$47) -> 13 | U37: 15 | V37: 1109 | W37: =V37/U37 -> 73.933333 | X37: =RANK(W37, $W$30:$W$47) -> 13 | Z37: 17 | AA37: 1301 | AB37: =AA37/Z37 -> 76.529412 | AC37: =RANK(AB37, $AB$30:$AB$47) -> 10 | AE37: 15 | AF37: 1121 | AG37: =AF37/AE37 -> 74.733333 | AH37: =RANK(AG37, $AG$30:$AG$47) -> 12 | AJ37: 14 | AK37: 893 | AL37: =AK37/AJ37 -> 63.785714 | AM37: =RANK(AL37, $AL$30:$AL$47) -> 14 | AO37: 17 | AP37: 1343 | AQ37: =AP37/AO37 -> 79 | AR37: =RANK(AQ37,$AQ$30:$AQ$47) -> 12 | AT37: 16 | AU37: 1280 | AV37: =AU37/AT37 -> 80 | AW37: =RANK(AV37, $AV$30:$AV$47) -> 11
C38: 9 | D38: 青花椒麻雞肉拌麵 | E38: =VLOOKUP(D38,'12產線配置圖 (2)'!$A$2:$C$25,2,0) -> 17 | F38: =VLOOKUP(D38,'12產線配置圖 (2)'!$A$2:$C$25,3,0) -> 1565 | G38: =F38/E38 -> 92.058824 | I38: =AVERAGE(P38,U38,Z38,AE38,AJ38,AO38,AT38) -> 16.142857 | J38: =AVERAGE(Q38,V38,AA38,AF38,AK38,AP38,AU38) -> 1406.8571 | K38: =AVERAGE(R38,W38,AB38,AG38,AL38,AQ38,AV38) -> 87.578453 | M38: =RANK(K38, K$30:$K$47) -> 8 | P38: 17 | Q38: 1505 | R38: =Q38/P38 -> 88.529412 | S38: =RANK(R38,$R$30:$R$47) -> 8 | U38: 15 | V38: 1283 | W38: =V38/U38 -> 85.533333 | X38: =RANK(W38, $W$30:$W$47) -> 8 | Z38: 17 | AA38: 1427 | AB38: =AA38/Z38 -> 83.941176 | AC38: =RANK(AB38, $AB$30:$AB$47) -> 8 | AE38: 17 | AF38: 1215 | AG38: =AF38/AE38 -> 71.470588 | AH38: =RANK(AG38, $AG$30:$AG$47) -> 14 | AJ38: 13 | AK38: 1309 | AL38: =AK38/AJ38 -> 100.69231 | AM38: =RANK(AL38, $AL$30:$AL$47) -> 8 | AO38: 17 | AP38: 1545 | AQ38: =AP38/AO38 -> 90.882353 | AR38: =RANK(AQ38,$AQ$30:$AQ$47) -> 7 | AT38: 17 | AU38: 1564 | AV38: =AU38/AT38 -> 92 | AW38: =RANK(AV38, $AV$30:$AV$47) -> 7
C39: 10 | D39: 剝皮辣椒雞奶油扁麵 | E39: =VLOOKUP(D39,'12產線配置圖 (2)'!$A$2:$C$25,2,0) -> 18 | F39: =VLOOKUP(D39,'12產線配置圖 (2)'!$A$2:$C$25,3,0) -> 1565 | G39: =F39/E39 -> 86.944444 | I39: =AVERAGE(P39,U39,Z39,AE39,AJ39,AO39,AT39) -> 17.571429 | J39: =AVERAGE(Q39,V39,AA39,AF39,AK39,AP39,AU39) -> 1471.1429 | K39: =AVERAGE(R39,W39,AB39,AG39,AL39,AQ39,AV39) -> 84.166607 | M39: =RANK(K39, K$30:$K$47) -> 10 | P39: 18 | Q39: 1545 | R39: =Q39/P39 -> 85.833333 | S39: =RANK(R39,$R$30:$R$47) -> 9 | U39: 18 | V39: 1403 | W39: =V39/U39 -> 77.944444 | X39: =RANK(W39, $W$30:$W$47) -> 11 | Z39: 19 | AA39: 1512 | AB39: =AA39/Z39 -> 79.578947 | AC39: =RANK(AB39, $AB$30:$AB$47) -> 9 | AE39: 18 | AF39: 1394 | AG39: =AF39/AE39 -> 77.444444 | AH39: =RANK(AG39, $AG$30:$AG$47) -> 11 | AJ39: 14 | AK39: 1353 | AL39: =AK39/AJ39 -> 96.642857 | AM39: =RANK(AL39, $AL$30:$AL$47) -> 10 | AO39: 18 | AP39: 1540 | AQ39: =AP39/AO39 -> 85.555556 | AR39: =RANK(AQ39,$AQ$30:$AQ$47) -> 10 | AT39: 18 | AU39: 1551 | AV39: =AU39/AT39 -> 86.166667 | AW39: =RANK(AV39, $AV$30:$AV$47) -> 10
C40: 11 | D40: 濃拿坡里義大利麵 | E40: =VLOOKUP(D40,'12產線配置圖 (2)'!$A$2:$C$25,2,0) -> 16 | F40: =VLOOKUP(D40,'12產線配置圖 (2)'!$A$2:$C$25,3,0) -> 1406 | G40: =F40/E40 -> 87.875 | I40: =AVERAGE(P40,U40,Z40,AE40,AJ40,AO40,AT40) -> 14 | J40: =AVERAGE(Q40,V40,AA40,AF40,AK40,AP40,AU40) -> 1042 | K40: =AVERAGE(R40,W40,AB40,AG40,AL40,AQ40,AV40) -> 74.337415 | M40: =RANK(K40, K$30:$K$47) -> 14 | P40: 14 | Q40: 1054 | R40: =Q40/P40 -> 75.285714 | S40: =RANK(R40,$R$30:$R$47) -> 14 | U40: 14 | V40: 1150 | W40: =V40/U40 -> 82.142857 | X40: =RANK(W40, $W$30:$W$47) -> 10 | Z40: 15 | AA40: 1083 | AB40: =AA40/Z40 -> 72.2 | AC40: =RANK(AB40, $AB$30:$AB$47) -> 14 | AE40: 15 | AF40: 1086 | AG40: =AF40/AE40 -> 72.4 | AH40: =RANK(AG40, $AG$30:$AG$47) -> 13 | AJ40: 10 | AK40: 708 | AL40: =AK40/AJ40 -> 70.8 | AM40: =RANK(AL40, $AL$30:$AL$47) -> 12 | AO40: 15 | AP40: 1028 | AQ40: =AP40/AO40 -> 68.533333 | AR40: =RANK(AQ40,$AQ$30:$AQ$47) -> 15 | AT40: 15 | AU40: 1185 | AV40: =AU40/AT40 -> 79 | AW40: =RANK(AV40, $AV$30:$AV$47) -> 12
...

Sheet （５-3）品群別人時生產性(微波小吃)
B1: 月平均人時性 | C1: =AVERAGE(L7,L27,L47,L67,L87,L107) -> 104.17605
B2: 產線配置圖－每週更新 | N2: 資料繳交 | O2: 日期 | Z2: 46023 | AE2: 46024 | AJ2: 46025 | AO2: 46026 | AT2: 46027
P3: 二 | U3: 三 | Z3: 四 | AE3: 五 | AJ3: 六 | AO3: 日 | AT3: 一
B4: 品群 | C4: 商品名稱 | E4: 計畫 | H4: 平均人時性 | I4: 實績 | L4: 平均人時性 | M4: 排名 | O4: 日報 | P4: 實際 | T4: 平均人時性 | U4: 實際 | Y4: 平均人時性 | Z4: 實際 | AD4: 平均人時性 | AE4: 實際 | AI4: 平均人時性 | AJ4: 實際 | AN4: 平均人時性 | AO4: 實際 | AS4: 平均人時性 | AT4: 實際 | AX4: 平均人時性
E5: 產線配置圖 | I5: 產線配置圖 | P5: 生產實績 | U5: 生產實績 | Z5: 生產實績 | AE5: 生產實績 | AJ5: 生產實績 | AO5: 生產實績 | AT5: 生產實績
E6: 人數 | F6: 產能／時 | G6: 人時性 | I6: 人數 | J6: 產能／時 | K6: 人時性 | P6: 人數 | Q6: 產能／時 | R6: 人時性 | S6: 排名 | U6: 人數 | V6: 產能／時 | W6: 人時性 | X6: 排名 | Z6: 人數 | AA6: 產能／時 | AB6: 人時性 | AC6: 排名 | AE6: 人數 | AF6: 產能／時 | AG6: 人時性 | AH6: 排名 | AJ6: 人數 | AK6: 產能／時 | AL6: 人時性 | AM6: 排名 | AO6: 人數 | AP6: 產能／時 | AQ6: 人時性 | AR6: 排名 | AT6: 人數 | AU6: 產能／時 | AV6: 人時性 | AW6: 排名
B7: 微波小吃 | C7: 1 | D7: 小滷青蔬 | E7: =VLOOKUP(D7,'12產線配置圖 (2)'!$A$2:$C$30,2,0) -> 13 | F7: =VLOOKUP(D7,'12產線配置圖 (2)'!$A$2:$C$30,3,0) -> 1565 | G7: =F7/E7 -> 120.38462 | H7: =AVERAGE(G7:G21) -> 127.07265 | I7: =AVERAGE(P7,U7,Z7,AE7,AJ7,AO7,AT7) -> 12.6 | J7: =AVERAGE(Q7,V7,AA7,AF7,AK7,AP7,AU7) -> 1373.2 | K7: =AVERAGE(AB7,AG7,AL7,AQ7,AV7) -> 109.04487 | L7: =IFERROR(AVERAGE(K7:K21),"-") -> 104.21395 | M7: =RANK(K7,$K$7:$K$9) -> 2 | R7: =Q7/P7 -> #DIV/0! | S7: =RANK(R7, R$7:R$21) -> #DIV/0! | T7: =AVERAGE(R7:R21) -> #DIV/0! | W7: =V7/U7 -> #DIV/0! | X7: =RANK(W7,W$107:W$109) -> #DIV/0! | Y7: =AVERAGE(W7:W21) -> #DIV/0! | Z7: 13 | AA7: 1465 | AB7: =AA7/Z7 -> 112.69231 | AC7: =RANK(AB7,AB$7:AB$9) -> 2 | AD7: =AVERAGE(AB7:AB21) -> 113.59441 | AE7: 12 | AF7: 1347 | AG7: =AF7/AE7 -> 112.25 | AH7: =RANK(AG7,AG$7:AG$9) -> 2 | AI7: =AVERAGE(AG7:AG21) -> 93.712121 | AJ7: 13 | AK7: 1263 | AL7: =AK7/AJ7 -> 97.153846 | AM7: =RANK(AL7,AL$7:AL$9) -> 3 | AN7: =AVERAGE(AL7:AL21) -> 101.32906 | AO7: 12 | AP7: 1316 | AQ7: =AP7/AO7 -> 109.66667 | AR7: =RANK(AQ7,AQ$7:AQ$9) -> 2 | AS7: =AVERAGE(AQ7:AQ21) -> 102.86364 | AT7: 13 | AU7: 1475 | AV7: =AU7/AT7 -> 113.46154 | AW7: =RANK(AV7,AV$7:AV$9) -> 1 | AX7: =AVERAGE(AV7:AV21) -> 109.57051
C8: 2 | D8: 起司馬鈴薯 | E8: =VLOOKUP(D8,'12產線配置圖 (2)'!$A$2:$C$30,2,0) -> 12 | F8: =VLOOKUP(D8,'12產線配置圖 (2)'!$A$2:$C$30,3,0) -> 1565 | G8: =F8/E8 -> 130.41667 | I8: =AVERAGE(P8,U8,Z8,AE8,AJ8,AO8,AT8) -> 11.6 | J8: =AVERAGE(Q8,V8,AA8,AF8,AK8,AP8,AU8) -> 1318.2 | K8: =AVERAGE(AB8,AG8,AL8,AQ8,AV8) -> 113.70303 | M8: =RANK(K8,$K$7:$K$9) -> 1 | R8: =Q8/P8 -> #DIV/0! | S8: =RANK(R8, R$7:R$21) -> #DIV/0! | W8: =V8/U8 -> #DIV/0! | X8: =RANK(W8,W$107:W$109) -> #DIV/0! | Z8: 11 | AA8: 1211 | AB8: =AA8/Z8 -> 110.09091 | AC8: =RANK(AB8,AB$7:AB$9) -> 3 | AE8: 12 | AF8: 1455 | AG8: =AF8/AE8 -> 121.25 | AH8: =RANK(AG8,AG$7:AG$9) -> 1 | AJ8: 12 | AK8: 1296 | AL8: =AK8/AJ8 -> 108 | AM8: =RANK(AL8,AL$7:AL$9) -> 1 | AO8: 11 | AP8: 1332 | AQ8: =AP8/AO8 -> 121.09091 | AR8: =RANK(AQ8,AQ$7:AQ$9) -> 1 | AT8: 12 | AU8: 1297 | AV8: =AU8/AT8 -> 108.08333 | AW8: =RANK(AV8,AV$7:AV$9) -> 2
C9: 3 | D9: 台式綜合甜不辣 | E9: =VLOOKUP(D9,'12產線配置圖 (2)'!$A$2:$C$30,2,0) -> 12 | F9: =VLOOKUP(D9,'12產線配置圖 (2)'!$A$2:$C$30,3,0) -> 1565 | G9: =F9/E9 -> 130.41667 | I9: =AVERAGE(P9,U9,Z9,AE9,AJ9,AO9,AT9) -> 11.8 | J9: =AVERAGE(Q9,V9,AA9,AF9,AK9,AP9,AU9) -> 1069.2 | K9: =AVERAGE(AB9,AG9,AL9,AQ9,AV9) -> 89.893939 | M9: =RANK(K9,$K$7:$K$9) -> 3 | R9: =Q9/P9 -> #DIV/0! | S9: =RANK(R9, R$7:R$21) -> #DIV/0! | W9: =V9/U9 -> #DIV/0! | X9: =RANK(W9,W$107:W$109) -> #DIV/0! | Z9: 12 | AA9: 1416 | AB9: =AA9/Z9 -> 118 | AC9: =RANK(AB9,AB$7:AB$9) -> 1 | AE9: 11 | AF9: 524 | AG9: =AF9/AE9 -> 47.636364 | AH9: =RANK(AG9,AG$7:AG$9) -> 3 | AJ9: 12 | AK9: 1186 | AL9: =AK9/AJ9 -> 98.833333 | AM9: =RANK(AL9,AL$7:AL$9) -> 2 | AO9: 12 | AP9: 934 | AQ9: =AP9/AO9 -> 77.833333 | AR9: =RANK(AQ9,AQ$7:AQ$9) -> 3 | AT9: 12 | AU9: 1286 | AV9: =AU9/AT9 -> 107.16667 | AW9: =RANK(AV9,AV$7:AV$9) -> 3
C10: 4
C11: 5
C12: 6
C13: 7
C14: 8
C15: 9
C16: 10
C17: 11
C18: 12
C19: 13
C20: 14
C21: 15
B22: 產線配置圖－每週更新 | N22: 資料繳交 | O22: 日期 | P22: 46028 | U22: 46029 | Z22: 46030 | AE22: 46031 | AJ22: 46032 | AO22: 46033 | AT22: 46034
P23: 二 | U23: 三 | Z23: 四 | AE23: 五 | AJ23: 六 | AO23: 日 | AT23: 一
B24: 品群 | C24: 商品名稱 | E24: 計畫 | H24: 平均人時性 | I24: 實績 | L24: 平均人時性 | M24: 排名 | O24: 日報 | P24: 實際 | T24: 平均人時性 | U24: 實際 | Y24: 平均人時性 | Z24: 實際 | AD24: 平均人時性 | AE24: 實際 | AI24: 平均人時性 | AJ24: 實際 | AN24: 平均人時性 | AO24: 實際 | AS24: 平均人時性 | AT24: 實際 | AX24: 平均人時性
E25: 產線配置圖 | I25: 產線配置圖 | P25: 生產實績 | U25: 生產實績 | Z25: 生產實績 | AE25: 生產實績 | AJ25: 生產實績 | AO25: 生產實績 | AT25: 生產實績
E26: 人數 | F26: 產能／時 | G26: 人時性 | I26: 人數 | J26: 產能／時 | K26: 人時性 | P26: 人數 | Q26: 產能／時 | R26: 人時性 | S26: 排名 | U26: 人數 | V26: 產能／時 | W26: 人時性 | X26: 排名 | Z26: 人數 | AA26: 產能／時 | AB26: 人時性 | AC26: 排名 | AE26: 人數 | AF26: 產能／時 | AG26: 人時性 | AH26: 排名 | AJ26: 人數 | AK26: 產能／時 | AL26: 人時性 | AM26: 排名 | AO26: 人數 | AP26: 產能／時 | AQ26: 人時性 | AR26: 排名 | AT26: 人數 | AU26: 產能／時 | AV26: 人時性 | AW26: 排名
B27: 微波小吃 | C27: 1 | D27: 小滷青蔬 | E27: =VLOOKUP(D27,'12產線配置圖 (2)'!$A$2:$C$30,2,0) -> 13 | F27: =VLOOKUP(D27,'12產線配置圖 (2)'!$A$2:$C$30,3,0) -> 1565 | G27: =F27/E27 -> 120.38462 | H27: =AVERAGE(G27:G41) -> 127.07265 | I27: =AVERAGE(P27,U27,Z27,AE27,AJ27,AO27,AT27) -> 12.714286 | J27: =AVERAGE(Q27,V27,AA27,AF27,AK27,AP27,AU27) -> 1415.5714 | K27: =AVERAGE(R27,W27,AB27,AG27,AL27,AQ27,AV27) -> 111.3837 | L27: =IFERROR(AVERAGE(K27:K41),"-") -> 103.40193 | M27: =RANK(K27, K$27:$K$41) -> 2 | P27: 13 | Q27: 1436 | R27: =Q27/P27 -> 110.46154 | S27: =RANK(R27, $R$27:$R$41) -> 2 | T27: =AVERAGE(R27:R41) -> 104.2094 | U27: 13 | V27: 1335 | W27: =V27/U27 -> 102.69231 | X27: =RANK(W27, $W$27:$W$41) -> 2 | Y27: =AVERAGE(W27:W41) -> 93.258547 | Z27: 12 | AA27: 1285 | AB27: =AA27/Z27 -> 107.08333 | AC27: =RANK(AB27, $AB$27:$AB$29) -> 2 | AD27: =AVERAGE(AB27:AB41) -> 107.14899 | AE27: 12 | AF27: 1438 | AG27: =AF27/AE27 -> 119.83333 | AH27: =RANK(AG27, $AG$27:$AG$29) -> 1 | AI27: =AVERAGE(AG27:AG41) -> 100.32576 | AJ27: 13 | AK27: 1416 | AL27: =AK27/AJ27 -> 108.92308 | AM27: =RANK(AL27, $AL$27:$AL$29) -> 2 | AN27: =AVERAGE(AL27:AL41) -> 109.57436 | AO27: 13 | AP27: 1531 | AQ27: =AP27/AO27 -> 117.76923 | AR27: =RANK(AQ27, $AQ$27:$AQ$41) -> 2 | AS27: =AVERAGE(AQ27:AQ41) -> 104.44328 | AT27: 13 | AU27: 1468 | AV27: =AU27/AT27 -> 112.92308 | AW27: =RANK(AV27, $AV$27:$AV$41) -> 2 | AX27: =AVERAGE(AV27:AV41) -> 104.85315
