Workbook

Sheet 生產管理報表(月)
A1: 長家廠生產管理報表
A3: 月別 | B3: 8 | C3: 工廠 | D3: 長家廠
A4: （１）收支狀況 | E4: ※單位：千元 | G4: （２）ＫＰＩ達成進度
A5: 項目 | B5: 當月 | C5: 前月 | D5: 差異 | E5: 累計 | G5: 項目 | H5: KPI | I5: 當月 | J5: 前月 | K5: 累計 | L5: ※補充
A6: 業績金額 | B6: 84284.94 | D6: =B6-C6 -> 84284.94 | G6: 人時性(個/月均) | H6: 109.4 | I6: 97.1 | L6: 個／MH
A7: 訂單數量 | B7: 1717015 | D7: =B7-C7 -> 1717015 | G7: 人時達成率(%/月均) | H7: 0.8 | I7: 0.912 | L7: 達成率
A8: 材料費 | B8: 53121.6 | D8: =B8-C8 -> 53121.6 | G8: 半成品-報廢(%) | H8: 0.0025 | I8: 0.008 | L8: 報廢率
A9: 材料費率 | B9: 0.62806824 | D9: =B9-C9 -> 0.62806824 | G9: 半成品-超用(%) | H9: 0.0025 | I9: 0.011 | L9: 超用率
A10: 勞務成本 | B10: 9692.78 | D10: =B10-C10 -> 9692.78 | G10: 固定產線-導入率(%) | H10: 1 | I10: 0.429 | L10: 導入率
A11: 勞務費率 | B11: =B10/B6 -> 0.11500014 | D11: =B11-C11 -> 0.11500014 | G11: 教育訓練-實施率(%) | H11: 1 | I11: 0.617 | L11: 實施率
A13: （３）業績構成比 | G13: （４）訂單數量構成比
B14: 當月 | C14: 比例 | D14: 前月 | E14: 差異 | H14: 當月 | I14: 比例 | J14: 前月 | K14: 差異
A15: 熱食義麵(122,123,124,126) | B15: 77138.6 | C15: =IFERROR(B15/$B$6,"") -> 0.91521214 | E15: =IFERROR(C15-D15,"") -> 0.91521214 | G15: 熱食義麵(122,123,124,126) | H15: 1458501 | I15: =IFERROR(H15/$B$7,"") -> 0.84943987 | K15: =IFERROR(I15-J15,"") -> 0.84943987
A16: 季節調理麵(111,112) | C16: =IFERROR(B16/$B$6,"") -> 0 | E16: =IFERROR(C16-D16,"") -> 0 | G16: 季節調理麵(111,112) | I16: =IFERROR(H16/$B$7,"") -> 0 | K16: =IFERROR(I16-J16,"") -> 0
A17: 微波小吃(153,154,155) | B17: 7146.3 | C17: =IFERROR(B17/$B$6,"") -> 0.084787389 | E17: =IFERROR(C17-D17,"") -> 0.084787389 | G17: 微波小吃(153,154,155) | H17: 258514 | I17: =IFERROR(H17/$B$7,"") -> 0.15056013 | K17: =IFERROR(I17-J17,"") -> 0.15056013
C18: =SUM(C15:C17) -> 0.99999953 | D18: =SUM(D15:D17) -> 0 | I18: =SUM(I15:I17) -> 1 | J18: =SUM(J15:J17) -> 0
A20: （５）品群別人時生產性
A21: 品群 | B21: 當月 | C21: 前月 | D21: 差異 | E21: 累計
A22: 熱食義麵(122,123,124,126) | B22: 95.6 | D22: 0
A23: 季節調理麵(111,112) | D23: 0
A24: 微波小吃(153,154,155) | B24: 109.8 | D24: 0

Sheet 生產管理報表(週) 
A1: 長家廠生產管理報表
A3: 月別 | B3: 8 | C3: 週別 | D3: W5 | E3: 工廠 | F3: 長家廠
A4: （１）收支狀況 | E4: ※單位：千元 | G4: （２）ＫＰＩ達成進度
A5: 項目 | B5: 當週 | C5: 前週 | D5: 差異 | E5: 累計 | G5: 項目 | H5: KPI | I5: 當週 | J5: 前週 | K5: 累計 | L5: ※補充
A6: 業績金額 | B6: 18926.95 | C6: 20083.9 | D6: =B6-C6 -> -1156.95 | E6: 68252 | G6: 人時性(個/月均) | H6: 109.4 | J6: 94.7 | L6: 個／MH
A7: 訂單數量 | B7: 390615 | C7: 400711 | D7: =B7-C7 -> -10096 | E7: 1385195 | G7: 人時達成率(%/月均) | H7: 0.8 | I7: =I6/H6 -> 0 | J7: =J6/H6 -> 0.86563071 | L7: 達成率
A8: 材料費 | B8: 11935.81 | C8: 12660.243 | D8: =B8-C8 -> -724.433 | E8: 43010 | G8: 半成品-報廢(%) | H8: 0.0025 | J8: 0.007 | L8: 報廢率
A9: 材料費率 | B9: =B8/B6 -> 0.63062511 | C9: =C8/C6 -> 0.63036776 | D9: =B9-C9 -> 0.00025735667 | E9: =E8/E6 -> 0.63016468 | G9: 半成品-超用(%) | H9: 0.0025 | J9: 0.005 | L9: 超用率
A10: 勞務成本 | D10: =B10-C10 -> 0 | G10: 固定產線-導入率(%) | H10: 1 | I10: 0.429 | J10: 0.429 | K10: 0.429 | L10: 導入率
A11: 勞務費率 | D11: =B11-C11 -> 0 | G11: 教育訓練-實施率(%) | H11: 1 | I11: 0.714 | J11: 0.714 | K11: 0.548 | L11: 實施率
A13: （３）業績構成比 | G13: （４）訂單數量構成比
B14: 當週 | C14: 比例 | D14: 前週 | E14: 差異 | H14: 當週 | I14: 比例 | J14: 前週 | K14: 差異
A15: 熱食義麵(122,123,124,126) | B15: 16921.96 | C15: =IFERROR(B15/$B$6,"") -> 0.89406693 | D15: 0.9265 | E15: =IFERROR(C15-D15,"") -> -0.032433074 | G15: 熱食義麵(122,123,124,126) | H15: 318207 | I15: =IFERROR(H15/$B$7,"") -> 0.81463077 | J15: 0.8666 | K15: =IFERROR(I15-J15,"") -> -0.051969225
A16: 季節調理麵(111,112) | C16: =IFERROR(B16/$B$6,"") -> 0 | E16: =IFERROR(C16-D16,"") -> 0 | G16: 季節調理麵(111,112) | I16: =IFERROR(H16/$B$7,"") -> 0 | K16: =IFERROR(I16-J16,"") -> 0
A17: 微波小吃(153,154,155) | B17: 2004.98 | C17: =IFERROR(B17/$B$6,"") -> 0.10593255 | D17: 0.0735 | E17: =IFERROR(C17-D17,"") -> 0.032432546 | G17: 微波小吃(153,154,155) | H17: 72408 | I17: =IFERROR(H17/$B$7,"") -> 0.18536923 | J17: 0.1334 | K17: =IFERROR(I17-J17,"") -> 0.051969225
C18: =SUM(C15:C17) -> 0.99999947 | D18: =SUM(D15:D17) -> 1 | I18: =SUM(I15:I17) -> 1 | J18: =SUM(J15:J17) -> 1
A20: （５）品群別人時生產性
A21: 品群 | B21: 當週 | C21: 前週 | D21: 差異 | E21: 累計
A22: 熱食義麵(122,123,124,126) | B22: 97.1 | C22: 91.5 | D22: =B22-C22 -> 5.6
A23: 季節調理麵(111,112) | D23: =B23-C23 -> 0
A24: 微波小吃(153,154,155) | B24: 113.6 | C24: 108 | D24: =B24-C24 -> 5.6

Sheet （１）收支狀況
B2: （１）收支狀況
B3: 資料繳交日 | C3: 月份 | D3: 日期 | F3: 營業額(元) | I3: 訂單數量(個) | L3: 材料費(元) | O3: 材料費率（材料費／營業額） | R3: 勞務成本（全廠人事成本） | U3: 勞務費率（勞務成本／營業額）
F4: 日 | G4: 週累積 | H4: 月累積 | I4: 日 | J4: 週累積 | K4: 月累積 | L4: 日 | M4: 週累積 | N4: 月累積 | O4: 日 | P4: 週累積 | Q4: 月累積 | R4: 日 | S4: 週累積 | T4: 月累積 | U4: 日 | V4: 週累積 | W4: 月累積
B5: =D17 -> 45882 | C5: 八 | D5: 45870 | E5: 五 | F5: 2385266.7 | G5: =SUM(F5:F8) -> 10607384 | H5: =SUM(F5:F35) -> 84284948 | I5: 48634 | J5: =SUM(I5:I8) -> 217451 | K5: =SUM(I5:I35) -> 1717015 | L5: 1500654 | M5: =SUM(L5:L8) -> 6679908 | N5: =SUM(L5:L35) -> 53121602 | O5: =L5/F5 -> 0.62913469 | P5: =SUM(O5:O8) -> 2.5188712 | Q5: =N5/H5 -> 0.63026202 | S5: =SUM(R5:R8) -> 0 | T5: =SUM(R5:R35) -> 0 | U5: =R5/F5 -> 0 | V5: =SUM(U5:U8) -> 0 | W5: =T5/H5 -> 0
D6: 45871 | E6: 六 | F6: 2388905.3 | I6: 50077 | L6: 1504727 | O6: =L6/F6 -> 0.62988139 | U6: =R6/F6 -> 0
D7: 45872 | E7: 日 | F7: 2899844.4 | I7: 59089 | L7: 1824425 | O7: =L7/F7 -> 0.62914582 | U7: =R7/F7 -> 0
D8: 45873 | E8: 一 | F8: 2933367.4 | I8: 59651 | L8: 1850102 | O8: =L8/F8 -> 0.63070926 | U8: =R8/F8 -> 0
D9: 45874 | E9: 二 | F9: 3567472.8 | G9: =SUM(F9:F15) -> 19947142 | I9: 72576 | J9: =SUM(I9:I15) -> 408990 | L9: 2250309 | M9: =SUM(L9:L15) -> 12571005 | O9: =L9/F9 -> 0.63078519 | P9: =M9/G9 -> 0.63021585 | S9: =SUM(R9:R15) -> 0 | U9: =R9/F9 -> 0 | V9: =S9/G9 -> 0
D10: 45875 | E10: 三 | F10: 3253153.3 | I10: 66419 | L10: 2050043 | O10: =L10/F10 -> 0.63017105 | U10: =R10/F10 -> 0
D11: 45876 | E11: 四 | F11: 3065389 | I11: 62707 | L11: 1930254 | O11: =L11/F11 -> 0.629693 | U11: =R11/F11 -> 0
D12: 45877 | E12: 五 | F12: 2194710 | I12: 45233 | L12: 1382797 | O12: =L12/F12 -> 0.6300591 | U12: =R12/F12 -> 0
D13: 45878 | E13: 六 | F13: 2228264 | I13: 46023 | L13: 1400538 | O13: =L13/F13 -> 0.62853324 | U13: =R13/F13 -> 0
D14: 45879 | E14: 日 | F14: 2819551 | I14: 58090 | L14: 1779532 | O14: =L14/F14 -> 0.6311402 | U14: =R14/F14 -> 0
D15: 45880 | E15: 一 | F15: 2818602 | I15: 57942 | L15: 1777532 | O15: =L15/F15 -> 0.63064313 | U15: =R15/F15 -> 0
B16: =D24 -> 45889 | D16: 45881 | E16: 二 | F16: 2662577 | G16: =SUM(F16:F22) -> 17613170 | I16: 54761 | J16: =SUM(I16:I22) -> 358043 | L16: 1680559 | M16: =SUM(L16:L22) -> 11099822 | O16: =L16/F16 -> 0.63117761 | P16: =M16/G16 -> 0.63020012 | S16: =SUM(R16:R22) -> 0 | U16: =R16/F16 -> 0 | V16: =S16/G16 -> 0
D17: 45882 | E17: 三 | F17: 2744633 | I17: 56324 | L17: 1728237 | O17: =L17/F17 -> 0.62967872 | U17: =R17/F17 -> 0
D18: 45883 | E18: 四 | F18: 2633487.9 | I18: 53933 | L18: 1658928 | O18: =L18/F18 -> 0.62993568 | U18: =R18/F18 -> 0
D19: 45884 | E19: 五 | F19: 2147438.5 | I19: 44208 | L19: 1353772 | O19: =L19/F19 -> 0.63041248 | U19: =R19/F19 -> 0
D20: 45885 | E20: 六 | F20: 2076344 | I20: 42811 | L20: 1306830 | O20: =L20/F20 -> 0.62938994 | U20: =R20/F20 -> 0
D21: 45886 | E21: 日 | F21: 2596695 | I21: 53433 | L21: 1635724 | O21: =L21/F21 -> 0.62992535 | U21: =R21/F21 -> 0
D22: 45887 | E22: 一 | F22: 2751995 | I22: 52573 | L22: 1735772 | O22: =L22/F22 -> 0.63073225 | U22: =R22/F22 -> 0
B23: =D24 -> 45889 | D23: 45888 | E23: 二 | F23: 3663246 | G23: =SUM(F23:F29) -> 20083919 | I23: 71465 | J23: =SUM(I23:I29) -> 400711 | L23: 2310843 | M23: =SUM(L23:L29) -> 12660243 | O23: =L23/F23 -> 0.63081841 | P23: =M23/G23 -> 0.63036716 | S23: =SUM(R23:R29) -> 0 | U23: =R23/F23 -> 0 | V23: =S23/G23 -> 0
D24: 45889 | E24: 三 | F24: 3220104.3 | I24: 63950 | L24: 2030129 | O24: =L24/F24 -> 0.63045442 | U24: =R24/F24 -> 0
D25: 45890 | E25: 四 | F25: 2984286.3 | I25: 59293 | L25: 1880865 | O25: =L25/F25 -> 0.63025621 | U25: =R25/F25 -> 0
D26: 45891 | E26: 五 | F26: 2143867.2 | I26: 43229 | L26: 1350457 | O26: =L26/F26 -> 0.62991634 | U26: =R26/F26 -> 0
D27: 45892 | E27: 六 | F27: 2337356.9 | I27: 46688 | L27: 1472951 | O27: =L27/F27 -> 0.63017804 | U27: =R27/F27 -> 0
D28: 45893 | E28: 日 | F28: 2795939.1 | I28: 56606 | L28: 1762805 | O28: =L28/F28 -> 0.63048762 | U28: =R28/F28 -> 0
D29: 45894 | E29: 一 | F29: 2939119 | I29: 59480 | L29: 1852193 | O29: =L29/F29 -> 0.63018646 | U29: =R29/F29 -> 0
B30: =D38 -> 45903 | D30: 45895 | E30: 二 | F30: 2910871 | G30: =SUM(F30:F36) -> 18926952 | I30: 62340 | J30: =SUM(I30:I36) -> 390615 | L30: 1836323 | M30: =SUM(L30:L36) -> 11935817 | O30: =L30/F30 -> 0.63085001 | P30: =M30/G30 -> 0.63062542 | S30: =SUM(R30:R36) -> 0 | U30: =R30/F30 -> 0 | V30: =S30/G30 -> 0
D31: 45896 | E31: 三 | F31: 2829056.5 | I31: 58742 | L31: 1784703 | O31: =L31/F31 -> 0.63084743 | U31: =R31/F31 -> 0
D32: 45897 | E32: 四 | F32: 2742274 | I32: 56809 | L32: 1725366 | O32: =L32/F32 -> 0.62917345 | U32: =R32/F32 -> 0
D33: 45898 | E33: 五 | F33: 2263407.1 | I33: 46138 | L33: 1428435 | O33: =L33/F33 -> 0.63109945 | U33: =R33/F33 -> 0
D34: 45899 | E34: 六 | F34: 2324525 | I34: 47670 | L34: 1463604 | O34: =L34/F34 -> 0.62963572 | U34: =R34/F34 -> 0
D35: 45900 | E35: 日 | F35: 2963199.4 | I35: 60121 | L35: 1872193 | O35: =L35/F35 -> 0.63181472 | U35: =R35/F35 -> 0
D36: 45901 | E36: 一 | F36: 2893618.9 | I36: 58795 | L36: 1825193 | O36: =L36/F36 -> 0.63076482
D37: 45902 | E37: 二 | G37: =SUM(F37:F43) -> 0 | J37: =SUM(I37:I43) -> 0 | M37: =SUM(L37:L43) -> 0 | O37: =L37/F37 -> #DIV/0! | P37: =M37/G37 -> #DIV/0! | S37: =SUM(R37:R43) -> 0 | V37: =SUM(U37:U43) -> 0
D38: 45903 | E38: 三 | O38: =L38/F38 -> #DIV/0!
D39: 45904 | E39: 四 | O39: =L39/F39 -> #DIV/0!
D40: 45905 | E40: 五 | O40: =L40/F40 -> #DIV/0!
D41: 45906 | E41: 六 | O41: =L41/F41 -> #DIV/0!
...

Sheet （２）ＫＰＩ達成進度
C1: 109.4
B2: （２）ＫＰＩ達成進度
B3: 資料繳交日 | C3: 月份 | D3: 日期 | F3: 人時生產性(個/人) | I3: 人時生產性達成率(%) | L3: 半成品報廢(%) | O3: 半成品超用(%) | R3: 固定產線-導入率(固定產線數/總產線數) | U3: 教育訓練-實施率(進度/計畫)
F4: 日 | G4: 週平均 | H4: 月平均 | I4: 日 | J4: 週平均 | K4: 月平均 | L4: 日 | M4: 週平均 | N4: 月平均 | O4: 日 | P4: 週平均 | Q4: 月平均 | R4: 日 | S4: 週平均 | T4: 月平均 | U4: 日 | V4: 週平均 | W4: 月平均
B5: =D17 -> 45882 | C5: 八 | D5: 45870 | E5: 五 | F5: 100.6 | G5: =AVERAGE(F5:F8) -> 99.775 | H5: =AVERAGE(F5:F35) -> 97.125806 | I5: =F5/$C$1 -> 0.91956124 | J5: =AVERAGE(I5:I8) -> 0.91202011 | K5: =AVERAGE(I5:I35) -> 0.88780445 | L5: 0.00902 | M5: =AVERAGE(L5:L8) -> 0.009125 | N5: =AVERAGE(L5:L35) -> 0.0076116129 | O5: 0.0103 | P5: =AVERAGE(O5:O8) -> 0.0119 | Q5: =AVERAGE(O5:O35) -> 0.011045161 | R5: 0.429 | S5: =AVERAGE(R5:R8) -> 0.429 | T5: =AVERAGE(R5:R35) -> 0.429 | U5: 0.286 | V5: =AVERAGE(U5:U8) -> 0.32175 | W5: =AVERAGE(U5:U35) -> 0.61741935
D6: 45871 | E6: 六 | F6: 101.4 | I6: =F6/$C$1 -> 0.92687386 | L6: 0.01053 | O6: 0.0136 | R6: 0.429 | U6: 0.286
D7: 45872 | E7: 日 | F7: 100.8 | I7: =F7/$C$1 -> 0.9213894 | L7: 0.00818 | O7: 0.0103 | R7: 0.429 | U7: 0.286
D8: 45873 | E8: 一 | F8: 96.3 | I8: =F8/$C$1 -> 0.88025594 | L8: 0.00877 | O8: 0.0134 | R8: 0.429 | U8: 0.429
D9: 45874 | E9: 二 | F9: 91.2 | G9: =AVERAGE(F9:F15) -> 96.285714 | I9: =F9/$C$1 -> 0.83363803 | J9: =AVERAGE(I9:I15) -> 0.88012536 | L9: 0.00731 | M9: =AVERAGE(L9:L15) -> 0.0090885714 | O9: 0.021 | P9: =AVERAGE(O9:O15) -> 0.020714286 | R9: 0.429 | S9: =AVERAGE(R9:R15) -> 0.429 | U9: 0.429 | V9: =AVERAGE(U9:U15) -> 0.51042857
D10: 45875 | E10: 三 | F10: 94.5 | I10: =F10/$C$1 -> 0.86380256 | L10: 0.00808 | O10: 0.0212 | R10: 0.429 | U10: 0.429
D11: 45876 | E11: 四 | F11: 100.1 | I11: =F11/$C$1 -> 0.91499086 | L11: 0.01012 | O11: 0.0204 | R11: 0.429 | U11: 0.429
D12: 45877 | E12: 五 | F12: 96.7 | I12: =F12/$C$1 -> 0.88391225 | L12: 0.00951 | O12: 0.0232 | R12: 0.429 | U12: 0.429
D13: 45878 | E13: 六 | F13: 95.8 | I13: =F13/$C$1 -> 0.87568556 | L13: 0.0113 | O13: 0.0197 | R13: 0.429 | U13: 0.429
D14: 45879 | E14: 日 | F14: 98.4 | I14: =F14/$C$1 -> 0.89945155 | L14: 0.01054 | O14: 0.0159 | R14: 0.429 | U14: 0.714
D15: 45880 | E15: 一 | F15: 97.3 | I15: =F15/$C$1 -> 0.88939671 | L15: 0.00676 | O15: 0.0236 | R15: 0.429 | U15: 0.714
B16: =D24 -> 45889 | D16: 45881 | E16: 二 | F16: 99.5 | G16: =AVERAGE(F16:F22) -> 97.457143 | I16: =F16/$C$1 -> 0.9095064 | J16: =AVERAGE(I16:I22) -> 0.89083312 | L16: 0.00807 | M16: =AVERAGE(L16:L22) -> 0.0080285714 | O16: 0.023 | P16: =AVERAGE(O16:O22) -> 0.013114286 | R16: 0.429 | S16: =AVERAGE(R16:R22) -> 0.429 | U16: 0.714 | V16: =AVERAGE(U16:U22) -> 0.714
D17: 45882 | E17: 三 | F17: 98.3 | I17: =F17/$C$1 -> 0.89853748 | L17: 0.00793 | O17: 0.0224 | R17: 0.429 | U17: 0.714
D18: 45883 | E18: 四 | F18: 99.4 | I18: =F18/$C$1 -> 0.90859232 | L18: 0.0147 | O18: 0.0159 | R18: 0.429 | U18: 0.714
D19: 45884 | E19: 五 | F19: 91.7 | I19: =F19/$C$1 -> 0.83820841 | L19: 0.007 | O19: 0.0056 | R19: 0.429 | U19: 0.714
D20: 45885 | E20: 六 | F20: 96.1 | I20: =F20/$C$1 -> 0.87842779 | L20: 0.0054 | O20: 0.0079 | R20: 0.429 | U20: 0.714
D21: 45886 | E21: 日 | F21: 100.3 | I21: =F21/$C$1 -> 0.91681901 | L21: 0.006 | O21: 0.0084 | R21: 0.429 | U21: 0.714
D22: 45887 | E22: 一 | F22: 96.9 | I22: =F22/$C$1 -> 0.8857404 | L22: 0.0071 | O22: 0.0086 | R22: 0.429 | U22: 0.714
B23: =D24 -> 45889 | D23: 45888 | E23: 二 | F23: 94.1 | G23: =AVERAGE(F23:F29) -> 94.685714 | I23: =F23/$C$1 -> 0.86014625 | J23: =AVERAGE(I23:I29) -> 0.86550013 | L23: 0.00655 | M23: =AVERAGE(L23:L29) -> 0.00719 | O23: 0.0058 | P23: =AVERAGE(O23:O29) -> 0.0052428571 | R23: 0.429 | S23: =AVERAGE(R23:R29) -> 0.429 | U23: 0.714 | V23: =AVERAGE(U23:U29) -> 0.714
D24: 45889 | E24: 三 | F24: 98.3 | I24: =F24/$C$1 -> 0.89853748 | L24: 0.0074 | O24: 0.0058 | R24: 0.429 | U24: 0.714
D25: 45890 | E25: 四 | F25: 95.4 | I25: =F25/$C$1 -> 0.87202925 | L25: 0.00817 | O25: 0.0064 | R25: 0.429 | U25: 0.714
D26: 45891 | E26: 五 | F26: 87.2 | I26: =F26/$C$1 -> 0.79707495 | L26: 0.00724 | O26: 0.0065 | R26: 0.429 | U26: 0.714
D27: 45892 | E27: 六 | F27: 94.6 | I27: =F27/$C$1 -> 0.86471664 | L27: 0.00651 | O27: 0.0049 | R27: 0.429 | U27: 0.714
D28: 45893 | E28: 日 | F28: 96.7 | I28: =F28/$C$1 -> 0.88391225 | L28: 0.00746 | O28: 0.0045 | R28: 0.429 | U28: 0.714
D29: 45894 | E29: 一 | F29: 96.5 | I29: =F29/$C$1 -> 0.8820841 | L29: 0.007 | O29: 0.0028 | R29: 0.429 | U29: 0.714
B30: =D38 -> 45903 | D30: 45895 | E30: 二 | F30: 96.5 | G30: =AVERAGE(F30:F36) -> 98.628571 | I30: =F30/$C$1 -> 0.8820841 | J30: =AVERAGE(I30:I36) -> 0.90154087 | L30: 0.0059 | M30: =AVERAGE(L30:L36) -> 0.0047585714 | O30: 0.0072 | P30: =AVERAGE(O30:O36) -> 0.0033285714 | R30: 0.429 | S30: =AVERAGE(R30:R36) -> 0.429 | U30: 0.714 | V30: =AVERAGE(U30:U36) -> 0.714
D31: 45896 | E31: 三 | F31: 96.5 | I31: =F31/$C$1 -> 0.8820841 | L31: 0.0054 | O31: 0.0038 | R31: 0.429 | U31: 0.714
D32: 45897 | E32: 四 | F32: 102.1 | I32: =F32/$C$1 -> 0.93327239 | L32: 0.0047 | O32: 0.0019 | R32: 0.429 | U32: 0.714
D33: 45898 | E33: 五 | F33: 97.6 | I33: =F33/$C$1 -> 0.89213894 | L33: 0.00458 | O33: 0.0028 | R33: 0.429 | U33: 0.714
D34: 45899 | E34: 六 | F34: 98 | I34: =F34/$C$1 -> 0.89579525 | L34: 0.00451 | O34: 0.002 | R34: 0.429 | U34: 0.714
D35: 45900 | E35: 日 | F35: 102.1 | I35: =F35/$C$1 -> 0.93327239 | L35: 0.00422 | O35: 0.0036 | R35: 0.429 | U35: 0.714
D36: 45901 | E36: 一 | F36: 97.6 | I36: =F36/$C$1 -> 0.89213894 | L36: 0.004 | O36: 0.002 | R36: 0.429
D37: 45902 | E37: 二 | G37: =AVERAGE(F37:F43) -> #DIV/0! | I37: =F37/$C$1 -> 0 | J37: =AVERAGE(I37:I43) -> 0 | M37: =AVERAGE(L37:L43) -> #DIV/0! | P37: =AVERAGE(O37:O43) -> #DIV/0! | S37: =AVERAGE(R37:R43) -> #DIV/0! | V37: =AVERAGE(U37:U43) -> #DIV/0!
D38: 45903 | E38: 三 | I38: =F38/$C$1 -> 0
D39: 45904 | E39: 四 | I39: =F39/$C$1 -> 0
D40: 45905 | E40: 五 | I40: =F40/$C$1 -> 0
...

Sheet （３）業績構成比
B2: （3）業績構成比
B3: 資料繳交日 | C3: 月份 | D3: 日期 | F3: 營業額 | I3: 品類業績
I4: 熱食義麵 | K4: 季節調理麵 | M4: 微波小吃
F5: 日 | G5: 週累積 | H5: 月累積 | I5: 一配 | K5: 一配 | M5: 一配
I6: 業績(元) | J6: 比例(%) | K6: 業績(元) | L6: 比例(%) | M6: 業績(元) | N6: 比例(%)
B7: =D19 -> 45882 | C7: 八 | D7: 45870 | E7: 五 | F7: =SUM(I7,K7,M7) -> 2385266.7 | G7: =SUM(F7:F10) -> 10607384 | H7: =SUM(F7:F37) -> 84284948 | I7: 2195130 | J7: =I7/F7 -> 0.92028702 | L7: =K7/F7 -> 0 | M7: 190136.72 | N7: =M7/F7 -> 0.079712982
D8: 45871 | E8: 六 | F8: =SUM(I8,K8,M8) -> 2388905.3 | I8: 2194190.1 | J8: =I8/F8 -> 0.91849186 | L8: =K8/F8 -> 0 | M8: 194715.24 | N8: =M8/F8 -> 0.081508145
D9: 45872 | E9: 日 | F9: =SUM(I9,K9,M9) -> 2899844.4 | I9: 2660909.2 | J9: =I9/F9 -> 0.91760411 | L9: =K9/F9 -> 0 | M9: 238935.25 | N9: =M9/F9 -> 0.082395886
D10: 45873 | E10: 一 | F10: =SUM(I10,K10,M10) -> 2933368 | I10: 2698249 | J10: =I10/F10 -> 0.91984674 | L10: =K10/F10 -> 0 | M10: 235119 | N10: =M10/F10 -> 0.080153257
D11: 45874 | E11: 二 | F11: =SUM(I11,K11,M11) -> 3567473 | G11: =SUM(F11:F17) -> 19947142 | I11: 3338114 | J11: =I11/F11 -> 0.93570827 | L11: =K11/F11 -> 0 | M11: 229359 | N11: =M11/F11 -> 0.064291727
D12: 45875 | E12: 三 | F12: =SUM(I12,K12,M12) -> 3253153 | I12: 3022277 | J12: =I12/F12 -> 0.92903008 | L12: =K12/F12 -> 0 | M12: 230876 | N12: =M12/F12 -> 0.070969917
D13: 45876 | E13: 四 | F13: =SUM(I13,K13,M13) -> 3065389 | I13: 2847697 | J13: =I13/F13 -> 0.92898389 | L13: =K13/F13 -> 0 | M13: 217692 | N13: =M13/F13 -> 0.071016109
D14: 45877 | E14: 五 | F14: =SUM(I14,K14,M14) -> 2194710 | I14: 2005404 | J14: =I14/F14 -> 0.91374441 | L14: =K14/F14 -> 0 | M14: 189306 | N14: =M14/F14 -> 0.086255587
D15: 45878 | E15: 六 | F15: =SUM(I15,K15,M15) -> 2228264 | I15: 2036693 | J15: =I15/F15 -> 0.91402679 | L15: =K15/F15 -> 0 | M15: 191571 | N15: =M15/F15 -> 0.085973206
D16: 45879 | E16: 日 | F16: =SUM(I16,K16,M16) -> 2819551 | I16: 2583047.8 | J16: =I16/F16 -> 0.91612025 | L16: =K16/F16 -> 0 | M16: 236503.23 | N16: =M16/F16 -> 0.083879748
D17: 45880 | E17: 一 | F17: =SUM(I17,K17,M17) -> 2818602 | I17: 2589298 | J17: =I17/F17 -> 0.91864619 | L17: =K17/F17 -> 0 | M17: 229304 | N17: =M17/F17 -> 0.081353806
B18: =D26 -> 45889 | D18: 45881 | E18: 二 | F18: =SUM(I18,K18,M18) -> 2662577 | G18: =SUM(F18:F24) -> 17613170 | I18: 2437291 | J18: =I18/F18 -> 0.91538799 | L18: =K18/F18 -> 0 | M18: 225286 | N18: =M18/F18 -> 0.084612013
D19: 45882 | E19: 三 | F19: =SUM(I19,K19,M19) -> 2744634 | I19: 2513938 | J19: =I19/F19 -> 0.91594653 | L19: =K19/F19 -> 0 | M19: 230696 | N19: =M19/F19 -> 0.084053466
D20: 45883 | E20: 四 | F20: =SUM(I20,K20,M20) -> 2633487.9 | I20: 2417904.1 | J20: =I20/F20 -> 0.91813755 | L20: =K20/F20 -> 0 | M20: 215583.77 | N20: =M20/F20 -> 0.081862449
D21: 45884 | E21: 五 | F21: =SUM(I21,K21,M21) -> 2147438.5 | I21: 1950980.8 | J21: =I21/F21 -> 0.90851537 | L21: =K21/F21 -> 0 | M21: 196457.62 | N21: =M21/F21 -> 0.091484634
D22: 45885 | E22: 六 | F22: =SUM(I22,K22,M22) -> 2076344 | I22: 1882467.2 | J22: =I22/F22 -> 0.90662588 | L22: =K22/F22 -> 0 | M22: 193876.8 | N22: =M22/F22 -> 0.093374125
D23: 45886 | E23: 日 | F23: =SUM(I23,K23,M23) -> 2596695 | I23: 2364186.9 | J23: =I23/F23 -> 0.91045999 | L23: =K23/F23 -> 0 | M23: 232508.1 | N23: =M23/F23 -> 0.089540012
D24: 45887 | E24: 一 | F24: =SUM(I24,K24,M24) -> 2751994 | I24: 2519486 | J24: =I24/F24 -> 0.9155129 | L24: =K24/F24 -> 0 | M24: 232508 | N24: =M24/F24 -> 0.084487103
B25: =D33 -> 45896 | D25: 45888 | E25: 二 | F25: =SUM(I25,K25,M25) -> 3663245.5 | G25: =SUM(F25:F31) -> 20083918 | I25: 3433508.6 | J25: =I25/F25 -> 0.93728596 | L25: =K25/F25 -> 0 | M25: 229736.94 | N25: =M25/F25 -> 0.062714044
D26: 45889 | E26: 三 | F26: =SUM(I26,K26,M26) -> 3220104.3 | I26: 2994134.3 | J26: =I26/F26 -> 0.92982524 | L26: =K26/F26 -> 0 | M26: 225970.05 | N26: =M26/F26 -> 0.070174761
D27: 45890 | E27: 四 | F27: =SUM(I27,K27,M27) -> 2984286.3 | I27: 2770927.9 | J27: =I27/F27 -> 0.92850606 | L27: =K27/F27 -> 0 | M27: 213358.4 | N27: =M27/F27 -> 0.071493944
D28: 45891 | E28: 五 | F28: =SUM(I28,K28,M28) -> 2143867.2 | I28: 1968339.7 | J28: =I28/F28 -> 0.91812577 | L28: =K28/F28 -> 0 | M28: 175527.48 | N28: =M28/F28 -> 0.081874231
D29: 45892 | E29: 六 | F29: =SUM(I29,K29,M29) -> 2337356.9 | I29: 2156126.7 | J29: =I29/F29 -> 0.92246363 | L29: =K29/F29 -> 0 | M29: 181230.17 | N29: =M29/F29 -> 0.07753637
D30: 45893 | E30: 日 | F30: =SUM(I30,K30,M30) -> 2795939.1 | I30: 2570126 | J30: =I30/F30 -> 0.91923532 | L30: =K30/F30 -> 0 | M30: 225813.14 | N30: =M30/F30 -> 0.080764684
D31: 45894 | E31: 一 | F31: =SUM(I31,K31,M31) -> 2939119 | I31: 2713996.1 | J31: =I31/F31 -> 0.92340462 | L31: =K31/F31 -> 0 | M31: 225122.93 | N31: =M31/F31 -> 0.076595377
B32: =D40 -> 45903 | D32: 45895 | E32: 二 | F32: =SUM(I32,K32,M32) -> 2910871 | G32: =SUM(F32:F38) -> 18926952 | I32: 2490177.2 | J32: =I32/F32 -> 0.85547494 | L32: =K32/F32 -> 0 | M32: 420693.81 | N32: =M32/F32 -> 0.14452506
D33: 45896 | E33: 三 | F33: =SUM(I33,K33,M33) -> 2829056.5 | I33: 2503046.8 | J33: =I33/F33 -> 0.88476382 | L33: =K33/F33 -> 0 | M33: 326009.67 | N33: =M33/F33 -> 0.11523618
D34: 45897 | E34: 四 | F34: =SUM(I34,K34,M34) -> 2742273.9 | I34: 2432199.8 | J34: =I34/F34 -> 0.88692809 | L34: =K34/F34 -> 0 | M34: 310074.14 | N34: =M34/F34 -> 0.11307191
D35: 45898 | E35: 五 | F35: =SUM(I35,K35,M35) -> 2263407.1 | I35: 2048584.5 | J35: =I35/F35 -> 0.9050888 | L35: =K35/F35 -> 0 | M35: 214822.69 | N35: =M35/F35 -> 0.094911201
D36: 45899 | E36: 六 | F36: =SUM(I36,K36,M36) -> 2324525 | I36: 2089081.5 | J36: =I36/F36 -> 0.89871327 | L36: =K36/F36 -> 0 | M36: 235443.53 | N36: =M36/F36 -> 0.10128673
D37: 45900 | E37: 日 | F37: =SUM(I37,K37,M37) -> 2963199.4 | I37: 2711101.8 | J37: =I37/F37 -> 0.91492387 | L37: =K37/F37 -> 0 | M37: 252097.55 | N37: =M37/F37 -> 0.085076135
D38: 45901 | E38: 一 | F38: =SUM(I38,K38,M38) -> 2893618.9 | I38: 2647777.4 | J38: =I38/F38 -> 0.91504011 | L38: =K38/F38 -> 0 | M38: 245841.55 | N38: =M38/F38 -> 0.084959892
D39: 45902 | E39: 二 | F39: =SUM(I39,K39,M39) -> 0 | G39: =SUM(F39:F45) -> 0 | J39: =I39/F39 -> #DIV/0! | L39: =K39/F39 -> #DIV/0! | N39: =M39/F39 -> #DIV/0!
D40: 45903 | E40: 三 | F40: =SUM(I40,K40,M40) -> 0 | J40: =I40/F40 -> #DIV/0! | L40: =K40/F40 -> #DIV/0! | N40: =M40/F40 -> #DIV/0!
D41: 45904 | E41: 四 | F41: =SUM(I41,K41,M41) -> 0 | J41: =I41/F41 -> #DIV/0! | L41: =K41/F41 -> #DIV/0! | N41: =M41/F41 -> #DIV/0!
...

Sheet （４）訂單數量構成比
B2: （4）訂單數量構成比
B3: 資料繳交日 | C3: 月份 | D3: 日期 | F3: 訂單量 | I3: 品類訂單量
I4: 熱食義麵 | K4: 季節調理麵 | M4: 微波小吃
F5: 日 | G5: 週累積 | H5: 月累積 | I5: 一配 | K5: 一配 | M5: 一配
I6: 訂單數 | J6: 比例(%) | K6: 訂單數 | L6: 比例(%) | M6: 訂單數 | N6: 比例(%)
B7: =D19 -> 45882 | C7: 八 | D7: 45870 | E7: 五 | F7: =SUM(I7,K7,M7) -> 48634 | G7: =SUM(F7:F10) -> 217451 | H7: =SUM(F7:F37) -> 1717015 | I7: 41763 | J7: =I7/F7 -> 0.85872024 | L7: =K7/F7 -> 0 | M7: 6871 | N7: =M7/F7 -> 0.14127976
D8: 45871 | E8: 六 | F8: =SUM(I8,K8,M8) -> 50077 | I8: 43038 | J8: =I8/F8 -> 0.85943647 | L8: =K8/F8 -> 0 | M8: 7039 | N8: =M8/F8 -> 0.14056353
D9: 45872 | E9: 日 | F9: =SUM(I9,K9,M9) -> 59089 | I9: 50442 | J9: =I9/F9 -> 0.85366143 | L9: =K9/F9 -> 0 | M9: 8647 | N9: =M9/F9 -> 0.14633857
D10: 45873 | E10: 一 | F10: =SUM(I10,K10,M10) -> 59651 | I10: 51137 | J10: =I10/F10 -> 0.85726979 | L10: =K10/F10 -> 0 | M10: 8514 | N10: =M10/F10 -> 0.14273021
D11: 45874 | E11: 二 | F11: =SUM(I11,K11,M11) -> 72576 | G11: =SUM(F11:F17) -> 408990 | I11: 64272 | J11: =I11/F11 -> 0.88558201 | L11: =K11/F11 -> 0 | M11: 8304 | N11: =M11/F11 -> 0.11441799
D12: 45875 | E12: 三 | F12: =SUM(I12,K12,M12) -> 66419 | I12: 58065 | J12: =I12/F12 -> 0.87422274 | L12: =K12/F12 -> 0 | M12: 8354 | N12: =M12/F12 -> 0.12577726
D13: 45876 | E13: 四 | F13: =SUM(I13,K13,M13) -> 62707 | I13: 54834 | J13: =I13/F13 -> 0.87444783 | L13: =K13/F13 -> 0 | M13: 7873 | N13: =M13/F13 -> 0.12555217
D14: 45877 | E14: 五 | F14: =SUM(I14,K14,M14) -> 45233 | I14: 38391 | J14: =I14/F14 -> 0.84873875 | L14: =K14/F14 -> 0 | M14: 6842 | N14: =M14/F14 -> 0.15126125
D15: 45878 | E15: 六 | F15: =SUM(I15,K15,M15) -> 46023 | I15: 39093 | J15: =I15/F15 -> 0.84942311 | L15: =K15/F15 -> 0 | M15: 6930 | N15: =M15/F15 -> 0.15057689
D16: 45879 | E16: 日 | F16: =SUM(I16,K16,M16) -> 58090 | I16: 49524 | J16: =I16/F16 -> 0.85253916 | L16: =K16/F16 -> 0 | M16: 8566 | N16: =M16/F16 -> 0.14746084
D17: 45880 | E17: 一 | F17: =SUM(I17,K17,M17) -> 57942 | I17: 49640 | J17: =I17/F17 -> 0.85671879 | L17: =K17/F17 -> 0 | M17: 8302 | N17: =M17/F17 -> 0.14328121
B18: =D26 -> 45889 | D18: 45881 | E18: 二 | F18: =SUM(I18,K18,M18) -> 54761 | G18: =SUM(F18:F24) -> 358043 | I18: 46599 | J18: =I18/F18 -> 0.85095232 | L18: =K18/F18 -> 0 | M18: 8162 | N18: =M18/F18 -> 0.14904768
D19: 45882 | E19: 三 | F19: =SUM(I19,K19,M19) -> 56324 | I19: 47970 | J19: =I19/F19 -> 0.85167957 | L19: =K19/F19 -> 0 | M19: 8354 | N19: =M19/F19 -> 0.14832043
D20: 45883 | E20: 四 | F20: =SUM(I20,K20,M20) -> 53933 | I20: 46125 | J20: =I20/F20 -> 0.85522778 | L20: =K20/F20 -> 0 | M20: 7808 | N20: =M20/F20 -> 0.14477222
D21: 45884 | E21: 五 | F21: =SUM(I21,K21,M21) -> 44208 | I21: 37105 | J21: =I21/F21 -> 0.83932772 | L21: =K21/F21 -> 0 | M21: 7103 | N21: =M21/F21 -> 0.16067228
D22: 45885 | E22: 六 | F22: =SUM(I22,K22,M22) -> 42811 | I22: 35797 | J22: =I22/F22 -> 0.8361636 | L22: =K22/F22 -> 0 | M22: 7014 | N22: =M22/F22 -> 0.1638364
D23: 45886 | E23: 日 | F23: =SUM(I23,K23,M23) -> 53433 | I23: 45010 | J23: =I23/F23 -> 0.84236333 | L23: =K23/F23 -> 0 | M23: 8423 | N23: =M23/F23 -> 0.15763667
D24: 45887 | E24: 一 | F24: =SUM(I24,K24,M24) -> 52573 | I24: 44150 | J24: =I24/F24 -> 0.83978468 | L24: =K24/F24 -> 0 | M24: 8423 | N24: =M24/F24 -> 0.16021532
B25: =D26 -> 45889 | D25: 45888 | E25: 二 | F25: =SUM(I25,K25,M25) -> 71465 | G25: =SUM(F25:F31) -> 400711 | I25: 63140 | J25: =I25/F25 -> 0.88350941 | L25: =K25/F25 -> 0 | M25: 8325 | N25: =M25/F25 -> 0.11649059
D26: 45889 | E26: 三 | F26: =SUM(I26,K26,M26) -> 63950 | I26: 55768 | J26: =I26/F26 -> 0.87205629 | L26: =K26/F26 -> 0 | M26: 8182 | N26: =M26/F26 -> 0.12794371
D27: 45890 | E27: 四 | F27: =SUM(I27,K27,M27) -> 59293 | I27: 51567 | J27: =I27/F27 -> 0.86969794 | L27: =K27/F27 -> 0 | M27: 7726 | N27: =M27/F27 -> 0.13030206
D28: 45891 | E28: 五 | F28: =SUM(I28,K28,M28) -> 43229 | I28: 36883 | J28: =I28/F28 -> 0.8532004 | L28: =K28/F28 -> 0 | M28: 6346 | N28: =M28/F28 -> 0.1467996
D29: 45892 | E29: 六 | F29: =SUM(I29,K29,M29) -> 46688 | I29: 40136 | J29: =I29/F29 -> 0.85966415 | L29: =K29/F29 -> 0 | M29: 6552 | N29: =M29/F29 -> 0.14033585
D30: 45893 | E30: 日 | F30: =SUM(I30,K30,M30) -> 56606 | I30: 48427 | J30: =I30/F30 -> 0.85551002 | L30: =K30/F30 -> 0 | M30: 8179 | N30: =M30/F30 -> 0.14448998
D31: 45894 | E31: 一 | F31: =SUM(I31,K31,M31) -> 59480 | I31: 51327 | J31: =I31/F31 -> 0.86292872 | L31: =K31/F31 -> 0 | M31: 8153 | N31: =M31/F31 -> 0.13707128
B32: =D40 -> 45903 | D32: 45895 | E32: 二 | F32: =SUM(I32,K32,M32) -> 62340 | G32: =SUM(F32:F37) -> 331820 | I32: 46919 | J32: =I32/F32 -> 0.75263073 | L32: =K32/F32 -> 0 | M32: 15421 | N32: =M32/F32 -> 0.24736927
D33: 45896 | E33: 三 | F33: =SUM(I33,K33,M33) -> 58742 | I33: 47052 | J33: =I33/F33 -> 0.80099418 | L33: =K33/F33 -> 0 | M33: 11690 | N33: =M33/F33 -> 0.19900582
D34: 45897 | E34: 四 | F34: =SUM(I34,K34,M34) -> 56809 | I34: 45692 | J34: =I34/F34 -> 0.80430918 | L34: =K34/F34 -> 0 | M34: 11117 | N34: =M34/F34 -> 0.19569082
D35: 45898 | E35: 五 | F35: =SUM(I35,K35,M35) -> 46138 | I35: 38409 | J35: =I35/F35 -> 0.83248082 | L35: =K35/F35 -> 0 | M35: 7729 | N35: =M35/F35 -> 0.16751918
D36: 45899 | E36: 六 | F36: =SUM(I36,K36,M36) -> 47670 | I36: 39211 | J36: =I36/F36 -> 0.82255087 | L36: =K36/F36 -> 0 | M36: 8459 | N36: =M36/F36 -> 0.17744913
D37: 45900 | E37: 日 | F37: =SUM(I37,K37,M37) -> 60121 | I37: 51015 | J37: =I37/F37 -> 0.84853878 | L37: =K37/F37 -> 0 | M37: 9106 | N37: =M37/F37 -> 0.15146122
D38: 45901 | E38: 一 | F38: =SUM(I38,K38,M38) -> 58795 | I38: 49909 | J38: =I38/F38 -> 0.8488647 | L38: =K38/F38 -> 0 | M38: 8886 | N38: =M38/F38 -> 0.1511353
D39: 45902 | E39: 二 | F39: =SUM(I39,K39,M39) -> 0 | G39: =SUM(F39:F45) -> 0 | J39: =I39/F39 -> #DIV/0! | L39: =K39/F39 -> #DIV/0! | N39: =M39/F39 -> #DIV/0!
D40: 45903 | E40: 三 | F40: =SUM(I40,K40,M40) -> 0 | J40: =I40/F40 -> #DIV/0! | L40: =K40/F40 -> #DIV/0! | N40: =M40/F40 -> #DIV/0!
D41: 45904 | E41: 四 | F41: =SUM(I41,K41,M41) -> 0 | J41: =I41/F41 -> #DIV/0! | L41: =K41/F41 -> #DIV/0! | N41: =M41/F41 -> #DIV/0!
...

Sheet （５-1）品群別人時生產性（熱食義麵）
B1: 月平均人時性 | C1: =AVERAGE(L7,L27,L47,L67,L90) -> 95.555687
B2: 產線配置圖－每週更新 | N2: 資料繳交 | O2: 日期 | AE2: 45870 | AJ2: 45871 | AO2: 45872 | AT2: 45873
P3: 二 | U3: 三 | Z3: 四 | AE3: 五 | AJ3: 六 | AO3: 日 | AT3: 一
B4: 品群 | C4: 商品名稱 | E4: 計畫 | H4: 平均人時性 | I4: 實績 | L4: 平均人時性 | M4: 排名 | O4: 日報 | P4: 實際 | T4: 平均人時性 | U4: 實際 | Y4: 平均人時性 | Z4: 實際 | AD4: 平均人時性 | AE4: 實際 | AI4: 平均人時性 | AJ4: 實際 | AN4: 平均人時性 | AO4: 實際 | AS4: 平均人時性 | AT4: 實際 | AX4: 平均人時性
E5: 產線配置圖 | I5: 產線配置圖 | P5: 生產實績 | U5: 生產實績 | Z5: 生產實績 | AE5: 生產實績 | AJ5: 生產實績 | AO5: 生產實績 | AT5: 生產實績
E6: 人數 | F6: 產能／時 | G6: 人時性 | I6: 人數 | J6: 產能／時 | K6: 人時性 | P6: 人數 | Q6: 產能／時 | R6: 人時性 | S6: 排名 | U6: 人數 | V6: 產能／時 | W6: 人時性 | X6: 排名 | Z6: 人數 | AA6: 產能／時 | AB6: 人時性 | AC6: 排名 | AE6: 人數 | AF6: 產能／時 | AG6: 人時性 | AH6: 排名 | AJ6: 人數 | AK6: 產能／時 | AL6: 人時性 | AM6: 排名 | AO6: 人數 | AP6: 產能／時 | AQ6: 人時性 | AR6: 排名 | AT6: 人數 | AU6: 產能／時 | AV6: 人時性 | AW6: 排名
B7: 熱食義麵 | C7: 1 | D7: 義式蕃茄起司義大利麵 | E7: =VLOOKUP(D7,'[1]0801-0804產線配置圖'!$A$2:$C$17,2,0) -> 12 | F7: =VLOOKUP(D7,'[1]0801-0804產線配置圖'!$A$2:$C$17,3,0) -> 2000 | G7: =F7/E7 -> 166.66667 | H7: =AVERAGE(G7:G21) -> 104.05274 | I7: =AVERAGE(P7,U7,Z7,AE7,AJ7,AO7,AT7) -> 12 | J7: =AVERAGE(Q7,V7,AA7,AF7,AK7,AP7,AU7) -> 1725 | K7: =AVERAGE(AG7,AL7,AQ7,AV7) -> 143.75 | L7: =IFERROR(AVERAGE(K7:K21),"-") -> 99.875984 | M7: =RANK(K7, K$7:$K$21) -> 1 | R7: =Q7/P7 -> #DIV/0! | S7: =RANK(R7, R$7:R$21) -> #DIV/0! | T7: =AVERAGE(R7:R21) -> #DIV/0! | W7: =V7/U7 -> #DIV/0! | X7: =RANK(W7, W$7:W$21) -> #DIV/0! | Y7: =AVERAGE(W7:W21) -> #DIV/0! | AB7: =AA7/Z7 -> #DIV/0! | AC7: =RANK(AB7, AB$7:AB$21) -> #DIV/0! | AD7: =AVERAGE(AB7:AB21) -> #DIV/0! | AE7: 12 | AF7: 1636 | AG7: =AF7/AE7 -> 136.33333 | AH7: =RANK(AG7, AG$7:AG$21) -> 3 | AI7: =AVERAGE(AG7:AG21) -> 108.53435 | AJ7: 12 | AK7: 1735 | AL7: =AK7/AJ7 -> 144.58333 | AM7: =RANK(AL7, AL$7:AL$21) -> 1 | AN7: =AVERAGE(AL7:AL21) -> 97.267563 | AO7: 12 | AP7: 1636 | AQ7: =AP7/AO7 -> 136.33333 | AR7: =RANK(AQ7, AQ$7:AQ$21) -> 2 | AS7: =AVERAGE(AQ7:AQ21) -> 97.609828 | AT7: 12 | AU7: 1893 | AV7: =AU7/AT7 -> 157.75 | AW7: =RANK(AV7, AV$7:AV$21) -> 1 | AX7: =AVERAGE(AV7:AV21) -> 96.693845
C8: 2 | D8: 奶油培根義大利麵 | E8: =VLOOKUP(D8,'[1]0801-0804產線配置圖'!$A$2:$C$17,2,0) -> 13 | F8: =VLOOKUP(D8,'[1]0801-0804產線配置圖'!$A$2:$C$17,3,0) -> 2000 | G8: =F8/E8 -> 153.84615 | I8: =AVERAGE(P8,U8,Z8,AE8,AJ8,AO8,AT8) -> 12.75 | J8: =AVERAGE(Q8,V8,AA8,AF8,AK8,AP8,AU8) -> 1672.75 | K8: =AVERAGE(AG8,AL8,AQ8,AV8) -> 130.96314 | M8: =RANK(K8, K$7:$K$21) -> 2 | R8: =Q8/P8 -> #DIV/0! | S8: =RANK(R8, R$7:R$21) -> #DIV/0! | W8: =V8/U8 -> #DIV/0! | X8: =RANK(W8, W$7:W$21) -> #DIV/0! | AB8: =AA8/Z8 -> #DIV/0! | AC8: =RANK(AB8, AB$7:AB$21) -> #DIV/0! | AE8: 13 | AF8: 1620 | AG8: =AF8/AE8 -> 124.61538 | AH8: =RANK(AG8, AG$7:AG$21) -> 5 | AJ8: 12 | AK8: 1429 | AL8: =AK8/AJ8 -> 119.08333 | AM8: =RANK(AL8, AL$7:AL$21) -> 3 | AO8: 13 | AP8: 1620 | AQ8: =AP8/AO8 -> 124.61538 | AR8: =RANK(AQ8, AQ$7:AQ$21) -> 3 | AT8: 13 | AU8: 2022 | AV8: =AU8/AT8 -> 155.53846 | AW8: =RANK(AV8, AV$7:AV$21) -> 2
C9: 3 | D9: 熱那亞青醬義大利麵 | E9: =VLOOKUP(D9,'[1]0801-0804產線配置圖'!$A$2:$C$17,2,0) -> 16 | F9: =VLOOKUP(D9,'[1]0801-0804產線配置圖'!$A$2:$C$17,3,0) -> 1915 | G9: =F9/E9 -> 119.6875 | I9: =AVERAGE(P9,U9,Z9,AE9,AJ9,AO9,AT9) -> 15.5 | J9: =AVERAGE(Q9,V9,AA9,AF9,AK9,AP9,AU9) -> 1460 | K9: =AVERAGE(AG9,AL9,AQ9,AV9) -> 94.321429 | M9: =RANK(K9, K$7:$K$21) -> 7 | R9: =Q9/P9 -> #DIV/0! | S9: =RANK(R9, R$7:R$21) -> #DIV/0! | W9: =V9/U9 -> #DIV/0! | X9: =RANK(W9, W$7:W$21) -> #DIV/0! | AB9: =AA9/Z9 -> #DIV/0! | AC9: =RANK(AB9, AB$7:AB$21) -> #DIV/0! | AE9: 16 | AF9: 1418 | AG9: =AF9/AE9 -> 88.625 | AH9: =RANK(AG9, AG$7:AG$21) -> 11 | AJ9: 14 | AK9: 1376 | AL9: =AK9/AJ9 -> 98.285714 | AM9: =RANK(AL9, AL$7:AL$21) -> 7 | AO9: 16 | AP9: 1418 | AQ9: =AP9/AO9 -> 88.625 | AR9: =RANK(AQ9, AQ$7:AQ$21) -> 10 | AT9: 16 | AU9: 1628 | AV9: =AU9/AT9 -> 101.75 | AW9: =RANK(AV9, AV$7:AV$21) -> 4
C10: 4 | D10: 焗烤起司雙饗筆尖麵 | E10: =VLOOKUP(D10,'[1]0801-0804產線配置圖'!$A$2:$C$17,2,0) -> 18 | F10: =VLOOKUP(D10,'[1]0801-0804產線配置圖'!$A$2:$C$17,3,0) -> 1565 | G10: =F10/E10 -> 86.944444 | I10: =AVERAGE(P10,U10,Z10,AE10,AJ10,AO10,AT10) -> 14.75 | J10: =AVERAGE(Q10,V10,AA10,AF10,AK10,AP10,AU10) -> 1534.75 | K10: =AVERAGE(AG10,AL10,AQ10,AV10) -> 104.69643 | M10: =RANK(K10, K$7:$K$21) -> 6 | R10: =Q10/P10 -> #DIV/0! | S10: =RANK(R10, R$7:R$21) -> #DIV/0! | W10: =V10/U10 -> #DIV/0! | X10: =RANK(W10, W$7:W$21) -> #DIV/0! | AB10: =AA10/Z10 -> #DIV/0! | AC10: =RANK(AB10, AB$7:AB$21) -> #DIV/0! | AE10: 14 | AF10: 1581 | AG10: =AF10/AE10 -> 112.92857 | AH10: =RANK(AG10, AG$7:AG$21) -> 7 | AJ10: 14 | AK10: 1414 | AL10: =AK10/AJ10 -> 101 | AM10: =RANK(AL10, AL$7:AL$21) -> 5 | AO10: 14 | AP10: 1580 | AQ10: =AP10/AO10 -> 112.85714 | AR10: =RANK(AQ10, AQ$7:AQ$21) -> 5 | AT10: 17 | AU10: 1564 | AV10: =AU10/AT10 -> 92 | AW10: =RANK(AV10, AV$7:AV$21) -> 6
C11: 5 | D11: 白酒蛤蜊義大利麵 | E11: =VLOOKUP(D11,'[1]0801-0804產線配置圖'!$A$2:$C$17,2,0) -> 14 | F11: =VLOOKUP(D11,'[1]0801-0804產線配置圖'!$A$2:$C$17,3,0) -> 1714 | G11: =F11/E11 -> 122.42857 | I11: =AVERAGE(P11,U11,Z11,AE11,AJ11,AO11,AT11) -> 13 | J11: =AVERAGE(Q11,V11,AA11,AF11,AK11,AP11,AU11) -> 1643.25 | K11: =AVERAGE(AG11,AL11,AQ11,AV11) -> 127.46772 | M11: =RANK(K11, K$7:$K$21) -> 3 | R11: =Q11/P11 -> #DIV/0! | S11: =RANK(R11, R$7:R$21) -> #DIV/0! | W11: =V11/U11 -> #DIV/0! | X11: =RANK(W11, W$7:W$21) -> #DIV/0! | AB11: =AA11/Z11 -> #DIV/0! | AC11: =RANK(AB11, AB$7:AB$21) -> #DIV/0! | AE11: 13 | AF11: 1857 | AG11: =AF11/AE11 -> 142.84615 | AH11: =RANK(AG11, AG$7:AG$21) -> 2 | AJ11: 12 | AK11: 1677 | AL11: =AK11/AJ11 -> 139.75 | AM11: =RANK(AL11, AL$7:AL$21) -> 2 | AO11: 13 | AP11: 1857 | AQ11: =AP11/AO11 -> 142.84615 | AR11: =RANK(AQ11, AQ$7:AQ$21) -> 1 | AT11: 14 | AU11: 1182 | AV11: =AU11/AT11 -> 84.428571 | AW11: =RANK(AV11, AV$7:AV$21) -> 8
C12: 6 | D12: 韓式炸雞義大利麵 | E12: =VLOOKUP(D12,'[1]0801-0804產線配置圖'!$A$2:$C$17,2,0) -> 16 | F12: =VLOOKUP(D12,'[1]0801-0804產線配置圖'!$A$2:$C$17,3,0) -> 1818 | G12: =F12/E12 -> 113.625 | I12: =AVERAGE(P12,U12,Z12,AE12,AJ12,AO12,AT12) -> 14.25 | J12: =AVERAGE(Q12,V12,AA12,AF12,AK12,AP12,AU12) -> 1695.25 | K12: =AVERAGE(AG12,AL12,AQ12,AV12) -> 118.85112 | M12: =RANK(K12, K$7:$K$21) -> 5 | R12: =Q12/P12 -> #DIV/0! | S12: =RANK(R12, R$7:R$21) -> #DIV/0! | W12: =V12/U12 -> #DIV/0! | X12: =RANK(W12, W$7:W$21) -> #DIV/0! | AB12: =AA12/Z12 -> #DIV/0! | AC12: =RANK(AB12, AB$7:AB$21) -> #DIV/0! | AE12: 13 | AF12: 1507 | AG12: =AF12/AE12 -> 115.92308 | AH12: =RANK(AG12, AG$7:AG$21) -> 6 | AJ12: 16 | AK12: 1818 | AL12: =AK12/AJ12 -> 113.625 | AM12: =RANK(AL12, AL$7:AL$21) -> 4 | AO12: 13 | AP12: 1507 | AQ12: =AP12/AO12 -> 115.92308 | AR12: =RANK(AQ12, AQ$7:AQ$21) -> 4 | AT12: 15 | AU12: 1949 | AV12: =AU12/AT12 -> 129.93333 | AW12: =RANK(AV12, AV$7:AV$21) -> 3
C13: 7 | D13: 蒜香蝦蝦義大利麵 | E13: =VLOOKUP(D13,'[1]0801-0804產線配置圖'!$A$2:$C$17,2,0) -> 16 | F13: =VLOOKUP(D13,'[1]0801-0804產線配置圖'!$A$2:$C$17,3,0) -> 1552 | G13: =F13/E13 -> 97 | I13: =AVERAGE(P13,U13,Z13,AE13,AJ13,AO13,AT13) -> 12.25 | J13: =AVERAGE(Q13,V13,AA13,AF13,AK13,AP13,AU13) -> 1061.25 | K13: =AVERAGE(AG13,AL13,AQ13,AV13) -> 87.055195 | M13: =RANK(K13, K$7:$K$21) -> 10 | R13: =Q13/P13 -> #DIV/0! | S13: =RANK(R13, R$7:R$21) -> #DIV/0! | W13: =V13/U13 -> #DIV/0! | X13: =RANK(W13, W$7:W$21) -> #DIV/0! | AB13: =AA13/Z13 -> #DIV/0! | AC13: =RANK(AB13, AB$7:AB$21) -> #DIV/0! | AE13: 12 | AF13: 1068 | AG13: =AF13/AE13 -> 89 | AH13: =RANK(AG13, AG$7:AG$21) -> 10 | AJ13: 11 | AK13: 1005 | AL13: =AK13/AJ13 -> 91.363636 | AM13: =RANK(AL13, AL$7:AL$21) -> 9 | AO13: 12 | AP13: 1068 | AQ13: =AP13/AO13 -> 89 | AR13: =RANK(AQ13, AQ$7:AQ$21) -> 9 | AT13: 14 | AU13: 1104 | AV13: =AU13/AT13 -> 78.857143 | AW13: =RANK(AV13, AV$7:AV$21) -> 9
C14: 8 | D14: 焗奶油扇貝筆尖麵 | E14: =VLOOKUP(D14,'[1]0801-0804產線配置圖'!$A$2:$C$17,2,0) -> 17 | F14: =VLOOKUP(D14,'[1]0801-0804產線配置圖'!$A$2:$C$17,3,0) -> 1565 | G14: =F14/E14 -> 92.058824 | I14: =AVERAGE(P14,U14,Z14,AE14,AJ14,AO14,AT14) -> 14.75 | J14: =AVERAGE(Q14,V14,AA14,AF14,AK14,AP14,AU14) -> 1369.5 | K14: =AVERAGE(AG14,AL14,AQ14,AV14) -> 92.684874 | M14: =RANK(K14, K$7:$K$21) -> 8 | R14: =Q14/P14 -> #DIV/0! | S14: =RANK(R14, R$7:R$21) -> #DIV/0! | W14: =V14/U14 -> #DIV/0! | X14: =RANK(W14, W$7:W$21) -> #DIV/0! | AB14: =AA14/Z14 -> #DIV/0! | AC14: =RANK(AB14, AB$7:AB$21) -> #DIV/0! | AE14: 14 | AF14: 1274 | AG14: =AF14/AE14 -> 91 | AH14: =RANK(AG14, AG$7:AG$21) -> 9 | AJ14: 14 | AK14: 1300 | AL14: =AK14/AJ14 -> 92.857143 | AM14: =RANK(AL14, AL$7:AL$21) -> 8 | AO14: 14 | AP14: 1274 | AQ14: =AP14/AO14 -> 91 | AR14: =RANK(AQ14, AQ$7:AQ$21) -> 8 | AT14: 17 | AU14: 1630 | AV14: =AU14/AT14 -> 95.882353 | AW14: =RANK(AV14, AV$7:AV$21) -> 5
C15: 9 | D15: 拿坡里義大利麵 | E15: =VLOOKUP(D15,'[1]0801-0804產線配置圖'!$A$2:$C$17,2,0) -> 16 | F15: =VLOOKUP(D15,'[1]0801-0804產線配置圖'!$A$2:$C$17,3,0) -> 1390 | G15: =F15/E15 -> 86.875 | I15: =AVERAGE(P15,U15,Z15,AE15,AJ15,AO15,AT15) -> 16 | J15: =AVERAGE(Q15,V15,AA15,AF15,AK15,AP15,AU15) -> 1040.75 | K15: =AVERAGE(AG15,AL15,AQ15,AV15) -> 65.046875 | M15: =RANK(K15, K$7:$K$21) -> 14 | R15: =Q15/P15 -> #DIV/0! | S15: =RANK(R15, R$7:R$21) -> #DIV/0! | W15: =V15/U15 -> #DIV/0! | X15: =RANK(W15, W$7:W$21) -> #DIV/0! | AB15: =AA15/Z15 -> #DIV/0! | AC15: =RANK(AB15, AB$7:AB$21) -> #DIV/0! | AE15: 16 | AF15: 1001 | AG15: =AF15/AE15 -> 62.5625 | AH15: =RANK(AG15, AG$7:AG$21) -> 13 | AJ15: 16 | AK15: 1276 | AL15: =AK15/AJ15 -> 79.75 | AM15: =RANK(AL15, AL$7:AL$21) -> 10 | AO15: 16 | AP15: 1001 | AQ15: =AP15/AO15 -> 62.5625 | AR15: =RANK(AQ15, AQ$7:AQ$21) -> 13 | AT15: 16 | AU15: 885 | AV15: =AU15/AT15 -> 55.3125 | AW15: =RANK(AV15, AV$7:AV$21) -> 13
C16: 10 | D16: 奶油明太子細扁麵 | E16: =VLOOKUP(D16,'[1]0801-0804產線配置圖'!$A$2:$C$17,2,0) -> 18 | F16: =VLOOKUP(D16,'[1]0801-0804產線配置圖'!$A$2:$C$17,3,0) -> 1565 | G16: =F16/E16 -> 86.944444 | I16: =AVERAGE(P16,U16,Z16,AE16,AJ16,AO16,AT16) -> 15.75 | J16: =AVERAGE(Q16,V16,AA16,AF16,AK16,AP16,AU16) -> 1279.25 | K16: =AVERAGE(AG16,AL16,AQ16,AV16) -> 81.663889 | M16: =RANK(K16, K$7:$K$21) -> 11 | R16: =Q16/P16 -> #DIV/0! | S16: =RANK(R16, R$7:R$21) -> #DIV/0! | W16: =V16/U16 -> #DIV/0! | X16: =RANK(W16, W$7:W$21) -> #DIV/0! | AB16: =AA16/Z16 -> #DIV/0! | AC16: =RANK(AB16, AB$7:AB$21) -> #DIV/0! | AE16: 15 | AF16: 1873 | AG16: =AF16/AE16 -> 124.86667 | AH16: =RANK(AG16, AG$7:AG$21) -> 4 | AJ16: 15 | AK16: 1005 | AL16: =AK16/AJ16 -> 67 | AM16: =RANK(AL16, AL$7:AL$21) -> 13 | AO16: 15 | AP16: 936 | AQ16: =AP16/AO16 -> 62.4 | AR16: =RANK(AQ16, AQ$7:AQ$21) -> 14 | AT16: 18 | AU16: 1303 | AV16: =AU16/AT16 -> 72.388889 | AW16: =RANK(AV16, AV$7:AV$21) -> 11
C17: 11 | D17: 黑胡椒燻豬腿義大利麵 | E17: =VLOOKUP(D17,'[1]0801-0804產線配置圖'!$A$2:$C$17,2,0) -> 18 | F17: =VLOOKUP(D17,'[1]0801-0804產線配置圖'!$A$2:$C$17,3,0) -> 1500 | G17: =F17/E17 -> 83.333333 | I17: =AVERAGE(P17,U17,Z17,AE17,AJ17,AO17,AT17) -> 10.75 | J17: =AVERAGE(Q17,V17,AA17,AF17,AK17,AP17,AU17) -> 1271 | K17: =AVERAGE(AG17,AL17,AQ17,AV17) -> 120.30152 | M17: =RANK(K17, K$7:$K$21) -> 4 | R17: =Q17/P17 -> #DIV/0! | S17: =RANK(R17, R$7:R$21) -> #DIV/0! | W17: =V17/U17 -> #DIV/0! | X17: =RANK(W17, W$7:W$21) -> #DIV/0! | AB17: =AA17/Z17 -> #DIV/0! | AC17: =RANK(AB17, AB$7:AB$21) -> #DIV/0! | AE17: 10 | AF17: 1946 | AG17: =AF17/AE17 -> 194.6 | AH17: =RANK(AG17, AG$7:AG$21) -> 1 | AJ17: 11 | AK17: 1103 | AL17: =AK17/AJ17 -> 100.27273 | AM17: =RANK(AL17, AL$7:AL$21) -> 6 | AO17: 10 | AP17: 1005 | AQ17: =AP17/AO17 -> 100.5 | AR17: =RANK(AQ17, AQ$7:AQ$21) -> 6 | AT17: 12 | AU17: 1030 | AV17: =AU17/AT17 -> 85.833333 | AW17: =RANK(AV17, AV$7:AV$21) -> 7
C18: 12 | D18: 卡曼橘油醋冷義大利麵 | E18: =VLOOKUP(D18,'[1]0801-0804產線配置圖'!$A$2:$C$17,2,0) -> 16 | F18: =VLOOKUP(D18,'[1]0801-0804產線配置圖'!$A$2:$C$17,3,0) -> 1636 | G18: =F18/E18 -> 102.25 | I18: =AVERAGE(P18,U18,Z18,AE18,AJ18,AO18,AT18) -> 16 | J18: =AVERAGE(Q18,V18,AA18,AF18,AK18,AP18,AU18) -> 1412.3333 | K18: =AVERAGE(AG18,AL18,AQ18,AV18) -> 88.270833 | M18: =RANK(K18, K$7:$K$21) -> 9 | R18: =Q18/P18 -> #DIV/0! | S18: =RANK(R18, R$7:R$21) -> #DIV/0! | W18: =V18/U18 -> #DIV/0! | X18: =RANK(W18, W$7:W$21) -> #DIV/0! | AB18: =AA18/Z18 -> #DIV/0! | AC18: =RANK(AB18, AB$7:AB$21) -> #DIV/0! | AE18: 16 | AF18: 1485 | AG18: =AF18/AE18 -> 92.8125 | AH18: =RANK(AG18, AG$7:AG$21) -> 8 | AJ18: 16 | AK18: 1267 | AL18: =AK18/AJ18 -> 79.1875 | AM18: =RANK(AL18, AL$7:AL$21) -> 11 | AO18: 16 | AP18: 1485 | AQ18: =AP18/AO18 -> 92.8125 | AR18: =RANK(AQ18, AQ$7:AQ$21) -> 7
C19: 13 | D19: 奶油蒜香雞義大利麵 | E19: =VLOOKUP(D19,'[1]0801-0804產線配置圖'!$A$2:$C$17,2,0) -> 18 | F19: =VLOOKUP(D19,'[1]0801-0804產線配置圖'!$A$2:$C$17,3,0) -> 1200 | G19: =F19/E19 -> 66.666667 | I19: =AVERAGE(P19,U19,Z19,AE19,AJ19,AO19,AT19) -> 16.75 | J19: =AVERAGE(Q19,V19,AA19,AF19,AK19,AP19,AU19) -> 1101 | K19: =AVERAGE(AG19,AL19,AQ19,AV19) -> 65.72201 | M19: =RANK(K19, K$7:$K$21) -> 13 | R19: =Q19/P19 -> #DIV/0! | S19: =RANK(R19, R$7:R$21) -> #DIV/0! | W19: =V19/U19 -> #DIV/0! | X19: =RANK(W19, W$7:W$21) -> #DIV/0! | AB19: =AA19/Z19 -> #DIV/0! | AC19: =RANK(AB19, AB$7:AB$21) -> #DIV/0! | AE19: 17 | AF19: 1022 | AG19: =AF19/AE19 -> 60.117647 | AH19: =RANK(AG19, AG$7:AG$21) -> 14 | AJ19: 15 | AK19: 1047 | AL19: =AK19/AJ19 -> 69.8 | AM19: =RANK(AL19, AL$7:AL$21) -> 12 | AO19: 16 | AP19: 1021 | AQ19: =AP19/AO19 -> 63.8125 | AR19: =RANK(AQ19, AQ$7:AQ$21) -> 12 | AT19: 19 | AU19: 1314 | AV19: =AU19/AT19 -> 69.157895 | AW19: =RANK(AV19, AV$7:AV$21) -> 12
C20: 14 | D20: 蕃茄莎莎鮪魚冷義大利麵 | E20: =VLOOKUP(D20,'[1]0801-0804產線配置圖'!$A$2:$C$17,2,0) -> 17 | F20: =VLOOKUP(D20,'[1]0801-0804產線配置圖'!$A$2:$C$17,3,0) -> 1333 | G20: =F20/E20 -> 78.411765 | I20: =AVERAGE(P20,U20,Z20,AE20,AJ20,AO20,AT20) -> 16 | J20: =AVERAGE(Q20,V20,AA20,AF20,AK20,AP20,AU20) -> 1239.5 | K20: =AVERAGE(AG20,AL20,AQ20,AV20) -> 77.46875 | M20: =RANK(K20, K$7:$K$21) -> 12 | R20: =Q20/P20 -> #DIV/0! | S20: =RANK(R20, R$7:R$21) -> #DIV/0! | W20: =V20/U20 -> #DIV/0! | X20: =RANK(W20, W$7:W$21) -> #DIV/0! | AB20: =AA20/Z20 -> #DIV/0! | AC20: =RANK(AB20, AB$7:AB$21) -> #DIV/0! | AE20: 16 | AF20: 1332 | AG20: =AF20/AE20 -> 83.25 | AH20: =RANK(AG20, AG$7:AG$21) -> 12 | AJ20: 16 | AK20: 1043 | AL20: =AK20/AJ20 -> 65.1875 | AM20: =RANK(AL20, AL$7:AL$21) -> 14 | AO20: 16 | AP20: 1332 | AQ20: =AP20/AO20 -> 83.25 | AR20: =RANK(AQ20, AQ$7:AQ$21) -> 11 | AT20: 16 | AU20: 1251 | AV20: =AU20/AT20 -> 78.1875 | AW20: =RANK(AV20, AV$7:AV$21) -> 10
C21: 15 | I21: =AVERAGE(P21,U21,Z21,AE21,AJ21,AO21,AT21) -> #DIV/0! | J21: =AVERAGE(Q21,V21,AA21,AF21,AK21,AP21,AU21) -> #DIV/0! | M21: =RANK(K21, K$7:$K$21) -> #N/A | R21: =Q21/P21 -> #DIV/0! | S21: =RANK(R21, R$7:R$21) -> #DIV/0! | W21: =V21/U21 -> #DIV/0! | X21: =RANK(W21, W$7:W$21) -> #DIV/0! | AB21: =AA21/Z21 -> #DIV/0! | AC21: =RANK(AB21, AB$7:AB$21) -> #DIV/0! | AR21: =RANK(AQ21, AQ$7:AQ$21) -> #N/A
B22: 產線配置圖－每週更新 | N22: 資料繳交 | O22: 日期 | P22: 45874 | U22: 45875 | Z22: 45876 | AE22: 45877 | AJ22: 45878 | AO22: 45879 | AT22: 45880
P23: 二 | U23: 三 | Z23: 四 | AE23: 五 | AJ23: 六 | AO23: 日 | AT23: 一
B24: 品群 | C24: 商品名稱 | E24: 計畫 | H24: 平均人時性 | I24: 實績 | L24: 平均人時性 | M24: 排名 | O24: 日報 | P24: 實際 | T24: 平均人時性 | U24: 實際 | Y24: 平均人時性 | Z24: 實際 | AD24: 平均人時性 | AE24: 實際 | AI24: 平均人時性 | AJ24: 實際 | AN24: 平均人時性 | AO24: 實際 | AS24: 平均人時性 | AT24: 實際 | AX24: 平均人時性
E25: 產線配置圖 | I25: 產線配置圖 | P25: 生產實績 | U25: 生產實績 | Z25: 生產實績 | AE25: 生產實績 | AJ25: 生產實績 | AO25: 生產實績 | AT25: 生產實績
E26: 人數 | F26: 產能／時 | G26: 人時性 | I26: 人數 | J26: 產能／時 | K26: 人時性 | P26: 人數 | Q26: 產能／時 | R26: 人時性 | S26: 排名 | U26: 人數 | V26: 產能／時 | W26: 人時性 | X26: 排名 | Z26: 人數 | AA26: 產能／時 | AB26: 人時性 | AC26: 排名 | AE26: 人數 | AF26: 產能／時 | AG26: 人時性 | AH26: 排名 | AJ26: 人數 | AK26: 產能／時 | AL26: 人時性 | AM26: 排名 | AO26: 人數 | AP26: 產能／時 | AQ26: 人時性 | AR26: 排名 | AT26: 人數 | AU26: 產能／時 | AV26: 人時性 | AW26: 排名
B27: 熱食義麵 | C27: 1 | D27: 義式蕃茄起司義大利麵 | E27: =VLOOKUP(D27,'[1]0805產線配置圖'!$A$2:$C$17,2,0) -> 12 | F27: =VLOOKUP(D27,'[1]0805產線配置圖'!$A$2:$C$17,3,0) -> 2000 | G27: =F27/E27 -> 166.66667 | H27: =AVERAGE(G27:G41) -> 102.10435 | I27: =AVERAGE(P27,U27,Z27,AE27,AJ27,AO27,AT27) -> 12 | J27: =AVERAGE(Q27,V27,AA27,AF27,AK27,AP27,AU27) -> 1769.7143 | K27: =AVERAGE(R27,W27,AB27,AG27,AL27,AQ27,AV27) -> 147.47619 | L27: =IFERROR(AVERAGE(K27:K41),"-") -> 93.59343 | M27: =RANK(K27, K$27:$K$41) -> 1 | P27: 12 | Q27: 1889 | R27: =Q27/P27 -> 157.41667 | S27: =RANK(R27,$R$27:$R$41) -> 1 | T27: =AVERAGE(R27:R41) -> 93.344014 | U27: 12 | V27: 1702 | W27: =V27/U27 -> 141.83333 | X27: =RANK(W27, $W$27:$W$41) -> 1 | Y27: =AVERAGE(W27:W41) -> 91.861797 | Z27: 12 | AA27: 1820 | AB27: =AA27/Z27 -> 151.66667 | AC27: =RANK(AB27, $AB$27:$AB$40) -> 1 | AD27: =AVERAGE(AB27:AB41) -> 94.63309 | AE27: 12 | AF27: 1816 | AG27: =AF27/AE27 -> 151.33333 | AH27: =RANK(AG27, $AG$27:$AG$40) -> 1 | AI27: =AVERAGE(AG27:AG41) -> 93.173344 | AJ27: 12 | AK27: 1584 | AL27: =AK27/AJ27 -> 132 | AM27: =RANK(AL27, $AL$27:$AL$40) -> 1 | AN27: =AVERAGE(AL27:AL41) -> 89.787954 | AO27: 12 | AP27: 1787 | AQ27: =AP27/AO27 -> 148.91667 | AR27: =RANK(AQ27,$AQ$27:$AQ$40) -> 1 | AS27: =AVERAGE(AQ27:AQ41) -> 98.8924 | AT27: 12 | AU27: 1790 | AV27: =AU27/AT27 -> 149.16667 | AW27: =RANK(AV27, $AV$27:$AV$40) -> 1 | AX27: =AVERAGE(AV27:AV41) -> 93.461412
C28: 2 | D28: 奶油培根義大利麵 | E28: =VLOOKUP(D28,'[1]0805產線配置圖'!$A$2:$C$17,2,0) -> 13 | F28: =VLOOKUP(D28,'[1]0805產線配置圖'!$A$2:$C$17,3,0) -> 2000 | G28: =F28/E28 -> 153.84615 | I28: =AVERAGE(P28,U28,Z28,AE28,AJ28,AO28,AT28) -> 13 | J28: =AVERAGE(Q28,V28,AA28,AF28,AK28,AP28,AU28) -> 1797.1429 | K28: =AVERAGE(R28,W28,AB28,AG28,AL28,AQ28,AV28) -> 138.24176 | M28: =RANK(K28, K$27:$K$41) -> 2 | P28: 13 | Q28: 1777 | R28: =Q28/P28 -> 136.69231 | S28: =RANK(R28,$R$27:$R$41) -> 2 | U28: 13 | V28: 1758 | W28: =V28/U28 -> 135.23077 | X28: =RANK(W28, $W$27:$W$41) -> 2 | Z28: 13 | AA28: 1800 | AB28: =AA28/Z28 -> 138.46154 | AC28: =RANK(AB28, $AB$27:$AB$40) -> 2 | AE28: 13 | AF28: 1868 | AG28: =AF28/AE28 -> 143.69231 | AH28: =RANK(AG28, $AG$27:$AG$40) -> 2 | AJ28: 13 | AK28: 1690 | AL28: =AK28/AJ28 -> 130 | AM28: =RANK(AL28, $AL$27:$AL$40) -> 2 | AO28: 13 | AP28: 1812 | AQ28: =AP28/AO28 -> 139.38462 | AR28: =RANK(AQ28,$AQ$27:$AQ$40) -> 2 | AT28: 13 | AU28: 1875 | AV28: =AU28/AT28 -> 144.23077 | AW28: =RANK(AV28, $AV$27:$AV$40) -> 2
C29: 3 | D29: 熱那亞青醬義大利麵 | E29: =VLOOKUP(D29,'[1]0805產線配置圖'!$A$2:$C$17,2,0) -> 16 | F29: =VLOOKUP(D29,'[1]0805產線配置圖'!$A$2:$C$17,3,0) -> 1915 | G29: =F29/E29 -> 119.6875 | I29: =AVERAGE(P29,U29,Z29,AE29,AJ29,AO29,AT29) -> 15.857143 | J29: =AVERAGE(Q29,V29,AA29,AF29,AK29,AP29,AU29) -> 1565.2857 | K29: =AVERAGE(R29,W29,AB29,AG29,AL29,AQ29,AV29) -> 98.691667 | M29: =RANK(K29, K$27:$K$41) -> 4 | P29: 16 | Q29: 1679 | R29: =Q29/P29 -> 104.9375 | S29: =RANK(R29,$R$27:$R$41) -> 3 | U29: 16 | V29: 1645 | W29: =V29/U29 -> 102.8125 | X29: =RANK(W29, $W$27:$W$41) -> 4 | Z29: 16 | AA29: 1536 | AB29: =AA29/Z29 -> 96 | AC29: =RANK(AB29, $AB$27:$AB$40) -> 5 | AE29: 15 | AF29: 1516 | AG29: =AF29/AE29 -> 101.06667 | AH29: =RANK(AG29, $AG$27:$AG$40) -> 3 | AJ29: 15 | AK29: 1341 | AL29: =AK29/AJ29 -> 89.4 | AM29: =RANK(AL29, $AL$27:$AL$40) -> 6 | AO29: 16 | AP29: 1642 | AQ29: =AP29/AO29 -> 102.625 | AR29: =RANK(AQ29,$AQ$27:$AQ$40) -> 5 | AT29: 17 | AU29: 1598 | AV29: =AU29/AT29 -> 94 | AW29: =RANK(AV29, $AV$27:$AV$40) -> 6
C30: 4 | D30: 焗烤起司雙饗筆尖麵 | E30: =VLOOKUP(D30,'[1]0805產線配置圖'!$A$2:$C$17,2,0) -> 18 | F30: =VLOOKUP(D30,'[1]0805產線配置圖'!$A$2:$C$17,3,0) -> 1565 | G30: =F30/E30 -> 86.944444 | I30: =AVERAGE(P30,U30,Z30,AE30,AJ30,AO30,AT30) -> 17.285714 | J30: =AVERAGE(Q30,V30,AA30,AF30,AK30,AP30,AU30) -> 1564 | K30: =AVERAGE(R30,W30,AB30,AG30,AL30,AQ30,AV30) -> 90.55007 | M30: =RANK(K30, K$27:$K$41) -> 8 | P30: 18 | Q30: 1626 | R30: =Q30/P30 -> 90.333333 | S30: =RANK(R30,$R$27:$R$41) -> 7 | U30: 17 | V30: 1535 | W30: =V30/U30 -> 90.294118 | X30: =RANK(W30, $W$27:$W$41) -> 7 | Z30: 18 | AA30: 1614 | AB30: =AA30/Z30 -> 89.666667 | AC30: =RANK(AB30, $AB$27:$AB$40) -> 9 | AE30: 17 | AF30: 1616 | AG30: =AF30/AE30 -> 95.058824 | AH30: =RANK(AG30, $AG$27:$AG$40) -> 6 | AJ30: 17 | AK30: 1508 | AL30: =AK30/AJ30 -> 88.705882 | AM30: =RANK(AL30, $AL$27:$AL$40) -> 8 | AO30: 16 | AP30: 1498 | AQ30: =AP30/AO30 -> 93.625 | AR30: =RANK(AQ30,$AQ$27:$AQ$40) -> 8 | AT30: 18 | AU30: 1551 | AV30: =AU30/AT30 -> 86.166667 | AW30: =RANK(AV30, $AV$27:$AV$40) -> 8
C31: 5 | D31: 白酒蛤蜊義大利麵 | E31: =VLOOKUP(D31,'[1]0805產線配置圖'!$A$2:$C$17,2,0) -> 15 | F31: =VLOOKUP(D31,'[1]0805產線配置圖'!$A$2:$C$17,3,0) -> 1565 | G31: =F31/E31 -> 104.33333 | I31: =AVERAGE(P31,U31,Z31,AE31,AJ31,AO31,AT31) -> 12.428571 | J31: =AVERAGE(Q31,V31,AA31,AF31,AK31,AP31,AU31) -> 1209.1429 | K31: =AVERAGE(R31,W31,AB31,AG31,AL31,AQ31,AV31) -> 97.551722 | M31: =RANK(K31, K$27:$K$41) -> 5 | P31: 12 | Q31: 1122 | R31: =Q31/P31 -> 93.5 | S31: =RANK(R31,$R$27:$R$41) -> 6 | U31: 14 | V31: 1057 | W31: =V31/U31 -> 75.5 | X31: =RANK(W31, $W$27:$W$41) -> 11 | Z31: 12 | AA31: 1279 | AB31: =AA31/Z31 -> 106.58333 | AC31: =RANK(AB31, $AB$27:$AB$40) -> 3 | AE31: 11 | AF31: 1091 | AG31: =AF31/AE31 -> 99.181818 | AH31: =RANK(AG31, $AG$27:$AG$40) -> 4 | AJ31: 11 | AK31: 1125 | AL31: =AK31/AJ31 -> 102.27273 | AM31: =RANK(AL31, $AL$27:$AL$40) -> 3 | AO31: 13 | AP31: 1190 | AQ31: =AP31/AO31 -> 91.538462 | AR31: =RANK(AQ31,$AQ$27:$AQ$40) -> 9 | AT31: 14 | AU31: 1600 | AV31: =AU31/AT31 -> 114.28571 | AW31: =RANK(AV31, $AV$27:$AV$40) -> 3
C32: 6 | D32: 韓式起司炸雞義大利麵 | E32: =VLOOKUP(D32,'[1]0805產線配置圖'!$A$2:$C$17,2,0) -> 17 | F32: =VLOOKUP(D32,'[1]0805產線配置圖'!$A$2:$C$17,3,0) -> 1895 | G32: =F32/E32 -> 111.47059 | I32: =AVERAGE(P32,U32,Z32,AE32,AJ32,AO32,AT32) -> 15.857143 | J32: =AVERAGE(Q32,V32,AA32,AF32,AK32,AP32,AU32) -> 1626.7143 | K32: =AVERAGE(R32,W32,AB32,AG32,AL32,AQ32,AV32) -> 102.47237 | M32: =RANK(K32, K$27:$K$41) -> 3 | P32: 17 | Q32: 1756 | R32: =Q32/P32 -> 103.29412 | S32: =RANK(R32,$R$27:$R$41) -> 4 | U32: 16 | V32: 1680 | W32: =V32/U32 -> 105 | X32: =RANK(W32, $W$27:$W$41) -> 3 | Z32: 16 | AA32: 1636 | AB32: =AA32/Z32 -> 102.25 | AC32: =RANK(AB32, $AB$27:$AB$40) -> 4 | AE32: 15 | AF32: 1434 | AG32: =AF32/AE32 -> 95.6 | AH32: =RANK(AG32, $AG$27:$AG$40) -> 5 | AJ32: 15 | AK32: 1464 | AL32: =AK32/AJ32 -> 97.6 | AM32: =RANK(AL32, $AL$27:$AL$40) -> 4 | AO32: 16 | AP32: 1895 | AQ32: =AP32/AO32 -> 118.4375 | AR32: =RANK(AQ32,$AQ$27:$AQ$40) -> 3 | AT32: 16 | AU32: 1522 | AV32: =AU32/AT32 -> 95.125 | AW32: =RANK(AV32, $AV$27:$AV$40) -> 5
C33: 7 | D33: 蒜香蝦蝦義大利麵 | E33: =VLOOKUP(D33,'[1]0805產線配置圖'!$A$2:$C$17,2,0) -> 16 | F33: =VLOOKUP(D33,'[1]0805產線配置圖'!$A$2:$C$17,3,0) -> 1552 | G33: =F33/E33 -> 97 | I33: =AVERAGE(P33,U33,Z33,AE33,AJ33,AO33,AT33) -> 15.571429 | J33: =AVERAGE(Q33,V33,AA33,AF33,AK33,AP33,AU33) -> 1290.5714 | K33: =AVERAGE(R33,W33,AB33,AG33,AL33,AQ33,AV33) -> 82.677311 | M33: =RANK(K33, K$27:$K$41) -> 9 | P33: 16 | Q33: 1402 | R33: =Q33/P33 -> 87.625 | S33: =RANK(R33,$R$27:$R$41) -> 9 | U33: 16 | V33: 1247 | W33: =V33/U33 -> 77.9375 | X33: =RANK(W33, $W$27:$W$41) -> 10 | Z33: 16 | AA33: 1439 | AB33: =AA33/Z33 -> 89.9375 | AC33: =RANK(AB33, $AB$27:$AB$40) -> 8 | AE33: 17 | AF33: 1444 | AG33: =AF33/AE33 -> 84.941176 | AH33: =RANK(AG33, $AG$27:$AG$40) -> 9 | AJ33: 15 | AK33: 1259 | AL33: =AK33/AJ33 -> 83.933333 | AM33: =RANK(AL33, $AL$27:$AL$40) -> 9 | AO33: 14 | AP33: 1015 | AQ33: =AP33/AO33 -> 72.5 | AR33: =RANK(AQ33,$AQ$27:$AQ$40) -> 13 | AT33: 15 | AU33: 1228 | AV33: =AU33/AT33 -> 81.866667 | AW33: =RANK(AV33, $AV$27:$AV$40) -> 9
C34: 8 | D34: 焗奶油扇貝筆尖麵 | E34: =VLOOKUP(D34,'[1]0805產線配置圖'!$A$2:$C$17,2,0) -> 17 | F34: =VLOOKUP(D34,'[1]0805產線配置圖'!$A$2:$C$17,3,0) -> 1565 | G34: =F34/E34 -> 92.058824 | I34: =AVERAGE(P34,U34,Z34,AE34,AJ34,AO34,AT34) -> 16.571429 | J34: =AVERAGE(Q34,V34,AA34,AF34,AK34,AP34,AU34) -> 1604.2857 | K34: =AVERAGE(R34,W34,AB34,AG34,AL34,AQ34,AV34) -> 96.808824 | M34: =RANK(K34, K$27:$K$41) -> 6 | P34: 17 | Q34: 1655 | R34: =Q34/P34 -> 97.352941 | S34: =RANK(R34,$R$27:$R$41) -> 5 | U34: 16 | V34: 1637 | W34: =V34/U34 -> 102.3125 | X34: =RANK(W34, $W$27:$W$41) -> 5 | Z34: 17 | AA34: 1627 | AB34: =AA34/Z34 -> 95.705882 | AC34: =RANK(AB34, $AB$27:$AB$40) -> 6 | AE34: 17 | AF34: 1576 | AG34: =AF34/AE34 -> 92.705882 | AH34: =RANK(AG34, $AG$27:$AG$40) -> 7 | AJ34: 16 | AK34: 1424 | AL34: =AK34/AJ34 -> 89 | AM34: =RANK(AL34, $AL$27:$AL$40) -> 7 | AO34: 16 | AP34: 1583 | AQ34: =AP34/AO34 -> 98.9375 | AR34: =RANK(AQ34,$AQ$27:$AQ$40) -> 6 | AT34: 17 | AU34: 1728 | AV34: =AU34/AT34 -> 101.64706 | AW34: =RANK(AV34, $AV$27:$AV$40) -> 4
C35: 9 | D35: 拿坡里義大利麵 | E35: =VLOOKUP(D35,'[1]0805產線配置圖'!$A$2:$C$17,2,0) -> 16 | F35: =VLOOKUP(D35,'[1]0805產線配置圖'!$A$2:$C$17,3,0) -> 1390 | G35: =F35/E35 -> 86.875 | I35: =AVERAGE(P35,U35,Z35,AE35,AJ35,AO35,AT35) -> 14.142857 | J35: =AVERAGE(Q35,V35,AA35,AF35,AK35,AP35,AU35) -> 812.71429 | K35: =AVERAGE(R35,W35,AB35,AG35,AL35,AQ35,AV35) -> 57.427734 | M35: =RANK(K35, K$27:$K$41) -> 14 | P35: 14 | Q35: 747 | R35: =Q35/P35 -> 53.357143 | S35: =RANK(R35,$R$27:$R$41) -> 14 | U35: 15 | V35: 918 | W35: =V35/U35 -> 61.2 | X35: =RANK(W35, $W$27:$W$41) -> 14 | Z35: 15 | AA35: 829 | AB35: =AA35/Z35 -> 55.266667 | AC35: =RANK(AB35, $AB$27:$AB$40) -> 14 | AE35: 14 | AF35: 819 | AG35: =AF35/AE35 -> 58.5 | AH35: =RANK(AG35, $AG$27:$AG$40) -> 14 | AJ35: 13 | AK35: 720 | AL35: =AK35/AJ35 -> 55.384615 | AM35: =RANK(AL35, $AL$27:$AL$40) -> 14 | AO35: 14 | AP35: 743 | AQ35: =AP35/AO35 -> 53.071429 | AR35: =RANK(AQ35,$AQ$27:$AQ$40) -> 14 | AT35: 14 | AU35: 913 | AV35: =AU35/AT35 -> 65.214286 | AW35: =RANK(AV35, $AV$27:$AV$40) -> 13
C36: 10 | D36: 奶油明太子細扁麵 | E36: =VLOOKUP(D36,'[1]0805產線配置圖'!$A$2:$C$17,2,0) -> 18 | F36: =VLOOKUP(D36,'[1]0805產線配置圖'!$A$2:$C$17,3,0) -> 1565 | G36: =F36/E36 -> 86.944444 | I36: =AVERAGE(P36,U36,Z36,AE36,AJ36,AO36,AT36) -> 17.142857 | J36: =AVERAGE(Q36,V36,AA36,AF36,AK36,AP36,AU36) -> 1322.2857 | K36: =AVERAGE(R36,W36,AB36,AG36,AL36,AQ36,AV36) -> 77.965221 | M36: =RANK(K36, K$27:$K$41) -> 10 | P36: 18 | Q36: 1265 | R36: =Q36/P36 -> 70.277778 | S36: =RANK(R36,$R$27:$R$41) -> 11 | U36: 18 | V36: 1413 | W36: =V36/U36 -> 78.5 | X36: =RANK(W36, $W$27:$W$41) -> 9 | Z36: 20 | AA36: 1399 | AB36: =AA36/Z36 -> 69.95 | AC36: =RANK(AB36, $AB$27:$AB$40) -> 13 | AE36: 16 | AF36: 1177 | AG36: =AF36/AE36 -> 73.5625 | AH36: =RANK(AG36, $AG$27:$AG$40) -> 11 | AJ36: 16 | AK36: 1178 | AL36: =AK36/AJ36 -> 73.625 | AM36: =RANK(AL36, $AL$27:$AL$40) -> 11 | AO36: 14 | AP36: 1446 | AQ36: =AP36/AO36 -> 103.28571 | AR36: =RANK(AQ36,$AQ$27:$AQ$40) -> 4 | AT36: 18 | AU36: 1378 | AV36: =AU36/AT36 -> 76.555556 | AW36: =RANK(AV36, $AV$27:$AV$40) -> 11
C37: 11 | D37: 黑胡椒燻豬腿義大利麵 | E37: =VLOOKUP(D37,'[1]0805產線配置圖'!$A$2:$C$17,2,0) -> 18 | F37: =VLOOKUP(D37,'[1]0805產線配置圖'!$A$2:$C$17,3,0) -> 1500 | G37: =F37/E37 -> 83.333333 | I37: =AVERAGE(P37,U37,Z37,AE37,AJ37,AO37,AT37) -> 18 | J37: =AVERAGE(Q37,V37,AA37,AF37,AK37,AP37,AU37) -> 1380.1429 | K37: =AVERAGE(R37,W37,AB37,AG37,AL37,AQ37,AV37) -> 76.869328 | M37: =RANK(K37, K$27:$K$41) -> 12 | P37: 18 | Q37: 1249 | R37: =Q37/P37 -> 69.388889 | S37: =RANK(R37,$R$27:$R$41) -> 12 | U37: 18 | V37: 1208 | W37: =V37/U37 -> 67.111111 | X37: =RANK(W37, $W$27:$W$41) -> 13 | Z37: 20 | AA37: 1477 | AB37: =AA37/Z37 -> 73.85 | AC37: =RANK(AB37, $AB$27:$AB$40) -> 12 | AE37: 17 | AF37: 1402 | AG37: =AF37/AE37 -> 82.470588 | AH37: =RANK(AG37, $AG$27:$AG$40) -> 10 | AJ37: 18 | AK37: 1226 | AL37: =AK37/AJ37 -> 68.111111 | AM37: =RANK(AL37, $AL$27:$AL$40) -> 13 | AO37: 17 | AP37: 1526 | AQ37: =AP37/AO37 -> 89.764706 | AR37: =RANK(AQ37,$AQ$27:$AQ$40) -> 11 | AT37: 18 | AU37: 1573 | AV37: =AU37/AT37 -> 87.388889 | AW37: =RANK(AV37, $AV$27:$AV$40) -> 7
C38: 12 | D38: 泰式海鮮冷義大利麵 | E38: =VLOOKUP(D38,'[1]0805產線配置圖'!$A$2:$C$17,2,0) -> 18 | F38: =VLOOKUP(D38,'[1]0805產線配置圖'!$A$2:$C$17,3,0) -> 1714 | G38: =F38/E38 -> 95.222222 | I38: =AVERAGE(P38,U38,Z38,AE38,AJ38,AO38,AT38) -> 16.714286 | J38: =AVERAGE(Q38,V38,AA38,AF38,AK38,AP38,AU38) -> 1514.4286 | K38: =AVERAGE(R38,W38,AB38,AG38,AL38,AQ38,AV38) -> 90.553466 | M38: =RANK(K38, K$27:$K$41) -> 7 | P38: 18 | Q38: 1622 | R38: =Q38/P38 -> 90.111111 | S38: =RANK(R38,$R$27:$R$41) -> 8 | U38: 18 | V38: 1714 | W38: =V38/U38 -> 95.222222 | X38: =RANK(W38, $W$27:$W$41) -> 6 | Z38: 16 | AA38: 1492 | AB38: =AA38/Z38 -> 93.25 | AC38: =RANK(AB38, $AB$27:$AB$40) -> 7 | AE38: 17 | AF38: 1483 | AG38: =AF38/AE38 -> 87.235294 | AH38: =RANK(AG38, $AG$27:$AG$40) -> 8 | AJ38: 17 | AK38: 1618 | AL38: =AK38/AJ38 -> 95.176471 | AM38: =RANK(AL38, $AL$27:$AL$40) -> 5 | AO38: 15 | AP38: 1411 | AQ38: =AP38/AO38 -> 94.066667 | AR38: =RANK(AQ38,$AQ$27:$AQ$40) -> 7 | AT38: 16 | AU38: 1261 | AV38: =AU38/AT38 -> 78.8125 | AW38: =RANK(AV38, $AV$27:$AV$40) -> 10
C39: 13 | D39: 奶油蒜香雞義大利麵 | E39: =VLOOKUP(D39,'[1]0805產線配置圖'!$A$2:$C$17,2,0) -> 18 | F39: =VLOOKUP(D39,'[1]0805產線配置圖'!$A$2:$C$17,3,0) -> 1200 | G39: =F39/E39 -> 66.666667 | I39: =AVERAGE(P39,U39,Z39,AE39,AJ39,AO39,AT39) -> 18.142857 | J39: =AVERAGE(Q39,V39,AA39,AF39,AK39,AP39,AU39) -> 1397 | K39: =AVERAGE(R39,W39,AB39,AG39,AL39,AQ39,AV39) -> 77.151681 | M39: =RANK(K39, K$27:$K$41) -> 11 | P39: 18 | Q39: 1170 | R39: =Q39/P39 -> 65 | S39: =RANK(R39,$R$27:$R$41) -> 13 | U39: 18 | V39: 1460 | W39: =V39/U39 -> 81.111111 | X39: =RANK(W39, $W$27:$W$41) -> 8 | Z39: 20 | AA39: 1493 | AB39: =AA39/Z39 -> 74.65 | AC39: =RANK(AB39, $AB$27:$AB$40) -> 11 | AE39: 18 | AF39: 1308 | AG39: =AF39/AE39 -> 72.666667 | AH39: =RANK(AG39, $AG$27:$AG$40) -> 12 | AJ39: 18 | AK39: 1462 | AL39: =AK39/AJ39 -> 81.222222 | AM39: =RANK(AL39, $AL$27:$AL$40) -> 10 | AO39: 17 | AP39: 1554 | AQ39: =AP39/AO39 -> 91.411765 | AR39: =RANK(AQ39,$AQ$27:$AQ$40) -> 10 | AT39: 18 | AU39: 1332 | AV39: =AU39/AT39 -> 74 | AW39: =RANK(AV39, $AV$27:$AV$40) -> 12
C40: 14 | D40: 蕃茄莎莎鮪魚冷義大利麵 | E40: =VLOOKUP(D40,'[1]0805產線配置圖'!$A$2:$C$17,2,0) -> 17 | F40: =VLOOKUP(D40,'[1]0805產線配置圖'!$A$2:$C$17,3,0) -> 1333 | G40: =F40/E40 -> 78.411765 | I40: =AVERAGE(P40,U40,Z40,AE40,AJ40,AO40,AT40) -> 16 | J40: =AVERAGE(Q40,V40,AA40,AF40,AK40,AP40,AU40) -> 1211.2857 | K40: =AVERAGE(R40,W40,AB40,AG40,AL40,AQ40,AV40) -> 75.870678 | M40: =RANK(K40, K$27:$K$41) -> 13 | P40: 17 | Q40: 1488 | R40: =Q40/P40 -> 87.529412 | S40: =RANK(R40,$R$27:$R$41) -> 10 | U40: 17 | V40: 1224 | W40: =V40/U40 -> 72 | X40: =RANK(W40, $W$27:$W$41) -> 12 | Z40: 16 | AA40: 1402 | AB40: =AA40/Z40 -> 87.625 | AC40: =RANK(AB40, $AB$27:$AB$40) -> 10 | AE40: 17 | AF40: 1129 | AG40: =AF40/AE40 -> 66.411765 | AH40: =RANK(AG40, $AG$27:$AG$40) -> 13 | AJ40: 15 | AK40: 1059 | AL40: =AK40/AJ40 -> 70.6 | AM40: =RANK(AL40, $AL$27:$AL$40) -> 12 | AO40: 14 | AP40: 1217 | AQ40: =AP40/AO40 -> 86.928571 | AR40: =RANK(AQ40,$AQ$27:$AQ$40) -> 12 | AT40: 16 | AU40: 960 | AV40: =AU40/AT40 -> 60 | AW40: =RANK(AV40, $AV$27:$AV$40) -> 14
...

Sheet （５-2）品群別人時生產性(季節調理麵) 
B1: 月平均人時性 | C1: =AVERAGE(L7,L27,L47,L67,L87) -> #DIV/0!
B2: 產線配置圖－每週更新 | N2: 資料繳交 | O2: 日期 | AE2: 45870 | AJ2: 45871 | AO2: 45872 | AT2: 45873
P3: 二 | U3: 三 | Z3: 四 | AE3: 五 | AJ3: 六 | AO3: 日 | AT3: 一
B4: 品群 | C4: 商品名稱 | E4: 計畫 | H4: 平均人時性 | I4: 實績 | L4: 平均人時性 | M4: 排名 | O4: 日報 | P4: 實際 | T4: 平均人時性 | U4: 實際 | Y4: 平均人時性 | Z4: 實際 | AD4: 平均人時性 | AE4: 實際 | AI4: 平均人時性 | AJ4: 實際 | AN4: 平均人時性 | AO4: 實際 | AS4: 平均人時性 | AT4: 實際 | AX4: 平均人時性
E5: 產線配置圖 | I5: 產線配置圖 | P5: 生產實績 | U5: 生產實績 | Z5: 生產實績 | AE5: 生產實績 | AJ5: 生產實績 | AO5: 生產實績 | AT5: 生產實績
E6: 人數 | F6: 產能／時 | G6: 人時性 | I6: 人數 | J6: 產能／時 | K6: 人時性 | P6: 人數 | Q6: 產能／時 | R6: 人時性 | S6: 排名 | U6: 人數 | V6: 產能／時 | W6: 人時性 | X6: 排名 | Z6: 人數 | AA6: 產能／時 | AB6: 人時性 | AC6: 排名 | AE6: 人數 | AF6: 產能／時 | AG6: 人時性 | AH6: 排名 | AJ6: 人數 | AK6: 產能／時 | AL6: 人時性 | AM6: 排名 | AO6: 人數 | AP6: 產能／時 | AQ6: 人時性 | AR6: 排名 | AT6: 人數 | AU6: 產能／時 | AV6: 人時性 | AW6: 排名
B7: 熱食調理麵 | C7: 1 | H7: =AVERAGE(G7:G21) -> #DIV/0! | I7: =AVERAGE(P7,U7,Z7,AE7,AJ7,AO7,AT7) -> #DIV/0! | J7: =AVERAGE(Q7,V7,AA7,AF7,AK7,AP7,AU7) -> #DIV/0! | K7: =AVERAGE(R7,W7,AB7,AG7,AL7,AQ7,AV7) -> #DIV/0! | L7: =AVERAGE(K7:K21) -> #DIV/0! | M7: =RANK(K7, K$7:$K$21) -> #DIV/0! | S7: =RANK(R7, R$7:R$21) -> #N/A | T7: =AVERAGE(R7:R21) -> #DIV/0! | X7: =RANK(W7, W$7:W$21) -> #N/A | Y7: =AVERAGE(W7:W21) -> #DIV/0! | AC7: =RANK(AB7, AB$7:AB$21) -> #N/A | AD7: =AVERAGE(AB7:AB21) -> #DIV/0! | AH7: =RANK(AG7, AG$7:AG$21) -> #N/A | AI7: =AVERAGE(AG7:AG21) -> #DIV/0! | AM7: =RANK(AL7, AL$7:AL$21) -> #N/A | AN7: =AVERAGE(AL7:AL21) -> #DIV/0! | AR7: =RANK(AQ7, AQ$7:AQ$21) -> #N/A | AS7: =AVERAGE(AQ7:AQ21) -> #DIV/0! | AW7: =RANK(AV7, AV$7:AV$21) -> #N/A | AX7: =AVERAGE(AV7:AV21) -> #DIV/0!
